Workbook

Sheet はじめに
B1: 広島市 区役所窓口 来庁者データ見える化ブック
B2: はじめての方でも、クリックだけで「いつ・どの区が・どれくらい混むか」が分かります。
B4: 使い方は3ステップ
C5: ① 黄色いセルを探す | D5: 各シートの上のほうにある黄色いセルが「選ぶところ」です。▼ボタンから選ぶだけ。
C6: ② 選ぶ | D6: 区・月・開庁時間などを選ぶと、数字もグラフも一瞬で切り替わります。
C7: ③ グラフを見る | D7: ダッシュボードの上の「💡」の一文が、選んだ内容を日本語で説明してくれます。
B9: シート案内（クリックで移動）
C10: ダッシュボード | D10: 全体像。区・月・開庁時間を選ぶと、KPI・グラフが切り替わる中心シート。
C11: ヒートマップ | D11: 曜日×時間、月×時間、区ごとの1日の流れを色で見る。
C12: カレンダー | D12: 1日ごとの来庁者数を、年間カレンダーで色分け。
C13: シミュレーター | D13: 何時に開けて何時に閉めると何人カバーできるか、案を比べる。
C14: 業務ランキング | D14: どの窓口業務が多いか、待ち時間が長いのはどれか。
C15: PDF突合 | D15: 元のPDFの数字とこのブックの集計が一致するかのチェック表。
C16: データ | D16: 集計済みのデータ置き場（触らなくてOK）。
B18: 色の意味
D19: 黄色＝あなたが選ぶセル
D20: 青緑＝開庁時間の「内」／ふつうの値
D21: オレンジ＝開庁時間の「外」／注目してほしい値
D22: 赤＝とくに多い・混んでいる
B24: 言葉の説明
C25: 発券 | D25: 窓口の番号札（整理券）を取ること。＝来庁した人の数として数えています。
C26: 15分ごとの時間帯 | D26: 例「9:00」は 9:00〜9:15 に発券した人数。元のPDFでは終わりの時刻（9-15）で表記しています。
C27: 開庁時間外 | D27: 選んだ開庁時間より前・後に発券した人。窓口の時間を変えたとき、影響を受けそうな人数の目安。
C28: 待ち時間 | D28: 番号札を取ってから呼ばれるまでの時間。3時間を超える極端な値は平均から除いています。
B30: 元データ
C31: 区役所の番号発券機の記録（令和7年4月〜令和8年3月、762,002件）を集計。個人を特定する情報は含まれていません。

Sheet ダッシュボード
B1: 広島市 区役所窓口 来庁者ダッシュボード（令和7年度）
B2: 番号発券機のデータ（2025年4月〜2026年3月、762,002人分）を見える化しました。黄色いセルを▼から選ぶと、グラフが全部切り替わります。
B4: ① 区 | D4: 全区 | H4: ② 月 | J4: 全期間 | N4: ③ 開庁(案) | P4: 0.375 | T4: ④ 〜まで | V4: 0.6875 | Y4: ←選んでね
B5: ※ マクロ版（.xlsm）には「区を順番に再生」「月を順番に再生」などのボタンが付いています。
B7: 来庁者の合計（人） | G7: 1日あたり（人） | L7: 一番混む15分 | Q7: 開庁時間外の割合 | V7: 平均待ち時間（分）
B8: ='計算'!B12 -> 762002 | G8: ='計算'!B23 -> 2953.4961 | L8: ='計算'!B17 -> 10:30〜10:45 | Q8: ='計算'!B15 -> 0.10972806 | V8: ='計算'!B24 -> 7.8387378
B10: ='ダッシュボード'!$D$4&" ／ "&'ダッシュボード'!$J$4 -> 全区 ／ 全期間 | G10: ="営業日 "&'計算'!B22&" 日" -> 営業日 258 日 | L10: ="最大 "&TEXT('計算'!B18,"#,##0")&" 人" -> 最大 26,217 人 | Q10: =TEXT('計算'!B14,"#,##0")&" 人が時間外" -> 83,613 人が時間外 | V10: ="3時間超の外れ値を除く" -> 3時間超の外れ値を除く
B12: ="💡 "&'ダッシュボード'!$D$4&"の"&'ダッシュボード'!$J$4&"は、"&'計算'!B17&"が一番混みます。開庁時間("&TEXT('ダッシュボード'!$P$4,"h:mm")&"〜"&TEXT('ダッシュボード'!$V$4,"h:mm")&")の外で、"&TEXT('計算'!B14,"#,##0")&"人（"&TEXT('計算'!B15,"0.0%")&"）が来庁しています。" -> 💡 全区の全期間は、10:30〜10:45が一番混みます。開庁時間(9:00〜16:30)の外で、83,613人（11.0%）が来庁しています。
B48: ※「開庁時間外」＝③〜④で選んだ時間帯より前・後に発券された人。窓口を何時に開閉するとどれだけの人をカバーできるかの目安です。

Sheet ヒートマップ
B1: 混雑ヒートマップ ― 色が濃いほど混んでいます
B3: 区を選ぶ → | C3: 全区 | E3: 数字は隠してあります。マスにカーソルを合わせて、上の数式バーを見ると人数が分かります。
B5: ① 曜日 × 時間帯（選んだ区の1年間の合計）
B6: 曜日 | D6: 7時 | H6: 8時 | L6: 9時 | P6: 10時 | T6: 11時 | X6: 12時 | AB6: 13時 | AF6: 14時 | AJ6: 15時 | AN6: 16時 | AR6: 17時 | AV6: 18時 | AZ6: 19時 | BD6: 20時
B7: 月 | D7: =IFERROR(INDEX('データ'!D$127:D$189,MATCH($C$3&"|"&$B7,'データ'!$A$127:$A$189,0)),0) -> 0 | E7: =IFERROR(INDEX('データ'!E$127:E$189,MATCH($C$3&"|"&$B7,'データ'!$A$127:$A$189,0)),0) -> 0 | F7: =IFERROR(INDEX('データ'!F$127:F$189,MATCH($C$3&"|"&$B7,'データ'!$A$127:$A$189,0)),0) -> 0 | G7: =IFERROR(INDEX('データ'!G$127:G$189,MATCH($C$3&"|"&$B7,'データ'!$A$127:$A$189,0)),0) -> 43 | H7: =IFERROR(INDEX('データ'!H$127:H$189,MATCH($C$3&"|"&$B7,'データ'!$A$127:$A$189,0)),0) -> 314 | I7: =IFERROR(INDEX('データ'!I$127:I$189,MATCH($C$3&"|"&$B7,'データ'!$A$127:$A$189,0)),0) -> 1645 | J7: =IFERROR(INDEX('データ'!J$127:J$189,MATCH($C$3&"|"&$B7,'データ'!$A$127:$A$189,0)),0) -> 3375 | K7: =IFERROR(INDEX('データ'!K$127:K$189,MATCH($C$3&"|"&$B7,'データ'!$A$127:$A$189,0)),0) -> 3651 | ... BG7: =IFERROR(INDEX('データ'!BG$127:BG$189,MATCH($C$3&"|"&$B7,'データ'!$A$127:$A$189,0)),0) -> 0
B8: 火 | D8: =IFERROR(INDEX('データ'!D$127:D$189,MATCH($C$3&"|"&$B8,'データ'!$A$127:$A$189,0)),0) -> 0 | E8: =IFERROR(INDEX('データ'!E$127:E$189,MATCH($C$3&"|"&$B8,'データ'!$A$127:$A$189,0)),0) -> 0 | F8: =IFERROR(INDEX('データ'!F$127:F$189,MATCH($C$3&"|"&$B8,'データ'!$A$127:$A$189,0)),0) -> 2 | G8: =IFERROR(INDEX('データ'!G$127:G$189,MATCH($C$3&"|"&$B8,'データ'!$A$127:$A$189,0)),0) -> 33 | H8: =IFERROR(INDEX('データ'!H$127:H$189,MATCH($C$3&"|"&$B8,'データ'!$A$127:$A$189,0)),0) -> 344 | I8: =IFERROR(INDEX('データ'!I$127:I$189,MATCH($C$3&"|"&$B8,'データ'!$A$127:$A$189,0)),0) -> 1404 | J8: =IFERROR(INDEX('データ'!J$127:J$189,MATCH($C$3&"|"&$B8,'データ'!$A$127:$A$189,0)),0) -> 3116 | K8: =IFERROR(INDEX('データ'!K$127:K$189,MATCH($C$3&"|"&$B8,'データ'!$A$127:$A$189,0)),0) -> 3250 | ... BG8: =IFERROR(INDEX('データ'!BG$127:BG$189,MATCH($C$3&"|"&$B8,'データ'!$A$127:$A$189,0)),0) -> 0
B9: 水 | D9: =IFERROR(INDEX('データ'!D$127:D$189,MATCH($C$3&"|"&$B9,'データ'!$A$127:$A$189,0)),0) -> 0 | E9: =IFERROR(INDEX('データ'!E$127:E$189,MATCH($C$3&"|"&$B9,'データ'!$A$127:$A$189,0)),0) -> 0 | F9: =IFERROR(INDEX('データ'!F$127:F$189,MATCH($C$3&"|"&$B9,'データ'!$A$127:$A$189,0)),0) -> 0 | G9: =IFERROR(INDEX('データ'!G$127:G$189,MATCH($C$3&"|"&$B9,'データ'!$A$127:$A$189,0)),0) -> 24 | H9: =IFERROR(INDEX('データ'!H$127:H$189,MATCH($C$3&"|"&$B9,'データ'!$A$127:$A$189,0)),0) -> 287 | I9: =IFERROR(INDEX('データ'!I$127:I$189,MATCH($C$3&"|"&$B9,'データ'!$A$127:$A$189,0)),0) -> 1258 | J9: =IFERROR(INDEX('データ'!J$127:J$189,MATCH($C$3&"|"&$B9,'データ'!$A$127:$A$189,0)),0) -> 2958 | K9: =IFERROR(INDEX('データ'!K$127:K$189,MATCH($C$3&"|"&$B9,'データ'!$A$127:$A$189,0)),0) -> 2987 | ... BG9: =IFERROR(INDEX('データ'!BG$127:BG$189,MATCH($C$3&"|"&$B9,'データ'!$A$127:$A$189,0)),0) -> 0
B10: 木 | D10: =IFERROR(INDEX('データ'!D$127:D$189,MATCH($C$3&"|"&$B10,'データ'!$A$127:$A$189,0)),0) -> 0 | E10: =IFERROR(INDEX('データ'!E$127:E$189,MATCH($C$3&"|"&$B10,'データ'!$A$127:$A$189,0)),0) -> 0 | F10: =IFERROR(INDEX('データ'!F$127:F$189,MATCH($C$3&"|"&$B10,'データ'!$A$127:$A$189,0)),0) -> 0 | G10: =IFERROR(INDEX('データ'!G$127:G$189,MATCH($C$3&"|"&$B10,'データ'!$A$127:$A$189,0)),0) -> 36 | H10: =IFERROR(INDEX('データ'!H$127:H$189,MATCH($C$3&"|"&$B10,'データ'!$A$127:$A$189,0)),0) -> 266 | I10: =IFERROR(INDEX('データ'!I$127:I$189,MATCH($C$3&"|"&$B10,'データ'!$A$127:$A$189,0)),0) -> 1215 | J10: =IFERROR(INDEX('データ'!J$127:J$189,MATCH($C$3&"|"&$B10,'データ'!$A$127:$A$189,0)),0) -> 2748 | K10: =IFERROR(INDEX('データ'!K$127:K$189,MATCH($C$3&"|"&$B10,'データ'!$A$127:$A$189,0)),0) -> 3056 | ... BG10: =IFERROR(INDEX('データ'!BG$127:BG$189,MATCH($C$3&"|"&$B10,'データ'!$A$127:$A$189,0)),0) -> 0
B11: 金 | D11: =IFERROR(INDEX('データ'!D$127:D$189,MATCH($C$3&"|"&$B11,'データ'!$A$127:$A$189,0)),0) -> 0 | E11: =IFERROR(INDEX('データ'!E$127:E$189,MATCH($C$3&"|"&$B11,'データ'!$A$127:$A$189,0)),0) -> 0 | F11: =IFERROR(INDEX('データ'!F$127:F$189,MATCH($C$3&"|"&$B11,'データ'!$A$127:$A$189,0)),0) -> 1 | G11: =IFERROR(INDEX('データ'!G$127:G$189,MATCH($C$3&"|"&$B11,'データ'!$A$127:$A$189,0)),0) -> 37 | H11: =IFERROR(INDEX('データ'!H$127:H$189,MATCH($C$3&"|"&$B11,'データ'!$A$127:$A$189,0)),0) -> 315 | I11: =IFERROR(INDEX('データ'!I$127:I$189,MATCH($C$3&"|"&$B11,'データ'!$A$127:$A$189,0)),0) -> 1264 | J11: =IFERROR(INDEX('データ'!J$127:J$189,MATCH($C$3&"|"&$B11,'データ'!$A$127:$A$189,0)),0) -> 2932 | K11: =IFERROR(INDEX('データ'!K$127:K$189,MATCH($C$3&"|"&$B11,'データ'!$A$127:$A$189,0)),0) -> 3282 | ... BG11: =IFERROR(INDEX('データ'!BG$127:BG$189,MATCH($C$3&"|"&$B11,'データ'!$A$127:$A$189,0)),0) -> 0
B12: 土 | D12: =IFERROR(INDEX('データ'!D$127:D$189,MATCH($C$3&"|"&$B12,'データ'!$A$127:$A$189,0)),0) -> 0 | E12: =IFERROR(INDEX('データ'!E$127:E$189,MATCH($C$3&"|"&$B12,'データ'!$A$127:$A$189,0)),0) -> 0 | F12: =IFERROR(INDEX('データ'!F$127:F$189,MATCH($C$3&"|"&$B12,'データ'!$A$127:$A$189,0)),0) -> 0 | G12: =IFERROR(INDEX('データ'!G$127:G$189,MATCH($C$3&"|"&$B12,'データ'!$A$127:$A$189,0)),0) -> 0 | H12: =IFERROR(INDEX('データ'!H$127:H$189,MATCH($C$3&"|"&$B12,'データ'!$A$127:$A$189,0)),0) -> 1 | I12: =IFERROR(INDEX('データ'!I$127:I$189,MATCH($C$3&"|"&$B12,'データ'!$A$127:$A$189,0)),0) -> 10 | J12: =IFERROR(INDEX('データ'!J$127:J$189,MATCH($C$3&"|"&$B12,'データ'!$A$127:$A$189,0)),0) -> 19 | K12: =IFERROR(INDEX('データ'!K$127:K$189,MATCH($C$3&"|"&$B12,'データ'!$A$127:$A$189,0)),0) -> 11 | ... BG12: =IFERROR(INDEX('データ'!BG$127:BG$189,MATCH($C$3&"|"&$B12,'データ'!$A$127:$A$189,0)),0) -> 0
B13: 日 | D13: =IFERROR(INDEX('データ'!D$127:D$189,MATCH($C$3&"|"&$B13,'データ'!$A$127:$A$189,0)),0) -> 0 | E13: =IFERROR(INDEX('データ'!E$127:E$189,MATCH($C$3&"|"&$B13,'データ'!$A$127:$A$189,0)),0) -> 0 | F13: =IFERROR(INDEX('データ'!F$127:F$189,MATCH($C$3&"|"&$B13,'データ'!$A$127:$A$189,0)),0) -> 0 | G13: =IFERROR(INDEX('データ'!G$127:G$189,MATCH($C$3&"|"&$B13,'データ'!$A$127:$A$189,0)),0) -> 10 | H13: =IFERROR(INDEX('データ'!H$127:H$189,MATCH($C$3&"|"&$B13,'データ'!$A$127:$A$189,0)),0) -> 83 | I13: =IFERROR(INDEX('データ'!I$127:I$189,MATCH($C$3&"|"&$B13,'データ'!$A$127:$A$189,0)),0) -> 189 | J13: =IFERROR(INDEX('データ'!J$127:J$189,MATCH($C$3&"|"&$B13,'データ'!$A$127:$A$189,0)),0) -> 218 | K13: =IFERROR(INDEX('データ'!K$127:K$189,MATCH($C$3&"|"&$B13,'データ'!$A$127:$A$189,0)),0) -> 190 | ... BG13: =IFERROR(INDEX('データ'!BG$127:BG$189,MATCH($C$3&"|"&$B13,'データ'!$A$127:$A$189,0)),0) -> 0
B15: ② 月 × 時間帯（選んだ区）
D16: 7時 | H16: 8時 | L16: 9時 | P16: 10時 | T16: 11時 | X16: 12時 | AB16: 13時 | AF16: 14時 | AJ16: 15時 | AN16: 16時 | AR16: 17時 | AV16: 18時 | AZ16: 19時 | BD16: 20時
B17: 4月 | D17: =IFERROR(INDEX('データ'!D$7:D$123,MATCH($C$3&"|"&$B17,'データ'!$A$7:$A$123,0)),0) -> 0 | E17: =IFERROR(INDEX('データ'!E$7:E$123,MATCH($C$3&"|"&$B17,'データ'!$A$7:$A$123,0)),0) -> 0 | F17: =IFERROR(INDEX('データ'!F$7:F$123,MATCH($C$3&"|"&$B17,'データ'!$A$7:$A$123,0)),0) -> 0 | G17: =IFERROR(INDEX('データ'!G$7:G$123,MATCH($C$3&"|"&$B17,'データ'!$A$7:$A$123,0)),0) -> 23 | H17: =IFERROR(INDEX('データ'!H$7:H$123,MATCH($C$3&"|"&$B17,'データ'!$A$7:$A$123,0)),0) -> 186 | I17: =IFERROR(INDEX('データ'!I$7:I$123,MATCH($C$3&"|"&$B17,'データ'!$A$7:$A$123,0)),0) -> 801 | J17: =IFERROR(INDEX('データ'!J$7:J$123,MATCH($C$3&"|"&$B17,'データ'!$A$7:$A$123,0)),0) -> 1479 | K17: =IFERROR(INDEX('データ'!K$7:K$123,MATCH($C$3&"|"&$B17,'データ'!$A$7:$A$123,0)),0) -> 1695 | ... BG17: =IFERROR(INDEX('データ'!BG$7:BG$123,MATCH($C$3&"|"&$B17,'データ'!$A$7:$A$123,0)),0) -> 0
B18: 5月 | D18: =IFERROR(INDEX('データ'!D$7:D$123,MATCH($C$3&"|"&$B18,'データ'!$A$7:$A$123,0)),0) -> 0 | E18: =IFERROR(INDEX('データ'!E$7:E$123,MATCH($C$3&"|"&$B18,'データ'!$A$7:$A$123,0)),0) -> 0 | F18: =IFERROR(INDEX('データ'!F$7:F$123,MATCH($C$3&"|"&$B18,'データ'!$A$7:$A$123,0)),0) -> 2 | G18: =IFERROR(INDEX('データ'!G$7:G$123,MATCH($C$3&"|"&$B18,'データ'!$A$7:$A$123,0)),0) -> 18 | H18: =IFERROR(INDEX('データ'!H$7:H$123,MATCH($C$3&"|"&$B18,'データ'!$A$7:$A$123,0)),0) -> 169 | I18: =IFERROR(INDEX('データ'!I$7:I$123,MATCH($C$3&"|"&$B18,'データ'!$A$7:$A$123,0)),0) -> 645 | J18: =IFERROR(INDEX('データ'!J$7:J$123,MATCH($C$3&"|"&$B18,'データ'!$A$7:$A$123,0)),0) -> 1373 | K18: =IFERROR(INDEX('データ'!K$7:K$123,MATCH($C$3&"|"&$B18,'データ'!$A$7:$A$123,0)),0) -> 1502 | ... BG18: =IFERROR(INDEX('データ'!BG$7:BG$123,MATCH($C$3&"|"&$B18,'データ'!$A$7:$A$123,0)),0) -> 0
B19: 6月 | D19: =IFERROR(INDEX('データ'!D$7:D$123,MATCH($C$3&"|"&$B19,'データ'!$A$7:$A$123,0)),0) -> 0 | E19: =IFERROR(INDEX('データ'!E$7:E$123,MATCH($C$3&"|"&$B19,'データ'!$A$7:$A$123,0)),0) -> 0 | F19: =IFERROR(INDEX('データ'!F$7:F$123,MATCH($C$3&"|"&$B19,'データ'!$A$7:$A$123,0)),0) -> 1 | G19: =IFERROR(INDEX('データ'!G$7:G$123,MATCH($C$3&"|"&$B19,'データ'!$A$7:$A$123,0)),0) -> 14 | H19: =IFERROR(INDEX('データ'!H$7:H$123,MATCH($C$3&"|"&$B19,'データ'!$A$7:$A$123,0)),0) -> 150 | I19: =IFERROR(INDEX('データ'!I$7:I$123,MATCH($C$3&"|"&$B19,'データ'!$A$7:$A$123,0)),0) -> 591 | J19: =IFERROR(INDEX('データ'!J$7:J$123,MATCH($C$3&"|"&$B19,'データ'!$A$7:$A$123,0)),0) -> 1256 | K19: =IFERROR(INDEX('データ'!K$7:K$123,MATCH($C$3&"|"&$B19,'データ'!$A$7:$A$123,0)),0) -> 1482 | ... BG19: =IFERROR(INDEX('データ'!BG$7:BG$123,MATCH($C$3&"|"&$B19,'データ'!$A$7:$A$123,0)),0) -> 0
B20: 7月 | D20: =IFERROR(INDEX('データ'!D$7:D$123,MATCH($C$3&"|"&$B20,'データ'!$A$7:$A$123,0)),0) -> 0 | E20: =IFERROR(INDEX('データ'!E$7:E$123,MATCH($C$3&"|"&$B20,'データ'!$A$7:$A$123,0)),0) -> 0 | F20: =IFERROR(INDEX('データ'!F$7:F$123,MATCH($C$3&"|"&$B20,'データ'!$A$7:$A$123,0)),0) -> 0 | G20: =IFERROR(INDEX('データ'!G$7:G$123,MATCH($C$3&"|"&$B20,'データ'!$A$7:$A$123,0)),0) -> 38 | H20: =IFERROR(INDEX('データ'!H$7:H$123,MATCH($C$3&"|"&$B20,'データ'!$A$7:$A$123,0)),0) -> 217 | I20: =IFERROR(INDEX('データ'!I$7:I$123,MATCH($C$3&"|"&$B20,'データ'!$A$7:$A$123,0)),0) -> 766 | J20: =IFERROR(INDEX('データ'!J$7:J$123,MATCH($C$3&"|"&$B20,'データ'!$A$7:$A$123,0)),0) -> 1541 | K20: =IFERROR(INDEX('データ'!K$7:K$123,MATCH($C$3&"|"&$B20,'データ'!$A$7:$A$123,0)),0) -> 1666 | ... BG20: =IFERROR(INDEX('データ'!BG$7:BG$123,MATCH($C$3&"|"&$B20,'データ'!$A$7:$A$123,0)),0) -> 0
B21: 8月 | D21: =IFERROR(INDEX('データ'!D$7:D$123,MATCH($C$3&"|"&$B21,'データ'!$A$7:$A$123,0)),0) -> 0 | E21: =IFERROR(INDEX('データ'!E$7:E$123,MATCH($C$3&"|"&$B21,'データ'!$A$7:$A$123,0)),0) -> 0 | F21: =IFERROR(INDEX('データ'!F$7:F$123,MATCH($C$3&"|"&$B21,'データ'!$A$7:$A$123,0)),0) -> 0 | G21: =IFERROR(INDEX('データ'!G$7:G$123,MATCH($C$3&"|"&$B21,'データ'!$A$7:$A$123,0)),0) -> 25 | H21: =IFERROR(INDEX('データ'!H$7:H$123,MATCH($C$3&"|"&$B21,'データ'!$A$7:$A$123,0)),0) -> 187 | I21: =IFERROR(INDEX('データ'!I$7:I$123,MATCH($C$3&"|"&$B21,'データ'!$A$7:$A$123,0)),0) -> 610 | J21: =IFERROR(INDEX('データ'!J$7:J$123,MATCH($C$3&"|"&$B21,'データ'!$A$7:$A$123,0)),0) -> 1303 | K21: =IFERROR(INDEX('データ'!K$7:K$123,MATCH($C$3&"|"&$B21,'データ'!$A$7:$A$123,0)),0) -> 1462 | ... BG21: =IFERROR(INDEX('データ'!BG$7:BG$123,MATCH($C$3&"|"&$B21,'データ'!$A$7:$A$123,0)),0) -> 0
B22: 9月 | D22: =IFERROR(INDEX('データ'!D$7:D$123,MATCH($C$3&"|"&$B22,'データ'!$A$7:$A$123,0)),0) -> 0 | E22: =IFERROR(INDEX('データ'!E$7:E$123,MATCH($C$3&"|"&$B22,'データ'!$A$7:$A$123,0)),0) -> 0 | F22: =IFERROR(INDEX('データ'!F$7:F$123,MATCH($C$3&"|"&$B22,'データ'!$A$7:$A$123,0)),0) -> 0 | G22: =IFERROR(INDEX('データ'!G$7:G$123,MATCH($C$3&"|"&$B22,'データ'!$A$7:$A$123,0)),0) -> 16 | H22: =IFERROR(INDEX('データ'!H$7:H$123,MATCH($C$3&"|"&$B22,'データ'!$A$7:$A$123,0)),0) -> 152 | I22: =IFERROR(INDEX('データ'!I$7:I$123,MATCH($C$3&"|"&$B22,'データ'!$A$7:$A$123,0)),0) -> 492 | J22: =IFERROR(INDEX('データ'!J$7:J$123,MATCH($C$3&"|"&$B22,'データ'!$A$7:$A$123,0)),0) -> 1121 | K22: =IFERROR(INDEX('データ'!K$7:K$123,MATCH($C$3&"|"&$B22,'データ'!$A$7:$A$123,0)),0) -> 1291 | ... BG22: =IFERROR(INDEX('データ'!BG$7:BG$123,MATCH($C$3&"|"&$B22,'データ'!$A$7:$A$123,0)),0) -> 0
B23: 10月 | D23: =IFERROR(INDEX('データ'!D$7:D$123,MATCH($C$3&"|"&$B23,'データ'!$A$7:$A$123,0)),0) -> 0 | E23: =IFERROR(INDEX('データ'!E$7:E$123,MATCH($C$3&"|"&$B23,'データ'!$A$7:$A$123,0)),0) -> 0 | F23: =IFERROR(INDEX('データ'!F$7:F$123,MATCH($C$3&"|"&$B23,'データ'!$A$7:$A$123,0)),0) -> 0 | G23: =IFERROR(INDEX('データ'!G$7:G$123,MATCH($C$3&"|"&$B23,'データ'!$A$7:$A$123,0)),0) -> 18 | H23: =IFERROR(INDEX('データ'!H$7:H$123,MATCH($C$3&"|"&$B23,'データ'!$A$7:$A$123,0)),0) -> 161 | I23: =IFERROR(INDEX('データ'!I$7:I$123,MATCH($C$3&"|"&$B23,'データ'!$A$7:$A$123,0)),0) -> 476 | J23: =IFERROR(INDEX('データ'!J$7:J$123,MATCH($C$3&"|"&$B23,'データ'!$A$7:$A$123,0)),0) -> 1189 | K23: =IFERROR(INDEX('データ'!K$7:K$123,MATCH($C$3&"|"&$B23,'データ'!$A$7:$A$123,0)),0) -> 1400 | ... BG23: =IFERROR(INDEX('データ'!BG$7:BG$123,MATCH($C$3&"|"&$B23,'データ'!$A$7:$A$123,0)),0) -> 0
B24: 11月 | D24: =IFERROR(INDEX('データ'!D$7:D$123,MATCH($C$3&"|"&$B24,'データ'!$A$7:$A$123,0)),0) -> 0 | E24: =IFERROR(INDEX('データ'!E$7:E$123,MATCH($C$3&"|"&$B24,'データ'!$A$7:$A$123,0)),0) -> 0 | F24: =IFERROR(INDEX('データ'!F$7:F$123,MATCH($C$3&"|"&$B24,'データ'!$A$7:$A$123,0)),0) -> 0 | G24: =IFERROR(INDEX('データ'!G$7:G$123,MATCH($C$3&"|"&$B24,'データ'!$A$7:$A$123,0)),0) -> 22 | H24: =IFERROR(INDEX('データ'!H$7:H$123,MATCH($C$3&"|"&$B24,'データ'!$A$7:$A$123,0)),0) -> 115 | I24: =IFERROR(INDEX('データ'!I$7:I$123,MATCH($C$3&"|"&$B24,'データ'!$A$7:$A$123,0)),0) -> 341 | J24: =IFERROR(INDEX('データ'!J$7:J$123,MATCH($C$3&"|"&$B24,'データ'!$A$7:$A$123,0)),0) -> 793 | K24: =IFERROR(INDEX('データ'!K$7:K$123,MATCH($C$3&"|"&$B24,'データ'!$A$7:$A$123,0)),0) -> 934 | ... BG24: =IFERROR(INDEX('データ'!BG$7:BG$123,MATCH($C$3&"|"&$B24,'データ'!$A$7:$A$123,0)),0) -> 0
B25: 12月 | D25: =IFERROR(INDEX('データ'!D$7:D$123,MATCH($C$3&"|"&$B25,'データ'!$A$7:$A$123,0)),0) -> 0 | E25: =IFERROR(INDEX('データ'!E$7:E$123,MATCH($C$3&"|"&$B25,'データ'!$A$7:$A$123,0)),0) -> 0 | F25: =IFERROR(INDEX('データ'!F$7:F$123,MATCH($C$3&"|"&$B25,'データ'!$A$7:$A$123,0)),0) -> 0 | G25: =IFERROR(INDEX('データ'!G$7:G$123,MATCH($C$3&"|"&$B25,'データ'!$A$7:$A$123,0)),0) -> 2 | H25: =IFERROR(INDEX('データ'!H$7:H$123,MATCH($C$3&"|"&$B25,'データ'!$A$7:$A$123,0)),0) -> 43 | I25: =IFERROR(INDEX('データ'!I$7:I$123,MATCH($C$3&"|"&$B25,'データ'!$A$7:$A$123,0)),0) -> 366 | J25: =IFERROR(INDEX('データ'!J$7:J$123,MATCH($C$3&"|"&$B25,'データ'!$A$7:$A$123,0)),0) -> 1021 | K25: =IFERROR(INDEX('データ'!K$7:K$123,MATCH($C$3&"|"&$B25,'データ'!$A$7:$A$123,0)),0) -> 1014 | ... BG25: =IFERROR(INDEX('データ'!BG$7:BG$123,MATCH($C$3&"|"&$B25,'データ'!$A$7:$A$123,0)),0) -> 0
B26: 1月 | D26: =IFERROR(INDEX('データ'!D$7:D$123,MATCH($C$3&"|"&$B26,'データ'!$A$7:$A$123,0)),0) -> 0 | E26: =IFERROR(INDEX('データ'!E$7:E$123,MATCH($C$3&"|"&$B26,'データ'!$A$7:$A$123,0)),0) -> 0 | F26: =IFERROR(INDEX('データ'!F$7:F$123,MATCH($C$3&"|"&$B26,'データ'!$A$7:$A$123,0)),0) -> 0 | G26: =IFERROR(INDEX('データ'!G$7:G$123,MATCH($C$3&"|"&$B26,'データ'!$A$7:$A$123,0)),0) -> 3 | H26: =IFERROR(INDEX('データ'!H$7:H$123,MATCH($C$3&"|"&$B26,'データ'!$A$7:$A$123,0)),0) -> 46 | I26: =IFERROR(INDEX('データ'!I$7:I$123,MATCH($C$3&"|"&$B26,'データ'!$A$7:$A$123,0)),0) -> 406 | J26: =IFERROR(INDEX('データ'!J$7:J$123,MATCH($C$3&"|"&$B26,'データ'!$A$7:$A$123,0)),0) -> 930 | K26: =IFERROR(INDEX('データ'!K$7:K$123,MATCH($C$3&"|"&$B26,'データ'!$A$7:$A$123,0)),0) -> 878 | ... BG26: =IFERROR(INDEX('データ'!BG$7:BG$123,MATCH($C$3&"|"&$B26,'データ'!$A$7:$A$123,0)),0) -> 0
B27: 2月 | D27: =IFERROR(INDEX('データ'!D$7:D$123,MATCH($C$3&"|"&$B27,'データ'!$A$7:$A$123,0)),0) -> 0 | E27: =IFERROR(INDEX('データ'!E$7:E$123,MATCH($C$3&"|"&$B27,'データ'!$A$7:$A$123,0)),0) -> 0 | F27: =IFERROR(INDEX('データ'!F$7:F$123,MATCH($C$3&"|"&$B27,'データ'!$A$7:$A$123,0)),0) -> 0 | G27: =IFERROR(INDEX('データ'!G$7:G$123,MATCH($C$3&"|"&$B27,'データ'!$A$7:$A$123,0)),0) -> 1 | H27: =IFERROR(INDEX('データ'!H$7:H$123,MATCH($C$3&"|"&$B27,'データ'!$A$7:$A$123,0)),0) -> 52 | I27: =IFERROR(INDEX('データ'!I$7:I$123,MATCH($C$3&"|"&$B27,'データ'!$A$7:$A$123,0)),0) -> 510 | J27: =IFERROR(INDEX('データ'!J$7:J$123,MATCH($C$3&"|"&$B27,'データ'!$A$7:$A$123,0)),0) -> 1301 | K27: =IFERROR(INDEX('データ'!K$7:K$123,MATCH($C$3&"|"&$B27,'データ'!$A$7:$A$123,0)),0) -> 1250 | ... BG27: =IFERROR(INDEX('データ'!BG$7:BG$123,MATCH($C$3&"|"&$B27,'データ'!$A$7:$A$123,0)),0) -> 0
B28: 3月 | D28: =IFERROR(INDEX('データ'!D$7:D$123,MATCH($C$3&"|"&$B28,'データ'!$A$7:$A$123,0)),0) -> 0 | E28: =IFERROR(INDEX('データ'!E$7:E$123,MATCH($C$3&"|"&$B28,'データ'!$A$7:$A$123,0)),0) -> 0 | F28: =IFERROR(INDEX('データ'!F$7:F$123,MATCH($C$3&"|"&$B28,'データ'!$A$7:$A$123,0)),0) -> 0 | G28: =IFERROR(INDEX('データ'!G$7:G$123,MATCH($C$3&"|"&$B28,'データ'!$A$7:$A$123,0)),0) -> 3 | H28: =IFERROR(INDEX('データ'!H$7:H$123,MATCH($C$3&"|"&$B28,'データ'!$A$7:$A$123,0)),0) -> 132 | I28: =IFERROR(INDEX('データ'!I$7:I$123,MATCH($C$3&"|"&$B28,'データ'!$A$7:$A$123,0)),0) -> 981 | J28: =IFERROR(INDEX('データ'!J$7:J$123,MATCH($C$3&"|"&$B28,'データ'!$A$7:$A$123,0)),0) -> 2059 | K28: =IFERROR(INDEX('データ'!K$7:K$123,MATCH($C$3&"|"&$B28,'データ'!$A$7:$A$123,0)),0) -> 1853 | ... BG28: =IFERROR(INDEX('データ'!BG$7:BG$123,MATCH($C$3&"|"&$B28,'データ'!$A$7:$A$123,0)),0) -> 0
B30: ③ 区ごとの1日の流れ（各区の中で一番混む所が赤。形のちがいを比べてください）
B31: 区 | C31: 1年の形 | D31: 7時 | H31: 8時 | L31: 9時 | P31: 10時 | T31: 11時 | X31: 12時 | AB31: 13時 | AF31: 14時 | AJ31: 15時 | AN31: 16時 | AR31: 17時 | AV31: 18時 | AZ31: 19時 | BD31: 20時
B32: 中区 | D32: =INDEX('データ'!D$7:D$123,MATCH($B32&"|全期間",'データ'!$A$7:$A$123,0)) -> 0 | E32: =INDEX('データ'!E$7:E$123,MATCH($B32&"|全期間",'データ'!$A$7:$A$123,0)) -> 0 | F32: =INDEX('データ'!F$7:F$123,MATCH($B32&"|全期間",'データ'!$A$7:$A$123,0)) -> 1 | G32: =INDEX('データ'!G$7:G$123,MATCH($B32&"|全期間",'データ'!$A$7:$A$123,0)) -> 0 | H32: =INDEX('データ'!H$7:H$123,MATCH($B32&"|全期間",'データ'!$A$7:$A$123,0)) -> 46 | I32: =INDEX('データ'!I$7:I$123,MATCH($B32&"|全期間",'データ'!$A$7:$A$123,0)) -> 345 | J32: =INDEX('データ'!J$7:J$123,MATCH($B32&"|全期間",'データ'!$A$7:$A$123,0)) -> 1064 | K32: =INDEX('データ'!K$7:K$123,MATCH($B32&"|全期間",'データ'!$A$7:$A$123,0)) -> 2310 | ... BG32: =INDEX('データ'!BG$7:BG$123,MATCH($B32&"|全期間",'データ'!$A$7:$A$123,0)) -> 0
B33: 東区 | D33: =INDEX('データ'!D$7:D$123,MATCH($B33&"|全期間",'データ'!$A$7:$A$123,0)) -> 0 | E33: =INDEX('データ'!E$7:E$123,MATCH($B33&"|全期間",'データ'!$A$7:$A$123,0)) -> 0 | F33: =INDEX('データ'!F$7:F$123,MATCH($B33&"|全期間",'データ'!$A$7:$A$123,0)) -> 0 | G33: =INDEX('データ'!G$7:G$123,MATCH($B33&"|全期間",'データ'!$A$7:$A$123,0)) -> 9 | H33: =INDEX('データ'!H$7:H$123,MATCH($B33&"|全期間",'データ'!$A$7:$A$123,0)) -> 137 | I33: =INDEX('データ'!I$7:I$123,MATCH($B33&"|全期間",'データ'!$A$7:$A$123,0)) -> 1027 | J33: =INDEX('データ'!J$7:J$123,MATCH($B33&"|全期間",'データ'!$A$7:$A$123,0)) -> 1681 | K33: =INDEX('データ'!K$7:K$123,MATCH($B33&"|全期間",'データ'!$A$7:$A$123,0)) -> 1814 | ... BG33: =INDEX('データ'!BG$7:BG$123,MATCH($B33&"|全期間",'データ'!$A$7:$A$123,0)) -> 0
B34: 南区 | D34: =INDEX('データ'!D$7:D$123,MATCH($B34&"|全期間",'データ'!$A$7:$A$123,0)) -> 0 | E34: =INDEX('データ'!E$7:E$123,MATCH($B34&"|全期間",'データ'!$A$7:$A$123,0)) -> 0 | F34: =INDEX('データ'!F$7:F$123,MATCH($B34&"|全期間",'データ'!$A$7:$A$123,0)) -> 1 | G34: =INDEX('データ'!G$7:G$123,MATCH($B34&"|全期間",'データ'!$A$7:$A$123,0)) -> 24 | H34: =INDEX('データ'!H$7:H$123,MATCH($B34&"|全期間",'データ'!$A$7:$A$123,0)) -> 152 | I34: =INDEX('データ'!I$7:I$123,MATCH($B34&"|全期間",'データ'!$A$7:$A$123,0)) -> 1466 | J34: =INDEX('データ'!J$7:J$123,MATCH($B34&"|全期間",'データ'!$A$7:$A$123,0)) -> 3002 | K34: =INDEX('データ'!K$7:K$123,MATCH($B34&"|全期間",'データ'!$A$7:$A$123,0)) -> 2851 | ... BG34: =INDEX('データ'!BG$7:BG$123,MATCH($B34&"|全期間",'データ'!$A$7:$A$123,0)) -> 0
B35: 西区 | D35: =INDEX('データ'!D$7:D$123,MATCH($B35&"|全期間",'データ'!$A$7:$A$123,0)) -> 0 | E35: =INDEX('データ'!E$7:E$123,MATCH($B35&"|全期間",'データ'!$A$7:$A$123,0)) -> 0 | F35: =INDEX('データ'!F$7:F$123,MATCH($B35&"|全期間",'データ'!$A$7:$A$123,0)) -> 0 | G35: =INDEX('データ'!G$7:G$123,MATCH($B35&"|全期間",'データ'!$A$7:$A$123,0)) -> 3 | H35: =INDEX('データ'!H$7:H$123,MATCH($B35&"|全期間",'データ'!$A$7:$A$123,0)) -> 48 | I35: =INDEX('データ'!I$7:I$123,MATCH($B35&"|全期間",'データ'!$A$7:$A$123,0)) -> 1360 | J35: =INDEX('データ'!J$7:J$123,MATCH($B35&"|全期間",'データ'!$A$7:$A$123,0)) -> 3832 | K35: =INDEX('データ'!K$7:K$123,MATCH($B35&"|全期間",'データ'!$A$7:$A$123,0)) -> 3275 | ... BG35: =INDEX('データ'!BG$7:BG$123,MATCH($B35&"|全期間",'データ'!$A$7:$A$123,0)) -> 0
B36: 安佐南区 | D36: =INDEX('データ'!D$7:D$123,MATCH($B36&"|全期間",'データ'!$A$7:$A$123,0)) -> 0 | E36: =INDEX('データ'!E$7:E$123,MATCH($B36&"|全期間",'データ'!$A$7:$A$123,0)) -> 0 | F36: =INDEX('データ'!F$7:F$123,MATCH($B36&"|全期間",'データ'!$A$7:$A$123,0)) -> 1 | G36: =INDEX('データ'!G$7:G$123,MATCH($B36&"|全期間",'データ'!$A$7:$A$123,0)) -> 144 | H36: =INDEX('データ'!H$7:H$123,MATCH($B36&"|全期間",'データ'!$A$7:$A$123,0)) -> 1081 | I36: =INDEX('データ'!I$7:I$123,MATCH($B36&"|全期間",'データ'!$A$7:$A$123,0)) -> 1719 | J36: =INDEX('データ'!J$7:J$123,MATCH($B36&"|全期間",'データ'!$A$7:$A$123,0)) -> 2053 | K36: =INDEX('データ'!K$7:K$123,MATCH($B36&"|全期間",'データ'!$A$7:$A$123,0)) -> 2257 | ... BG36: =INDEX('データ'!BG$7:BG$123,MATCH($B36&"|全期間",'データ'!$A$7:$A$123,0)) -> 0
B37: 安佐北区 | D37: =INDEX('データ'!D$7:D$123,MATCH($B37&"|全期間",'データ'!$A$7:$A$123,0)) -> 0 | E37: =INDEX('データ'!E$7:E$123,MATCH($B37&"|全期間",'データ'!$A$7:$A$123,0)) -> 0 | F37: =INDEX('データ'!F$7:F$123,MATCH($B37&"|全期間",'データ'!$A$7:$A$123,0)) -> 0 | G37: =INDEX('データ'!G$7:G$123,MATCH($B37&"|全期間",'データ'!$A$7:$A$123,0)) -> 1 | H37: =INDEX('データ'!H$7:H$123,MATCH($B37&"|全期間",'データ'!$A$7:$A$123,0)) -> 12 | I37: =INDEX('データ'!I$7:I$123,MATCH($B37&"|全期間",'データ'!$A$7:$A$123,0)) -> 133 | J37: =INDEX('データ'!J$7:J$123,MATCH($B37&"|全期間",'データ'!$A$7:$A$123,0)) -> 810 | K37: =INDEX('データ'!K$7:K$123,MATCH($B37&"|全期間",'データ'!$A$7:$A$123,0)) -> 1025 | ... BG37: =INDEX('データ'!BG$7:BG$123,MATCH($B37&"|全期間",'データ'!$A$7:$A$123,0)) -> 0
B38: 安芸区 | D38: =INDEX('データ'!D$7:D$123,MATCH($B38&"|全期間",'データ'!$A$7:$A$123,0)) -> 0 | E38: =INDEX('データ'!E$7:E$123,MATCH($B38&"|全期間",'データ'!$A$7:$A$123,0)) -> 0 | F38: =INDEX('データ'!F$7:F$123,MATCH($B38&"|全期間",'データ'!$A$7:$A$123,0)) -> 0 | G38: =INDEX('データ'!G$7:G$123,MATCH($B38&"|全期間",'データ'!$A$7:$A$123,0)) -> 0 | H38: =INDEX('データ'!H$7:H$123,MATCH($B38&"|全期間",'データ'!$A$7:$A$123,0)) -> 3 | I38: =INDEX('データ'!I$7:I$123,MATCH($B38&"|全期間",'データ'!$A$7:$A$123,0)) -> 190 | J38: =INDEX('データ'!J$7:J$123,MATCH($B38&"|全期間",'データ'!$A$7:$A$123,0)) -> 676 | K38: =INDEX('データ'!K$7:K$123,MATCH($B38&"|全期間",'データ'!$A$7:$A$123,0)) -> 746 | ... BG38: =INDEX('データ'!BG$7:BG$123,MATCH($B38&"|全期間",'データ'!$A$7:$A$123,0)) -> 0
B39: 佐伯区 | D39: =INDEX('データ'!D$7:D$123,MATCH($B39&"|全期間",'データ'!$A$7:$A$123,0)) -> 0 | E39: =INDEX('データ'!E$7:E$123,MATCH($B39&"|全期間",'データ'!$A$7:$A$123,0)) -> 0 | F39: =INDEX('データ'!F$7:F$123,MATCH($B39&"|全期間",'データ'!$A$7:$A$123,0)) -> 0 | G39: =INDEX('データ'!G$7:G$123,MATCH($B39&"|全期間",'データ'!$A$7:$A$123,0)) -> 2 | H39: =INDEX('データ'!H$7:H$123,MATCH($B39&"|全期間",'データ'!$A$7:$A$123,0)) -> 131 | I39: =INDEX('データ'!I$7:I$123,MATCH($B39&"|全期間",'データ'!$A$7:$A$123,0)) -> 745 | J39: =INDEX('データ'!J$7:J$123,MATCH($B39&"|全期間",'データ'!$A$7:$A$123,0)) -> 2248 | K39: =INDEX('データ'!K$7:K$123,MATCH($B39&"|全期間",'データ'!$A$7:$A$123,0)) -> 2149 | ... BG39: =INDEX('データ'!BG$7:BG$123,MATCH($B39&"|全期間",'データ'!$A$7:$A$123,0)) -> 0
B41: 凡例： | O41: 空いている ← → 混んでいる

Sheet カレンダー
B1: 来庁者カレンダー ― 1日ごとの来庁者数（色が濃いほど多い日）
A2: =MATCH($C$3,'データ'!$B$312:$J$312,0) -> 1
B3: 区を選ぶ → | C3: 全区 | E3: ※「全区」は8区の合計。区を選ぶと、その区だけのカレンダーになります。
B5: 2025年4月 | J5: 2025年5月 | R5: 2025年6月 | Z5: 2025年7月
B6: 月 | C6: 火 | D6: 水 | E6: 木 | F6: 金 | G6: 土 | H6: 日 | J6: 月 | K6: 火 | L6: 水 | M6: 木 | N6: 金 | O6: 土 | P6: 日 | R6: 月 | S6: 火 | T6: 水 | U6: 木 | V6: 金 | W6: 土 | X6: 日 | Z6: 月 | AA6: 火 | AB6: 水 | AC6: 木 | AD6: 金 | AE6: 土 | AF6: 日
B7: =DATE(2025,4,1)-WEEKDAY(DATE(2025,4,1),2)+1 -> 45747 | C7: =DATE(2025,4,1)-WEEKDAY(DATE(2025,4,1),2)+2 -> 45748 | D7: =DATE(2025,4,1)-WEEKDAY(DATE(2025,4,1),2)+3 -> 45749 | E7: =DATE(2025,4,1)-WEEKDAY(DATE(2025,4,1),2)+4 -> 45750 | F7: =DATE(2025,4,1)-WEEKDAY(DATE(2025,4,1),2)+5 -> 45751 | G7: =DATE(2025,4,1)-WEEKDAY(DATE(2025,4,1),2)+6 -> 45752 | H7: =DATE(2025,4,1)-WEEKDAY(DATE(2025,4,1),2)+7 -> 45753 | J7: =DATE(2025,5,1)-WEEKDAY(DATE(2025,5,1),2)+1 -> 45775 | K7: =DATE(2025,5,1)-WEEKDAY(DATE(2025,5,1),2)+2 -> 45776 | L7: =DATE(2025,5,1)-WEEKDAY(DATE(2025,5,1),2)+3 -> 45777 | M7: =DATE(2025,5,1)-WEEKDAY(DATE(2025,5,1),2)+4 -> 45778 | N7: =DATE(2025,5,1)-WEEKDAY(DATE(2025,5,1),2)+5 -> 45779 | O7: =DATE(2025,5,1)-WEEKDAY(DATE(2025,5,1),2)+6 -> 45780 | P7: =DATE(2025,5,1)-WEEKDAY(DATE(2025,5,1),2)+7 -> 45781 | R7: =DATE(2025,6,1)-WEEKDAY(DATE(2025,6,1),2)+1 -> 45803 | S7: =DATE(2025,6,1)-WEEKDAY(DATE(2025,6,1),2)+2 -> 45804 | T7: =DATE(2025,6,1)-WEEKDAY(DATE(2025,6,1),2)+3 -> 45805 | U7: =DATE(2025,6,1)-WEEKDAY(DATE(2025,6,1),2)+4 -> 45806 | V7: =DATE(2025,6,1)-WEEKDAY(DATE(2025,6,1),2)+5 -> 45807 | W7: =DATE(2025,6,1)-WEEKDAY(DATE(2025,6,1),2)+6 -> 45808 | X7: =DATE(2025,6,1)-WEEKDAY(DATE(2025,6,1),2)+7 -> 45809 | Z7: =DATE(2025,7,1)-WEEKDAY(DATE(2025,7,1),2)+1 -> 45838 | AA7: =DATE(2025,7,1)-WEEKDAY(DATE(2025,7,1),2)+2 -> 45839 | AB7: =DATE(2025,7,1)-WEEKDAY(DATE(2025,7,1),2)+3 -> 45840 | AC7: =DATE(2025,7,1)-WEEKDAY(DATE(2025,7,1),2)+4 -> 45841 | AD7: =DATE(2025,7,1)-WEEKDAY(DATE(2025,7,1),2)+5 -> 45842 | AE7: =DATE(2025,7,1)-WEEKDAY(DATE(2025,7,1),2)+6 -> 45843 | AF7: =DATE(2025,7,1)-WEEKDAY(DATE(2025,7,1),2)+7 -> 45844
B8: =IF(MONTH(B7)=4,IF(IFERROR(INDEX('データ'!$B$313:$J$677,MATCH(B7,'データ'!$A$313:$A$677,0),$A$2),0)=0,"",INDEX('データ'!$B$313:$J$677,MATCH(B7,'データ'!$A$313:$A$677,0),$A$2)),"") | C8: =IF(MONTH(C7)=4,IF(IFERROR(INDEX('データ'!$B$313:$J$677,MATCH(C7,'データ'!$A$313:$A$677,0),$A$2),0)=0,"",INDEX('データ'!$B$313:$J$677,MATCH(C7,'データ'!$A$313:$A$677,0),$A$2)),"") -> 4032 | D8: =IF(MONTH(D7)=4,IF(IFERROR(INDEX('データ'!$B$313:$J$677,MATCH(D7,'データ'!$A$313:$A$677,0),$A$2),0)=0,"",INDEX('データ'!$B$313:$J$677,MATCH(D7,'データ'!$A$313:$A$677,0),$A$2)),"") -> 3588 | E8: =IF(MONTH(E7)=4,IF(IFERROR(INDEX('データ'!$B$313:$J$677,MATCH(E7,'データ'!$A$313:$A$677,0),$A$2),0)=0,"",INDEX('データ'!$B$313:$J$677,MATCH(E7,'データ'!$A$313:$A$677,0),$A$2)),"") -> 3560 | F8: =IF(MONTH(F7)=4,IF(IFERROR(INDEX('データ'!$B$313:$J$677,MATCH(F7,'データ'!$A$313:$A$677,0),$A$2),0)=0,"",INDEX('データ'!$B$313:$J$677,MATCH(F7,'データ'!$A$313:$A$677,0),$A$2)),"") -> 3487 | G8: =IF(MONTH(G7)=4,IF(IFERROR(INDEX('データ'!$B$313:$J$677,MATCH(G7,'データ'!$A$313:$A$677,0),$A$2),0)=0,"",INDEX('データ'!$B$313:$J$677,MATCH(G7,'データ'!$A$313:$A$677,0),$A$2)),"") | H8: =IF(MONTH(H7)=4,IF(IFERROR(INDEX('データ'!$B$313:$J$677,MATCH(H7,'データ'!$A$313:$A$677,0),$A$2),0)=0,"",INDEX('データ'!$B$313:$J$677,MATCH(H7,'データ'!$A$313:$A$677,0),$A$2)),"") | J8: =IF(MONTH(J7)=5,IF(IFERROR(INDEX('データ'!$B$313:$J$677,MATCH(J7,'データ'!$A$313:$A$677,0),$A$2),0)=0,"",INDEX('データ'!$B$313:$J$677,MATCH(J7,'データ'!$A$313:$A$677,0),$A$2)),"") | K8: =IF(MONTH(K7)=5,IF(IFERROR(INDEX('データ'!$B$313:$J$677,MATCH(K7,'データ'!$A$313:$A$677,0),$A$2),0)=0,"",INDEX('データ'!$B$313:$J$677,MATCH(K7,'データ'!$A$313:$A$677,0),$A$2)),"") | L8: =IF(MONTH(L7)=5,IF(IFERROR(INDEX('データ'!$B$313:$J$677,MATCH(L7,'データ'!$A$313:$A$677,0),$A$2),0)=0,"",INDEX('データ'!$B$313:$J$677,MATCH(L7,'データ'!$A$313:$A$677,0),$A$2)),"") | M8: =IF(MONTH(M7)=5,IF(IFERROR(INDEX('データ'!$B$313:$J$677,MATCH(M7,'データ'!$A$313:$A$677,0),$A$2),0)=0,"",INDEX('データ'!$B$313:$J$677,MATCH(M7,'データ'!$A$313:$A$677,0),$A$2)),"") -> 3842 | N8: =IF(MONTH(N7)=5,IF(IFERROR(INDEX('データ'!$B$313:$J$677,MATCH(N7,'データ'!$A$313:$A$677,0),$A$2),0)=0,"",INDEX('データ'!$B$313:$J$677,MATCH(N7,'データ'!$A$313:$A$677,0),$A$2)),"") -> 3546 | O8: =IF(MONTH(O7)=5,IF(IFERROR(INDEX('データ'!$B$313:$J$677,MATCH(O7,'データ'!$A$313:$A$677,0),$A$2),0)=0,"",INDEX('データ'!$B$313:$J$677,MATCH(O7,'データ'!$A$313:$A$677,0),$A$2)),"") | P8: =IF(MONTH(P7)=5,IF(IFERROR(INDEX('データ'!$B$313:$J$677,MATCH(P7,'データ'!$A$313:$A$677,0),$A$2),0)=0,"",INDEX('データ'!$B$313:$J$677,MATCH(P7,'データ'!$A$313:$A$677,0),$A$2)),"") | R8: =IF(MONTH(R7)=6,IF(IFERROR(INDEX('データ'!$B$313:$J$677,MATCH(R7,'データ'!$A$313:$A$677,0),$A$2),0)=0,"",INDEX('データ'!$B$313:$J$677,MATCH(R7,'データ'!$A$313:$A$677,0),$A$2)),"") | S8: =IF(MONTH(S7)=6,IF(IFERROR(INDEX('データ'!$B$313:$J$677,MATCH(S7,'データ'!$A$313:$A$677,0),$A$2),0)=0,"",INDEX('データ'!$B$313:$J$677,MATCH(S7,'データ'!$A$313:$A$677,0),$A$2)),"") | T8: =IF(MONTH(T7)=6,IF(IFERROR(INDEX('データ'!$B$313:$J$677,MATCH(T7,'データ'!$A$313:$A$677,0),$A$2),0)=0,"",INDEX('データ'!$B$313:$J$677,MATCH(T7,'データ'!$A$313:$A$677,0),$A$2)),"") | U8: =IF(MONTH(U7)=6,IF(IFERROR(INDEX('データ'!$B$313:$J$677,MATCH(U7,'データ'!$A$313:$A$677,0),$A$2),0)=0,"",INDEX('データ'!$B$313:$J$677,MATCH(U7,'データ'!$A$313:$A$677,0),$A$2)),"") | V8: =IF(MONTH(V7)=6,IF(IFERROR(INDEX('データ'!$B$313:$J$677,MATCH(V7,'データ'!$A$313:$A$677,0),$A$2),0)=0,"",INDEX('データ'!$B$313:$J$677,MATCH(V7,'データ'!$A$313:$A$677,0),$A$2)),"") | W8: =IF(MONTH(W7)=6,IF(IFERROR(INDEX('データ'!$B$313:$J$677,MATCH(W7,'データ'!$A$313:$A$677,0),$A$2),0)=0,"",INDEX('データ'!$B$313:$J$677,MATCH(W7,'データ'!$A$313:$A$677,0),$A$2)),"") | X8: =IF(MONTH(X7)=6,IF(IFERROR(INDEX('データ'!$B$313:$J$677,MATCH(X7,'データ'!$A$313:$A$677,0),$A$2),0)=0,"",INDEX('データ'!$B$313:$J$677,MATCH(X7,'データ'!$A$313:$A$677,0),$A$2)),"") | Z8: =IF(MONTH(Z7)=7,IF(IFERROR(INDEX('データ'!$B$313:$J$677,MATCH(Z7,'データ'!$A$313:$A$677,0),$A$2),0)=0,"",INDEX('データ'!$B$313:$J$677,MATCH(Z7,'データ'!$A$313:$A$677,0),$A$2)),"") | AA8: =IF(MONTH(AA7)=7,IF(IFERROR(INDEX('データ'!$B$313:$J$677,MATCH(AA7,'データ'!$A$313:$A$677,0),$A$2),0)=0,"",INDEX('データ'!$B$313:$J$677,MATCH(AA7,'データ'!$A$313:$A$677,0),$A$2)),"") -> 3024 | AB8: =IF(MONTH(AB7)=7,IF(IFERROR(INDEX('データ'!$B$313:$J$677,MATCH(AB7,'データ'!$A$313:$A$677,0),$A$2),0)=0,"",INDEX('データ'!$B$313:$J$677,MATCH(AB7,'データ'!$A$313:$A$677,0),$A$2)),"") -> 2912 | AC8: =IF(MONTH(AC7)=7,IF(IFERROR(INDEX('データ'!$B$313:$J$677,MATCH(AC7,'データ'!$A$313:$A$677,0),$A$2),0)=0,"",INDEX('データ'!$B$313:$J$677,MATCH(AC7,'データ'!$A$313:$A$677,0),$A$2)),"") -> 2856 | AD8: =IF(MONTH(AD7)=7,IF(IFERROR(INDEX('データ'!$B$313:$J$677,MATCH(AD7,'データ'!$A$313:$A$677,0),$A$2),0)=0,"",INDEX('データ'!$B$313:$J$677,MATCH(AD7,'データ'!$A$313:$A$677,0),$A$2)),"") -> 3048 | AE8: =IF(MONTH(AE7)=7,IF(IFERROR(INDEX('データ'!$B$313:$J$677,MATCH(AE7,'データ'!$A$313:$A$677,0),$A$2),0)=0,"",INDEX('データ'!$B$313:$J$677,MATCH(AE7,'データ'!$A$313:$A$677,0),$A$2)),"") | AF8: =IF(MONTH(AF7)=7,IF(IFERROR(INDEX('データ'!$B$313:$J$677,MATCH(AF7,'データ'!$A$313:$A$677,0),$A$2),0)=0,"",INDEX('データ'!$B$313:$J$677,MATCH(AF7,'データ'!$A$313:$A$677,0),$A$2)),"")
B9: =DATE(2025,4,1)-WEEKDAY(DATE(2025,4,1),2)+8 -> 45754 | C9: =DATE(2025,4,1)-WEEKDAY(DATE(2025,4,1),2)+9 -> 45755 | D9: =DATE(2025,4,1)-WEEKDAY(DATE(2025,4,1),2)+10 -> 45756 | E9: =DATE(2025,4,1)-WEEKDAY(DATE(2025,4,1),2)+11 -> 45757 | F9: =DATE(2025,4,1)-WEEKDAY(DATE(2025,4,1),2)+12 -> 45758 | G9: =DATE(2025,4,1)-WEEKDAY(DATE(2025,4,1),2)+13 -> 45759 | H9: =DATE(2025,4,1)-WEEKDAY(DATE(2025,4,1),2)+14 -> 45760 | J9: =DATE(2025,5,1)-WEEKDAY(DATE(2025,5,1),2)+8 -> 45782 | K9: =DATE(2025,5,1)-WEEKDAY(DATE(2025,5,1),2)+9 -> 45783 | L9: =DATE(2025,5,1)-WEEKDAY(DATE(2025,5,1),2)+10 -> 45784 | M9: =DATE(2025,5,1)-WEEKDAY(DATE(2025,5,1),2)+11 -> 45785 | N9: =DATE(2025,5,1)-WEEKDAY(DATE(2025,5,1),2)+12 -> 45786 | O9: =DATE(2025,5,1)-WEEKDAY(DATE(2025,5,1),2)+13 -> 45787 | P9: =DATE(2025,5,1)-WEEKDAY(DATE(2025,5,1),2)+14 -> 45788 | R9: =DATE(2025,6,1)-WEEKDAY(DATE(2025,6,1),2)+8 -> 45810 | S9: =DATE(2025,6,1)-WEEKDAY(DATE(2025,6,1),2)+9 -> 45811 | T9: =DATE(2025,6,1)-WEEKDAY(DATE(2025,6,1),2)+10 -> 45812 | U9: =DATE(2025,6,1)-WEEKDAY(DATE(2025,6,1),2)+11 -> 45813 | V9: =DATE(2025,6,1)-WEEKDAY(DATE(2025,6,1),2)+12 -> 45814 | W9: =DATE(2025,6,1)-WEEKDAY(DATE(2025,6,1),2)+13 -> 45815 | X9: =DATE(2025,6,1)-WEEKDAY(DATE(2025,6,1),2)+14 -> 45816 | Z9: =DATE(2025,7,1)-WEEKDAY(DATE(2025,7,1),2)+8 -> 45845 | AA9: =DATE(2025,7,1)-WEEKDAY(DATE(2025,7,1),2)+9 -> 45846 | AB9: =DATE(2025,7,1)-WEEKDAY(DATE(2025,7,1),2)+10 -> 45847 | AC9: =DATE(2025,7,1)-WEEKDAY(DATE(2025,7,1),2)+11 -> 45848 | AD9: =DATE(2025,7,1)-WEEKDAY(DATE(2025,7,1),2)+12 -> 45849 | AE9: =DATE(2025,7,1)-WEEKDAY(DATE(2025,7,1),2)+13 -> 45850 | AF9: =DATE(2025,7,1)-WEEKDAY(DATE(2025,7,1),2)+14 -> 45851
B10: =IF(MONTH(B9)=4,IF(IFERROR(INDEX('データ'!$B$313:$J$677,MATCH(B9,'データ'!$A$313:$A$677,0),$A$2),0)=0,"",INDEX('データ'!$B$313:$J$677,MATCH(B9,'データ'!$A$313:$A$677,0),$A$2)),"") -> 3875 | C10: =IF(MONTH(C9)=4,IF(IFERROR(INDEX('データ'!$B$313:$J$677,MATCH(C9,'データ'!$A$313:$A$677,0),$A$2),0)=0,"",INDEX('データ'!$B$313:$J$677,MATCH(C9,'データ'!$A$313:$A$677,0),$A$2)),"") -> 3288 | D10: =IF(MONTH(D9)=4,IF(IFERROR(INDEX('データ'!$B$313:$J$677,MATCH(D9,'データ'!$A$313:$A$677,0),$A$2),0)=0,"",INDEX('データ'!$B$313:$J$677,MATCH(D9,'データ'!$A$313:$A$677,0),$A$2)),"") -> 3225 | E10: =IF(MONTH(E9)=4,IF(IFERROR(INDEX('データ'!$B$313:$J$677,MATCH(E9,'データ'!$A$313:$A$677,0),$A$2),0)=0,"",INDEX('データ'!$B$313:$J$677,MATCH(E9,'データ'!$A$313:$A$677,0),$A$2)),"") -> 2651 | F10: =IF(MONTH(F9)=4,IF(IFERROR(INDEX('データ'!$B$313:$J$677,MATCH(F9,'データ'!$A$313:$A$677,0),$A$2),0)=0,"",INDEX('データ'!$B$313:$J$677,MATCH(F9,'データ'!$A$313:$A$677,0),$A$2)),"") -> 3091 | G10: =IF(MONTH(G9)=4,IF(IFERROR(INDEX('データ'!$B$313:$J$677,MATCH(G9,'データ'!$A$313:$A$677,0),$A$2),0)=0,"",INDEX('データ'!$B$313:$J$677,MATCH(G9,'データ'!$A$313:$A$677,0),$A$2)),"") | H10: =IF(MONTH(H9)=4,IF(IFERROR(INDEX('データ'!$B$313:$J$677,MATCH(H9,'データ'!$A$313:$A$677,0),$A$2),0)=0,"",INDEX('データ'!$B$313:$J$677,MATCH(H9,'データ'!$A$313:$A$677,0),$A$2)),"") -> 85 | J10: =IF(MONTH(J9)=5,IF(IFERROR(INDEX('データ'!$B$313:$J$677,MATCH(J9,'データ'!$A$313:$A$677,0),$A$2),0)=0,"",INDEX('データ'!$B$313:$J$677,MATCH(J9,'データ'!$A$313:$A$677,0),$A$2)),"") | K10: =IF(MONTH(K9)=5,IF(IFERROR(INDEX('データ'!$B$313:$J$677,MATCH(K9,'データ'!$A$313:$A$677,0),$A$2),0)=0,"",INDEX('データ'!$B$313:$J$677,MATCH(K9,'データ'!$A$313:$A$677,0),$A$2)),"") | L10: =IF(MONTH(L9)=5,IF(IFERROR(INDEX('データ'!$B$313:$J$677,MATCH(L9,'データ'!$A$313:$A$677,0),$A$2),0)=0,"",INDEX('データ'!$B$313:$J$677,MATCH(L9,'データ'!$A$313:$A$677,0),$A$2)),"") -> 3462 | M10: =IF(MONTH(M9)=5,IF(IFERROR(INDEX('データ'!$B$313:$J$677,MATCH(M9,'データ'!$A$313:$A$677,0),$A$2),0)=0,"",INDEX('データ'!$B$313:$J$677,MATCH(M9,'データ'!$A$313:$A$677,0),$A$2)),"") -> 3133 | N10: =IF(MONTH(N9)=5,IF(IFERROR(INDEX('データ'!$B$313:$J$677,MATCH(N9,'データ'!$A$313:$A$677,0),$A$2),0)=0,"",INDEX('データ'!$B$313:$J$677,MATCH(N9,'データ'!$A$313:$A$677,0),$A$2)),"") -> 2556 | O10: =IF(MONTH(O9)=5,IF(IFERROR(INDEX('データ'!$B$313:$J$677,MATCH(O9,'データ'!$A$313:$A$677,0),$A$2),0)=0,"",INDEX('データ'!$B$313:$J$677,MATCH(O9,'データ'!$A$313:$A$677,0),$A$2)),"") | P10: =IF(MONTH(P9)=5,IF(IFERROR(INDEX('データ'!$B$313:$J$677,MATCH(P9,'データ'!$A$313:$A$677,0),$A$2),0)=0,"",INDEX('データ'!$B$313:$J$677,MATCH(P9,'データ'!$A$313:$A$677,0),$A$2)),"") -> 383 | R10: =IF(MONTH(R9)=6,IF(IFERROR(INDEX('データ'!$B$313:$J$677,MATCH(R9,'データ'!$A$313:$A$677,0),$A$2),0)=0,"",INDEX('データ'!$B$313:$J$677,MATCH(R9,'データ'!$A$313:$A$677,0),$A$2)),"") -> 3649 | S10: =IF(MONTH(S9)=6,IF(IFERROR(INDEX('データ'!$B$313:$J$677,MATCH(S9,'データ'!$A$313:$A$677,0),$A$2),0)=0,"",INDEX('データ'!$B$313:$J$677,MATCH(S9,'データ'!$A$313:$A$677,0),$A$2)),"") -> 2848 | T10: =IF(MONTH(T9)=6,IF(IFERROR(INDEX('データ'!$B$313:$J$677,MATCH(T9,'データ'!$A$313:$A$677,0),$A$2),0)=0,"",INDEX('データ'!$B$313:$J$677,MATCH(T9,'データ'!$A$313:$A$677,0),$A$2)),"") -> 3364 | U10: =IF(MONTH(U9)=6,IF(IFERROR(INDEX('データ'!$B$313:$J$677,MATCH(U9,'データ'!$A$313:$A$677,0),$A$2),0)=0,"",INDEX('データ'!$B$313:$J$677,MATCH(U9,'データ'!$A$313:$A$677,0),$A$2)),"") -> 3025 | V10: =IF(MONTH(V9)=6,IF(IFERROR(INDEX('データ'!$B$313:$J$677,MATCH(V9,'データ'!$A$313:$A$677,0),$A$2),0)=0,"",INDEX('データ'!$B$313:$J$677,MATCH(V9,'データ'!$A$313:$A$677,0),$A$2)),"") -> 3254 | W10: =IF(MONTH(W9)=6,IF(IFERROR(INDEX('データ'!$B$313:$J$677,MATCH(W9,'データ'!$A$313:$A$677,0),$A$2),0)=0,"",INDEX('データ'!$B$313:$J$677,MATCH(W9,'データ'!$A$313:$A$677,0),$A$2)),"") | X10: =IF(MONTH(X9)=6,IF(IFERROR(INDEX('データ'!$B$313:$J$677,MATCH(X9,'データ'!$A$313:$A$677,0),$A$2),0)=0,"",INDEX('データ'!$B$313:$J$677,MATCH(X9,'データ'!$A$313:$A$677,0),$A$2)),"") | Z10: =IF(MONTH(Z9)=7,IF(IFERROR(INDEX('データ'!$B$313:$J$677,MATCH(Z9,'データ'!$A$313:$A$677,0),$A$2),0)=0,"",INDEX('データ'!$B$313:$J$677,MATCH(Z9,'データ'!$A$313:$A$677,0),$A$2)),"") -> 3688 | AA10: =IF(MONTH(AA9)=7,IF(IFERROR(INDEX('データ'!$B$313:$J$677,MATCH(AA9,'データ'!$A$313:$A$677,0),$A$2),0)=0,"",INDEX('データ'!$B$313:$J$677,MATCH(AA9,'データ'!$A$313:$A$677,0),$A$2)),"") -> 3069 | AB10: =IF(MONTH(AB9)=7,IF(IFERROR(INDEX('データ'!$B$313:$J$677,MATCH(AB9,'データ'!$A$313:$A$677,0),$A$2),0)=0,"",INDEX('データ'!$B$313:$J$677,MATCH(AB9,'データ'!$A$313:$A$677,0),$A$2)),"") -> 2924 | AC10: =IF(MONTH(AC9)=7,IF(IFERROR(INDEX('データ'!$B$313:$J$677,MATCH(AC9,'データ'!$A$313:$A$677,0),$A$2),0)=0,"",INDEX('データ'!$B$313:$J$677,MATCH(AC9,'データ'!$A$313:$A$677,0),$A$2)),"") -> 2859 | AD10: =IF(MONTH(AD9)=7,IF(IFERROR(INDEX('データ'!$B$313:$J$677,MATCH(AD9,'データ'!$A$313:$A$677,0),$A$2),0)=0,"",INDEX('データ'!$B$313:$J$677,MATCH(AD9,'データ'!$A$313:$A$677,0),$A$2)),"") -> 2973 | AE10: =IF(MONTH(AE9)=7,IF(IFERROR(INDEX('データ'!$B$313:$J$677,MATCH(AE9,'データ'!$A$313:$A$677,0),$A$2),0)=0,"",INDEX('データ'!$B$313:$J$677,MATCH(AE9,'データ'!$A$313:$A$677,0),$A$2)),"") | AF10: =IF(MONTH(AF9)=7,IF(IFERROR(INDEX('データ'!$B$313:$J$677,MATCH(AF9,'データ'!$A$313:$A$677,0),$A$2),0)=0,"",INDEX('データ'!$B$313:$J$677,MATCH(AF9,'データ'!$A$313:$A$677,0),$A$2)),"") -> 675
B11: =DATE(2025,4,1)-WEEKDAY(DATE(2025,4,1),2)+15 -> 45761 | C11: =DATE(2025,4,1)-WEEKDAY(DATE(2025,4,1),2)+16 -> 45762 | D11: =DATE(2025,4,1)-WEEKDAY(DATE(2025,4,1),2)+17 -> 45763 | E11: =DATE(2025,4,1)-WEEKDAY(DATE(2025,4,1),2)+18 -> 45764 | F11: =DATE(2025,4,1)-WEEKDAY(DATE(2025,4,1),2)+19 -> 45765 | G11: =DATE(2025,4,1)-WEEKDAY(DATE(2025,4,1),2)+20 -> 45766 | H11: =DATE(2025,4,1)-WEEKDAY(DATE(2025,4,1),2)+21 -> 45767 | J11: =DATE(2025,5,1)-WEEKDAY(DATE(2025,5,1),2)+15 -> 45789 | K11: =DATE(2025,5,1)-WEEKDAY(DATE(2025,5,1),2)+16 -> 45790 | L11: =DATE(2025,5,1)-WEEKDAY(DATE(2025,5,1),2)+17 -> 45791 | M11: =DATE(2025,5,1)-WEEKDAY(DATE(2025,5,1),2)+18 -> 45792 | N11: =DATE(2025,5,1)-WEEKDAY(DATE(2025,5,1),2)+19 -> 45793 | O11: =DATE(2025,5,1)-WEEKDAY(DATE(2025,5,1),2)+20 -> 45794 | P11: =DATE(2025,5,1)-WEEKDAY(DATE(2025,5,1),2)+21 -> 45795 | R11: =DATE(2025,6,1)-WEEKDAY(DATE(2025,6,1),2)+15 -> 45817 | S11: =DATE(2025,6,1)-WEEKDAY(DATE(2025,6,1),2)+16 -> 45818 | T11: =DATE(2025,6,1)-WEEKDAY(DATE(2025,6,1),2)+17 -> 45819 | U11: =DATE(2025,6,1)-WEEKDAY(DATE(2025,6,1),2)+18 -> 45820 | V11: =DATE(2025,6,1)-WEEKDAY(DATE(2025,6,1),2)+19 -> 45821 | W11: =DATE(2025,6,1)-WEEKDAY(DATE(2025,6,1),2)+20 -> 45822 | X11: =DATE(2025,6,1)-WEEKDAY(DATE(2025,6,1),2)+21 -> 45823 | Z11: =DATE(2025,7,1)-WEEKDAY(DATE(2025,7,1),2)+15 -> 45852 | AA11: =DATE(2025,7,1)-WEEKDAY(DATE(2025,7,1),2)+16 -> 45853 | AB11: =DATE(2025,7,1)-WEEKDAY(DATE(2025,7,1),2)+17 -> 45854 | AC11: =DATE(2025,7,1)-WEEKDAY(DATE(2025,7,1),2)+18 -> 45855 | AD11: =DATE(2025,7,1)-WEEKDAY(DATE(2025,7,1),2)+19 -> 45856 | AE11: =DATE(2025,7,1)-WEEKDAY(DATE(2025,7,1),2)+20 -> 45857 | AF11: =DATE(2025,7,1)-WEEKDAY(DATE(2025,7,1),2)+21 -> 45858
B12: =IF(MONTH(B11)=4,IF(IFERROR(INDEX('データ'!$B$313:$J$677,MATCH(B11,'データ'!$A$313:$A$677,0),$A$2),0)=0,"",INDEX('データ'!$B$313:$J$677,MATCH(B11,'データ'!$A$313:$A$677,0),$A$2)),"") -> 3075 | C12: =IF(MONTH(C11)=4,IF(IFERROR(INDEX('データ'!$B$313:$J$677,MATCH(C11,'データ'!$A$313:$A$677,0),$A$2),0)=0,"",INDEX('データ'!$B$313:$J$677,MATCH(C11,'データ'!$A$313:$A$677,0),$A$2)),"") -> 2890 | D12: =IF(MONTH(D11)=4,IF(IFERROR(INDEX('データ'!$B$313:$J$677,MATCH(D11,'データ'!$A$313:$A$677,0),$A$2),0)=0,"",INDEX('データ'!$B$313:$J$677,MATCH(D11,'データ'!$A$313:$A$677,0),$A$2)),"") -> 3025 | E12: =IF(MONTH(E11)=4,IF(IFERROR(INDEX('データ'!$B$313:$J$677,MATCH(E11,'データ'!$A$313:$A$677,0),$A$2),0)=0,"",INDEX('データ'!$B$313:$J$677,MATCH(E11,'データ'!$A$313:$A$677,0),$A$2)),"") -> 2844 | F12: =IF(MONTH(F11)=4,IF(IFERROR(INDEX('データ'!$B$313:$J$677,MATCH(F11,'データ'!$A$313:$A$677,0),$A$2),0)=0,"",INDEX('データ'!$B$313:$J$677,MATCH(F11,'データ'!$A$313:$A$677,0),$A$2)),"") -> 3361 | G12: =IF(MONTH(G11)=4,IF(IFERROR(INDEX('データ'!$B$313:$J$677,MATCH(G11,'データ'!$A$313:$A$677,0),$A$2),0)=0,"",INDEX('データ'!$B$313:$J$677,MATCH(G11,'データ'!$A$313:$A$677,0),$A$2)),"") | H12: =IF(MONTH(H11)=4,IF(IFERROR(INDEX('データ'!$B$313:$J$677,MATCH(H11,'データ'!$A$313:$A$677,0),$A$2),0)=0,"",INDEX('データ'!$B$313:$J$677,MATCH(H11,'データ'!$A$313:$A$677,0),$A$2)),"") | J12: =IF(MONTH(J11)=5,IF(IFERROR(INDEX('データ'!$B$313:$J$677,MATCH(J11,'データ'!$A$313:$A$677,0),$A$2),0)=0,"",INDEX('データ'!$B$313:$J$677,MATCH(J11,'データ'!$A$313:$A$677,0),$A$2)),"") -> 3720 | K12: =IF(MONTH(K11)=5,IF(IFERROR(INDEX('データ'!$B$313:$J$677,MATCH(K11,'データ'!$A$313:$A$677,0),$A$2),0)=0,"",INDEX('データ'!$B$313:$J$677,MATCH(K11,'データ'!$A$313:$A$677,0),$A$2)),"") -> 3190 | L12: =IF(MONTH(L11)=5,IF(IFERROR(INDEX('データ'!$B$313:$J$677,MATCH(L11,'データ'!$A$313:$A$677,0),$A$2),0)=0,"",INDEX('データ'!$B$313:$J$677,MATCH(L11,'データ'!$A$313:$A$677,0),$A$2)),"") -> 3160 | M12: =IF(MONTH(M11)=5,IF(IFERROR(INDEX('データ'!$B$313:$J$677,MATCH(M11,'データ'!$A$313:$A$677,0),$A$2),0)=0,"",INDEX('データ'!$B$313:$J$677,MATCH(M11,'データ'!$A$313:$A$677,0),$A$2)),"") -> 3085 | N12: =IF(MONTH(N11)=5,IF(IFERROR(INDEX('データ'!$B$313:$J$677,MATCH(N11,'データ'!$A$313:$A$677,0),$A$2),0)=0,"",INDEX('データ'!$B$313:$J$677,MATCH(N11,'データ'!$A$313:$A$677,0),$A$2)),"") -> 3009 | O12: =IF(MONTH(O11)=5,IF(IFERROR(INDEX('データ'!$B$313:$J$677,MATCH(O11,'データ'!$A$313:$A$677,0),$A$2),0)=0,"",INDEX('データ'!$B$313:$J$677,MATCH(O11,'データ'!$A$313:$A$677,0),$A$2)),"") | P12: =IF(MONTH(P11)=5,IF(IFERROR(INDEX('データ'!$B$313:$J$677,MATCH(P11,'データ'!$A$313:$A$677,0),$A$2),0)=0,"",INDEX('データ'!$B$313:$J$677,MATCH(P11,'データ'!$A$313:$A$677,0),$A$2)),"") | R12: =IF(MONTH(R11)=6,IF(IFERROR(INDEX('データ'!$B$313:$J$677,MATCH(R11,'データ'!$A$313:$A$677,0),$A$2),0)=0,"",INDEX('データ'!$B$313:$J$677,MATCH(R11,'データ'!$A$313:$A$677,0),$A$2)),"") -> 3245 | S12: =IF(MONTH(S11)=6,IF(IFERROR(INDEX('データ'!$B$313:$J$677,MATCH(S11,'データ'!$A$313:$A$677,0),$A$2),0)=0,"",INDEX('データ'!$B$313:$J$677,MATCH(S11,'データ'!$A$313:$A$677,0),$A$2)),"") -> 2521 | T12: =IF(MONTH(T11)=6,IF(IFERROR(INDEX('データ'!$B$313:$J$677,MATCH(T11,'データ'!$A$313:$A$677,0),$A$2),0)=0,"",INDEX('データ'!$B$313:$J$677,MATCH(T11,'データ'!$A$313:$A$677,0),$A$2)),"") -> 3151 | U12: =IF(MONTH(U11)=6,IF(IFERROR(INDEX('データ'!$B$313:$J$677,MATCH(U11,'データ'!$A$313:$A$677,0),$A$2),0)=0,"",INDEX('データ'!$B$313:$J$677,MATCH(U11,'データ'!$A$313:$A$677,0),$A$2)),"") -> 2934 | V12: =IF(MONTH(V11)=6,IF(IFERROR(INDEX('データ'!$B$313:$J$677,MATCH(V11,'データ'!$A$313:$A$677,0),$A$2),0)=0,"",INDEX('データ'!$B$313:$J$677,MATCH(V11,'データ'!$A$313:$A$677,0),$A$2)),"") -> 3398 | W12: =IF(MONTH(W11)=6,IF(IFERROR(INDEX('データ'!$B$313:$J$677,MATCH(W11,'データ'!$A$313:$A$677,0),$A$2),0)=0,"",INDEX('データ'!$B$313:$J$677,MATCH(W11,'データ'!$A$313:$A$677,0),$A$2)),"") | X12: =IF(MONTH(X11)=6,IF(IFERROR(INDEX('データ'!$B$313:$J$677,MATCH(X11,'データ'!$A$313:$A$677,0),$A$2),0)=0,"",INDEX('データ'!$B$313:$J$677,MATCH(X11,'データ'!$A$313:$A$677,0),$A$2)),"") | Z12: =IF(MONTH(Z11)=7,IF(IFERROR(INDEX('データ'!$B$313:$J$677,MATCH(Z11,'データ'!$A$313:$A$677,0),$A$2),0)=0,"",INDEX('データ'!$B$313:$J$677,MATCH(Z11,'データ'!$A$313:$A$677,0),$A$2)),"") -> 2973 | AA12: =IF(MONTH(AA11)=7,IF(IFERROR(INDEX('データ'!$B$313:$J$677,MATCH(AA11,'データ'!$A$313:$A$677,0),$A$2),0)=0,"",INDEX('データ'!$B$313:$J$677,MATCH(AA11,'データ'!$A$313:$A$677,0),$A$2)),"") -> 3229 | AB12: =IF(MONTH(AB11)=7,IF(IFERROR(INDEX('データ'!$B$313:$J$677,MATCH(AB11,'データ'!$A$313:$A$677,0),$A$2),0)=0,"",INDEX('データ'!$B$313:$J$677,MATCH(AB11,'データ'!$A$313:$A$677,0),$A$2)),"") -> 2989 | AC12: =IF(MONTH(AC11)=7,IF(IFERROR(INDEX('データ'!$B$313:$J$677,MATCH(AC11,'データ'!$A$313:$A$677,0),$A$2),0)=0,"",INDEX('データ'!$B$313:$J$677,MATCH(AC11,'データ'!$A$313:$A$677,0),$A$2)),"") -> 2622 | AD12: =IF(MONTH(AD11)=7,IF(IFERROR(INDEX('データ'!$B$313:$J$677,MATCH(AD11,'データ'!$A$313:$A$677,0),$A$2),0)=0,"",INDEX('データ'!$B$313:$J$677,MATCH(AD11,'データ'!$A$313:$A$677,0),$A$2)),"") -> 2841 | AE12: =IF(MONTH(AE11)=7,IF(IFERROR(INDEX('データ'!$B$313:$J$677,MATCH(AE11,'データ'!$A$313:$A$677,0),$A$2),0)=0,"",INDEX('データ'!$B$313:$J$677,MATCH(AE11,'データ'!$A$313:$A$677,0),$A$2)),"") | AF12: =IF(MONTH(AF11)=7,IF(IFERROR(INDEX('データ'!$B$313:$J$677,MATCH(AF11,'データ'!$A$313:$A$677,0),$A$2),0)=0,"",INDEX('データ'!$B$313:$J$677,MATCH(AF11,'データ'!$A$313:$A$677,0),$A$2)),"")
B13: =DATE(2025,4,1)-WEEKDAY(DATE(2025,4,1),2)+22 -> 45768 | C13: =DATE(2025,4,1)-WEEKDAY(DATE(2025,4,1),2)+23 -> 45769 | D13: =DATE(2025,4,1)-WEEKDAY(DATE(2025,4,1),2)+24 -> 45770 | E13: =DATE(2025,4,1)-WEEKDAY(DATE(2025,4,1),2)+25 -> 45771 | F13: =DATE(2025,4,1)-WEEKDAY(DATE(2025,4,1),2)+26 -> 45772 | G13: =DATE(2025,4,1)-WEEKDAY(DATE(2025,4,1),2)+27 -> 45773 | H13: =DATE(2025,4,1)-WEEKDAY(DATE(2025,4,1),2)+28 -> 45774 | J13: =DATE(2025,5,1)-WEEKDAY(DATE(2025,5,1),2)+22 -> 45796 | K13: =DATE(2025,5,1)-WEEKDAY(DATE(2025,5,1),2)+23 -> 45797 | L13: =DATE(2025,5,1)-WEEKDAY(DATE(2025,5,1),2)+24 -> 45798 | M13: =DATE(2025,5,1)-WEEKDAY(DATE(2025,5,1),2)+25 -> 45799 | N13: =DATE(2025,5,1)-WEEKDAY(DATE(2025,5,1),2)+26 -> 45800 | O13: =DATE(2025,5,1)-WEEKDAY(DATE(2025,5,1),2)+27 -> 45801 | P13: =DATE(2025,5,1)-WEEKDAY(DATE(2025,5,1),2)+28 -> 45802 | R13: =DATE(2025,6,1)-WEEKDAY(DATE(2025,6,1),2)+22 -> 45824 | S13: =DATE(2025,6,1)-WEEKDAY(DATE(2025,6,1),2)+23 -> 45825 | T13: =DATE(2025,6,1)-WEEKDAY(DATE(2025,6,1),2)+24 -> 45826 | U13: =DATE(2025,6,1)-WEEKDAY(DATE(2025,6,1),2)+25 -> 45827 | V13: =DATE(2025,6,1)-WEEKDAY(DATE(2025,6,1),2)+26 -> 45828 | W13: =DATE(2025,6,1)-WEEKDAY(DATE(2025,6,1),2)+27 -> 45829 | X13: =DATE(2025,6,1)-WEEKDAY(DATE(2025,6,1),2)+28 -> 45830 | Z13: =DATE(2025,7,1)-WEEKDAY(DATE(2025,7,1),2)+22 -> 45859 | AA13: =DATE(2025,7,1)-WEEKDAY(DATE(2025,7,1),2)+23 -> 45860 | AB13: =DATE(2025,7,1)-WEEKDAY(DATE(2025,7,1),2)+24 -> 45861 | AC13: =DATE(2025,7,1)-WEEKDAY(DATE(2025,7,1),2)+25 -> 45862 | AD13: =DATE(2025,7,1)-WEEKDAY(DATE(2025,7,1),2)+26 -> 45863 | AE13: =DATE(2025,7,1)-WEEKDAY(DATE(2025,7,1),2)+27 -> 45864 | AF13: =DATE(2025,7,1)-WEEKDAY(DATE(2025,7,1),2)+28 -> 45865
B14: =IF(MONTH(B13)=4,IF(IFERROR(INDEX('データ'!$B$313:$J$677,MATCH(B13,'データ'!$A$313:$A$677,0),$A$2),0)=0,"",INDEX('データ'!$B$313:$J$677,MATCH(B13,'データ'!$A$313:$A$677,0),$A$2)),"") -> 3588 | C14: =IF(MONTH(C13)=4,IF(IFERROR(INDEX('データ'!$B$313:$J$677,MATCH(C13,'データ'!$A$313:$A$677,0),$A$2),0)=0,"",INDEX('データ'!$B$313:$J$677,MATCH(C13,'データ'!$A$313:$A$677,0),$A$2)),"") -> 2834 | D14: =IF(MONTH(D13)=4,IF(IFERROR(INDEX('データ'!$B$313:$J$677,MATCH(D13,'データ'!$A$313:$A$677,0),$A$2),0)=0,"",INDEX('データ'!$B$313:$J$677,MATCH(D13,'データ'!$A$313:$A$677,0),$A$2)),"") -> 2840 | E14: =IF(MONTH(E13)=4,IF(IFERROR(INDEX('データ'!$B$313:$J$677,MATCH(E13,'データ'!$A$313:$A$677,0),$A$2),0)=0,"",INDEX('データ'!$B$313:$J$677,MATCH(E13,'データ'!$A$313:$A$677,0),$A$2)),"") -> 2701 | F14: =IF(MONTH(F13)=4,IF(IFERROR(INDEX('データ'!$B$313:$J$677,MATCH(F13,'データ'!$A$313:$A$677,0),$A$2),0)=0,"",INDEX('データ'!$B$313:$J$677,MATCH(F13,'データ'!$A$313:$A$677,0),$A$2)),"") -> 2974 | G14: =IF(MONTH(G13)=4,IF(IFERROR(INDEX('データ'!$B$313:$J$677,MATCH(G13,'データ'!$A$313:$A$677,0),$A$2),0)=0,"",INDEX('データ'!$B$313:$J$677,MATCH(G13,'データ'!$A$313:$A$677,0),$A$2)),"") | H14: =IF(MONTH(H13)=4,IF(IFERROR(INDEX('データ'!$B$313:$J$677,MATCH(H13,'データ'!$A$313:$A$677,0),$A$2),0)=0,"",INDEX('データ'!$B$313:$J$677,MATCH(H13,'データ'!$A$313:$A$677,0),$A$2)),"") | J14: =IF(MONTH(J13)=5,IF(IFERROR(INDEX('データ'!$B$313:$J$677,MATCH(J13,'データ'!$A$313:$A$677,0),$A$2),0)=0,"",INDEX('データ'!$B$313:$J$677,MATCH(J13,'データ'!$A$313:$A$677,0),$A$2)),"") -> 3432 | K14: =IF(MONTH(K13)=5,IF(IFERROR(INDEX('データ'!$B$313:$J$677,MATCH(K13,'データ'!$A$313:$A$677,0),$A$2),0)=0,"",INDEX('データ'!$B$313:$J$677,MATCH(K13,'データ'!$A$313:$A$677,0),$A$2)),"") -> 3096 | L14: =IF(MONTH(L13)=5,IF(IFERROR(INDEX('データ'!$B$313:$J$677,MATCH(L13,'データ'!$A$313:$A$677,0),$A$2),0)=0,"",INDEX('データ'!$B$313:$J$677,MATCH(L13,'データ'!$A$313:$A$677,0),$A$2)),"") -> 2730 | M14: =IF(MONTH(M13)=5,IF(IFERROR(INDEX('データ'!$B$313:$J$677,MATCH(M13,'データ'!$A$313:$A$677,0),$A$2),0)=0,"",INDEX('データ'!$B$313:$J$677,MATCH(M13,'データ'!$A$313:$A$677,0),$A$2)),"") -> 2747 | N14: =IF(MONTH(N13)=5,IF(IFERROR(INDEX('データ'!$B$313:$J$677,MATCH(N13,'データ'!$A$313:$A$677,0),$A$2),0)=0,"",INDEX('データ'!$B$313:$J$677,MATCH(N13,'データ'!$A$313:$A$677,0),$A$2)),"") -> 3130 | O14: =IF(MONTH(O13)=5,IF(IFERROR(INDEX('データ'!$B$313:$J$677,MATCH(O13,'データ'!$A$313:$A$677,0),$A$2),0)=0,"",INDEX('データ'!$B$313:$J$677,MATCH(O13,'データ'!$A$313:$A$677,0),$A$2)),"") | P14: =IF(MONTH(P13)=5,IF(IFERROR(INDEX('データ'!$B$313:$J$677,MATCH(P13,'データ'!$A$313:$A$677,0),$A$2),0)=0,"",INDEX('データ'!$B$313:$J$677,MATCH(P13,'データ'!$A$313:$A$677,0),$A$2)),"") | R14: =IF(MONTH(R13)=6,IF(IFERROR(INDEX('データ'!$B$313:$J$677,MATCH(R13,'データ'!$A$313:$A$677,0),$A$2),0)=0,"",INDEX('データ'!$B$313:$J$677,MATCH(R13,'データ'!$A$313:$A$677,0),$A$2)),"") -> 3641 | S14: =IF(MONTH(S13)=6,IF(IFERROR(INDEX('データ'!$B$313:$J$677,MATCH(S13,'データ'!$A$313:$A$677,0),$A$2),0)=0,"",INDEX('データ'!$B$313:$J$677,MATCH(S13,'データ'!$A$313:$A$677,0),$A$2)),"") -> 3126 | T14: =IF(MONTH(T13)=6,IF(IFERROR(INDEX('データ'!$B$313:$J$677,MATCH(T13,'データ'!$A$313:$A$677,0),$A$2),0)=0,"",INDEX('データ'!$B$313:$J$677,MATCH(T13,'データ'!$A$313:$A$677,0),$A$2)),"") -> 3011 | U14: =IF(MONTH(U13)=6,IF(IFERROR(INDEX('データ'!$B$313:$J$677,MATCH(U13,'データ'!$A$313:$A$677,0),$A$2),0)=0,"",INDEX('データ'!$B$313:$J$677,MATCH(U13,'データ'!$A$313:$A$677,0),$A$2)),"") -> 2705 | V14: =IF(MONTH(V13)=6,IF(IFERROR(INDEX('データ'!$B$313:$J$677,MATCH(V13,'データ'!$A$313:$A$677,0),$A$2),0)=0,"",INDEX('データ'!$B$313:$J$677,MATCH(V13,'データ'!$A$313:$A$677,0),$A$2)),"") -> 3011 | W14: =IF(MONTH(W13)=6,IF(IFERROR(INDEX('データ'!$B$313:$J$677,MATCH(W13,'データ'!$A$313:$A$677,0),$A$2),0)=0,"",INDEX('データ'!$B$313:$J$677,MATCH(W13,'データ'!$A$313:$A$677,0),$A$2)),"") | X14: =IF(MONTH(X13)=6,IF(IFERROR(INDEX('データ'!$B$313:$J$677,MATCH(X13,'データ'!$A$313:$A$677,0),$A$2),0)=0,"",INDEX('データ'!$B$313:$J$677,MATCH(X13,'データ'!$A$313:$A$677,0),$A$2)),"") | Z14: =IF(MONTH(Z13)=7,IF(IFERROR(INDEX('データ'!$B$313:$J$677,MATCH(Z13,'データ'!$A$313:$A$677,0),$A$2),0)=0,"",INDEX('データ'!$B$313:$J$677,MATCH(Z13,'データ'!$A$313:$A$677,0),$A$2)),"") | AA14: =IF(MONTH(AA13)=7,IF(IFERROR(INDEX('データ'!$B$313:$J$677,MATCH(AA13,'データ'!$A$313:$A$677,0),$A$2),0)=0,"",INDEX('データ'!$B$313:$J$677,MATCH(AA13,'データ'!$A$313:$A$677,0),$A$2)),"") -> 3363 | AB14: =IF(MONTH(AB13)=7,IF(IFERROR(INDEX('データ'!$B$313:$J$677,MATCH(AB13,'データ'!$A$313:$A$677,0),$A$2),0)=0,"",INDEX('データ'!$B$313:$J$677,MATCH(AB13,'データ'!$A$313:$A$677,0),$A$2)),"") -> 3228 | AC14: =IF(MONTH(AC13)=7,IF(IFERROR(INDEX('データ'!$B$313:$J$677,MATCH(AC13,'データ'!$A$313:$A$677,0),$A$2),0)=0,"",INDEX('データ'!$B$313:$J$677,MATCH(AC13,'データ'!$A$313:$A$677,0),$A$2)),"") -> 3353 | AD14: =IF(MONTH(AD13)=7,IF(IFERROR(INDEX('データ'!$B$313:$J$677,MATCH(AD13,'データ'!$A$313:$A$677,0),$A$2),0)=0,"",INDEX('データ'!$B$313:$J$677,MATCH(AD13,'データ'!$A$313:$A$677,0),$A$2)),"") -> 3222 | AE14: =IF(MONTH(AE13)=7,IF(IFERROR(INDEX('データ'!$B$313:$J$677,MATCH(AE13,'データ'!$A$313:$A$677,0),$A$2),0)=0,"",INDEX('データ'!$B$313:$J$677,MATCH(AE13,'データ'!$A$313:$A$677,0),$A$2)),"") | AF14: =IF(MONTH(AF13)=7,IF(IFERROR(INDEX('データ'!$B$313:$J$677,MATCH(AF13,'データ'!$A$313:$A$677,0),$A$2),0)=0,"",INDEX('データ'!$B$313:$J$677,MATCH(AF13,'データ'!$A$313:$A$677,0),$A$2)),"")
B15: =DATE(2025,4,1)-WEEKDAY(DATE(2025,4,1),2)+29 -> 45775 | C15: =DATE(2025,4,1)-WEEKDAY(DATE(2025,4,1),2)+30 -> 45776 | D15: =DATE(2025,4,1)-WEEKDAY(DATE(2025,4,1),2)+31 -> 45777 | E15: =DATE(2025,4,1)-WEEKDAY(DATE(2025,4,1),2)+32 -> 45778 | F15: =DATE(2025,4,1)-WEEKDAY(DATE(2025,4,1),2)+33 -> 45779 | G15: =DATE(2025,4,1)-WEEKDAY(DATE(2025,4,1),2)+34 -> 45780 | H15: =DATE(2025,4,1)-WEEKDAY(DATE(2025,4,1),2)+35 -> 45781 | J15: =DATE(2025,5,1)-WEEKDAY(DATE(2025,5,1),2)+29 -> 45803 | K15: =DATE(2025,5,1)-WEEKDAY(DATE(2025,5,1),2)+30 -> 45804 | L15: =DATE(2025,5,1)-WEEKDAY(DATE(2025,5,1),2)+31 -> 45805 | M15: =DATE(2025,5,1)-WEEKDAY(DATE(2025,5,1),2)+32 -> 45806 | N15: =DATE(2025,5,1)-WEEKDAY(DATE(2025,5,1),2)+33 -> 45807 | O15: =DATE(2025,5,1)-WEEKDAY(DATE(2025,5,1),2)+34 -> 45808 | P15: =DATE(2025,5,1)-WEEKDAY(DATE(2025,5,1),2)+35 -> 45809 | R15: =DATE(2025,6,1)-WEEKDAY(DATE(2025,6,1),2)+29 -> 45831 | S15: =DATE(2025,6,1)-WEEKDAY(DATE(2025,6,1),2)+30 -> 45832 | T15: =DATE(2025,6,1)-WEEKDAY(DATE(2025,6,1),2)+31 -> 45833 | U15: =DATE(2025,6,1)-WEEKDAY(DATE(2025,6,1),2)+32 -> 45834 | V15: =DATE(2025,6,1)-WEEKDAY(DATE(2025,6,1),2)+33 -> 45835 | W15: =DATE(2025,6,1)-WEEKDAY(DATE(2025,6,1),2)+34 -> 45836 | X15: =DATE(2025,6,1)-WEEKDAY(DATE(2025,6,1),2)+35 -> 45837 | Z15: =DATE(2025,7,1)-WEEKDAY(DATE(2025,7,1),2)+29 -> 45866 | AA15: =DATE(2025,7,1)-WEEKDAY(DATE(2025,7,1),2)+30 -> 45867 | AB15: =DATE(2025,7,1)-WEEKDAY(DATE(2025,7,1),2)+31 -> 45868 | AC15: =DATE(2025,7,1)-WEEKDAY(DATE(2025,7,1),2)+32 -> 45869 | AD15: =DATE(2025,7,1)-WEEKDAY(DATE(2025,7,1),2)+33 -> 45870 | AE15: =DATE(2025,7,1)-WEEKDAY(DATE(2025,7,1),2)+34 -> 45871 | AF15: =DATE(2025,7,1)-WEEKDAY(DATE(2025,7,1),2)+35 -> 45872
B16: =IF(MONTH(B15)=4,IF(IFERROR(INDEX('データ'!$B$313:$J$677,MATCH(B15,'データ'!$A$313:$A$677,0),$A$2),0)=0,"",INDEX('データ'!$B$313:$J$677,MATCH(B15,'データ'!$A$313:$A$677,0),$A$2)),"") -> 4494 | C16: =IF(MONTH(C15)=4,IF(IFERROR(INDEX('データ'!$B$313:$J$677,MATCH(C15,'データ'!$A$313:$A$677,0),$A$2),0)=0,"",INDEX('データ'!$B$313:$J$677,MATCH(C15,'データ'!$A$313:$A$677,0),$A$2)),"") | D16: =IF(MONTH(D15)=4,IF(IFERROR(INDEX('データ'!$B$313:$J$677,MATCH(D15,'データ'!$A$313:$A$677,0),$A$2),0)=0,"",INDEX('データ'!$B$313:$J$677,MATCH(D15,'データ'!$A$313:$A$677,0),$A$2)),"") -> 4200 | E16: =IF(MONTH(E15)=4,IF(IFERROR(INDEX('データ'!$B$313:$J$677,MATCH(E15,'データ'!$A$313:$A$677,0),$A$2),0)=0,"",INDEX('データ'!$B$313:$J$677,MATCH(E15,'データ'!$A$313:$A$677,0),$A$2)),"") | F16: =IF(MONTH(F15)=4,IF(IFERROR(INDEX('データ'!$B$313:$J$677,MATCH(F15,'データ'!$A$313:$A$677,0),$A$2),0)=0,"",INDEX('データ'!$B$313:$J$677,MATCH(F15,'データ'!$A$313:$A$677,0),$A$2)),"") | G16: =IF(MONTH(G15)=4,IF(IFERROR(INDEX('データ'!$B$313:$J$677,MATCH(G15,'データ'!$A$313:$A$677,0),$A$2),0)=0,"",INDEX('データ'!$B$313:$J$677,MATCH(G15,'データ'!$A$313:$A$677,0),$A$2)),"") | H16: =IF(MONTH(H15)=4,IF(IFERROR(INDEX('データ'!$B$313:$J$677,MATCH(H15,'データ'!$A$313:$A$677,0),$A$2),0)=0,"",INDEX('データ'!$B$313:$J$677,MATCH(H15,'データ'!$A$313:$A$677,0),$A$2)),"") | J16: =IF(MONTH(J15)=5,IF(IFERROR(INDEX('データ'!$B$313:$J$677,MATCH(J15,'データ'!$A$313:$A$677,0),$A$2),0)=0,"",INDEX('データ'!$B$313:$J$677,MATCH(J15,'データ'!$A$313:$A$677,0),$A$2)),"") -> 3543 | K16: =IF(MONTH(K15)=5,IF(IFERROR(INDEX('データ'!$B$313:$J$677,MATCH(K15,'データ'!$A$313:$A$677,0),$A$2),0)=0,"",INDEX('データ'!$B$313:$J$677,MATCH(K15,'データ'!$A$313:$A$677,0),$A$2)),"") -> 3016 | L16: =IF(MONTH(L15)=5,IF(IFERROR(INDEX('データ'!$B$313:$J$677,MATCH(L15,'データ'!$A$313:$A$677,0),$A$2),0)=0,"",INDEX('データ'!$B$313:$J$677,MATCH(L15,'データ'!$A$313:$A$677,0),$A$2)),"") -> 2859 | M16: =IF(MONTH(M15)=5,IF(IFERROR(INDEX('データ'!$B$313:$J$677,MATCH(M15,'データ'!$A$313:$A$677,0),$A$2),0)=0,"",INDEX('データ'!$B$313:$J$677,MATCH(M15,'データ'!$A$313:$A$677,0),$A$2)),"") -> 2828 | N16: =IF(MONTH(N15)=5,IF(IFERROR(INDEX('データ'!$B$313:$J$677,MATCH(N15,'データ'!$A$313:$A$677,0),$A$2),0)=0,"",INDEX('データ'!$B$313:$J$677,MATCH(N15,'データ'!$A$313:$A$677,0),$A$2)),"") -> 2824 | O16: =IF(MONTH(O15)=5,IF(IFERROR(INDEX('データ'!$B$313:$J$677,MATCH(O15,'データ'!$A$313:$A$677,0),$A$2),0)=0,"",INDEX('データ'!$B$313:$J$677,MATCH(O15,'データ'!$A$313:$A$677,0),$A$2)),"") | P16: =IF(MONTH(P15)=5,IF(IFERROR(INDEX('データ'!$B$313:$J$677,MATCH(P15,'データ'!$A$313:$A$677,0),$A$2),0)=0,"",INDEX('データ'!$B$313:$J$677,MATCH(P15,'データ'!$A$313:$A$677,0),$A$2)),"") | R16: =IF(MONTH(R15)=6,IF(IFERROR(INDEX('データ'!$B$313:$J$677,MATCH(R15,'データ'!$A$313:$A$677,0),$A$2),0)=0,"",INDEX('データ'!$B$313:$J$677,MATCH(R15,'データ'!$A$313:$A$677,0),$A$2)),"") -> 3103 | S16: =IF(MONTH(S15)=6,IF(IFERROR(INDEX('データ'!$B$313:$J$677,MATCH(S15,'データ'!$A$313:$A$677,0),$A$2),0)=0,"",INDEX('データ'!$B$313:$J$677,MATCH(S15,'データ'!$A$313:$A$677,0),$A$2)),"") -> 2485 | T16: =IF(MONTH(T15)=6,IF(IFERROR(INDEX('データ'!$B$313:$J$677,MATCH(T15,'データ'!$A$313:$A$677,0),$A$2),0)=0,"",INDEX('データ'!$B$313:$J$677,MATCH(T15,'データ'!$A$313:$A$677,0),$A$2)),"") -> 2831 | U16: =IF(MONTH(U15)=6,IF(IFERROR(INDEX('データ'!$B$313:$J$677,MATCH(U15,'データ'!$A$313:$A$677,0),$A$2),0)=0,"",INDEX('データ'!$B$313:$J$677,MATCH(U15,'データ'!$A$313:$A$677,0),$A$2)),"") -> 2855 | V16: =IF(MONTH(V15)=6,IF(IFERROR(INDEX('データ'!$B$313:$J$677,MATCH(V15,'データ'!$A$313:$A$677,0),$A$2),0)=0,"",INDEX('データ'!$B$313:$J$677,MATCH(V15,'データ'!$A$313:$A$677,0),$A$2)),"") -> 3235 | W16: =IF(MONTH(W15)=6,IF(IFERROR(INDEX('データ'!$B$313:$J$677,MATCH(W15,'データ'!$A$313:$A$677,0),$A$2),0)=0,"",INDEX('データ'!$B$313:$J$677,MATCH(W15,'データ'!$A$313:$A$677,0),$A$2)),"") | X16: =IF(MONTH(X15)=6,IF(IFERROR(INDEX('データ'!$B$313:$J$677,MATCH(X15,'データ'!$A$313:$A$677,0),$A$2),0)=0,"",INDEX('データ'!$B$313:$J$677,MATCH(X15,'データ'!$A$313:$A$677,0),$A$2)),"") | Z16: =IF(MONTH(Z15)=7,IF(IFERROR(INDEX('データ'!$B$313:$J$677,MATCH(Z15,'データ'!$A$313:$A$677,0),$A$2),0)=0,"",INDEX('データ'!$B$313:$J$677,MATCH(Z15,'データ'!$A$313:$A$677,0),$A$2)),"") -> 3634 | AA16: =IF(MONTH(AA15)=7,IF(IFERROR(INDEX('データ'!$B$313:$J$677,MATCH(AA15,'データ'!$A$313:$A$677,0),$A$2),0)=0,"",INDEX('データ'!$B$313:$J$677,MATCH(AA15,'データ'!$A$313:$A$677,0),$A$2)),"") -> 3178 | AB16: =IF(MONTH(AB15)=7,IF(IFERROR(INDEX('データ'!$B$313:$J$677,MATCH(AB15,'データ'!$A$313:$A$677,0),$A$2),0)=0,"",INDEX('データ'!$B$313:$J$677,MATCH(AB15,'データ'!$A$313:$A$677,0),$A$2)),"") -> 3046 | AC16: =IF(MONTH(AC15)=7,IF(IFERROR(INDEX('データ'!$B$313:$J$677,MATCH(AC15,'データ'!$A$313:$A$677,0),$A$2),0)=0,"",INDEX('データ'!$B$313:$J$677,MATCH(AC15,'データ'!$A$313:$A$677,0),$A$2)),"") -> 2763 | AD16: =IF(MONTH(AD15)=7,IF(IFERROR(INDEX('データ'!$B$313:$J$677,MATCH(AD15,'データ'!$A$313:$A$677,0),$A$2),0)=0,"",INDEX('データ'!$B$313:$J$677,MATCH(AD15,'データ'!$A$313:$A$677,0),$A$2)),"") | AE16: =IF(MONTH(AE15)=7,IF(IFERROR(INDEX('データ'!$B$313:$J$677,MATCH(AE15,'データ'!$A$313:$A$677,0),$A$2),0)=0,"",INDEX('データ'!$B$313:$J$677,MATCH(AE15,'データ'!$A$313:$A$677,0),$A$2)),"") | AF16: =IF(MONTH(AF15)=7,IF(IFERROR(INDEX('データ'!$B$313:$J$677,MATCH(AF15,'データ'!$A$313:$A$677,0),$A$2),0)=0,"",INDEX('データ'!$B$313:$J$677,MATCH(AF15,'データ'!$A$313:$A$677,0),$A$2)),"")
