Workbook

Sheet はじめに
B1: 来庁者数・窓口時間の集計
B2: 番号発券機データ（令和7年4月〜令和8年3月、762,002件）を集計。市民部・厚生部の削減効果は、発券機のCSVを取り込んで計算。
B4: シート
B5: 計算の説明 | C5: どのデータを、どんな条件で、どう計算しているか（初めに読むシート）
B6: ダッシュボード | C6: 区・月・開庁時間・指標を選択して、来庁者数と待ち時間等を表示
B7: 時間外削減効果 | C7: 市民部・厚生部の時間外削減効果（総括）
B8: 市民部 | C8: 市民部の削減効果の計算（発券機CSVの取込＋発券数×平均処理時間）
B9: 厚生部 | C9: 厚生部の削減効果の計算（発券機CSVの取込＋発券数×平均処理時間）
B10: 待ち・対応時間 | C10: 区別の待ち時間・対応時間・滞在時間、待ち時間の分布
B11: ヒートマップ | C11: 曜日×時間、月×時間、区別の時間帯分布
B12: カレンダー | C12: 日別の来庁者数・平均待ち・平均対応
B13: シミュレーター | C13: 開庁時間案ごとの時間外の発券数
B14: 業務ランキング | C14: 窓口業務別の件数と平均時間
B15: データ | C15: 集計データ
B16: 取込_市民部 | C16: 市民部・厚生部のCSV取込結果（取込_市民部／取込_厚生部／取込_業務別）
B17: 用語
B18: 発券 | C18: 番号札を取ること。来庁1件として数える。
B19: 待ち時間 | C19: 発券から呼出まで。
B20: 対応時間（処理時間） | C20: 呼出から処理済みまで。
B21: 滞在時間 | C21: 発券から処理済みまで（待ち＋対応）。
B22: 開庁時間外 | C22: 指定した開庁時間の前後に発券された件数。
B24: 注意
B25: (1) | C25: 3時間を超える待ち・対応時間は平均から除く。処理済みの時刻がない件（約5%）は対応・滞在の平均に含まれない。
B26: (2) | C26: 記録のない区・月がある：中区 12月（14日分のみ）、東区 1月（10日分のみ）、南区 11月（記録なし）、安佐北区 1月（7日分のみ）。該当月の人数は少なく表示される。
B27: (3) | C27: 黄色のセルは選択・入力項目。
B28: (4) | C28: 市民部・厚生部の数字は、発券機CSVを集計した取込_○○のシートの値から計算している（このファイルはマクロなし。CSVの取り込み直しはマクロ版で行う）。

Sheet ダッシュボード
B1: 来庁者数集計（令和7年度）
B2: 番号発券機データ（令和7年4月〜令和8年3月、762,002件）。黄色のセルは選択項目。
B4: ① 区 | D4: 全区 | H4: ② 月 | J4: 全期間 | N4: ③ 開始 | P4: 0.375 | T4: ④ 終了 | V4: 0.6875
B5: ⑤ 指標 | D5: 来庁者数 | J5: ③④は開庁時間（案）。⑤は時間帯別・区別・月別グラフの指標。
C7: 来庁者の合計（人） | I7: 1日あたり（人） | O7: 来庁者数最大の15分 | U7: 開庁時間外の割合
C8: ='計算'!B13 -> 762002 | I8: ='計算'!B24 -> 2953.4961 | O8: ='計算'!B18 -> 10:30〜10:45 | U8: ='計算'!B16 -> 0.10972806
C10: ='ダッシュボード'!$D$4&" ／ "&'ダッシュボード'!$J$4 -> 全区 ／ 全期間 | I10: ="営業日 "&'計算'!B23&" 日" -> 営業日 258 日 | O10: ="最大 "&TEXT('計算'!B19,"#,##0")&" 人" -> 最大 26,217 人 | U10: =TEXT('計算'!B15,"#,##0")&" 人が時間外" -> 83,613 人が時間外
C12: 平均待ち時間（分） | I12: 15分以内に呼ばれた割合 | O12: 平均対応時間（分） | U12: 平均滞在時間（分）
C13: ='計算'!B25 -> 7.8387378 | I13: ='計算'!B26 -> 0.84952364 | O13: ='計算'!B27 -> 7.6375636 | U13: ='計算'!B28 -> 15.309631
C15: ="発券→呼出" -> 発券→呼出 | I15: ="待ち時間15分未満" -> 待ち時間15分未満 | O15: ="呼出→処理済み" -> 呼出→処理済み | U15: ="発券→処理済み" -> 発券→処理済み
B53: 来庁者数の多い日（上位5日、選択した区） | N53: 平均待ち時間の長い日（上位5日、選択した区）
B54: 1位 | D54: =INDEX('データ'!$A$880:$A$1244,MATCH(I54,INDEX('データ'!$B$880:$J$1244,0,'計算'!$B$22),0)) -> 46104 | I54: =LARGE(INDEX('データ'!$B$880:$J$1244,0,'計算'!$B$22),1) -> 5392 | N54: 1位 | P54: =INDEX('データ'!$A$880:$A$1244,MATCH(V54,INDEX('データ'!$L$880:$T$1244,0,'計算'!$B$22),0)) -> 46032 | V54: =LARGE(INDEX('データ'!$L$880:$T$1244,0,'計算'!$B$22),1) -> 168.2
B55: 2位 | D55: =INDEX('データ'!$A$880:$A$1244,MATCH(I55,INDEX('データ'!$B$880:$J$1244,0,'計算'!$B$22),0)) -> 46111 | I55: =LARGE(INDEX('データ'!$B$880:$J$1244,0,'計算'!$B$22),2) -> 5319 | N55: 2位 | P55: =INDEX('データ'!$A$880:$A$1244,MATCH(V55,INDEX('データ'!$L$880:$T$1244,0,'計算'!$B$22),0)) -> 46005 | V55: =LARGE(INDEX('データ'!$L$880:$T$1244,0,'計算'!$B$22),2) -> 98.9
B56: 3位 | D56: =INDEX('データ'!$A$880:$A$1244,MATCH(I56,INDEX('データ'!$B$880:$J$1244,0,'計算'!$B$22),0)) -> 46090 | I56: =LARGE(INDEX('データ'!$B$880:$J$1244,0,'計算'!$B$22),3) -> 4814 | N56: 3位 | P56: =INDEX('データ'!$A$880:$A$1244,MATCH(V56,INDEX('データ'!$L$880:$T$1244,0,'計算'!$B$22),0)) -> 45998 | V56: =LARGE(INDEX('データ'!$L$880:$T$1244,0,'計算'!$B$22),3) -> 58.4
B57: 4位 | D57: =INDEX('データ'!$A$880:$A$1244,MATCH(I57,INDEX('データ'!$B$880:$J$1244,0,'計算'!$B$22),0)) -> 46097 | I57: =LARGE(INDEX('データ'!$B$880:$J$1244,0,'計算'!$B$22),4) -> 4720 | N57: 4位 | P57: =INDEX('データ'!$A$880:$A$1244,MATCH(V57,INDEX('データ'!$L$880:$T$1244,0,'計算'!$B$22),0)) -> 46039 | V57: =LARGE(INDEX('データ'!$L$880:$T$1244,0,'計算'!$B$22),4) -> 48.3
B58: 5位 | D58: =INDEX('データ'!$A$880:$A$1244,MATCH(I58,INDEX('データ'!$B$880:$J$1244,0,'計算'!$B$22),0)) -> 45881 | I58: =LARGE(INDEX('データ'!$B$880:$J$1244,0,'計算'!$B$22),5) -> 4680 | N58: 5位 | P58: =INDEX('データ'!$A$880:$A$1244,MATCH(V58,INDEX('データ'!$L$880:$T$1244,0,'計算'!$B$22),0)) -> 46034 | V58: =LARGE(INDEX('データ'!$L$880:$T$1244,0,'計算'!$B$22),5) -> 34.6
B60: 注：開庁時間外＝③〜④の時間帯の前後に発券された件数。待ち＝発券→呼出、対応＝呼出→処理済み、滞在＝発券→処理済み。3時間超の値は平均から除く。
B61: 注：記録のない区・月がある（中区 12月（14日分のみ）、東区 1月（10日分のみ）、南区 11月（記録なし）、安佐北区 1月（7日分のみ） など）。該当月の人数は少なく表示される。

Sheet 時間外削減効果
B1: 時間外削減効果（市民部・厚生部）
B2: 窓口の受付時間を短縮した場合に減らせる、時間外の窓口対応時間の見込み（時間／年）。
B4: 削減効果
B5: 区分 | C5: 削減対象の発券数（年間・件） | D5: 平均処理時間（分） | E5: 削減効果（時間／年） | F5: 別添の値（時間／年） | G5: 差
B6: 市民部（8区役所） | C6: ='市民部'!C22 -> 38403 | D6: ='市民部'!D22 -> 9.1814608 | E6: ='市民部'!F22 -> 5876.594 | F6: ='市民部'!F26 -> 6131.4933 | G6: =E6/F6-1 -> -0.04157215
B7: 厚生部（8区役所に換算） | C7: ='厚生部'!F20 -> 37209.143 | D7: ='厚生部'!C7 -> 18.28506 | E7: ='厚生部'!G20 -> 11339.523 | F7: ='厚生部'!H24 -> 10372.526 | G7: =E7/F7-1 -> 0.093226838
B8: 合計 | E8: =E6+E7 -> 17216.117 | F8: =F6+F7 -> 16504.019 | G8: =E8/F8-1 -> 0.04314697
B10: 時間外勤務の実績との比較（令和7年度、給与課提供）
B11: 区分 | C11: 時間外勤務の実績（時間） | D11: 削減効果（時間） | E11: 実績に対する割合
B12: 市民部（市民課・保険年金課） | C12: 38566 | D12: =E6 -> 5876.594 | E12: =D12/C12 -> 0.15237759
B13: 厚生部（地域支えあい課・福祉課） | C13: 92894 | D13: =E7 -> 11339.523 | E13: =D13/C13 -> 0.12206949
B14: 合計 | C14: =C12+C13 -> 131460 | D14: =D12+D13 -> 17216.117 | E14: =D14/C14 -> 0.13096088
B15: 職員ベースの試算（別添「区役所別集計」） | C15: =C52 -> 18660 | D15: 年間削減時間（時間）。正規職員数×1日の削減時間×営業日数
B17: 区別：職員ベースの試算とデータ算出（時間／年）
B18: 区 | C18: 市民課（職員ベース） | D18: 市民部（データ） | E18: 福祉課（職員ベース） | F18: 厚生部（データ）
B19: 中区 | C19: =C40*$C$50*$C$51 -> 960 | D19: ='市民部'!F14 -> 1644.5527 | E19: =D40*$C$50*$C$51 -> 1560 | F19: ='厚生部'!G12 -> 986.78374
B20: 東区 | C20: =C41*$C$50*$C$51 -> 660 | D20: ='市民部'!F15 -> 539.41082 | E20: =D41*$C$50*$C$51 -> 1500 | F20: ='厚生部'!G13 -> 711.28883
B21: 南区 | C21: =C42*$C$50*$C$51 -> 780 | D21: ='市民部'!F16 -> 828.47381 | E21: =D42*$C$50*$C$51 -> 1680 | F21: ='厚生部'!G14 -> 2152.1516
B22: 西区 | C22: =C43*$C$50*$C$51 -> 1020 | D22: ='市民部'!F17 -> 1165.2804 | E22: =D43*$C$50*$C$51 -> 1860 | F22: ='厚生部'!G15 -> 2773.2341
B23: 安佐南区 | C23: =C44*$C$50*$C$51 -> 660 | D23: ='市民部'!F18 -> 218.67179 | E23: =D44*$C$50*$C$51 -> 2040 | F23: ='厚生部'!G16 -> 1273.8592
B24: 安佐北区 | C24: =C45*$C$50*$C$51 -> 540 | D24: ='市民部'!F19 -> 457.5428 | E24: =D45*$C$50*$C$51 -> 1680 | F24: ='厚生部'!G17 -> 728.35489
B25: 安芸区 | C25: =C46*$C$50*$C$51 -> 360 | D25: ='市民部'!F20 -> 271.46519 | E25: =D46*$C$50*$C$51 -> 1140 | F25: ='厚生部'!G19/7 -> 1417.4404
B26: 佐伯区 | C26: =C47*$C$50*$C$51 -> 660 | D26: ='市民部'!F21 -> 751.19652 | E26: =D47*$C$50*$C$51 -> 1560 | F26: ='厚生部'!G18 -> 1296.4108
B27: 計 | C27: =SUM(C19:C26) -> 5640 | D27: =SUM(D19:D26) -> 5876.594 | E27: =SUM(E19:E26) -> 13020 | F27: =SUM(F19:F26) -> 11339.523
B28: 注：厚生部の安芸区は7区計÷7で補完。
B30: 算出方法
B31: (1) 市民部：2025年1〜12月の16:30〜17:15の発券数 × 同期間の平均処理時間（呼出→処理済み）。いずれも発券機のCSVから集計。
B32: (2) 厚生部：令和8年4〜9月の16:30以降の発券数を区ごとに月平均×12で年間換算し、期間の平均処理時間を掛ける。安芸区は7区計×8÷7で換算。
B33: (3) 平均処理時間・基準時刻・集計期間は、市民部・厚生部シートの黄色のセルで変更できる。
B38: 職員ベースの設定（別添「区役所別集計」の値）
B39: 区 | C39: 市民課の正規職員（人） | D39: 福祉課の正規職員（人）
B40: 中区 | C40: 16 | D40: 26
B41: 東区 | C41: 11 | D41: 25
B42: 南区 | C42: 13 | D42: 28
B43: 西区 | C43: 17 | D43: 31
B44: 安佐南区 | C44: 11 | D44: 34
B45: 安佐北区 | C45: 9 | D45: 28
B46: 安芸区 | C46: 6 | D46: 19
B47: 佐伯区 | C47: 11 | D47: 26
B48: 計 | C48: =SUM(C40:C47) -> 94 | D48: =SUM(D40:D47) -> 217
...

Sheet 計算の説明
B1: 計算の説明（どのデータを、どんな条件で、どう計算しているか）
B2: 数字は、各シートの値をそのまま表示しています。条件を変えると、ここも変わります。
B4: 1. 何を計算しているか
B5: 窓口の受付を16:30で終わりにした場合、16:30以降に来た人の対応にかかっていた時間（＝減らせる時間外の窓口対応時間）が、1年でどれくらいになるかを求めています。
B7: 2. 使っているデータ
B8: 項目 | C8: 市民部（市民課） | D8: 厚生部（福祉課など）
B9: 元のデータ | C9: 市民課の番号発券機のCSV（1日1ファイル、区ごとのフォルダ） | D9: 厚生部の番号発券機のCSV（令和8年のR8.○月フォルダ、区ごと）
B10: CSVから読む項目 | C10: 発券した時刻、呼び出した時刻、処理が済んだ時刻 | D10: 同左（さらに窓口の業務の種類）
B11: データの範囲 | C11: 2024年1月〜2025年12月（計算に使うのは「市民部」シートの集計期間） | D11: 令和8年4月〜9月
B12: ないデータ | C12: 南区の2025年11月など、記録のない月がある | D12: 東区の8・9月、安芸区は全期間ない
B13: 使わないファイル | C13: 「全区」フォルダ（各区のコピー）。同じ区・同じ日のファイルが重複しているときは1つだけ使う。 | D13: 同左
B14: 取り込んだ件数（発券） | C14: =SUM('取込_市民部'!$C$8:$C$1007) -> 1339669 | D14: =SUM('取込_厚生部'!$C$8:$C$1007) -> 203959
B16: 3. 計算の条件
B17: 項目 | C17: 市民部 | D17: 厚生部
B18: 減らす時間帯 | C18: ="発券が "&TEXT('市民部'!C4,"h:mm")&" 〜 "&TEXT('市民部'!C5,"h:mm")&" の人" -> 発券が 16:30 〜 17:15 の人 | D18: ="発券が "&TEXT('厚生部'!C4,"h:mm")&" 以降の人" -> 発券が 16:30 以降の人
B19: 集計する期間 | C19: =LEFT('市民部'!C6,4)&"年"&RIGHT('市民部'!C6,2)&"月 〜 "&LEFT('市民部'!C7,4)&"年"&RIGHT('市民部'!C7,2)&"月" -> 2025年01月 〜 2025年12月 | D19: =LEFT('厚生部'!C8,4)&"年"&RIGHT('厚生部'!C8,2)&"月 〜 "&LEFT('厚生部'!D8,4)&"年"&RIGHT('厚生部'!D8,2)&"月" -> 2026年04月 〜 2026年09月
B20: 1年分への直し方 | C20: 集計期間が1年分なので、そのまま使う | D20: 区ごとに「1か月あたりの件数」を出して12倍する。データのない区（安芸区）は、他の7区の合計を8÷7倍して補う
B21: 1件あたりの処理時間 | C21: 集計期間の平均（呼出から処理済みまで） | D21: 集計期間の平均（呼出から処理済みまで）
B22: 平均処理時間（分） | C22: ='市民部'!C10 -> 9.1814608 | D22: ='厚生部'!C7 -> 18.28506
B23: 時刻の細かさ | C23: 15分ごとにまとめて数える | D23: 15分ごとにまとめて数える
B25: 4. 計算の手順
B26: 市民部 | C26: 内容 | E26: 数値
B27: ① 対象の人数 | C27: 減らす時間帯に発券した件数（8区の合計） | E27: ='市民部'!C22 -> 38403
B28: ② 平均処理時間（分） | C28: 1人の対応にかかった時間の平均 | E28: ='市民部'!D22 -> 9.1814608
B29: ③ 合計の時間（分） | C29: ① × ② | E29: ='市民部'!E22 -> 352595.64
B30: ④ 減らせる時間（時間） | C30: ③ ÷ 60（分を時間に直す） | E30: ='市民部'!F22 -> 5876.594
B32: 厚生部 | C32: 内容 | E32: 数値
B33: ① 対象の人数（期間計） | C33: 基準時刻以降に発券した件数（7区の合計） | E33: ='厚生部'!D19 -> 15890
B34: ② 1年分に直す | C34: 区ごとに 件数 ÷ データのある月数 × 12 をして合計 | E34: ='厚生部'!F19 -> 32558
B35: ③ 8区に換算 | C35: ② × 8 ÷ 7（安芸区の分を補う） | E35: ='厚生部'!F20 -> 37209.143
B36: ④ 平均処理時間（分） | C36: 1人の対応にかかった時間の平均 | E36: ='厚生部'!C7 -> 18.28506
B37: ⑤ 減らせる時間（時間） | C37: ③ × ④ ÷ 60 | E37: ='厚生部'!G20 -> 11339.523
B39: 合計（時間／年） | C39: 市民部 ＋ 厚生部。「時間外削減効果」シートの合計と同じ | E39: ='時間外削減効果'!E8 -> 17216.117
B41: 5. 見るときの注意
B42: ・記録のない月がある区は、その月の人数が少なく出る（市民部の「データのある月数」で確認できる）。
B43: ・厚生部は半年分のデータを12倍しているので、月による来庁数の違い（繁忙期など）は反映されていない。
B44: ・処理時間は、呼出から処理済みまでの時間。長く放置された件も除かずに平均している。
B45: ・別添の値（市民部6,131時間、厚生部10,373時間）とは、期間やデータの範囲が違うため、少し差が出る。
B47: → 時間外削減効果の総括へ

Sheet 市民部
B1: 市民部の時間外削減効果
B2: 削減対象の発券数 × 平均処理時間 ÷ 60 ＝ 削減できる窓口対応時間（時間／年）。発券機のCSVを取り込んで集計する。
B4: 削減対象の発券時間 開始 | C4: 0.6875
B5: 削減対象の発券時間 終了（これより前） | C5: 0.71875 | D5: 現行の受付終了時刻（15分刻みで集計）
B6: 集計期間 開始（年月） | C6: 202501 | D6: 発券数・平均処理時間とも、この期間で集計
B7: 集計期間 終了（年月） | C7: 202512
B8: 平均処理時間（分）の指定 | D8: 空欄の場合は実績平均を使用
B9: 平均処理時間の実績（集計期間） | C9: =IFERROR(SUMIFS('取込_市民部'!$D$8:$D$1007,'取込_市民部'!$B$8:$B$1007,">="&C6,'取込_市民部'!$B$8:$B$1007,"<="&C7)/SUMIFS('取込_市民部'!$E$8:$E$1007,'取込_市民部'!$B$8:$B$1007,">="&C6,'取込_市民部'!$B$8:$B$1007,"<="&C7),0) -> 9.1814608
B10: 採用する平均処理時間（分） | C10: =IF(ISNUMBER(C8),C8,C9) -> 9.1814608
B12: 区別
B13: 区 | C13: 削減対象の発券数（件） | D13: 平均処理時間（分） | E13: 分 | F13: 削減時間（時間） | G13: データのある月数
B14: 中区 | C14: =SUMPRODUCT(('取込_市民部'!$A$8:$A$1007=$B14)*('取込_市民部'!$B$8:$B$1007>=$C$6)*('取込_市民部'!$B$8:$B$1007<=$C$7)*('取込_市民部'!$F$6:$CW$6>=ROUND($C$4*1440,0))*('取込_市民部'!$F$6:$CW$6<ROUND($C$5*1440,0))*'取込_市民部'!$F$8:$CW$1007) -> 10747 | D14: =$C$10 -> 9.1814608 | E14: =C14*D14 -> 98673.159 | F14: =E14/60 -> 1644.5527 | G14: =SUMPRODUCT(('取込_市民部'!$A$8:$A$1007=$B14)*('取込_市民部'!$B$8:$B$1007>=$C$6)*('取込_市民部'!$B$8:$B$1007<=$C$7)*('取込_市民部'!$C$8:$C$1007>0)) -> 11
B15: 東区 | C15: =SUMPRODUCT(('取込_市民部'!$A$8:$A$1007=$B15)*('取込_市民部'!$B$8:$B$1007>=$C$6)*('取込_市民部'!$B$8:$B$1007<=$C$7)*('取込_市民部'!$F$6:$CW$6>=ROUND($C$4*1440,0))*('取込_市民部'!$F$6:$CW$6<ROUND($C$5*1440,0))*'取込_市民部'!$F$8:$CW$1007) -> 3525 | D15: =$C$10 -> 9.1814608 | E15: =C15*D15 -> 32364.649 | F15: =E15/60 -> 539.41082 | G15: =SUMPRODUCT(('取込_市民部'!$A$8:$A$1007=$B15)*('取込_市民部'!$B$8:$B$1007>=$C$6)*('取込_市民部'!$B$8:$B$1007<=$C$7)*('取込_市民部'!$C$8:$C$1007>0)) -> 12
B16: 南区 | C16: =SUMPRODUCT(('取込_市民部'!$A$8:$A$1007=$B16)*('取込_市民部'!$B$8:$B$1007>=$C$6)*('取込_市民部'!$B$8:$B$1007<=$C$7)*('取込_市民部'!$F$6:$CW$6>=ROUND($C$4*1440,0))*('取込_市民部'!$F$6:$CW$6<ROUND($C$5*1440,0))*'取込_市民部'!$F$8:$CW$1007) -> 5414 | D16: =$C$10 -> 9.1814608 | E16: =C16*D16 -> 49708.429 | F16: =E16/60 -> 828.47381 | G16: =SUMPRODUCT(('取込_市民部'!$A$8:$A$1007=$B16)*('取込_市民部'!$B$8:$B$1007>=$C$6)*('取込_市民部'!$B$8:$B$1007<=$C$7)*('取込_市民部'!$C$8:$C$1007>0)) -> 10
B17: 西区 | C17: =SUMPRODUCT(('取込_市民部'!$A$8:$A$1007=$B17)*('取込_市民部'!$B$8:$B$1007>=$C$6)*('取込_市民部'!$B$8:$B$1007<=$C$7)*('取込_市民部'!$F$6:$CW$6>=ROUND($C$4*1440,0))*('取込_市民部'!$F$6:$CW$6<ROUND($C$5*1440,0))*'取込_市民部'!$F$8:$CW$1007) -> 7615 | D17: =$C$10 -> 9.1814608 | E17: =C17*D17 -> 69916.824 | F17: =E17/60 -> 1165.2804 | G17: =SUMPRODUCT(('取込_市民部'!$A$8:$A$1007=$B17)*('取込_市民部'!$B$8:$B$1007>=$C$6)*('取込_市民部'!$B$8:$B$1007<=$C$7)*('取込_市民部'!$C$8:$C$1007>0)) -> 12
B18: 安佐南区 | C18: =SUMPRODUCT(('取込_市民部'!$A$8:$A$1007=$B18)*('取込_市民部'!$B$8:$B$1007>=$C$6)*('取込_市民部'!$B$8:$B$1007<=$C$7)*('取込_市民部'!$F$6:$CW$6>=ROUND($C$4*1440,0))*('取込_市民部'!$F$6:$CW$6<ROUND($C$5*1440,0))*'取込_市民部'!$F$8:$CW$1007) -> 1429 | D18: =$C$10 -> 9.1814608 | E18: =C18*D18 -> 13120.307 | F18: =E18/60 -> 218.67179 | G18: =SUMPRODUCT(('取込_市民部'!$A$8:$A$1007=$B18)*('取込_市民部'!$B$8:$B$1007>=$C$6)*('取込_市民部'!$B$8:$B$1007<=$C$7)*('取込_市民部'!$C$8:$C$1007>0)) -> 11
B19: 安佐北区 | C19: =SUMPRODUCT(('取込_市民部'!$A$8:$A$1007=$B19)*('取込_市民部'!$B$8:$B$1007>=$C$6)*('取込_市民部'!$B$8:$B$1007<=$C$7)*('取込_市民部'!$F$6:$CW$6>=ROUND($C$4*1440,0))*('取込_市民部'!$F$6:$CW$6<ROUND($C$5*1440,0))*'取込_市民部'!$F$8:$CW$1007) -> 2990 | D19: =$C$10 -> 9.1814608 | E19: =C19*D19 -> 27452.568 | F19: =E19/60 -> 457.5428 | G19: =SUMPRODUCT(('取込_市民部'!$A$8:$A$1007=$B19)*('取込_市民部'!$B$8:$B$1007>=$C$6)*('取込_市民部'!$B$8:$B$1007<=$C$7)*('取込_市民部'!$C$8:$C$1007>0)) -> 12
B20: 安芸区 | C20: =SUMPRODUCT(('取込_市民部'!$A$8:$A$1007=$B20)*('取込_市民部'!$B$8:$B$1007>=$C$6)*('取込_市民部'!$B$8:$B$1007<=$C$7)*('取込_市民部'!$F$6:$CW$6>=ROUND($C$4*1440,0))*('取込_市民部'!$F$6:$CW$6<ROUND($C$5*1440,0))*'取込_市民部'!$F$8:$CW$1007) -> 1774 | D20: =$C$10 -> 9.1814608 | E20: =C20*D20 -> 16287.911 | F20: =E20/60 -> 271.46519 | G20: =SUMPRODUCT(('取込_市民部'!$A$8:$A$1007=$B20)*('取込_市民部'!$B$8:$B$1007>=$C$6)*('取込_市民部'!$B$8:$B$1007<=$C$7)*('取込_市民部'!$C$8:$C$1007>0)) -> 12
B21: 佐伯区 | C21: =SUMPRODUCT(('取込_市民部'!$A$8:$A$1007=$B21)*('取込_市民部'!$B$8:$B$1007>=$C$6)*('取込_市民部'!$B$8:$B$1007<=$C$7)*('取込_市民部'!$F$6:$CW$6>=ROUND($C$4*1440,0))*('取込_市民部'!$F$6:$CW$6<ROUND($C$5*1440,0))*'取込_市民部'!$F$8:$CW$1007) -> 4909 | D21: =$C$10 -> 9.1814608 | E21: =C21*D21 -> 45071.791 | F21: =E21/60 -> 751.19652 | G21: =SUMPRODUCT(('取込_市民部'!$A$8:$A$1007=$B21)*('取込_市民部'!$B$8:$B$1007>=$C$6)*('取込_市民部'!$B$8:$B$1007<=$C$7)*('取込_市民部'!$C$8:$C$1007>0)) -> 12
B22: 計 | C22: =SUM(C14:C21) -> 38403 | D22: =C10 -> 9.1814608 | E22: =SUM(E14:E21) -> 352595.64 | F22: =SUM(F14:F21) -> 5876.594
B24: 別添の値
B25: 区分 | C25: 発券数（件） | D25: 平均処理時間（分） | E25: 分 | F25: 時間
B26: 市民部8区役所12ヶ月 | C26: 39988 | D26: 9.2 | E26: =C26*D26 -> 367889.6 | F26: =E26/60 -> 6131.4933
B27: 差（データ−別添） | C27: =C22-C26 -> -1585 | F27: =F22/F26-1 -> -0.04157215
B29: 注：別添の発券数（39,988件）は令和7年度の集計。取り込んだCSVの範囲（2024年1月〜2025年12月）では、2025年1〜12月を既定の集計期間としている。
B30: 注：南区の2025年11月、令和7年度後半など、発券機データのない月がある。「データのある月数」で確認できる。
B31: 注：取り込んだCSVは、同じ区・同じ日のファイルが複数あるときは最初の1つだけ使う（区をまたいだコピーの混入を防ぐため）。

Sheet 厚生部
B1: 厚生部の時間外削減効果
B2: 発券機のCSVから、基準時刻以降の発券数を年間に換算し、平均処理時間を掛ける。安芸区のデータがないため、7区の値を×8÷7で8区に換算。
B4: 基準時刻（これ以降の発券） | C4: 0.6875 | D4: 15分刻みで集計
B5: 平均処理時間（分）の指定 | D5: 空欄の場合は集計期間の実績平均を使用
B6: 平均処理時間の実績（集計期間） | C6: =IFERROR(SUMIFS('取込_厚生部'!$D$8:$D$1007,'取込_厚生部'!$B$8:$B$1007,">="&C8,'取込_厚生部'!$B$8:$B$1007,"<="&D8)/SUMIFS('取込_厚生部'!$E$8:$E$1007,'取込_厚生部'!$B$8:$B$1007,">="&C8,'取込_厚生部'!$B$8:$B$1007,"<="&D8),0) -> 18.28506
B7: 採用する平均処理時間（分） | C7: =IF(ISNUMBER(C5),C5,C6) -> 18.28506
B8: 集計期間（年月〜年月） | C8: 202604 | D8: 202609
B10: 区別
B11: 区 | C11: データのある月数 | D11: 基準以降の発券数（期間計） | E11: 月平均（件） | F11: 年間換算（件） | G11: 削減時間（時間／年）
B12: 中区 | C12: =SUMPRODUCT(('取込_厚生部'!$A$8:$A$1007=$B12)*('取込_厚生部'!$B$8:$B$1007>=$C$8)*('取込_厚生部'!$B$8:$B$1007<=$D$8)*('取込_厚生部'!$C$8:$C$1007>0)) -> 6 | D12: =SUMPRODUCT(('取込_厚生部'!$A$8:$A$1007=$B12)*('取込_厚生部'!$B$8:$B$1007>=$C$8)*('取込_厚生部'!$B$8:$B$1007<=$D$8)*('取込_厚生部'!$F$6:$CW$6>=ROUND($C$4*1440,0))*'取込_厚生部'!$F$8:$CW$1007) -> 1619 | E12: =IF(C12=0,0,D12/C12) -> 269.83333 | F12: =E12*12 -> 3238 | G12: =F12*$C$7/60 -> 986.78374
B13: 東区 | C13: =SUMPRODUCT(('取込_厚生部'!$A$8:$A$1007=$B13)*('取込_厚生部'!$B$8:$B$1007>=$C$8)*('取込_厚生部'!$B$8:$B$1007<=$D$8)*('取込_厚生部'!$C$8:$C$1007>0)) -> 4 | D13: =SUMPRODUCT(('取込_厚生部'!$A$8:$A$1007=$B13)*('取込_厚生部'!$B$8:$B$1007>=$C$8)*('取込_厚生部'!$B$8:$B$1007<=$D$8)*('取込_厚生部'!$F$6:$CW$6>=ROUND($C$4*1440,0))*'取込_厚生部'!$F$8:$CW$1007) -> 778 | E13: =IF(C13=0,0,D13/C13) -> 194.5 | F13: =E13*12 -> 2334 | G13: =F13*$C$7/60 -> 711.28883
B14: 南区 | C14: =SUMPRODUCT(('取込_厚生部'!$A$8:$A$1007=$B14)*('取込_厚生部'!$B$8:$B$1007>=$C$8)*('取込_厚生部'!$B$8:$B$1007<=$D$8)*('取込_厚生部'!$C$8:$C$1007>0)) -> 6 | D14: =SUMPRODUCT(('取込_厚生部'!$A$8:$A$1007=$B14)*('取込_厚生部'!$B$8:$B$1007>=$C$8)*('取込_厚生部'!$B$8:$B$1007<=$D$8)*('取込_厚生部'!$F$6:$CW$6>=ROUND($C$4*1440,0))*'取込_厚生部'!$F$8:$CW$1007) -> 3531 | E14: =IF(C14=0,0,D14/C14) -> 588.5 | F14: =E14*12 -> 7062 | G14: =F14*$C$7/60 -> 2152.1516
B15: 西区 | C15: =SUMPRODUCT(('取込_厚生部'!$A$8:$A$1007=$B15)*('取込_厚生部'!$B$8:$B$1007>=$C$8)*('取込_厚生部'!$B$8:$B$1007<=$D$8)*('取込_厚生部'!$C$8:$C$1007>0)) -> 6 | D15: =SUMPRODUCT(('取込_厚生部'!$A$8:$A$1007=$B15)*('取込_厚生部'!$B$8:$B$1007>=$C$8)*('取込_厚生部'!$B$8:$B$1007<=$D$8)*('取込_厚生部'!$F$6:$CW$6>=ROUND($C$4*1440,0))*'取込_厚生部'!$F$8:$CW$1007) -> 4550 | E15: =IF(C15=0,0,D15/C15) -> 758.33333 | F15: =E15*12 -> 9100 | G15: =F15*$C$7/60 -> 2773.2341
B16: 安佐南区 | C16: =SUMPRODUCT(('取込_厚生部'!$A$8:$A$1007=$B16)*('取込_厚生部'!$B$8:$B$1007>=$C$8)*('取込_厚生部'!$B$8:$B$1007<=$D$8)*('取込_厚生部'!$C$8:$C$1007>0)) -> 6 | D16: =SUMPRODUCT(('取込_厚生部'!$A$8:$A$1007=$B16)*('取込_厚生部'!$B$8:$B$1007>=$C$8)*('取込_厚生部'!$B$8:$B$1007<=$D$8)*('取込_厚生部'!$F$6:$CW$6>=ROUND($C$4*1440,0))*'取込_厚生部'!$F$8:$CW$1007) -> 2090 | E16: =IF(C16=0,0,D16/C16) -> 348.33333 | F16: =E16*12 -> 4180 | G16: =F16*$C$7/60 -> 1273.8592
B17: 安佐北区 | C17: =SUMPRODUCT(('取込_厚生部'!$A$8:$A$1007=$B17)*('取込_厚生部'!$B$8:$B$1007>=$C$8)*('取込_厚生部'!$B$8:$B$1007<=$D$8)*('取込_厚生部'!$C$8:$C$1007>0)) -> 6 | D17: =SUMPRODUCT(('取込_厚生部'!$A$8:$A$1007=$B17)*('取込_厚生部'!$B$8:$B$1007>=$C$8)*('取込_厚生部'!$B$8:$B$1007<=$D$8)*('取込_厚生部'!$F$6:$CW$6>=ROUND($C$4*1440,0))*'取込_厚生部'!$F$8:$CW$1007) -> 1195 | E17: =IF(C17=0,0,D17/C17) -> 199.16667 | F17: =E17*12 -> 2390 | G17: =F17*$C$7/60 -> 728.35489
B18: 佐伯区 | C18: =SUMPRODUCT(('取込_厚生部'!$A$8:$A$1007=$B18)*('取込_厚生部'!$B$8:$B$1007>=$C$8)*('取込_厚生部'!$B$8:$B$1007<=$D$8)*('取込_厚生部'!$C$8:$C$1007>0)) -> 6 | D18: =SUMPRODUCT(('取込_厚生部'!$A$8:$A$1007=$B18)*('取込_厚生部'!$B$8:$B$1007>=$C$8)*('取込_厚生部'!$B$8:$B$1007<=$D$8)*('取込_厚生部'!$F$6:$CW$6>=ROUND($C$4*1440,0))*'取込_厚生部'!$F$8:$CW$1007) -> 2127 | E18: =IF(C18=0,0,D18/C18) -> 354.5 | F18: =E18*12 -> 4254 | G18: =F18*$C$7/60 -> 1296.4108
B19: 7区計 | D19: =SUM(D12:D18) -> 15890 | F19: =SUM(F12:F18) -> 32558 | G19: =SUM(G12:G18) -> 9922.083
B20: 8区換算（×8÷7） | F20: =F19*8/7 -> 37209.143 | G20: =G19*8/7 -> 11339.523
B22: 別添の値
B23: 区分 | C23: 発券数（2ヶ月） | D23: 平均処理時間（分） | E23: 分 | F23: 時間 | G23: 12ヶ月換算 | H23: 8区換算
B24: 厚生部7区役所（安芸区除く）2ヶ月 | C24: 4449 | D24: 20.4 | E24: 90759.6 | F24: 1512.66 | G24: 9075.96 | H24: 10372.526
B25: 差（データ−別添） | H25: =G20/H24-1 -> 0.093226838
B27: 月別の発券数（全時間帯）
B28: 区 | C28: =$C$8 -> 202604 | D28: =IF(C28="","",IF(IF(MOD(C28,100)=12,C28+89,C28+1)>$D$8,"",IF(MOD(C28,100)=12,C28+89,C28+1))) -> 202605 | E28: =IF(D28="","",IF(IF(MOD(D28,100)=12,D28+89,D28+1)>$D$8,"",IF(MOD(D28,100)=12,D28+89,D28+1))) -> 202606 | F28: =IF(E28="","",IF(IF(MOD(E28,100)=12,E28+89,E28+1)>$D$8,"",IF(MOD(E28,100)=12,E28+89,E28+1))) -> 202607 | G28: =IF(F28="","",IF(IF(MOD(F28,100)=12,F28+89,F28+1)>$D$8,"",IF(MOD(F28,100)=12,F28+89,F28+1))) -> 202608 | H28: =IF(G28="","",IF(IF(MOD(G28,100)=12,G28+89,G28+1)>$D$8,"",IF(MOD(G28,100)=12,G28+89,G28+1))) -> 202609
B29: 中区 | C29: =IF(C$28="","",SUMIFS('取込_厚生部'!$C$8:$C$1007,'取込_厚生部'!$A$8:$A$1007,$B29,'取込_厚生部'!$B$8:$B$1007,C$28)) -> 3767 | D29: =IF(D$28="","",SUMIFS('取込_厚生部'!$C$8:$C$1007,'取込_厚生部'!$A$8:$A$1007,$B29,'取込_厚生部'!$B$8:$B$1007,D$28)) -> 3465 | E29: =IF(E$28="","",SUMIFS('取込_厚生部'!$C$8:$C$1007,'取込_厚生部'!$A$8:$A$1007,$B29,'取込_厚生部'!$B$8:$B$1007,E$28)) -> 4777 | F29: =IF(F$28="","",SUMIFS('取込_厚生部'!$C$8:$C$1007,'取込_厚生部'!$A$8:$A$1007,$B29,'取込_厚生部'!$B$8:$B$1007,F$28)) -> 4638 | G29: =IF(G$28="","",SUMIFS('取込_厚生部'!$C$8:$C$1007,'取込_厚生部'!$A$8:$A$1007,$B29,'取込_厚生部'!$B$8:$B$1007,G$28)) -> 5250 | H29: =IF(H$28="","",SUMIFS('取込_厚生部'!$C$8:$C$1007,'取込_厚生部'!$A$8:$A$1007,$B29,'取込_厚生部'!$B$8:$B$1007,H$28)) -> 3938
B30: 東区 | C30: =IF(C$28="","",SUMIFS('取込_厚生部'!$C$8:$C$1007,'取込_厚生部'!$A$8:$A$1007,$B30,'取込_厚生部'!$B$8:$B$1007,C$28)) -> 3595 | D30: =IF(D$28="","",SUMIFS('取込_厚生部'!$C$8:$C$1007,'取込_厚生部'!$A$8:$A$1007,$B30,'取込_厚生部'!$B$8:$B$1007,D$28)) -> 3507 | E30: =IF(E$28="","",SUMIFS('取込_厚生部'!$C$8:$C$1007,'取込_厚生部'!$A$8:$A$1007,$B30,'取込_厚生部'!$B$8:$B$1007,E$28)) -> 4559 | F30: =IF(F$28="","",SUMIFS('取込_厚生部'!$C$8:$C$1007,'取込_厚生部'!$A$8:$A$1007,$B30,'取込_厚生部'!$B$8:$B$1007,F$28)) -> 4412 | G30: =IF(G$28="","",SUMIFS('取込_厚生部'!$C$8:$C$1007,'取込_厚生部'!$A$8:$A$1007,$B30,'取込_厚生部'!$B$8:$B$1007,G$28)) -> 0 | H30: =IF(H$28="","",SUMIFS('取込_厚生部'!$C$8:$C$1007,'取込_厚生部'!$A$8:$A$1007,$B30,'取込_厚生部'!$B$8:$B$1007,H$28)) -> 0
B31: 南区 | C31: =IF(C$28="","",SUMIFS('取込_厚生部'!$C$8:$C$1007,'取込_厚生部'!$A$8:$A$1007,$B31,'取込_厚生部'!$B$8:$B$1007,C$28)) -> 3624 | D31: =IF(D$28="","",SUMIFS('取込_厚生部'!$C$8:$C$1007,'取込_厚生部'!$A$8:$A$1007,$B31,'取込_厚生部'!$B$8:$B$1007,D$28)) -> 3868 | E31: =IF(E$28="","",SUMIFS('取込_厚生部'!$C$8:$C$1007,'取込_厚生部'!$A$8:$A$1007,$B31,'取込_厚生部'!$B$8:$B$1007,E$28)) -> 5278 | F31: =IF(F$28="","",SUMIFS('取込_厚生部'!$C$8:$C$1007,'取込_厚生部'!$A$8:$A$1007,$B31,'取込_厚生部'!$B$8:$B$1007,F$28)) -> 5466 | G31: =IF(G$28="","",SUMIFS('取込_厚生部'!$C$8:$C$1007,'取込_厚生部'!$A$8:$A$1007,$B31,'取込_厚生部'!$B$8:$B$1007,G$28)) -> 5944 | H31: =IF(H$28="","",SUMIFS('取込_厚生部'!$C$8:$C$1007,'取込_厚生部'!$A$8:$A$1007,$B31,'取込_厚生部'!$B$8:$B$1007,H$28)) -> 4485
B32: 西区 | C32: =IF(C$28="","",SUMIFS('取込_厚生部'!$C$8:$C$1007,'取込_厚生部'!$A$8:$A$1007,$B32,'取込_厚生部'!$B$8:$B$1007,C$28)) -> 5370 | D32: =IF(D$28="","",SUMIFS('取込_厚生部'!$C$8:$C$1007,'取込_厚生部'!$A$8:$A$1007,$B32,'取込_厚生部'!$B$8:$B$1007,D$28)) -> 5020 | E32: =IF(E$28="","",SUMIFS('取込_厚生部'!$C$8:$C$1007,'取込_厚生部'!$A$8:$A$1007,$B32,'取込_厚生部'!$B$8:$B$1007,E$28)) -> 6607 | F32: =IF(F$28="","",SUMIFS('取込_厚生部'!$C$8:$C$1007,'取込_厚生部'!$A$8:$A$1007,$B32,'取込_厚生部'!$B$8:$B$1007,F$28)) -> 6636 | G32: =IF(G$28="","",SUMIFS('取込_厚生部'!$C$8:$C$1007,'取込_厚生部'!$A$8:$A$1007,$B32,'取込_厚生部'!$B$8:$B$1007,G$28)) -> 7296 | H32: =IF(H$28="","",SUMIFS('取込_厚生部'!$C$8:$C$1007,'取込_厚生部'!$A$8:$A$1007,$B32,'取込_厚生部'!$B$8:$B$1007,H$28)) -> 5534
B33: 安佐南区 | C33: =IF(C$28="","",SUMIFS('取込_厚生部'!$C$8:$C$1007,'取込_厚生部'!$A$8:$A$1007,$B33,'取込_厚生部'!$B$8:$B$1007,C$28)) -> 6558 | D33: =IF(D$28="","",SUMIFS('取込_厚生部'!$C$8:$C$1007,'取込_厚生部'!$A$8:$A$1007,$B33,'取込_厚生部'!$B$8:$B$1007,D$28)) -> 6316 | E33: =IF(E$28="","",SUMIFS('取込_厚生部'!$C$8:$C$1007,'取込_厚生部'!$A$8:$A$1007,$B33,'取込_厚生部'!$B$8:$B$1007,E$28)) -> 8023 | F33: =IF(F$28="","",SUMIFS('取込_厚生部'!$C$8:$C$1007,'取込_厚生部'!$A$8:$A$1007,$B33,'取込_厚生部'!$B$8:$B$1007,F$28)) -> 8089 | G33: =IF(G$28="","",SUMIFS('取込_厚生部'!$C$8:$C$1007,'取込_厚生部'!$A$8:$A$1007,$B33,'取込_厚生部'!$B$8:$B$1007,G$28)) -> 8307 | H33: =IF(H$28="","",SUMIFS('取込_厚生部'!$C$8:$C$1007,'取込_厚生部'!$A$8:$A$1007,$B33,'取込_厚生部'!$B$8:$B$1007,H$28)) -> 6681
B34: 安佐北区 | C34: =IF(C$28="","",SUMIFS('取込_厚生部'!$C$8:$C$1007,'取込_厚生部'!$A$8:$A$1007,$B34,'取込_厚生部'!$B$8:$B$1007,C$28)) -> 3284 | D34: =IF(D$28="","",SUMIFS('取込_厚生部'!$C$8:$C$1007,'取込_厚生部'!$A$8:$A$1007,$B34,'取込_厚生部'!$B$8:$B$1007,D$28)) -> 3112 | E34: =IF(E$28="","",SUMIFS('取込_厚生部'!$C$8:$C$1007,'取込_厚生部'!$A$8:$A$1007,$B34,'取込_厚生部'!$B$8:$B$1007,E$28)) -> 4312 | F34: =IF(F$28="","",SUMIFS('取込_厚生部'!$C$8:$C$1007,'取込_厚生部'!$A$8:$A$1007,$B34,'取込_厚生部'!$B$8:$B$1007,F$28)) -> 4192 | G34: =IF(G$28="","",SUMIFS('取込_厚生部'!$C$8:$C$1007,'取込_厚生部'!$A$8:$A$1007,$B34,'取込_厚生部'!$B$8:$B$1007,G$28)) -> 4785 | H34: =IF(H$28="","",SUMIFS('取込_厚生部'!$C$8:$C$1007,'取込_厚生部'!$A$8:$A$1007,$B34,'取込_厚生部'!$B$8:$B$1007,H$28)) -> 3328
B35: 佐伯区 | C35: =IF(C$28="","",SUMIFS('取込_厚生部'!$C$8:$C$1007,'取込_厚生部'!$A$8:$A$1007,$B35,'取込_厚生部'!$B$8:$B$1007,C$28)) -> 4240 | D35: =IF(D$28="","",SUMIFS('取込_厚生部'!$C$8:$C$1007,'取込_厚生部'!$A$8:$A$1007,$B35,'取込_厚生部'!$B$8:$B$1007,D$28)) -> 4020 | E35: =IF(E$28="","",SUMIFS('取込_厚生部'!$C$8:$C$1007,'取込_厚生部'!$A$8:$A$1007,$B35,'取込_厚生部'!$B$8:$B$1007,E$28)) -> 5511 | F35: =IF(F$28="","",SUMIFS('取込_厚生部'!$C$8:$C$1007,'取込_厚生部'!$A$8:$A$1007,$B35,'取込_厚生部'!$B$8:$B$1007,F$28)) -> 5217 | G35: =IF(G$28="","",SUMIFS('取込_厚生部'!$C$8:$C$1007,'取込_厚生部'!$A$8:$A$1007,$B35,'取込_厚生部'!$B$8:$B$1007,G$28)) -> 6528 | H35: =IF(H$28="","",SUMIFS('取込_厚生部'!$C$8:$C$1007,'取込_厚生部'!$A$8:$A$1007,$B35,'取込_厚生部'!$B$8:$B$1007,H$28)) -> 4420
B36: 計 | C36: =SUM(C29:C35) -> 30438 | D36: =SUM(D29:D35) -> 29308 | E36: =SUM(E29:E35) -> 39067 | F36: =SUM(F29:F35) -> 38650 | G36: =SUM(G29:G35) -> 38110 | H36: =SUM(H29:H35) -> 28386
B38: 基準以降
B39: 区 | C39: =C28 -> 202604 | D39: =D28 -> 202605 | E39: =E28 -> 202606 | F39: =F28 -> 202607 | G39: =G28 -> 202608 | H39: =H28 -> 202609
B40: 中区 | C40: =IF(C$39="","",SUMPRODUCT(('取込_厚生部'!$A$8:$A$1007=$B40)*('取込_厚生部'!$B$8:$B$1007=C$39)*('取込_厚生部'!$F$6:$CW$6>=ROUND($C$4*1440,0))*'取込_厚生部'!$F$8:$CW$1007)) -> 251 | D40: =IF(D$39="","",SUMPRODUCT(('取込_厚生部'!$A$8:$A$1007=$B40)*('取込_厚生部'!$B$8:$B$1007=D$39)*('取込_厚生部'!$F$6:$CW$6>=ROUND($C$4*1440,0))*'取込_厚生部'!$F$8:$CW$1007)) -> 232 | E40: =IF(E$39="","",SUMPRODUCT(('取込_厚生部'!$A$8:$A$1007=$B40)*('取込_厚生部'!$B$8:$B$1007=E$39)*('取込_厚生部'!$F$6:$CW$6>=ROUND($C$4*1440,0))*'取込_厚生部'!$F$8:$CW$1007)) -> 276 | F40: =IF(F$39="","",SUMPRODUCT(('取込_厚生部'!$A$8:$A$1007=$B40)*('取込_厚生部'!$B$8:$B$1007=F$39)*('取込_厚生部'!$F$6:$CW$6>=ROUND($C$4*1440,0))*'取込_厚生部'!$F$8:$CW$1007)) -> 279 | G40: =IF(G$39="","",SUMPRODUCT(('取込_厚生部'!$A$8:$A$1007=$B40)*('取込_厚生部'!$B$8:$B$1007=G$39)*('取込_厚生部'!$F$6:$CW$6>=ROUND($C$4*1440,0))*'取込_厚生部'!$F$8:$CW$1007)) -> 348 | H40: =IF(H$39="","",SUMPRODUCT(('取込_厚生部'!$A$8:$A$1007=$B40)*('取込_厚生部'!$B$8:$B$1007=H$39)*('取込_厚生部'!$F$6:$CW$6>=ROUND($C$4*1440,0))*'取込_厚生部'!$F$8:$CW$1007)) -> 233
B41: 東区 | C41: =IF(C$39="","",SUMPRODUCT(('取込_厚生部'!$A$8:$A$1007=$B41)*('取込_厚生部'!$B$8:$B$1007=C$39)*('取込_厚生部'!$F$6:$CW$6>=ROUND($C$4*1440,0))*'取込_厚生部'!$F$8:$CW$1007)) -> 159 | D41: =IF(D$39="","",SUMPRODUCT(('取込_厚生部'!$A$8:$A$1007=$B41)*('取込_厚生部'!$B$8:$B$1007=D$39)*('取込_厚生部'!$F$6:$CW$6>=ROUND($C$4*1440,0))*'取込_厚生部'!$F$8:$CW$1007)) -> 191 | E41: =IF(E$39="","",SUMPRODUCT(('取込_厚生部'!$A$8:$A$1007=$B41)*('取込_厚生部'!$B$8:$B$1007=E$39)*('取込_厚生部'!$F$6:$CW$6>=ROUND($C$4*1440,0))*'取込_厚生部'!$F$8:$CW$1007)) -> 213 | F41: =IF(F$39="","",SUMPRODUCT(('取込_厚生部'!$A$8:$A$1007=$B41)*('取込_厚生部'!$B$8:$B$1007=F$39)*('取込_厚生部'!$F$6:$CW$6>=ROUND($C$4*1440,0))*'取込_厚生部'!$F$8:$CW$1007)) -> 215 | G41: =IF(G$39="","",SUMPRODUCT(('取込_厚生部'!$A$8:$A$1007=$B41)*('取込_厚生部'!$B$8:$B$1007=G$39)*('取込_厚生部'!$F$6:$CW$6>=ROUND($C$4*1440,0))*'取込_厚生部'!$F$8:$CW$1007)) -> 0 | H41: =IF(H$39="","",SUMPRODUCT(('取込_厚生部'!$A$8:$A$1007=$B41)*('取込_厚生部'!$B$8:$B$1007=H$39)*('取込_厚生部'!$F$6:$CW$6>=ROUND($C$4*1440,0))*'取込_厚生部'!$F$8:$CW$1007)) -> 0
B42: 南区 | C42: =IF(C$39="","",SUMPRODUCT(('取込_厚生部'!$A$8:$A$1007=$B42)*('取込_厚生部'!$B$8:$B$1007=C$39)*('取込_厚生部'!$F$6:$CW$6>=ROUND($C$4*1440,0))*'取込_厚生部'!$F$8:$CW$1007)) -> 428 | D42: =IF(D$39="","",SUMPRODUCT(('取込_厚生部'!$A$8:$A$1007=$B42)*('取込_厚生部'!$B$8:$B$1007=D$39)*('取込_厚生部'!$F$6:$CW$6>=ROUND($C$4*1440,0))*'取込_厚生部'!$F$8:$CW$1007)) -> 472 | E42: =IF(E$39="","",SUMPRODUCT(('取込_厚生部'!$A$8:$A$1007=$B42)*('取込_厚生部'!$B$8:$B$1007=E$39)*('取込_厚生部'!$F$6:$CW$6>=ROUND($C$4*1440,0))*'取込_厚生部'!$F$8:$CW$1007)) -> 603 | F42: =IF(F$39="","",SUMPRODUCT(('取込_厚生部'!$A$8:$A$1007=$B42)*('取込_厚生部'!$B$8:$B$1007=F$39)*('取込_厚生部'!$F$6:$CW$6>=ROUND($C$4*1440,0))*'取込_厚生部'!$F$8:$CW$1007)) -> 697 | G42: =IF(G$39="","",SUMPRODUCT(('取込_厚生部'!$A$8:$A$1007=$B42)*('取込_厚生部'!$B$8:$B$1007=G$39)*('取込_厚生部'!$F$6:$CW$6>=ROUND($C$4*1440,0))*'取込_厚生部'!$F$8:$CW$1007)) -> 797 | H42: =IF(H$39="","",SUMPRODUCT(('取込_厚生部'!$A$8:$A$1007=$B42)*('取込_厚生部'!$B$8:$B$1007=H$39)*('取込_厚生部'!$F$6:$CW$6>=ROUND($C$4*1440,0))*'取込_厚生部'!$F$8:$CW$1007)) -> 534
B43: 西区 | C43: =IF(C$39="","",SUMPRODUCT(('取込_厚生部'!$A$8:$A$1007=$B43)*('取込_厚生部'!$B$8:$B$1007=C$39)*('取込_厚生部'!$F$6:$CW$6>=ROUND($C$4*1440,0))*'取込_厚生部'!$F$8:$CW$1007)) -> 737 | D43: =IF(D$39="","",SUMPRODUCT(('取込_厚生部'!$A$8:$A$1007=$B43)*('取込_厚生部'!$B$8:$B$1007=D$39)*('取込_厚生部'!$F$6:$CW$6>=ROUND($C$4*1440,0))*'取込_厚生部'!$F$8:$CW$1007)) -> 595 | E43: =IF(E$39="","",SUMPRODUCT(('取込_厚生部'!$A$8:$A$1007=$B43)*('取込_厚生部'!$B$8:$B$1007=E$39)*('取込_厚生部'!$F$6:$CW$6>=ROUND($C$4*1440,0))*'取込_厚生部'!$F$8:$CW$1007)) -> 784 | F43: =IF(F$39="","",SUMPRODUCT(('取込_厚生部'!$A$8:$A$1007=$B43)*('取込_厚生部'!$B$8:$B$1007=F$39)*('取込_厚生部'!$F$6:$CW$6>=ROUND($C$4*1440,0))*'取込_厚生部'!$F$8:$CW$1007)) -> 828 | G43: =IF(G$39="","",SUMPRODUCT(('取込_厚生部'!$A$8:$A$1007=$B43)*('取込_厚生部'!$B$8:$B$1007=G$39)*('取込_厚生部'!$F$6:$CW$6>=ROUND($C$4*1440,0))*'取込_厚生部'!$F$8:$CW$1007)) -> 933 | H43: =IF(H$39="","",SUMPRODUCT(('取込_厚生部'!$A$8:$A$1007=$B43)*('取込_厚生部'!$B$8:$B$1007=H$39)*('取込_厚生部'!$F$6:$CW$6>=ROUND($C$4*1440,0))*'取込_厚生部'!$F$8:$CW$1007)) -> 673
B44: 安佐南区 | C44: =IF(C$39="","",SUMPRODUCT(('取込_厚生部'!$A$8:$A$1007=$B44)*('取込_厚生部'!$B$8:$B$1007=C$39)*('取込_厚生部'!$F$6:$CW$6>=ROUND($C$4*1440,0))*'取込_厚生部'!$F$8:$CW$1007)) -> 267 | D44: =IF(D$39="","",SUMPRODUCT(('取込_厚生部'!$A$8:$A$1007=$B44)*('取込_厚生部'!$B$8:$B$1007=D$39)*('取込_厚生部'!$F$6:$CW$6>=ROUND($C$4*1440,0))*'取込_厚生部'!$F$8:$CW$1007)) -> 239 | E44: =IF(E$39="","",SUMPRODUCT(('取込_厚生部'!$A$8:$A$1007=$B44)*('取込_厚生部'!$B$8:$B$1007=E$39)*('取込_厚生部'!$F$6:$CW$6>=ROUND($C$4*1440,0))*'取込_厚生部'!$F$8:$CW$1007)) -> 332 | F44: =IF(F$39="","",SUMPRODUCT(('取込_厚生部'!$A$8:$A$1007=$B44)*('取込_厚生部'!$B$8:$B$1007=F$39)*('取込_厚生部'!$F$6:$CW$6>=ROUND($C$4*1440,0))*'取込_厚生部'!$F$8:$CW$1007)) -> 445 | G44: =IF(G$39="","",SUMPRODUCT(('取込_厚生部'!$A$8:$A$1007=$B44)*('取込_厚生部'!$B$8:$B$1007=G$39)*('取込_厚生部'!$F$6:$CW$6>=ROUND($C$4*1440,0))*'取込_厚生部'!$F$8:$CW$1007)) -> 459 | H44: =IF(H$39="","",SUMPRODUCT(('取込_厚生部'!$A$8:$A$1007=$B44)*('取込_厚生部'!$B$8:$B$1007=H$39)*('取込_厚生部'!$F$6:$CW$6>=ROUND($C$4*1440,0))*'取込_厚生部'!$F$8:$CW$1007)) -> 348
B45: 安佐北区 | C45: =IF(C$39="","",SUMPRODUCT(('取込_厚生部'!$A$8:$A$1007=$B45)*('取込_厚生部'!$B$8:$B$1007=C$39)*('取込_厚生部'!$F$6:$CW$6>=ROUND($C$4*1440,0))*'取込_厚生部'!$F$8:$CW$1007)) -> 150 | D45: =IF(D$39="","",SUMPRODUCT(('取込_厚生部'!$A$8:$A$1007=$B45)*('取込_厚生部'!$B$8:$B$1007=D$39)*('取込_厚生部'!$F$6:$CW$6>=ROUND($C$4*1440,0))*'取込_厚生部'!$F$8:$CW$1007)) -> 149 | E45: =IF(E$39="","",SUMPRODUCT(('取込_厚生部'!$A$8:$A$1007=$B45)*('取込_厚生部'!$B$8:$B$1007=E$39)*('取込_厚生部'!$F$6:$CW$6>=ROUND($C$4*1440,0))*'取込_厚生部'!$F$8:$CW$1007)) -> 186 | F45: =IF(F$39="","",SUMPRODUCT(('取込_厚生部'!$A$8:$A$1007=$B45)*('取込_厚生部'!$B$8:$B$1007=F$39)*('取込_厚生部'!$F$6:$CW$6>=ROUND($C$4*1440,0))*'取込_厚生部'!$F$8:$CW$1007)) -> 216 | G45: =IF(G$39="","",SUMPRODUCT(('取込_厚生部'!$A$8:$A$1007=$B45)*('取込_厚生部'!$B$8:$B$1007=G$39)*('取込_厚生部'!$F$6:$CW$6>=ROUND($C$4*1440,0))*'取込_厚生部'!$F$8:$CW$1007)) -> 323 | H45: =IF(H$39="","",SUMPRODUCT(('取込_厚生部'!$A$8:$A$1007=$B45)*('取込_厚生部'!$B$8:$B$1007=H$39)*('取込_厚生部'!$F$6:$CW$6>=ROUND($C$4*1440,0))*'取込_厚生部'!$F$8:$CW$1007)) -> 171
...

Sheet 待ち・対応時間
B1: 待ち時間・対応時間・滞在時間
B3: 月 | C3: 全期間 | E3: 待ち＝発券→呼出、対応＝呼出→処理済み、滞在＝発券→処理済み（平均・分）
B5: 区ごとの比較
B6: 区 | C6: 来庁者数 | D6: 平均待ち(分) | E6: 15分以内率 | F6: 30分以内率 | G6: 平均対応(分) | H6: 平均滞在(分) | I6: 60分以上待った人
B7: 全区 | C7: =INDEX('データ'!D$759:D$875,MATCH($B7&"|"&$C$3,'データ'!$A$7:$A$123,0)) -> 762002 | D7: =IFERROR(INDEX('データ'!E$759:E$875,MATCH($B7&"|"&$C$3,'データ'!$A$7:$A$123,0))/INDEX('データ'!F$759:F$875,MATCH($B7&"|"&$C$3,'データ'!$A$7:$A$123,0))/60,0) -> 7.8387378 | E7: =IFERROR(SUM(INDEX('データ'!K$759:K$875,MATCH($B7&"|"&$C$3,'データ'!$A$7:$A$123,0)),INDEX('データ'!L$759:L$875,MATCH($B7&"|"&$C$3,'データ'!$A$7:$A$123,0)),INDEX('データ'!M$759:M$875,MATCH($B7&"|"&$C$3,'データ'!$A$7:$A$123,0)))/SUM(INDEX('データ'!K$759:K$875,MATCH($B7&"|"&$C$3,'データ'!$A$7:$A$123,0)),INDEX('データ'!L$759:L$875,MATCH($B7&"|"&$C$3,'データ'!$A$7:$A$123,0)),INDEX('データ'!M$759:M$875,MATCH($B7&"|"&$C$3,'データ'!$A$7:$A$123,0)),INDEX('データ'!N$759:N$875,MATCH($B7&"|"&$C$3,'データ'!$A$7:$A$123,0)),INDEX('データ'!O$759:O$875,MATCH($B7&"|"&$C$3,'データ'!$A$7:$A$123,0)),INDEX('データ'!P$759:P$875,MATCH($B7&"|"&$C$3,'データ'!$A$7:$A$123,0))),0) -> 0.84952364 | F7: =IFERROR(SUM(INDEX('データ'!K$759:K$875,MATCH($B7&"|"&$C$3,'データ'!$A$7:$A$123,0)),INDEX('データ'!L$759:L$875,MATCH($B7&"|"&$C$3,'データ'!$A$7:$A$123,0)),INDEX('データ'!M$759:M$875,MATCH($B7&"|"&$C$3,'データ'!$A$7:$A$123,0)),INDEX('データ'!N$759:N$875,MATCH($B7&"|"&$C$3,'データ'!$A$7:$A$123,0)))/SUM(INDEX('データ'!K$759:K$875,MATCH($B7&"|"&$C$3,'データ'!$A$7:$A$123,0)),INDEX('データ'!L$759:L$875,MATCH($B7&"|"&$C$3,'データ'!$A$7:$A$123,0)),INDEX('データ'!M$759:M$875,MATCH($B7&"|"&$C$3,'データ'!$A$7:$A$123,0)),INDEX('データ'!N$759:N$875,MATCH($B7&"|"&$C$3,'データ'!$A$7:$A$123,0)),INDEX('データ'!O$759:O$875,MATCH($B7&"|"&$C$3,'データ'!$A$7:$A$123,0)),INDEX('データ'!P$759:P$875,MATCH($B7&"|"&$C$3,'データ'!$A$7:$A$123,0))),0) -> 0.94102391 | G7: =IFERROR(INDEX('データ'!G$759:G$875,MATCH($B7&"|"&$C$3,'データ'!$A$7:$A$123,0))/INDEX('データ'!H$759:H$875,MATCH($B7&"|"&$C$3,'データ'!$A$7:$A$123,0))/60,0) -> 7.6375636 | H7: =IFERROR(INDEX('データ'!I$759:I$875,MATCH($B7&"|"&$C$3,'データ'!$A$7:$A$123,0))/INDEX('データ'!J$759:J$875,MATCH($B7&"|"&$C$3,'データ'!$A$7:$A$123,0))/60,0) -> 15.309631 | I7: =INDEX('データ'!P$759:P$875,MATCH($B7&"|"&$C$3,'データ'!$A$7:$A$123,0)) -> 12040
B8: 中区 | C8: =INDEX('データ'!D$759:D$875,MATCH($B8&"|"&$C$3,'データ'!$A$7:$A$123,0)) -> 143974 | D8: =IFERROR(INDEX('データ'!E$759:E$875,MATCH($B8&"|"&$C$3,'データ'!$A$7:$A$123,0))/INDEX('データ'!F$759:F$875,MATCH($B8&"|"&$C$3,'データ'!$A$7:$A$123,0))/60,0) -> 4.5271817 | E8: =IFERROR(SUM(INDEX('データ'!K$759:K$875,MATCH($B8&"|"&$C$3,'データ'!$A$7:$A$123,0)),INDEX('データ'!L$759:L$875,MATCH($B8&"|"&$C$3,'データ'!$A$7:$A$123,0)),INDEX('データ'!M$759:M$875,MATCH($B8&"|"&$C$3,'データ'!$A$7:$A$123,0)))/SUM(INDEX('データ'!K$759:K$875,MATCH($B8&"|"&$C$3,'データ'!$A$7:$A$123,0)),INDEX('データ'!L$759:L$875,MATCH($B8&"|"&$C$3,'データ'!$A$7:$A$123,0)),INDEX('データ'!M$759:M$875,MATCH($B8&"|"&$C$3,'データ'!$A$7:$A$123,0)),INDEX('データ'!N$759:N$875,MATCH($B8&"|"&$C$3,'データ'!$A$7:$A$123,0)),INDEX('データ'!O$759:O$875,MATCH($B8&"|"&$C$3,'データ'!$A$7:$A$123,0)),INDEX('データ'!P$759:P$875,MATCH($B8&"|"&$C$3,'データ'!$A$7:$A$123,0))),0) -> 0.92569726 | F8: =IFERROR(SUM(INDEX('データ'!K$759:K$875,MATCH($B8&"|"&$C$3,'データ'!$A$7:$A$123,0)),INDEX('データ'!L$759:L$875,MATCH($B8&"|"&$C$3,'データ'!$A$7:$A$123,0)),INDEX('データ'!M$759:M$875,MATCH($B8&"|"&$C$3,'データ'!$A$7:$A$123,0)),INDEX('データ'!N$759:N$875,MATCH($B8&"|"&$C$3,'データ'!$A$7:$A$123,0)))/SUM(INDEX('データ'!K$759:K$875,MATCH($B8&"|"&$C$3,'データ'!$A$7:$A$123,0)),INDEX('データ'!L$759:L$875,MATCH($B8&"|"&$C$3,'データ'!$A$7:$A$123,0)),INDEX('データ'!M$759:M$875,MATCH($B8&"|"&$C$3,'データ'!$A$7:$A$123,0)),INDEX('データ'!N$759:N$875,MATCH($B8&"|"&$C$3,'データ'!$A$7:$A$123,0)),INDEX('データ'!O$759:O$875,MATCH($B8&"|"&$C$3,'データ'!$A$7:$A$123,0)),INDEX('データ'!P$759:P$875,MATCH($B8&"|"&$C$3,'データ'!$A$7:$A$123,0))),0) -> 0.98299564 | G8: =IFERROR(INDEX('データ'!G$759:G$875,MATCH($B8&"|"&$C$3,'データ'!$A$7:$A$123,0))/INDEX('データ'!H$759:H$875,MATCH($B8&"|"&$C$3,'データ'!$A$7:$A$123,0))/60,0) -> 7.869897 | H8: =IFERROR(INDEX('データ'!I$759:I$875,MATCH($B8&"|"&$C$3,'データ'!$A$7:$A$123,0))/INDEX('データ'!J$759:J$875,MATCH($B8&"|"&$C$3,'データ'!$A$7:$A$123,0))/60,0) -> 12.372074 | I8: =INDEX('データ'!P$759:P$875,MATCH($B8&"|"&$C$3,'データ'!$A$7:$A$123,0)) -> 455
B9: 東区 | C9: =INDEX('データ'!D$759:D$875,MATCH($B9&"|"&$C$3,'データ'!$A$7:$A$123,0)) -> 81818 | D9: =IFERROR(INDEX('データ'!E$759:E$875,MATCH($B9&"|"&$C$3,'データ'!$A$7:$A$123,0))/INDEX('データ'!F$759:F$875,MATCH($B9&"|"&$C$3,'データ'!$A$7:$A$123,0))/60,0) -> 4.3975001 | E9: =IFERROR(SUM(INDEX('データ'!K$759:K$875,MATCH($B9&"|"&$C$3,'データ'!$A$7:$A$123,0)),INDEX('データ'!L$759:L$875,MATCH($B9&"|"&$C$3,'データ'!$A$7:$A$123,0)),INDEX('データ'!M$759:M$875,MATCH($B9&"|"&$C$3,'データ'!$A$7:$A$123,0)))/SUM(INDEX('データ'!K$759:K$875,MATCH($B9&"|"&$C$3,'データ'!$A$7:$A$123,0)),INDEX('データ'!L$759:L$875,MATCH($B9&"|"&$C$3,'データ'!$A$7:$A$123,0)),INDEX('データ'!M$759:M$875,MATCH($B9&"|"&$C$3,'データ'!$A$7:$A$123,0)),INDEX('データ'!N$759:N$875,MATCH($B9&"|"&$C$3,'データ'!$A$7:$A$123,0)),INDEX('データ'!O$759:O$875,MATCH($B9&"|"&$C$3,'データ'!$A$7:$A$123,0)),INDEX('データ'!P$759:P$875,MATCH($B9&"|"&$C$3,'データ'!$A$7:$A$123,0))),0) -> 0.94102797 | F9: =IFERROR(SUM(INDEX('データ'!K$759:K$875,MATCH($B9&"|"&$C$3,'データ'!$A$7:$A$123,0)),INDEX('データ'!L$759:L$875,MATCH($B9&"|"&$C$3,'データ'!$A$7:$A$123,0)),INDEX('データ'!M$759:M$875,MATCH($B9&"|"&$C$3,'データ'!$A$7:$A$123,0)),INDEX('データ'!N$759:N$875,MATCH($B9&"|"&$C$3,'データ'!$A$7:$A$123,0)))/SUM(INDEX('データ'!K$759:K$875,MATCH($B9&"|"&$C$3,'データ'!$A$7:$A$123,0)),INDEX('データ'!L$759:L$875,MATCH($B9&"|"&$C$3,'データ'!$A$7:$A$123,0)),INDEX('データ'!M$759:M$875,MATCH($B9&"|"&$C$3,'データ'!$A$7:$A$123,0)),INDEX('データ'!N$759:N$875,MATCH($B9&"|"&$C$3,'データ'!$A$7:$A$123,0)),INDEX('データ'!O$759:O$875,MATCH($B9&"|"&$C$3,'データ'!$A$7:$A$123,0)),INDEX('データ'!P$759:P$875,MATCH($B9&"|"&$C$3,'データ'!$A$7:$A$123,0))),0) -> 0.98189907 | G9: =IFERROR(INDEX('データ'!G$759:G$875,MATCH($B9&"|"&$C$3,'データ'!$A$7:$A$123,0))/INDEX('データ'!H$759:H$875,MATCH($B9&"|"&$C$3,'データ'!$A$7:$A$123,0))/60,0) -> 8.644546 | H9: =IFERROR(INDEX('データ'!I$759:I$875,MATCH($B9&"|"&$C$3,'データ'!$A$7:$A$123,0))/INDEX('データ'!J$759:J$875,MATCH($B9&"|"&$C$3,'データ'!$A$7:$A$123,0))/60,0) -> 13.029044 | I9: =INDEX('データ'!P$759:P$875,MATCH($B9&"|"&$C$3,'データ'!$A$7:$A$123,0)) -> 465
B10: 南区 | C10: =INDEX('データ'!D$759:D$875,MATCH($B10&"|"&$C$3,'データ'!$A$7:$A$123,0)) -> 115887 | D10: =IFERROR(INDEX('データ'!E$759:E$875,MATCH($B10&"|"&$C$3,'データ'!$A$7:$A$123,0))/INDEX('データ'!F$759:F$875,MATCH($B10&"|"&$C$3,'データ'!$A$7:$A$123,0))/60,0) -> 14.264511 | E10: =IFERROR(SUM(INDEX('データ'!K$759:K$875,MATCH($B10&"|"&$C$3,'データ'!$A$7:$A$123,0)),INDEX('データ'!L$759:L$875,MATCH($B10&"|"&$C$3,'データ'!$A$7:$A$123,0)),INDEX('データ'!M$759:M$875,MATCH($B10&"|"&$C$3,'データ'!$A$7:$A$123,0)))/SUM(INDEX('データ'!K$759:K$875,MATCH($B10&"|"&$C$3,'データ'!$A$7:$A$123,0)),INDEX('データ'!L$759:L$875,MATCH($B10&"|"&$C$3,'データ'!$A$7:$A$123,0)),INDEX('データ'!M$759:M$875,MATCH($B10&"|"&$C$3,'データ'!$A$7:$A$123,0)),INDEX('データ'!N$759:N$875,MATCH($B10&"|"&$C$3,'データ'!$A$7:$A$123,0)),INDEX('データ'!O$759:O$875,MATCH($B10&"|"&$C$3,'データ'!$A$7:$A$123,0)),INDEX('データ'!P$759:P$875,MATCH($B10&"|"&$C$3,'データ'!$A$7:$A$123,0))),0) -> 0.71184381 | F10: =IFERROR(SUM(INDEX('データ'!K$759:K$875,MATCH($B10&"|"&$C$3,'データ'!$A$7:$A$123,0)),INDEX('データ'!L$759:L$875,MATCH($B10&"|"&$C$3,'データ'!$A$7:$A$123,0)),INDEX('データ'!M$759:M$875,MATCH($B10&"|"&$C$3,'データ'!$A$7:$A$123,0)),INDEX('データ'!N$759:N$875,MATCH($B10&"|"&$C$3,'データ'!$A$7:$A$123,0)))/SUM(INDEX('データ'!K$759:K$875,MATCH($B10&"|"&$C$3,'データ'!$A$7:$A$123,0)),INDEX('データ'!L$759:L$875,MATCH($B10&"|"&$C$3,'データ'!$A$7:$A$123,0)),INDEX('データ'!M$759:M$875,MATCH($B10&"|"&$C$3,'データ'!$A$7:$A$123,0)),INDEX('データ'!N$759:N$875,MATCH($B10&"|"&$C$3,'データ'!$A$7:$A$123,0)),INDEX('データ'!O$759:O$875,MATCH($B10&"|"&$C$3,'データ'!$A$7:$A$123,0)),INDEX('データ'!P$759:P$875,MATCH($B10&"|"&$C$3,'データ'!$A$7:$A$123,0))),0) -> 0.84992751 | G10: =IFERROR(INDEX('データ'!G$759:G$875,MATCH($B10&"|"&$C$3,'データ'!$A$7:$A$123,0))/INDEX('データ'!H$759:H$875,MATCH($B10&"|"&$C$3,'データ'!$A$7:$A$123,0))/60,0) -> 6.3850113 | H10: =IFERROR(INDEX('データ'!I$759:I$875,MATCH($B10&"|"&$C$3,'データ'!$A$7:$A$123,0))/INDEX('データ'!J$759:J$875,MATCH($B10&"|"&$C$3,'データ'!$A$7:$A$123,0))/60,0) -> 20.469119 | I10: =INDEX('データ'!P$759:P$875,MATCH($B10&"|"&$C$3,'データ'!$A$7:$A$123,0)) -> 5875
B11: 西区 | C11: =INDEX('データ'!D$759:D$875,MATCH($B11&"|"&$C$3,'データ'!$A$7:$A$123,0)) -> 141243 | D11: =IFERROR(INDEX('データ'!E$759:E$875,MATCH($B11&"|"&$C$3,'データ'!$A$7:$A$123,0))/INDEX('データ'!F$759:F$875,MATCH($B11&"|"&$C$3,'データ'!$A$7:$A$123,0))/60,0) -> 8.7043545 | E11: =IFERROR(SUM(INDEX('データ'!K$759:K$875,MATCH($B11&"|"&$C$3,'データ'!$A$7:$A$123,0)),INDEX('データ'!L$759:L$875,MATCH($B11&"|"&$C$3,'データ'!$A$7:$A$123,0)),INDEX('データ'!M$759:M$875,MATCH($B11&"|"&$C$3,'データ'!$A$7:$A$123,0)))/SUM(INDEX('データ'!K$759:K$875,MATCH($B11&"|"&$C$3,'データ'!$A$7:$A$123,0)),INDEX('データ'!L$759:L$875,MATCH($B11&"|"&$C$3,'データ'!$A$7:$A$123,0)),INDEX('データ'!M$759:M$875,MATCH($B11&"|"&$C$3,'データ'!$A$7:$A$123,0)),INDEX('データ'!N$759:N$875,MATCH($B11&"|"&$C$3,'データ'!$A$7:$A$123,0)),INDEX('データ'!O$759:O$875,MATCH($B11&"|"&$C$3,'データ'!$A$7:$A$123,0)),INDEX('データ'!P$759:P$875,MATCH($B11&"|"&$C$3,'データ'!$A$7:$A$123,0))),0) -> 0.81311601 | F11: =IFERROR(SUM(INDEX('データ'!K$759:K$875,MATCH($B11&"|"&$C$3,'データ'!$A$7:$A$123,0)),INDEX('データ'!L$759:L$875,MATCH($B11&"|"&$C$3,'データ'!$A$7:$A$123,0)),INDEX('データ'!M$759:M$875,MATCH($B11&"|"&$C$3,'データ'!$A$7:$A$123,0)),INDEX('データ'!N$759:N$875,MATCH($B11&"|"&$C$3,'データ'!$A$7:$A$123,0)))/SUM(INDEX('データ'!K$759:K$875,MATCH($B11&"|"&$C$3,'データ'!$A$7:$A$123,0)),INDEX('データ'!L$759:L$875,MATCH($B11&"|"&$C$3,'データ'!$A$7:$A$123,0)),INDEX('データ'!M$759:M$875,MATCH($B11&"|"&$C$3,'データ'!$A$7:$A$123,0)),INDEX('データ'!N$759:N$875,MATCH($B11&"|"&$C$3,'データ'!$A$7:$A$123,0)),INDEX('データ'!O$759:O$875,MATCH($B11&"|"&$C$3,'データ'!$A$7:$A$123,0)),INDEX('データ'!P$759:P$875,MATCH($B11&"|"&$C$3,'データ'!$A$7:$A$123,0))),0) -> 0.93121971 | G11: =IFERROR(INDEX('データ'!G$759:G$875,MATCH($B11&"|"&$C$3,'データ'!$A$7:$A$123,0))/INDEX('データ'!H$759:H$875,MATCH($B11&"|"&$C$3,'データ'!$A$7:$A$123,0))/60,0) -> 6.1987521 | H11: =IFERROR(INDEX('データ'!I$759:I$875,MATCH($B11&"|"&$C$3,'データ'!$A$7:$A$123,0))/INDEX('データ'!J$759:J$875,MATCH($B11&"|"&$C$3,'データ'!$A$7:$A$123,0))/60,0) -> 14.873418 | I11: =INDEX('データ'!P$759:P$875,MATCH($B11&"|"&$C$3,'データ'!$A$7:$A$123,0)) -> 1566
B12: 安佐南区 | C12: =INDEX('データ'!D$759:D$875,MATCH($B12&"|"&$C$3,'データ'!$A$7:$A$123,0)) -> 88181 | D12: =IFERROR(INDEX('データ'!E$759:E$875,MATCH($B12&"|"&$C$3,'データ'!$A$7:$A$123,0))/INDEX('データ'!F$759:F$875,MATCH($B12&"|"&$C$3,'データ'!$A$7:$A$123,0))/60,0) -> 13.970985 | E12: =IFERROR(SUM(INDEX('データ'!K$759:K$875,MATCH($B12&"|"&$C$3,'データ'!$A$7:$A$123,0)),INDEX('データ'!L$759:L$875,MATCH($B12&"|"&$C$3,'データ'!$A$7:$A$123,0)),INDEX('データ'!M$759:M$875,MATCH($B12&"|"&$C$3,'データ'!$A$7:$A$123,0)))/SUM(INDEX('データ'!K$759:K$875,MATCH($B12&"|"&$C$3,'データ'!$A$7:$A$123,0)),INDEX('データ'!L$759:L$875,MATCH($B12&"|"&$C$3,'データ'!$A$7:$A$123,0)),INDEX('データ'!M$759:M$875,MATCH($B12&"|"&$C$3,'データ'!$A$7:$A$123,0)),INDEX('データ'!N$759:N$875,MATCH($B12&"|"&$C$3,'データ'!$A$7:$A$123,0)),INDEX('データ'!O$759:O$875,MATCH($B12&"|"&$C$3,'データ'!$A$7:$A$123,0)),INDEX('データ'!P$759:P$875,MATCH($B12&"|"&$C$3,'データ'!$A$7:$A$123,0))),0) -> 0.69754357 | F12: =IFERROR(SUM(INDEX('データ'!K$759:K$875,MATCH($B12&"|"&$C$3,'データ'!$A$7:$A$123,0)),INDEX('データ'!L$759:L$875,MATCH($B12&"|"&$C$3,'データ'!$A$7:$A$123,0)),INDEX('データ'!M$759:M$875,MATCH($B12&"|"&$C$3,'データ'!$A$7:$A$123,0)),INDEX('データ'!N$759:N$875,MATCH($B12&"|"&$C$3,'データ'!$A$7:$A$123,0)))/SUM(INDEX('データ'!K$759:K$875,MATCH($B12&"|"&$C$3,'データ'!$A$7:$A$123,0)),INDEX('データ'!L$759:L$875,MATCH($B12&"|"&$C$3,'データ'!$A$7:$A$123,0)),INDEX('データ'!M$759:M$875,MATCH($B12&"|"&$C$3,'データ'!$A$7:$A$123,0)),INDEX('データ'!N$759:N$875,MATCH($B12&"|"&$C$3,'データ'!$A$7:$A$123,0)),INDEX('データ'!O$759:O$875,MATCH($B12&"|"&$C$3,'データ'!$A$7:$A$123,0)),INDEX('データ'!P$759:P$875,MATCH($B12&"|"&$C$3,'データ'!$A$7:$A$123,0))),0) -> 0.86187732 | G12: =IFERROR(INDEX('データ'!G$759:G$875,MATCH($B12&"|"&$C$3,'データ'!$A$7:$A$123,0))/INDEX('データ'!H$759:H$875,MATCH($B12&"|"&$C$3,'データ'!$A$7:$A$123,0))/60,0) -> 7.2427846 | H12: =IFERROR(INDEX('データ'!I$759:I$875,MATCH($B12&"|"&$C$3,'データ'!$A$7:$A$123,0))/INDEX('データ'!J$759:J$875,MATCH($B12&"|"&$C$3,'データ'!$A$7:$A$123,0))/60,0) -> 21.02121 | I12: =INDEX('データ'!P$759:P$875,MATCH($B12&"|"&$C$3,'データ'!$A$7:$A$123,0)) -> 3352
B13: 安佐北区 | C13: =INDEX('データ'!D$759:D$875,MATCH($B13&"|"&$C$3,'データ'!$A$7:$A$123,0)) -> 48568 | D13: =IFERROR(INDEX('データ'!E$759:E$875,MATCH($B13&"|"&$C$3,'データ'!$A$7:$A$123,0))/INDEX('データ'!F$759:F$875,MATCH($B13&"|"&$C$3,'データ'!$A$7:$A$123,0))/60,0) -> 3.4987133 | E13: =IFERROR(SUM(INDEX('データ'!K$759:K$875,MATCH($B13&"|"&$C$3,'データ'!$A$7:$A$123,0)),INDEX('データ'!L$759:L$875,MATCH($B13&"|"&$C$3,'データ'!$A$7:$A$123,0)),INDEX('データ'!M$759:M$875,MATCH($B13&"|"&$C$3,'データ'!$A$7:$A$123,0)))/SUM(INDEX('データ'!K$759:K$875,MATCH($B13&"|"&$C$3,'データ'!$A$7:$A$123,0)),INDEX('データ'!L$759:L$875,MATCH($B13&"|"&$C$3,'データ'!$A$7:$A$123,0)),INDEX('データ'!M$759:M$875,MATCH($B13&"|"&$C$3,'データ'!$A$7:$A$123,0)),INDEX('データ'!N$759:N$875,MATCH($B13&"|"&$C$3,'データ'!$A$7:$A$123,0)),INDEX('データ'!O$759:O$875,MATCH($B13&"|"&$C$3,'データ'!$A$7:$A$123,0)),INDEX('データ'!P$759:P$875,MATCH($B13&"|"&$C$3,'データ'!$A$7:$A$123,0))),0) -> 0.9677506 | F13: =IFERROR(SUM(INDEX('データ'!K$759:K$875,MATCH($B13&"|"&$C$3,'データ'!$A$7:$A$123,0)),INDEX('データ'!L$759:L$875,MATCH($B13&"|"&$C$3,'データ'!$A$7:$A$123,0)),INDEX('データ'!M$759:M$875,MATCH($B13&"|"&$C$3,'データ'!$A$7:$A$123,0)),INDEX('データ'!N$759:N$875,MATCH($B13&"|"&$C$3,'データ'!$A$7:$A$123,0)))/SUM(INDEX('データ'!K$759:K$875,MATCH($B13&"|"&$C$3,'データ'!$A$7:$A$123,0)),INDEX('データ'!L$759:L$875,MATCH($B13&"|"&$C$3,'データ'!$A$7:$A$123,0)),INDEX('データ'!M$759:M$875,MATCH($B13&"|"&$C$3,'データ'!$A$7:$A$123,0)),INDEX('データ'!N$759:N$875,MATCH($B13&"|"&$C$3,'データ'!$A$7:$A$123,0)),INDEX('データ'!O$759:O$875,MATCH($B13&"|"&$C$3,'データ'!$A$7:$A$123,0)),INDEX('データ'!P$759:P$875,MATCH($B13&"|"&$C$3,'データ'!$A$7:$A$123,0))),0) -> 0.99750021 | G13: =IFERROR(INDEX('データ'!G$759:G$875,MATCH($B13&"|"&$C$3,'データ'!$A$7:$A$123,0))/INDEX('データ'!H$759:H$875,MATCH($B13&"|"&$C$3,'データ'!$A$7:$A$123,0))/60,0) -> 8.3550143 | H13: =IFERROR(INDEX('データ'!I$759:I$875,MATCH($B13&"|"&$C$3,'データ'!$A$7:$A$123,0))/INDEX('データ'!J$759:J$875,MATCH($B13&"|"&$C$3,'データ'!$A$7:$A$123,0))/60,0) -> 11.859127 | I13: =INDEX('データ'!P$759:P$875,MATCH($B13&"|"&$C$3,'データ'!$A$7:$A$123,0)) -> 19
B14: 安芸区 | C14: =INDEX('データ'!D$759:D$875,MATCH($B14&"|"&$C$3,'データ'!$A$7:$A$123,0)) -> 37567 | D14: =IFERROR(INDEX('データ'!E$759:E$875,MATCH($B14&"|"&$C$3,'データ'!$A$7:$A$123,0))/INDEX('データ'!F$759:F$875,MATCH($B14&"|"&$C$3,'データ'!$A$7:$A$123,0))/60,0) -> 2.3776665 | E14: =IFERROR(SUM(INDEX('データ'!K$759:K$875,MATCH($B14&"|"&$C$3,'データ'!$A$7:$A$123,0)),INDEX('データ'!L$759:L$875,MATCH($B14&"|"&$C$3,'データ'!$A$7:$A$123,0)),INDEX('データ'!M$759:M$875,MATCH($B14&"|"&$C$3,'データ'!$A$7:$A$123,0)))/SUM(INDEX('データ'!K$759:K$875,MATCH($B14&"|"&$C$3,'データ'!$A$7:$A$123,0)),INDEX('データ'!L$759:L$875,MATCH($B14&"|"&$C$3,'データ'!$A$7:$A$123,0)),INDEX('データ'!M$759:M$875,MATCH($B14&"|"&$C$3,'データ'!$A$7:$A$123,0)),INDEX('データ'!N$759:N$875,MATCH($B14&"|"&$C$3,'データ'!$A$7:$A$123,0)),INDEX('データ'!O$759:O$875,MATCH($B14&"|"&$C$3,'データ'!$A$7:$A$123,0)),INDEX('データ'!P$759:P$875,MATCH($B14&"|"&$C$3,'データ'!$A$7:$A$123,0))),0) -> 0.97299393 | F14: =IFERROR(SUM(INDEX('データ'!K$759:K$875,MATCH($B14&"|"&$C$3,'データ'!$A$7:$A$123,0)),INDEX('データ'!L$759:L$875,MATCH($B14&"|"&$C$3,'データ'!$A$7:$A$123,0)),INDEX('データ'!M$759:M$875,MATCH($B14&"|"&$C$3,'データ'!$A$7:$A$123,0)),INDEX('データ'!N$759:N$875,MATCH($B14&"|"&$C$3,'データ'!$A$7:$A$123,0)))/SUM(INDEX('データ'!K$759:K$875,MATCH($B14&"|"&$C$3,'データ'!$A$7:$A$123,0)),INDEX('データ'!L$759:L$875,MATCH($B14&"|"&$C$3,'データ'!$A$7:$A$123,0)),INDEX('データ'!M$759:M$875,MATCH($B14&"|"&$C$3,'データ'!$A$7:$A$123,0)),INDEX('データ'!N$759:N$875,MATCH($B14&"|"&$C$3,'データ'!$A$7:$A$123,0)),INDEX('データ'!O$759:O$875,MATCH($B14&"|"&$C$3,'データ'!$A$7:$A$123,0)),INDEX('データ'!P$759:P$875,MATCH($B14&"|"&$C$3,'データ'!$A$7:$A$123,0))),0) -> 0.99441162 | G14: =IFERROR(INDEX('データ'!G$759:G$875,MATCH($B14&"|"&$C$3,'データ'!$A$7:$A$123,0))/INDEX('データ'!H$759:H$875,MATCH($B14&"|"&$C$3,'データ'!$A$7:$A$123,0))/60,0) -> 14.894857 | H14: =IFERROR(INDEX('データ'!I$759:I$875,MATCH($B14&"|"&$C$3,'データ'!$A$7:$A$123,0))/INDEX('データ'!J$759:J$875,MATCH($B14&"|"&$C$3,'データ'!$A$7:$A$123,0))/60,0) -> 17.242039 | I14: =INDEX('データ'!P$759:P$875,MATCH($B14&"|"&$C$3,'データ'!$A$7:$A$123,0)) -> 60
B15: 佐伯区 | C15: =INDEX('データ'!D$759:D$875,MATCH($B15&"|"&$C$3,'データ'!$A$7:$A$123,0)) -> 104764 | D15: =IFERROR(INDEX('データ'!E$759:E$875,MATCH($B15&"|"&$C$3,'データ'!$A$7:$A$123,0))/INDEX('データ'!F$759:F$875,MATCH($B15&"|"&$C$3,'データ'!$A$7:$A$123,0))/60,0) -> 5.6626135 | E15: =IFERROR(SUM(INDEX('データ'!K$759:K$875,MATCH($B15&"|"&$C$3,'データ'!$A$7:$A$123,0)),INDEX('データ'!L$759:L$875,MATCH($B15&"|"&$C$3,'データ'!$A$7:$A$123,0)),INDEX('データ'!M$759:M$875,MATCH($B15&"|"&$C$3,'データ'!$A$7:$A$123,0)))/SUM(INDEX('データ'!K$759:K$875,MATCH($B15&"|"&$C$3,'データ'!$A$7:$A$123,0)),INDEX('データ'!L$759:L$875,MATCH($B15&"|"&$C$3,'データ'!$A$7:$A$123,0)),INDEX('データ'!M$759:M$875,MATCH($B15&"|"&$C$3,'データ'!$A$7:$A$123,0)),INDEX('データ'!N$759:N$875,MATCH($B15&"|"&$C$3,'データ'!$A$7:$A$123,0)),INDEX('データ'!O$759:O$875,MATCH($B15&"|"&$C$3,'データ'!$A$7:$A$123,0)),INDEX('データ'!P$759:P$875,MATCH($B15&"|"&$C$3,'データ'!$A$7:$A$123,0))),0) -> 0.9024073 | F15: =IFERROR(SUM(INDEX('データ'!K$759:K$875,MATCH($B15&"|"&$C$3,'データ'!$A$7:$A$123,0)),INDEX('データ'!L$759:L$875,MATCH($B15&"|"&$C$3,'データ'!$A$7:$A$123,0)),INDEX('データ'!M$759:M$875,MATCH($B15&"|"&$C$3,'データ'!$A$7:$A$123,0)),INDEX('データ'!N$759:N$875,MATCH($B15&"|"&$C$3,'データ'!$A$7:$A$123,0)))/SUM(INDEX('データ'!K$759:K$875,MATCH($B15&"|"&$C$3,'データ'!$A$7:$A$123,0)),INDEX('データ'!L$759:L$875,MATCH($B15&"|"&$C$3,'データ'!$A$7:$A$123,0)),INDEX('データ'!M$759:M$875,MATCH($B15&"|"&$C$3,'データ'!$A$7:$A$123,0)),INDEX('データ'!N$759:N$875,MATCH($B15&"|"&$C$3,'データ'!$A$7:$A$123,0)),INDEX('データ'!O$759:O$875,MATCH($B15&"|"&$C$3,'データ'!$A$7:$A$123,0)),INDEX('データ'!P$759:P$875,MATCH($B15&"|"&$C$3,'データ'!$A$7:$A$123,0))),0) -> 0.98597894 | G15: =IFERROR(INDEX('データ'!G$759:G$875,MATCH($B15&"|"&$C$3,'データ'!$A$7:$A$123,0))/INDEX('データ'!H$759:H$875,MATCH($B15&"|"&$C$3,'データ'!$A$7:$A$123,0))/60,0) -> 7.1985816 | H15: =IFERROR(INDEX('データ'!I$759:I$875,MATCH($B15&"|"&$C$3,'データ'!$A$7:$A$123,0))/INDEX('データ'!J$759:J$875,MATCH($B15&"|"&$C$3,'データ'!$A$7:$A$123,0))/60,0) -> 12.878106 | I15: =INDEX('データ'!P$759:P$875,MATCH($B15&"|"&$C$3,'データ'!$A$7:$A$123,0)) -> 248
B18: 待ち＋対応（区別・平均分） | L18: 待ち時間の分布（区別）
L20: 区 | M20: 5分未満 | N20: 5〜10分 | O20: 10〜15分 | P20: 15〜30分 | Q20: 30〜60分 | R20: 60分以上
L21: 全区 | M21: =IFERROR(INDEX('データ'!K$759:K$875,MATCH($L21&"|"&$C$3,'データ'!$A$7:$A$123,0))/SUM(INDEX('データ'!K$759:K$875,MATCH($L21&"|"&$C$3,'データ'!$A$7:$A$123,0)),INDEX('データ'!L$759:L$875,MATCH($L21&"|"&$C$3,'データ'!$A$7:$A$123,0)),INDEX('データ'!M$759:M$875,MATCH($L21&"|"&$C$3,'データ'!$A$7:$A$123,0)),INDEX('データ'!N$759:N$875,MATCH($L21&"|"&$C$3,'データ'!$A$7:$A$123,0)),INDEX('データ'!O$759:O$875,MATCH($L21&"|"&$C$3,'データ'!$A$7:$A$123,0)),INDEX('データ'!P$759:P$875,MATCH($L21&"|"&$C$3,'データ'!$A$7:$A$123,0))),0) -> 0.64020554 | N21: =IFERROR(INDEX('データ'!L$759:L$875,MATCH($L21&"|"&$C$3,'データ'!$A$7:$A$123,0))/SUM(INDEX('データ'!K$759:K$875,MATCH($L21&"|"&$C$3,'データ'!$A$7:$A$123,0)),INDEX('データ'!L$759:L$875,MATCH($L21&"|"&$C$3,'データ'!$A$7:$A$123,0)),INDEX('データ'!M$759:M$875,MATCH($L21&"|"&$C$3,'データ'!$A$7:$A$123,0)),INDEX('データ'!N$759:N$875,MATCH($L21&"|"&$C$3,'データ'!$A$7:$A$123,0)),INDEX('データ'!O$759:O$875,MATCH($L21&"|"&$C$3,'データ'!$A$7:$A$123,0)),INDEX('データ'!P$759:P$875,MATCH($L21&"|"&$C$3,'データ'!$A$7:$A$123,0))),0) -> 0.13594375 | O21: =IFERROR(INDEX('データ'!M$759:M$875,MATCH($L21&"|"&$C$3,'データ'!$A$7:$A$123,0))/SUM(INDEX('データ'!K$759:K$875,MATCH($L21&"|"&$C$3,'データ'!$A$7:$A$123,0)),INDEX('データ'!L$759:L$875,MATCH($L21&"|"&$C$3,'データ'!$A$7:$A$123,0)),INDEX('データ'!M$759:M$875,MATCH($L21&"|"&$C$3,'データ'!$A$7:$A$123,0)),INDEX('データ'!N$759:N$875,MATCH($L21&"|"&$C$3,'データ'!$A$7:$A$123,0)),INDEX('データ'!O$759:O$875,MATCH($L21&"|"&$C$3,'データ'!$A$7:$A$123,0)),INDEX('データ'!P$759:P$875,MATCH($L21&"|"&$C$3,'データ'!$A$7:$A$123,0))),0) -> 0.073374351 | P21: =IFERROR(INDEX('データ'!N$759:N$875,MATCH($L21&"|"&$C$3,'データ'!$A$7:$A$123,0))/SUM(INDEX('データ'!K$759:K$875,MATCH($L21&"|"&$C$3,'データ'!$A$7:$A$123,0)),INDEX('データ'!L$759:L$875,MATCH($L21&"|"&$C$3,'データ'!$A$7:$A$123,0)),INDEX('データ'!M$759:M$875,MATCH($L21&"|"&$C$3,'データ'!$A$7:$A$123,0)),INDEX('データ'!N$759:N$875,MATCH($L21&"|"&$C$3,'データ'!$A$7:$A$123,0)),INDEX('データ'!O$759:O$875,MATCH($L21&"|"&$C$3,'データ'!$A$7:$A$123,0)),INDEX('データ'!P$759:P$875,MATCH($L21&"|"&$C$3,'データ'!$A$7:$A$123,0))),0) -> 0.091500272 | Q21: =IFERROR(INDEX('データ'!O$759:O$875,MATCH($L21&"|"&$C$3,'データ'!$A$7:$A$123,0))/SUM(INDEX('データ'!K$759:K$875,MATCH($L21&"|"&$C$3,'データ'!$A$7:$A$123,0)),INDEX('データ'!L$759:L$875,MATCH($L21&"|"&$C$3,'データ'!$A$7:$A$123,0)),INDEX('データ'!M$759:M$875,MATCH($L21&"|"&$C$3,'データ'!$A$7:$A$123,0)),INDEX('データ'!N$759:N$875,MATCH($L21&"|"&$C$3,'データ'!$A$7:$A$123,0)),INDEX('データ'!O$759:O$875,MATCH($L21&"|"&$C$3,'データ'!$A$7:$A$123,0)),INDEX('データ'!P$759:P$875,MATCH($L21&"|"&$C$3,'データ'!$A$7:$A$123,0))),0) -> 0.043117063 | R21: =IFERROR(INDEX('データ'!P$759:P$875,MATCH($L21&"|"&$C$3,'データ'!$A$7:$A$123,0))/SUM(INDEX('データ'!K$759:K$875,MATCH($L21&"|"&$C$3,'データ'!$A$7:$A$123,0)),INDEX('データ'!L$759:L$875,MATCH($L21&"|"&$C$3,'データ'!$A$7:$A$123,0)),INDEX('データ'!M$759:M$875,MATCH($L21&"|"&$C$3,'データ'!$A$7:$A$123,0)),INDEX('データ'!N$759:N$875,MATCH($L21&"|"&$C$3,'データ'!$A$7:$A$123,0)),INDEX('データ'!O$759:O$875,MATCH($L21&"|"&$C$3,'データ'!$A$7:$A$123,0)),INDEX('データ'!P$759:P$875,MATCH($L21&"|"&$C$3,'データ'!$A$7:$A$123,0))),0) -> 0.015859029
L22: 中区 | M22: =IFERROR(INDEX('データ'!K$759:K$875,MATCH($L22&"|"&$C$3,'データ'!$A$7:$A$123,0))/SUM(INDEX('データ'!K$759:K$875,MATCH($L22&"|"&$C$3,'データ'!$A$7:$A$123,0)),INDEX('データ'!L$759:L$875,MATCH($L22&"|"&$C$3,'データ'!$A$7:$A$123,0)),INDEX('データ'!M$759:M$875,MATCH($L22&"|"&$C$3,'データ'!$A$7:$A$123,0)),INDEX('データ'!N$759:N$875,MATCH($L22&"|"&$C$3,'データ'!$A$7:$A$123,0)),INDEX('データ'!O$759:O$875,MATCH($L22&"|"&$C$3,'データ'!$A$7:$A$123,0)),INDEX('データ'!P$759:P$875,MATCH($L22&"|"&$C$3,'データ'!$A$7:$A$123,0))),0) -> 0.7455401 | N22: =IFERROR(INDEX('データ'!L$759:L$875,MATCH($L22&"|"&$C$3,'データ'!$A$7:$A$123,0))/SUM(INDEX('データ'!K$759:K$875,MATCH($L22&"|"&$C$3,'データ'!$A$7:$A$123,0)),INDEX('データ'!L$759:L$875,MATCH($L22&"|"&$C$3,'データ'!$A$7:$A$123,0)),INDEX('データ'!M$759:M$875,MATCH($L22&"|"&$C$3,'データ'!$A$7:$A$123,0)),INDEX('データ'!N$759:N$875,MATCH($L22&"|"&$C$3,'データ'!$A$7:$A$123,0)),INDEX('データ'!O$759:O$875,MATCH($L22&"|"&$C$3,'データ'!$A$7:$A$123,0)),INDEX('データ'!P$759:P$875,MATCH($L22&"|"&$C$3,'データ'!$A$7:$A$123,0))),0) -> 0.12257342 | O22: =IFERROR(INDEX('データ'!M$759:M$875,MATCH($L22&"|"&$C$3,'データ'!$A$7:$A$123,0))/SUM(INDEX('データ'!K$759:K$875,MATCH($L22&"|"&$C$3,'データ'!$A$7:$A$123,0)),INDEX('データ'!L$759:L$875,MATCH($L22&"|"&$C$3,'データ'!$A$7:$A$123,0)),INDEX('データ'!M$759:M$875,MATCH($L22&"|"&$C$3,'データ'!$A$7:$A$123,0)),INDEX('データ'!N$759:N$875,MATCH($L22&"|"&$C$3,'データ'!$A$7:$A$123,0)),INDEX('データ'!O$759:O$875,MATCH($L22&"|"&$C$3,'データ'!$A$7:$A$123,0)),INDEX('データ'!P$759:P$875,MATCH($L22&"|"&$C$3,'データ'!$A$7:$A$123,0))),0) -> 0.057583752 | P22: =IFERROR(INDEX('データ'!N$759:N$875,MATCH($L22&"|"&$C$3,'データ'!$A$7:$A$123,0))/SUM(INDEX('データ'!K$759:K$875,MATCH($L22&"|"&$C$3,'データ'!$A$7:$A$123,0)),INDEX('データ'!L$759:L$875,MATCH($L22&"|"&$C$3,'データ'!$A$7:$A$123,0)),INDEX('データ'!M$759:M$875,MATCH($L22&"|"&$C$3,'データ'!$A$7:$A$123,0)),INDEX('データ'!N$759:N$875,MATCH($L22&"|"&$C$3,'データ'!$A$7:$A$123,0)),INDEX('データ'!O$759:O$875,MATCH($L22&"|"&$C$3,'データ'!$A$7:$A$123,0)),INDEX('データ'!P$759:P$875,MATCH($L22&"|"&$C$3,'データ'!$A$7:$A$123,0))),0) -> 0.057298373 | Q22: =IFERROR(INDEX('データ'!O$759:O$875,MATCH($L22&"|"&$C$3,'データ'!$A$7:$A$123,0))/SUM(INDEX('データ'!K$759:K$875,MATCH($L22&"|"&$C$3,'データ'!$A$7:$A$123,0)),INDEX('データ'!L$759:L$875,MATCH($L22&"|"&$C$3,'データ'!$A$7:$A$123,0)),INDEX('データ'!M$759:M$875,MATCH($L22&"|"&$C$3,'データ'!$A$7:$A$123,0)),INDEX('データ'!N$759:N$875,MATCH($L22&"|"&$C$3,'データ'!$A$7:$A$123,0)),INDEX('データ'!O$759:O$875,MATCH($L22&"|"&$C$3,'データ'!$A$7:$A$123,0)),INDEX('データ'!P$759:P$875,MATCH($L22&"|"&$C$3,'データ'!$A$7:$A$123,0))),0) -> 0.013837362 | R22: =IFERROR(INDEX('データ'!P$759:P$875,MATCH($L22&"|"&$C$3,'データ'!$A$7:$A$123,0))/SUM(INDEX('データ'!K$759:K$875,MATCH($L22&"|"&$C$3,'データ'!$A$7:$A$123,0)),INDEX('データ'!L$759:L$875,MATCH($L22&"|"&$C$3,'データ'!$A$7:$A$123,0)),INDEX('データ'!M$759:M$875,MATCH($L22&"|"&$C$3,'データ'!$A$7:$A$123,0)),INDEX('データ'!N$759:N$875,MATCH($L22&"|"&$C$3,'データ'!$A$7:$A$123,0)),INDEX('データ'!O$759:O$875,MATCH($L22&"|"&$C$3,'データ'!$A$7:$A$123,0)),INDEX('データ'!P$759:P$875,MATCH($L22&"|"&$C$3,'データ'!$A$7:$A$123,0))),0) -> 0.0031670019
L23: 東区 | M23: =IFERROR(INDEX('データ'!K$759:K$875,MATCH($L23&"|"&$C$3,'データ'!$A$7:$A$123,0))/SUM(INDEX('データ'!K$759:K$875,MATCH($L23&"|"&$C$3,'データ'!$A$7:$A$123,0)),INDEX('データ'!L$759:L$875,MATCH($L23&"|"&$C$3,'データ'!$A$7:$A$123,0)),INDEX('データ'!M$759:M$875,MATCH($L23&"|"&$C$3,'データ'!$A$7:$A$123,0)),INDEX('データ'!N$759:N$875,MATCH($L23&"|"&$C$3,'データ'!$A$7:$A$123,0)),INDEX('データ'!O$759:O$875,MATCH($L23&"|"&$C$3,'データ'!$A$7:$A$123,0)),INDEX('データ'!P$759:P$875,MATCH($L23&"|"&$C$3,'データ'!$A$7:$A$123,0))),0) -> 0.75626854 | N23: =IFERROR(INDEX('データ'!L$759:L$875,MATCH($L23&"|"&$C$3,'データ'!$A$7:$A$123,0))/SUM(INDEX('データ'!K$759:K$875,MATCH($L23&"|"&$C$3,'データ'!$A$7:$A$123,0)),INDEX('データ'!L$759:L$875,MATCH($L23&"|"&$C$3,'データ'!$A$7:$A$123,0)),INDEX('データ'!M$759:M$875,MATCH($L23&"|"&$C$3,'データ'!$A$7:$A$123,0)),INDEX('データ'!N$759:N$875,MATCH($L23&"|"&$C$3,'データ'!$A$7:$A$123,0)),INDEX('データ'!O$759:O$875,MATCH($L23&"|"&$C$3,'データ'!$A$7:$A$123,0)),INDEX('データ'!P$759:P$875,MATCH($L23&"|"&$C$3,'データ'!$A$7:$A$123,0))),0) -> 0.12522366 | O23: =IFERROR(INDEX('データ'!M$759:M$875,MATCH($L23&"|"&$C$3,'データ'!$A$7:$A$123,0))/SUM(INDEX('データ'!K$759:K$875,MATCH($L23&"|"&$C$3,'データ'!$A$7:$A$123,0)),INDEX('データ'!L$759:L$875,MATCH($L23&"|"&$C$3,'データ'!$A$7:$A$123,0)),INDEX('データ'!M$759:M$875,MATCH($L23&"|"&$C$3,'データ'!$A$7:$A$123,0)),INDEX('データ'!N$759:N$875,MATCH($L23&"|"&$C$3,'データ'!$A$7:$A$123,0)),INDEX('データ'!O$759:O$875,MATCH($L23&"|"&$C$3,'データ'!$A$7:$A$123,0)),INDEX('データ'!P$759:P$875,MATCH($L23&"|"&$C$3,'データ'!$A$7:$A$123,0))),0) -> 0.059535773 | P23: =IFERROR(INDEX('データ'!N$759:N$875,MATCH($L23&"|"&$C$3,'データ'!$A$7:$A$123,0))/SUM(INDEX('データ'!K$759:K$875,MATCH($L23&"|"&$C$3,'データ'!$A$7:$A$123,0)),INDEX('データ'!L$759:L$875,MATCH($L23&"|"&$C$3,'データ'!$A$7:$A$123,0)),INDEX('データ'!M$759:M$875,MATCH($L23&"|"&$C$3,'データ'!$A$7:$A$123,0)),INDEX('データ'!N$759:N$875,MATCH($L23&"|"&$C$3,'データ'!$A$7:$A$123,0)),INDEX('データ'!O$759:O$875,MATCH($L23&"|"&$C$3,'データ'!$A$7:$A$123,0)),INDEX('データ'!P$759:P$875,MATCH($L23&"|"&$C$3,'データ'!$A$7:$A$123,0))),0) -> 0.0408711 | Q23: =IFERROR(INDEX('データ'!O$759:O$875,MATCH($L23&"|"&$C$3,'データ'!$A$7:$A$123,0))/SUM(INDEX('データ'!K$759:K$875,MATCH($L23&"|"&$C$3,'データ'!$A$7:$A$123,0)),INDEX('データ'!L$759:L$875,MATCH($L23&"|"&$C$3,'データ'!$A$7:$A$123,0)),INDEX('データ'!M$759:M$875,MATCH($L23&"|"&$C$3,'データ'!$A$7:$A$123,0)),INDEX('データ'!N$759:N$875,MATCH($L23&"|"&$C$3,'データ'!$A$7:$A$123,0)),INDEX('データ'!O$759:O$875,MATCH($L23&"|"&$C$3,'データ'!$A$7:$A$123,0)),INDEX('データ'!P$759:P$875,MATCH($L23&"|"&$C$3,'データ'!$A$7:$A$123,0))),0) -> 0.012402265 | R23: =IFERROR(INDEX('データ'!P$759:P$875,MATCH($L23&"|"&$C$3,'データ'!$A$7:$A$123,0))/SUM(INDEX('データ'!K$759:K$875,MATCH($L23&"|"&$C$3,'データ'!$A$7:$A$123,0)),INDEX('データ'!L$759:L$875,MATCH($L23&"|"&$C$3,'データ'!$A$7:$A$123,0)),INDEX('データ'!M$759:M$875,MATCH($L23&"|"&$C$3,'データ'!$A$7:$A$123,0)),INDEX('データ'!N$759:N$875,MATCH($L23&"|"&$C$3,'データ'!$A$7:$A$123,0)),INDEX('データ'!O$759:O$875,MATCH($L23&"|"&$C$3,'データ'!$A$7:$A$123,0)),INDEX('データ'!P$759:P$875,MATCH($L23&"|"&$C$3,'データ'!$A$7:$A$123,0))),0) -> 0.0056986691
