Workbook

Sheet 10月
B1: 令和８年度職員住宅賃貸借契約使用料等一覧 | L1: =IF(SUMPRODUCT(--ISERROR(O7:P45))+COUNTIF(K7:K45,"要確認")=0,"入力チェック：異常なし","入力チェック："&(SUMPRODUCT(--ISERROR(O7:P45))+COUNTIF(K7:K45,"要確認"))&"件要確認（赤色セルを確認）") -> 入力チェック：異常なし
B2: № | C2: 名 称 | D2: 物件名 | E2: 物件所在地 | F2: 使用料の計算 | T2: 改定 | V2: 10月分 | X2: 入居者 | AB2: 納付郵送先
F3: ①賃料の２割 | H3: ②国家公務員宿舎法による算出 | T3: R7計算 | V3: 入居日数 | W3: 当月数 | X3: R8 | Y3: 所属 | Z3: 職位
F4: 月額賃料 | H4: 建築年月 | I4: 構造 | J4: 住宅区分 | K4: 構造区分 | L4: 経過年数 | M4: 居住面積 | N4: 単赴手当 | O4: 基準額 | P4: 控除額 | Q4: 計算額 | W4: 31
G5: ×20/100 | J5: (選択) | K5: (自動) | L5: 46113 | Q5: 10円未満 切捨て | S5: 大文字文字列
B7: =ROW()-6 -> 1 | C7: =[1]一覧!C7 -> 東京公舎６６号 | F7: =[1]一覧!P7 -> 129000 | G7: =F7*0.2 -> 25800 | H7: =[1]一覧!F7 -> 35247 | I7: =[1]一覧!G7 -> ＲＣ | J7: 東京事務所職員等 | K7: =IFERROR(INDEX(区分設定!$C$6:$C$40,MATCH(I7,区分設定!$B$6:$B$40,0)),"要確認") -> 鉄骨・RC造 | L7: =DATEDIF(H7,$L$5,"Y") -> 29 | M7: 44 | N7: 無 | O7: =INDEX(基準額表!$C$7:$G$8,MATCH($J7,基準額表!$B$7:$B$8,0),MATCH($M7,基準額表!$C$4:$G$4,1)) -> 696 | P7: =INDEX(控除額表!$F$6:$J$300,MATCH($N7&"|"&$K7&"|"&$J7,控除額表!$A$6:$A$300,0)+COUNTIFS(控除額表!$A$6:$A$300,$N7&"|"&$K7&"|"&$J7,控除額表!$E$6:$E$300,"<="&$L7)-1,MATCH($M7,控除額表!$F$4:$J$4,1)) -> 138 | Q7: =ROUNDDOWN((O7-P7)*M7,-1) -> 24550 | R7: =IF(G7>Q7,G7,Q7) -> 25800 | S7: =DBCS(FIXED(TEXT(R7,"@"),0)) -> ２５，８００ | T7: 25800 | U7: =IF(AND(R7<>T7,X7="継続"),"○","") | V7: 31 | W7: =ROUNDDOWN(R7*V7/$W$4,0) -> 25800
B8: =ROW()-6 -> 2 | C8: =[1]一覧!C8 -> 東京公舎６７号 | F8: =[1]一覧!P8 -> 127000 | G8: =F8*0.2 -> 25400 | H8: =[1]一覧!F8 -> 35247 | I8: =[1]一覧!G8 -> ＲＣ | J8: 東京事務所職員等 | K8: =IFERROR(INDEX(区分設定!$C$6:$C$40,MATCH(I8,区分設定!$B$6:$B$40,0)),"要確認") -> 鉄骨・RC造 | L8: =DATEDIF(H8,$L$5,"Y") -> 29 | M8: 44 | N8: 有 | O8: =INDEX(基準額表!$C$7:$G$8,MATCH($J8,基準額表!$B$7:$B$8,0),MATCH($M8,基準額表!$C$4:$G$4,1)) -> 696 | P8: =INDEX(控除額表!$F$6:$J$300,MATCH($N8&"|"&$K8&"|"&$J8,控除額表!$A$6:$A$300,0)+COUNTIFS(控除額表!$A$6:$A$300,$N8&"|"&$K8&"|"&$J8,控除額表!$E$6:$E$300,"<="&$L8)-1,MATCH($M8,控除額表!$F$4:$J$4,1)) -> 337 | Q8: =ROUNDDOWN((O8-P8)*M8,-1) -> 15790 | R8: =IF(G8>Q8,G8,Q8) -> 25400 | S8: =DBCS(FIXED(TEXT(R8,"@"),0)) -> ２５，４００ | T8: 25400 | U8: =IF(AND(R8<>T8,X8="継続"),"○","") | V8: 31 | W8: =ROUNDDOWN(R8*V8/$W$4,0) -> 25400
B9: =ROW()-6 -> 3 | C9: =[1]一覧!C9 -> 東京公舎８６号 | F9: =[1]一覧!P9 -> 110000 | G9: =F9*0.2 -> 22000 | H9: =[1]一覧!F9 -> 32721 | I9: =[1]一覧!G9 -> ＲＣ | J9: 東京事務所職員等 | K9: =IFERROR(INDEX(区分設定!$C$6:$C$40,MATCH(I9,区分設定!$B$6:$B$40,0)),"要確認") -> 鉄骨・RC造 | L9: =DATEDIF(H9,$L$5,"Y") -> 36 | M9: 51 | N9: 無 | O9: =INDEX(基準額表!$C$7:$G$8,MATCH($J9,基準額表!$B$7:$B$8,0),MATCH($M9,基準額表!$C$4:$G$4,1)) -> 696 | P9: =INDEX(控除額表!$F$6:$J$300,MATCH($N9&"|"&$K9&"|"&$J9,控除額表!$A$6:$A$300,0)+COUNTIFS(控除額表!$A$6:$A$300,$N9&"|"&$K9&"|"&$J9,控除額表!$E$6:$E$300,"<="&$L9)-1,MATCH($M9,控除額表!$F$4:$J$4,1)) -> 193 | Q9: =ROUNDDOWN((O9-P9)*M9,-1) -> 25650 | R9: =IF(G9>Q9,G9,Q9) -> 25650 | S9: =DBCS(FIXED(TEXT(R9,"@"),0)) -> ２５，６５０ | T9: 22000 | U9: =IF(AND(R9<>T9,X9="継続"),"○","") | V9: 31 | W9: =ROUNDDOWN(R9*V9/$W$4,0) -> 25650
B10: =ROW()-6 -> 4 | C10: =[1]一覧!C10 -> 東京公舎８８号 | F10: =[1]一覧!P10 -> 109000 | G10: =F10*0.2 -> 21800 | H10: =[1]一覧!F10 -> 37196 | I10: =[1]一覧!G10 -> ＲＣ | J10: 東京事務所職員等 | K10: =IFERROR(INDEX(区分設定!$C$6:$C$40,MATCH(I10,区分設定!$B$6:$B$40,0)),"要確認") -> 鉄骨・RC造 | L10: =DATEDIF(H10,$L$5,"Y") -> 24 | M10: 30 | N10: 有 | O10: =INDEX(基準額表!$C$7:$G$8,MATCH($J10,基準額表!$B$7:$B$8,0),MATCH($M10,基準額表!$C$4:$G$4,1)) -> 696 | P10: =INDEX(控除額表!$F$6:$J$300,MATCH($N10&"|"&$K10&"|"&$J10,控除額表!$A$6:$A$300,0)+COUNTIFS(控除額表!$A$6:$A$300,$N10&"|"&$K10&"|"&$J10,控除額表!$E$6:$E$300,"<="&$L10)-1,MATCH($M10,控除額表!$F$4:$J$4,1)) -> 317 | Q10: =ROUNDDOWN((O10-P10)*M10,-1) -> 11370 | R10: =IF(G10>Q10,G10,Q10) -> 21800 | S10: =DBCS(FIXED(TEXT(R10,"@"),0)) -> ２１，８００ | T10: 21800 | U10: =IF(AND(R10<>T10,X10="継続"),"○","") | V10: 31 | W10: =ROUNDDOWN(R10*V10/$W$4,0) -> 21800
B11: =ROW()-6 -> 5 | C11: =[1]一覧!C11 -> 東京公舎９０号 | F11: =[1]一覧!P11 -> 135000 | G11: =F11*0.2 -> 27000 | H11: =[1]一覧!F11 -> 35278 | I11: =[1]一覧!G11 -> ＲＣ | J11: 東京事務所職員等 | K11: =IFERROR(INDEX(区分設定!$C$6:$C$40,MATCH(I11,区分設定!$B$6:$B$40,0)),"要確認") -> 鉄骨・RC造 | L11: =DATEDIF(H11,$L$5,"Y") -> 29 | M11: 54 | N11: 無 | O11: =INDEX(基準額表!$C$7:$G$8,MATCH($J11,基準額表!$B$7:$B$8,0),MATCH($M11,基準額表!$C$4:$G$4,1)) -> 696 | P11: =INDEX(控除額表!$F$6:$J$300,MATCH($N11&"|"&$K11&"|"&$J11,控除額表!$A$6:$A$300,0)+COUNTIFS(控除額表!$A$6:$A$300,$N11&"|"&$K11&"|"&$J11,控除額表!$E$6:$E$300,"<="&$L11)-1,MATCH($M11,控除額表!$F$4:$J$4,1)) -> 138 | Q11: =ROUNDDOWN((O11-P11)*M11,-1) -> 30130 | R11: =IF(G11>Q11,G11,Q11) -> 30130 | S11: =DBCS(FIXED(TEXT(R11,"@"),0)) -> ３０，１３０ | T11: 30130 | U11: =IF(AND(R11<>T11,X11="継続"),"○","") | V11: 31 | W11: =ROUNDDOWN(R11*V11/$W$4,0) -> 30130
B12: =ROW()-6 -> 6 | C12: =[1]一覧!C12 -> 東京公舎９３号 | F12: =[1]一覧!P12 -> 104000 | G12: =F12*0.2 -> 20800 | H12: =[1]一覧!F12 -> 37196 | I12: =[1]一覧!G12 -> ＲＣ | J12: 東京事務所職員等 | K12: =IFERROR(INDEX(区分設定!$C$6:$C$40,MATCH(I12,区分設定!$B$6:$B$40,0)),"要確認") -> 鉄骨・RC造 | L12: =DATEDIF(H12,$L$5,"Y") -> 24 | M12: 28 | N12: 無 | O12: =INDEX(基準額表!$C$7:$G$8,MATCH($J12,基準額表!$B$7:$B$8,0),MATCH($M12,基準額表!$C$4:$G$4,1)) -> 696 | P12: =INDEX(控除額表!$F$6:$J$300,MATCH($N12&"|"&$K12&"|"&$J12,控除額表!$A$6:$A$300,0)+COUNTIFS(控除額表!$A$6:$A$300,$N12&"|"&$K12&"|"&$J12,控除額表!$E$6:$E$300,"<="&$L12)-1,MATCH($M12,控除額表!$F$4:$J$4,1)) -> 111 | Q12: =ROUNDDOWN((O12-P12)*M12,-1) -> 16380 | R12: =IF(G12>Q12,G12,Q12) -> 20800 | S12: =DBCS(FIXED(TEXT(R12,"@"),0)) -> ２０，８００ | T12: 20800 | U12: =IF(AND(R12<>T12,X12="継続"),"○","") | V12: 31 | W12: =ROUNDDOWN(R12*V12/$W$4,0) -> 20800
B13: =ROW()-6 -> 7 | C13: =[1]一覧!C13 -> 東京公舎９４号 | F13: =[1]一覧!P13 -> 102000 | G13: =F13*0.2 -> 20400 | H13: =[1]一覧!F13 -> 37196 | I13: =[1]一覧!G13 -> ＲＣ | J13: 東京事務所職員等 | K13: =IFERROR(INDEX(区分設定!$C$6:$C$40,MATCH(I13,区分設定!$B$6:$B$40,0)),"要確認") -> 鉄骨・RC造 | L13: =DATEDIF(H13,$L$5,"Y") -> 24 | M13: 27 | N13: 無 | O13: =INDEX(基準額表!$C$7:$G$8,MATCH($J13,基準額表!$B$7:$B$8,0),MATCH($M13,基準額表!$C$4:$G$4,1)) -> 696 | P13: =INDEX(控除額表!$F$6:$J$300,MATCH($N13&"|"&$K13&"|"&$J13,控除額表!$A$6:$A$300,0)+COUNTIFS(控除額表!$A$6:$A$300,$N13&"|"&$K13&"|"&$J13,控除額表!$E$6:$E$300,"<="&$L13)-1,MATCH($M13,控除額表!$F$4:$J$4,1)) -> 111 | Q13: =ROUNDDOWN((O13-P13)*M13,-1) -> 15790 | R13: =IF(G13>Q13,G13,Q13) -> 20400 | S13: =DBCS(FIXED(TEXT(R13,"@"),0)) -> ２０，４００ | T13: 20400 | U13: =IF(AND(R13<>T13,X13="継続"),"○","") | V13: 31 | W13: =ROUNDDOWN(R13*V13/$W$4,0) -> 20400
B14: =ROW()-6 -> 8 | C14: =[1]一覧!C14 -> 東京公舎９７号 | F14: =[1]一覧!P14 -> 127000 | G14: =F14*0.2 -> 25400 | H14: =[1]一覧!F14 -> 37377 | I14: =[1]一覧!G14 -> ＲＣ | J14: 東京事務所職員等 | K14: =IFERROR(INDEX(区分設定!$C$6:$C$40,MATCH(I14,区分設定!$B$6:$B$40,0)),"要確認") -> 鉄骨・RC造 | L14: =DATEDIF(H14,$L$5,"Y") -> 23 | M14: 36 | N14: 有 | O14: =INDEX(基準額表!$C$7:$G$8,MATCH($J14,基準額表!$B$7:$B$8,0),MATCH($M14,基準額表!$C$4:$G$4,1)) -> 696 | P14: =INDEX(控除額表!$F$6:$J$300,MATCH($N14&"|"&$K14&"|"&$J14,控除額表!$A$6:$A$300,0)+COUNTIFS(控除額表!$A$6:$A$300,$N14&"|"&$K14&"|"&$J14,控除額表!$E$6:$E$300,"<="&$L14)-1,MATCH($M14,控除額表!$F$4:$J$4,1)) -> 317 | Q14: =ROUNDDOWN((O14-P14)*M14,-1) -> 13640 | R14: =IF(G14>Q14,G14,Q14) -> 25400 | S14: =DBCS(FIXED(TEXT(R14,"@"),0)) -> ２５，４００ | T14: 25400 | U14: =IF(AND(R14<>T14,X14="継続"),"○","") | V14: 31 | W14: =ROUNDDOWN(R14*V14/$W$4,0) -> 25400
B15: =ROW()-6 -> 9 | C15: =[1]一覧!C15 -> 東京公舎１０１号 | F15: =[1]一覧!P15 -> 125000 | G15: =F15*0.2 -> 25000 | H15: =[1]一覧!F15 -> 37306 | I15: =[1]一覧!G15 -> ＲＣ | J15: 東京事務所職員等 | K15: =IFERROR(INDEX(区分設定!$C$6:$C$40,MATCH(I15,区分設定!$B$6:$B$40,0)),"要確認") -> 鉄骨・RC造 | L15: =DATEDIF(H15,$L$5,"Y") -> 24 | M15: 48 | N15: 無 | O15: =INDEX(基準額表!$C$7:$G$8,MATCH($J15,基準額表!$B$7:$B$8,0),MATCH($M15,基準額表!$C$4:$G$4,1)) -> 696 | P15: =INDEX(控除額表!$F$6:$J$300,MATCH($N15&"|"&$K15&"|"&$J15,控除額表!$A$6:$A$300,0)+COUNTIFS(控除額表!$A$6:$A$300,$N15&"|"&$K15&"|"&$J15,控除額表!$E$6:$E$300,"<="&$L15)-1,MATCH($M15,控除額表!$F$4:$J$4,1)) -> 111 | Q15: =ROUNDDOWN((O15-P15)*M15,-1) -> 28080 | R15: =IF(G15>Q15,G15,Q15) -> 28080 | S15: =DBCS(FIXED(TEXT(R15,"@"),0)) -> ２８，０８０ | T15: 25000 | U15: =IF(AND(R15<>T15,X15="継続"),"○","") | V15: 31 | W15: =ROUNDDOWN(R15*V15/$W$4,0) -> 28080
B16: =ROW()-6 -> 10 | C16: =[1]一覧!C16 -> 東京公舎１０２号 | F16: =[1]一覧!P16 -> 120000 | G16: =F16*0.2 -> 24000 | H16: =[1]一覧!F16 -> 39934 | I16: =[1]一覧!G16 -> ＲＣ | J16: 東京事務所職員等 | K16: =IFERROR(INDEX(区分設定!$C$6:$C$40,MATCH(I16,区分設定!$B$6:$B$40,0)),"要確認") -> 鉄骨・RC造 | L16: =DATEDIF(H16,$L$5,"Y") -> 16 | M16: 32 | N16: 無 | O16: =INDEX(基準額表!$C$7:$G$8,MATCH($J16,基準額表!$B$7:$B$8,0),MATCH($M16,基準額表!$C$4:$G$4,1)) -> 696 | P16: =INDEX(控除額表!$F$6:$J$300,MATCH($N16&"|"&$K16&"|"&$J16,控除額表!$A$6:$A$300,0)+COUNTIFS(控除額表!$A$6:$A$300,$N16&"|"&$K16&"|"&$J16,控除額表!$E$6:$E$300,"<="&$L16)-1,MATCH($M16,控除額表!$F$4:$J$4,1)) -> 83 | Q16: =ROUNDDOWN((O16-P16)*M16,-1) -> 19610 | R16: =IF(G16>Q16,G16,Q16) -> 24000 | S16: =DBCS(FIXED(TEXT(R16,"@"),0)) -> ２４，０００ | T16: 24000 | U16: =IF(AND(R16<>T16,X16="継続"),"○","") | V16: 31 | W16: =ROUNDDOWN(R16*V16/$W$4,0) -> 24000
B17: =ROW()-6 -> 11 | C17: =[1]一覧!C17 -> 東京公舎１０３号 | F17: =[1]一覧!P17 -> 140000 | G17: =F17*0.2 -> 28000 | H17: =[1]一覧!F17 -> 32752 | I17: =[1]一覧!G17 -> ＲＣ | J17: 東京事務所職員等 | K17: =IFERROR(INDEX(区分設定!$C$6:$C$40,MATCH(I17,区分設定!$B$6:$B$40,0)),"要確認") -> 鉄骨・RC造 | L17: =DATEDIF(H17,$L$5,"Y") -> 36 | M17: 54 | N17: 無 | O17: =INDEX(基準額表!$C$7:$G$8,MATCH($J17,基準額表!$B$7:$B$8,0),MATCH($M17,基準額表!$C$4:$G$4,1)) -> 696 | P17: =INDEX(控除額表!$F$6:$J$300,MATCH($N17&"|"&$K17&"|"&$J17,控除額表!$A$6:$A$300,0)+COUNTIFS(控除額表!$A$6:$A$300,$N17&"|"&$K17&"|"&$J17,控除額表!$E$6:$E$300,"<="&$L17)-1,MATCH($M17,控除額表!$F$4:$J$4,1)) -> 193 | Q17: =ROUNDDOWN((O17-P17)*M17,-1) -> 27160 | R17: =IF(G17>Q17,G17,Q17) -> 28000 | S17: =DBCS(FIXED(TEXT(R17,"@"),0)) -> ２８，０００ | T17: 28000 | U17: =IF(AND(R17<>T17,X17="継続"),"○","") | V17: 31 | W17: =ROUNDDOWN(R17*V17/$W$4,0) -> 28000
B18: =ROW()-6 -> 12 | C18: =[1]一覧!C18 -> 東京公舎１０４号 | F18: =[1]一覧!P18 -> 95000 | G18: =F18*0.2 -> 19000 | H18: =[1]一覧!F18 -> 32325 | I18: =[1]一覧!G18 -> ＲＣ | J18: 東京事務所職員等 | K18: =IFERROR(INDEX(区分設定!$C$6:$C$40,MATCH(I18,区分設定!$B$6:$B$40,0)),"要確認") -> 鉄骨・RC造 | L18: =DATEDIF(H18,$L$5,"Y") -> 37 | M18: 39 | N18: 有 | O18: =INDEX(基準額表!$C$7:$G$8,MATCH($J18,基準額表!$B$7:$B$8,0),MATCH($M18,基準額表!$C$4:$G$4,1)) -> 696 | P18: =INDEX(控除額表!$F$6:$J$300,MATCH($N18&"|"&$K18&"|"&$J18,控除額表!$A$6:$A$300,0)+COUNTIFS(控除額表!$A$6:$A$300,$N18&"|"&$K18&"|"&$J18,控除額表!$E$6:$E$300,"<="&$L18)-1,MATCH($M18,控除額表!$F$4:$J$4,1)) -> 366 | Q18: =ROUNDDOWN((O18-P18)*M18,-1) -> 12870 | R18: =IF(G18>Q18,G18,Q18) -> 19000 | S18: =DBCS(FIXED(TEXT(R18,"@"),0)) -> １９，０００ | T18: 19610 | U18: =IF(AND(R18<>T18,X18="継続"),"○","") | V18: 31 | W18: =ROUNDDOWN(R18*V18/$W$4,0) -> 19000
... B32: =ROW()-6 -> 26 | C32: =[1]一覧!C32 -> 東京公舎１２８号 | F32: =[1]一覧!P32 -> 127000 | G32: =F32*0.2 -> 25400 | H32: =[1]一覧!F32 -> 37347 | I32: =[1]一覧!G32 -> ＲＣ | J32: 東京事務所職員等 | K32: =IFERROR(INDEX(区分設定!$C$6:$C$40,MATCH(I32,区分設定!$B$6:$B$40,0)),"要確認") -> 鉄骨・RC造 | L32: =DATEDIF(H32,$L$5,"Y") -> 24 | M32: 35 | N32: 有 | O32: =INDEX(基準額表!$C$7:$G$8,MATCH($J32,基準額表!$B$7:$B$8,0),MATCH($M32,基準額表!$C$4:$G$4,1)) -> 696 | P32: =INDEX(控除額表!$F$6:$J$300,MATCH($N32&"|"&$K32&"|"&$J32,控除額表!$A$6:$A$300,0)+COUNTIFS(控除額表!$A$6:$A$300,$N32&"|"&$K32&"|"&$J32,控除額表!$E$6:$E$300,"<="&$L32)-1,MATCH($M32,控除額表!$F$4:$J$4,1)) -> 317 | Q32: =ROUNDDOWN((O32-P32)*M32,-1) -> 13260 | R32: =IF(G32>Q32,G32,Q32) -> 25400 | S32: =DBCS(FIXED(TEXT(R32,"@"),0)) -> ２５，４００ | T32: 25400 | U32: =IF(AND(R32<>T32,X32="継続"),"○","") | V32: 31 | W32: =ROUNDDOWN(R32*V32/$W$4,0) -> 25400
B33: =ROW()-6 -> 27 | C33: =[1]一覧!C33 -> 東京公舎１２９号 | F33: =[1]一覧!P33 -> 150000 | G33: =F33*0.2 -> 30000 | H33: =[1]一覧!F33 -> 34912 | I33: =[1]一覧!G33 -> ＲＣ | J33: 東京事務所職員等 | K33: =IFERROR(INDEX(区分設定!$C$6:$C$40,MATCH(I33,区分設定!$B$6:$B$40,0)),"要確認") -> 鉄骨・RC造 | L33: =DATEDIF(H33,$L$5,"Y") -> 30 | M33: 59 | N33: 無 | O33: =INDEX(基準額表!$C$7:$G$8,MATCH($J33,基準額表!$B$7:$B$8,0),MATCH($M33,基準額表!$C$4:$G$4,1)) -> 870 | P33: =INDEX(控除額表!$F$6:$J$300,MATCH($N33&"|"&$K33&"|"&$J33,控除額表!$A$6:$A$300,0)+COUNTIFS(控除額表!$A$6:$A$300,$N33&"|"&$K33&"|"&$J33,控除額表!$E$6:$E$300,"<="&$L33)-1,MATCH($M33,控除額表!$F$4:$J$4,1)) -> 207 | Q33: =ROUNDDOWN((O33-P33)*M33,-1) -> 39110 | R33: =IF(G33>Q33,G33,Q33) -> 39110 | S33: =DBCS(FIXED(TEXT(R33,"@"),0)) -> ３９，１１０ | T33: － | U33: =IF(AND(R33<>T33,X33="継続"),"○","") | V33: 31 | W33: =ROUNDDOWN(R33*V33/$W$4,0) -> 39110
B34: =ROW()-6 -> 28 | C34: =[1]一覧!C34 -> 札幌公舎 | F34: =[1]一覧!P34 -> 78000 | G34: =F34*0.2 -> 15600 | H34: =[1]一覧!F34 -> 39142 | I34: =[1]一覧!G34 -> ＲＣ | J34: その他 | K34: =IFERROR(INDEX(区分設定!$C$6:$C$40,MATCH(I34,区分設定!$B$6:$B$40,0)),"要確認") -> 鉄骨・RC造 | L34: =DATEDIF(H34,$L$5,"Y") -> 19 | M34: 39 | N34: 無 | O34: =INDEX(基準額表!$C$7:$G$8,MATCH($J34,基準額表!$B$7:$B$8,0),MATCH($M34,基準額表!$C$4:$G$4,1)) -> 498 | P34: =INDEX(控除額表!$F$6:$J$300,MATCH($N34&"|"&$K34&"|"&$J34,控除額表!$A$6:$A$300,0)+COUNTIFS(控除額表!$A$6:$A$300,$N34&"|"&$K34&"|"&$J34,控除額表!$E$6:$E$300,"<="&$L34)-1,MATCH($M34,控除額表!$F$4:$J$4,1)) -> 83 | Q34: =ROUNDDOWN((O34-P34)*M34,-1) -> 16180 | R34: =IF(G34>Q34,G34,Q34) -> 16180 | S34: =DBCS(FIXED(TEXT(R34,"@"),0)) -> １６，１８０ | T34: 16180 | U34: =IF(AND(R34<>T34,X34="継続"),"○","") | V34: 31 | W34: =ROUNDDOWN(R34*V34/$W$4,0) -> 16180
B35: =ROW()-6 -> 29 | C35: =[1]一覧!C35 -> 京都公舎 | F35: =[1]一覧!P35 -> 70000 | G35: =F35*0.2 -> 14000 | H35: =[1]一覧!F35 -> 40210 | I35: =[1]一覧!G35 -> ＲＣ | J35: その他 | K35: =IFERROR(INDEX(区分設定!$C$6:$C$40,MATCH(I35,区分設定!$B$6:$B$40,0)),"要確認") -> 鉄骨・RC造 | L35: =DATEDIF(H35,$L$5,"Y") -> 16 | M35: 28 | N35: 無 | O35: =INDEX(基準額表!$C$7:$G$8,MATCH($J35,基準額表!$B$7:$B$8,0),MATCH($M35,基準額表!$C$4:$G$4,1)) -> 498 | P35: =INDEX(控除額表!$F$6:$J$300,MATCH($N35&"|"&$K35&"|"&$J35,控除額表!$A$6:$A$300,0)+COUNTIFS(控除額表!$A$6:$A$300,$N35&"|"&$K35&"|"&$J35,控除額表!$E$6:$E$300,"<="&$L35)-1,MATCH($M35,控除額表!$F$4:$J$4,1)) -> 83 | Q35: =ROUNDDOWN((O35-P35)*M35,-1) -> 11620 | R35: =IF(G35>Q35,G35,Q35) -> 14000 | S35: =DBCS(FIXED(TEXT(R35,"@"),0)) -> １４，０００ | T35: 14000 | U35: =IF(AND(R35<>T35,X35="継続"),"○","") | V35: 31 | W35: =ROUNDDOWN(R35*V35/$W$4,0) -> 14000
B36: =ROW()-6 -> 30 | C36: =[1]一覧!C36 -> 観音町公舎 | F36: =[1]一覧!P36 -> 84000 | G36: =F36*0.2 -> 16800 | H36: =[1]一覧!F36 -> 37104 | I36: =[1]一覧!G36 -> ＲＣ | J36: その他 | K36: =IFERROR(INDEX(区分設定!$C$6:$C$40,MATCH(I36,区分設定!$B$6:$B$40,0)),"要確認") -> 鉄骨・RC造 | L36: =DATEDIF(H36,$L$5,"Y") -> 24 | M36: 50 | N36: 無 | O36: =INDEX(基準額表!$C$7:$G$8,MATCH($J36,基準額表!$B$7:$B$8,0),MATCH($M36,基準額表!$C$4:$G$4,1)) -> 498 | P36: =INDEX(控除額表!$F$6:$J$300,MATCH($N36&"|"&$K36&"|"&$J36,控除額表!$A$6:$A$300,0)+COUNTIFS(控除額表!$A$6:$A$300,$N36&"|"&$K36&"|"&$J36,控除額表!$E$6:$E$300,"<="&$L36)-1,MATCH($M36,控除額表!$F$4:$J$4,1)) -> 111 | Q36: =ROUNDDOWN((O36-P36)*M36,-1) -> 19350 | R36: =IF(G36>Q36,G36,Q36) -> 19350 | S36: =DBCS(FIXED(TEXT(R36,"@"),0)) -> １９，３５０ | T36: 19350 | U36: =IF(AND(R36<>T36,X36="継続"),"○","") | V36: 31 | W36: =ROUNDDOWN(R36*V36/$W$4,0) -> 19350
B37: =ROW()-6 -> 31 | C37: =[1]一覧!C37 -> 鶴見町第２公舎 | F37: 125000 | G37: =F37*0.2 -> 25000 | H37: =[1]一覧!F37 -> 35765 | I37: =[1]一覧!G37 -> ＲＣ | J37: その他 | K37: =IFERROR(INDEX(区分設定!$C$6:$C$40,MATCH(I37,区分設定!$B$6:$B$40,0)),"要確認") -> 鉄骨・RC造 | L37: =DATEDIF(H37,$L$5,"Y") -> 28 | M37: 73 | N37: 無 | O37: =INDEX(基準額表!$C$7:$G$8,MATCH($J37,基準額表!$B$7:$B$8,0),MATCH($M37,基準額表!$C$4:$G$4,1)) -> 809 | P37: =INDEX(控除額表!$F$6:$J$300,MATCH($N37&"|"&$K37&"|"&$J37,控除額表!$A$6:$A$300,0)+COUNTIFS(控除額表!$A$6:$A$300,$N37&"|"&$K37&"|"&$J37,控除額表!$E$6:$E$300,"<="&$L37)-1,MATCH($M37,控除額表!$F$4:$J$4,1)) -> 207 | Q37: =ROUNDDOWN((O37-P37)*M37,-1) -> 43940 | R37: =IF(G37>Q37,G37,Q37) -> 43940 | S37: =DBCS(FIXED(TEXT(R37,"@"),0)) -> ４３，９４０ | T37: 43940 | U37: =IF(AND(R37<>T37,X37="継続"),"○","") | V37: 31 | W37: =ROUNDDOWN(R37*V37/$W$4,0) -> 43940
B38: =ROW()-6 -> 32 | C38: =[1]一覧!C38 -> 上幟町公舎 | F38: =[1]一覧!P38 -> 120000 | G38: =F38*0.2 -> 24000 | H38: =[1]一覧!F38 -> 34881 | I38: =[1]一覧!G38 -> ＲＣ | J38: その他 | K38: =IFERROR(INDEX(区分設定!$C$6:$C$40,MATCH(I38,区分設定!$B$6:$B$40,0)),"要確認") -> 鉄骨・RC造 | L38: =DATEDIF(H38,$L$5,"Y") -> 30 | M38: 75 | N38: 無 | O38: =INDEX(基準額表!$C$7:$G$8,MATCH($J38,基準額表!$B$7:$B$8,0),MATCH($M38,基準額表!$C$4:$G$4,1)) -> 809 | P38: =INDEX(控除額表!$F$6:$J$300,MATCH($N38&"|"&$K38&"|"&$J38,控除額表!$A$6:$A$300,0)+COUNTIFS(控除額表!$A$6:$A$300,$N38&"|"&$K38&"|"&$J38,控除額表!$E$6:$E$300,"<="&$L38)-1,MATCH($M38,控除額表!$F$4:$J$4,1)) -> 248 | Q38: =ROUNDDOWN((O38-P38)*M38,-1) -> 42070 | R38: =IF(G38>Q38,G38,Q38) -> 42070 | S38: =DBCS(FIXED(TEXT(R38,"@"),0)) -> ４２，０７０ | T38: 45150 | U38: =IF(AND(R38<>T38,X38="継続"),"○","") | V38: 31 | W38: =ROUNDDOWN(R38*V38/$W$4,0) -> 42070
B39: =ROW()-6 -> 33 | C39: =[1]一覧!C39 -> 国泰寺公舎 | F39: =[1]一覧!P39 -> 70000 | G39: =F39*0.2 -> 14000 | H39: =[1]一覧!F39 -> 36192 | I39: =[1]一覧!G39 -> ＲＣ | J39: その他 | K39: =IFERROR(INDEX(区分設定!$C$6:$C$40,MATCH(I39,区分設定!$B$6:$B$40,0)),"要確認") -> 鉄骨・RC造 | L39: =DATEDIF(H39,$L$5,"Y") -> 27 | M39: 40 | N39: 無 | O39: =INDEX(基準額表!$C$7:$G$8,MATCH($J39,基準額表!$B$7:$B$8,0),MATCH($M39,基準額表!$C$4:$G$4,1)) -> 498 | P39: =INDEX(控除額表!$F$6:$J$300,MATCH($N39&"|"&$K39&"|"&$J39,控除額表!$A$6:$A$300,0)+COUNTIFS(控除額表!$A$6:$A$300,$N39&"|"&$K39&"|"&$J39,控除額表!$E$6:$E$300,"<="&$L39)-1,MATCH($M39,控除額表!$F$4:$J$4,1)) -> 138 | Q39: =ROUNDDOWN((O39-P39)*M39,-1) -> 14400 | R39: =IF(G39>Q39,G39,Q39) -> 14400 | S39: =DBCS(FIXED(TEXT(R39,"@"),0)) -> １４，４００ | T39: 14400 | U39: =IF(AND(R39<>T39,X39="継続"),"○","") | V39: 31 | W39: =ROUNDDOWN(R39*V39/$W$4,0) -> 14400
B40: =ROW()-6 -> 34 | C40: =[1]一覧!C40 -> 西川口町公舎 | F40: =[1]一覧!P40 -> 70000 | G40: =F40*0.2 -> 14000 | H40: =[1]一覧!F40 -> 35125 | I40: =[1]一覧!G40 -> 鉄骨造 | J40: その他 | K40: =IFERROR(INDEX(区分設定!$C$6:$C$40,MATCH(I40,区分設定!$B$6:$B$40,0)),"要確認") -> 鉄骨・RC造 | L40: =DATEDIF(H40,$L$5,"Y") -> 30 | M40: 61 | N40: 無 | O40: =INDEX(基準額表!$C$7:$G$8,MATCH($J40,基準額表!$B$7:$B$8,0),MATCH($M40,基準額表!$C$4:$G$4,1)) -> 622 | P40: =INDEX(控除額表!$F$6:$J$300,MATCH($N40&"|"&$K40&"|"&$J40,控除額表!$A$6:$A$300,0)+COUNTIFS(控除額表!$A$6:$A$300,$N40&"|"&$K40&"|"&$J40,控除額表!$E$6:$E$300,"<="&$L40)-1,MATCH($M40,控除額表!$F$4:$J$4,1)) -> 207 | Q40: =ROUNDDOWN((O40-P40)*M40,-1) -> 25310 | R40: =IF(G40>Q40,G40,Q40) -> 25310 | S40: =DBCS(FIXED(TEXT(R40,"@"),0)) -> ２５，３１０ | T40: 27380 | U40: =IF(AND(R40<>T40,X40="継続"),"○","") | V40: 31 | W40: =ROUNDDOWN(R40*V40/$W$4,0) -> 25310
B41: =ROW()-6 -> 35 | C41: =[1]一覧!C41 -> 富士見町公舎 | F41: =[1]一覧!P41 -> 84000 | G41: =F41*0.2 -> 16800 | H41: =[1]一覧!F41 -> 38749 | I41: =[1]一覧!G41 -> ＲＣ | J41: その他 | K41: =IFERROR(INDEX(区分設定!$C$6:$C$40,MATCH(I41,区分設定!$B$6:$B$40,0)),"要確認") -> 鉄骨・RC造 | L41: =DATEDIF(H41,$L$5,"Y") -> 20 | M41: 49 | N41: 無 | O41: =INDEX(基準額表!$C$7:$G$8,MATCH($J41,基準額表!$B$7:$B$8,0),MATCH($M41,基準額表!$C$4:$G$4,1)) -> 498 | P41: =INDEX(控除額表!$F$6:$J$300,MATCH($N41&"|"&$K41&"|"&$J41,控除額表!$A$6:$A$300,0)+COUNTIFS(控除額表!$A$6:$A$300,$N41&"|"&$K41&"|"&$J41,控除額表!$E$6:$E$300,"<="&$L41)-1,MATCH($M41,控除額表!$F$4:$J$4,1)) -> 111 | Q41: =ROUNDDOWN((O41-P41)*M41,-1) -> 18960 | R41: =IF(G41>Q41,G41,Q41) -> 18960 | S41: =DBCS(FIXED(TEXT(R41,"@"),0)) -> １８，９６０ | T41: 20330 | U41: =IF(AND(R41<>T41,X41="継続"),"○","") | V41: 31 | W41: =ROUNDDOWN(R41*V41/$W$4,0) -> 18960
B42: =ROW()-6 -> 36 | C42: =[1]一覧!C42 -> 幟町公舎 | F42: =[1]一覧!P42 -> 110000 | G42: =F42*0.2 -> 22000 | H42: =[1]一覧!F42 -> 38749 | I42: =[1]一覧!G42 -> ＲＣ | J42: その他 | K42: =IFERROR(INDEX(区分設定!$C$6:$C$40,MATCH(I42,区分設定!$B$6:$B$40,0)),"要確認") -> 鉄骨・RC造 | L42: =DATEDIF(H42,$L$5,"Y") -> 20 | M42: 60 | N42: 有 | O42: =INDEX(基準額表!$C$7:$G$8,MATCH($J42,基準額表!$B$7:$B$8,0),MATCH($M42,基準額表!$C$4:$G$4,1)) -> 622 | P42: =INDEX(控除額表!$F$6:$J$300,MATCH($N42&"|"&$K42&"|"&$J42,控除額表!$A$6:$A$300,0)+COUNTIFS(控除額表!$A$6:$A$300,$N42&"|"&$K42&"|"&$J42,控除額表!$E$6:$E$300,"<="&$L42)-1,MATCH($M42,控除額表!$F$4:$J$4,1)) -> 332 | Q42: =ROUNDDOWN((O42-P42)*M42,-1) -> 17400 | R42: =IF(G42>Q42,G42,Q42) -> 22000 | S42: =DBCS(FIXED(TEXT(R42,"@"),0)) -> ２２，０００ | T42: 22000 | U42: =IF(AND(R42<>T42,X42="継続"),"○","") | V42: 31 | W42: =ROUNDDOWN(R42*V42/$W$4,0) -> 22000
B43: =ROW()-6 -> 37 | C43: =[1]一覧!C43 -> 大手町公舎 | F43: =[1]一覧!P43 -> 209000 | G43: =F43*0.2 -> 41800 | H43: =[1]一覧!F43 -> 27334 | I43: =[1]一覧!G43 -> ＲＣ | J43: その他 | K43: =IFERROR(INDEX(区分設定!$C$6:$C$40,MATCH(I43,区分設定!$B$6:$B$40,0)),"要確認") -> 鉄骨・RC造 | L43: =DATEDIF(H43,$L$5,"Y") -> 51 | M43: 175 | N43: 無 | O43: =INDEX(基準額表!$C$7:$G$8,MATCH($J43,基準額表!$B$7:$B$8,0),MATCH($M43,基準額表!$C$4:$G$4,1)) -> 1213 | P43: =INDEX(控除額表!$F$6:$J$300,MATCH($N43&"|"&$K43&"|"&$J43,控除額表!$A$6:$A$300,0)+COUNTIFS(控除額表!$A$6:$A$300,$N43&"|"&$K43&"|"&$J43,控除額表!$E$6:$E$300,"<="&$L43)-1,MATCH($M43,控除額表!$F$4:$J$4,1)) -> 557 | Q43: =ROUNDDOWN((O43-P43)*M43,-1) -> 114800 | R43: =IF(G43>Q43,G43,Q43) -> 114800 | S43: =DBCS(FIXED(TEXT(R43,"@"),0)) -> １１４，８００ | T43: 114800 | U43: =IF(AND(R43<>T43,X43="継続"),"○","") | V43: 31 | W43: =ROUNDDOWN(R43*V43/$W$4,0) -> 114800
B44: =ROW()-6 -> 38 | C44: =[1]一覧!C44 -> 小町公舎 | F44: =[1]一覧!P44 -> 76000 | G44: =F44*0.2 -> 15200 | H44: =[1]一覧!F44 -> 41456 | I44: =[1]一覧!G44 -> ＲＣ | J44: その他 | K44: =IFERROR(INDEX(区分設定!$C$6:$C$40,MATCH(I44,区分設定!$B$6:$B$40,0)),"要確認") -> 鉄骨・RC造 | L44: =DATEDIF(H44,$L$5,"Y") -> 12 | M44: 36 | N44: 無 | O44: =INDEX(基準額表!$C$7:$G$8,MATCH($J44,基準額表!$B$7:$B$8,0),MATCH($M44,基準額表!$C$4:$G$4,1)) -> 498 | P44: =INDEX(控除額表!$F$6:$J$300,MATCH($N44&"|"&$K44&"|"&$J44,控除額表!$A$6:$A$300,0)+COUNTIFS(控除額表!$A$6:$A$300,$N44&"|"&$K44&"|"&$J44,控除額表!$E$6:$E$300,"<="&$L44)-1,MATCH($M44,控除額表!$F$4:$J$4,1)) -> 0 | Q44: =ROUNDDOWN((O44-P44)*M44,-1) -> 17920 | R44: =IF(G44>Q44,G44,Q44) -> 17920 | S44: =DBCS(FIXED(TEXT(R44,"@"),0)) -> １７，９２０ | T44: － | U44: =IF(AND(R44<>T44,X44="継続"),"○","") | V44: 31 | W44: =ROUNDDOWN(R44*V44/$W$4,0) -> 17920
B45: =ROW()-6 -> 39 | C45: =[1]一覧!C45 -> 国泰寺公舎２号 | F45: =[1]一覧!P45 -> 68000 | G45: =F45*0.2 -> 13600 | H45: =[1]一覧!F45 -> 36192 | I45: =[1]一覧!G45 -> ＲＣ | J45: その他 | K45: =IFERROR(INDEX(区分設定!$C$6:$C$40,MATCH(I45,区分設定!$B$6:$B$40,0)),"要確認") -> 鉄骨・RC造 | L45: =DATEDIF(H45,$L$5,"Y") -> 27 | M45: 40 | N45: 無 | O45: =INDEX(基準額表!$C$7:$G$8,MATCH($J45,基準額表!$B$7:$B$8,0),MATCH($M45,基準額表!$C$4:$G$4,1)) -> 498 | P45: =INDEX(控除額表!$F$6:$J$300,MATCH($N45&"|"&$K45&"|"&$J45,控除額表!$A$6:$A$300,0)+COUNTIFS(控除額表!$A$6:$A$300,$N45&"|"&$K45&"|"&$J45,控除額表!$E$6:$E$300,"<="&$L45)-1,MATCH($M45,控除額表!$F$4:$J$4,1)) -> 138 | Q45: =ROUNDDOWN((O45-P45)*M45,-1) -> 14400 | R45: =IF(G45>Q45,G45,Q45) -> 14400 | S45: =DBCS(FIXED(TEXT(R45,"@"),0)) -> １４，４００ | T45: － | U45: =IF(AND(R45<>T45,X45="継続"),"○","") | V45: 31 | W45: =ROUNDDOWN(R45*V45/$W$4,0) -> 14400
B46: 合 計 | F46: =SUBTOTAL(9,(F7:F45)) -> 4254600 | G46: =SUM(G7:G45) -> 850920 | R46: =SUM(R7:R45) -> 1003240 | W46: =SUM(W7:W45) -> 1003240

Sheet 使い方
B1: 使い方（職員住宅使用料の自動算定）
B3: ■ 何が変わったか
B4: ・「基準額」「控除額」を表から目視で拾う作業をなくし、住宅区分・構造・単身赴任手当・経過年数・居住面積から自動で算定します。
B5: ・根拠表は別シート（基準額表・控除額表）に収録。数値は要綱 別表第１・第２（R6.9.1）および 02 基準使用料・控除額.xlsx と全件一致を確認済み。
B7: ■ 入力するセル（10月シート）
B8: ・J列 住宅区分：「東京事務所職員等」か「その他」を選択（黄色セル。従来の基準額から自動判定した初期値を設定済み）。
B9: ・M列 居住面積（調整済延べ面積＝延べ面積−公用部分、1㎡未満切捨て後の値）、N列 単赴手当（有／無）。
B10: ・H列 建築年月、I列 構造、L5 基準日（経過年数の算定基準日）。H・I列は従来どおり外部ブック(R8_職員住宅一覧)から参照。
B12: ■ 自動で計算されるセル
B13: ・K 構造区分：I列の表記を「区分設定」シートで木造／組積造／鉄骨・RC造に読み替え。
B14: ・L 経過年数＝DATEDIF(建築年月, 基準日, "Y")。
B15: ・O 基準額＝住宅区分×居住面積の区分で「基準額表」から取得。
... B24: ・DATEDIFの第3引数は全角「Ｙ」から半角"Y"に変更しました（計算結果は同じ）。

Sheet 基準額表
B1: 基準使用料（1㎡あたり・月額・円） 単身赴任手当 有・無共通
B2: 出典：広島市職員住宅使用料算定要綱 別表第１ 1（令和6年9月1日施行）。数値は要綱改正時のみ更新（青字＝法定値の入力セル）。
B4: 面積下限(㎡) | C4: 0 | D4: 55 | E4: 70 | F4: 80 | G4: 100
B5: 延べ面積 | C5: 55㎡未満 | D5: 55㎡以上 70㎡未満 | E5: 70㎡以上 80㎡未満 | F5: 80㎡以上 100㎡未満 | G5: 100㎡以上
B6: 住宅区分
B7: 東京事務所職員等 | C7: 696 | D7: 870 | E7: 1305 | F7: 1566 | G7: 1827
B8: その他 | C8: 498 | D8: 622 | E8: 809 | F8: 995 | G8: 1213
B10: 東京事務所職員等＝東京事務所職員及びひろしまプロモーションセンター職員が居住する住宅。その他＝それ以外の職員が居住する住宅。
B11: ※自動車保管場所の基準使用料・調整額（02ファイルの下段）は、10月シートが賃料の2割と比較する方式のため未使用。

Sheet 控除額表
A1: 経年による控除額（1㎡あたり・月額・円）
A2: 出典：広島市職員住宅使用料算定要綱 別表第１ 2（単身赴任手当なし）・別表第２（あり）。経過年数は「年数(下限)以上」で該当行を判定（例：29年→25年行）。
A3: 同一キーの行は連続させ、年数(下限)の昇順に並べること。行の追加・改正はこの表だけを直せばよい（10月シートは自動で追従）。300行目まで参照。
A4: 面積下限(㎡)→ | F4: 0 | G4: 55 | H4: 70 | I4: 80 | J4: 100
A5: キー(自動) | B5: 単身赴任 手当 | C5: 構造区分 | D5: 住宅区分 | E5: 年数 (下限) | F5: 55㎡未満 | G5: 55㎡以上 70㎡未満 | H5: 70㎡以上 80㎡未満 | I5: 80㎡以上 100㎡未満 | J5: 100㎡以上 | K5: 備考
A6: =B6&"|"&C6&"|"&D6 -> 無|木造|東京事務所職員等 | B6: 無 | C6: 木造 | D6: 東京事務所職員等 | E6: 0 | F6: 0 | G6: 0 | H6: 0 | I6: 0 | J6: 0 | K6: 原表に行なし。5年未満は控除なし(0円)として補完
A7: =B7&"|"&C7&"|"&D7 -> 無|木造|東京事務所職員等 | B7: 無 | C7: 木造 | D7: 東京事務所職員等 | E7: 5 | F7: 0 | G7: 0 | H7: 0 | I7: 0 | J7: 0
A8: =B8&"|"&C8&"|"&D8 -> 無|木造|東京事務所職員等 | B8: 無 | C8: 木造 | D8: 東京事務所職員等 | E8: 10 | F8: 0 | G8: 56 | H8: 0 | I8: 90 | J8: 165
A9: =B9&"|"&C9&"|"&D9 -> 無|木造|東京事務所職員等 | B9: 無 | C9: 木造 | D9: 東京事務所職員等 | E9: 15 | F9: 124 | G9: 156 | H9: 187 | I9: 233 | J9: 333
A10: =B10&"|"&C10&"|"&D10 -> 無|木造|東京事務所職員等 | B10: 無 | C10: 木造 | D10: 東京事務所職員等 | E10: 20 | F10: 186 | G10: 282 | H10: 279 | I10: 406 | J10: 581
A11: =B11&"|"&C11&"|"&D11 -> 無|木造|東京事務所職員等 | B11: 無 | C11: 木造 | D11: 東京事務所職員等 | E11: 25 | F11: 248 | G11: 348 | H11: 371 | I11: 532 | J11: 705
A12: =B12&"|"&C12&"|"&D12 -> 無|木造|東京事務所職員等 | B12: 無 | C12: 木造 | D12: 東京事務所職員等 | E12: 30 | F12: 312 | G12: 420 | H12: 385 | I12: 638 | J12: 843
A13: =B13&"|"&C13&"|"&D13 -> 無|木造|その他 | B13: 無 | C13: 木造 | D13: その他 | E13: 0 | F13: 0 | G13: 0 | H13: 0 | I13: 0 | J13: 0 | K13: 原表に行なし。5年未満は控除なし(0円)として補完
A14: =B14&"|"&C14&"|"&D14 -> 無|木造|その他 | B14: 無 | C14: 木造 | D14: その他 | E14: 5 | F14: 0 | G14: 0 | H14: 0 | I14: 0 | J14: 0
A15: =B15&"|"&C15&"|"&D15 -> 無|木造|その他 | B15: 無 | C15: 木造 | D15: その他 | E15: 10 | F15: 46 | G15: 76 | H15: 55 | I15: 133 | J15: 173
A16: =B16&"|"&C16&"|"&D16 -> 無|木造|その他 | B16: 無 | C16: 木造 | D16: その他 | E16: 15 | F16: 124 | G16: 172 | H16: 187 | I16: 263 | J16: 335
A17: =B17&"|"&C17&"|"&D17 -> 無|木造|その他 | B17: 無 | C17: 木造 | D17: その他 | E17: 20 | F17: 212 | G17: 292 | H17: 307 | I17: 433 | J17: 569
A18: =B18&"|"&C18&"|"&D18 -> 無|木造|その他 | B18: 無 | C18: 木造 | D18: その他 | E18: 25 | F18: 270 | G18: 356 | H18: 393 | I18: 553 | J18: 687
A19: =B19&"|"&C19&"|"&D19 -> 無|木造|その他 | B19: 無 | C19: 木造 | D19: その他 | E19: 30 | F19: 284 | G19: 404 | H19: 479 | I19: 655 | J19: 817
A20: =B20&"|"&C20&"|"&D20 -> 無|組積造|東京事務所職員等 | B20: 無 | C20: 組積造 | D20: 東京事務所職員等 | E20: 0 | F20: 0 | G20: 0 | H20: 0 | I20: 0 | J20: 0 | K20: 原表に行なし。5年未満は控除なし(0円)として補完
A21: =B21&"|"&C21&"|"&D21 -> 無|組積造|東京事務所職員等 | B21: 無 | C21: 組積造 | D21: 東京事務所職員等 | E21: 5 | F21: 0 | G21: 0 | H21: 0 | I21: 0 | J21: 0
A22: =B22&"|"&C22&"|"&D22 -> 無|組積造|東京事務所職員等 | B22: 無 | C22: 組積造 | D22: 東京事務所職員等 | E22: 10 | F22: 0 | G22: 0 | H22: 0 | I22: 0 | J22: 0
A23: =B23&"|"&C23&"|"&D23 -> 無|組積造|東京事務所職員等 | B23: 無 | C23: 組積造 | D23: 東京事務所職員等 | E23: 15 | F23: 124 | G23: 156 | H23: 187 | I23: 233 | J23: 280
A24: =B24&"|"&C24&"|"&D24 -> 無|組積造|東京事務所職員等 | B24: 無 | C24: 組積造 | D24: 東京事務所職員等 | E24: 20 | F24: 186 | G24: 233 | H24: 279 | I24: 349 | J24: 419
A25: =B25&"|"&C25&"|"&D25 -> 無|組積造|東京事務所職員等 | B25: 無 | C25: 組積造 | D25: 東京事務所職員等 | E25: 25 | F25: 217 | G25: 271 | H25: 325 | I25: 407 | J25: 488
A26: =B26&"|"&C26&"|"&D26 -> 無|組積造|東京事務所職員等 | B26: 無 | C26: 組積造 | D26: 東京事務所職員等 | E26: 30 | F26: 232 | G26: 290 | H26: 348 | I26: 435 | J26: 522
A27: =B27&"|"&C27&"|"&D27 -> 無|組積造|東京事務所職員等 | B27: 無 | C27: 組積造 | D27: 東京事務所職員等 | E27: 35 | F27: 248 | G27: 309 | H27: 371 | I27: 464 | J27: 557
A28: =B28&"|"&C28&"|"&D28 -> 無|組積造|その他 | B28: 無 | C28: 組積造 | D28: その他 | E28: 0 | F28: 0 | G28: 0 | H28: 0 | I28: 0 | J28: 0 | K28: 原表に行なし。5年未満は控除なし(0円)として補完
A29: =B29&"|"&C29&"|"&D29 -> 無|組積造|その他 | B29: 無 | C29: 組積造 | D29: その他 | E29: 5 | F29: 0 | G29: 0 | H29: 0 | I29: 0 | J29: 0
A30: =B30&"|"&C30&"|"&D30 -> 無|組積造|その他 | B30: 無 | C30: 組積造 | D30: その他 | E30: 10 | F30: 0 | G30: 0 | H30: 0 | I30: 0 | J30: 1
A31: =B31&"|"&C31&"|"&D31 -> 無|組積造|その他 | B31: 無 | C31: 組積造 | D31: その他 | E31: 15 | F31: 124 | G31: 156 | H31: 187 | I31: 233 | J31: 280
A32: =B32&"|"&C32&"|"&D32 -> 無|組積造|その他 | B32: 無 | C32: 組積造 | D32: その他 | E32: 20 | F32: 186 | G32: 233 | H32: 279 | I32: 349 | J32: 419
A33: =B33&"|"&C33&"|"&D33 -> 無|組積造|その他 | B33: 無 | C33: 組積造 | D33: その他 | E33: 25 | F33: 217 | G33: 271 | H33: 325 | I33: 407 | J33: 488
A34: =B34&"|"&C34&"|"&D34 -> 無|組積造|その他 | B34: 無 | C34: 組積造 | D34: その他 | E34: 30 | F34: 232 | G34: 290 | H34: 348 | I34: 435 | J34: 522
A35: =B35&"|"&C35&"|"&D35 -> 無|組積造|その他 | B35: 無 | C35: 組積造 | D35: その他 | E35: 35 | F35: 248 | G35: 309 | H35: 371 | I35: 464 | J35: 557
A36: =B36&"|"&C36&"|"&D36 -> 無|鉄骨・RC造|東京事務所職員等 | B36: 無 | C36: 鉄骨・RC造 | D36: 東京事務所職員等 | E36: 0 | F36: 0 | G36: 0 | H36: 0 | I36: 0 | J36: 0 | K36: 原表に行なし。5年未満は控除なし(0円)として補完
A37: =B37&"|"&C37&"|"&D37 -> 無|鉄骨・RC造|東京事務所職員等 | B37: 無 | C37: 鉄骨・RC造 | D37: 東京事務所職員等 | E37: 5 | F37: 0 | G37: 0 | H37: 0 | I37: 0 | J37: 0
A38: =B38&"|"&C38&"|"&D38 -> 無|鉄骨・RC造|東京事務所職員等 | B38: 無 | C38: 鉄骨・RC造 | D38: 東京事務所職員等 | E38: 10 | F38: 0 | G38: 0 | H38: 0 | I38: 0 | J38: 0
A39: =B39&"|"&C39&"|"&D39 -> 無|鉄骨・RC造|東京事務所職員等 | B39: 無 | C39: 鉄骨・RC造 | D39: 東京事務所職員等 | E39: 15 | F39: 83 | G39: 104 | H39: 125 | I39: 156 | J39: 188
A40: =B40&"|"&C40&"|"&D40 -> 無|鉄骨・RC造|東京事務所職員等 | B40: 無 | C40: 鉄骨・RC造 | D40: 東京事務所職員等 | E40: 20 | F40: 111 | G40: 139 | H40: 166 | I40: 208 | J40: 249
...

Sheet 区分設定
B1: 構造区分の読み替え表
B2: 10月シート「構造」列の表記 → 控除額表の構造区分。未登録の表記は「要確認」と表示されるので、下の空行に追加してください（青字・40行目まで有効）。
B3: ※「ＲＣ」「SRC」「鉄骨造」は実データに存在する表記。それ以外は予備として追加した読み替え（要綱の構造区分：木造／組積造／鉄骨・鉄筋コンクリート造及び鉄筋コンクリート造）。
B5: 構造（10月シートの表記） | C5: 構造区分
B6: ＲＣ | C6: 鉄骨・RC造
B7: SRC | C7: 鉄骨・RC造
B8: 鉄骨造 | C8: 鉄骨・RC造
B9: RC | C9: 鉄骨・RC造
B10: ＳＲＣ | C10: 鉄骨・RC造
B11: 鉄筋コンクリート造 | C11: 鉄骨・RC造
B12: 鉄骨鉄筋コンクリート造 | C12: 鉄骨・RC造
B13: Ｓ | C13: 鉄骨・RC造
B14: 木造 | C14: 木造
B15: Ｗ | C15: 木造
B16: 組積造 | C16: 組積造
... B19: 石造 | C19: 組積造
