Workbook

Sheet ホーム
B1: 共済掛金・負担金 管理ブック
B2: 報告書を1回入力すれば、検算・明細表・伝票入力へ反映されます（令和8年度）
B4: 対象ブロック | C4: 2026-10 月例 | D4: ← ここで月を切り替えると、下の集計・検算・伝票入力が切り替わります
B6: 進捗（対象ブロック） | C6: 団体数 | F6: チェック（対象ブロック） | G6: 団体数 | H6: 伝票入力へ出る行数
B7: 未受領 | C7: =COUNTIFS(報告入力!$A$7:$A$696,$C$4,報告入力!$C$7:$C$696,"未受領") -> 35 | F7: 検算：要確認 | G7: =COUNTIFS(報告入力!$A$7:$A$696,$C$4,報告入力!$D$7:$D$696,"要確認") -> 0 | H7: =COUNT(伝票入力!A7:A600) -> 0
B8: 受領済（入金待ち） | C8: =COUNTIFS(報告入力!$A$7:$A$696,$C$4,報告入力!$C$7:$C$696,"受領済") -> 8 | F8: 検算：問題なし | G8: =COUNTIFS(報告入力!$A$7:$A$696,$C$4,報告入力!$D$7:$D$696,"問題なし") -> 0
B9: 入金確認済（起票待ち） | C9: =COUNTIFS(報告入力!$A$7:$A$696,$C$4,報告入力!$C$7:$C$696,"入金確認済") -> 0 | F9: 検算：標準報酬月額が未入力 | G9: =COUNTIFS(報告入力!$A$7:$A$696,$C$4,報告入力!$D$7:$D$696,"標報未入力") -> 8
B10: 起票済 | C10: =COUNTIFS(報告入力!$A$7:$A$696,$C$4,報告入力!$C$7:$C$696,"起票済") -> 0 | F10: 入金：不一致 | G10: =COUNTIFS(報告入力!$A$7:$A$696,$C$4,報告入力!$F$7:$F$696,"不一致") -> 0
B11: 報告なし（対象外） | C11: =COUNTIFS(報告入力!$A$7:$A$696,$C$4,報告入力!$C$7:$C$696,"報告なし") -> 3 | F11: 入金：未入金（受領済） | G11: =COUNTIFS(報告入力!$A$7:$A$696,$C$4,報告入力!$F$7:$F$696,"未入金") -> 8
B12: 合計 | C12: =SUM(C7:C11) -> 46 | F12: 明細表との照合（報告入力の合計＝☆掛負収入の総計） | G12: =IF(SUMIFS(報告入力!$CF$7:$CF$696,報告入力!$A$7:$A$696,$C$4)=INDEX('☆掛負収入'!$G$1:$G$1200,INDEX(設定!$E$20:$E$34,MATCH($C$4,設定!$A$20:$A$34,0))+63)+INDEX('☆掛負収入'!$J$1:$J$1200,INDEX(設定!$E$20:$E$34,MATCH($C$4,設定!$A$20:$A$34,0))+63)+INDEX('☆掛負収入'!$M$1:$M$1200,INDEX(設定!$E$20:$E$34,MATCH($C$4,設定!$A$20:$A$34,0))+63)+INDEX('☆掛負収入'!$P$1:$P$1200,INDEX(設定!$E$20:$E$34,MATCH($C$4,設定!$A$20:$A$34,0))+63),"一致","差異あり") -> 一致
B15: 未受領の団体（報告待ち） | F15: 検算で要確認の団体 | H15: 最大乖離率
B16: =IFERROR(INDEX(検算!$A$7:$A$52,MATCH(1,検算!$AI$7:$AI$52,0)),"") -> 市長部局 | F16: =IFERROR(INDEX(検算!$A$7:$A$52,MATCH(1,検算!$AJ$7:$AJ$52,0)),"") | H16: =IFERROR(INDEX(検算!$AK$7:$AK$52,MATCH(1,検算!$AJ$7:$AJ$52,0)),"")
B17: =IFERROR(INDEX(検算!$A$7:$A$52,MATCH(2,検算!$AI$7:$AI$52,0)),"") -> 下水道局 | F17: =IFERROR(INDEX(検算!$A$7:$A$52,MATCH(2,検算!$AJ$7:$AJ$52,0)),"") | H17: =IFERROR(INDEX(検算!$AK$7:$AK$52,MATCH(2,検算!$AJ$7:$AJ$52,0)),"")
B18: =IFERROR(INDEX(検算!$A$7:$A$52,MATCH(3,検算!$AI$7:$AI$52,0)),"") -> 消防局 | F18: =IFERROR(INDEX(検算!$A$7:$A$52,MATCH(3,検算!$AJ$7:$AJ$52,0)),"") | H18: =IFERROR(INDEX(検算!$AK$7:$AK$52,MATCH(3,検算!$AJ$7:$AJ$52,0)),"")
B19: =IFERROR(INDEX(検算!$A$7:$A$52,MATCH(4,検算!$AI$7:$AI$52,0)),"") -> 議会事務局 | F19: =IFERROR(INDEX(検算!$A$7:$A$52,MATCH(4,検算!$AJ$7:$AJ$52,0)),"") | H19: =IFERROR(INDEX(検算!$AK$7:$AK$52,MATCH(4,検算!$AJ$7:$AJ$52,0)),"")
B20: =IFERROR(INDEX(検算!$A$7:$A$52,MATCH(5,検算!$AI$7:$AI$52,0)),"") -> 教育委員会（総務課） | F20: =IFERROR(INDEX(検算!$A$7:$A$52,MATCH(5,検算!$AJ$7:$AJ$52,0)),"") | H20: =IFERROR(INDEX(検算!$AK$7:$AK$52,MATCH(5,検算!$AJ$7:$AJ$52,0)),"")
B21: =IFERROR(INDEX(検算!$A$7:$A$52,MATCH(6,検算!$AI$7:$AI$52,0)),"") -> 選挙管理委員会 | F21: =IFERROR(INDEX(検算!$A$7:$A$52,MATCH(6,検算!$AJ$7:$AJ$52,0)),"") | H21: =IFERROR(INDEX(検算!$AK$7:$AK$52,MATCH(6,検算!$AJ$7:$AJ$52,0)),"")
B22: =IFERROR(INDEX(検算!$A$7:$A$52,MATCH(7,検算!$AI$7:$AI$52,0)),"") -> 人事委員会 | F22: =IFERROR(INDEX(検算!$A$7:$A$52,MATCH(7,検算!$AJ$7:$AJ$52,0)),"") | H22: =IFERROR(INDEX(検算!$AK$7:$AK$52,MATCH(7,検算!$AJ$7:$AJ$52,0)),"")
B23: =IFERROR(INDEX(検算!$A$7:$A$52,MATCH(8,検算!$AI$7:$AI$52,0)),"") -> 監査事務局 | F23: =IFERROR(INDEX(検算!$A$7:$A$52,MATCH(8,検算!$AJ$7:$AJ$52,0)),"") | H23: =IFERROR(INDEX(検算!$AK$7:$AK$52,MATCH(8,検算!$AJ$7:$AJ$52,0)),"")
B24: =IFERROR(INDEX(検算!$A$7:$A$52,MATCH(9,検算!$AI$7:$AI$52,0)),"") -> 農業委員会 | F24: =IFERROR(INDEX(検算!$A$7:$A$52,MATCH(9,検算!$AJ$7:$AJ$52,0)),"") | H24: =IFERROR(INDEX(検算!$AK$7:$AK$52,MATCH(9,検算!$AJ$7:$AJ$52,0)),"")
B25: =IFERROR(INDEX(検算!$A$7:$A$52,MATCH(10,検算!$AI$7:$AI$52,0)),"") -> 水道局 | F25: =IFERROR(INDEX(検算!$A$7:$A$52,MATCH(10,検算!$AJ$7:$AJ$52,0)),"") | H25: =IFERROR(INDEX(検算!$AK$7:$AK$52,MATCH(10,検算!$AJ$7:$AJ$52,0)),"")
B26: =IFERROR(INDEX(検算!$A$7:$A$52,MATCH(11,検算!$AI$7:$AI$52,0)),"") -> 医療政策課(安芸市民) | F26: =IFERROR(INDEX(検算!$A$7:$A$52,MATCH(11,検算!$AJ$7:$AJ$52,0)),"") | H26: =IFERROR(INDEX(検算!$AK$7:$AK$52,MATCH(11,検算!$AJ$7:$AJ$52,0)),"")
B27: =IFERROR(INDEX(検算!$A$7:$A$52,MATCH(12,検算!$AI$7:$AI$52,0)),"") -> 教育委員会（教育給与課） | F27: =IFERROR(INDEX(検算!$A$7:$A$52,MATCH(12,検算!$AJ$7:$AJ$52,0)),"") | H27: =IFERROR(INDEX(検算!$AK$7:$AK$52,MATCH(12,検算!$AJ$7:$AJ$52,0)),"")
B28: =IFERROR(INDEX(検算!$A$7:$A$52,MATCH(13,検算!$AI$7:$AI$52,0)),"") -> 平和文化センター | F28: =IFERROR(INDEX(検算!$A$7:$A$52,MATCH(13,検算!$AJ$7:$AJ$52,0)),"") | H28: =IFERROR(INDEX(検算!$AK$7:$AK$52,MATCH(13,検算!$AJ$7:$AJ$52,0)),"")
B29: =IFERROR(INDEX(検算!$A$7:$A$52,MATCH(14,検算!$AI$7:$AI$52,0)),"") -> 社会福祉事業団 | F29: =IFERROR(INDEX(検算!$A$7:$A$52,MATCH(14,検算!$AJ$7:$AJ$52,0)),"") | H29: =IFERROR(INDEX(検算!$AK$7:$AK$52,MATCH(14,検算!$AJ$7:$AJ$52,0)),"")
B30: =IFERROR(INDEX(検算!$A$7:$A$52,MATCH(15,検算!$AI$7:$AI$52,0)),"") -> 原爆障害対策協議会 | F30: =IFERROR(INDEX(検算!$A$7:$A$52,MATCH(15,検算!$AJ$7:$AJ$52,0)),"") | H30: =IFERROR(INDEX(検算!$AK$7:$AK$52,MATCH(15,検算!$AJ$7:$AJ$52,0)),"")
B32: ※一覧は最大15件まで表示します。全件は 報告入力／検算 シートで確認してください。
B34: ■ 毎月の流れ
B35: 1 報告書を受領 | C35: 報告入力：受領日を入力し、標準報酬月額（②）と報告書の金額（③）を入力します。1回の入力で下流すべてに反映されます。
B36: 2 検算（自動） | C36: 報告入力の「検算」列／検算シートに 問題なし・要確認 が自動表示されます。乖離率がしきい値（設定）以上で要確認（赤）。
B37: 3 明細表（自動反映） | C37: ☆掛負収入の該当月ブロックに金額が自動で入ります。色も自動：赤字＝未受領（前年値）／黒字＝受領済／緑＝入金確認済。
B38: 4 入金確認 | C38: 通帳の入金額を 報告入力の「通帳入金額」へ入力。期待額と一致すれば「一致」となり自動で入金確認済（緑）になります。
B39: 5 伝票入力 | C39: 伝票入力シートに、入金確認済の団体が伝票の入力順（経理区分→団体→貸方科目）で並びます。そのまま共済システムへ転記し、終えたら報告入力の「起票済」に○。
B41: ■ 色・用語
B42: 黄色セル | C42: 入力するセル（既存の運用で黄色＝入力と同じ意味）
B43: 灰色セル／灰色の列 | C43: 自動計算（入力しない）
B44: 状態 | C44: 未受領 → 受領済 → 入金確認済 → 起票済 の順に自動で進みます（受領日・通帳入金額・○の入力に応じて）
B45: 受領日欄 | C45: 日付／「済」（過去分）／「なし」（その月は報告のない団体）
B46: 仮置き（前年値） | C46: 未受領の間は、旧ファイルで赤字だった前年数値を明細表に表示し続けます（元の数値を変えないため）
B48: ■ 既存シートについて
...

Sheet 報告入力
A1: 報告入力（報告書を1回入力するだけ）
A2: 団体から届いた報告書の内容を、該当ブロックの黄色セルへ入力します。検算・明細表（☆掛負収入）・伝票入力へ自動で反映されます。
A3: 使い方：A列「ブロック」のフィルタで対象月を選んでください（現在は対象ブロックだけ表示）。灰色の列は計算用です（列グループ［＋］で開閉）。並べ替えは可。
A4: 受領日欄：報告書を受け取ったら日付を入力（過去分は「済」）。報告のない団体は「なし」。空欄の間は「未受領」＝前年の数値（仮置き）が明細表に表示されます。
C5: 自動判定 | G5: ①報告書の受領 | I5: ②標準報酬月額の総額（円）※検算用 | L5: ③報告書の金額（円） 長期（組合員／事業主）／短期／介護／子ども・子育て支援納付金 | W5: ④入金（通帳）の照合 | AG5: ⑤確認・起票 | AJ5: （計算用）未受領の間の仮置き（前年値） | AU5: （計算用）明細表へ反映する値 | BF5: （計算用）見込額＝標準報酬×料率 | BN5: （計算用）報告額の集計 | BV5: （計算用）乖離率
A6: ブロック | B6: 団体名 | C6: 状態 | D6: 検算 | E6: 前月比 | F6: 入金 | G6: 受領日 （日付／済／なし） | H6: 提出方法 | I6: 長期 | J6: 短期 | K6: 介護 | L6: 厚生年金 保険料 （組合員） | M6: 退職等年金 掛金 | N6: 厚生年金 保険料 （事業主） | O6: 退職等年金 負担金 | P6: 経過的長期 | Q6: 短期 掛金 | R6: 短期 負担金 | S6: 介護 掛金 | T6: 介護 負担金 | U6: 子ども・子育て 支援納付金 掛金 | V6: 子ども・子育て 支援納付金 負担金 | W6: 振込方式 | X6: 通帳 入金日 | Y6: 期待額① | Z6: 通帳入金額① | AA6: 期待額② | AB6: 通帳入金額② | AC6: 期待額③ | AD6: 通帳入金額③ | AE6: 期待額④ | AF6: 通帳入金額④ | AG6: 入金確認 （手動○） | AH6: 起票済 （○） | AI6: 備考 | AJ6: 仮置き1 | AK6: 仮置き2 | AL6: 仮置き3 | AM6: 仮置き4 | AN6: 仮置き5 | AO6: 仮置き6 | AP6: 仮置き7 | AQ6: 仮置き8 | AR6: 仮置き9 | AS6: 仮置き10 | AT6: 仮置き11 | AU6: 反映1 | AV6: 反映2 | AW6: 反映3 | AX6: 反映4 | AY6: 反映5 | AZ6: 反映6 | BA6: 反映7 | BB6: 反映8 | BC6: 反映9 | BD6: 反映10 | BE6: 反映11 | BF6: 見込長期掛金 | BG6: 見込長期負担金 | BH6: 見込短期掛金 | BI6: 見込短期負担金 | BJ6: 見込介護掛金 | BK6: 見込介護負担金 | BL6: 見込子子掛金 | BM6: 見込子子負担金 | BN6: 報告長期掛金 | BO6: 報告長期負担金 | BP6: 報告短期掛金 | BQ6: 報告短期負担金 | BR6: 報告介護掛金 | BS6: 報告介護負担金 | BT6: 報告子子掛金 | BU6: 報告子子負担金 | BV6: 乖離長期掛金 | BW6: 乖離長期負担金 | BX6: 乖離短期掛金 | BY6: 乖離短期負担金 | BZ6: 乖離介護掛金 | CA6: 乖離介護負担金 | CB6: 乖離子子掛金 | CC6: 乖離子子負担金 | CD6: 最大乖離 | CE6: 前月総額 | CF6: 当月総額 | CG6: キー | CH6: 検算対象 | CI6: 前ブロックID
A7: 2026-04 月例 | B7: 市長部局 | C7: =IF(G7="","未受領",IF(G7="なし","報告なし",IF(AH7="○","起票済",IF(OR(AG7="○",F7="一致",F7="入金不要"),"入金確認済","受領済")))) -> 入金確認済 | D7: =IF(OR(G7="",G7="なし"),"―",IF(CH7="N","対象外",IF(AND(I7="",J7="",K7=""),"標報未入力",IF(CD7>=設定!$B$4,"要確認","問題なし")))) -> 対象外 | E7: =IF(OR(G7="",G7="なし",CE7="",CF7=0),"―",IF(CF7=CE7,"前月同額",IF(CE7=0,"―",IF(ABS(CF7/CE7-1)>=設定!$B$5,"変動大 "&TEXT(CF7/CE7-1,"+0%;-0%"),"〇")))) -> ― | F7: =IF(OR(G7="",G7="なし"),"―",IF(CF7=0,"入金不要",IF(COUNT(Z7,AB7,AD7,AF7)=0,IF(AG7="○","手動確認","未入金"),IF(AND(N(Z7)=Y7,IF(AA7="",TRUE(),N(AB7)=AA7),IF(AC7="",TRUE(),N(AD7)=AC7),IF(AE7="",TRUE(),N(AF7)=AE7)),"一致","不一致")))) -> 手動確認 | G7: 済 | L7: 237888288 | M7: 19545382 | N7: 340368825 | O7: 18931427 | P7: 229767 | Q7: 172293834 | R7: 170938710 | S7: 15691597 | T7: 15239233 | U7: 3806352 | V7: 3733563 | W7: =IFERROR(INDEX(設定!$E$61:$E$106,MATCH(B7,設定!$B$61:$B$106,0)),"合算") -> 合算 | Y7: =IF(OR(G7="",G7="なし"),"",IF(W7="合算",CF7,IF(W7="掛金・負担金別",(AU7+AV7+AZ7+BB7+BD7),SUM(AU7:AY7)))) -> 998666978 | AA7: =IF(OR(G7="",G7="なし"),"",IF(W7="掛金・負担金別",(AW7+AX7+AY7+BA7+BC7+BE7),IF(W7="経理区分別",AZ7+BA7,""))) | AC7: =IF(OR(G7="",G7="なし"),"",IF(W7="経理区分別",BB7+BC7,"")) | AE7: =IF(OR(G7="",G7="なし"),"",IF(W7="経理区分別",BD7+BE7,"")) | AG7: ○ | AU7: =IF($G7="",AJ7,L7) -> 237888288 | AV7: =IF($G7="",AK7,M7) -> 19545382 | AW7: =IF($G7="",AL7,N7) -> 340368825 | AX7: =IF($G7="",AM7,O7) -> 18931427 | AY7: =IF($G7="",AN7,P7) -> 229767 | AZ7: =IF($G7="",AO7,Q7) -> 172293834 | BA7: =IF($G7="",AP7,R7) -> 170938710 | BB7: =IF($G7="",AQ7,S7) -> 15691597 | ... BE7: =IF($G7="",AT7,V7) -> 3733563 | BF7: =ROUNDDOWN(I7*設定!$B$10/1000,0)+ROUNDDOWN(I7*設定!$B$11/1000,0) -> 0 | BG7: =ROUNDDOWN(I7*設定!$C$10/1000,0)+ROUNDDOWN(I7*設定!$C$11/1000,0)+ROUNDDOWN(I7*設定!$C$12/1000,0) -> 0 | BH7: =ROUNDDOWN(J7*設定!$B$13/1000,0) -> 0 | BI7: =ROUNDDOWN(J7*設定!$C$13/1000,0) -> 0 | BJ7: =ROUNDDOWN(K7*設定!$B$14/1000,0) -> 0 | BK7: =ROUNDDOWN(K7*設定!$C$14/1000,0) -> 0 | BL7: =ROUNDDOWN(J7*設定!$B$15/1000,0) -> 0 | BM7: =ROUNDDOWN(J7*設定!$C$15/1000,0) -> 0 | BN7: =L7+M7 -> 257433670 | BO7: =N7+O7+P7 -> 359530019 | BP7: =Q7 -> 172293834 | BQ7: =R7 -> 170938710 | BR7: =S7 -> 15691597 | BS7: =T7 -> 15239233 | BT7: =U7 -> 3806352 | BU7: =V7 -> 3733563 | BV7: =IF(BF7=0,IF(BN7=0,0,1),(BN7-BF7)/BF7) -> 1 | BW7: =IF(BG7=0,IF(BO7=0,0,1),(BO7-BG7)/BG7) -> 1 | BX7: =IF(BH7=0,IF(BP7=0,0,1),(BP7-BH7)/BH7) -> 1 | BY7: =IF(BI7=0,IF(BQ7=0,0,1),(BQ7-BI7)/BI7) -> 1 | BZ7: =IF(BJ7=0,IF(BR7=0,0,1),(BR7-BJ7)/BJ7) -> 1 | CA7: =IF(BK7=0,IF(BS7=0,0,1),(BS7-BK7)/BK7) -> 1 | CB7: =IF(BL7=0,IF(BT7=0,0,1),(BT7-BL7)/BL7) -> 1 | CC7: =IF(BM7=0,IF(BU7=0,0,1),(BU7-BM7)/BM7) -> 1 | CD7: =MAX(MAX(BV7:CC7),-MIN(BV7:CC7)) -> 1 | CE7: =IF(CI7="","",SUMIFS($CF$7:$CF$696,$A$7:$A$696,CI7,$B$7:$B$696,B7)) | CF7: =SUM(AU7:BE7) -> 998666978 | CG7: =A7&"|"&B7 -> 2026-04 月例|市長部局 | CH7: =IFERROR(INDEX(設定!$D$61:$D$106,MATCH(B7,設定!$B$61:$B$106,0)),"Y") -> N | CI7: =IFERROR(INDEX(設定!$D$20:$D$34,MATCH(A7,設定!$A$20:$A$34,0))&"","")
A8: 2026-04 月例 | B8: 下水道局 | C8: =IF(G8="","未受領",IF(G8="なし","報告なし",IF(AH8="○","起票済",IF(OR(AG8="○",F8="一致",F8="入金不要"),"入金確認済","受領済")))) -> 入金確認済 | D8: =IF(OR(G8="",G8="なし"),"―",IF(CH8="N","対象外",IF(AND(I8="",J8="",K8=""),"標報未入力",IF(CD8>=設定!$B$4,"要確認","問題なし")))) -> 標報未入力 | E8: =IF(OR(G8="",G8="なし",CE8="",CF8=0),"―",IF(CF8=CE8,"前月同額",IF(CE8=0,"―",IF(ABS(CF8/CE8-1)>=設定!$B$5,"変動大 "&TEXT(CF8/CE8-1,"+0%;-0%"),"〇")))) -> ― | F8: =IF(OR(G8="",G8="なし"),"―",IF(CF8=0,"入金不要",IF(COUNT(Z8,AB8,AD8,AF8)=0,IF(AG8="○","手動確認","未入金"),IF(AND(N(Z8)=Y8,IF(AA8="",TRUE(),N(AB8)=AA8),IF(AC8="",TRUE(),N(AD8)=AC8),IF(AE8="",TRUE(),N(AF8)=AE8)),"一致","不一致")))) -> 手動確認 | G8: 済 | L8: 16501383 | M8: 1352571 | N8: 23660244 | O8: 1344682 | P8: 15795 | Q8: 9654896 | R8: 9790061 | S8: 1025788 | T8: 1025788 | U8: 214057 | V8: 214129 | W8: =IFERROR(INDEX(設定!$E$61:$E$106,MATCH(B8,設定!$B$61:$B$106,0)),"合算") -> 合算 | Y8: =IF(OR(G8="",G8="なし"),"",IF(W8="合算",CF8,IF(W8="掛金・負担金別",(AU8+AV8+AZ8+BB8+BD8),SUM(AU8:AY8)))) -> 64799394 | AA8: =IF(OR(G8="",G8="なし"),"",IF(W8="掛金・負担金別",(AW8+AX8+AY8+BA8+BC8+BE8),IF(W8="経理区分別",AZ8+BA8,""))) | AC8: =IF(OR(G8="",G8="なし"),"",IF(W8="経理区分別",BB8+BC8,"")) | AE8: =IF(OR(G8="",G8="なし"),"",IF(W8="経理区分別",BD8+BE8,"")) | AG8: ○ | AU8: =IF($G8="",AJ8,L8) -> 16501383 | AV8: =IF($G8="",AK8,M8) -> 1352571 | AW8: =IF($G8="",AL8,N8) -> 23660244 | AX8: =IF($G8="",AM8,O8) -> 1344682 | AY8: =IF($G8="",AN8,P8) -> 15795 | AZ8: =IF($G8="",AO8,Q8) -> 9654896 | BA8: =IF($G8="",AP8,R8) -> 9790061 | BB8: =IF($G8="",AQ8,S8) -> 1025788 | ... BE8: =IF($G8="",AT8,V8) -> 214129 | BF8: =ROUNDDOWN(I8*設定!$B$10/1000,0)+ROUNDDOWN(I8*設定!$B$11/1000,0) -> 0 | BG8: =ROUNDDOWN(I8*設定!$C$10/1000,0)+ROUNDDOWN(I8*設定!$C$11/1000,0)+ROUNDDOWN(I8*設定!$C$12/1000,0) -> 0 | BH8: =ROUNDDOWN(J8*設定!$B$13/1000,0) -> 0 | BI8: =ROUNDDOWN(J8*設定!$C$13/1000,0) -> 0 | BJ8: =ROUNDDOWN(K8*設定!$B$14/1000,0) -> 0 | BK8: =ROUNDDOWN(K8*設定!$C$14/1000,0) -> 0 | BL8: =ROUNDDOWN(J8*設定!$B$15/1000,0) -> 0 | BM8: =ROUNDDOWN(J8*設定!$C$15/1000,0) -> 0 | BN8: =L8+M8 -> 17853954 | BO8: =N8+O8+P8 -> 25020721 | BP8: =Q8 -> 9654896 | BQ8: =R8 -> 9790061 | BR8: =S8 -> 1025788 | BS8: =T8 -> 1025788 | BT8: =U8 -> 214057 | BU8: =V8 -> 214129 | BV8: =IF(BF8=0,IF(BN8=0,0,1),(BN8-BF8)/BF8) -> 1 | BW8: =IF(BG8=0,IF(BO8=0,0,1),(BO8-BG8)/BG8) -> 1 | BX8: =IF(BH8=0,IF(BP8=0,0,1),(BP8-BH8)/BH8) -> 1 | BY8: =IF(BI8=0,IF(BQ8=0,0,1),(BQ8-BI8)/BI8) -> 1 | BZ8: =IF(BJ8=0,IF(BR8=0,0,1),(BR8-BJ8)/BJ8) -> 1 | CA8: =IF(BK8=0,IF(BS8=0,0,1),(BS8-BK8)/BK8) -> 1 | CB8: =IF(BL8=0,IF(BT8=0,0,1),(BT8-BL8)/BL8) -> 1 | CC8: =IF(BM8=0,IF(BU8=0,0,1),(BU8-BM8)/BM8) -> 1 | CD8: =MAX(MAX(BV8:CC8),-MIN(BV8:CC8)) -> 1 | CE8: =IF(CI8="","",SUMIFS($CF$7:$CF$696,$A$7:$A$696,CI8,$B$7:$B$696,B8)) | CF8: =SUM(AU8:BE8) -> 64799394 | CG8: =A8&"|"&B8 -> 2026-04 月例|下水道局 | CH8: =IFERROR(INDEX(設定!$D$61:$D$106,MATCH(B8,設定!$B$61:$B$106,0)),"Y") -> Y | CI8: =IFERROR(INDEX(設定!$D$20:$D$34,MATCH(A8,設定!$A$20:$A$34,0))&"","")
A9: 2026-04 月例 | B9: 消防局 | C9: =IF(G9="","未受領",IF(G9="なし","報告なし",IF(AH9="○","起票済",IF(OR(AG9="○",F9="一致",F9="入金不要"),"入金確認済","受領済")))) -> 入金確認済 | D9: =IF(OR(G9="",G9="なし"),"―",IF(CH9="N","対象外",IF(AND(I9="",J9="",K9=""),"標報未入力",IF(CD9>=設定!$B$4,"要確認","問題なし")))) -> 対象外 | E9: =IF(OR(G9="",G9="なし",CE9="",CF9=0),"―",IF(CF9=CE9,"前月同額",IF(CE9=0,"―",IF(ABS(CF9/CE9-1)>=設定!$B$5,"変動大 "&TEXT(CF9/CE9-1,"+0%;-0%"),"〇")))) -> ― | F9: =IF(OR(G9="",G9="なし"),"―",IF(CF9=0,"入金不要",IF(COUNT(Z9,AB9,AD9,AF9)=0,IF(AG9="○","手動確認","未入金"),IF(AND(N(Z9)=Y9,IF(AA9="",TRUE(),N(AB9)=AA9),IF(AC9="",TRUE(),N(AD9)=AC9),IF(AE9="",TRUE(),N(AF9)=AE9)),"一致","不一致")))) -> 手動確認 | G9: 済 | L9: 55191060 | M9: 4523856 | N9: 79301786 | O9: 4501510 | P9: 52817 | Q9: 31993182 | R9: 32380013 | S9: 2034923 | T9: 2021968 | U9: 709341 | V9: 707179 | W9: =IFERROR(INDEX(設定!$E$61:$E$106,MATCH(B9,設定!$B$61:$B$106,0)),"合算") -> 合算 | Y9: =IF(OR(G9="",G9="なし"),"",IF(W9="合算",CF9,IF(W9="掛金・負担金別",(AU9+AV9+AZ9+BB9+BD9),SUM(AU9:AY9)))) -> 213417635 | AA9: =IF(OR(G9="",G9="なし"),"",IF(W9="掛金・負担金別",(AW9+AX9+AY9+BA9+BC9+BE9),IF(W9="経理区分別",AZ9+BA9,""))) | AC9: =IF(OR(G9="",G9="なし"),"",IF(W9="経理区分別",BB9+BC9,"")) | AE9: =IF(OR(G9="",G9="なし"),"",IF(W9="経理区分別",BD9+BE9,"")) | AG9: ○ | AU9: =IF($G9="",AJ9,L9) -> 55191060 | AV9: =IF($G9="",AK9,M9) -> 4523856 | AW9: =IF($G9="",AL9,N9) -> 79301786 | AX9: =IF($G9="",AM9,O9) -> 4501510 | AY9: =IF($G9="",AN9,P9) -> 52817 | AZ9: =IF($G9="",AO9,Q9) -> 31993182 | BA9: =IF($G9="",AP9,R9) -> 32380013 | BB9: =IF($G9="",AQ9,S9) -> 2034923 | ... BE9: =IF($G9="",AT9,V9) -> 707179 | BF9: =ROUNDDOWN(I9*設定!$B$10/1000,0)+ROUNDDOWN(I9*設定!$B$11/1000,0) -> 0 | BG9: =ROUNDDOWN(I9*設定!$C$10/1000,0)+ROUNDDOWN(I9*設定!$C$11/1000,0)+ROUNDDOWN(I9*設定!$C$12/1000,0) -> 0 | BH9: =ROUNDDOWN(J9*設定!$B$13/1000,0) -> 0 | BI9: =ROUNDDOWN(J9*設定!$C$13/1000,0) -> 0 | BJ9: =ROUNDDOWN(K9*設定!$B$14/1000,0) -> 0 | BK9: =ROUNDDOWN(K9*設定!$C$14/1000,0) -> 0 | BL9: =ROUNDDOWN(J9*設定!$B$15/1000,0) -> 0 | BM9: =ROUNDDOWN(J9*設定!$C$15/1000,0) -> 0 | BN9: =L9+M9 -> 59714916 | BO9: =N9+O9+P9 -> 83856113 | BP9: =Q9 -> 31993182 | BQ9: =R9 -> 32380013 | BR9: =S9 -> 2034923 | BS9: =T9 -> 2021968 | BT9: =U9 -> 709341 | BU9: =V9 -> 707179 | BV9: =IF(BF9=0,IF(BN9=0,0,1),(BN9-BF9)/BF9) -> 1 | BW9: =IF(BG9=0,IF(BO9=0,0,1),(BO9-BG9)/BG9) -> 1 | BX9: =IF(BH9=0,IF(BP9=0,0,1),(BP9-BH9)/BH9) -> 1 | BY9: =IF(BI9=0,IF(BQ9=0,0,1),(BQ9-BI9)/BI9) -> 1 | BZ9: =IF(BJ9=0,IF(BR9=0,0,1),(BR9-BJ9)/BJ9) -> 1 | CA9: =IF(BK9=0,IF(BS9=0,0,1),(BS9-BK9)/BK9) -> 1 | CB9: =IF(BL9=0,IF(BT9=0,0,1),(BT9-BL9)/BL9) -> 1 | CC9: =IF(BM9=0,IF(BU9=0,0,1),(BU9-BM9)/BM9) -> 1 | CD9: =MAX(MAX(BV9:CC9),-MIN(BV9:CC9)) -> 1 | CE9: =IF(CI9="","",SUMIFS($CF$7:$CF$696,$A$7:$A$696,CI9,$B$7:$B$696,B9)) | CF9: =SUM(AU9:BE9) -> 213417635 | CG9: =A9&"|"&B9 -> 2026-04 月例|消防局 | CH9: =IFERROR(INDEX(設定!$D$61:$D$106,MATCH(B9,設定!$B$61:$B$106,0)),"Y") -> N | CI9: =IFERROR(INDEX(設定!$D$20:$D$34,MATCH(A9,設定!$A$20:$A$34,0))&"","")
A10: 2026-04 月例 | B10: 議会事務局 | C10: =IF(G10="","未受領",IF(G10="なし","報告なし",IF(AH10="○","起票済",IF(OR(AG10="○",F10="一致",F10="入金不要"),"入金確認済","受領済")))) -> 入金確認済 | D10: =IF(OR(G10="",G10="なし"),"―",IF(CH10="N","対象外",IF(AND(I10="",J10="",K10=""),"標報未入力",IF(CD10>=設定!$B$4,"要確認","問題なし")))) -> 標報未入力 | E10: =IF(OR(G10="",G10="なし",CE10="",CF10=0),"―",IF(CF10=CE10,"前月同額",IF(CE10=0,"―",IF(ABS(CF10/CE10-1)>=設定!$B$5,"変動大 "&TEXT(CF10/CE10-1,"+0%;-0%"),"〇")))) -> ― | F10: =IF(OR(G10="",G10="なし"),"―",IF(CF10=0,"入金不要",IF(COUNT(Z10,AB10,AD10,AF10)=0,IF(AG10="○","手動確認","未入金"),IF(AND(N(Z10)=Y10,IF(AA10="",TRUE(),N(AB10)=AA10),IF(AC10="",TRUE(),N(AD10)=AC10),IF(AE10="",TRUE(),N(AF10)=AE10)),"一致","不一致")))) -> 手動確認 | G10: 済 | L10: 1810785 | M10: 148425 | N10: 2609982 | O10: 148425 | P10: 1740 | Q10: 1059618 | R10: 1069678 | S10: 103520 | T10: 102399 | U10: 23316 | V10: 23324 | W10: =IFERROR(INDEX(設定!$E$61:$E$106,MATCH(B10,設定!$B$61:$B$106,0)),"合算") -> 合算 | Y10: =IF(OR(G10="",G10="なし"),"",IF(W10="合算",CF10,IF(W10="掛金・負担金別",(AU10+AV10+AZ10+BB10+BD10),SUM(AU10:AY10)))) -> 7101212 | AA10: =IF(OR(G10="",G10="なし"),"",IF(W10="掛金・負担金別",(AW10+AX10+AY10+BA10+BC10+BE10),IF(W10="経理区分別",AZ10+BA10,""))) | AC10: =IF(OR(G10="",G10="なし"),"",IF(W10="経理区分別",BB10+BC10,"")) | AE10: =IF(OR(G10="",G10="なし"),"",IF(W10="経理区分別",BD10+BE10,"")) | AG10: ○ | AU10: =IF($G10="",AJ10,L10) -> 1810785 | AV10: =IF($G10="",AK10,M10) -> 148425 | AW10: =IF($G10="",AL10,N10) -> 2609982 | AX10: =IF($G10="",AM10,O10) -> 148425 | AY10: =IF($G10="",AN10,P10) -> 1740 | AZ10: =IF($G10="",AO10,Q10) -> 1059618 | BA10: =IF($G10="",AP10,R10) -> 1069678 | BB10: =IF($G10="",AQ10,S10) -> 103520 | ... BE10: =IF($G10="",AT10,V10) -> 23324 | BF10: =ROUNDDOWN(I10*設定!$B$10/1000,0)+ROUNDDOWN(I10*設定!$B$11/1000,0) -> 0 | BG10: =ROUNDDOWN(I10*設定!$C$10/1000,0)+ROUNDDOWN(I10*設定!$C$11/1000,0)+ROUNDDOWN(I10*設定!$C$12/1000,0) -> 0 | BH10: =ROUNDDOWN(J10*設定!$B$13/1000,0) -> 0 | BI10: =ROUNDDOWN(J10*設定!$C$13/1000,0) -> 0 | BJ10: =ROUNDDOWN(K10*設定!$B$14/1000,0) -> 0 | BK10: =ROUNDDOWN(K10*設定!$C$14/1000,0) -> 0 | BL10: =ROUNDDOWN(J10*設定!$B$15/1000,0) -> 0 | BM10: =ROUNDDOWN(J10*設定!$C$15/1000,0) -> 0 | BN10: =L10+M10 -> 1959210 | BO10: =N10+O10+P10 -> 2760147 | BP10: =Q10 -> 1059618 | BQ10: =R10 -> 1069678 | BR10: =S10 -> 103520 | BS10: =T10 -> 102399 | BT10: =U10 -> 23316 | BU10: =V10 -> 23324 | BV10: =IF(BF10=0,IF(BN10=0,0,1),(BN10-BF10)/BF10) -> 1 | BW10: =IF(BG10=0,IF(BO10=0,0,1),(BO10-BG10)/BG10) -> 1 | BX10: =IF(BH10=0,IF(BP10=0,0,1),(BP10-BH10)/BH10) -> 1 | BY10: =IF(BI10=0,IF(BQ10=0,0,1),(BQ10-BI10)/BI10) -> 1 | BZ10: =IF(BJ10=0,IF(BR10=0,0,1),(BR10-BJ10)/BJ10) -> 1 | CA10: =IF(BK10=0,IF(BS10=0,0,1),(BS10-BK10)/BK10) -> 1 | CB10: =IF(BL10=0,IF(BT10=0,0,1),(BT10-BL10)/BL10) -> 1 | CC10: =IF(BM10=0,IF(BU10=0,0,1),(BU10-BM10)/BM10) -> 1 | CD10: =MAX(MAX(BV10:CC10),-MIN(BV10:CC10)) -> 1 | CE10: =IF(CI10="","",SUMIFS($CF$7:$CF$696,$A$7:$A$696,CI10,$B$7:$B$696,B10)) | CF10: =SUM(AU10:BE10) -> 7101212 | CG10: =A10&"|"&B10 -> 2026-04 月例|議会事務局 | CH10: =IFERROR(INDEX(設定!$D$61:$D$106,MATCH(B10,設定!$B$61:$B$106,0)),"Y") -> Y | CI10: =IFERROR(INDEX(設定!$D$20:$D$34,MATCH(A10,設定!$A$20:$A$34,0))&"","")
A11: 2026-04 月例 | B11: 教育委員会（総務課） | C11: =IF(G11="","未受領",IF(G11="なし","報告なし",IF(AH11="○","起票済",IF(OR(AG11="○",F11="一致",F11="入金不要"),"入金確認済","受領済")))) -> 入金確認済 | D11: =IF(OR(G11="",G11="なし"),"―",IF(CH11="N","対象外",IF(AND(I11="",J11="",K11=""),"標報未入力",IF(CD11>=設定!$B$4,"要確認","問題なし")))) -> 対象外 | E11: =IF(OR(G11="",G11="なし",CE11="",CF11=0),"―",IF(CF11=CE11,"前月同額",IF(CE11=0,"―",IF(ABS(CF11/CE11-1)>=設定!$B$5,"変動大 "&TEXT(CF11/CE11-1,"+0%;-0%"),"〇")))) -> ― | F11: =IF(OR(G11="",G11="なし"),"―",IF(CF11=0,"入金不要",IF(COUNT(Z11,AB11,AD11,AF11)=0,IF(AG11="○","手動確認","未入金"),IF(AND(N(Z11)=Y11,IF(AA11="",TRUE(),N(AB11)=AA11),IF(AC11="",TRUE(),N(AD11)=AC11),IF(AE11="",TRUE(),N(AF11)=AE11)),"一致","不一致")))) -> 手動確認 | G11: 済 | L11: 23624294 | M11: 1936418 | N11: 33978096 | O11: 1934423 | P11: 22597 | Q11: 23056933 | R11: 23380527 | S11: 2704450 | T11: 2700114 | U11: 510014 | V11: 511951 | W11: =IFERROR(INDEX(設定!$E$61:$E$106,MATCH(B11,設定!$B$61:$B$106,0)),"合算") -> 合算 | Y11: =IF(OR(G11="",G11="なし"),"",IF(W11="合算",CF11,IF(W11="掛金・負担金別",(AU11+AV11+AZ11+BB11+BD11),SUM(AU11:AY11)))) -> 114359817 | AA11: =IF(OR(G11="",G11="なし"),"",IF(W11="掛金・負担金別",(AW11+AX11+AY11+BA11+BC11+BE11),IF(W11="経理区分別",AZ11+BA11,""))) | AC11: =IF(OR(G11="",G11="なし"),"",IF(W11="経理区分別",BB11+BC11,"")) | AE11: =IF(OR(G11="",G11="なし"),"",IF(W11="経理区分別",BD11+BE11,"")) | AG11: ○ | AU11: =IF($G11="",AJ11,L11) -> 23624294 | AV11: =IF($G11="",AK11,M11) -> 1936418 | AW11: =IF($G11="",AL11,N11) -> 33978096 | AX11: =IF($G11="",AM11,O11) -> 1934423 | AY11: =IF($G11="",AN11,P11) -> 22597 | AZ11: =IF($G11="",AO11,Q11) -> 23056933 | BA11: =IF($G11="",AP11,R11) -> 23380527 | BB11: =IF($G11="",AQ11,S11) -> 2704450 | ... BE11: =IF($G11="",AT11,V11) -> 511951 | BF11: =ROUNDDOWN(I11*設定!$B$10/1000,0)+ROUNDDOWN(I11*設定!$B$11/1000,0) -> 0 | BG11: =ROUNDDOWN(I11*設定!$C$10/1000,0)+ROUNDDOWN(I11*設定!$C$11/1000,0)+ROUNDDOWN(I11*設定!$C$12/1000,0) -> 0 | BH11: =ROUNDDOWN(J11*設定!$B$13/1000,0) -> 0 | BI11: =ROUNDDOWN(J11*設定!$C$13/1000,0) -> 0 | BJ11: =ROUNDDOWN(K11*設定!$B$14/1000,0) -> 0 | BK11: =ROUNDDOWN(K11*設定!$C$14/1000,0) -> 0 | BL11: =ROUNDDOWN(J11*設定!$B$15/1000,0) -> 0 | BM11: =ROUNDDOWN(J11*設定!$C$15/1000,0) -> 0 | BN11: =L11+M11 -> 25560712 | BO11: =N11+O11+P11 -> 35935116 | BP11: =Q11 -> 23056933 | BQ11: =R11 -> 23380527 | BR11: =S11 -> 2704450 | BS11: =T11 -> 2700114 | BT11: =U11 -> 510014 | BU11: =V11 -> 511951 | BV11: =IF(BF11=0,IF(BN11=0,0,1),(BN11-BF11)/BF11) -> 1 | BW11: =IF(BG11=0,IF(BO11=0,0,1),(BO11-BG11)/BG11) -> 1 | BX11: =IF(BH11=0,IF(BP11=0,0,1),(BP11-BH11)/BH11) -> 1 | BY11: =IF(BI11=0,IF(BQ11=0,0,1),(BQ11-BI11)/BI11) -> 1 | BZ11: =IF(BJ11=0,IF(BR11=0,0,1),(BR11-BJ11)/BJ11) -> 1 | CA11: =IF(BK11=0,IF(BS11=0,0,1),(BS11-BK11)/BK11) -> 1 | CB11: =IF(BL11=0,IF(BT11=0,0,1),(BT11-BL11)/BL11) -> 1 | CC11: =IF(BM11=0,IF(BU11=0,0,1),(BU11-BM11)/BM11) -> 1 | CD11: =MAX(MAX(BV11:CC11),-MIN(BV11:CC11)) -> 1 | CE11: =IF(CI11="","",SUMIFS($CF$7:$CF$696,$A$7:$A$696,CI11,$B$7:$B$696,B11)) | CF11: =SUM(AU11:BE11) -> 114359817 | CG11: =A11&"|"&B11 -> 2026-04 月例|教育委員会（総務課） | CH11: =IFERROR(INDEX(設定!$D$61:$D$106,MATCH(B11,設定!$B$61:$B$106,0)),"Y") -> N | CI11: =IFERROR(INDEX(設定!$D$20:$D$34,MATCH(A11,設定!$A$20:$A$34,0))&"","")
A12: 2026-04 月例 | B12: 選挙管理委員会 | C12: =IF(G12="","未受領",IF(G12="なし","報告なし",IF(AH12="○","起票済",IF(OR(AG12="○",F12="一致",F12="入金不要"),"入金確認済","受領済")))) -> 入金確認済 | D12: =IF(OR(G12="",G12="なし"),"―",IF(CH12="N","対象外",IF(AND(I12="",J12="",K12=""),"標報未入力",IF(CD12>=設定!$B$4,"要確認","問題なし")))) -> 標報未入力 | E12: =IF(OR(G12="",G12="なし",CE12="",CF12=0),"―",IF(CF12=CE12,"前月同額",IF(CE12=0,"―",IF(ABS(CF12/CE12-1)>=設定!$B$5,"変動大 "&TEXT(CF12/CE12-1,"+0%;-0%"),"〇")))) -> ― | F12: =IF(OR(G12="",G12="なし"),"―",IF(CF12=0,"入金不要",IF(COUNT(Z12,AB12,AD12,AF12)=0,IF(AG12="○","手動確認","未入金"),IF(AND(N(Z12)=Y12,IF(AA12="",TRUE(),N(AB12)=AA12),IF(AC12="",TRUE(),N(AD12)=AC12),IF(AE12="",TRUE(),N(AF12)=AE12)),"一致","不一致")))) -> 手動確認 | G12: 済 | L12: 326655 | M12: 26775 | N12: 469098 | O12: 26775 | P12: 310 | Q12: 205363 | R12: 208810 | S12: 15800 | T12: 15800 | U12: 4552 | V12: 4553 | W12: =IFERROR(INDEX(設定!$E$61:$E$106,MATCH(B12,設定!$B$61:$B$106,0)),"合算") -> 合算 | Y12: =IF(OR(G12="",G12="なし"),"",IF(W12="合算",CF12,IF(W12="掛金・負担金別",(AU12+AV12+AZ12+BB12+BD12),SUM(AU12:AY12)))) -> 1304491 | AA12: =IF(OR(G12="",G12="なし"),"",IF(W12="掛金・負担金別",(AW12+AX12+AY12+BA12+BC12+BE12),IF(W12="経理区分別",AZ12+BA12,""))) | AC12: =IF(OR(G12="",G12="なし"),"",IF(W12="経理区分別",BB12+BC12,"")) | AE12: =IF(OR(G12="",G12="なし"),"",IF(W12="経理区分別",BD12+BE12,"")) | AG12: ○ | AU12: =IF($G12="",AJ12,L12) -> 326655 | AV12: =IF($G12="",AK12,M12) -> 26775 | AW12: =IF($G12="",AL12,N12) -> 469098 | AX12: =IF($G12="",AM12,O12) -> 26775 | AY12: =IF($G12="",AN12,P12) -> 310 | AZ12: =IF($G12="",AO12,Q12) -> 205363 | BA12: =IF($G12="",AP12,R12) -> 208810 | BB12: =IF($G12="",AQ12,S12) -> 15800 | ... BE12: =IF($G12="",AT12,V12) -> 4553 | BF12: =ROUNDDOWN(I12*設定!$B$10/1000,0)+ROUNDDOWN(I12*設定!$B$11/1000,0) -> 0 | BG12: =ROUNDDOWN(I12*設定!$C$10/1000,0)+ROUNDDOWN(I12*設定!$C$11/1000,0)+ROUNDDOWN(I12*設定!$C$12/1000,0) -> 0 | BH12: =ROUNDDOWN(J12*設定!$B$13/1000,0) -> 0 | BI12: =ROUNDDOWN(J12*設定!$C$13/1000,0) -> 0 | BJ12: =ROUNDDOWN(K12*設定!$B$14/1000,0) -> 0 | BK12: =ROUNDDOWN(K12*設定!$C$14/1000,0) -> 0 | BL12: =ROUNDDOWN(J12*設定!$B$15/1000,0) -> 0 | BM12: =ROUNDDOWN(J12*設定!$C$15/1000,0) -> 0 | BN12: =L12+M12 -> 353430 | BO12: =N12+O12+P12 -> 496183 | BP12: =Q12 -> 205363 | BQ12: =R12 -> 208810 | BR12: =S12 -> 15800 | BS12: =T12 -> 15800 | BT12: =U12 -> 4552 | BU12: =V12 -> 4553 | BV12: =IF(BF12=0,IF(BN12=0,0,1),(BN12-BF12)/BF12) -> 1 | BW12: =IF(BG12=0,IF(BO12=0,0,1),(BO12-BG12)/BG12) -> 1 | BX12: =IF(BH12=0,IF(BP12=0,0,1),(BP12-BH12)/BH12) -> 1 | BY12: =IF(BI12=0,IF(BQ12=0,0,1),(BQ12-BI12)/BI12) -> 1 | BZ12: =IF(BJ12=0,IF(BR12=0,0,1),(BR12-BJ12)/BJ12) -> 1 | CA12: =IF(BK12=0,IF(BS12=0,0,1),(BS12-BK12)/BK12) -> 1 | CB12: =IF(BL12=0,IF(BT12=0,0,1),(BT12-BL12)/BL12) -> 1 | CC12: =IF(BM12=0,IF(BU12=0,0,1),(BU12-BM12)/BM12) -> 1 | CD12: =MAX(MAX(BV12:CC12),-MIN(BV12:CC12)) -> 1 | CE12: =IF(CI12="","",SUMIFS($CF$7:$CF$696,$A$7:$A$696,CI12,$B$7:$B$696,B12)) | CF12: =SUM(AU12:BE12) -> 1304491 | CG12: =A12&"|"&B12 -> 2026-04 月例|選挙管理委員会 | CH12: =IFERROR(INDEX(設定!$D$61:$D$106,MATCH(B12,設定!$B$61:$B$106,0)),"Y") -> Y | CI12: =IFERROR(INDEX(設定!$D$20:$D$34,MATCH(A12,設定!$A$20:$A$34,0))&"","")
A13: 2026-04 月例 | B13: 人事委員会 | C13: =IF(G13="","未受領",IF(G13="なし","報告なし",IF(AH13="○","起票済",IF(OR(AG13="○",F13="一致",F13="入金不要"),"入金確認済","受領済")))) -> 入金確認済 | D13: =IF(OR(G13="",G13="なし"),"―",IF(CH13="N","対象外",IF(AND(I13="",J13="",K13=""),"標報未入力",IF(CD13>=設定!$B$4,"要確認","問題なし")))) -> 標報未入力 | E13: =IF(OR(G13="",G13="なし",CE13="",CF13=0),"―",IF(CF13=CE13,"前月同額",IF(CE13=0,"―",IF(ABS(CF13/CE13-1)>=設定!$B$5,"変動大 "&TEXT(CF13/CE13-1,"+0%;-0%"),"〇")))) -> ― | F13: =IF(OR(G13="",G13="なし"),"―",IF(CF13=0,"入金不要",IF(COUNT(Z13,AB13,AD13,AF13)=0,IF(AG13="○","手動確認","未入金"),IF(AND(N(Z13)=Y13,IF(AA13="",TRUE(),N(AB13)=AA13),IF(AC13="",TRUE(),N(AD13)=AC13),IF(AE13="",TRUE(),N(AF13)=AE13)),"一致","不一致")))) -> 手動確認 | G13: 済 | L13: 597495 | M13: 48975 | N13: 858042 | O13: 48975 | P13: 567 | Q13: 343825 | R13: 349599 | S13: 28282 | T13: 28282 | U13: 7621 | V13: 7624 | W13: =IFERROR(INDEX(設定!$E$61:$E$106,MATCH(B13,設定!$B$61:$B$106,0)),"合算") -> 合算 | Y13: =IF(OR(G13="",G13="なし"),"",IF(W13="合算",CF13,IF(W13="掛金・負担金別",(AU13+AV13+AZ13+BB13+BD13),SUM(AU13:AY13)))) -> 2319287 | AA13: =IF(OR(G13="",G13="なし"),"",IF(W13="掛金・負担金別",(AW13+AX13+AY13+BA13+BC13+BE13),IF(W13="経理区分別",AZ13+BA13,""))) | AC13: =IF(OR(G13="",G13="なし"),"",IF(W13="経理区分別",BB13+BC13,"")) | AE13: =IF(OR(G13="",G13="なし"),"",IF(W13="経理区分別",BD13+BE13,"")) | AG13: ○ | AU13: =IF($G13="",AJ13,L13) -> 597495 | AV13: =IF($G13="",AK13,M13) -> 48975 | AW13: =IF($G13="",AL13,N13) -> 858042 | AX13: =IF($G13="",AM13,O13) -> 48975 | AY13: =IF($G13="",AN13,P13) -> 567 | AZ13: =IF($G13="",AO13,Q13) -> 343825 | BA13: =IF($G13="",AP13,R13) -> 349599 | BB13: =IF($G13="",AQ13,S13) -> 28282 | ... BE13: =IF($G13="",AT13,V13) -> 7624 | BF13: =ROUNDDOWN(I13*設定!$B$10/1000,0)+ROUNDDOWN(I13*設定!$B$11/1000,0) -> 0 | BG13: =ROUNDDOWN(I13*設定!$C$10/1000,0)+ROUNDDOWN(I13*設定!$C$11/1000,0)+ROUNDDOWN(I13*設定!$C$12/1000,0) -> 0 | BH13: =ROUNDDOWN(J13*設定!$B$13/1000,0) -> 0 | BI13: =ROUNDDOWN(J13*設定!$C$13/1000,0) -> 0 | BJ13: =ROUNDDOWN(K13*設定!$B$14/1000,0) -> 0 | BK13: =ROUNDDOWN(K13*設定!$C$14/1000,0) -> 0 | BL13: =ROUNDDOWN(J13*設定!$B$15/1000,0) -> 0 | BM13: =ROUNDDOWN(J13*設定!$C$15/1000,0) -> 0 | BN13: =L13+M13 -> 646470 | BO13: =N13+O13+P13 -> 907584 | BP13: =Q13 -> 343825 | BQ13: =R13 -> 349599 | BR13: =S13 -> 28282 | BS13: =T13 -> 28282 | BT13: =U13 -> 7621 | BU13: =V13 -> 7624 | BV13: =IF(BF13=0,IF(BN13=0,0,1),(BN13-BF13)/BF13) -> 1 | BW13: =IF(BG13=0,IF(BO13=0,0,1),(BO13-BG13)/BG13) -> 1 | BX13: =IF(BH13=0,IF(BP13=0,0,1),(BP13-BH13)/BH13) -> 1 | BY13: =IF(BI13=0,IF(BQ13=0,0,1),(BQ13-BI13)/BI13) -> 1 | BZ13: =IF(BJ13=0,IF(BR13=0,0,1),(BR13-BJ13)/BJ13) -> 1 | CA13: =IF(BK13=0,IF(BS13=0,0,1),(BS13-BK13)/BK13) -> 1 | CB13: =IF(BL13=0,IF(BT13=0,0,1),(BT13-BL13)/BL13) -> 1 | CC13: =IF(BM13=0,IF(BU13=0,0,1),(BU13-BM13)/BM13) -> 1 | CD13: =MAX(MAX(BV13:CC13),-MIN(BV13:CC13)) -> 1 | CE13: =IF(CI13="","",SUMIFS($CF$7:$CF$696,$A$7:$A$696,CI13,$B$7:$B$696,B13)) | CF13: =SUM(AU13:BE13) -> 2319287 | CG13: =A13&"|"&B13 -> 2026-04 月例|人事委員会 | CH13: =IFERROR(INDEX(設定!$D$61:$D$106,MATCH(B13,設定!$B$61:$B$106,0)),"Y") -> Y | CI13: =IFERROR(INDEX(設定!$D$20:$D$34,MATCH(A13,設定!$A$20:$A$34,0))&"","")
A14: 2026-04 月例 | B14: 監査事務局 | C14: =IF(G14="","未受領",IF(G14="なし","報告なし",IF(AH14="○","起票済",IF(OR(AG14="○",F14="一致",F14="入金不要"),"入金確認済","受領済")))) -> 入金確認済 | D14: =IF(OR(G14="",G14="なし"),"―",IF(CH14="N","対象外",IF(AND(I14="",J14="",K14=""),"標報未入力",IF(CD14>=設定!$B$4,"要確認","問題なし")))) -> 標報未入力 | E14: =IF(OR(G14="",G14="なし",CE14="",CF14=0),"―",IF(CF14=CE14,"前月同額",IF(CE14=0,"―",IF(ABS(CF14/CE14-1)>=設定!$B$5,"変動大 "&TEXT(CF14/CE14-1,"+0%;-0%"),"〇")))) -> ― | F14: =IF(OR(G14="",G14="なし"),"―",IF(CF14=0,"入金不要",IF(COUNT(Z14,AB14,AD14,AF14)=0,IF(AG14="○","手動確認","未入金"),IF(AND(N(Z14)=Y14,IF(AA14="",TRUE(),N(AB14)=AA14),IF(AC14="",TRUE(),N(AD14)=AC14),IF(AE14="",TRUE(),N(AF14)=AE14)),"一致","不一致")))) -> 手動確認 | G14: 済 | L14: 1324920 | M14: 108600 | N14: 1913844 | O14: 108600 | P14: 1282 | Q14: 768034 | R14: 781174 | S14: 104201 | T14: 104201 | U14: 17023 | V14: 17030 | W14: =IFERROR(INDEX(設定!$E$61:$E$106,MATCH(B14,設定!$B$61:$B$106,0)),"合算") -> 合算 | Y14: =IF(OR(G14="",G14="なし"),"",IF(W14="合算",CF14,IF(W14="掛金・負担金別",(AU14+AV14+AZ14+BB14+BD14),SUM(AU14:AY14)))) -> 5248909 | AA14: =IF(OR(G14="",G14="なし"),"",IF(W14="掛金・負担金別",(AW14+AX14+AY14+BA14+BC14+BE14),IF(W14="経理区分別",AZ14+BA14,""))) | AC14: =IF(OR(G14="",G14="なし"),"",IF(W14="経理区分別",BB14+BC14,"")) | AE14: =IF(OR(G14="",G14="なし"),"",IF(W14="経理区分別",BD14+BE14,"")) | AG14: ○ | AU14: =IF($G14="",AJ14,L14) -> 1324920 | AV14: =IF($G14="",AK14,M14) -> 108600 | AW14: =IF($G14="",AL14,N14) -> 1913844 | AX14: =IF($G14="",AM14,O14) -> 108600 | AY14: =IF($G14="",AN14,P14) -> 1282 | AZ14: =IF($G14="",AO14,Q14) -> 768034 | BA14: =IF($G14="",AP14,R14) -> 781174 | BB14: =IF($G14="",AQ14,S14) -> 104201 | ... BE14: =IF($G14="",AT14,V14) -> 17030 | BF14: =ROUNDDOWN(I14*設定!$B$10/1000,0)+ROUNDDOWN(I14*設定!$B$11/1000,0) -> 0 | BG14: =ROUNDDOWN(I14*設定!$C$10/1000,0)+ROUNDDOWN(I14*設定!$C$11/1000,0)+ROUNDDOWN(I14*設定!$C$12/1000,0) -> 0 | BH14: =ROUNDDOWN(J14*設定!$B$13/1000,0) -> 0 | BI14: =ROUNDDOWN(J14*設定!$C$13/1000,0) -> 0 | BJ14: =ROUNDDOWN(K14*設定!$B$14/1000,0) -> 0 | BK14: =ROUNDDOWN(K14*設定!$C$14/1000,0) -> 0 | BL14: =ROUNDDOWN(J14*設定!$B$15/1000,0) -> 0 | BM14: =ROUNDDOWN(J14*設定!$C$15/1000,0) -> 0 | BN14: =L14+M14 -> 1433520 | BO14: =N14+O14+P14 -> 2023726 | BP14: =Q14 -> 768034 | BQ14: =R14 -> 781174 | BR14: =S14 -> 104201 | BS14: =T14 -> 104201 | BT14: =U14 -> 17023 | BU14: =V14 -> 17030 | BV14: =IF(BF14=0,IF(BN14=0,0,1),(BN14-BF14)/BF14) -> 1 | BW14: =IF(BG14=0,IF(BO14=0,0,1),(BO14-BG14)/BG14) -> 1 | BX14: =IF(BH14=0,IF(BP14=0,0,1),(BP14-BH14)/BH14) -> 1 | BY14: =IF(BI14=0,IF(BQ14=0,0,1),(BQ14-BI14)/BI14) -> 1 | BZ14: =IF(BJ14=0,IF(BR14=0,0,1),(BR14-BJ14)/BJ14) -> 1 | CA14: =IF(BK14=0,IF(BS14=0,0,1),(BS14-BK14)/BK14) -> 1 | CB14: =IF(BL14=0,IF(BT14=0,0,1),(BT14-BL14)/BL14) -> 1 | CC14: =IF(BM14=0,IF(BU14=0,0,1),(BU14-BM14)/BM14) -> 1 | CD14: =MAX(MAX(BV14:CC14),-MIN(BV14:CC14)) -> 1 | CE14: =IF(CI14="","",SUMIFS($CF$7:$CF$696,$A$7:$A$696,CI14,$B$7:$B$696,B14)) | CF14: =SUM(AU14:BE14) -> 5248909 | CG14: =A14&"|"&B14 -> 2026-04 月例|監査事務局 | CH14: =IFERROR(INDEX(設定!$D$61:$D$106,MATCH(B14,設定!$B$61:$B$106,0)),"Y") -> Y | CI14: =IFERROR(INDEX(設定!$D$20:$D$34,MATCH(A14,設定!$A$20:$A$34,0))&"","")
A15: 2026-04 月例 | B15: 農業委員会 | C15: =IF(G15="","未受領",IF(G15="なし","報告なし",IF(AH15="○","起票済",IF(OR(AG15="○",F15="一致",F15="入金不要"),"入金確認済","受領済")))) -> 入金確認済 | D15: =IF(OR(G15="",G15="なし"),"―",IF(CH15="N","対象外",IF(AND(I15="",J15="",K15=""),"標報未入力",IF(CD15>=設定!$B$4,"要確認","問題なし")))) -> 標報未入力 | E15: =IF(OR(G15="",G15="なし",CE15="",CF15=0),"―",IF(CF15=CE15,"前月同額",IF(CE15=0,"―",IF(ABS(CF15/CE15-1)>=設定!$B$5,"変動大 "&TEXT(CF15/CE15-1,"+0%;-0%"),"〇")))) -> ― | F15: =IF(OR(G15="",G15="なし"),"―",IF(CF15=0,"入金不要",IF(COUNT(Z15,AB15,AD15,AF15)=0,IF(AG15="○","手動確認","未入金"),IF(AND(N(Z15)=Y15,IF(AA15="",TRUE(),N(AB15)=AA15),IF(AC15="",TRUE(),N(AD15)=AC15),IF(AE15="",TRUE(),N(AF15)=AE15)),"一致","不一致")))) -> 手動確認 | G15: 済 | L15: 409920 | M15: 33600 | N15: 588672 | O15: 33600 | P15: 389 | Q15: 306800 | R15: 311950 | S15: 35042 | T15: 35044 | U15: 6800 | V15: 6803 | W15: =IFERROR(INDEX(設定!$E$61:$E$106,MATCH(B15,設定!$B$61:$B$106,0)),"合算") -> 合算 | Y15: =IF(OR(G15="",G15="なし"),"",IF(W15="合算",CF15,IF(W15="掛金・負担金別",(AU15+AV15+AZ15+BB15+BD15),SUM(AU15:AY15)))) -> 1768620 | AA15: =IF(OR(G15="",G15="なし"),"",IF(W15="掛金・負担金別",(AW15+AX15+AY15+BA15+BC15+BE15),IF(W15="経理区分別",AZ15+BA15,""))) | AC15: =IF(OR(G15="",G15="なし"),"",IF(W15="経理区分別",BB15+BC15,"")) | AE15: =IF(OR(G15="",G15="なし"),"",IF(W15="経理区分別",BD15+BE15,"")) | AG15: ○ | AU15: =IF($G15="",AJ15,L15) -> 409920 | AV15: =IF($G15="",AK15,M15) -> 33600 | AW15: =IF($G15="",AL15,N15) -> 588672 | AX15: =IF($G15="",AM15,O15) -> 33600 | AY15: =IF($G15="",AN15,P15) -> 389 | AZ15: =IF($G15="",AO15,Q15) -> 306800 | BA15: =IF($G15="",AP15,R15) -> 311950 | BB15: =IF($G15="",AQ15,S15) -> 35042 | ... BE15: =IF($G15="",AT15,V15) -> 6803 | BF15: =ROUNDDOWN(I15*設定!$B$10/1000,0)+ROUNDDOWN(I15*設定!$B$11/1000,0) -> 0 | BG15: =ROUNDDOWN(I15*設定!$C$10/1000,0)+ROUNDDOWN(I15*設定!$C$11/1000,0)+ROUNDDOWN(I15*設定!$C$12/1000,0) -> 0 | BH15: =ROUNDDOWN(J15*設定!$B$13/1000,0) -> 0 | BI15: =ROUNDDOWN(J15*設定!$C$13/1000,0) -> 0 | BJ15: =ROUNDDOWN(K15*設定!$B$14/1000,0) -> 0 | BK15: =ROUNDDOWN(K15*設定!$C$14/1000,0) -> 0 | BL15: =ROUNDDOWN(J15*設定!$B$15/1000,0) -> 0 | BM15: =ROUNDDOWN(J15*設定!$C$15/1000,0) -> 0 | BN15: =L15+M15 -> 443520 | BO15: =N15+O15+P15 -> 622661 | BP15: =Q15 -> 306800 | BQ15: =R15 -> 311950 | BR15: =S15 -> 35042 | BS15: =T15 -> 35044 | BT15: =U15 -> 6800 | BU15: =V15 -> 6803 | BV15: =IF(BF15=0,IF(BN15=0,0,1),(BN15-BF15)/BF15) -> 1 | BW15: =IF(BG15=0,IF(BO15=0,0,1),(BO15-BG15)/BG15) -> 1 | BX15: =IF(BH15=0,IF(BP15=0,0,1),(BP15-BH15)/BH15) -> 1 | BY15: =IF(BI15=0,IF(BQ15=0,0,1),(BQ15-BI15)/BI15) -> 1 | BZ15: =IF(BJ15=0,IF(BR15=0,0,1),(BR15-BJ15)/BJ15) -> 1 | CA15: =IF(BK15=0,IF(BS15=0,0,1),(BS15-BK15)/BK15) -> 1 | CB15: =IF(BL15=0,IF(BT15=0,0,1),(BT15-BL15)/BL15) -> 1 | CC15: =IF(BM15=0,IF(BU15=0,0,1),(BU15-BM15)/BM15) -> 1 | CD15: =MAX(MAX(BV15:CC15),-MIN(BV15:CC15)) -> 1 | CE15: =IF(CI15="","",SUMIFS($CF$7:$CF$696,$A$7:$A$696,CI15,$B$7:$B$696,B15)) | CF15: =SUM(AU15:BE15) -> 1768620 | CG15: =A15&"|"&B15 -> 2026-04 月例|農業委員会 | CH15: =IFERROR(INDEX(設定!$D$61:$D$106,MATCH(B15,設定!$B$61:$B$106,0)),"Y") -> Y | CI15: =IFERROR(INDEX(設定!$D$20:$D$34,MATCH(A15,設定!$A$20:$A$34,0))&"","")
A16: 2026-04 月例 | B16: 水道局 | C16: =IF(G16="","未受領",IF(G16="なし","報告なし",IF(AH16="○","起票済",IF(OR(AG16="○",F16="一致",F16="入金不要"),"入金確認済","受領済")))) -> 入金確認済 | D16: =IF(OR(G16="",G16="なし"),"―",IF(CH16="N","対象外",IF(AND(I16="",J16="",K16=""),"標報未入力",IF(CD16>=設定!$B$4,"要確認","問題なし")))) -> 対象外 | E16: =IF(OR(G16="",G16="なし",CE16="",CF16=0),"―",IF(CF16=CE16,"前月同額",IF(CE16=0,"―",IF(ABS(CF16/CE16-1)>=設定!$B$5,"変動大 "&TEXT(CF16/CE16-1,"+0%;-0%"),"〇")))) -> ― | F16: =IF(OR(G16="",G16="なし"),"―",IF(CF16=0,"入金不要",IF(COUNT(Z16,AB16,AD16,AF16)=0,IF(AG16="○","手動確認","未入金"),IF(AND(N(Z16)=Y16,IF(AA16="",TRUE(),N(AB16)=AA16),IF(AC16="",TRUE(),N(AD16)=AC16),IF(AE16="",TRUE(),N(AF16)=AE16)),"一致","不一致")))) -> 手動確認 | G16: 済 | L16: 22388403 | M16: 1835115 | N16: 32251750 | O16: 1835115 | P16: 21475 | Q16: 13373486 | R16: 13600282 | S16: 1322950 | T16: 1322950 | U16: 296479 | V16: 296570 | W16: =IFERROR(INDEX(設定!$E$61:$E$106,MATCH(B16,設定!$B$61:$B$106,0)),"合算") -> 合算 | Y16: =IF(OR(G16="",G16="なし"),"",IF(W16="合算",CF16,IF(W16="掛金・負担金別",(AU16+AV16+AZ16+BB16+BD16),SUM(AU16:AY16)))) -> 88544575 | AA16: =IF(OR(G16="",G16="なし"),"",IF(W16="掛金・負担金別",(AW16+AX16+AY16+BA16+BC16+BE16),IF(W16="経理区分別",AZ16+BA16,""))) | AC16: =IF(OR(G16="",G16="なし"),"",IF(W16="経理区分別",BB16+BC16,"")) | AE16: =IF(OR(G16="",G16="なし"),"",IF(W16="経理区分別",BD16+BE16,"")) | AG16: ○ | AU16: =IF($G16="",AJ16,L16) -> 22388403 | AV16: =IF($G16="",AK16,M16) -> 1835115 | AW16: =IF($G16="",AL16,N16) -> 32251750 | AX16: =IF($G16="",AM16,O16) -> 1835115 | AY16: =IF($G16="",AN16,P16) -> 21475 | AZ16: =IF($G16="",AO16,Q16) -> 13373486 | BA16: =IF($G16="",AP16,R16) -> 13600282 | BB16: =IF($G16="",AQ16,S16) -> 1322950 | ... BE16: =IF($G16="",AT16,V16) -> 296570 | BF16: =ROUNDDOWN(I16*設定!$B$10/1000,0)+ROUNDDOWN(I16*設定!$B$11/1000,0) -> 0 | BG16: =ROUNDDOWN(I16*設定!$C$10/1000,0)+ROUNDDOWN(I16*設定!$C$11/1000,0)+ROUNDDOWN(I16*設定!$C$12/1000,0) -> 0 | BH16: =ROUNDDOWN(J16*設定!$B$13/1000,0) -> 0 | BI16: =ROUNDDOWN(J16*設定!$C$13/1000,0) -> 0 | BJ16: =ROUNDDOWN(K16*設定!$B$14/1000,0) -> 0 | BK16: =ROUNDDOWN(K16*設定!$C$14/1000,0) -> 0 | BL16: =ROUNDDOWN(J16*設定!$B$15/1000,0) -> 0 | BM16: =ROUNDDOWN(J16*設定!$C$15/1000,0) -> 0 | BN16: =L16+M16 -> 24223518 | BO16: =N16+O16+P16 -> 34108340 | BP16: =Q16 -> 13373486 | BQ16: =R16 -> 13600282 | BR16: =S16 -> 1322950 | BS16: =T16 -> 1322950 | BT16: =U16 -> 296479 | BU16: =V16 -> 296570 | BV16: =IF(BF16=0,IF(BN16=0,0,1),(BN16-BF16)/BF16) -> 1 | BW16: =IF(BG16=0,IF(BO16=0,0,1),(BO16-BG16)/BG16) -> 1 | BX16: =IF(BH16=0,IF(BP16=0,0,1),(BP16-BH16)/BH16) -> 1 | BY16: =IF(BI16=0,IF(BQ16=0,0,1),(BQ16-BI16)/BI16) -> 1 | BZ16: =IF(BJ16=0,IF(BR16=0,0,1),(BR16-BJ16)/BJ16) -> 1 | CA16: =IF(BK16=0,IF(BS16=0,0,1),(BS16-BK16)/BK16) -> 1 | CB16: =IF(BL16=0,IF(BT16=0,0,1),(BT16-BL16)/BL16) -> 1 | CC16: =IF(BM16=0,IF(BU16=0,0,1),(BU16-BM16)/BM16) -> 1 | CD16: =MAX(MAX(BV16:CC16),-MIN(BV16:CC16)) -> 1 | CE16: =IF(CI16="","",SUMIFS($CF$7:$CF$696,$A$7:$A$696,CI16,$B$7:$B$696,B16)) | CF16: =SUM(AU16:BE16) -> 88544575 | CG16: =A16&"|"&B16 -> 2026-04 月例|水道局 | CH16: =IFERROR(INDEX(設定!$D$61:$D$106,MATCH(B16,設定!$B$61:$B$106,0)),"Y") -> N | CI16: =IFERROR(INDEX(設定!$D$20:$D$34,MATCH(A16,設定!$A$20:$A$34,0))&"","")
A17: 2026-04 月例 | B17: 医療政策課(安芸市民) | C17: =IF(G17="","未受領",IF(G17="なし","報告なし",IF(AH17="○","起票済",IF(OR(AG17="○",F17="一致",F17="入金不要"),"入金確認済","受領済")))) -> 入金確認済 | D17: =IF(OR(G17="",G17="なし"),"―",IF(CH17="N","対象外",IF(AND(I17="",J17="",K17=""),"標報未入力",IF(CD17>=設定!$B$4,"要確認","問題なし")))) -> 標報未入力 | E17: =IF(OR(G17="",G17="なし",CE17="",CF17=0),"―",IF(CF17=CE17,"前月同額",IF(CE17=0,"―",IF(ABS(CF17/CE17-1)>=設定!$B$5,"変動大 "&TEXT(CF17/CE17-1,"+0%;-0%"),"〇")))) -> ― | F17: =IF(OR(G17="",G17="なし"),"―",IF(CF17=0,"入金不要",IF(COUNT(Z17,AB17,AD17,AF17)=0,IF(AG17="○","手動確認","未入金"),IF(AND(N(Z17)=Y17,IF(AA17="",TRUE(),N(AB17)=AA17),IF(AC17="",TRUE(),N(AD17)=AC17),IF(AE17="",TRUE(),N(AF17)=AE17)),"一致","不一致")))) -> 手動確認 | G17: 済 | L17: 48495 | M17: 3975 | N17: 69642 | O17: 3975 | P17: 46 | Q17: 27485 | R17: 27946 | S17: 4187 | T17: 4187 | U17: 609 | V17: 609 | W17: =IFERROR(INDEX(設定!$E$61:$E$106,MATCH(B17,設定!$B$61:$B$106,0)),"合算") -> 合算 | Y17: =IF(OR(G17="",G17="なし"),"",IF(W17="合算",CF17,IF(W17="掛金・負担金別",(AU17+AV17+AZ17+BB17+BD17),SUM(AU17:AY17)))) -> 191156 | AA17: =IF(OR(G17="",G17="なし"),"",IF(W17="掛金・負担金別",(AW17+AX17+AY17+BA17+BC17+BE17),IF(W17="経理区分別",AZ17+BA17,""))) | AC17: =IF(OR(G17="",G17="なし"),"",IF(W17="経理区分別",BB17+BC17,"")) | AE17: =IF(OR(G17="",G17="なし"),"",IF(W17="経理区分別",BD17+BE17,"")) | AG17: ○ | AU17: =IF($G17="",AJ17,L17) -> 48495 | AV17: =IF($G17="",AK17,M17) -> 3975 | AW17: =IF($G17="",AL17,N17) -> 69642 | AX17: =IF($G17="",AM17,O17) -> 3975 | AY17: =IF($G17="",AN17,P17) -> 46 | AZ17: =IF($G17="",AO17,Q17) -> 27485 | BA17: =IF($G17="",AP17,R17) -> 27946 | BB17: =IF($G17="",AQ17,S17) -> 4187 | ... BE17: =IF($G17="",AT17,V17) -> 609 | BF17: =ROUNDDOWN(I17*設定!$B$10/1000,0)+ROUNDDOWN(I17*設定!$B$11/1000,0) -> 0 | BG17: =ROUNDDOWN(I17*設定!$C$10/1000,0)+ROUNDDOWN(I17*設定!$C$11/1000,0)+ROUNDDOWN(I17*設定!$C$12/1000,0) -> 0 | BH17: =ROUNDDOWN(J17*設定!$B$13/1000,0) -> 0 | BI17: =ROUNDDOWN(J17*設定!$C$13/1000,0) -> 0 | BJ17: =ROUNDDOWN(K17*設定!$B$14/1000,0) -> 0 | BK17: =ROUNDDOWN(K17*設定!$C$14/1000,0) -> 0 | BL17: =ROUNDDOWN(J17*設定!$B$15/1000,0) -> 0 | BM17: =ROUNDDOWN(J17*設定!$C$15/1000,0) -> 0 | BN17: =L17+M17 -> 52470 | BO17: =N17+O17+P17 -> 73663 | BP17: =Q17 -> 27485 | BQ17: =R17 -> 27946 | BR17: =S17 -> 4187 | BS17: =T17 -> 4187 | BT17: =U17 -> 609 | BU17: =V17 -> 609 | BV17: =IF(BF17=0,IF(BN17=0,0,1),(BN17-BF17)/BF17) -> 1 | BW17: =IF(BG17=0,IF(BO17=0,0,1),(BO17-BG17)/BG17) -> 1 | BX17: =IF(BH17=0,IF(BP17=0,0,1),(BP17-BH17)/BH17) -> 1 | BY17: =IF(BI17=0,IF(BQ17=0,0,1),(BQ17-BI17)/BI17) -> 1 | BZ17: =IF(BJ17=0,IF(BR17=0,0,1),(BR17-BJ17)/BJ17) -> 1 | CA17: =IF(BK17=0,IF(BS17=0,0,1),(BS17-BK17)/BK17) -> 1 | CB17: =IF(BL17=0,IF(BT17=0,0,1),(BT17-BL17)/BL17) -> 1 | CC17: =IF(BM17=0,IF(BU17=0,0,1),(BU17-BM17)/BM17) -> 1 | CD17: =MAX(MAX(BV17:CC17),-MIN(BV17:CC17)) -> 1 | CE17: =IF(CI17="","",SUMIFS($CF$7:$CF$696,$A$7:$A$696,CI17,$B$7:$B$696,B17)) | CF17: =SUM(AU17:BE17) -> 191156 | CG17: =A17&"|"&B17 -> 2026-04 月例|医療政策課(安芸市民) | CH17: =IFERROR(INDEX(設定!$D$61:$D$106,MATCH(B17,設定!$B$61:$B$106,0)),"Y") -> Y | CI17: =IFERROR(INDEX(設定!$D$20:$D$34,MATCH(A17,設定!$A$20:$A$34,0))&"","")
A18: 2026-04 月例 | B18: 教育委員会（教育給与課） | C18: =IF(G18="","未受領",IF(G18="なし","報告なし",IF(AH18="○","起票済",IF(OR(AG18="○",F18="一致",F18="入金不要"),"入金確認済","受領済")))) -> 入金確認済 | D18: =IF(OR(G18="",G18="なし"),"―",IF(CH18="N","対象外",IF(AND(I18="",J18="",K18=""),"標報未入力",IF(CD18>=設定!$B$4,"要確認","問題なし")))) -> 標報未入力 | E18: =IF(OR(G18="",G18="なし",CE18="",CF18=0),"―",IF(CF18=CE18,"前月同額",IF(CE18=0,"―",IF(ABS(CF18/CE18-1)>=設定!$B$5,"変動大 "&TEXT(CF18/CE18-1,"+0%;-0%"),"〇")))) -> ― | F18: =IF(OR(G18="",G18="なし"),"―",IF(CF18=0,"入金不要",IF(COUNT(Z18,AB18,AD18,AF18)=0,IF(AG18="○","手動確認","未入金"),IF(AND(N(Z18)=Y18,IF(AA18="",TRUE(),N(AB18)=AA18),IF(AC18="",TRUE(),N(AD18)=AC18),IF(AE18="",TRUE(),N(AF18)=AE18)),"一致","不一致")))) -> 入金不要 | G18: 済 | L18: 0 | M18: 0 | P18: 0 | Q18: 0 | R18: 0 | S18: 0 | T18: 0 | U18: 0 | V18: 0 | W18: =IFERROR(INDEX(設定!$E$61:$E$106,MATCH(B18,設定!$B$61:$B$106,0)),"合算") -> 合算 | Y18: =IF(OR(G18="",G18="なし"),"",IF(W18="合算",CF18,IF(W18="掛金・負担金別",(AU18+AV18+AZ18+BB18+BD18),SUM(AU18:AY18)))) -> 0 | AA18: =IF(OR(G18="",G18="なし"),"",IF(W18="掛金・負担金別",(AW18+AX18+AY18+BA18+BC18+BE18),IF(W18="経理区分別",AZ18+BA18,""))) | AC18: =IF(OR(G18="",G18="なし"),"",IF(W18="経理区分別",BB18+BC18,"")) | AE18: =IF(OR(G18="",G18="なし"),"",IF(W18="経理区分別",BD18+BE18,"")) | AU18: =IF($G18="",AJ18,L18) -> 0 | AV18: =IF($G18="",AK18,M18) -> 0 | AW18: =IF($G18="",AL18,N18) -> 0 | AX18: =IF($G18="",AM18,O18) -> 0 | AY18: =IF($G18="",AN18,P18) -> 0 | AZ18: =IF($G18="",AO18,Q18) -> 0 | BA18: =IF($G18="",AP18,R18) -> 0 | BB18: =IF($G18="",AQ18,S18) -> 0 | ... BE18: =IF($G18="",AT18,V18) -> 0 | BF18: =ROUNDDOWN(I18*設定!$B$10/1000,0)+ROUNDDOWN(I18*設定!$B$11/1000,0) -> 0 | BG18: =ROUNDDOWN(I18*設定!$C$10/1000,0)+ROUNDDOWN(I18*設定!$C$11/1000,0)+ROUNDDOWN(I18*設定!$C$12/1000,0) -> 0 | BH18: =ROUNDDOWN(J18*設定!$B$13/1000,0) -> 0 | BI18: =ROUNDDOWN(J18*設定!$C$13/1000,0) -> 0 | BJ18: =ROUNDDOWN(K18*設定!$B$14/1000,0) -> 0 | BK18: =ROUNDDOWN(K18*設定!$C$14/1000,0) -> 0 | BL18: =ROUNDDOWN(J18*設定!$B$15/1000,0) -> 0 | BM18: =ROUNDDOWN(J18*設定!$C$15/1000,0) -> 0 | BN18: =L18+M18 -> 0 | BO18: =N18+O18+P18 -> 0 | BP18: =Q18 -> 0 | BQ18: =R18 -> 0 | BR18: =S18 -> 0 | BS18: =T18 -> 0 | BT18: =U18 -> 0 | BU18: =V18 -> 0 | BV18: =IF(BF18=0,IF(BN18=0,0,1),(BN18-BF18)/BF18) -> 0 | BW18: =IF(BG18=0,IF(BO18=0,0,1),(BO18-BG18)/BG18) -> 0 | BX18: =IF(BH18=0,IF(BP18=0,0,1),(BP18-BH18)/BH18) -> 0 | BY18: =IF(BI18=0,IF(BQ18=0,0,1),(BQ18-BI18)/BI18) -> 0 | BZ18: =IF(BJ18=0,IF(BR18=0,0,1),(BR18-BJ18)/BJ18) -> 0 | CA18: =IF(BK18=0,IF(BS18=0,0,1),(BS18-BK18)/BK18) -> 0 | CB18: =IF(BL18=0,IF(BT18=0,0,1),(BT18-BL18)/BL18) -> 0 | CC18: =IF(BM18=0,IF(BU18=0,0,1),(BU18-BM18)/BM18) -> 0 | CD18: =MAX(MAX(BV18:CC18),-MIN(BV18:CC18)) -> 0 | CE18: =IF(CI18="","",SUMIFS($CF$7:$CF$696,$A$7:$A$696,CI18,$B$7:$B$696,B18)) | CF18: =SUM(AU18:BE18) -> 0 | CG18: =A18&"|"&B18 -> 2026-04 月例|教育委員会（教育給与課） | CH18: =IFERROR(INDEX(設定!$D$61:$D$106,MATCH(B18,設定!$B$61:$B$106,0)),"Y") -> Y | CI18: =IFERROR(INDEX(設定!$D$20:$D$34,MATCH(A18,設定!$A$20:$A$34,0))&"","")
A19: 2026-04 月例 | B19: 地方税共同機構 | C19: =IF(G19="","未受領",IF(G19="なし","報告なし",IF(AH19="○","起票済",IF(OR(AG19="○",F19="一致",F19="入金不要"),"入金確認済","受領済")))) -> 報告なし | D19: =IF(OR(G19="",G19="なし"),"―",IF(CH19="N","対象外",IF(AND(I19="",J19="",K19=""),"標報未入力",IF(CD19>=設定!$B$4,"要確認","問題なし")))) -> ― | E19: =IF(OR(G19="",G19="なし",CE19="",CF19=0),"―",IF(CF19=CE19,"前月同額",IF(CE19=0,"―",IF(ABS(CF19/CE19-1)>=設定!$B$5,"変動大 "&TEXT(CF19/CE19-1,"+0%;-0%"),"〇")))) -> ― | F19: =IF(OR(G19="",G19="なし"),"―",IF(CF19=0,"入金不要",IF(COUNT(Z19,AB19,AD19,AF19)=0,IF(AG19="○","手動確認","未入金"),IF(AND(N(Z19)=Y19,IF(AA19="",TRUE(),N(AB19)=AA19),IF(AC19="",TRUE(),N(AD19)=AC19),IF(AE19="",TRUE(),N(AF19)=AE19)),"一致","不一致")))) -> ― | G19: なし | W19: =IFERROR(INDEX(設定!$E$61:$E$106,MATCH(B19,設定!$B$61:$B$106,0)),"合算") -> 合算 | Y19: =IF(OR(G19="",G19="なし"),"",IF(W19="合算",CF19,IF(W19="掛金・負担金別",(AU19+AV19+AZ19+BB19+BD19),SUM(AU19:AY19)))) | AA19: =IF(OR(G19="",G19="なし"),"",IF(W19="掛金・負担金別",(AW19+AX19+AY19+BA19+BC19+BE19),IF(W19="経理区分別",AZ19+BA19,""))) | AC19: =IF(OR(G19="",G19="なし"),"",IF(W19="経理区分別",BB19+BC19,"")) | AE19: =IF(OR(G19="",G19="なし"),"",IF(W19="経理区分別",BD19+BE19,"")) | AU19: =IF($G19="",AJ19,L19) -> 0 | AV19: =IF($G19="",AK19,M19) -> 0 | AW19: =IF($G19="",AL19,N19) -> 0 | AX19: =IF($G19="",AM19,O19) -> 0 | AY19: =IF($G19="",AN19,P19) -> 0 | AZ19: =IF($G19="",AO19,Q19) -> 0 | BA19: =IF($G19="",AP19,R19) -> 0 | BB19: =IF($G19="",AQ19,S19) -> 0 | ... BE19: =IF($G19="",AT19,V19) -> 0 | BF19: =ROUNDDOWN(I19*設定!$B$10/1000,0)+ROUNDDOWN(I19*設定!$B$11/1000,0) -> 0 | BG19: =ROUNDDOWN(I19*設定!$C$10/1000,0)+ROUNDDOWN(I19*設定!$C$11/1000,0)+ROUNDDOWN(I19*設定!$C$12/1000,0) -> 0 | BH19: =ROUNDDOWN(J19*設定!$B$13/1000,0) -> 0 | BI19: =ROUNDDOWN(J19*設定!$C$13/1000,0) -> 0 | BJ19: =ROUNDDOWN(K19*設定!$B$14/1000,0) -> 0 | BK19: =ROUNDDOWN(K19*設定!$C$14/1000,0) -> 0 | BL19: =ROUNDDOWN(J19*設定!$B$15/1000,0) -> 0 | BM19: =ROUNDDOWN(J19*設定!$C$15/1000,0) -> 0 | BN19: =L19+M19 -> 0 | BO19: =N19+O19+P19 -> 0 | BP19: =Q19 -> 0 | BQ19: =R19 -> 0 | BR19: =S19 -> 0 | BS19: =T19 -> 0 | BT19: =U19 -> 0 | BU19: =V19 -> 0 | BV19: =IF(BF19=0,IF(BN19=0,0,1),(BN19-BF19)/BF19) -> 0 | BW19: =IF(BG19=0,IF(BO19=0,0,1),(BO19-BG19)/BG19) -> 0 | BX19: =IF(BH19=0,IF(BP19=0,0,1),(BP19-BH19)/BH19) -> 0 | BY19: =IF(BI19=0,IF(BQ19=0,0,1),(BQ19-BI19)/BI19) -> 0 | BZ19: =IF(BJ19=0,IF(BR19=0,0,1),(BR19-BJ19)/BJ19) -> 0 | CA19: =IF(BK19=0,IF(BS19=0,0,1),(BS19-BK19)/BK19) -> 0 | CB19: =IF(BL19=0,IF(BT19=0,0,1),(BT19-BL19)/BL19) -> 0 | CC19: =IF(BM19=0,IF(BU19=0,0,1),(BU19-BM19)/BM19) -> 0 | CD19: =MAX(MAX(BV19:CC19),-MIN(BV19:CC19)) -> 0 | CE19: =IF(CI19="","",SUMIFS($CF$7:$CF$696,$A$7:$A$696,CI19,$B$7:$B$696,B19)) | CF19: =SUM(AU19:BE19) -> 0 | CG19: =A19&"|"&B19 -> 2026-04 月例|地方税共同機構 | CH19: =IFERROR(INDEX(設定!$D$61:$D$106,MATCH(B19,設定!$B$61:$B$106,0)),"Y") -> Y | CI19: =IFERROR(INDEX(設定!$D$20:$D$34,MATCH(A19,設定!$A$20:$A$34,0))&"","")
A20: 2026-04 月例 | B20: 平和文化センター | C20: =IF(G20="","未受領",IF(G20="なし","報告なし",IF(AH20="○","起票済",IF(OR(AG20="○",F20="一致",F20="入金不要"),"入金確認済","受領済")))) -> 入金確認済 | D20: =IF(OR(G20="",G20="なし"),"―",IF(CH20="N","対象外",IF(AND(I20="",J20="",K20=""),"標報未入力",IF(CD20>=設定!$B$4,"要確認","問題なし")))) -> 標報未入力 | E20: =IF(OR(G20="",G20="なし",CE20="",CF20=0),"―",IF(CF20=CE20,"前月同額",IF(CE20=0,"―",IF(ABS(CF20/CE20-1)>=設定!$B$5,"変動大 "&TEXT(CF20/CE20-1,"+0%;-0%"),"〇")))) -> ― | F20: =IF(OR(G20="",G20="なし"),"―",IF(CF20=0,"入金不要",IF(COUNT(Z20,AB20,AD20,AF20)=0,IF(AG20="○","手動確認","未入金"),IF(AND(N(Z20)=Y20,IF(AA20="",TRUE(),N(AB20)=AA20),IF(AC20="",TRUE(),N(AD20)=AC20),IF(AE20="",TRUE(),N(AF20)=AE20)),"一致","不一致")))) -> 手動確認 | G20: 済 | L20: 0 | M20: 0 | N20: 765855 | O20: 62775 | P20: 789 | Q20: 0 | R20: 441236 | S20: 0 | T20: 54826 | U20: 0 | V20: 9775 | W20: =IFERROR(INDEX(設定!$E$61:$E$106,MATCH(B20,設定!$B$61:$B$106,0)),"合算") -> 合算 | Y20: =IF(OR(G20="",G20="なし"),"",IF(W20="合算",CF20,IF(W20="掛金・負担金別",(AU20+AV20+AZ20+BB20+BD20),SUM(AU20:AY20)))) -> 1335256 | AA20: =IF(OR(G20="",G20="なし"),"",IF(W20="掛金・負担金別",(AW20+AX20+AY20+BA20+BC20+BE20),IF(W20="経理区分別",AZ20+BA20,""))) | AC20: =IF(OR(G20="",G20="なし"),"",IF(W20="経理区分別",BB20+BC20,"")) | AE20: =IF(OR(G20="",G20="なし"),"",IF(W20="経理区分別",BD20+BE20,"")) | AG20: ○ | AU20: =IF($G20="",AJ20,L20) -> 0 | AV20: =IF($G20="",AK20,M20) -> 0 | AW20: =IF($G20="",AL20,N20) -> 765855 | AX20: =IF($G20="",AM20,O20) -> 62775 | AY20: =IF($G20="",AN20,P20) -> 789 | AZ20: =IF($G20="",AO20,Q20) -> 0 | BA20: =IF($G20="",AP20,R20) -> 441236 | BB20: =IF($G20="",AQ20,S20) -> 0 | ... BE20: =IF($G20="",AT20,V20) -> 9775 | BF20: =ROUNDDOWN(I20*設定!$B$10/1000,0)+ROUNDDOWN(I20*設定!$B$11/1000,0) -> 0 | BG20: =ROUNDDOWN(I20*設定!$C$10/1000,0)+ROUNDDOWN(I20*設定!$C$11/1000,0)+ROUNDDOWN(I20*設定!$C$12/1000,0) -> 0 | BH20: =ROUNDDOWN(J20*設定!$B$13/1000,0) -> 0 | BI20: =ROUNDDOWN(J20*設定!$C$13/1000,0) -> 0 | BJ20: =ROUNDDOWN(K20*設定!$B$14/1000,0) -> 0 | BK20: =ROUNDDOWN(K20*設定!$C$14/1000,0) -> 0 | BL20: =ROUNDDOWN(J20*設定!$B$15/1000,0) -> 0 | BM20: =ROUNDDOWN(J20*設定!$C$15/1000,0) -> 0 | BN20: =L20+M20 -> 0 | BO20: =N20+O20+P20 -> 829419 | BP20: =Q20 -> 0 | BQ20: =R20 -> 441236 | BR20: =S20 -> 0 | BS20: =T20 -> 54826 | BT20: =U20 -> 0 | BU20: =V20 -> 9775 | BV20: =IF(BF20=0,IF(BN20=0,0,1),(BN20-BF20)/BF20) -> 0 | BW20: =IF(BG20=0,IF(BO20=0,0,1),(BO20-BG20)/BG20) -> 1 | BX20: =IF(BH20=0,IF(BP20=0,0,1),(BP20-BH20)/BH20) -> 0 | BY20: =IF(BI20=0,IF(BQ20=0,0,1),(BQ20-BI20)/BI20) -> 1 | BZ20: =IF(BJ20=0,IF(BR20=0,0,1),(BR20-BJ20)/BJ20) -> 0 | CA20: =IF(BK20=0,IF(BS20=0,0,1),(BS20-BK20)/BK20) -> 1 | CB20: =IF(BL20=0,IF(BT20=0,0,1),(BT20-BL20)/BL20) -> 0 | CC20: =IF(BM20=0,IF(BU20=0,0,1),(BU20-BM20)/BM20) -> 1 | CD20: =MAX(MAX(BV20:CC20),-MIN(BV20:CC20)) -> 1 | CE20: =IF(CI20="","",SUMIFS($CF$7:$CF$696,$A$7:$A$696,CI20,$B$7:$B$696,B20)) | CF20: =SUM(AU20:BE20) -> 1335256 | CG20: =A20&"|"&B20 -> 2026-04 月例|平和文化センター | CH20: =IFERROR(INDEX(設定!$D$61:$D$106,MATCH(B20,設定!$B$61:$B$106,0)),"Y") -> Y | CI20: =IFERROR(INDEX(設定!$D$20:$D$34,MATCH(A20,設定!$A$20:$A$34,0))&"","")
A21: 2026-04 月例 | B21: 社会福祉事業団 | C21: =IF(G21="","未受領",IF(G21="なし","報告なし",IF(AH21="○","起票済",IF(OR(AG21="○",F21="一致",F21="入金不要"),"入金確認済","受領済")))) -> 入金確認済 | D21: =IF(OR(G21="",G21="なし"),"―",IF(CH21="N","対象外",IF(AND(I21="",J21="",K21=""),"標報未入力",IF(CD21>=設定!$B$4,"要確認","問題なし")))) -> 標報未入力 | E21: =IF(OR(G21="",G21="なし",CE21="",CF21=0),"―",IF(CF21=CE21,"前月同額",IF(CE21=0,"―",IF(ABS(CF21/CE21-1)>=設定!$B$5,"変動大 "&TEXT(CF21/CE21-1,"+0%;-0%"),"〇")))) -> ― | F21: =IF(OR(G21="",G21="なし"),"―",IF(CF21=0,"入金不要",IF(COUNT(Z21,AB21,AD21,AF21)=0,IF(AG21="○","手動確認","未入金"),IF(AND(N(Z21)=Y21,IF(AA21="",TRUE(),N(AB21)=AA21),IF(AC21="",TRUE(),N(AD21)=AC21),IF(AE21="",TRUE(),N(AF21)=AE21)),"一致","不一致")))) -> 手動確認 | G21: 済 | N21: 2045940 | O21: 167700 | P21: 1993 | R21: 1308159 | T21: 141726 | V21: 28976 | W21: =IFERROR(INDEX(設定!$E$61:$E$106,MATCH(B21,設定!$B$61:$B$106,0)),"合算") -> 合算 | Y21: =IF(OR(G21="",G21="なし"),"",IF(W21="合算",CF21,IF(W21="掛金・負担金別",(AU21+AV21+AZ21+BB21+BD21),SUM(AU21:AY21)))) -> 3694494 | AA21: =IF(OR(G21="",G21="なし"),"",IF(W21="掛金・負担金別",(AW21+AX21+AY21+BA21+BC21+BE21),IF(W21="経理区分別",AZ21+BA21,""))) | AC21: =IF(OR(G21="",G21="なし"),"",IF(W21="経理区分別",BB21+BC21,"")) | AE21: =IF(OR(G21="",G21="なし"),"",IF(W21="経理区分別",BD21+BE21,"")) | AG21: ○ | AU21: =IF($G21="",AJ21,L21) -> 0 | AV21: =IF($G21="",AK21,M21) -> 0 | AW21: =IF($G21="",AL21,N21) -> 2045940 | AX21: =IF($G21="",AM21,O21) -> 167700 | AY21: =IF($G21="",AN21,P21) -> 1993 | AZ21: =IF($G21="",AO21,Q21) -> 0 | BA21: =IF($G21="",AP21,R21) -> 1308159 | BB21: =IF($G21="",AQ21,S21) -> 0 | ... BE21: =IF($G21="",AT21,V21) -> 28976 | BF21: =ROUNDDOWN(I21*設定!$B$10/1000,0)+ROUNDDOWN(I21*設定!$B$11/1000,0) -> 0 | BG21: =ROUNDDOWN(I21*設定!$C$10/1000,0)+ROUNDDOWN(I21*設定!$C$11/1000,0)+ROUNDDOWN(I21*設定!$C$12/1000,0) -> 0 | BH21: =ROUNDDOWN(J21*設定!$B$13/1000,0) -> 0 | BI21: =ROUNDDOWN(J21*設定!$C$13/1000,0) -> 0 | BJ21: =ROUNDDOWN(K21*設定!$B$14/1000,0) -> 0 | BK21: =ROUNDDOWN(K21*設定!$C$14/1000,0) -> 0 | BL21: =ROUNDDOWN(J21*設定!$B$15/1000,0) -> 0 | BM21: =ROUNDDOWN(J21*設定!$C$15/1000,0) -> 0 | BN21: =L21+M21 -> 0 | BO21: =N21+O21+P21 -> 2215633 | BP21: =Q21 -> 0 | BQ21: =R21 -> 1308159 | BR21: =S21 -> 0 | BS21: =T21 -> 141726 | BT21: =U21 -> 0 | BU21: =V21 -> 28976 | BV21: =IF(BF21=0,IF(BN21=0,0,1),(BN21-BF21)/BF21) -> 0 | BW21: =IF(BG21=0,IF(BO21=0,0,1),(BO21-BG21)/BG21) -> 1 | BX21: =IF(BH21=0,IF(BP21=0,0,1),(BP21-BH21)/BH21) -> 0 | BY21: =IF(BI21=0,IF(BQ21=0,0,1),(BQ21-BI21)/BI21) -> 1 | BZ21: =IF(BJ21=0,IF(BR21=0,0,1),(BR21-BJ21)/BJ21) -> 0 | CA21: =IF(BK21=0,IF(BS21=0,0,1),(BS21-BK21)/BK21) -> 1 | CB21: =IF(BL21=0,IF(BT21=0,0,1),(BT21-BL21)/BL21) -> 0 | CC21: =IF(BM21=0,IF(BU21=0,0,1),(BU21-BM21)/BM21) -> 1 | CD21: =MAX(MAX(BV21:CC21),-MIN(BV21:CC21)) -> 1 | CE21: =IF(CI21="","",SUMIFS($CF$7:$CF$696,$A$7:$A$696,CI21,$B$7:$B$696,B21)) | CF21: =SUM(AU21:BE21) -> 3694494 | CG21: =A21&"|"&B21 -> 2026-04 月例|社会福祉事業団 | CH21: =IFERROR(INDEX(設定!$D$61:$D$106,MATCH(B21,設定!$B$61:$B$106,0)),"Y") -> Y | CI21: =IFERROR(INDEX(設定!$D$20:$D$34,MATCH(A21,設定!$A$20:$A$34,0))&"","")
A22: 2026-04 月例 | B22: 原爆障害対策協議会 | C22: =IF(G22="","未受領",IF(G22="なし","報告なし",IF(AH22="○","起票済",IF(OR(AG22="○",F22="一致",F22="入金不要"),"入金確認済","受領済")))) -> 入金確認済 | D22: =IF(OR(G22="",G22="なし"),"―",IF(CH22="N","対象外",IF(AND(I22="",J22="",K22=""),"標報未入力",IF(CD22>=設定!$B$4,"要確認","問題なし")))) -> 標報未入力 | E22: =IF(OR(G22="",G22="なし",CE22="",CF22=0),"―",IF(CF22=CE22,"前月同額",IF(CE22=0,"―",IF(ABS(CF22/CE22-1)>=設定!$B$5,"変動大 "&TEXT(CF22/CE22-1,"+0%;-0%"),"〇")))) -> ― | F22: =IF(OR(G22="",G22="なし"),"―",IF(CF22=0,"入金不要",IF(COUNT(Z22,AB22,AD22,AF22)=0,IF(AG22="○","手動確認","未入金"),IF(AND(N(Z22)=Y22,IF(AA22="",TRUE(),N(AB22)=AA22),IF(AC22="",TRUE(),N(AD22)=AC22),IF(AE22="",TRUE(),N(AF22)=AE22)),"一致","不一致")))) -> 手動確認 | G22: 済 | N22: 59475 | O22: 4875 | P22: 56 | R22: 36856 | T22: 5609 | V22: 816 | W22: =IFERROR(INDEX(設定!$E$61:$E$106,MATCH(B22,設定!$B$61:$B$106,0)),"合算") -> 合算 | Y22: =IF(OR(G22="",G22="なし"),"",IF(W22="合算",CF22,IF(W22="掛金・負担金別",(AU22+AV22+AZ22+BB22+BD22),SUM(AU22:AY22)))) -> 107687 | AA22: =IF(OR(G22="",G22="なし"),"",IF(W22="掛金・負担金別",(AW22+AX22+AY22+BA22+BC22+BE22),IF(W22="経理区分別",AZ22+BA22,""))) | AC22: =IF(OR(G22="",G22="なし"),"",IF(W22="経理区分別",BB22+BC22,"")) | AE22: =IF(OR(G22="",G22="なし"),"",IF(W22="経理区分別",BD22+BE22,"")) | AG22: ○ | AU22: =IF($G22="",AJ22,L22) -> 0 | AV22: =IF($G22="",AK22,M22) -> 0 | AW22: =IF($G22="",AL22,N22) -> 59475 | AX22: =IF($G22="",AM22,O22) -> 4875 | AY22: =IF($G22="",AN22,P22) -> 56 | AZ22: =IF($G22="",AO22,Q22) -> 0 | BA22: =IF($G22="",AP22,R22) -> 36856 | BB22: =IF($G22="",AQ22,S22) -> 0 | ... BE22: =IF($G22="",AT22,V22) -> 816 | BF22: =ROUNDDOWN(I22*設定!$B$10/1000,0)+ROUNDDOWN(I22*設定!$B$11/1000,0) -> 0 | BG22: =ROUNDDOWN(I22*設定!$C$10/1000,0)+ROUNDDOWN(I22*設定!$C$11/1000,0)+ROUNDDOWN(I22*設定!$C$12/1000,0) -> 0 | BH22: =ROUNDDOWN(J22*設定!$B$13/1000,0) -> 0 | BI22: =ROUNDDOWN(J22*設定!$C$13/1000,0) -> 0 | BJ22: =ROUNDDOWN(K22*設定!$B$14/1000,0) -> 0 | BK22: =ROUNDDOWN(K22*設定!$C$14/1000,0) -> 0 | BL22: =ROUNDDOWN(J22*設定!$B$15/1000,0) -> 0 | BM22: =ROUNDDOWN(J22*設定!$C$15/1000,0) -> 0 | BN22: =L22+M22 -> 0 | BO22: =N22+O22+P22 -> 64406 | BP22: =Q22 -> 0 | BQ22: =R22 -> 36856 | BR22: =S22 -> 0 | BS22: =T22 -> 5609 | BT22: =U22 -> 0 | BU22: =V22 -> 816 | BV22: =IF(BF22=0,IF(BN22=0,0,1),(BN22-BF22)/BF22) -> 0 | BW22: =IF(BG22=0,IF(BO22=0,0,1),(BO22-BG22)/BG22) -> 1 | BX22: =IF(BH22=0,IF(BP22=0,0,1),(BP22-BH22)/BH22) -> 0 | BY22: =IF(BI22=0,IF(BQ22=0,0,1),(BQ22-BI22)/BI22) -> 1 | BZ22: =IF(BJ22=0,IF(BR22=0,0,1),(BR22-BJ22)/BJ22) -> 0 | CA22: =IF(BK22=0,IF(BS22=0,0,1),(BS22-BK22)/BK22) -> 1 | CB22: =IF(BL22=0,IF(BT22=0,0,1),(BT22-BL22)/BL22) -> 0 | CC22: =IF(BM22=0,IF(BU22=0,0,1),(BU22-BM22)/BM22) -> 1 | CD22: =MAX(MAX(BV22:CC22),-MIN(BV22:CC22)) -> 1 | CE22: =IF(CI22="","",SUMIFS($CF$7:$CF$696,$A$7:$A$696,CI22,$B$7:$B$696,B22)) | CF22: =SUM(AU22:BE22) -> 107687 | CG22: =A22&"|"&B22 -> 2026-04 月例|原爆障害対策協議会 | CH22: =IFERROR(INDEX(設定!$D$61:$D$106,MATCH(B22,設定!$B$61:$B$106,0)),"Y") -> Y | CI22: =IFERROR(INDEX(設定!$D$20:$D$34,MATCH(A22,設定!$A$20:$A$34,0))&"","")
A23: 2026-04 月例 | B23: 産業振興センター | C23: =IF(G23="","未受領",IF(G23="なし","報告なし",IF(AH23="○","起票済",IF(OR(AG23="○",F23="一致",F23="入金不要"),"入金確認済","受領済")))) -> 入金確認済 | D23: =IF(OR(G23="",G23="なし"),"―",IF(CH23="N","対象外",IF(AND(I23="",J23="",K23=""),"標報未入力",IF(CD23>=設定!$B$4,"要確認","問題なし")))) -> 標報未入力 | E23: =IF(OR(G23="",G23="なし",CE23="",CF23=0),"―",IF(CF23=CE23,"前月同額",IF(CE23=0,"―",IF(ABS(CF23/CE23-1)>=設定!$B$5,"変動大 "&TEXT(CF23/CE23-1,"+0%;-0%"),"〇")))) -> ― | F23: =IF(OR(G23="",G23="なし"),"―",IF(CF23=0,"入金不要",IF(COUNT(Z23,AB23,AD23,AF23)=0,IF(AG23="○","手動確認","未入金"),IF(AND(N(Z23)=Y23,IF(AA23="",TRUE(),N(AB23)=AA23),IF(AC23="",TRUE(),N(AD23)=AC23),IF(AE23="",TRUE(),N(AF23)=AE23)),"一致","不一致")))) -> 手動確認 | G23: 済 | N23: 417240 | O23: 34200 | P23: 395 | R23: 236708 | T23: 30968 | V23: 5243 | W23: =IFERROR(INDEX(設定!$E$61:$E$106,MATCH(B23,設定!$B$61:$B$106,0)),"合算") -> 合算 | Y23: =IF(OR(G23="",G23="なし"),"",IF(W23="合算",CF23,IF(W23="掛金・負担金別",(AU23+AV23+AZ23+BB23+BD23),SUM(AU23:AY23)))) -> 724754 | AA23: =IF(OR(G23="",G23="なし"),"",IF(W23="掛金・負担金別",(AW23+AX23+AY23+BA23+BC23+BE23),IF(W23="経理区分別",AZ23+BA23,""))) | AC23: =IF(OR(G23="",G23="なし"),"",IF(W23="経理区分別",BB23+BC23,"")) | AE23: =IF(OR(G23="",G23="なし"),"",IF(W23="経理区分別",BD23+BE23,"")) | AG23: ○ | AU23: =IF($G23="",AJ23,L23) -> 0 | AV23: =IF($G23="",AK23,M23) -> 0 | AW23: =IF($G23="",AL23,N23) -> 417240 | AX23: =IF($G23="",AM23,O23) -> 34200 | AY23: =IF($G23="",AN23,P23) -> 395 | AZ23: =IF($G23="",AO23,Q23) -> 0 | BA23: =IF($G23="",AP23,R23) -> 236708 | BB23: =IF($G23="",AQ23,S23) -> 0 | ... BE23: =IF($G23="",AT23,V23) -> 5243 | BF23: =ROUNDDOWN(I23*設定!$B$10/1000,0)+ROUNDDOWN(I23*設定!$B$11/1000,0) -> 0 | BG23: =ROUNDDOWN(I23*設定!$C$10/1000,0)+ROUNDDOWN(I23*設定!$C$11/1000,0)+ROUNDDOWN(I23*設定!$C$12/1000,0) -> 0 | BH23: =ROUNDDOWN(J23*設定!$B$13/1000,0) -> 0 | BI23: =ROUNDDOWN(J23*設定!$C$13/1000,0) -> 0 | BJ23: =ROUNDDOWN(K23*設定!$B$14/1000,0) -> 0 | BK23: =ROUNDDOWN(K23*設定!$C$14/1000,0) -> 0 | BL23: =ROUNDDOWN(J23*設定!$B$15/1000,0) -> 0 | BM23: =ROUNDDOWN(J23*設定!$C$15/1000,0) -> 0 | BN23: =L23+M23 -> 0 | BO23: =N23+O23+P23 -> 451835 | BP23: =Q23 -> 0 | BQ23: =R23 -> 236708 | BR23: =S23 -> 0 | BS23: =T23 -> 30968 | BT23: =U23 -> 0 | BU23: =V23 -> 5243 | BV23: =IF(BF23=0,IF(BN23=0,0,1),(BN23-BF23)/BF23) -> 0 | BW23: =IF(BG23=0,IF(BO23=0,0,1),(BO23-BG23)/BG23) -> 1 | BX23: =IF(BH23=0,IF(BP23=0,0,1),(BP23-BH23)/BH23) -> 0 | BY23: =IF(BI23=0,IF(BQ23=0,0,1),(BQ23-BI23)/BI23) -> 1 | BZ23: =IF(BJ23=0,IF(BR23=0,0,1),(BR23-BJ23)/BJ23) -> 0 | CA23: =IF(BK23=0,IF(BS23=0,0,1),(BS23-BK23)/BK23) -> 1 | CB23: =IF(BL23=0,IF(BT23=0,0,1),(BT23-BL23)/BL23) -> 0 | CC23: =IF(BM23=0,IF(BU23=0,0,1),(BU23-BM23)/BM23) -> 1 | CD23: =MAX(MAX(BV23:CC23),-MIN(BV23:CC23)) -> 1 | CE23: =IF(CI23="","",SUMIFS($CF$7:$CF$696,$A$7:$A$696,CI23,$B$7:$B$696,B23)) | CF23: =SUM(AU23:BE23) -> 724754 | CG23: =A23&"|"&B23 -> 2026-04 月例|産業振興センター | CH23: =IFERROR(INDEX(設定!$D$61:$D$106,MATCH(B23,設定!$B$61:$B$106,0)),"Y") -> Y | CI23: =IFERROR(INDEX(設定!$D$20:$D$34,MATCH(A23,設定!$A$20:$A$34,0))&"","")
