Workbook

Sheet 使い方
A1: 傷病手当金 算定表（試算＋調整額＋差額を1ファイルで計算）
A3: 【何が変わったか】
A4: 従来：①簡易試算シートで標準支給額を算出 → ②別ファイルの給与調整シートで調整額を算出 → ③差し引いて支給額を確認
A5: 今回：「入力」シートに入れるだけで、標準支給額・調整額・差引支給額（差額）が「算定表」シートに一度に表示されます。
A7: 【使い方】
A8: 1．「入力」シート：職員番号・氏名・病気休暇開始日を入力（黄色のセルのみ）。退職者は退職日と退職時附加金の受給有無も入力。
A9: 2．「入力」シート：給与証明に基づき、報酬が変わる日（10割→8割→無給、給与改定日など）ごとに1行ずつ入力。
A10: 3．「入力」シート：標準報酬月額（直近12か月＋支給予定月）を入力。基幹で日額を確認済みの場合は「傷病手当日額の確認値」に入力。
A11: 4．「算定表」シートで、月別（月の途中で区分が変わる場合は分割）・法定／附加別の標準支給額・調整額・差引支給額を確認。
A12: 5．「月別集計」シートで月ごと・法定／附加ごとの差引支給額を確認し、桐／基幹の入力額と照合（調整額はマイナスで入力）。
A14: 【シート構成】
A15: 使い方 ／ 入力（黄色セルのみ入力） ／ 算定表（結果。印刷用） ／ 月別集計（基幹入力用） ／ カレンダーマスタ（月ごとの勤務を要する日数）
... A21: ・報酬日額が傷病手当日額以上の月は「支給なし」とし、手当の給付期間の延長は本ファイルでは計算していません。

Sheet 入力
A1: 傷病手当金 算定表（入力シート）
A2: 黄色のセル（青字）だけ入力してください。試算・調整額・差額は「算定表」シートに自動表示されます。
A4: 職員番号 | C4: 0000000 | G4: ■ 給付期間（自動計算）
A5: 氏名 | C5: 広島 太郎 | G5: 支給開始日（待機3日後） | J5: =C6+3
A6: 病気休暇の開始日 | C6: 45495 | D6: ※待機期間（3日）は年休でも可 | G6: 法定給付の末日（1年6月） | J6: =DATE(YEAR(J5)+1,MONTH(J5)+6,DAY(J5)-1)
A7: 退職日（任意） | D7: ※退職者のみ入力（在職中は空欄）。法定給付は退職後も末日まで算定 | G7: 附加給付の開始日 | J7: =J6+1
A8: 傷病手当日額の確認値（任意） | D8: ※基幹の仮入力で確認した日額。入力すると全期間この額で算定。空欄なら下の標準報酬から試算 | G8: 附加給付の末日（+6月） | J8: =DATE(YEAR(J7),MONTH(J7)+6,DAY(J7)-1)
A9: 退職時附加金の受給（退職者のみ） | D9: ※退職日を入力した場合のみ。「有」なら附加は退職日まで、空欄・「無」なら法定のみ | G9: 算定の最終日 | J9: =IF(C7="",J8,IF(C9="有",MAX(J6,MIN(J8,C7)),J6))
A11: ■ 給与状況（給与課の給与証明で確認） ※報酬が変わる日ごとに1行。開始日の古い順に上から入力
A12: 区分 | B12: 開始日 | C12: 終了日 （自動） | D12: 給料月額 | E12: 地域手当 | F12: 扶養手当 | G12: 住居手当 | H12: 日額で支給 されるもの | I12: 月額で支給 されるもの
A13: 10割 | B13: 45495 | C13: =IF(B13="","",IF(AND(B14<>"",B14>B13),B14-1,$J$9)) | D13: 225300 | E13: 22530 | F13: 0 | G13: 0 | H13: =IF(B13="","",D13+E13) | I13: =IF(B13="","",F13+G13)
A14: 10割 | B14: 45658 | C14: =IF(B14="","",IF(AND(B15<>"",B15>B14),B15-1,$J$9)) | D14: 235200 | E14: 23520 | F14: 0 | G14: 0 | H14: =IF(B14="","",D14+E14) | I14: =IF(B14="","",F14+G14)
A15: 8割 | B15: 45675 | C15: =IF(B15="","",IF(AND(B16<>"",B16>B15),B16-1,$J$9)) | D15: 188160 | E15: 18816 | F15: 0 | G15: 0 | H15: =IF(B15="","",D15+E15) | I15: =IF(B15="","",F15+G15)
A16: 8割 | B16: 45748 | C16: =IF(B16="","",IF(AND(B17<>"",B17>B16),B17-1,$J$9)) | D16: 193980 | E16: 19398 | F16: 0 | G16: 0 | H16: =IF(B16="","",D16+E16) | I16: =IF(B16="","",F16+G16)
A17: 8割 | B17: 46023 | C17: =IF(B17="","",IF(AND(B18<>"",B18>B17),B18-1,$J$9)) | D17: 200243 | E17: 20024 | F17: 0 | G17: 0 | H17: =IF(B17="","",D17+E17) | I17: =IF(B17="","",F17+G17)
A18: 無給 | B18: 46040 | C18: =IF(B18="","",IF(AND(B19<>"",B19>B18),B19-1,$J$9)) | D18: 0 | E18: 0 | F18: 0 | G18: 0 | H18: =IF(B18="","",D18+E18) | I18: =IF(B18="","",F18+G18)
C19: =IF(B19="","",IF(AND(B20<>"",B20>B19),B20-1,$J$9)) | H19: =IF(B19="","",D19+E19) | I19: =IF(B19="","",F19+G19)
C20: =IF(B20="","",$J$9) | H20: =IF(B20="","",D20+E20) | I20: =IF(B20="","",F20+G20)
A21: ※日額で支給されるもの＝給料月額＋地域手当、月額で支給されるもの＝扶養手当＋住居手当（旧「計算内訳シート」「給与調整」と同じ区分）。無給期間は全て0。
A22: ※例のデータは、旧「給与調整」シートの給与証明の日額（247,830円など）から逆算したサンプルです。実際の証明額で書き換えてください。
A24: ■ 報酬日額（自動計算）＝ 日額で支給されるもの ÷ 勤務を要する日数 ＋ 月額で支給されるもの ÷ 22 （円未満切捨）
A25: 区分 | B25: 開始日 | C25: 20日の月 | D25: 21日の月 | E25: 22日の月 | F25: 23日の月
A26: =IF(B13="","",A13) | B26: =IF(B13="","",B13) | C26: =IF($B13="","",ROUNDDOWN($H13/20+$I13/22,0)) | D26: =IF($B13="","",ROUNDDOWN($H13/21+$I13/22,0)) | E26: =IF($B13="","",ROUNDDOWN($H13/22+$I13/22,0)) | F26: =IF($B13="","",ROUNDDOWN($H13/23+$I13/22,0))
A27: =IF(B14="","",A14) | B27: =IF(B14="","",B14) | C27: =IF($B14="","",ROUNDDOWN($H14/20+$I14/22,0)) | D27: =IF($B14="","",ROUNDDOWN($H14/21+$I14/22,0)) | E27: =IF($B14="","",ROUNDDOWN($H14/22+$I14/22,0)) | F27: =IF($B14="","",ROUNDDOWN($H14/23+$I14/22,0))
A28: =IF(B15="","",A15) | B28: =IF(B15="","",B15) | C28: =IF($B15="","",ROUNDDOWN($H15/20+$I15/22,0)) | D28: =IF($B15="","",ROUNDDOWN($H15/21+$I15/22,0)) | E28: =IF($B15="","",ROUNDDOWN($H15/22+$I15/22,0)) | F28: =IF($B15="","",ROUNDDOWN($H15/23+$I15/22,0))
A29: =IF(B16="","",A16) | B29: =IF(B16="","",B16) | C29: =IF($B16="","",ROUNDDOWN($H16/20+$I16/22,0)) | D29: =IF($B16="","",ROUNDDOWN($H16/21+$I16/22,0)) | E29: =IF($B16="","",ROUNDDOWN($H16/22+$I16/22,0)) | F29: =IF($B16="","",ROUNDDOWN($H16/23+$I16/22,0))
A30: =IF(B17="","",A17) | B30: =IF(B17="","",B17) | C30: =IF($B17="","",ROUNDDOWN($H17/20+$I17/22,0)) | D30: =IF($B17="","",ROUNDDOWN($H17/21+$I17/22,0)) | E30: =IF($B17="","",ROUNDDOWN($H17/22+$I17/22,0)) | F30: =IF($B17="","",ROUNDDOWN($H17/23+$I17/22,0))
A31: =IF(B18="","",A18) | B31: =IF(B18="","",B18) | C31: =IF($B18="","",ROUNDDOWN($H18/20+$I18/22,0)) | D31: =IF($B18="","",ROUNDDOWN($H18/21+$I18/22,0)) | E31: =IF($B18="","",ROUNDDOWN($H18/22+$I18/22,0)) | F31: =IF($B18="","",ROUNDDOWN($H18/23+$I18/22,0))
A32: =IF(B19="","",A19) | B32: =IF(B19="","",B19) | C32: =IF($B19="","",ROUNDDOWN($H19/20+$I19/22,0)) | D32: =IF($B19="","",ROUNDDOWN($H19/21+$I19/22,0)) | E32: =IF($B19="","",ROUNDDOWN($H19/22+$I19/22,0)) | F32: =IF($B19="","",ROUNDDOWN($H19/23+$I19/22,0))
A33: =IF(B20="","",A20) | B33: =IF(B20="","",B20) | C33: =IF($B20="","",ROUNDDOWN($H20/20+$I20/22,0)) | D33: =IF($B20="","",ROUNDDOWN($H20/21+$I20/22,0)) | E33: =IF($B20="","",ROUNDDOWN($H20/22+$I20/22,0)) | F33: =IF($B20="","",ROUNDDOWN($H20/23+$I20/22,0))
A35: ■ 標準報酬月額と傷病手当日額の試算（直近12か月平均 ÷ 22 → 10円未満四捨五入 → ×2/3 → 1円未満四捨五入）
A36: 年月 | B36: 標準報酬 月額 | C36: 直近12月 平均 | D36: ÷22 | E36: 10円未満 四捨五入 | F36: ×2/3 | G36: 傷病手当 日額
A37: =DATE(YEAR($J$5),MONTH($J$5)-12+0,1) | B37: 440000
A38: =DATE(YEAR($J$5),MONTH($J$5)-12+1,1) | B38: 440000
A39: =DATE(YEAR($J$5),MONTH($J$5)-12+2,1) | B39: 410000
A40: =DATE(YEAR($J$5),MONTH($J$5)-12+3,1) | B40: 410000
A41: =DATE(YEAR($J$5),MONTH($J$5)-12+4,1) | B41: 410000
A42: =DATE(YEAR($J$5),MONTH($J$5)-12+5,1) | B42: 410000
A43: =DATE(YEAR($J$5),MONTH($J$5)-12+6,1) | B43: 410000
A44: =DATE(YEAR($J$5),MONTH($J$5)-12+7,1) | B44: 410000
...

Sheet 月別集計
A1: =算定表!A1
A2: 基幹システム入力用：月ごと・法定／附加ごとに集計します（給与区分で行が分かれる月も1行にまとめています）。
A5: 番号 | B5: 年 | C5: 月 | D5: 給付 区分 | E5: 支給期間 （始） | F5: 支給期間 （終） | G5: 支給日数 | H5: 標準支給額 | I5: 調整額 | J5: 差引支給額 （基幹入力額） | K5: 備考 | L5: 行
A6: =IF(ROW()-5<=MAX(算定表!$Q$6:$Q$53),ROW()-5,"") | B6: =IF(A6="","",INDEX(算定表!$B$6:$B$53,L6)) | C6: =IF(A6="","",INDEX(算定表!$C$6:$C$53,L6)) | D6: =IF(A6="","",INDEX(算定表!$E$6:$E$53,L6)) | E6: =IF(A6="","",INDEX(算定表!$F$6:$F$53,L6)) | F6: =IF(A6="","",LOOKUP(2,1/((算定表!$B$6:$B$53=B6)*(算定表!$C$6:$C$53=C6)*(算定表!$E$6:$E$53=D6)),算定表!$G$6:$G$53)) | G6: =IF(A6="","",SUMIFS(算定表!$I$6:$I$53,算定表!$B$6:$B$53,B6,算定表!$C$6:$C$53,C6,算定表!$E$6:$E$53,D6)) | H6: =IF(A6="","",SUMIFS(算定表!$M$6:$M$53,算定表!$B$6:$B$53,B6,算定表!$C$6:$C$53,C6,算定表!$E$6:$E$53,D6)) | I6: =IF(A6="","",SUMIFS(算定表!$N$6:$N$53,算定表!$B$6:$B$53,B6,算定表!$C$6:$C$53,C6,算定表!$E$6:$E$53,D6)) | J6: =IF(A6="","",SUMIFS(算定表!$O$6:$O$53,算定表!$B$6:$B$53,B6,算定表!$C$6:$C$53,C6,算定表!$E$6:$E$53,D6)) | K6: =IF(A6="","",IF(J6=0,"支給なし","")) | L6: =IF(A6="","",MATCH(A6,算定表!$Q$6:$Q$53,0))
A7: =IF(ROW()-5<=MAX(算定表!$Q$6:$Q$53),ROW()-5,"") | B7: =IF(A7="","",INDEX(算定表!$B$6:$B$53,L7)) | C7: =IF(A7="","",INDEX(算定表!$C$6:$C$53,L7)) | D7: =IF(A7="","",INDEX(算定表!$E$6:$E$53,L7)) | E7: =IF(A7="","",INDEX(算定表!$F$6:$F$53,L7)) | F7: =IF(A7="","",LOOKUP(2,1/((算定表!$B$6:$B$53=B7)*(算定表!$C$6:$C$53=C7)*(算定表!$E$6:$E$53=D7)),算定表!$G$6:$G$53)) | G7: =IF(A7="","",SUMIFS(算定表!$I$6:$I$53,算定表!$B$6:$B$53,B7,算定表!$C$6:$C$53,C7,算定表!$E$6:$E$53,D7)) | H7: =IF(A7="","",SUMIFS(算定表!$M$6:$M$53,算定表!$B$6:$B$53,B7,算定表!$C$6:$C$53,C7,算定表!$E$6:$E$53,D7)) | I7: =IF(A7="","",SUMIFS(算定表!$N$6:$N$53,算定表!$B$6:$B$53,B7,算定表!$C$6:$C$53,C7,算定表!$E$6:$E$53,D7)) | J7: =IF(A7="","",SUMIFS(算定表!$O$6:$O$53,算定表!$B$6:$B$53,B7,算定表!$C$6:$C$53,C7,算定表!$E$6:$E$53,D7)) | K7: =IF(A7="","",IF(J7=0,"支給なし","")) | L7: =IF(A7="","",MATCH(A7,算定表!$Q$6:$Q$53,0))
A8: =IF(ROW()-5<=MAX(算定表!$Q$6:$Q$53),ROW()-5,"") | B8: =IF(A8="","",INDEX(算定表!$B$6:$B$53,L8)) | C8: =IF(A8="","",INDEX(算定表!$C$6:$C$53,L8)) | D8: =IF(A8="","",INDEX(算定表!$E$6:$E$53,L8)) | E8: =IF(A8="","",INDEX(算定表!$F$6:$F$53,L8)) | F8: =IF(A8="","",LOOKUP(2,1/((算定表!$B$6:$B$53=B8)*(算定表!$C$6:$C$53=C8)*(算定表!$E$6:$E$53=D8)),算定表!$G$6:$G$53)) | G8: =IF(A8="","",SUMIFS(算定表!$I$6:$I$53,算定表!$B$6:$B$53,B8,算定表!$C$6:$C$53,C8,算定表!$E$6:$E$53,D8)) | H8: =IF(A8="","",SUMIFS(算定表!$M$6:$M$53,算定表!$B$6:$B$53,B8,算定表!$C$6:$C$53,C8,算定表!$E$6:$E$53,D8)) | I8: =IF(A8="","",SUMIFS(算定表!$N$6:$N$53,算定表!$B$6:$B$53,B8,算定表!$C$6:$C$53,C8,算定表!$E$6:$E$53,D8)) | J8: =IF(A8="","",SUMIFS(算定表!$O$6:$O$53,算定表!$B$6:$B$53,B8,算定表!$C$6:$C$53,C8,算定表!$E$6:$E$53,D8)) | K8: =IF(A8="","",IF(J8=0,"支給なし","")) | L8: =IF(A8="","",MATCH(A8,算定表!$Q$6:$Q$53,0))
A9: =IF(ROW()-5<=MAX(算定表!$Q$6:$Q$53),ROW()-5,"") | B9: =IF(A9="","",INDEX(算定表!$B$6:$B$53,L9)) | C9: =IF(A9="","",INDEX(算定表!$C$6:$C$53,L9)) | D9: =IF(A9="","",INDEX(算定表!$E$6:$E$53,L9)) | E9: =IF(A9="","",INDEX(算定表!$F$6:$F$53,L9)) | F9: =IF(A9="","",LOOKUP(2,1/((算定表!$B$6:$B$53=B9)*(算定表!$C$6:$C$53=C9)*(算定表!$E$6:$E$53=D9)),算定表!$G$6:$G$53)) | G9: =IF(A9="","",SUMIFS(算定表!$I$6:$I$53,算定表!$B$6:$B$53,B9,算定表!$C$6:$C$53,C9,算定表!$E$6:$E$53,D9)) | H9: =IF(A9="","",SUMIFS(算定表!$M$6:$M$53,算定表!$B$6:$B$53,B9,算定表!$C$6:$C$53,C9,算定表!$E$6:$E$53,D9)) | I9: =IF(A9="","",SUMIFS(算定表!$N$6:$N$53,算定表!$B$6:$B$53,B9,算定表!$C$6:$C$53,C9,算定表!$E$6:$E$53,D9)) | J9: =IF(A9="","",SUMIFS(算定表!$O$6:$O$53,算定表!$B$6:$B$53,B9,算定表!$C$6:$C$53,C9,算定表!$E$6:$E$53,D9)) | K9: =IF(A9="","",IF(J9=0,"支給なし","")) | L9: =IF(A9="","",MATCH(A9,算定表!$Q$6:$Q$53,0))
A10: =IF(ROW()-5<=MAX(算定表!$Q$6:$Q$53),ROW()-5,"") | B10: =IF(A10="","",INDEX(算定表!$B$6:$B$53,L10)) | C10: =IF(A10="","",INDEX(算定表!$C$6:$C$53,L10)) | D10: =IF(A10="","",INDEX(算定表!$E$6:$E$53,L10)) | E10: =IF(A10="","",INDEX(算定表!$F$6:$F$53,L10)) | F10: =IF(A10="","",LOOKUP(2,1/((算定表!$B$6:$B$53=B10)*(算定表!$C$6:$C$53=C10)*(算定表!$E$6:$E$53=D10)),算定表!$G$6:$G$53)) | G10: =IF(A10="","",SUMIFS(算定表!$I$6:$I$53,算定表!$B$6:$B$53,B10,算定表!$C$6:$C$53,C10,算定表!$E$6:$E$53,D10)) | H10: =IF(A10="","",SUMIFS(算定表!$M$6:$M$53,算定表!$B$6:$B$53,B10,算定表!$C$6:$C$53,C10,算定表!$E$6:$E$53,D10)) | I10: =IF(A10="","",SUMIFS(算定表!$N$6:$N$53,算定表!$B$6:$B$53,B10,算定表!$C$6:$C$53,C10,算定表!$E$6:$E$53,D10)) | J10: =IF(A10="","",SUMIFS(算定表!$O$6:$O$53,算定表!$B$6:$B$53,B10,算定表!$C$6:$C$53,C10,算定表!$E$6:$E$53,D10)) | K10: =IF(A10="","",IF(J10=0,"支給なし","")) | L10: =IF(A10="","",MATCH(A10,算定表!$Q$6:$Q$53,0))
A11: =IF(ROW()-5<=MAX(算定表!$Q$6:$Q$53),ROW()-5,"") | B11: =IF(A11="","",INDEX(算定表!$B$6:$B$53,L11)) | C11: =IF(A11="","",INDEX(算定表!$C$6:$C$53,L11)) | D11: =IF(A11="","",INDEX(算定表!$E$6:$E$53,L11)) | E11: =IF(A11="","",INDEX(算定表!$F$6:$F$53,L11)) | F11: =IF(A11="","",LOOKUP(2,1/((算定表!$B$6:$B$53=B11)*(算定表!$C$6:$C$53=C11)*(算定表!$E$6:$E$53=D11)),算定表!$G$6:$G$53)) | G11: =IF(A11="","",SUMIFS(算定表!$I$6:$I$53,算定表!$B$6:$B$53,B11,算定表!$C$6:$C$53,C11,算定表!$E$6:$E$53,D11)) | H11: =IF(A11="","",SUMIFS(算定表!$M$6:$M$53,算定表!$B$6:$B$53,B11,算定表!$C$6:$C$53,C11,算定表!$E$6:$E$53,D11)) | I11: =IF(A11="","",SUMIFS(算定表!$N$6:$N$53,算定表!$B$6:$B$53,B11,算定表!$C$6:$C$53,C11,算定表!$E$6:$E$53,D11)) | J11: =IF(A11="","",SUMIFS(算定表!$O$6:$O$53,算定表!$B$6:$B$53,B11,算定表!$C$6:$C$53,C11,算定表!$E$6:$E$53,D11)) | K11: =IF(A11="","",IF(J11=0,"支給なし","")) | L11: =IF(A11="","",MATCH(A11,算定表!$Q$6:$Q$53,0))
A12: =IF(ROW()-5<=MAX(算定表!$Q$6:$Q$53),ROW()-5,"") | B12: =IF(A12="","",INDEX(算定表!$B$6:$B$53,L12)) | C12: =IF(A12="","",INDEX(算定表!$C$6:$C$53,L12)) | D12: =IF(A12="","",INDEX(算定表!$E$6:$E$53,L12)) | E12: =IF(A12="","",INDEX(算定表!$F$6:$F$53,L12)) | F12: =IF(A12="","",LOOKUP(2,1/((算定表!$B$6:$B$53=B12)*(算定表!$C$6:$C$53=C12)*(算定表!$E$6:$E$53=D12)),算定表!$G$6:$G$53)) | G12: =IF(A12="","",SUMIFS(算定表!$I$6:$I$53,算定表!$B$6:$B$53,B12,算定表!$C$6:$C$53,C12,算定表!$E$6:$E$53,D12)) | H12: =IF(A12="","",SUMIFS(算定表!$M$6:$M$53,算定表!$B$6:$B$53,B12,算定表!$C$6:$C$53,C12,算定表!$E$6:$E$53,D12)) | I12: =IF(A12="","",SUMIFS(算定表!$N$6:$N$53,算定表!$B$6:$B$53,B12,算定表!$C$6:$C$53,C12,算定表!$E$6:$E$53,D12)) | J12: =IF(A12="","",SUMIFS(算定表!$O$6:$O$53,算定表!$B$6:$B$53,B12,算定表!$C$6:$C$53,C12,算定表!$E$6:$E$53,D12)) | K12: =IF(A12="","",IF(J12=0,"支給なし","")) | L12: =IF(A12="","",MATCH(A12,算定表!$Q$6:$Q$53,0))
A13: =IF(ROW()-5<=MAX(算定表!$Q$6:$Q$53),ROW()-5,"") | B13: =IF(A13="","",INDEX(算定表!$B$6:$B$53,L13)) | C13: =IF(A13="","",INDEX(算定表!$C$6:$C$53,L13)) | D13: =IF(A13="","",INDEX(算定表!$E$6:$E$53,L13)) | E13: =IF(A13="","",INDEX(算定表!$F$6:$F$53,L13)) | F13: =IF(A13="","",LOOKUP(2,1/((算定表!$B$6:$B$53=B13)*(算定表!$C$6:$C$53=C13)*(算定表!$E$6:$E$53=D13)),算定表!$G$6:$G$53)) | G13: =IF(A13="","",SUMIFS(算定表!$I$6:$I$53,算定表!$B$6:$B$53,B13,算定表!$C$6:$C$53,C13,算定表!$E$6:$E$53,D13)) | H13: =IF(A13="","",SUMIFS(算定表!$M$6:$M$53,算定表!$B$6:$B$53,B13,算定表!$C$6:$C$53,C13,算定表!$E$6:$E$53,D13)) | I13: =IF(A13="","",SUMIFS(算定表!$N$6:$N$53,算定表!$B$6:$B$53,B13,算定表!$C$6:$C$53,C13,算定表!$E$6:$E$53,D13)) | J13: =IF(A13="","",SUMIFS(算定表!$O$6:$O$53,算定表!$B$6:$B$53,B13,算定表!$C$6:$C$53,C13,算定表!$E$6:$E$53,D13)) | K13: =IF(A13="","",IF(J13=0,"支給なし","")) | L13: =IF(A13="","",MATCH(A13,算定表!$Q$6:$Q$53,0))
A14: =IF(ROW()-5<=MAX(算定表!$Q$6:$Q$53),ROW()-5,"") | B14: =IF(A14="","",INDEX(算定表!$B$6:$B$53,L14)) | C14: =IF(A14="","",INDEX(算定表!$C$6:$C$53,L14)) | D14: =IF(A14="","",INDEX(算定表!$E$6:$E$53,L14)) | E14: =IF(A14="","",INDEX(算定表!$F$6:$F$53,L14)) | F14: =IF(A14="","",LOOKUP(2,1/((算定表!$B$6:$B$53=B14)*(算定表!$C$6:$C$53=C14)*(算定表!$E$6:$E$53=D14)),算定表!$G$6:$G$53)) | G14: =IF(A14="","",SUMIFS(算定表!$I$6:$I$53,算定表!$B$6:$B$53,B14,算定表!$C$6:$C$53,C14,算定表!$E$6:$E$53,D14)) | H14: =IF(A14="","",SUMIFS(算定表!$M$6:$M$53,算定表!$B$6:$B$53,B14,算定表!$C$6:$C$53,C14,算定表!$E$6:$E$53,D14)) | I14: =IF(A14="","",SUMIFS(算定表!$N$6:$N$53,算定表!$B$6:$B$53,B14,算定表!$C$6:$C$53,C14,算定表!$E$6:$E$53,D14)) | J14: =IF(A14="","",SUMIFS(算定表!$O$6:$O$53,算定表!$B$6:$B$53,B14,算定表!$C$6:$C$53,C14,算定表!$E$6:$E$53,D14)) | K14: =IF(A14="","",IF(J14=0,"支給なし","")) | L14: =IF(A14="","",MATCH(A14,算定表!$Q$6:$Q$53,0))
A15: =IF(ROW()-5<=MAX(算定表!$Q$6:$Q$53),ROW()-5,"") | B15: =IF(A15="","",INDEX(算定表!$B$6:$B$53,L15)) | C15: =IF(A15="","",INDEX(算定表!$C$6:$C$53,L15)) | D15: =IF(A15="","",INDEX(算定表!$E$6:$E$53,L15)) | E15: =IF(A15="","",INDEX(算定表!$F$6:$F$53,L15)) | F15: =IF(A15="","",LOOKUP(2,1/((算定表!$B$6:$B$53=B15)*(算定表!$C$6:$C$53=C15)*(算定表!$E$6:$E$53=D15)),算定表!$G$6:$G$53)) | G15: =IF(A15="","",SUMIFS(算定表!$I$6:$I$53,算定表!$B$6:$B$53,B15,算定表!$C$6:$C$53,C15,算定表!$E$6:$E$53,D15)) | H15: =IF(A15="","",SUMIFS(算定表!$M$6:$M$53,算定表!$B$6:$B$53,B15,算定表!$C$6:$C$53,C15,算定表!$E$6:$E$53,D15)) | I15: =IF(A15="","",SUMIFS(算定表!$N$6:$N$53,算定表!$B$6:$B$53,B15,算定表!$C$6:$C$53,C15,算定表!$E$6:$E$53,D15)) | J15: =IF(A15="","",SUMIFS(算定表!$O$6:$O$53,算定表!$B$6:$B$53,B15,算定表!$C$6:$C$53,C15,算定表!$E$6:$E$53,D15)) | K15: =IF(A15="","",IF(J15=0,"支給なし","")) | L15: =IF(A15="","",MATCH(A15,算定表!$Q$6:$Q$53,0))
A16: =IF(ROW()-5<=MAX(算定表!$Q$6:$Q$53),ROW()-5,"") | B16: =IF(A16="","",INDEX(算定表!$B$6:$B$53,L16)) | C16: =IF(A16="","",INDEX(算定表!$C$6:$C$53,L16)) | D16: =IF(A16="","",INDEX(算定表!$E$6:$E$53,L16)) | E16: =IF(A16="","",INDEX(算定表!$F$6:$F$53,L16)) | F16: =IF(A16="","",LOOKUP(2,1/((算定表!$B$6:$B$53=B16)*(算定表!$C$6:$C$53=C16)*(算定表!$E$6:$E$53=D16)),算定表!$G$6:$G$53)) | G16: =IF(A16="","",SUMIFS(算定表!$I$6:$I$53,算定表!$B$6:$B$53,B16,算定表!$C$6:$C$53,C16,算定表!$E$6:$E$53,D16)) | H16: =IF(A16="","",SUMIFS(算定表!$M$6:$M$53,算定表!$B$6:$B$53,B16,算定表!$C$6:$C$53,C16,算定表!$E$6:$E$53,D16)) | I16: =IF(A16="","",SUMIFS(算定表!$N$6:$N$53,算定表!$B$6:$B$53,B16,算定表!$C$6:$C$53,C16,算定表!$E$6:$E$53,D16)) | J16: =IF(A16="","",SUMIFS(算定表!$O$6:$O$53,算定表!$B$6:$B$53,B16,算定表!$C$6:$C$53,C16,算定表!$E$6:$E$53,D16)) | K16: =IF(A16="","",IF(J16=0,"支給なし","")) | L16: =IF(A16="","",MATCH(A16,算定表!$Q$6:$Q$53,0))
A17: =IF(ROW()-5<=MAX(算定表!$Q$6:$Q$53),ROW()-5,"") | B17: =IF(A17="","",INDEX(算定表!$B$6:$B$53,L17)) | C17: =IF(A17="","",INDEX(算定表!$C$6:$C$53,L17)) | D17: =IF(A17="","",INDEX(算定表!$E$6:$E$53,L17)) | E17: =IF(A17="","",INDEX(算定表!$F$6:$F$53,L17)) | F17: =IF(A17="","",LOOKUP(2,1/((算定表!$B$6:$B$53=B17)*(算定表!$C$6:$C$53=C17)*(算定表!$E$6:$E$53=D17)),算定表!$G$6:$G$53)) | G17: =IF(A17="","",SUMIFS(算定表!$I$6:$I$53,算定表!$B$6:$B$53,B17,算定表!$C$6:$C$53,C17,算定表!$E$6:$E$53,D17)) | H17: =IF(A17="","",SUMIFS(算定表!$M$6:$M$53,算定表!$B$6:$B$53,B17,算定表!$C$6:$C$53,C17,算定表!$E$6:$E$53,D17)) | I17: =IF(A17="","",SUMIFS(算定表!$N$6:$N$53,算定表!$B$6:$B$53,B17,算定表!$C$6:$C$53,C17,算定表!$E$6:$E$53,D17)) | J17: =IF(A17="","",SUMIFS(算定表!$O$6:$O$53,算定表!$B$6:$B$53,B17,算定表!$C$6:$C$53,C17,算定表!$E$6:$E$53,D17)) | K17: =IF(A17="","",IF(J17=0,"支給なし","")) | L17: =IF(A17="","",MATCH(A17,算定表!$Q$6:$Q$53,0))
... A35: =IF(ROW()-5<=MAX(算定表!$Q$6:$Q$53),ROW()-5,"") | B35: =IF(A35="","",INDEX(算定表!$B$6:$B$53,L35)) | C35: =IF(A35="","",INDEX(算定表!$C$6:$C$53,L35)) | D35: =IF(A35="","",INDEX(算定表!$E$6:$E$53,L35)) | E35: =IF(A35="","",INDEX(算定表!$F$6:$F$53,L35)) | F35: =IF(A35="","",LOOKUP(2,1/((算定表!$B$6:$B$53=B35)*(算定表!$C$6:$C$53=C35)*(算定表!$E$6:$E$53=D35)),算定表!$G$6:$G$53)) | G35: =IF(A35="","",SUMIFS(算定表!$I$6:$I$53,算定表!$B$6:$B$53,B35,算定表!$C$6:$C$53,C35,算定表!$E$6:$E$53,D35)) | H35: =IF(A35="","",SUMIFS(算定表!$M$6:$M$53,算定表!$B$6:$B$53,B35,算定表!$C$6:$C$53,C35,算定表!$E$6:$E$53,D35)) | I35: =IF(A35="","",SUMIFS(算定表!$N$6:$N$53,算定表!$B$6:$B$53,B35,算定表!$C$6:$C$53,C35,算定表!$E$6:$E$53,D35)) | J35: =IF(A35="","",SUMIFS(算定表!$O$6:$O$53,算定表!$B$6:$B$53,B35,算定表!$C$6:$C$53,C35,算定表!$E$6:$E$53,D35)) | K35: =IF(A35="","",IF(J35=0,"支給なし","")) | L35: =IF(A35="","",MATCH(A35,算定表!$Q$6:$Q$53,0))
A37: 法定給付 計 | G37: =SUMIFS(G6:G35,$D$6:$D$35,"法定") | H37: =SUMIFS(H6:H35,$D$6:$D$35,"法定") | I37: =SUMIFS(I6:I35,$D$6:$D$35,"法定") | J37: =SUMIFS(J6:J35,$D$6:$D$35,"法定")
A38: 附加給付 計 | G38: =SUMIFS(G6:G35,$D$6:$D$35,"附加") | H38: =SUMIFS(H6:H35,$D$6:$D$35,"附加") | I38: =SUMIFS(I6:I35,$D$6:$D$35,"附加") | J38: =SUMIFS(J6:J35,$D$6:$D$35,"附加")
A39: 合 計 | G39: =SUM(G37:G38) | H39: =SUM(H37:H38) | I39: =SUM(I37:I38) | J39: =SUM(J37:J38)
A41: ■ 検算（算定表の合計との差。0なら整合）
A42: 差引支給額：月別集計 − 算定表 | J42: =J39-算定表!O57
A43: 支給日数：月別集計 − 算定表 | G43: =G39-算定表!I57
A45: ・基幹の「調整額」欄は、障害年金等との調整がある場合のみマイナスで追加入力します（本表の調整額は報酬との調整額）。

Sheet 算定表
A1: ="（"&入力!C4&"） "&入力!C5
A2: ="病気休暇：" & TEXT(入力!C6,"yyyy/m/d") & "～ 傷病手当（法定）：" & TEXT(入力!J5,"yyyy/m/d") & "～" & TEXT(入力!J6,"yyyy/m/d")& IF(入力!J9>入力!J6," 附加給付：" & TEXT(入力!J7,"yyyy/m/d") & "～" & TEXT(入力!J9,"yyyy/m/d")," 附加給付：なし")
A3: 標準支給額（報酬がないとした場合の額）から、報酬との調整額を差し引いた「差引支給額」を月別・給付区分別に自動計算します。
A5: 番号 | B5: 年 | C5: 月 | D5: 給与 区分 | E5: 給付 区分 | F5: 支給期間 （始） | G5: 支給期間 （終） | H5: 勤務を 要する日 | I5: 支給日数 （A） | J5: 傷病手当 日額（B） | K5: 報酬日額 （C） | L5: 支給 可否 | M5: 標準支給額 （F=B×A） | N5: 調整額 （G） | O5: 差引支給額 （E=F−G） | Q5: 集計用
A6: =IF(F6="","",1) | B6: =IF(F6="","",YEAR(F6)) | C6: =IF(F6="","",MONTH(F6)) | D6: =IF(F6="","",INDEX(入力!$A$13:$A$20,MATCH(F6,入力!$B$13:$B$20,1))) | E6: =IF(F6="","",IF(G6<=入力!$J$6,"法定","附加")) | F6: =入力!$J$5 | G6: =IF(F6="","",MIN(EOMONTH(F6,0),入力!$J$9,IF(AND(入力!$B$13<>"",入力!$B$13>F6),入力!$B$13-1,999999),IF(AND(入力!$B$14<>"",入力!$B$14>F6),入力!$B$14-1,999999),IF(AND(入力!$B$15<>"",入力!$B$15>F6),入力!$B$15-1,999999),IF(AND(入力!$B$16<>"",入力!$B$16>F6),入力!$B$16-1,999999),IF(AND(入力!$B$17<>"",入力!$B$17>F6),入力!$B$17-1,999999),IF(AND(入力!$B$18<>"",入力!$B$18>F6),入力!$B$18-1,999999),IF(AND(入力!$B$19<>"",入力!$B$19>F6),入力!$B$19-1,999999),IF(AND(入力!$B$20<>"",入力!$B$20>F6),入力!$B$20-1,999999),IF(AND(入力!$J$7<>"",入力!$J$7>F6),入力!$J$7-1,999999))) | H6: =IF(F6="","",IFERROR(VLOOKUP(DATE(B6,C6,1),カレンダーマスタ!$A$2:$B$97,2,0),NETWORKDAYS(DATE(B6,C6,1),EOMONTH(F6,0)))) | I6: =IF(F6="","",NETWORKDAYS(F6,G6)) | J6: =IF(F6="","",IF(入力!$C$8<>"",入力!$C$8,INDEX(入力!$G$37:$G$78,MATCH(DATE(B6,C6,1),入力!$A$37:$A$78,0)))) | K6: =IF(F6="","",ROUNDDOWN(INDEX(入力!$H$13:$H$20,MATCH(F6,入力!$B$13:$B$20,1))/H6+INDEX(入力!$I$13:$I$20,MATCH(F6,入力!$B$13:$B$20,1))/22,0)) | L6: =IF(F6="","",IF(J6>K6,"〇","×")) | M6: =IF(F6="","",J6*I6) | N6: =IF(F6="","",MIN(J6,K6)*I6) | O6: =IF(F6="","",M6-N6) | Q6: =IF(F6="","",IF(COUNTIFS($B$6:B6,B6,$C$6:C6,C6,$E$6:E6,E6)=1,MAX($Q$5:Q5)+1,""))
A7: =IF(F7="","",2) | B7: =IF(F7="","",YEAR(F7)) | C7: =IF(F7="","",MONTH(F7)) | D7: =IF(F7="","",INDEX(入力!$A$13:$A$20,MATCH(F7,入力!$B$13:$B$20,1))) | E7: =IF(F7="","",IF(G7<=入力!$J$6,"法定","附加")) | F7: =IF(G6="","",IF(G6>=入力!$J$9,"",G6+1)) | G7: =IF(F7="","",MIN(EOMONTH(F7,0),入力!$J$9,IF(AND(入力!$B$13<>"",入力!$B$13>F7),入力!$B$13-1,999999),IF(AND(入力!$B$14<>"",入力!$B$14>F7),入力!$B$14-1,999999),IF(AND(入力!$B$15<>"",入力!$B$15>F7),入力!$B$15-1,999999),IF(AND(入力!$B$16<>"",入力!$B$16>F7),入力!$B$16-1,999999),IF(AND(入力!$B$17<>"",入力!$B$17>F7),入力!$B$17-1,999999),IF(AND(入力!$B$18<>"",入力!$B$18>F7),入力!$B$18-1,999999),IF(AND(入力!$B$19<>"",入力!$B$19>F7),入力!$B$19-1,999999),IF(AND(入力!$B$20<>"",入力!$B$20>F7),入力!$B$20-1,999999),IF(AND(入力!$J$7<>"",入力!$J$7>F7),入力!$J$7-1,999999))) | H7: =IF(F7="","",IFERROR(VLOOKUP(DATE(B7,C7,1),カレンダーマスタ!$A$2:$B$97,2,0),NETWORKDAYS(DATE(B7,C7,1),EOMONTH(F7,0)))) | I7: =IF(F7="","",NETWORKDAYS(F7,G7)) | J7: =IF(F7="","",IF(入力!$C$8<>"",入力!$C$8,INDEX(入力!$G$37:$G$78,MATCH(DATE(B7,C7,1),入力!$A$37:$A$78,0)))) | K7: =IF(F7="","",ROUNDDOWN(INDEX(入力!$H$13:$H$20,MATCH(F7,入力!$B$13:$B$20,1))/H7+INDEX(入力!$I$13:$I$20,MATCH(F7,入力!$B$13:$B$20,1))/22,0)) | L7: =IF(F7="","",IF(J7>K7,"〇","×")) | M7: =IF(F7="","",J7*I7) | N7: =IF(F7="","",MIN(J7,K7)*I7) | O7: =IF(F7="","",M7-N7) | Q7: =IF(F7="","",IF(COUNTIFS($B$6:B7,B7,$C$6:C7,C7,$E$6:E7,E7)=1,MAX($Q$5:Q6)+1,""))
A8: =IF(F8="","",3) | B8: =IF(F8="","",YEAR(F8)) | C8: =IF(F8="","",MONTH(F8)) | D8: =IF(F8="","",INDEX(入力!$A$13:$A$20,MATCH(F8,入力!$B$13:$B$20,1))) | E8: =IF(F8="","",IF(G8<=入力!$J$6,"法定","附加")) | F8: =IF(G7="","",IF(G7>=入力!$J$9,"",G7+1)) | G8: =IF(F8="","",MIN(EOMONTH(F8,0),入力!$J$9,IF(AND(入力!$B$13<>"",入力!$B$13>F8),入力!$B$13-1,999999),IF(AND(入力!$B$14<>"",入力!$B$14>F8),入力!$B$14-1,999999),IF(AND(入力!$B$15<>"",入力!$B$15>F8),入力!$B$15-1,999999),IF(AND(入力!$B$16<>"",入力!$B$16>F8),入力!$B$16-1,999999),IF(AND(入力!$B$17<>"",入力!$B$17>F8),入力!$B$17-1,999999),IF(AND(入力!$B$18<>"",入力!$B$18>F8),入力!$B$18-1,999999),IF(AND(入力!$B$19<>"",入力!$B$19>F8),入力!$B$19-1,999999),IF(AND(入力!$B$20<>"",入力!$B$20>F8),入力!$B$20-1,999999),IF(AND(入力!$J$7<>"",入力!$J$7>F8),入力!$J$7-1,999999))) | H8: =IF(F8="","",IFERROR(VLOOKUP(DATE(B8,C8,1),カレンダーマスタ!$A$2:$B$97,2,0),NETWORKDAYS(DATE(B8,C8,1),EOMONTH(F8,0)))) | I8: =IF(F8="","",NETWORKDAYS(F8,G8)) | J8: =IF(F8="","",IF(入力!$C$8<>"",入力!$C$8,INDEX(入力!$G$37:$G$78,MATCH(DATE(B8,C8,1),入力!$A$37:$A$78,0)))) | K8: =IF(F8="","",ROUNDDOWN(INDEX(入力!$H$13:$H$20,MATCH(F8,入力!$B$13:$B$20,1))/H8+INDEX(入力!$I$13:$I$20,MATCH(F8,入力!$B$13:$B$20,1))/22,0)) | L8: =IF(F8="","",IF(J8>K8,"〇","×")) | M8: =IF(F8="","",J8*I8) | N8: =IF(F8="","",MIN(J8,K8)*I8) | O8: =IF(F8="","",M8-N8) | Q8: =IF(F8="","",IF(COUNTIFS($B$6:B8,B8,$C$6:C8,C8,$E$6:E8,E8)=1,MAX($Q$5:Q7)+1,""))
A9: =IF(F9="","",4) | B9: =IF(F9="","",YEAR(F9)) | C9: =IF(F9="","",MONTH(F9)) | D9: =IF(F9="","",INDEX(入力!$A$13:$A$20,MATCH(F9,入力!$B$13:$B$20,1))) | E9: =IF(F9="","",IF(G9<=入力!$J$6,"法定","附加")) | F9: =IF(G8="","",IF(G8>=入力!$J$9,"",G8+1)) | G9: =IF(F9="","",MIN(EOMONTH(F9,0),入力!$J$9,IF(AND(入力!$B$13<>"",入力!$B$13>F9),入力!$B$13-1,999999),IF(AND(入力!$B$14<>"",入力!$B$14>F9),入力!$B$14-1,999999),IF(AND(入力!$B$15<>"",入力!$B$15>F9),入力!$B$15-1,999999),IF(AND(入力!$B$16<>"",入力!$B$16>F9),入力!$B$16-1,999999),IF(AND(入力!$B$17<>"",入力!$B$17>F9),入力!$B$17-1,999999),IF(AND(入力!$B$18<>"",入力!$B$18>F9),入力!$B$18-1,999999),IF(AND(入力!$B$19<>"",入力!$B$19>F9),入力!$B$19-1,999999),IF(AND(入力!$B$20<>"",入力!$B$20>F9),入力!$B$20-1,999999),IF(AND(入力!$J$7<>"",入力!$J$7>F9),入力!$J$7-1,999999))) | H9: =IF(F9="","",IFERROR(VLOOKUP(DATE(B9,C9,1),カレンダーマスタ!$A$2:$B$97,2,0),NETWORKDAYS(DATE(B9,C9,1),EOMONTH(F9,0)))) | I9: =IF(F9="","",NETWORKDAYS(F9,G9)) | J9: =IF(F9="","",IF(入力!$C$8<>"",入力!$C$8,INDEX(入力!$G$37:$G$78,MATCH(DATE(B9,C9,1),入力!$A$37:$A$78,0)))) | K9: =IF(F9="","",ROUNDDOWN(INDEX(入力!$H$13:$H$20,MATCH(F9,入力!$B$13:$B$20,1))/H9+INDEX(入力!$I$13:$I$20,MATCH(F9,入力!$B$13:$B$20,1))/22,0)) | L9: =IF(F9="","",IF(J9>K9,"〇","×")) | M9: =IF(F9="","",J9*I9) | N9: =IF(F9="","",MIN(J9,K9)*I9) | O9: =IF(F9="","",M9-N9) | Q9: =IF(F9="","",IF(COUNTIFS($B$6:B9,B9,$C$6:C9,C9,$E$6:E9,E9)=1,MAX($Q$5:Q8)+1,""))
A10: =IF(F10="","",5) | B10: =IF(F10="","",YEAR(F10)) | C10: =IF(F10="","",MONTH(F10)) | D10: =IF(F10="","",INDEX(入力!$A$13:$A$20,MATCH(F10,入力!$B$13:$B$20,1))) | E10: =IF(F10="","",IF(G10<=入力!$J$6,"法定","附加")) | F10: =IF(G9="","",IF(G9>=入力!$J$9,"",G9+1)) | G10: =IF(F10="","",MIN(EOMONTH(F10,0),入力!$J$9,IF(AND(入力!$B$13<>"",入力!$B$13>F10),入力!$B$13-1,999999),IF(AND(入力!$B$14<>"",入力!$B$14>F10),入力!$B$14-1,999999),IF(AND(入力!$B$15<>"",入力!$B$15>F10),入力!$B$15-1,999999),IF(AND(入力!$B$16<>"",入力!$B$16>F10),入力!$B$16-1,999999),IF(AND(入力!$B$17<>"",入力!$B$17>F10),入力!$B$17-1,999999),IF(AND(入力!$B$18<>"",入力!$B$18>F10),入力!$B$18-1,999999),IF(AND(入力!$B$19<>"",入力!$B$19>F10),入力!$B$19-1,999999),IF(AND(入力!$B$20<>"",入力!$B$20>F10),入力!$B$20-1,999999),IF(AND(入力!$J$7<>"",入力!$J$7>F10),入力!$J$7-1,999999))) | H10: =IF(F10="","",IFERROR(VLOOKUP(DATE(B10,C10,1),カレンダーマスタ!$A$2:$B$97,2,0),NETWORKDAYS(DATE(B10,C10,1),EOMONTH(F10,0)))) | I10: =IF(F10="","",NETWORKDAYS(F10,G10)) | J10: =IF(F10="","",IF(入力!$C$8<>"",入力!$C$8,INDEX(入力!$G$37:$G$78,MATCH(DATE(B10,C10,1),入力!$A$37:$A$78,0)))) | K10: =IF(F10="","",ROUNDDOWN(INDEX(入力!$H$13:$H$20,MATCH(F10,入力!$B$13:$B$20,1))/H10+INDEX(入力!$I$13:$I$20,MATCH(F10,入力!$B$13:$B$20,1))/22,0)) | L10: =IF(F10="","",IF(J10>K10,"〇","×")) | M10: =IF(F10="","",J10*I10) | N10: =IF(F10="","",MIN(J10,K10)*I10) | O10: =IF(F10="","",M10-N10) | Q10: =IF(F10="","",IF(COUNTIFS($B$6:B10,B10,$C$6:C10,C10,$E$6:E10,E10)=1,MAX($Q$5:Q9)+1,""))
A11: =IF(F11="","",6) | B11: =IF(F11="","",YEAR(F11)) | C11: =IF(F11="","",MONTH(F11)) | D11: =IF(F11="","",INDEX(入力!$A$13:$A$20,MATCH(F11,入力!$B$13:$B$20,1))) | E11: =IF(F11="","",IF(G11<=入力!$J$6,"法定","附加")) | F11: =IF(G10="","",IF(G10>=入力!$J$9,"",G10+1)) | G11: =IF(F11="","",MIN(EOMONTH(F11,0),入力!$J$9,IF(AND(入力!$B$13<>"",入力!$B$13>F11),入力!$B$13-1,999999),IF(AND(入力!$B$14<>"",入力!$B$14>F11),入力!$B$14-1,999999),IF(AND(入力!$B$15<>"",入力!$B$15>F11),入力!$B$15-1,999999),IF(AND(入力!$B$16<>"",入力!$B$16>F11),入力!$B$16-1,999999),IF(AND(入力!$B$17<>"",入力!$B$17>F11),入力!$B$17-1,999999),IF(AND(入力!$B$18<>"",入力!$B$18>F11),入力!$B$18-1,999999),IF(AND(入力!$B$19<>"",入力!$B$19>F11),入力!$B$19-1,999999),IF(AND(入力!$B$20<>"",入力!$B$20>F11),入力!$B$20-1,999999),IF(AND(入力!$J$7<>"",入力!$J$7>F11),入力!$J$7-1,999999))) | H11: =IF(F11="","",IFERROR(VLOOKUP(DATE(B11,C11,1),カレンダーマスタ!$A$2:$B$97,2,0),NETWORKDAYS(DATE(B11,C11,1),EOMONTH(F11,0)))) | I11: =IF(F11="","",NETWORKDAYS(F11,G11)) | J11: =IF(F11="","",IF(入力!$C$8<>"",入力!$C$8,INDEX(入力!$G$37:$G$78,MATCH(DATE(B11,C11,1),入力!$A$37:$A$78,0)))) | K11: =IF(F11="","",ROUNDDOWN(INDEX(入力!$H$13:$H$20,MATCH(F11,入力!$B$13:$B$20,1))/H11+INDEX(入力!$I$13:$I$20,MATCH(F11,入力!$B$13:$B$20,1))/22,0)) | L11: =IF(F11="","",IF(J11>K11,"〇","×")) | M11: =IF(F11="","",J11*I11) | N11: =IF(F11="","",MIN(J11,K11)*I11) | O11: =IF(F11="","",M11-N11) | Q11: =IF(F11="","",IF(COUNTIFS($B$6:B11,B11,$C$6:C11,C11,$E$6:E11,E11)=1,MAX($Q$5:Q10)+1,""))
A12: =IF(F12="","",7) | B12: =IF(F12="","",YEAR(F12)) | C12: =IF(F12="","",MONTH(F12)) | D12: =IF(F12="","",INDEX(入力!$A$13:$A$20,MATCH(F12,入力!$B$13:$B$20,1))) | E12: =IF(F12="","",IF(G12<=入力!$J$6,"法定","附加")) | F12: =IF(G11="","",IF(G11>=入力!$J$9,"",G11+1)) | G12: =IF(F12="","",MIN(EOMONTH(F12,0),入力!$J$9,IF(AND(入力!$B$13<>"",入力!$B$13>F12),入力!$B$13-1,999999),IF(AND(入力!$B$14<>"",入力!$B$14>F12),入力!$B$14-1,999999),IF(AND(入力!$B$15<>"",入力!$B$15>F12),入力!$B$15-1,999999),IF(AND(入力!$B$16<>"",入力!$B$16>F12),入力!$B$16-1,999999),IF(AND(入力!$B$17<>"",入力!$B$17>F12),入力!$B$17-1,999999),IF(AND(入力!$B$18<>"",入力!$B$18>F12),入力!$B$18-1,999999),IF(AND(入力!$B$19<>"",入力!$B$19>F12),入力!$B$19-1,999999),IF(AND(入力!$B$20<>"",入力!$B$20>F12),入力!$B$20-1,999999),IF(AND(入力!$J$7<>"",入力!$J$7>F12),入力!$J$7-1,999999))) | H12: =IF(F12="","",IFERROR(VLOOKUP(DATE(B12,C12,1),カレンダーマスタ!$A$2:$B$97,2,0),NETWORKDAYS(DATE(B12,C12,1),EOMONTH(F12,0)))) | I12: =IF(F12="","",NETWORKDAYS(F12,G12)) | J12: =IF(F12="","",IF(入力!$C$8<>"",入力!$C$8,INDEX(入力!$G$37:$G$78,MATCH(DATE(B12,C12,1),入力!$A$37:$A$78,0)))) | K12: =IF(F12="","",ROUNDDOWN(INDEX(入力!$H$13:$H$20,MATCH(F12,入力!$B$13:$B$20,1))/H12+INDEX(入力!$I$13:$I$20,MATCH(F12,入力!$B$13:$B$20,1))/22,0)) | L12: =IF(F12="","",IF(J12>K12,"〇","×")) | M12: =IF(F12="","",J12*I12) | N12: =IF(F12="","",MIN(J12,K12)*I12) | O12: =IF(F12="","",M12-N12) | Q12: =IF(F12="","",IF(COUNTIFS($B$6:B12,B12,$C$6:C12,C12,$E$6:E12,E12)=1,MAX($Q$5:Q11)+1,""))
A13: =IF(F13="","",8) | B13: =IF(F13="","",YEAR(F13)) | C13: =IF(F13="","",MONTH(F13)) | D13: =IF(F13="","",INDEX(入力!$A$13:$A$20,MATCH(F13,入力!$B$13:$B$20,1))) | E13: =IF(F13="","",IF(G13<=入力!$J$6,"法定","附加")) | F13: =IF(G12="","",IF(G12>=入力!$J$9,"",G12+1)) | G13: =IF(F13="","",MIN(EOMONTH(F13,0),入力!$J$9,IF(AND(入力!$B$13<>"",入力!$B$13>F13),入力!$B$13-1,999999),IF(AND(入力!$B$14<>"",入力!$B$14>F13),入力!$B$14-1,999999),IF(AND(入力!$B$15<>"",入力!$B$15>F13),入力!$B$15-1,999999),IF(AND(入力!$B$16<>"",入力!$B$16>F13),入力!$B$16-1,999999),IF(AND(入力!$B$17<>"",入力!$B$17>F13),入力!$B$17-1,999999),IF(AND(入力!$B$18<>"",入力!$B$18>F13),入力!$B$18-1,999999),IF(AND(入力!$B$19<>"",入力!$B$19>F13),入力!$B$19-1,999999),IF(AND(入力!$B$20<>"",入力!$B$20>F13),入力!$B$20-1,999999),IF(AND(入力!$J$7<>"",入力!$J$7>F13),入力!$J$7-1,999999))) | H13: =IF(F13="","",IFERROR(VLOOKUP(DATE(B13,C13,1),カレンダーマスタ!$A$2:$B$97,2,0),NETWORKDAYS(DATE(B13,C13,1),EOMONTH(F13,0)))) | I13: =IF(F13="","",NETWORKDAYS(F13,G13)) | J13: =IF(F13="","",IF(入力!$C$8<>"",入力!$C$8,INDEX(入力!$G$37:$G$78,MATCH(DATE(B13,C13,1),入力!$A$37:$A$78,0)))) | K13: =IF(F13="","",ROUNDDOWN(INDEX(入力!$H$13:$H$20,MATCH(F13,入力!$B$13:$B$20,1))/H13+INDEX(入力!$I$13:$I$20,MATCH(F13,入力!$B$13:$B$20,1))/22,0)) | L13: =IF(F13="","",IF(J13>K13,"〇","×")) | M13: =IF(F13="","",J13*I13) | N13: =IF(F13="","",MIN(J13,K13)*I13) | O13: =IF(F13="","",M13-N13) | Q13: =IF(F13="","",IF(COUNTIFS($B$6:B13,B13,$C$6:C13,C13,$E$6:E13,E13)=1,MAX($Q$5:Q12)+1,""))
A14: =IF(F14="","",9) | B14: =IF(F14="","",YEAR(F14)) | C14: =IF(F14="","",MONTH(F14)) | D14: =IF(F14="","",INDEX(入力!$A$13:$A$20,MATCH(F14,入力!$B$13:$B$20,1))) | E14: =IF(F14="","",IF(G14<=入力!$J$6,"法定","附加")) | F14: =IF(G13="","",IF(G13>=入力!$J$9,"",G13+1)) | G14: =IF(F14="","",MIN(EOMONTH(F14,0),入力!$J$9,IF(AND(入力!$B$13<>"",入力!$B$13>F14),入力!$B$13-1,999999),IF(AND(入力!$B$14<>"",入力!$B$14>F14),入力!$B$14-1,999999),IF(AND(入力!$B$15<>"",入力!$B$15>F14),入力!$B$15-1,999999),IF(AND(入力!$B$16<>"",入力!$B$16>F14),入力!$B$16-1,999999),IF(AND(入力!$B$17<>"",入力!$B$17>F14),入力!$B$17-1,999999),IF(AND(入力!$B$18<>"",入力!$B$18>F14),入力!$B$18-1,999999),IF(AND(入力!$B$19<>"",入力!$B$19>F14),入力!$B$19-1,999999),IF(AND(入力!$B$20<>"",入力!$B$20>F14),入力!$B$20-1,999999),IF(AND(入力!$J$7<>"",入力!$J$7>F14),入力!$J$7-1,999999))) | H14: =IF(F14="","",IFERROR(VLOOKUP(DATE(B14,C14,1),カレンダーマスタ!$A$2:$B$97,2,0),NETWORKDAYS(DATE(B14,C14,1),EOMONTH(F14,0)))) | I14: =IF(F14="","",NETWORKDAYS(F14,G14)) | J14: =IF(F14="","",IF(入力!$C$8<>"",入力!$C$8,INDEX(入力!$G$37:$G$78,MATCH(DATE(B14,C14,1),入力!$A$37:$A$78,0)))) | K14: =IF(F14="","",ROUNDDOWN(INDEX(入力!$H$13:$H$20,MATCH(F14,入力!$B$13:$B$20,1))/H14+INDEX(入力!$I$13:$I$20,MATCH(F14,入力!$B$13:$B$20,1))/22,0)) | L14: =IF(F14="","",IF(J14>K14,"〇","×")) | M14: =IF(F14="","",J14*I14) | N14: =IF(F14="","",MIN(J14,K14)*I14) | O14: =IF(F14="","",M14-N14) | Q14: =IF(F14="","",IF(COUNTIFS($B$6:B14,B14,$C$6:C14,C14,$E$6:E14,E14)=1,MAX($Q$5:Q13)+1,""))
A15: =IF(F15="","",10) | B15: =IF(F15="","",YEAR(F15)) | C15: =IF(F15="","",MONTH(F15)) | D15: =IF(F15="","",INDEX(入力!$A$13:$A$20,MATCH(F15,入力!$B$13:$B$20,1))) | E15: =IF(F15="","",IF(G15<=入力!$J$6,"法定","附加")) | F15: =IF(G14="","",IF(G14>=入力!$J$9,"",G14+1)) | G15: =IF(F15="","",MIN(EOMONTH(F15,0),入力!$J$9,IF(AND(入力!$B$13<>"",入力!$B$13>F15),入力!$B$13-1,999999),IF(AND(入力!$B$14<>"",入力!$B$14>F15),入力!$B$14-1,999999),IF(AND(入力!$B$15<>"",入力!$B$15>F15),入力!$B$15-1,999999),IF(AND(入力!$B$16<>"",入力!$B$16>F15),入力!$B$16-1,999999),IF(AND(入力!$B$17<>"",入力!$B$17>F15),入力!$B$17-1,999999),IF(AND(入力!$B$18<>"",入力!$B$18>F15),入力!$B$18-1,999999),IF(AND(入力!$B$19<>"",入力!$B$19>F15),入力!$B$19-1,999999),IF(AND(入力!$B$20<>"",入力!$B$20>F15),入力!$B$20-1,999999),IF(AND(入力!$J$7<>"",入力!$J$7>F15),入力!$J$7-1,999999))) | H15: =IF(F15="","",IFERROR(VLOOKUP(DATE(B15,C15,1),カレンダーマスタ!$A$2:$B$97,2,0),NETWORKDAYS(DATE(B15,C15,1),EOMONTH(F15,0)))) | I15: =IF(F15="","",NETWORKDAYS(F15,G15)) | J15: =IF(F15="","",IF(入力!$C$8<>"",入力!$C$8,INDEX(入力!$G$37:$G$78,MATCH(DATE(B15,C15,1),入力!$A$37:$A$78,0)))) | K15: =IF(F15="","",ROUNDDOWN(INDEX(入力!$H$13:$H$20,MATCH(F15,入力!$B$13:$B$20,1))/H15+INDEX(入力!$I$13:$I$20,MATCH(F15,入力!$B$13:$B$20,1))/22,0)) | L15: =IF(F15="","",IF(J15>K15,"〇","×")) | M15: =IF(F15="","",J15*I15) | N15: =IF(F15="","",MIN(J15,K15)*I15) | O15: =IF(F15="","",M15-N15) | Q15: =IF(F15="","",IF(COUNTIFS($B$6:B15,B15,$C$6:C15,C15,$E$6:E15,E15)=1,MAX($Q$5:Q14)+1,""))
A16: =IF(F16="","",11) | B16: =IF(F16="","",YEAR(F16)) | C16: =IF(F16="","",MONTH(F16)) | D16: =IF(F16="","",INDEX(入力!$A$13:$A$20,MATCH(F16,入力!$B$13:$B$20,1))) | E16: =IF(F16="","",IF(G16<=入力!$J$6,"法定","附加")) | F16: =IF(G15="","",IF(G15>=入力!$J$9,"",G15+1)) | G16: =IF(F16="","",MIN(EOMONTH(F16,0),入力!$J$9,IF(AND(入力!$B$13<>"",入力!$B$13>F16),入力!$B$13-1,999999),IF(AND(入力!$B$14<>"",入力!$B$14>F16),入力!$B$14-1,999999),IF(AND(入力!$B$15<>"",入力!$B$15>F16),入力!$B$15-1,999999),IF(AND(入力!$B$16<>"",入力!$B$16>F16),入力!$B$16-1,999999),IF(AND(入力!$B$17<>"",入力!$B$17>F16),入力!$B$17-1,999999),IF(AND(入力!$B$18<>"",入力!$B$18>F16),入力!$B$18-1,999999),IF(AND(入力!$B$19<>"",入力!$B$19>F16),入力!$B$19-1,999999),IF(AND(入力!$B$20<>"",入力!$B$20>F16),入力!$B$20-1,999999),IF(AND(入力!$J$7<>"",入力!$J$7>F16),入力!$J$7-1,999999))) | H16: =IF(F16="","",IFERROR(VLOOKUP(DATE(B16,C16,1),カレンダーマスタ!$A$2:$B$97,2,0),NETWORKDAYS(DATE(B16,C16,1),EOMONTH(F16,0)))) | I16: =IF(F16="","",NETWORKDAYS(F16,G16)) | J16: =IF(F16="","",IF(入力!$C$8<>"",入力!$C$8,INDEX(入力!$G$37:$G$78,MATCH(DATE(B16,C16,1),入力!$A$37:$A$78,0)))) | K16: =IF(F16="","",ROUNDDOWN(INDEX(入力!$H$13:$H$20,MATCH(F16,入力!$B$13:$B$20,1))/H16+INDEX(入力!$I$13:$I$20,MATCH(F16,入力!$B$13:$B$20,1))/22,0)) | L16: =IF(F16="","",IF(J16>K16,"〇","×")) | M16: =IF(F16="","",J16*I16) | N16: =IF(F16="","",MIN(J16,K16)*I16) | O16: =IF(F16="","",M16-N16) | Q16: =IF(F16="","",IF(COUNTIFS($B$6:B16,B16,$C$6:C16,C16,$E$6:E16,E16)=1,MAX($Q$5:Q15)+1,""))
A17: =IF(F17="","",12) | B17: =IF(F17="","",YEAR(F17)) | C17: =IF(F17="","",MONTH(F17)) | D17: =IF(F17="","",INDEX(入力!$A$13:$A$20,MATCH(F17,入力!$B$13:$B$20,1))) | E17: =IF(F17="","",IF(G17<=入力!$J$6,"法定","附加")) | F17: =IF(G16="","",IF(G16>=入力!$J$9,"",G16+1)) | G17: =IF(F17="","",MIN(EOMONTH(F17,0),入力!$J$9,IF(AND(入力!$B$13<>"",入力!$B$13>F17),入力!$B$13-1,999999),IF(AND(入力!$B$14<>"",入力!$B$14>F17),入力!$B$14-1,999999),IF(AND(入力!$B$15<>"",入力!$B$15>F17),入力!$B$15-1,999999),IF(AND(入力!$B$16<>"",入力!$B$16>F17),入力!$B$16-1,999999),IF(AND(入力!$B$17<>"",入力!$B$17>F17),入力!$B$17-1,999999),IF(AND(入力!$B$18<>"",入力!$B$18>F17),入力!$B$18-1,999999),IF(AND(入力!$B$19<>"",入力!$B$19>F17),入力!$B$19-1,999999),IF(AND(入力!$B$20<>"",入力!$B$20>F17),入力!$B$20-1,999999),IF(AND(入力!$J$7<>"",入力!$J$7>F17),入力!$J$7-1,999999))) | H17: =IF(F17="","",IFERROR(VLOOKUP(DATE(B17,C17,1),カレンダーマスタ!$A$2:$B$97,2,0),NETWORKDAYS(DATE(B17,C17,1),EOMONTH(F17,0)))) | I17: =IF(F17="","",NETWORKDAYS(F17,G17)) | J17: =IF(F17="","",IF(入力!$C$8<>"",入力!$C$8,INDEX(入力!$G$37:$G$78,MATCH(DATE(B17,C17,1),入力!$A$37:$A$78,0)))) | K17: =IF(F17="","",ROUNDDOWN(INDEX(入力!$H$13:$H$20,MATCH(F17,入力!$B$13:$B$20,1))/H17+INDEX(入力!$I$13:$I$20,MATCH(F17,入力!$B$13:$B$20,1))/22,0)) | L17: =IF(F17="","",IF(J17>K17,"〇","×")) | M17: =IF(F17="","",J17*I17) | N17: =IF(F17="","",MIN(J17,K17)*I17) | O17: =IF(F17="","",M17-N17) | Q17: =IF(F17="","",IF(COUNTIFS($B$6:B17,B17,$C$6:C17,C17,$E$6:E17,E17)=1,MAX($Q$5:Q16)+1,""))
A18: =IF(F18="","",13) | B18: =IF(F18="","",YEAR(F18)) | C18: =IF(F18="","",MONTH(F18)) | D18: =IF(F18="","",INDEX(入力!$A$13:$A$20,MATCH(F18,入力!$B$13:$B$20,1))) | E18: =IF(F18="","",IF(G18<=入力!$J$6,"法定","附加")) | F18: =IF(G17="","",IF(G17>=入力!$J$9,"",G17+1)) | G18: =IF(F18="","",MIN(EOMONTH(F18,0),入力!$J$9,IF(AND(入力!$B$13<>"",入力!$B$13>F18),入力!$B$13-1,999999),IF(AND(入力!$B$14<>"",入力!$B$14>F18),入力!$B$14-1,999999),IF(AND(入力!$B$15<>"",入力!$B$15>F18),入力!$B$15-1,999999),IF(AND(入力!$B$16<>"",入力!$B$16>F18),入力!$B$16-1,999999),IF(AND(入力!$B$17<>"",入力!$B$17>F18),入力!$B$17-1,999999),IF(AND(入力!$B$18<>"",入力!$B$18>F18),入力!$B$18-1,999999),IF(AND(入力!$B$19<>"",入力!$B$19>F18),入力!$B$19-1,999999),IF(AND(入力!$B$20<>"",入力!$B$20>F18),入力!$B$20-1,999999),IF(AND(入力!$J$7<>"",入力!$J$7>F18),入力!$J$7-1,999999))) | H18: =IF(F18="","",IFERROR(VLOOKUP(DATE(B18,C18,1),カレンダーマスタ!$A$2:$B$97,2,0),NETWORKDAYS(DATE(B18,C18,1),EOMONTH(F18,0)))) | I18: =IF(F18="","",NETWORKDAYS(F18,G18)) | J18: =IF(F18="","",IF(入力!$C$8<>"",入力!$C$8,INDEX(入力!$G$37:$G$78,MATCH(DATE(B18,C18,1),入力!$A$37:$A$78,0)))) | K18: =IF(F18="","",ROUNDDOWN(INDEX(入力!$H$13:$H$20,MATCH(F18,入力!$B$13:$B$20,1))/H18+INDEX(入力!$I$13:$I$20,MATCH(F18,入力!$B$13:$B$20,1))/22,0)) | L18: =IF(F18="","",IF(J18>K18,"〇","×")) | M18: =IF(F18="","",J18*I18) | N18: =IF(F18="","",MIN(J18,K18)*I18) | O18: =IF(F18="","",M18-N18) | Q18: =IF(F18="","",IF(COUNTIFS($B$6:B18,B18,$C$6:C18,C18,$E$6:E18,E18)=1,MAX($Q$5:Q17)+1,""))
A19: =IF(F19="","",14) | B19: =IF(F19="","",YEAR(F19)) | C19: =IF(F19="","",MONTH(F19)) | D19: =IF(F19="","",INDEX(入力!$A$13:$A$20,MATCH(F19,入力!$B$13:$B$20,1))) | E19: =IF(F19="","",IF(G19<=入力!$J$6,"法定","附加")) | F19: =IF(G18="","",IF(G18>=入力!$J$9,"",G18+1)) | G19: =IF(F19="","",MIN(EOMONTH(F19,0),入力!$J$9,IF(AND(入力!$B$13<>"",入力!$B$13>F19),入力!$B$13-1,999999),IF(AND(入力!$B$14<>"",入力!$B$14>F19),入力!$B$14-1,999999),IF(AND(入力!$B$15<>"",入力!$B$15>F19),入力!$B$15-1,999999),IF(AND(入力!$B$16<>"",入力!$B$16>F19),入力!$B$16-1,999999),IF(AND(入力!$B$17<>"",入力!$B$17>F19),入力!$B$17-1,999999),IF(AND(入力!$B$18<>"",入力!$B$18>F19),入力!$B$18-1,999999),IF(AND(入力!$B$19<>"",入力!$B$19>F19),入力!$B$19-1,999999),IF(AND(入力!$B$20<>"",入力!$B$20>F19),入力!$B$20-1,999999),IF(AND(入力!$J$7<>"",入力!$J$7>F19),入力!$J$7-1,999999))) | H19: =IF(F19="","",IFERROR(VLOOKUP(DATE(B19,C19,1),カレンダーマスタ!$A$2:$B$97,2,0),NETWORKDAYS(DATE(B19,C19,1),EOMONTH(F19,0)))) | I19: =IF(F19="","",NETWORKDAYS(F19,G19)) | J19: =IF(F19="","",IF(入力!$C$8<>"",入力!$C$8,INDEX(入力!$G$37:$G$78,MATCH(DATE(B19,C19,1),入力!$A$37:$A$78,0)))) | K19: =IF(F19="","",ROUNDDOWN(INDEX(入力!$H$13:$H$20,MATCH(F19,入力!$B$13:$B$20,1))/H19+INDEX(入力!$I$13:$I$20,MATCH(F19,入力!$B$13:$B$20,1))/22,0)) | L19: =IF(F19="","",IF(J19>K19,"〇","×")) | M19: =IF(F19="","",J19*I19) | N19: =IF(F19="","",MIN(J19,K19)*I19) | O19: =IF(F19="","",M19-N19) | Q19: =IF(F19="","",IF(COUNTIFS($B$6:B19,B19,$C$6:C19,C19,$E$6:E19,E19)=1,MAX($Q$5:Q18)+1,""))
A20: =IF(F20="","",15) | B20: =IF(F20="","",YEAR(F20)) | C20: =IF(F20="","",MONTH(F20)) | D20: =IF(F20="","",INDEX(入力!$A$13:$A$20,MATCH(F20,入力!$B$13:$B$20,1))) | E20: =IF(F20="","",IF(G20<=入力!$J$6,"法定","附加")) | F20: =IF(G19="","",IF(G19>=入力!$J$9,"",G19+1)) | G20: =IF(F20="","",MIN(EOMONTH(F20,0),入力!$J$9,IF(AND(入力!$B$13<>"",入力!$B$13>F20),入力!$B$13-1,999999),IF(AND(入力!$B$14<>"",入力!$B$14>F20),入力!$B$14-1,999999),IF(AND(入力!$B$15<>"",入力!$B$15>F20),入力!$B$15-1,999999),IF(AND(入力!$B$16<>"",入力!$B$16>F20),入力!$B$16-1,999999),IF(AND(入力!$B$17<>"",入力!$B$17>F20),入力!$B$17-1,999999),IF(AND(入力!$B$18<>"",入力!$B$18>F20),入力!$B$18-1,999999),IF(AND(入力!$B$19<>"",入力!$B$19>F20),入力!$B$19-1,999999),IF(AND(入力!$B$20<>"",入力!$B$20>F20),入力!$B$20-1,999999),IF(AND(入力!$J$7<>"",入力!$J$7>F20),入力!$J$7-1,999999))) | H20: =IF(F20="","",IFERROR(VLOOKUP(DATE(B20,C20,1),カレンダーマスタ!$A$2:$B$97,2,0),NETWORKDAYS(DATE(B20,C20,1),EOMONTH(F20,0)))) | I20: =IF(F20="","",NETWORKDAYS(F20,G20)) | J20: =IF(F20="","",IF(入力!$C$8<>"",入力!$C$8,INDEX(入力!$G$37:$G$78,MATCH(DATE(B20,C20,1),入力!$A$37:$A$78,0)))) | K20: =IF(F20="","",ROUNDDOWN(INDEX(入力!$H$13:$H$20,MATCH(F20,入力!$B$13:$B$20,1))/H20+INDEX(入力!$I$13:$I$20,MATCH(F20,入力!$B$13:$B$20,1))/22,0)) | L20: =IF(F20="","",IF(J20>K20,"〇","×")) | M20: =IF(F20="","",J20*I20) | N20: =IF(F20="","",MIN(J20,K20)*I20) | O20: =IF(F20="","",M20-N20) | Q20: =IF(F20="","",IF(COUNTIFS($B$6:B20,B20,$C$6:C20,C20,$E$6:E20,E20)=1,MAX($Q$5:Q19)+1,""))
A21: =IF(F21="","",16) | B21: =IF(F21="","",YEAR(F21)) | C21: =IF(F21="","",MONTH(F21)) | D21: =IF(F21="","",INDEX(入力!$A$13:$A$20,MATCH(F21,入力!$B$13:$B$20,1))) | E21: =IF(F21="","",IF(G21<=入力!$J$6,"法定","附加")) | F21: =IF(G20="","",IF(G20>=入力!$J$9,"",G20+1)) | G21: =IF(F21="","",MIN(EOMONTH(F21,0),入力!$J$9,IF(AND(入力!$B$13<>"",入力!$B$13>F21),入力!$B$13-1,999999),IF(AND(入力!$B$14<>"",入力!$B$14>F21),入力!$B$14-1,999999),IF(AND(入力!$B$15<>"",入力!$B$15>F21),入力!$B$15-1,999999),IF(AND(入力!$B$16<>"",入力!$B$16>F21),入力!$B$16-1,999999),IF(AND(入力!$B$17<>"",入力!$B$17>F21),入力!$B$17-1,999999),IF(AND(入力!$B$18<>"",入力!$B$18>F21),入力!$B$18-1,999999),IF(AND(入力!$B$19<>"",入力!$B$19>F21),入力!$B$19-1,999999),IF(AND(入力!$B$20<>"",入力!$B$20>F21),入力!$B$20-1,999999),IF(AND(入力!$J$7<>"",入力!$J$7>F21),入力!$J$7-1,999999))) | H21: =IF(F21="","",IFERROR(VLOOKUP(DATE(B21,C21,1),カレンダーマスタ!$A$2:$B$97,2,0),NETWORKDAYS(DATE(B21,C21,1),EOMONTH(F21,0)))) | I21: =IF(F21="","",NETWORKDAYS(F21,G21)) | J21: =IF(F21="","",IF(入力!$C$8<>"",入力!$C$8,INDEX(入力!$G$37:$G$78,MATCH(DATE(B21,C21,1),入力!$A$37:$A$78,0)))) | K21: =IF(F21="","",ROUNDDOWN(INDEX(入力!$H$13:$H$20,MATCH(F21,入力!$B$13:$B$20,1))/H21+INDEX(入力!$I$13:$I$20,MATCH(F21,入力!$B$13:$B$20,1))/22,0)) | L21: =IF(F21="","",IF(J21>K21,"〇","×")) | M21: =IF(F21="","",J21*I21) | N21: =IF(F21="","",MIN(J21,K21)*I21) | O21: =IF(F21="","",M21-N21) | Q21: =IF(F21="","",IF(COUNTIFS($B$6:B21,B21,$C$6:C21,C21,$E$6:E21,E21)=1,MAX($Q$5:Q20)+1,""))
A22: =IF(F22="","",17) | B22: =IF(F22="","",YEAR(F22)) | C22: =IF(F22="","",MONTH(F22)) | D22: =IF(F22="","",INDEX(入力!$A$13:$A$20,MATCH(F22,入力!$B$13:$B$20,1))) | E22: =IF(F22="","",IF(G22<=入力!$J$6,"法定","附加")) | F22: =IF(G21="","",IF(G21>=入力!$J$9,"",G21+1)) | G22: =IF(F22="","",MIN(EOMONTH(F22,0),入力!$J$9,IF(AND(入力!$B$13<>"",入力!$B$13>F22),入力!$B$13-1,999999),IF(AND(入力!$B$14<>"",入力!$B$14>F22),入力!$B$14-1,999999),IF(AND(入力!$B$15<>"",入力!$B$15>F22),入力!$B$15-1,999999),IF(AND(入力!$B$16<>"",入力!$B$16>F22),入力!$B$16-1,999999),IF(AND(入力!$B$17<>"",入力!$B$17>F22),入力!$B$17-1,999999),IF(AND(入力!$B$18<>"",入力!$B$18>F22),入力!$B$18-1,999999),IF(AND(入力!$B$19<>"",入力!$B$19>F22),入力!$B$19-1,999999),IF(AND(入力!$B$20<>"",入力!$B$20>F22),入力!$B$20-1,999999),IF(AND(入力!$J$7<>"",入力!$J$7>F22),入力!$J$7-1,999999))) | H22: =IF(F22="","",IFERROR(VLOOKUP(DATE(B22,C22,1),カレンダーマスタ!$A$2:$B$97,2,0),NETWORKDAYS(DATE(B22,C22,1),EOMONTH(F22,0)))) | I22: =IF(F22="","",NETWORKDAYS(F22,G22)) | J22: =IF(F22="","",IF(入力!$C$8<>"",入力!$C$8,INDEX(入力!$G$37:$G$78,MATCH(DATE(B22,C22,1),入力!$A$37:$A$78,0)))) | K22: =IF(F22="","",ROUNDDOWN(INDEX(入力!$H$13:$H$20,MATCH(F22,入力!$B$13:$B$20,1))/H22+INDEX(入力!$I$13:$I$20,MATCH(F22,入力!$B$13:$B$20,1))/22,0)) | L22: =IF(F22="","",IF(J22>K22,"〇","×")) | M22: =IF(F22="","",J22*I22) | N22: =IF(F22="","",MIN(J22,K22)*I22) | O22: =IF(F22="","",M22-N22) | Q22: =IF(F22="","",IF(COUNTIFS($B$6:B22,B22,$C$6:C22,C22,$E$6:E22,E22)=1,MAX($Q$5:Q21)+1,""))
A23: =IF(F23="","",18) | B23: =IF(F23="","",YEAR(F23)) | C23: =IF(F23="","",MONTH(F23)) | D23: =IF(F23="","",INDEX(入力!$A$13:$A$20,MATCH(F23,入力!$B$13:$B$20,1))) | E23: =IF(F23="","",IF(G23<=入力!$J$6,"法定","附加")) | F23: =IF(G22="","",IF(G22>=入力!$J$9,"",G22+1)) | G23: =IF(F23="","",MIN(EOMONTH(F23,0),入力!$J$9,IF(AND(入力!$B$13<>"",入力!$B$13>F23),入力!$B$13-1,999999),IF(AND(入力!$B$14<>"",入力!$B$14>F23),入力!$B$14-1,999999),IF(AND(入力!$B$15<>"",入力!$B$15>F23),入力!$B$15-1,999999),IF(AND(入力!$B$16<>"",入力!$B$16>F23),入力!$B$16-1,999999),IF(AND(入力!$B$17<>"",入力!$B$17>F23),入力!$B$17-1,999999),IF(AND(入力!$B$18<>"",入力!$B$18>F23),入力!$B$18-1,999999),IF(AND(入力!$B$19<>"",入力!$B$19>F23),入力!$B$19-1,999999),IF(AND(入力!$B$20<>"",入力!$B$20>F23),入力!$B$20-1,999999),IF(AND(入力!$J$7<>"",入力!$J$7>F23),入力!$J$7-1,999999))) | H23: =IF(F23="","",IFERROR(VLOOKUP(DATE(B23,C23,1),カレンダーマスタ!$A$2:$B$97,2,0),NETWORKDAYS(DATE(B23,C23,1),EOMONTH(F23,0)))) | I23: =IF(F23="","",NETWORKDAYS(F23,G23)) | J23: =IF(F23="","",IF(入力!$C$8<>"",入力!$C$8,INDEX(入力!$G$37:$G$78,MATCH(DATE(B23,C23,1),入力!$A$37:$A$78,0)))) | K23: =IF(F23="","",ROUNDDOWN(INDEX(入力!$H$13:$H$20,MATCH(F23,入力!$B$13:$B$20,1))/H23+INDEX(入力!$I$13:$I$20,MATCH(F23,入力!$B$13:$B$20,1))/22,0)) | L23: =IF(F23="","",IF(J23>K23,"〇","×")) | M23: =IF(F23="","",J23*I23) | N23: =IF(F23="","",MIN(J23,K23)*I23) | O23: =IF(F23="","",M23-N23) | Q23: =IF(F23="","",IF(COUNTIFS($B$6:B23,B23,$C$6:C23,C23,$E$6:E23,E23)=1,MAX($Q$5:Q22)+1,""))
A24: =IF(F24="","",19) | B24: =IF(F24="","",YEAR(F24)) | C24: =IF(F24="","",MONTH(F24)) | D24: =IF(F24="","",INDEX(入力!$A$13:$A$20,MATCH(F24,入力!$B$13:$B$20,1))) | E24: =IF(F24="","",IF(G24<=入力!$J$6,"法定","附加")) | F24: =IF(G23="","",IF(G23>=入力!$J$9,"",G23+1)) | G24: =IF(F24="","",MIN(EOMONTH(F24,0),入力!$J$9,IF(AND(入力!$B$13<>"",入力!$B$13>F24),入力!$B$13-1,999999),IF(AND(入力!$B$14<>"",入力!$B$14>F24),入力!$B$14-1,999999),IF(AND(入力!$B$15<>"",入力!$B$15>F24),入力!$B$15-1,999999),IF(AND(入力!$B$16<>"",入力!$B$16>F24),入力!$B$16-1,999999),IF(AND(入力!$B$17<>"",入力!$B$17>F24),入力!$B$17-1,999999),IF(AND(入力!$B$18<>"",入力!$B$18>F24),入力!$B$18-1,999999),IF(AND(入力!$B$19<>"",入力!$B$19>F24),入力!$B$19-1,999999),IF(AND(入力!$B$20<>"",入力!$B$20>F24),入力!$B$20-1,999999),IF(AND(入力!$J$7<>"",入力!$J$7>F24),入力!$J$7-1,999999))) | H24: =IF(F24="","",IFERROR(VLOOKUP(DATE(B24,C24,1),カレンダーマスタ!$A$2:$B$97,2,0),NETWORKDAYS(DATE(B24,C24,1),EOMONTH(F24,0)))) | I24: =IF(F24="","",NETWORKDAYS(F24,G24)) | J24: =IF(F24="","",IF(入力!$C$8<>"",入力!$C$8,INDEX(入力!$G$37:$G$78,MATCH(DATE(B24,C24,1),入力!$A$37:$A$78,0)))) | K24: =IF(F24="","",ROUNDDOWN(INDEX(入力!$H$13:$H$20,MATCH(F24,入力!$B$13:$B$20,1))/H24+INDEX(入力!$I$13:$I$20,MATCH(F24,入力!$B$13:$B$20,1))/22,0)) | L24: =IF(F24="","",IF(J24>K24,"〇","×")) | M24: =IF(F24="","",J24*I24) | N24: =IF(F24="","",MIN(J24,K24)*I24) | O24: =IF(F24="","",M24-N24) | Q24: =IF(F24="","",IF(COUNTIFS($B$6:B24,B24,$C$6:C24,C24,$E$6:E24,E24)=1,MAX($Q$5:Q23)+1,""))
A25: =IF(F25="","",20) | B25: =IF(F25="","",YEAR(F25)) | C25: =IF(F25="","",MONTH(F25)) | D25: =IF(F25="","",INDEX(入力!$A$13:$A$20,MATCH(F25,入力!$B$13:$B$20,1))) | E25: =IF(F25="","",IF(G25<=入力!$J$6,"法定","附加")) | F25: =IF(G24="","",IF(G24>=入力!$J$9,"",G24+1)) | G25: =IF(F25="","",MIN(EOMONTH(F25,0),入力!$J$9,IF(AND(入力!$B$13<>"",入力!$B$13>F25),入力!$B$13-1,999999),IF(AND(入力!$B$14<>"",入力!$B$14>F25),入力!$B$14-1,999999),IF(AND(入力!$B$15<>"",入力!$B$15>F25),入力!$B$15-1,999999),IF(AND(入力!$B$16<>"",入力!$B$16>F25),入力!$B$16-1,999999),IF(AND(入力!$B$17<>"",入力!$B$17>F25),入力!$B$17-1,999999),IF(AND(入力!$B$18<>"",入力!$B$18>F25),入力!$B$18-1,999999),IF(AND(入力!$B$19<>"",入力!$B$19>F25),入力!$B$19-1,999999),IF(AND(入力!$B$20<>"",入力!$B$20>F25),入力!$B$20-1,999999),IF(AND(入力!$J$7<>"",入力!$J$7>F25),入力!$J$7-1,999999))) | H25: =IF(F25="","",IFERROR(VLOOKUP(DATE(B25,C25,1),カレンダーマスタ!$A$2:$B$97,2,0),NETWORKDAYS(DATE(B25,C25,1),EOMONTH(F25,0)))) | I25: =IF(F25="","",NETWORKDAYS(F25,G25)) | J25: =IF(F25="","",IF(入力!$C$8<>"",入力!$C$8,INDEX(入力!$G$37:$G$78,MATCH(DATE(B25,C25,1),入力!$A$37:$A$78,0)))) | K25: =IF(F25="","",ROUNDDOWN(INDEX(入力!$H$13:$H$20,MATCH(F25,入力!$B$13:$B$20,1))/H25+INDEX(入力!$I$13:$I$20,MATCH(F25,入力!$B$13:$B$20,1))/22,0)) | L25: =IF(F25="","",IF(J25>K25,"〇","×")) | M25: =IF(F25="","",J25*I25) | N25: =IF(F25="","",MIN(J25,K25)*I25) | O25: =IF(F25="","",M25-N25) | Q25: =IF(F25="","",IF(COUNTIFS($B$6:B25,B25,$C$6:C25,C25,$E$6:E25,E25)=1,MAX($Q$5:Q24)+1,""))
A26: =IF(F26="","",21) | B26: =IF(F26="","",YEAR(F26)) | C26: =IF(F26="","",MONTH(F26)) | D26: =IF(F26="","",INDEX(入力!$A$13:$A$20,MATCH(F26,入力!$B$13:$B$20,1))) | E26: =IF(F26="","",IF(G26<=入力!$J$6,"法定","附加")) | F26: =IF(G25="","",IF(G25>=入力!$J$9,"",G25+1)) | G26: =IF(F26="","",MIN(EOMONTH(F26,0),入力!$J$9,IF(AND(入力!$B$13<>"",入力!$B$13>F26),入力!$B$13-1,999999),IF(AND(入力!$B$14<>"",入力!$B$14>F26),入力!$B$14-1,999999),IF(AND(入力!$B$15<>"",入力!$B$15>F26),入力!$B$15-1,999999),IF(AND(入力!$B$16<>"",入力!$B$16>F26),入力!$B$16-1,999999),IF(AND(入力!$B$17<>"",入力!$B$17>F26),入力!$B$17-1,999999),IF(AND(入力!$B$18<>"",入力!$B$18>F26),入力!$B$18-1,999999),IF(AND(入力!$B$19<>"",入力!$B$19>F26),入力!$B$19-1,999999),IF(AND(入力!$B$20<>"",入力!$B$20>F26),入力!$B$20-1,999999),IF(AND(入力!$J$7<>"",入力!$J$7>F26),入力!$J$7-1,999999))) | H26: =IF(F26="","",IFERROR(VLOOKUP(DATE(B26,C26,1),カレンダーマスタ!$A$2:$B$97,2,0),NETWORKDAYS(DATE(B26,C26,1),EOMONTH(F26,0)))) | I26: =IF(F26="","",NETWORKDAYS(F26,G26)) | J26: =IF(F26="","",IF(入力!$C$8<>"",入力!$C$8,INDEX(入力!$G$37:$G$78,MATCH(DATE(B26,C26,1),入力!$A$37:$A$78,0)))) | K26: =IF(F26="","",ROUNDDOWN(INDEX(入力!$H$13:$H$20,MATCH(F26,入力!$B$13:$B$20,1))/H26+INDEX(入力!$I$13:$I$20,MATCH(F26,入力!$B$13:$B$20,1))/22,0)) | L26: =IF(F26="","",IF(J26>K26,"〇","×")) | M26: =IF(F26="","",J26*I26) | N26: =IF(F26="","",MIN(J26,K26)*I26) | O26: =IF(F26="","",M26-N26) | Q26: =IF(F26="","",IF(COUNTIFS($B$6:B26,B26,$C$6:C26,C26,$E$6:E26,E26)=1,MAX($Q$5:Q25)+1,""))
A27: =IF(F27="","",22) | B27: =IF(F27="","",YEAR(F27)) | C27: =IF(F27="","",MONTH(F27)) | D27: =IF(F27="","",INDEX(入力!$A$13:$A$20,MATCH(F27,入力!$B$13:$B$20,1))) | E27: =IF(F27="","",IF(G27<=入力!$J$6,"法定","附加")) | F27: =IF(G26="","",IF(G26>=入力!$J$9,"",G26+1)) | G27: =IF(F27="","",MIN(EOMONTH(F27,0),入力!$J$9,IF(AND(入力!$B$13<>"",入力!$B$13>F27),入力!$B$13-1,999999),IF(AND(入力!$B$14<>"",入力!$B$14>F27),入力!$B$14-1,999999),IF(AND(入力!$B$15<>"",入力!$B$15>F27),入力!$B$15-1,999999),IF(AND(入力!$B$16<>"",入力!$B$16>F27),入力!$B$16-1,999999),IF(AND(入力!$B$17<>"",入力!$B$17>F27),入力!$B$17-1,999999),IF(AND(入力!$B$18<>"",入力!$B$18>F27),入力!$B$18-1,999999),IF(AND(入力!$B$19<>"",入力!$B$19>F27),入力!$B$19-1,999999),IF(AND(入力!$B$20<>"",入力!$B$20>F27),入力!$B$20-1,999999),IF(AND(入力!$J$7<>"",入力!$J$7>F27),入力!$J$7-1,999999))) | H27: =IF(F27="","",IFERROR(VLOOKUP(DATE(B27,C27,1),カレンダーマスタ!$A$2:$B$97,2,0),NETWORKDAYS(DATE(B27,C27,1),EOMONTH(F27,0)))) | I27: =IF(F27="","",NETWORKDAYS(F27,G27)) | J27: =IF(F27="","",IF(入力!$C$8<>"",入力!$C$8,INDEX(入力!$G$37:$G$78,MATCH(DATE(B27,C27,1),入力!$A$37:$A$78,0)))) | K27: =IF(F27="","",ROUNDDOWN(INDEX(入力!$H$13:$H$20,MATCH(F27,入力!$B$13:$B$20,1))/H27+INDEX(入力!$I$13:$I$20,MATCH(F27,入力!$B$13:$B$20,1))/22,0)) | L27: =IF(F27="","",IF(J27>K27,"〇","×")) | M27: =IF(F27="","",J27*I27) | N27: =IF(F27="","",MIN(J27,K27)*I27) | O27: =IF(F27="","",M27-N27) | Q27: =IF(F27="","",IF(COUNTIFS($B$6:B27,B27,$C$6:C27,C27,$E$6:E27,E27)=1,MAX($Q$5:Q26)+1,""))
A28: =IF(F28="","",23) | B28: =IF(F28="","",YEAR(F28)) | C28: =IF(F28="","",MONTH(F28)) | D28: =IF(F28="","",INDEX(入力!$A$13:$A$20,MATCH(F28,入力!$B$13:$B$20,1))) | E28: =IF(F28="","",IF(G28<=入力!$J$6,"法定","附加")) | F28: =IF(G27="","",IF(G27>=入力!$J$9,"",G27+1)) | G28: =IF(F28="","",MIN(EOMONTH(F28,0),入力!$J$9,IF(AND(入力!$B$13<>"",入力!$B$13>F28),入力!$B$13-1,999999),IF(AND(入力!$B$14<>"",入力!$B$14>F28),入力!$B$14-1,999999),IF(AND(入力!$B$15<>"",入力!$B$15>F28),入力!$B$15-1,999999),IF(AND(入力!$B$16<>"",入力!$B$16>F28),入力!$B$16-1,999999),IF(AND(入力!$B$17<>"",入力!$B$17>F28),入力!$B$17-1,999999),IF(AND(入力!$B$18<>"",入力!$B$18>F28),入力!$B$18-1,999999),IF(AND(入力!$B$19<>"",入力!$B$19>F28),入力!$B$19-1,999999),IF(AND(入力!$B$20<>"",入力!$B$20>F28),入力!$B$20-1,999999),IF(AND(入力!$J$7<>"",入力!$J$7>F28),入力!$J$7-1,999999))) | H28: =IF(F28="","",IFERROR(VLOOKUP(DATE(B28,C28,1),カレンダーマスタ!$A$2:$B$97,2,0),NETWORKDAYS(DATE(B28,C28,1),EOMONTH(F28,0)))) | I28: =IF(F28="","",NETWORKDAYS(F28,G28)) | J28: =IF(F28="","",IF(入力!$C$8<>"",入力!$C$8,INDEX(入力!$G$37:$G$78,MATCH(DATE(B28,C28,1),入力!$A$37:$A$78,0)))) | K28: =IF(F28="","",ROUNDDOWN(INDEX(入力!$H$13:$H$20,MATCH(F28,入力!$B$13:$B$20,1))/H28+INDEX(入力!$I$13:$I$20,MATCH(F28,入力!$B$13:$B$20,1))/22,0)) | L28: =IF(F28="","",IF(J28>K28,"〇","×")) | M28: =IF(F28="","",J28*I28) | N28: =IF(F28="","",MIN(J28,K28)*I28) | O28: =IF(F28="","",M28-N28) | Q28: =IF(F28="","",IF(COUNTIFS($B$6:B28,B28,$C$6:C28,C28,$E$6:E28,E28)=1,MAX($Q$5:Q27)+1,""))
A29: =IF(F29="","",24) | B29: =IF(F29="","",YEAR(F29)) | C29: =IF(F29="","",MONTH(F29)) | D29: =IF(F29="","",INDEX(入力!$A$13:$A$20,MATCH(F29,入力!$B$13:$B$20,1))) | E29: =IF(F29="","",IF(G29<=入力!$J$6,"法定","附加")) | F29: =IF(G28="","",IF(G28>=入力!$J$9,"",G28+1)) | G29: =IF(F29="","",MIN(EOMONTH(F29,0),入力!$J$9,IF(AND(入力!$B$13<>"",入力!$B$13>F29),入力!$B$13-1,999999),IF(AND(入力!$B$14<>"",入力!$B$14>F29),入力!$B$14-1,999999),IF(AND(入力!$B$15<>"",入力!$B$15>F29),入力!$B$15-1,999999),IF(AND(入力!$B$16<>"",入力!$B$16>F29),入力!$B$16-1,999999),IF(AND(入力!$B$17<>"",入力!$B$17>F29),入力!$B$17-1,999999),IF(AND(入力!$B$18<>"",入力!$B$18>F29),入力!$B$18-1,999999),IF(AND(入力!$B$19<>"",入力!$B$19>F29),入力!$B$19-1,999999),IF(AND(入力!$B$20<>"",入力!$B$20>F29),入力!$B$20-1,999999),IF(AND(入力!$J$7<>"",入力!$J$7>F29),入力!$J$7-1,999999))) | H29: =IF(F29="","",IFERROR(VLOOKUP(DATE(B29,C29,1),カレンダーマスタ!$A$2:$B$97,2,0),NETWORKDAYS(DATE(B29,C29,1),EOMONTH(F29,0)))) | I29: =IF(F29="","",NETWORKDAYS(F29,G29)) | J29: =IF(F29="","",IF(入力!$C$8<>"",入力!$C$8,INDEX(入力!$G$37:$G$78,MATCH(DATE(B29,C29,1),入力!$A$37:$A$78,0)))) | K29: =IF(F29="","",ROUNDDOWN(INDEX(入力!$H$13:$H$20,MATCH(F29,入力!$B$13:$B$20,1))/H29+INDEX(入力!$I$13:$I$20,MATCH(F29,入力!$B$13:$B$20,1))/22,0)) | L29: =IF(F29="","",IF(J29>K29,"〇","×")) | M29: =IF(F29="","",J29*I29) | N29: =IF(F29="","",MIN(J29,K29)*I29) | O29: =IF(F29="","",M29-N29) | Q29: =IF(F29="","",IF(COUNTIFS($B$6:B29,B29,$C$6:C29,C29,$E$6:E29,E29)=1,MAX($Q$5:Q28)+1,""))
A30: =IF(F30="","",25) | B30: =IF(F30="","",YEAR(F30)) | C30: =IF(F30="","",MONTH(F30)) | D30: =IF(F30="","",INDEX(入力!$A$13:$A$20,MATCH(F30,入力!$B$13:$B$20,1))) | E30: =IF(F30="","",IF(G30<=入力!$J$6,"法定","附加")) | F30: =IF(G29="","",IF(G29>=入力!$J$9,"",G29+1)) | G30: =IF(F30="","",MIN(EOMONTH(F30,0),入力!$J$9,IF(AND(入力!$B$13<>"",入力!$B$13>F30),入力!$B$13-1,999999),IF(AND(入力!$B$14<>"",入力!$B$14>F30),入力!$B$14-1,999999),IF(AND(入力!$B$15<>"",入力!$B$15>F30),入力!$B$15-1,999999),IF(AND(入力!$B$16<>"",入力!$B$16>F30),入力!$B$16-1,999999),IF(AND(入力!$B$17<>"",入力!$B$17>F30),入力!$B$17-1,999999),IF(AND(入力!$B$18<>"",入力!$B$18>F30),入力!$B$18-1,999999),IF(AND(入力!$B$19<>"",入力!$B$19>F30),入力!$B$19-1,999999),IF(AND(入力!$B$20<>"",入力!$B$20>F30),入力!$B$20-1,999999),IF(AND(入力!$J$7<>"",入力!$J$7>F30),入力!$J$7-1,999999))) | H30: =IF(F30="","",IFERROR(VLOOKUP(DATE(B30,C30,1),カレンダーマスタ!$A$2:$B$97,2,0),NETWORKDAYS(DATE(B30,C30,1),EOMONTH(F30,0)))) | I30: =IF(F30="","",NETWORKDAYS(F30,G30)) | J30: =IF(F30="","",IF(入力!$C$8<>"",入力!$C$8,INDEX(入力!$G$37:$G$78,MATCH(DATE(B30,C30,1),入力!$A$37:$A$78,0)))) | K30: =IF(F30="","",ROUNDDOWN(INDEX(入力!$H$13:$H$20,MATCH(F30,入力!$B$13:$B$20,1))/H30+INDEX(入力!$I$13:$I$20,MATCH(F30,入力!$B$13:$B$20,1))/22,0)) | L30: =IF(F30="","",IF(J30>K30,"〇","×")) | M30: =IF(F30="","",J30*I30) | N30: =IF(F30="","",MIN(J30,K30)*I30) | O30: =IF(F30="","",M30-N30) | Q30: =IF(F30="","",IF(COUNTIFS($B$6:B30,B30,$C$6:C30,C30,$E$6:E30,E30)=1,MAX($Q$5:Q29)+1,""))
A31: =IF(F31="","",26) | B31: =IF(F31="","",YEAR(F31)) | C31: =IF(F31="","",MONTH(F31)) | D31: =IF(F31="","",INDEX(入力!$A$13:$A$20,MATCH(F31,入力!$B$13:$B$20,1))) | E31: =IF(F31="","",IF(G31<=入力!$J$6,"法定","附加")) | F31: =IF(G30="","",IF(G30>=入力!$J$9,"",G30+1)) | G31: =IF(F31="","",MIN(EOMONTH(F31,0),入力!$J$9,IF(AND(入力!$B$13<>"",入力!$B$13>F31),入力!$B$13-1,999999),IF(AND(入力!$B$14<>"",入力!$B$14>F31),入力!$B$14-1,999999),IF(AND(入力!$B$15<>"",入力!$B$15>F31),入力!$B$15-1,999999),IF(AND(入力!$B$16<>"",入力!$B$16>F31),入力!$B$16-1,999999),IF(AND(入力!$B$17<>"",入力!$B$17>F31),入力!$B$17-1,999999),IF(AND(入力!$B$18<>"",入力!$B$18>F31),入力!$B$18-1,999999),IF(AND(入力!$B$19<>"",入力!$B$19>F31),入力!$B$19-1,999999),IF(AND(入力!$B$20<>"",入力!$B$20>F31),入力!$B$20-1,999999),IF(AND(入力!$J$7<>"",入力!$J$7>F31),入力!$J$7-1,999999))) | H31: =IF(F31="","",IFERROR(VLOOKUP(DATE(B31,C31,1),カレンダーマスタ!$A$2:$B$97,2,0),NETWORKDAYS(DATE(B31,C31,1),EOMONTH(F31,0)))) | I31: =IF(F31="","",NETWORKDAYS(F31,G31)) | J31: =IF(F31="","",IF(入力!$C$8<>"",入力!$C$8,INDEX(入力!$G$37:$G$78,MATCH(DATE(B31,C31,1),入力!$A$37:$A$78,0)))) | K31: =IF(F31="","",ROUNDDOWN(INDEX(入力!$H$13:$H$20,MATCH(F31,入力!$B$13:$B$20,1))/H31+INDEX(入力!$I$13:$I$20,MATCH(F31,入力!$B$13:$B$20,1))/22,0)) | L31: =IF(F31="","",IF(J31>K31,"〇","×")) | M31: =IF(F31="","",J31*I31) | N31: =IF(F31="","",MIN(J31,K31)*I31) | O31: =IF(F31="","",M31-N31) | Q31: =IF(F31="","",IF(COUNTIFS($B$6:B31,B31,$C$6:C31,C31,$E$6:E31,E31)=1,MAX($Q$5:Q30)+1,""))
A32: =IF(F32="","",27) | B32: =IF(F32="","",YEAR(F32)) | C32: =IF(F32="","",MONTH(F32)) | D32: =IF(F32="","",INDEX(入力!$A$13:$A$20,MATCH(F32,入力!$B$13:$B$20,1))) | E32: =IF(F32="","",IF(G32<=入力!$J$6,"法定","附加")) | F32: =IF(G31="","",IF(G31>=入力!$J$9,"",G31+1)) | G32: =IF(F32="","",MIN(EOMONTH(F32,0),入力!$J$9,IF(AND(入力!$B$13<>"",入力!$B$13>F32),入力!$B$13-1,999999),IF(AND(入力!$B$14<>"",入力!$B$14>F32),入力!$B$14-1,999999),IF(AND(入力!$B$15<>"",入力!$B$15>F32),入力!$B$15-1,999999),IF(AND(入力!$B$16<>"",入力!$B$16>F32),入力!$B$16-1,999999),IF(AND(入力!$B$17<>"",入力!$B$17>F32),入力!$B$17-1,999999),IF(AND(入力!$B$18<>"",入力!$B$18>F32),入力!$B$18-1,999999),IF(AND(入力!$B$19<>"",入力!$B$19>F32),入力!$B$19-1,999999),IF(AND(入力!$B$20<>"",入力!$B$20>F32),入力!$B$20-1,999999),IF(AND(入力!$J$7<>"",入力!$J$7>F32),入力!$J$7-1,999999))) | H32: =IF(F32="","",IFERROR(VLOOKUP(DATE(B32,C32,1),カレンダーマスタ!$A$2:$B$97,2,0),NETWORKDAYS(DATE(B32,C32,1),EOMONTH(F32,0)))) | I32: =IF(F32="","",NETWORKDAYS(F32,G32)) | J32: =IF(F32="","",IF(入力!$C$8<>"",入力!$C$8,INDEX(入力!$G$37:$G$78,MATCH(DATE(B32,C32,1),入力!$A$37:$A$78,0)))) | K32: =IF(F32="","",ROUNDDOWN(INDEX(入力!$H$13:$H$20,MATCH(F32,入力!$B$13:$B$20,1))/H32+INDEX(入力!$I$13:$I$20,MATCH(F32,入力!$B$13:$B$20,1))/22,0)) | L32: =IF(F32="","",IF(J32>K32,"〇","×")) | M32: =IF(F32="","",J32*I32) | N32: =IF(F32="","",MIN(J32,K32)*I32) | O32: =IF(F32="","",M32-N32) | Q32: =IF(F32="","",IF(COUNTIFS($B$6:B32,B32,$C$6:C32,C32,$E$6:E32,E32)=1,MAX($Q$5:Q31)+1,""))
A33: =IF(F33="","",28) | B33: =IF(F33="","",YEAR(F33)) | C33: =IF(F33="","",MONTH(F33)) | D33: =IF(F33="","",INDEX(入力!$A$13:$A$20,MATCH(F33,入力!$B$13:$B$20,1))) | E33: =IF(F33="","",IF(G33<=入力!$J$6,"法定","附加")) | F33: =IF(G32="","",IF(G32>=入力!$J$9,"",G32+1)) | G33: =IF(F33="","",MIN(EOMONTH(F33,0),入力!$J$9,IF(AND(入力!$B$13<>"",入力!$B$13>F33),入力!$B$13-1,999999),IF(AND(入力!$B$14<>"",入力!$B$14>F33),入力!$B$14-1,999999),IF(AND(入力!$B$15<>"",入力!$B$15>F33),入力!$B$15-1,999999),IF(AND(入力!$B$16<>"",入力!$B$16>F33),入力!$B$16-1,999999),IF(AND(入力!$B$17<>"",入力!$B$17>F33),入力!$B$17-1,999999),IF(AND(入力!$B$18<>"",入力!$B$18>F33),入力!$B$18-1,999999),IF(AND(入力!$B$19<>"",入力!$B$19>F33),入力!$B$19-1,999999),IF(AND(入力!$B$20<>"",入力!$B$20>F33),入力!$B$20-1,999999),IF(AND(入力!$J$7<>"",入力!$J$7>F33),入力!$J$7-1,999999))) | H33: =IF(F33="","",IFERROR(VLOOKUP(DATE(B33,C33,1),カレンダーマスタ!$A$2:$B$97,2,0),NETWORKDAYS(DATE(B33,C33,1),EOMONTH(F33,0)))) | I33: =IF(F33="","",NETWORKDAYS(F33,G33)) | J33: =IF(F33="","",IF(入力!$C$8<>"",入力!$C$8,INDEX(入力!$G$37:$G$78,MATCH(DATE(B33,C33,1),入力!$A$37:$A$78,0)))) | K33: =IF(F33="","",ROUNDDOWN(INDEX(入力!$H$13:$H$20,MATCH(F33,入力!$B$13:$B$20,1))/H33+INDEX(入力!$I$13:$I$20,MATCH(F33,入力!$B$13:$B$20,1))/22,0)) | L33: =IF(F33="","",IF(J33>K33,"〇","×")) | M33: =IF(F33="","",J33*I33) | N33: =IF(F33="","",MIN(J33,K33)*I33) | O33: =IF(F33="","",M33-N33) | Q33: =IF(F33="","",IF(COUNTIFS($B$6:B33,B33,$C$6:C33,C33,$E$6:E33,E33)=1,MAX($Q$5:Q32)+1,""))
A34: =IF(F34="","",29) | B34: =IF(F34="","",YEAR(F34)) | C34: =IF(F34="","",MONTH(F34)) | D34: =IF(F34="","",INDEX(入力!$A$13:$A$20,MATCH(F34,入力!$B$13:$B$20,1))) | E34: =IF(F34="","",IF(G34<=入力!$J$6,"法定","附加")) | F34: =IF(G33="","",IF(G33>=入力!$J$9,"",G33+1)) | G34: =IF(F34="","",MIN(EOMONTH(F34,0),入力!$J$9,IF(AND(入力!$B$13<>"",入力!$B$13>F34),入力!$B$13-1,999999),IF(AND(入力!$B$14<>"",入力!$B$14>F34),入力!$B$14-1,999999),IF(AND(入力!$B$15<>"",入力!$B$15>F34),入力!$B$15-1,999999),IF(AND(入力!$B$16<>"",入力!$B$16>F34),入力!$B$16-1,999999),IF(AND(入力!$B$17<>"",入力!$B$17>F34),入力!$B$17-1,999999),IF(AND(入力!$B$18<>"",入力!$B$18>F34),入力!$B$18-1,999999),IF(AND(入力!$B$19<>"",入力!$B$19>F34),入力!$B$19-1,999999),IF(AND(入力!$B$20<>"",入力!$B$20>F34),入力!$B$20-1,999999),IF(AND(入力!$J$7<>"",入力!$J$7>F34),入力!$J$7-1,999999))) | H34: =IF(F34="","",IFERROR(VLOOKUP(DATE(B34,C34,1),カレンダーマスタ!$A$2:$B$97,2,0),NETWORKDAYS(DATE(B34,C34,1),EOMONTH(F34,0)))) | I34: =IF(F34="","",NETWORKDAYS(F34,G34)) | J34: =IF(F34="","",IF(入力!$C$8<>"",入力!$C$8,INDEX(入力!$G$37:$G$78,MATCH(DATE(B34,C34,1),入力!$A$37:$A$78,0)))) | K34: =IF(F34="","",ROUNDDOWN(INDEX(入力!$H$13:$H$20,MATCH(F34,入力!$B$13:$B$20,1))/H34+INDEX(入力!$I$13:$I$20,MATCH(F34,入力!$B$13:$B$20,1))/22,0)) | L34: =IF(F34="","",IF(J34>K34,"〇","×")) | M34: =IF(F34="","",J34*I34) | N34: =IF(F34="","",MIN(J34,K34)*I34) | O34: =IF(F34="","",M34-N34) | Q34: =IF(F34="","",IF(COUNTIFS($B$6:B34,B34,$C$6:C34,C34,$E$6:E34,E34)=1,MAX($Q$5:Q33)+1,""))
