Workbook
Name EMP_ID: '入力'!$C$4
Name EMP_NAME: '入力'!$C$5
Name DAILY_RATE: '入力'!$J$10
Name P_START: '入力'!$J$5
Name P_LEGAL_END: '入力'!$J$6
Name P_ADD_START: '入力'!$J$7
Name P_ADD_END: '入力'!$J$8
Name P_FINAL: '入力'!$J$9
Name EXT_MONTHS: '入力'!$D$85
Name EXT_DAYS: '入力'!$E$85

Sheet 使い方
A1: 傷病手当金 算定表（試算＋調整額＋差額を1ファイルで計算）
A3: 【何が変わったか】
A4: 従来：①簡易試算シートで標準支給額を算出 → ②別ファイルの給与調整シートで調整額を算出 → ③差し引いて支給額を確認
A5: 今回：「入力」シートに入れるだけで、標準支給額・調整額・差引支給額（差額）が「算定表」シートに一度に表示されます。
A7: 【使い方】
A8: 1．「入力」シート：職員番号・氏名・病気休暇開始日を入力（黄色のセルのみ）。退職者は退職日と退職時附加金の受給有無も入力。
A9: 2．「入力」シート：給与証明に基づき、報酬が変わる日（10割→8割→無給、給与改定日など）ごとに1行ずつ入力。
A10: 3．「入力」シート：標準報酬月額（待機後の初日の月の12か月前から）を入力。傷病手当日額は、算定表で初めて〇になった月の額で全期間固定されます。基幹で日額を確認済みなら「傷病手当日額の確認値」に入力。
A11: 4．「算定表」シートで、月別（月の途中で区分が変わる場合は分割）・法定／附加別の標準支給額・調整額・差引支給額を確認。
A12: 5．出勤した期間があれば、「入力」シートの出勤期間（82行目〜、10件まで）に開始日・終了日を入力。法定末日・附加開始日・附加末日・最終日が自動で延びます。
A13: 6．「月別集計」シートで月ごと・法定／附加ごとの差引支給額を確認し、桐／基幹の入力額と照合（調整額はマイナスで入力）。
A14: 7．請求期間ごとの内訳が必要なとき：「請求シート雛形」の黄色に請求期間（始・終）を入れる。マクロを取り込んだ .xlsm なら、自動で請求シートが追加される。
... A25: ・標準報酬の表は、支給開始月より後の月も「参考」として残しています（算定表のP列にも参考日額が出ます）。傷病手当日額は支給開始月の額で固定です。

Sheet 入力
A1: 傷病手当金 算定表（入力シート）
A2: 黄色のセル（青字）だけ入力してください。試算・調整額・差額は「算定表」シートに自動表示されます。（出勤期間は82行目以降）
A3: ※月の数え方は応当日の前日まで（例：待機後の初日7/25から1年6か月 → 翌々年1/24）。1年6か月は待機後の初日から数え、傷病手当日額は算定表で初めて〇になった月の額で固定します。
A4: 職員番号 | C4: 0000000 | G4: 待機後の初日（判定の開始） | J4: =C6+3
A5: 氏名 | C5: 広島 太郎 | G5: 初めて〇になった日（日額の基準） | J5: =IF(算定表!$AD$6="",J4,INDEX(算定表!$U$6:$U$53,算定表!$AD$6)) | K5: =IF(算定表!$AD$6="","※〇になる行がありません。待機後の初日を支給開始日にしています","")
A6: 病気休暇の開始日 | C6: 45495 | D6: ※待機期間（3日）は年休でも可 | G6: 法定給付の末日（1年6月＋出勤） | J6: =MAX($K$85:$K$95)
A7: 退職日（任意） | D7: ※退職者のみ入力（在職中は空欄）。法定給付は退職後も算定 | G7: 附加給付の開始日 | J7: =J6+1 | K7: =IF(J9<J7,"※退職のため附加給付は算定しません","")
A8: 傷病手当日額の確認値（任意） | D8: ※基幹で確認した日額。入力すると全期間この額で算定。空欄なら標準報酬から試算 | G8: 附加給付の末日（+6月＋出勤） | J8: =WORKDAY(EDATE(J7,6+MAX($I$85:$I$95))-1,MAX($J$85:$J$95))
A9: 退職時附加金の受給（退職者のみ） | D9: ※退職日を入力した人のみ。有なら附加は退職日まで、無・空欄なら法定のみ | G9: 算定の最終日 | J9: =IF(C7="",J8,IF(C9="有",MAX(J6,MIN(J8,C7)),J6))
G10: 傷病手当日額（〇になった月で固定） | J10: =IF(C8<>"",C8,IFERROR(INDEX($G$37:$G$78,MATCH(DATE(YEAR($J$5),MONTH($J$5),1),$A$37:$A$78,0)),0))
A11: ■ 給与状況（給与課の給与証明で確認） ※報酬が変わる日ごとに1行。開始日の古い順に上から入力
A12: 区分 | B12: 開始日 | C12: 終了日 （自動） | D12: 給料月額 | E12: 地域手当 | F12: 扶養手当 | G12: 住居手当 | H12: 日額で支給 されるもの | I12: 月額で支給 されるもの
A13: 10割 | B13: 45495 | C13: =IF(B13="","",IF(AND(B14<>"",B14>B13),B14-1,$J$9)) | D13: 225300 | E13: 22530 | F13: 0 | G13: 0 | H13: =IF(B13="","",D13+E13) | I13: =IF(B13="","",F13+G13)
A14: 10割 | B14: 45658 | C14: =IF(B14="","",IF(AND(B15<>"",B15>B14),B15-1,$J$9)) | D14: 235200 | E14: 23520 | F14: 0 | G14: 0 | H14: =IF(B14="","",D14+E14) | I14: =IF(B14="","",F14+G14)
A15: 8割 | B15: 45675 | C15: =IF(B15="","",IF(AND(B16<>"",B16>B15),B16-1,$J$9)) | D15: 188160 | E15: 18816 | F15: 0 | G15: 0 | H15: =IF(B15="","",D15+E15) | I15: =IF(B15="","",F15+G15)
A16: 8割 | B16: 45748 | C16: =IF(B16="","",IF(AND(B17<>"",B17>B16),B17-1,$J$9)) | D16: 193980 | E16: 19398 | F16: 0 | G16: 0 | H16: =IF(B16="","",D16+E16) | I16: =IF(B16="","",F16+G16)
A17: 8割 | B17: 46023 | C17: =IF(B17="","",IF(AND(B18<>"",B18>B17),B18-1,$J$9)) | D17: 200243 | E17: 20024 | F17: 0 | G17: 0 | H17: =IF(B17="","",D17+E17) | I17: =IF(B17="","",F17+G17)
A18: 無給 | B18: 46040 | C18: =IF(B18="","",IF(AND(B19<>"",B19>B18),B19-1,$J$9)) | D18: 0 | E18: 0 | F18: 0 | G18: 0 | H18: =IF(B18="","",D18+E18) | I18: =IF(B18="","",F18+G18)
C19: =IF(B19="","",IF(AND(B20<>"",B20>B19),B20-1,$J$9)) | H19: =IF(B19="","",D19+E19) | I19: =IF(B19="","",F19+G19)
C20: =IF(B20="","",$J$9) | H20: =IF(B20="","",D20+E20) | I20: =IF(B20="","",F20+G20)
A21: ※日額で支給されるもの＝給料月額＋地域手当、月額で支給されるもの＝扶養手当＋住居手当（旧「計算内訳シート」「給与調整」と同じ区分）。無給期間は全て0。
A22: ※例のデータは、旧「給与調整」シートの給与証明の日額（247,830円など）から逆算したサンプルです。実際の証明額で書き換えてください。
A24: ■ 報酬日額（自動計算）＝ 日額で支給されるもの ÷ 勤務を要する日数 ＋ 月額で支給されるもの ÷ 22 （円未満切捨）
A25: 区分 | B25: 開始日 | C25: 20日の月 | D25: 21日の月 | E25: 22日の月 | F25: 23日の月
A26: =IF(B13="","",A13) | B26: =IF(B13="","",B13) | C26: =IF($B13="","",ROUNDDOWN($H13/20+$I13/22,0)) | D26: =IF($B13="","",ROUNDDOWN($H13/21+$I13/22,0)) | E26: =IF($B13="","",ROUNDDOWN($H13/22+$I13/22,0)) | F26: =IF($B13="","",ROUNDDOWN($H13/23+$I13/22,0))
A27: =IF(B14="","",A14) | B27: =IF(B14="","",B14) | C27: =IF($B14="","",ROUNDDOWN($H14/20+$I14/22,0)) | D27: =IF($B14="","",ROUNDDOWN($H14/21+$I14/22,0)) | E27: =IF($B14="","",ROUNDDOWN($H14/22+$I14/22,0)) | F27: =IF($B14="","",ROUNDDOWN($H14/23+$I14/22,0))
A28: =IF(B15="","",A15) | B28: =IF(B15="","",B15) | C28: =IF($B15="","",ROUNDDOWN($H15/20+$I15/22,0)) | D28: =IF($B15="","",ROUNDDOWN($H15/21+$I15/22,0)) | E28: =IF($B15="","",ROUNDDOWN($H15/22+$I15/22,0)) | F28: =IF($B15="","",ROUNDDOWN($H15/23+$I15/22,0))
A29: =IF(B16="","",A16) | B29: =IF(B16="","",B16) | C29: =IF($B16="","",ROUNDDOWN($H16/20+$I16/22,0)) | D29: =IF($B16="","",ROUNDDOWN($H16/21+$I16/22,0)) | E29: =IF($B16="","",ROUNDDOWN($H16/22+$I16/22,0)) | F29: =IF($B16="","",ROUNDDOWN($H16/23+$I16/22,0))
A30: =IF(B17="","",A17) | B30: =IF(B17="","",B17) | C30: =IF($B17="","",ROUNDDOWN($H17/20+$I17/22,0)) | D30: =IF($B17="","",ROUNDDOWN($H17/21+$I17/22,0)) | E30: =IF($B17="","",ROUNDDOWN($H17/22+$I17/22,0)) | F30: =IF($B17="","",ROUNDDOWN($H17/23+$I17/22,0))
A31: =IF(B18="","",A18) | B31: =IF(B18="","",B18) | C31: =IF($B18="","",ROUNDDOWN($H18/20+$I18/22,0)) | D31: =IF($B18="","",ROUNDDOWN($H18/21+$I18/22,0)) | E31: =IF($B18="","",ROUNDDOWN($H18/22+$I18/22,0)) | F31: =IF($B18="","",ROUNDDOWN($H18/23+$I18/22,0))
A32: =IF(B19="","",A19) | B32: =IF(B19="","",B19) | C32: =IF($B19="","",ROUNDDOWN($H19/20+$I19/22,0)) | D32: =IF($B19="","",ROUNDDOWN($H19/21+$I19/22,0)) | E32: =IF($B19="","",ROUNDDOWN($H19/22+$I19/22,0)) | F32: =IF($B19="","",ROUNDDOWN($H19/23+$I19/22,0))
A33: =IF(B20="","",A20) | B33: =IF(B20="","",B20) | C33: =IF($B20="","",ROUNDDOWN($H20/20+$I20/22,0)) | D33: =IF($B20="","",ROUNDDOWN($H20/21+$I20/22,0)) | E33: =IF($B20="","",ROUNDDOWN($H20/22+$I20/22,0)) | F33: =IF($B20="","",ROUNDDOWN($H20/23+$I20/22,0))
A35: ■ 標準報酬月額と傷病手当日額の試算（直近12か月平均 ÷ 22 → 10円未満四捨五入 → ×2/3 → 1円未満四捨五入）
A36: 年月 | B36: 標準報酬 月額 | C36: 直近12月 平均 | D36: ÷22 | E36: 10円未満 四捨五入 | F36: ×2/3 | G36: 傷病手当 日額
A37: =DATE(YEAR($J$4),MONTH($J$4)-12+0,1) | B37: 440000 | H37: =IF($A37<DATE(YEAR($J$4),MONTH($J$4),1),"",IF($A37<DATE(YEAR($J$5),MONTH($J$5),1),"判定用（初めて〇になる前の月の額）",IF($A37=DATE(YEAR($J$5),MONTH($J$5),1),IF($C$8<>"","← 確認値（C8）の額を、全期間の傷病手当日額として固定して使います","← 初めて〇になった月の額を、全期間の傷病手当日額として固定して使います"),"参考（算定には使いません）")))
A38: =DATE(YEAR($J$4),MONTH($J$4)-12+1,1) | B38: 440000 | H38: =IF($A38<DATE(YEAR($J$4),MONTH($J$4),1),"",IF($A38<DATE(YEAR($J$5),MONTH($J$5),1),"判定用（初めて〇になる前の月の額）",IF($A38=DATE(YEAR($J$5),MONTH($J$5),1),IF($C$8<>"","← 確認値（C8）の額を、全期間の傷病手当日額として固定して使います","← 初めて〇になった月の額を、全期間の傷病手当日額として固定して使います"),"参考（算定には使いません）")))
A39: =DATE(YEAR($J$4),MONTH($J$4)-12+2,1) | B39: 410000 | H39: =IF($A39<DATE(YEAR($J$4),MONTH($J$4),1),"",IF($A39<DATE(YEAR($J$5),MONTH($J$5),1),"判定用（初めて〇になる前の月の額）",IF($A39=DATE(YEAR($J$5),MONTH($J$5),1),IF($C$8<>"","← 確認値（C8）の額を、全期間の傷病手当日額として固定して使います","← 初めて〇になった月の額を、全期間の傷病手当日額として固定して使います"),"参考（算定には使いません）")))
A40: =DATE(YEAR($J$4),MONTH($J$4)-12+3,1) | B40: 410000 | H40: =IF($A40<DATE(YEAR($J$4),MONTH($J$4),1),"",IF($A40<DATE(YEAR($J$5),MONTH($J$5),1),"判定用（初めて〇になる前の月の額）",IF($A40=DATE(YEAR($J$5),MONTH($J$5),1),IF($C$8<>"","← 確認値（C8）の額を、全期間の傷病手当日額として固定して使います","← 初めて〇になった月の額を、全期間の傷病手当日額として固定して使います"),"参考（算定には使いません）")))
A41: =DATE(YEAR($J$4),MONTH($J$4)-12+4,1) | B41: 410000 | H41: =IF($A41<DATE(YEAR($J$4),MONTH($J$4),1),"",IF($A41<DATE(YEAR($J$5),MONTH($J$5),1),"判定用（初めて〇になる前の月の額）",IF($A41=DATE(YEAR($J$5),MONTH($J$5),1),IF($C$8<>"","← 確認値（C8）の額を、全期間の傷病手当日額として固定して使います","← 初めて〇になった月の額を、全期間の傷病手当日額として固定して使います"),"参考（算定には使いません）")))
A42: =DATE(YEAR($J$4),MONTH($J$4)-12+5,1) | B42: 410000 | H42: =IF($A42<DATE(YEAR($J$4),MONTH($J$4),1),"",IF($A42<DATE(YEAR($J$5),MONTH($J$5),1),"判定用（初めて〇になる前の月の額）",IF($A42=DATE(YEAR($J$5),MONTH($J$5),1),IF($C$8<>"","← 確認値（C8）の額を、全期間の傷病手当日額として固定して使います","← 初めて〇になった月の額を、全期間の傷病手当日額として固定して使います"),"参考（算定には使いません）")))
...

Sheet 月別集計
A1: =算定表!A1
A2: 基幹システム入力用：月ごと・法定／附加ごとに集計します（給与区分で行が分かれる月も1行にまとめています）。
A3: ="支給開始日：" & TEXT(入力!J5,"[$-411]ggge""年""m""月""d""日""") & " 法定給付の末日：" & TEXT(入力!J6,"[$-411]ggge""年""m""月""d""日""") & " 附加給付：" & IF(入力!J9>入力!J6,TEXT(入力!J7,"[$-411]ggge""年""m""月""d""日""") & "～" & TEXT(入力!J8,"[$-411]ggge""年""m""月""d""日"""),"なし") & " 算定の最終日：" & TEXT(入力!J9,"[$-411]ggge""年""m""月""d""日""")
A4: ="傷病手当日額（初めて〇になった月で固定）：" & TEXT(入力!J10,"#,##0") & "円" & IF(OR(入力!D85>0,入力!E85>0)," 出勤による延長：" & IF(入力!D85>0,入力!D85 & "か月","") & IF(AND(入力!D85>0,入力!E85>0),"＋","") & IF(入力!E85>0,入力!E85 & "日（土日を除く）",""),"")
A5: 番号 | B5: 年 | C5: 月 | D5: 給付 区分 | E5: 支給期間 （始） | F5: 支給期間 （終） | G5: 支給日数 | H5: 標準支給額 | I5: 調整額 | J5: 差引支給額 （基幹入力額） | K5: 備考 | L5: 行
A6: =IF(ROW()-5<=MAX(算定表!$Q$6:$Q$53),ROW()-5,"") | B6: =IF(A6="","",INDEX(算定表!$B$6:$B$53,L6)) | C6: =IF(A6="","",INDEX(算定表!$C$6:$C$53,L6)) | D6: =IF(A6="","",INDEX(算定表!$E$6:$E$53,L6)) | E6: =IF(A6="","",INDEX(算定表!$F$6:$F$53,L6)) | F6: =IF(A6="","",LOOKUP(2,1/((算定表!$B$6:$B$53=B6)*(算定表!$C$6:$C$53=C6)*(算定表!$E$6:$E$53=D6)),算定表!$G$6:$G$53)) | G6: =IF(A6="","",SUMIFS(算定表!$I$6:$I$53,算定表!$B$6:$B$53,B6,算定表!$C$6:$C$53,C6,算定表!$E$6:$E$53,D6)) | H6: =IF(A6="","",SUMIFS(算定表!$M$6:$M$53,算定表!$B$6:$B$53,B6,算定表!$C$6:$C$53,C6,算定表!$E$6:$E$53,D6)) | I6: =IF(A6="","",SUMIFS(算定表!$N$6:$N$53,算定表!$B$6:$B$53,B6,算定表!$C$6:$C$53,C6,算定表!$E$6:$E$53,D6)) | J6: =IF(A6="","",SUMIFS(算定表!$O$6:$O$53,算定表!$B$6:$B$53,B6,算定表!$C$6:$C$53,C6,算定表!$E$6:$E$53,D6)) | K6: =IF(A6="","",IF(J6=0,"支給なし","")) | L6: =IF(A6="","",MATCH(A6,算定表!$Q$6:$Q$53,0))
A7: =IF(ROW()-5<=MAX(算定表!$Q$6:$Q$53),ROW()-5,"") | B7: =IF(A7="","",INDEX(算定表!$B$6:$B$53,L7)) | C7: =IF(A7="","",INDEX(算定表!$C$6:$C$53,L7)) | D7: =IF(A7="","",INDEX(算定表!$E$6:$E$53,L7)) | E7: =IF(A7="","",INDEX(算定表!$F$6:$F$53,L7)) | F7: =IF(A7="","",LOOKUP(2,1/((算定表!$B$6:$B$53=B7)*(算定表!$C$6:$C$53=C7)*(算定表!$E$6:$E$53=D7)),算定表!$G$6:$G$53)) | G7: =IF(A7="","",SUMIFS(算定表!$I$6:$I$53,算定表!$B$6:$B$53,B7,算定表!$C$6:$C$53,C7,算定表!$E$6:$E$53,D7)) | H7: =IF(A7="","",SUMIFS(算定表!$M$6:$M$53,算定表!$B$6:$B$53,B7,算定表!$C$6:$C$53,C7,算定表!$E$6:$E$53,D7)) | I7: =IF(A7="","",SUMIFS(算定表!$N$6:$N$53,算定表!$B$6:$B$53,B7,算定表!$C$6:$C$53,C7,算定表!$E$6:$E$53,D7)) | J7: =IF(A7="","",SUMIFS(算定表!$O$6:$O$53,算定表!$B$6:$B$53,B7,算定表!$C$6:$C$53,C7,算定表!$E$6:$E$53,D7)) | K7: =IF(A7="","",IF(J7=0,"支給なし","")) | L7: =IF(A7="","",MATCH(A7,算定表!$Q$6:$Q$53,0))
A8: =IF(ROW()-5<=MAX(算定表!$Q$6:$Q$53),ROW()-5,"") | B8: =IF(A8="","",INDEX(算定表!$B$6:$B$53,L8)) | C8: =IF(A8="","",INDEX(算定表!$C$6:$C$53,L8)) | D8: =IF(A8="","",INDEX(算定表!$E$6:$E$53,L8)) | E8: =IF(A8="","",INDEX(算定表!$F$6:$F$53,L8)) | F8: =IF(A8="","",LOOKUP(2,1/((算定表!$B$6:$B$53=B8)*(算定表!$C$6:$C$53=C8)*(算定表!$E$6:$E$53=D8)),算定表!$G$6:$G$53)) | G8: =IF(A8="","",SUMIFS(算定表!$I$6:$I$53,算定表!$B$6:$B$53,B8,算定表!$C$6:$C$53,C8,算定表!$E$6:$E$53,D8)) | H8: =IF(A8="","",SUMIFS(算定表!$M$6:$M$53,算定表!$B$6:$B$53,B8,算定表!$C$6:$C$53,C8,算定表!$E$6:$E$53,D8)) | I8: =IF(A8="","",SUMIFS(算定表!$N$6:$N$53,算定表!$B$6:$B$53,B8,算定表!$C$6:$C$53,C8,算定表!$E$6:$E$53,D8)) | J8: =IF(A8="","",SUMIFS(算定表!$O$6:$O$53,算定表!$B$6:$B$53,B8,算定表!$C$6:$C$53,C8,算定表!$E$6:$E$53,D8)) | K8: =IF(A8="","",IF(J8=0,"支給なし","")) | L8: =IF(A8="","",MATCH(A8,算定表!$Q$6:$Q$53,0))
A9: =IF(ROW()-5<=MAX(算定表!$Q$6:$Q$53),ROW()-5,"") | B9: =IF(A9="","",INDEX(算定表!$B$6:$B$53,L9)) | C9: =IF(A9="","",INDEX(算定表!$C$6:$C$53,L9)) | D9: =IF(A9="","",INDEX(算定表!$E$6:$E$53,L9)) | E9: =IF(A9="","",INDEX(算定表!$F$6:$F$53,L9)) | F9: =IF(A9="","",LOOKUP(2,1/((算定表!$B$6:$B$53=B9)*(算定表!$C$6:$C$53=C9)*(算定表!$E$6:$E$53=D9)),算定表!$G$6:$G$53)) | G9: =IF(A9="","",SUMIFS(算定表!$I$6:$I$53,算定表!$B$6:$B$53,B9,算定表!$C$6:$C$53,C9,算定表!$E$6:$E$53,D9)) | H9: =IF(A9="","",SUMIFS(算定表!$M$6:$M$53,算定表!$B$6:$B$53,B9,算定表!$C$6:$C$53,C9,算定表!$E$6:$E$53,D9)) | I9: =IF(A9="","",SUMIFS(算定表!$N$6:$N$53,算定表!$B$6:$B$53,B9,算定表!$C$6:$C$53,C9,算定表!$E$6:$E$53,D9)) | J9: =IF(A9="","",SUMIFS(算定表!$O$6:$O$53,算定表!$B$6:$B$53,B9,算定表!$C$6:$C$53,C9,算定表!$E$6:$E$53,D9)) | K9: =IF(A9="","",IF(J9=0,"支給なし","")) | L9: =IF(A9="","",MATCH(A9,算定表!$Q$6:$Q$53,0))
A10: =IF(ROW()-5<=MAX(算定表!$Q$6:$Q$53),ROW()-5,"") | B10: =IF(A10="","",INDEX(算定表!$B$6:$B$53,L10)) | C10: =IF(A10="","",INDEX(算定表!$C$6:$C$53,L10)) | D10: =IF(A10="","",INDEX(算定表!$E$6:$E$53,L10)) | E10: =IF(A10="","",INDEX(算定表!$F$6:$F$53,L10)) | F10: =IF(A10="","",LOOKUP(2,1/((算定表!$B$6:$B$53=B10)*(算定表!$C$6:$C$53=C10)*(算定表!$E$6:$E$53=D10)),算定表!$G$6:$G$53)) | G10: =IF(A10="","",SUMIFS(算定表!$I$6:$I$53,算定表!$B$6:$B$53,B10,算定表!$C$6:$C$53,C10,算定表!$E$6:$E$53,D10)) | H10: =IF(A10="","",SUMIFS(算定表!$M$6:$M$53,算定表!$B$6:$B$53,B10,算定表!$C$6:$C$53,C10,算定表!$E$6:$E$53,D10)) | I10: =IF(A10="","",SUMIFS(算定表!$N$6:$N$53,算定表!$B$6:$B$53,B10,算定表!$C$6:$C$53,C10,算定表!$E$6:$E$53,D10)) | J10: =IF(A10="","",SUMIFS(算定表!$O$6:$O$53,算定表!$B$6:$B$53,B10,算定表!$C$6:$C$53,C10,算定表!$E$6:$E$53,D10)) | K10: =IF(A10="","",IF(J10=0,"支給なし","")) | L10: =IF(A10="","",MATCH(A10,算定表!$Q$6:$Q$53,0))
A11: =IF(ROW()-5<=MAX(算定表!$Q$6:$Q$53),ROW()-5,"") | B11: =IF(A11="","",INDEX(算定表!$B$6:$B$53,L11)) | C11: =IF(A11="","",INDEX(算定表!$C$6:$C$53,L11)) | D11: =IF(A11="","",INDEX(算定表!$E$6:$E$53,L11)) | E11: =IF(A11="","",INDEX(算定表!$F$6:$F$53,L11)) | F11: =IF(A11="","",LOOKUP(2,1/((算定表!$B$6:$B$53=B11)*(算定表!$C$6:$C$53=C11)*(算定表!$E$6:$E$53=D11)),算定表!$G$6:$G$53)) | G11: =IF(A11="","",SUMIFS(算定表!$I$6:$I$53,算定表!$B$6:$B$53,B11,算定表!$C$6:$C$53,C11,算定表!$E$6:$E$53,D11)) | H11: =IF(A11="","",SUMIFS(算定表!$M$6:$M$53,算定表!$B$6:$B$53,B11,算定表!$C$6:$C$53,C11,算定表!$E$6:$E$53,D11)) | I11: =IF(A11="","",SUMIFS(算定表!$N$6:$N$53,算定表!$B$6:$B$53,B11,算定表!$C$6:$C$53,C11,算定表!$E$6:$E$53,D11)) | J11: =IF(A11="","",SUMIFS(算定表!$O$6:$O$53,算定表!$B$6:$B$53,B11,算定表!$C$6:$C$53,C11,算定表!$E$6:$E$53,D11)) | K11: =IF(A11="","",IF(J11=0,"支給なし","")) | L11: =IF(A11="","",MATCH(A11,算定表!$Q$6:$Q$53,0))
A12: =IF(ROW()-5<=MAX(算定表!$Q$6:$Q$53),ROW()-5,"") | B12: =IF(A12="","",INDEX(算定表!$B$6:$B$53,L12)) | C12: =IF(A12="","",INDEX(算定表!$C$6:$C$53,L12)) | D12: =IF(A12="","",INDEX(算定表!$E$6:$E$53,L12)) | E12: =IF(A12="","",INDEX(算定表!$F$6:$F$53,L12)) | F12: =IF(A12="","",LOOKUP(2,1/((算定表!$B$6:$B$53=B12)*(算定表!$C$6:$C$53=C12)*(算定表!$E$6:$E$53=D12)),算定表!$G$6:$G$53)) | G12: =IF(A12="","",SUMIFS(算定表!$I$6:$I$53,算定表!$B$6:$B$53,B12,算定表!$C$6:$C$53,C12,算定表!$E$6:$E$53,D12)) | H12: =IF(A12="","",SUMIFS(算定表!$M$6:$M$53,算定表!$B$6:$B$53,B12,算定表!$C$6:$C$53,C12,算定表!$E$6:$E$53,D12)) | I12: =IF(A12="","",SUMIFS(算定表!$N$6:$N$53,算定表!$B$6:$B$53,B12,算定表!$C$6:$C$53,C12,算定表!$E$6:$E$53,D12)) | J12: =IF(A12="","",SUMIFS(算定表!$O$6:$O$53,算定表!$B$6:$B$53,B12,算定表!$C$6:$C$53,C12,算定表!$E$6:$E$53,D12)) | K12: =IF(A12="","",IF(J12=0,"支給なし","")) | L12: =IF(A12="","",MATCH(A12,算定表!$Q$6:$Q$53,0))
A13: =IF(ROW()-5<=MAX(算定表!$Q$6:$Q$53),ROW()-5,"") | B13: =IF(A13="","",INDEX(算定表!$B$6:$B$53,L13)) | C13: =IF(A13="","",INDEX(算定表!$C$6:$C$53,L13)) | D13: =IF(A13="","",INDEX(算定表!$E$6:$E$53,L13)) | E13: =IF(A13="","",INDEX(算定表!$F$6:$F$53,L13)) | F13: =IF(A13="","",LOOKUP(2,1/((算定表!$B$6:$B$53=B13)*(算定表!$C$6:$C$53=C13)*(算定表!$E$6:$E$53=D13)),算定表!$G$6:$G$53)) | G13: =IF(A13="","",SUMIFS(算定表!$I$6:$I$53,算定表!$B$6:$B$53,B13,算定表!$C$6:$C$53,C13,算定表!$E$6:$E$53,D13)) | H13: =IF(A13="","",SUMIFS(算定表!$M$6:$M$53,算定表!$B$6:$B$53,B13,算定表!$C$6:$C$53,C13,算定表!$E$6:$E$53,D13)) | I13: =IF(A13="","",SUMIFS(算定表!$N$6:$N$53,算定表!$B$6:$B$53,B13,算定表!$C$6:$C$53,C13,算定表!$E$6:$E$53,D13)) | J13: =IF(A13="","",SUMIFS(算定表!$O$6:$O$53,算定表!$B$6:$B$53,B13,算定表!$C$6:$C$53,C13,算定表!$E$6:$E$53,D13)) | K13: =IF(A13="","",IF(J13=0,"支給なし","")) | L13: =IF(A13="","",MATCH(A13,算定表!$Q$6:$Q$53,0))
A14: =IF(ROW()-5<=MAX(算定表!$Q$6:$Q$53),ROW()-5,"") | B14: =IF(A14="","",INDEX(算定表!$B$6:$B$53,L14)) | C14: =IF(A14="","",INDEX(算定表!$C$6:$C$53,L14)) | D14: =IF(A14="","",INDEX(算定表!$E$6:$E$53,L14)) | E14: =IF(A14="","",INDEX(算定表!$F$6:$F$53,L14)) | F14: =IF(A14="","",LOOKUP(2,1/((算定表!$B$6:$B$53=B14)*(算定表!$C$6:$C$53=C14)*(算定表!$E$6:$E$53=D14)),算定表!$G$6:$G$53)) | G14: =IF(A14="","",SUMIFS(算定表!$I$6:$I$53,算定表!$B$6:$B$53,B14,算定表!$C$6:$C$53,C14,算定表!$E$6:$E$53,D14)) | H14: =IF(A14="","",SUMIFS(算定表!$M$6:$M$53,算定表!$B$6:$B$53,B14,算定表!$C$6:$C$53,C14,算定表!$E$6:$E$53,D14)) | I14: =IF(A14="","",SUMIFS(算定表!$N$6:$N$53,算定表!$B$6:$B$53,B14,算定表!$C$6:$C$53,C14,算定表!$E$6:$E$53,D14)) | J14: =IF(A14="","",SUMIFS(算定表!$O$6:$O$53,算定表!$B$6:$B$53,B14,算定表!$C$6:$C$53,C14,算定表!$E$6:$E$53,D14)) | K14: =IF(A14="","",IF(J14=0,"支給なし","")) | L14: =IF(A14="","",MATCH(A14,算定表!$Q$6:$Q$53,0))
A15: =IF(ROW()-5<=MAX(算定表!$Q$6:$Q$53),ROW()-5,"") | B15: =IF(A15="","",INDEX(算定表!$B$6:$B$53,L15)) | C15: =IF(A15="","",INDEX(算定表!$C$6:$C$53,L15)) | D15: =IF(A15="","",INDEX(算定表!$E$6:$E$53,L15)) | E15: =IF(A15="","",INDEX(算定表!$F$6:$F$53,L15)) | F15: =IF(A15="","",LOOKUP(2,1/((算定表!$B$6:$B$53=B15)*(算定表!$C$6:$C$53=C15)*(算定表!$E$6:$E$53=D15)),算定表!$G$6:$G$53)) | G15: =IF(A15="","",SUMIFS(算定表!$I$6:$I$53,算定表!$B$6:$B$53,B15,算定表!$C$6:$C$53,C15,算定表!$E$6:$E$53,D15)) | H15: =IF(A15="","",SUMIFS(算定表!$M$6:$M$53,算定表!$B$6:$B$53,B15,算定表!$C$6:$C$53,C15,算定表!$E$6:$E$53,D15)) | I15: =IF(A15="","",SUMIFS(算定表!$N$6:$N$53,算定表!$B$6:$B$53,B15,算定表!$C$6:$C$53,C15,算定表!$E$6:$E$53,D15)) | J15: =IF(A15="","",SUMIFS(算定表!$O$6:$O$53,算定表!$B$6:$B$53,B15,算定表!$C$6:$C$53,C15,算定表!$E$6:$E$53,D15)) | K15: =IF(A15="","",IF(J15=0,"支給なし","")) | L15: =IF(A15="","",MATCH(A15,算定表!$Q$6:$Q$53,0))
A16: =IF(ROW()-5<=MAX(算定表!$Q$6:$Q$53),ROW()-5,"") | B16: =IF(A16="","",INDEX(算定表!$B$6:$B$53,L16)) | C16: =IF(A16="","",INDEX(算定表!$C$6:$C$53,L16)) | D16: =IF(A16="","",INDEX(算定表!$E$6:$E$53,L16)) | E16: =IF(A16="","",INDEX(算定表!$F$6:$F$53,L16)) | F16: =IF(A16="","",LOOKUP(2,1/((算定表!$B$6:$B$53=B16)*(算定表!$C$6:$C$53=C16)*(算定表!$E$6:$E$53=D16)),算定表!$G$6:$G$53)) | G16: =IF(A16="","",SUMIFS(算定表!$I$6:$I$53,算定表!$B$6:$B$53,B16,算定表!$C$6:$C$53,C16,算定表!$E$6:$E$53,D16)) | H16: =IF(A16="","",SUMIFS(算定表!$M$6:$M$53,算定表!$B$6:$B$53,B16,算定表!$C$6:$C$53,C16,算定表!$E$6:$E$53,D16)) | I16: =IF(A16="","",SUMIFS(算定表!$N$6:$N$53,算定表!$B$6:$B$53,B16,算定表!$C$6:$C$53,C16,算定表!$E$6:$E$53,D16)) | J16: =IF(A16="","",SUMIFS(算定表!$O$6:$O$53,算定表!$B$6:$B$53,B16,算定表!$C$6:$C$53,C16,算定表!$E$6:$E$53,D16)) | K16: =IF(A16="","",IF(J16=0,"支給なし","")) | L16: =IF(A16="","",MATCH(A16,算定表!$Q$6:$Q$53,0))
A17: =IF(ROW()-5<=MAX(算定表!$Q$6:$Q$53),ROW()-5,"") | B17: =IF(A17="","",INDEX(算定表!$B$6:$B$53,L17)) | C17: =IF(A17="","",INDEX(算定表!$C$6:$C$53,L17)) | D17: =IF(A17="","",INDEX(算定表!$E$6:$E$53,L17)) | E17: =IF(A17="","",INDEX(算定表!$F$6:$F$53,L17)) | F17: =IF(A17="","",LOOKUP(2,1/((算定表!$B$6:$B$53=B17)*(算定表!$C$6:$C$53=C17)*(算定表!$E$6:$E$53=D17)),算定表!$G$6:$G$53)) | G17: =IF(A17="","",SUMIFS(算定表!$I$6:$I$53,算定表!$B$6:$B$53,B17,算定表!$C$6:$C$53,C17,算定表!$E$6:$E$53,D17)) | H17: =IF(A17="","",SUMIFS(算定表!$M$6:$M$53,算定表!$B$6:$B$53,B17,算定表!$C$6:$C$53,C17,算定表!$E$6:$E$53,D17)) | I17: =IF(A17="","",SUMIFS(算定表!$N$6:$N$53,算定表!$B$6:$B$53,B17,算定表!$C$6:$C$53,C17,算定表!$E$6:$E$53,D17)) | J17: =IF(A17="","",SUMIFS(算定表!$O$6:$O$53,算定表!$B$6:$B$53,B17,算定表!$C$6:$C$53,C17,算定表!$E$6:$E$53,D17)) | K17: =IF(A17="","",IF(J17=0,"支給なし","")) | L17: =IF(A17="","",MATCH(A17,算定表!$Q$6:$Q$53,0))
... A53: =IF(ROW()-5<=MAX(算定表!$Q$6:$Q$53),ROW()-5,"") | B53: =IF(A53="","",INDEX(算定表!$B$6:$B$53,L53)) | C53: =IF(A53="","",INDEX(算定表!$C$6:$C$53,L53)) | D53: =IF(A53="","",INDEX(算定表!$E$6:$E$53,L53)) | E53: =IF(A53="","",INDEX(算定表!$F$6:$F$53,L53)) | F53: =IF(A53="","",LOOKUP(2,1/((算定表!$B$6:$B$53=B53)*(算定表!$C$6:$C$53=C53)*(算定表!$E$6:$E$53=D53)),算定表!$G$6:$G$53)) | G53: =IF(A53="","",SUMIFS(算定表!$I$6:$I$53,算定表!$B$6:$B$53,B53,算定表!$C$6:$C$53,C53,算定表!$E$6:$E$53,D53)) | H53: =IF(A53="","",SUMIFS(算定表!$M$6:$M$53,算定表!$B$6:$B$53,B53,算定表!$C$6:$C$53,C53,算定表!$E$6:$E$53,D53)) | I53: =IF(A53="","",SUMIFS(算定表!$N$6:$N$53,算定表!$B$6:$B$53,B53,算定表!$C$6:$C$53,C53,算定表!$E$6:$E$53,D53)) | J53: =IF(A53="","",SUMIFS(算定表!$O$6:$O$53,算定表!$B$6:$B$53,B53,算定表!$C$6:$C$53,C53,算定表!$E$6:$E$53,D53)) | K53: =IF(A53="","",IF(J53=0,"支給なし","")) | L53: =IF(A53="","",MATCH(A53,算定表!$Q$6:$Q$53,0))
A55: 法定給付 計 | G55: =SUMIFS(G6:G53,$D$6:$D$53,"法定") | H55: =SUMIFS(H6:H53,$D$6:$D$53,"法定") | I55: =SUMIFS(I6:I53,$D$6:$D$53,"法定") | J55: =SUMIFS(J6:J53,$D$6:$D$53,"法定")
A56: 附加給付 計 | G56: =SUMIFS(G6:G53,$D$6:$D$53,"附加") | H56: =SUMIFS(H6:H53,$D$6:$D$53,"附加") | I56: =SUMIFS(I6:I53,$D$6:$D$53,"附加") | J56: =SUMIFS(J6:J53,$D$6:$D$53,"附加")
A57: 合 計 | G57: =SUM(G55:G56) | H57: =SUM(H55:H56) | I57: =SUM(I55:I56) | J57: =SUM(J55:J56)
A59: ■ 検算（算定表の合計との差。0なら整合）
A60: 差引支給額：月別集計 − 算定表 | J60: =J57-算定表!O57
A61: 支給日数：月別集計 − 算定表 | G61: =G57-算定表!I57
A63: ・基幹システムには、標準支給額（日額×日数）を入れ、報酬との調整分は「調整額」にマイナスで入力します。最終給付額が差引支給額と一致するか確認してください。

Sheet 算定表
A1: ="（"&入力!C4&"） "&入力!C5
A2: ="病気休暇：" & TEXT(入力!C6,"[$-411]ggge""年""m""月""d""日""") & "～ 傷病手当（法定）：" & TEXT(入力!J5,"[$-411]ggge""年""m""月""d""日""") & "～" & TEXT(入力!J6,"[$-411]ggge""年""m""月""d""日""")& IF(入力!J9>入力!J6," 附加給付：" & TEXT(入力!J7,"[$-411]ggge""年""m""月""d""日""") & "～" & TEXT(入力!J9,"[$-411]ggge""年""m""月""d""日""")," 附加給付：なし")
A3: 標準支給額（報酬がないとした場合の額）から、報酬との調整額を差し引いた「差引支給額」を月別・給付区分別に自動計算します。
A5: 番号 | B5: 年 | C5: 月 | D5: 給与 区分 | E5: 給付 区分 | F5: 支給期間 （始） | G5: 支給期間 （終） | H5: 勤務を 要する日 | I5: 支給日数 （A） | J5: 傷病手当 日額（B） | K5: 報酬日額 （C） | L5: 支給 可否 | M5: 標準支給額 （F=B×A） | N5: 調整額 （G） | O5: 差引支給額 （E=F−G） | P5: 参考 月ごとの試算日額 | Q5: 集計用 | R5: 出勤skip1 | S5: 出勤skip2 | U5: 判定_始 | V5: 判定_終 | W5: 判定_skip1 | X5: 判定_skip2 | Y5: 判定_勤務日 | Z5: 判定_日額 | AA5: 判定_報酬日額 | AB5: 判定_〇 | AD5: 初めて〇の行
A6: =IF(F6="","",1) | B6: =IF(F6="","",DATE(YEAR(F6),MONTH(F6),1)) | C6: =IF(F6="","",MONTH(F6)) | D6: =IF(F6="","",INDEX(入力!$A$13:$A$20,MATCH(F6,入力!$B$13:$B$20,1))) | E6: =IF(F6="","",IF(G6<=入力!$J$6,"法定","附加")) | F6: =入力!$J$4 | G6: =IF(F6="","",MIN(EOMONTH(F6,0),入力!$J$9,IF(AND(入力!$B$13<>"",入力!$B$13>F6),入力!$B$13-1,999999),IF(AND(入力!$B$14<>"",入力!$B$14>F6),入力!$B$14-1,999999),IF(AND(入力!$B$15<>"",入力!$B$15>F6),入力!$B$15-1,999999),IF(AND(入力!$B$16<>"",入力!$B$16>F6),入力!$B$16-1,999999),IF(AND(入力!$B$17<>"",入力!$B$17>F6),入力!$B$17-1,999999),IF(AND(入力!$B$18<>"",入力!$B$18>F6),入力!$B$18-1,999999),IF(AND(入力!$B$19<>"",入力!$B$19>F6),入力!$B$19-1,999999),IF(AND(入力!$B$20<>"",入力!$B$20>F6),入力!$B$20-1,999999),IF(AND(入力!$J$7<>"",入力!$J$7>F6),入力!$J$7-1,999999),IFERROR(SMALL(入力!$B$86:$B$95,COUNTIF(入力!$B$86:$B$95,"<="&F6)+1)-1,999999))) | H6: =IF(F6="","",IFERROR(VLOOKUP(B6,カレンダーマスタ!$A$2:$B$301,2,0),NETWORKDAYS(B6,EOMONTH(F6,0)))) | I6: =IF(F6="","",NETWORKDAYS(F6,G6)) | J6: =IF(F6="","",IF(入力!$C$8<>"",入力!$C$8,IF(F6<入力!$J$5,IFERROR(INDEX(入力!$G$37:$G$78,MATCH(B6,入力!$A$37:$A$78,0)),入力!$J$10),入力!$J$10))) | K6: =IF(F6="","",ROUNDDOWN(INDEX(入力!$H$13:$H$20,MATCH(F6,入力!$B$13:$B$20,1))/H6+INDEX(入力!$I$13:$I$20,MATCH(F6,入力!$B$13:$B$20,1))/22,0)) | L6: =IF(F6="","",IF(J6>K6,"〇","×")) | M6: =IF(F6="","",J6*I6) | N6: =IF(F6="","",MIN(J6,K6)*I6) | O6: =IF(F6="","",M6-N6) | P6: =IF(F6="","",IFERROR(INDEX(入力!$G$37:$G$78,MATCH(B6,入力!$A$37:$A$78,0)),"")) | Q6: =IF(F6="","",IF(COUNTIFS($B$6:B6,B6,$C$6:C6,C6,$E$6:E6,E6)=1,MAX($Q$5:Q5)+1,"")) | R6: =IF(G6="","",IF(COUNTIFS(入力!$B$86:$B$95,"<="&(G6+1),入力!$C$86:$C$95,">="&(G6+1))>0,SUMIFS(入力!$C$86:$C$95,入力!$B$86:$B$95,"<="&(G6+1),入力!$C$86:$C$95,">="&(G6+1))+1,G6+1)) | S6: =IF(R6="","",IF(COUNTIFS(入力!$B$86:$B$95,"<="&(R6),入力!$C$86:$C$95,">="&(R6))>0,SUMIFS(入力!$C$86:$C$95,入力!$B$86:$B$95,"<="&(R6),入力!$C$86:$C$95,">="&(R6))+1,R6)) | U6: =入力!$J$4 | V6: =IF(U6="","",MIN(EOMONTH(U6,0),IF(AND(入力!$B$13<>"",入力!$B$13>U6),入力!$B$13-1,999999),IF(AND(入力!$B$14<>"",入力!$B$14>U6),入力!$B$14-1,999999),IF(AND(入力!$B$15<>"",入力!$B$15>U6),入力!$B$15-1,999999),IF(AND(入力!$B$16<>"",入力!$B$16>U6),入力!$B$16-1,999999),IF(AND(入力!$B$17<>"",入力!$B$17>U6),入力!$B$17-1,999999),IF(AND(入力!$B$18<>"",入力!$B$18>U6),入力!$B$18-1,999999),IF(AND(入力!$B$19<>"",入力!$B$19>U6),入力!$B$19-1,999999),IF(AND(入力!$B$20<>"",入力!$B$20>U6),入力!$B$20-1,999999),IFERROR(SMALL(入力!$B$86:$B$95,COUNTIF(入力!$B$86:$B$95,"<="&U6)+1)-1,999999))) | W6: =IF(V6="","",IF(COUNTIFS(入力!$B$86:$B$95,"<="&(V6+1),入力!$C$86:$C$95,">="&(V6+1))>0,SUMIFS(入力!$C$86:$C$95,入力!$B$86:$B$95,"<="&(V6+1),入力!$C$86:$C$95,">="&(V6+1))+1,V6+1)) | X6: =IF(W6="","",IF(COUNTIFS(入力!$B$86:$B$95,"<="&(W6),入力!$C$86:$C$95,">="&(W6))>0,SUMIFS(入力!$C$86:$C$95,入力!$B$86:$B$95,"<="&(W6),入力!$C$86:$C$95,">="&(W6))+1,W6)) | Y6: =IF(U6="","",IFERROR(VLOOKUP(DATE(YEAR(U6),MONTH(U6),1),カレンダーマスタ!$A$2:$B$301,2,0),NETWORKDAYS(DATE(YEAR(U6),MONTH(U6),1),EOMONTH(U6,0)))) | Z6: =IF(U6="","",IF(入力!$C$8<>"",入力!$C$8,IFERROR(INDEX(入力!$G$37:$G$78,MATCH(DATE(YEAR(U6),MONTH(U6),1),入力!$A$37:$A$78,0)),0))) | AA6: =IF(U6="","",ROUNDDOWN(INDEX(入力!$H$13:$H$20,MATCH(U6,入力!$B$13:$B$20,1))/Y6+INDEX(入力!$I$13:$I$20,MATCH(U6,入力!$B$13:$B$20,1))/22,0)) | AB6: =IF(U6="",0,IF(AND(Z6>AA6,NETWORKDAYS(U6,V6)>0),1,0)) | AD6: =IFERROR(MATCH(1,AB6:AB53,0),"")
A7: =IF(F7="","",2) | B7: =IF(F7="","",DATE(YEAR(F7),MONTH(F7),1)) | C7: =IF(F7="","",MONTH(F7)) | D7: =IF(F7="","",INDEX(入力!$A$13:$A$20,MATCH(F7,入力!$B$13:$B$20,1))) | E7: =IF(F7="","",IF(G7<=入力!$J$6,"法定","附加")) | F7: =IF(G6="","",IF(G6>=入力!$J$9,"",IF(S6>入力!$J$9,"",S6))) | G7: =IF(F7="","",MIN(EOMONTH(F7,0),入力!$J$9,IF(AND(入力!$B$13<>"",入力!$B$13>F7),入力!$B$13-1,999999),IF(AND(入力!$B$14<>"",入力!$B$14>F7),入力!$B$14-1,999999),IF(AND(入力!$B$15<>"",入力!$B$15>F7),入力!$B$15-1,999999),IF(AND(入力!$B$16<>"",入力!$B$16>F7),入力!$B$16-1,999999),IF(AND(入力!$B$17<>"",入力!$B$17>F7),入力!$B$17-1,999999),IF(AND(入力!$B$18<>"",入力!$B$18>F7),入力!$B$18-1,999999),IF(AND(入力!$B$19<>"",入力!$B$19>F7),入力!$B$19-1,999999),IF(AND(入力!$B$20<>"",入力!$B$20>F7),入力!$B$20-1,999999),IF(AND(入力!$J$7<>"",入力!$J$7>F7),入力!$J$7-1,999999),IFERROR(SMALL(入力!$B$86:$B$95,COUNTIF(入力!$B$86:$B$95,"<="&F7)+1)-1,999999))) | H7: =IF(F7="","",IFERROR(VLOOKUP(B7,カレンダーマスタ!$A$2:$B$301,2,0),NETWORKDAYS(B7,EOMONTH(F7,0)))) | I7: =IF(F7="","",NETWORKDAYS(F7,G7)) | J7: =IF(F7="","",IF(入力!$C$8<>"",入力!$C$8,IF(F7<入力!$J$5,IFERROR(INDEX(入力!$G$37:$G$78,MATCH(B7,入力!$A$37:$A$78,0)),入力!$J$10),入力!$J$10))) | K7: =IF(F7="","",ROUNDDOWN(INDEX(入力!$H$13:$H$20,MATCH(F7,入力!$B$13:$B$20,1))/H7+INDEX(入力!$I$13:$I$20,MATCH(F7,入力!$B$13:$B$20,1))/22,0)) | L7: =IF(F7="","",IF(J7>K7,"〇","×")) | M7: =IF(F7="","",J7*I7) | N7: =IF(F7="","",MIN(J7,K7)*I7) | O7: =IF(F7="","",M7-N7) | P7: =IF(F7="","",IFERROR(INDEX(入力!$G$37:$G$78,MATCH(B7,入力!$A$37:$A$78,0)),"")) | Q7: =IF(F7="","",IF(COUNTIFS($B$6:B7,B7,$C$6:C7,C7,$E$6:E7,E7)=1,MAX($Q$5:Q6)+1,"")) | R7: =IF(G7="","",IF(COUNTIFS(入力!$B$86:$B$95,"<="&(G7+1),入力!$C$86:$C$95,">="&(G7+1))>0,SUMIFS(入力!$C$86:$C$95,入力!$B$86:$B$95,"<="&(G7+1),入力!$C$86:$C$95,">="&(G7+1))+1,G7+1)) | S7: =IF(R7="","",IF(COUNTIFS(入力!$B$86:$B$95,"<="&(R7),入力!$C$86:$C$95,">="&(R7))>0,SUMIFS(入力!$C$86:$C$95,入力!$B$86:$B$95,"<="&(R7),入力!$C$86:$C$95,">="&(R7))+1,R7)) | U7: =IF(OR(X6="",X6>入力!$J$4+3650),"",X6) | V7: =IF(U7="","",MIN(EOMONTH(U7,0),IF(AND(入力!$B$13<>"",入力!$B$13>U7),入力!$B$13-1,999999),IF(AND(入力!$B$14<>"",入力!$B$14>U7),入力!$B$14-1,999999),IF(AND(入力!$B$15<>"",入力!$B$15>U7),入力!$B$15-1,999999),IF(AND(入力!$B$16<>"",入力!$B$16>U7),入力!$B$16-1,999999),IF(AND(入力!$B$17<>"",入力!$B$17>U7),入力!$B$17-1,999999),IF(AND(入力!$B$18<>"",入力!$B$18>U7),入力!$B$18-1,999999),IF(AND(入力!$B$19<>"",入力!$B$19>U7),入力!$B$19-1,999999),IF(AND(入力!$B$20<>"",入力!$B$20>U7),入力!$B$20-1,999999),IFERROR(SMALL(入力!$B$86:$B$95,COUNTIF(入力!$B$86:$B$95,"<="&U7)+1)-1,999999))) | W7: =IF(V7="","",IF(COUNTIFS(入力!$B$86:$B$95,"<="&(V7+1),入力!$C$86:$C$95,">="&(V7+1))>0,SUMIFS(入力!$C$86:$C$95,入力!$B$86:$B$95,"<="&(V7+1),入力!$C$86:$C$95,">="&(V7+1))+1,V7+1)) | X7: =IF(W7="","",IF(COUNTIFS(入力!$B$86:$B$95,"<="&(W7),入力!$C$86:$C$95,">="&(W7))>0,SUMIFS(入力!$C$86:$C$95,入力!$B$86:$B$95,"<="&(W7),入力!$C$86:$C$95,">="&(W7))+1,W7)) | Y7: =IF(U7="","",IFERROR(VLOOKUP(DATE(YEAR(U7),MONTH(U7),1),カレンダーマスタ!$A$2:$B$301,2,0),NETWORKDAYS(DATE(YEAR(U7),MONTH(U7),1),EOMONTH(U7,0)))) | Z7: =IF(U7="","",IF(入力!$C$8<>"",入力!$C$8,IFERROR(INDEX(入力!$G$37:$G$78,MATCH(DATE(YEAR(U7),MONTH(U7),1),入力!$A$37:$A$78,0)),0))) | AA7: =IF(U7="","",ROUNDDOWN(INDEX(入力!$H$13:$H$20,MATCH(U7,入力!$B$13:$B$20,1))/Y7+INDEX(入力!$I$13:$I$20,MATCH(U7,入力!$B$13:$B$20,1))/22,0)) | AB7: =IF(U7="",0,IF(AND(Z7>AA7,NETWORKDAYS(U7,V7)>0),1,0))
A8: =IF(F8="","",3) | B8: =IF(F8="","",DATE(YEAR(F8),MONTH(F8),1)) | C8: =IF(F8="","",MONTH(F8)) | D8: =IF(F8="","",INDEX(入力!$A$13:$A$20,MATCH(F8,入力!$B$13:$B$20,1))) | E8: =IF(F8="","",IF(G8<=入力!$J$6,"法定","附加")) | F8: =IF(G7="","",IF(G7>=入力!$J$9,"",IF(S7>入力!$J$9,"",S7))) | G8: =IF(F8="","",MIN(EOMONTH(F8,0),入力!$J$9,IF(AND(入力!$B$13<>"",入力!$B$13>F8),入力!$B$13-1,999999),IF(AND(入力!$B$14<>"",入力!$B$14>F8),入力!$B$14-1,999999),IF(AND(入力!$B$15<>"",入力!$B$15>F8),入力!$B$15-1,999999),IF(AND(入力!$B$16<>"",入力!$B$16>F8),入力!$B$16-1,999999),IF(AND(入力!$B$17<>"",入力!$B$17>F8),入力!$B$17-1,999999),IF(AND(入力!$B$18<>"",入力!$B$18>F8),入力!$B$18-1,999999),IF(AND(入力!$B$19<>"",入力!$B$19>F8),入力!$B$19-1,999999),IF(AND(入力!$B$20<>"",入力!$B$20>F8),入力!$B$20-1,999999),IF(AND(入力!$J$7<>"",入力!$J$7>F8),入力!$J$7-1,999999),IFERROR(SMALL(入力!$B$86:$B$95,COUNTIF(入力!$B$86:$B$95,"<="&F8)+1)-1,999999))) | H8: =IF(F8="","",IFERROR(VLOOKUP(B8,カレンダーマスタ!$A$2:$B$301,2,0),NETWORKDAYS(B8,EOMONTH(F8,0)))) | I8: =IF(F8="","",NETWORKDAYS(F8,G8)) | J8: =IF(F8="","",IF(入力!$C$8<>"",入力!$C$8,IF(F8<入力!$J$5,IFERROR(INDEX(入力!$G$37:$G$78,MATCH(B8,入力!$A$37:$A$78,0)),入力!$J$10),入力!$J$10))) | K8: =IF(F8="","",ROUNDDOWN(INDEX(入力!$H$13:$H$20,MATCH(F8,入力!$B$13:$B$20,1))/H8+INDEX(入力!$I$13:$I$20,MATCH(F8,入力!$B$13:$B$20,1))/22,0)) | L8: =IF(F8="","",IF(J8>K8,"〇","×")) | M8: =IF(F8="","",J8*I8) | N8: =IF(F8="","",MIN(J8,K8)*I8) | O8: =IF(F8="","",M8-N8) | P8: =IF(F8="","",IFERROR(INDEX(入力!$G$37:$G$78,MATCH(B8,入力!$A$37:$A$78,0)),"")) | Q8: =IF(F8="","",IF(COUNTIFS($B$6:B8,B8,$C$6:C8,C8,$E$6:E8,E8)=1,MAX($Q$5:Q7)+1,"")) | R8: =IF(G8="","",IF(COUNTIFS(入力!$B$86:$B$95,"<="&(G8+1),入力!$C$86:$C$95,">="&(G8+1))>0,SUMIFS(入力!$C$86:$C$95,入力!$B$86:$B$95,"<="&(G8+1),入力!$C$86:$C$95,">="&(G8+1))+1,G8+1)) | S8: =IF(R8="","",IF(COUNTIFS(入力!$B$86:$B$95,"<="&(R8),入力!$C$86:$C$95,">="&(R8))>0,SUMIFS(入力!$C$86:$C$95,入力!$B$86:$B$95,"<="&(R8),入力!$C$86:$C$95,">="&(R8))+1,R8)) | U8: =IF(OR(X7="",X7>入力!$J$4+3650),"",X7) | V8: =IF(U8="","",MIN(EOMONTH(U8,0),IF(AND(入力!$B$13<>"",入力!$B$13>U8),入力!$B$13-1,999999),IF(AND(入力!$B$14<>"",入力!$B$14>U8),入力!$B$14-1,999999),IF(AND(入力!$B$15<>"",入力!$B$15>U8),入力!$B$15-1,999999),IF(AND(入力!$B$16<>"",入力!$B$16>U8),入力!$B$16-1,999999),IF(AND(入力!$B$17<>"",入力!$B$17>U8),入力!$B$17-1,999999),IF(AND(入力!$B$18<>"",入力!$B$18>U8),入力!$B$18-1,999999),IF(AND(入力!$B$19<>"",入力!$B$19>U8),入力!$B$19-1,999999),IF(AND(入力!$B$20<>"",入力!$B$20>U8),入力!$B$20-1,999999),IFERROR(SMALL(入力!$B$86:$B$95,COUNTIF(入力!$B$86:$B$95,"<="&U8)+1)-1,999999))) | W8: =IF(V8="","",IF(COUNTIFS(入力!$B$86:$B$95,"<="&(V8+1),入力!$C$86:$C$95,">="&(V8+1))>0,SUMIFS(入力!$C$86:$C$95,入力!$B$86:$B$95,"<="&(V8+1),入力!$C$86:$C$95,">="&(V8+1))+1,V8+1)) | X8: =IF(W8="","",IF(COUNTIFS(入力!$B$86:$B$95,"<="&(W8),入力!$C$86:$C$95,">="&(W8))>0,SUMIFS(入力!$C$86:$C$95,入力!$B$86:$B$95,"<="&(W8),入力!$C$86:$C$95,">="&(W8))+1,W8)) | Y8: =IF(U8="","",IFERROR(VLOOKUP(DATE(YEAR(U8),MONTH(U8),1),カレンダーマスタ!$A$2:$B$301,2,0),NETWORKDAYS(DATE(YEAR(U8),MONTH(U8),1),EOMONTH(U8,0)))) | Z8: =IF(U8="","",IF(入力!$C$8<>"",入力!$C$8,IFERROR(INDEX(入力!$G$37:$G$78,MATCH(DATE(YEAR(U8),MONTH(U8),1),入力!$A$37:$A$78,0)),0))) | AA8: =IF(U8="","",ROUNDDOWN(INDEX(入力!$H$13:$H$20,MATCH(U8,入力!$B$13:$B$20,1))/Y8+INDEX(入力!$I$13:$I$20,MATCH(U8,入力!$B$13:$B$20,1))/22,0)) | AB8: =IF(U8="",0,IF(AND(Z8>AA8,NETWORKDAYS(U8,V8)>0),1,0))
A9: =IF(F9="","",4) | B9: =IF(F9="","",DATE(YEAR(F9),MONTH(F9),1)) | C9: =IF(F9="","",MONTH(F9)) | D9: =IF(F9="","",INDEX(入力!$A$13:$A$20,MATCH(F9,入力!$B$13:$B$20,1))) | E9: =IF(F9="","",IF(G9<=入力!$J$6,"法定","附加")) | F9: =IF(G8="","",IF(G8>=入力!$J$9,"",IF(S8>入力!$J$9,"",S8))) | G9: =IF(F9="","",MIN(EOMONTH(F9,0),入力!$J$9,IF(AND(入力!$B$13<>"",入力!$B$13>F9),入力!$B$13-1,999999),IF(AND(入力!$B$14<>"",入力!$B$14>F9),入力!$B$14-1,999999),IF(AND(入力!$B$15<>"",入力!$B$15>F9),入力!$B$15-1,999999),IF(AND(入力!$B$16<>"",入力!$B$16>F9),入力!$B$16-1,999999),IF(AND(入力!$B$17<>"",入力!$B$17>F9),入力!$B$17-1,999999),IF(AND(入力!$B$18<>"",入力!$B$18>F9),入力!$B$18-1,999999),IF(AND(入力!$B$19<>"",入力!$B$19>F9),入力!$B$19-1,999999),IF(AND(入力!$B$20<>"",入力!$B$20>F9),入力!$B$20-1,999999),IF(AND(入力!$J$7<>"",入力!$J$7>F9),入力!$J$7-1,999999),IFERROR(SMALL(入力!$B$86:$B$95,COUNTIF(入力!$B$86:$B$95,"<="&F9)+1)-1,999999))) | H9: =IF(F9="","",IFERROR(VLOOKUP(B9,カレンダーマスタ!$A$2:$B$301,2,0),NETWORKDAYS(B9,EOMONTH(F9,0)))) | I9: =IF(F9="","",NETWORKDAYS(F9,G9)) | J9: =IF(F9="","",IF(入力!$C$8<>"",入力!$C$8,IF(F9<入力!$J$5,IFERROR(INDEX(入力!$G$37:$G$78,MATCH(B9,入力!$A$37:$A$78,0)),入力!$J$10),入力!$J$10))) | K9: =IF(F9="","",ROUNDDOWN(INDEX(入力!$H$13:$H$20,MATCH(F9,入力!$B$13:$B$20,1))/H9+INDEX(入力!$I$13:$I$20,MATCH(F9,入力!$B$13:$B$20,1))/22,0)) | L9: =IF(F9="","",IF(J9>K9,"〇","×")) | M9: =IF(F9="","",J9*I9) | N9: =IF(F9="","",MIN(J9,K9)*I9) | O9: =IF(F9="","",M9-N9) | P9: =IF(F9="","",IFERROR(INDEX(入力!$G$37:$G$78,MATCH(B9,入力!$A$37:$A$78,0)),"")) | Q9: =IF(F9="","",IF(COUNTIFS($B$6:B9,B9,$C$6:C9,C9,$E$6:E9,E9)=1,MAX($Q$5:Q8)+1,"")) | R9: =IF(G9="","",IF(COUNTIFS(入力!$B$86:$B$95,"<="&(G9+1),入力!$C$86:$C$95,">="&(G9+1))>0,SUMIFS(入力!$C$86:$C$95,入力!$B$86:$B$95,"<="&(G9+1),入力!$C$86:$C$95,">="&(G9+1))+1,G9+1)) | S9: =IF(R9="","",IF(COUNTIFS(入力!$B$86:$B$95,"<="&(R9),入力!$C$86:$C$95,">="&(R9))>0,SUMIFS(入力!$C$86:$C$95,入力!$B$86:$B$95,"<="&(R9),入力!$C$86:$C$95,">="&(R9))+1,R9)) | U9: =IF(OR(X8="",X8>入力!$J$4+3650),"",X8) | V9: =IF(U9="","",MIN(EOMONTH(U9,0),IF(AND(入力!$B$13<>"",入力!$B$13>U9),入力!$B$13-1,999999),IF(AND(入力!$B$14<>"",入力!$B$14>U9),入力!$B$14-1,999999),IF(AND(入力!$B$15<>"",入力!$B$15>U9),入力!$B$15-1,999999),IF(AND(入力!$B$16<>"",入力!$B$16>U9),入力!$B$16-1,999999),IF(AND(入力!$B$17<>"",入力!$B$17>U9),入力!$B$17-1,999999),IF(AND(入力!$B$18<>"",入力!$B$18>U9),入力!$B$18-1,999999),IF(AND(入力!$B$19<>"",入力!$B$19>U9),入力!$B$19-1,999999),IF(AND(入力!$B$20<>"",入力!$B$20>U9),入力!$B$20-1,999999),IFERROR(SMALL(入力!$B$86:$B$95,COUNTIF(入力!$B$86:$B$95,"<="&U9)+1)-1,999999))) | W9: =IF(V9="","",IF(COUNTIFS(入力!$B$86:$B$95,"<="&(V9+1),入力!$C$86:$C$95,">="&(V9+1))>0,SUMIFS(入力!$C$86:$C$95,入力!$B$86:$B$95,"<="&(V9+1),入力!$C$86:$C$95,">="&(V9+1))+1,V9+1)) | X9: =IF(W9="","",IF(COUNTIFS(入力!$B$86:$B$95,"<="&(W9),入力!$C$86:$C$95,">="&(W9))>0,SUMIFS(入力!$C$86:$C$95,入力!$B$86:$B$95,"<="&(W9),入力!$C$86:$C$95,">="&(W9))+1,W9)) | Y9: =IF(U9="","",IFERROR(VLOOKUP(DATE(YEAR(U9),MONTH(U9),1),カレンダーマスタ!$A$2:$B$301,2,0),NETWORKDAYS(DATE(YEAR(U9),MONTH(U9),1),EOMONTH(U9,0)))) | Z9: =IF(U9="","",IF(入力!$C$8<>"",入力!$C$8,IFERROR(INDEX(入力!$G$37:$G$78,MATCH(DATE(YEAR(U9),MONTH(U9),1),入力!$A$37:$A$78,0)),0))) | AA9: =IF(U9="","",ROUNDDOWN(INDEX(入力!$H$13:$H$20,MATCH(U9,入力!$B$13:$B$20,1))/Y9+INDEX(入力!$I$13:$I$20,MATCH(U9,入力!$B$13:$B$20,1))/22,0)) | AB9: =IF(U9="",0,IF(AND(Z9>AA9,NETWORKDAYS(U9,V9)>0),1,0))
A10: =IF(F10="","",5) | B10: =IF(F10="","",DATE(YEAR(F10),MONTH(F10),1)) | C10: =IF(F10="","",MONTH(F10)) | D10: =IF(F10="","",INDEX(入力!$A$13:$A$20,MATCH(F10,入力!$B$13:$B$20,1))) | E10: =IF(F10="","",IF(G10<=入力!$J$6,"法定","附加")) | F10: =IF(G9="","",IF(G9>=入力!$J$9,"",IF(S9>入力!$J$9,"",S9))) | G10: =IF(F10="","",MIN(EOMONTH(F10,0),入力!$J$9,IF(AND(入力!$B$13<>"",入力!$B$13>F10),入力!$B$13-1,999999),IF(AND(入力!$B$14<>"",入力!$B$14>F10),入力!$B$14-1,999999),IF(AND(入力!$B$15<>"",入力!$B$15>F10),入力!$B$15-1,999999),IF(AND(入力!$B$16<>"",入力!$B$16>F10),入力!$B$16-1,999999),IF(AND(入力!$B$17<>"",入力!$B$17>F10),入力!$B$17-1,999999),IF(AND(入力!$B$18<>"",入力!$B$18>F10),入力!$B$18-1,999999),IF(AND(入力!$B$19<>"",入力!$B$19>F10),入力!$B$19-1,999999),IF(AND(入力!$B$20<>"",入力!$B$20>F10),入力!$B$20-1,999999),IF(AND(入力!$J$7<>"",入力!$J$7>F10),入力!$J$7-1,999999),IFERROR(SMALL(入力!$B$86:$B$95,COUNTIF(入力!$B$86:$B$95,"<="&F10)+1)-1,999999))) | H10: =IF(F10="","",IFERROR(VLOOKUP(B10,カレンダーマスタ!$A$2:$B$301,2,0),NETWORKDAYS(B10,EOMONTH(F10,0)))) | I10: =IF(F10="","",NETWORKDAYS(F10,G10)) | J10: =IF(F10="","",IF(入力!$C$8<>"",入力!$C$8,IF(F10<入力!$J$5,IFERROR(INDEX(入力!$G$37:$G$78,MATCH(B10,入力!$A$37:$A$78,0)),入力!$J$10),入力!$J$10))) | K10: =IF(F10="","",ROUNDDOWN(INDEX(入力!$H$13:$H$20,MATCH(F10,入力!$B$13:$B$20,1))/H10+INDEX(入力!$I$13:$I$20,MATCH(F10,入力!$B$13:$B$20,1))/22,0)) | L10: =IF(F10="","",IF(J10>K10,"〇","×")) | M10: =IF(F10="","",J10*I10) | N10: =IF(F10="","",MIN(J10,K10)*I10) | O10: =IF(F10="","",M10-N10) | P10: =IF(F10="","",IFERROR(INDEX(入力!$G$37:$G$78,MATCH(B10,入力!$A$37:$A$78,0)),"")) | Q10: =IF(F10="","",IF(COUNTIFS($B$6:B10,B10,$C$6:C10,C10,$E$6:E10,E10)=1,MAX($Q$5:Q9)+1,"")) | R10: =IF(G10="","",IF(COUNTIFS(入力!$B$86:$B$95,"<="&(G10+1),入力!$C$86:$C$95,">="&(G10+1))>0,SUMIFS(入力!$C$86:$C$95,入力!$B$86:$B$95,"<="&(G10+1),入力!$C$86:$C$95,">="&(G10+1))+1,G10+1)) | S10: =IF(R10="","",IF(COUNTIFS(入力!$B$86:$B$95,"<="&(R10),入力!$C$86:$C$95,">="&(R10))>0,SUMIFS(入力!$C$86:$C$95,入力!$B$86:$B$95,"<="&(R10),入力!$C$86:$C$95,">="&(R10))+1,R10)) | U10: =IF(OR(X9="",X9>入力!$J$4+3650),"",X9) | V10: =IF(U10="","",MIN(EOMONTH(U10,0),IF(AND(入力!$B$13<>"",入力!$B$13>U10),入力!$B$13-1,999999),IF(AND(入力!$B$14<>"",入力!$B$14>U10),入力!$B$14-1,999999),IF(AND(入力!$B$15<>"",入力!$B$15>U10),入力!$B$15-1,999999),IF(AND(入力!$B$16<>"",入力!$B$16>U10),入力!$B$16-1,999999),IF(AND(入力!$B$17<>"",入力!$B$17>U10),入力!$B$17-1,999999),IF(AND(入力!$B$18<>"",入力!$B$18>U10),入力!$B$18-1,999999),IF(AND(入力!$B$19<>"",入力!$B$19>U10),入力!$B$19-1,999999),IF(AND(入力!$B$20<>"",入力!$B$20>U10),入力!$B$20-1,999999),IFERROR(SMALL(入力!$B$86:$B$95,COUNTIF(入力!$B$86:$B$95,"<="&U10)+1)-1,999999))) | W10: =IF(V10="","",IF(COUNTIFS(入力!$B$86:$B$95,"<="&(V10+1),入力!$C$86:$C$95,">="&(V10+1))>0,SUMIFS(入力!$C$86:$C$95,入力!$B$86:$B$95,"<="&(V10+1),入力!$C$86:$C$95,">="&(V10+1))+1,V10+1)) | X10: =IF(W10="","",IF(COUNTIFS(入力!$B$86:$B$95,"<="&(W10),入力!$C$86:$C$95,">="&(W10))>0,SUMIFS(入力!$C$86:$C$95,入力!$B$86:$B$95,"<="&(W10),入力!$C$86:$C$95,">="&(W10))+1,W10)) | Y10: =IF(U10="","",IFERROR(VLOOKUP(DATE(YEAR(U10),MONTH(U10),1),カレンダーマスタ!$A$2:$B$301,2,0),NETWORKDAYS(DATE(YEAR(U10),MONTH(U10),1),EOMONTH(U10,0)))) | Z10: =IF(U10="","",IF(入力!$C$8<>"",入力!$C$8,IFERROR(INDEX(入力!$G$37:$G$78,MATCH(DATE(YEAR(U10),MONTH(U10),1),入力!$A$37:$A$78,0)),0))) | AA10: =IF(U10="","",ROUNDDOWN(INDEX(入力!$H$13:$H$20,MATCH(U10,入力!$B$13:$B$20,1))/Y10+INDEX(入力!$I$13:$I$20,MATCH(U10,入力!$B$13:$B$20,1))/22,0)) | AB10: =IF(U10="",0,IF(AND(Z10>AA10,NETWORKDAYS(U10,V10)>0),1,0))
A11: =IF(F11="","",6) | B11: =IF(F11="","",DATE(YEAR(F11),MONTH(F11),1)) | C11: =IF(F11="","",MONTH(F11)) | D11: =IF(F11="","",INDEX(入力!$A$13:$A$20,MATCH(F11,入力!$B$13:$B$20,1))) | E11: =IF(F11="","",IF(G11<=入力!$J$6,"法定","附加")) | F11: =IF(G10="","",IF(G10>=入力!$J$9,"",IF(S10>入力!$J$9,"",S10))) | G11: =IF(F11="","",MIN(EOMONTH(F11,0),入力!$J$9,IF(AND(入力!$B$13<>"",入力!$B$13>F11),入力!$B$13-1,999999),IF(AND(入力!$B$14<>"",入力!$B$14>F11),入力!$B$14-1,999999),IF(AND(入力!$B$15<>"",入力!$B$15>F11),入力!$B$15-1,999999),IF(AND(入力!$B$16<>"",入力!$B$16>F11),入力!$B$16-1,999999),IF(AND(入力!$B$17<>"",入力!$B$17>F11),入力!$B$17-1,999999),IF(AND(入力!$B$18<>"",入力!$B$18>F11),入力!$B$18-1,999999),IF(AND(入力!$B$19<>"",入力!$B$19>F11),入力!$B$19-1,999999),IF(AND(入力!$B$20<>"",入力!$B$20>F11),入力!$B$20-1,999999),IF(AND(入力!$J$7<>"",入力!$J$7>F11),入力!$J$7-1,999999),IFERROR(SMALL(入力!$B$86:$B$95,COUNTIF(入力!$B$86:$B$95,"<="&F11)+1)-1,999999))) | H11: =IF(F11="","",IFERROR(VLOOKUP(B11,カレンダーマスタ!$A$2:$B$301,2,0),NETWORKDAYS(B11,EOMONTH(F11,0)))) | I11: =IF(F11="","",NETWORKDAYS(F11,G11)) | J11: =IF(F11="","",IF(入力!$C$8<>"",入力!$C$8,IF(F11<入力!$J$5,IFERROR(INDEX(入力!$G$37:$G$78,MATCH(B11,入力!$A$37:$A$78,0)),入力!$J$10),入力!$J$10))) | K11: =IF(F11="","",ROUNDDOWN(INDEX(入力!$H$13:$H$20,MATCH(F11,入力!$B$13:$B$20,1))/H11+INDEX(入力!$I$13:$I$20,MATCH(F11,入力!$B$13:$B$20,1))/22,0)) | L11: =IF(F11="","",IF(J11>K11,"〇","×")) | M11: =IF(F11="","",J11*I11) | N11: =IF(F11="","",MIN(J11,K11)*I11) | O11: =IF(F11="","",M11-N11) | P11: =IF(F11="","",IFERROR(INDEX(入力!$G$37:$G$78,MATCH(B11,入力!$A$37:$A$78,0)),"")) | Q11: =IF(F11="","",IF(COUNTIFS($B$6:B11,B11,$C$6:C11,C11,$E$6:E11,E11)=1,MAX($Q$5:Q10)+1,"")) | R11: =IF(G11="","",IF(COUNTIFS(入力!$B$86:$B$95,"<="&(G11+1),入力!$C$86:$C$95,">="&(G11+1))>0,SUMIFS(入力!$C$86:$C$95,入力!$B$86:$B$95,"<="&(G11+1),入力!$C$86:$C$95,">="&(G11+1))+1,G11+1)) | S11: =IF(R11="","",IF(COUNTIFS(入力!$B$86:$B$95,"<="&(R11),入力!$C$86:$C$95,">="&(R11))>0,SUMIFS(入力!$C$86:$C$95,入力!$B$86:$B$95,"<="&(R11),入力!$C$86:$C$95,">="&(R11))+1,R11)) | U11: =IF(OR(X10="",X10>入力!$J$4+3650),"",X10) | V11: =IF(U11="","",MIN(EOMONTH(U11,0),IF(AND(入力!$B$13<>"",入力!$B$13>U11),入力!$B$13-1,999999),IF(AND(入力!$B$14<>"",入力!$B$14>U11),入力!$B$14-1,999999),IF(AND(入力!$B$15<>"",入力!$B$15>U11),入力!$B$15-1,999999),IF(AND(入力!$B$16<>"",入力!$B$16>U11),入力!$B$16-1,999999),IF(AND(入力!$B$17<>"",入力!$B$17>U11),入力!$B$17-1,999999),IF(AND(入力!$B$18<>"",入力!$B$18>U11),入力!$B$18-1,999999),IF(AND(入力!$B$19<>"",入力!$B$19>U11),入力!$B$19-1,999999),IF(AND(入力!$B$20<>"",入力!$B$20>U11),入力!$B$20-1,999999),IFERROR(SMALL(入力!$B$86:$B$95,COUNTIF(入力!$B$86:$B$95,"<="&U11)+1)-1,999999))) | W11: =IF(V11="","",IF(COUNTIFS(入力!$B$86:$B$95,"<="&(V11+1),入力!$C$86:$C$95,">="&(V11+1))>0,SUMIFS(入力!$C$86:$C$95,入力!$B$86:$B$95,"<="&(V11+1),入力!$C$86:$C$95,">="&(V11+1))+1,V11+1)) | X11: =IF(W11="","",IF(COUNTIFS(入力!$B$86:$B$95,"<="&(W11),入力!$C$86:$C$95,">="&(W11))>0,SUMIFS(入力!$C$86:$C$95,入力!$B$86:$B$95,"<="&(W11),入力!$C$86:$C$95,">="&(W11))+1,W11)) | Y11: =IF(U11="","",IFERROR(VLOOKUP(DATE(YEAR(U11),MONTH(U11),1),カレンダーマスタ!$A$2:$B$301,2,0),NETWORKDAYS(DATE(YEAR(U11),MONTH(U11),1),EOMONTH(U11,0)))) | Z11: =IF(U11="","",IF(入力!$C$8<>"",入力!$C$8,IFERROR(INDEX(入力!$G$37:$G$78,MATCH(DATE(YEAR(U11),MONTH(U11),1),入力!$A$37:$A$78,0)),0))) | AA11: =IF(U11="","",ROUNDDOWN(INDEX(入力!$H$13:$H$20,MATCH(U11,入力!$B$13:$B$20,1))/Y11+INDEX(入力!$I$13:$I$20,MATCH(U11,入力!$B$13:$B$20,1))/22,0)) | AB11: =IF(U11="",0,IF(AND(Z11>AA11,NETWORKDAYS(U11,V11)>0),1,0))
A12: =IF(F12="","",7) | B12: =IF(F12="","",DATE(YEAR(F12),MONTH(F12),1)) | C12: =IF(F12="","",MONTH(F12)) | D12: =IF(F12="","",INDEX(入力!$A$13:$A$20,MATCH(F12,入力!$B$13:$B$20,1))) | E12: =IF(F12="","",IF(G12<=入力!$J$6,"法定","附加")) | F12: =IF(G11="","",IF(G11>=入力!$J$9,"",IF(S11>入力!$J$9,"",S11))) | G12: =IF(F12="","",MIN(EOMONTH(F12,0),入力!$J$9,IF(AND(入力!$B$13<>"",入力!$B$13>F12),入力!$B$13-1,999999),IF(AND(入力!$B$14<>"",入力!$B$14>F12),入力!$B$14-1,999999),IF(AND(入力!$B$15<>"",入力!$B$15>F12),入力!$B$15-1,999999),IF(AND(入力!$B$16<>"",入力!$B$16>F12),入力!$B$16-1,999999),IF(AND(入力!$B$17<>"",入力!$B$17>F12),入力!$B$17-1,999999),IF(AND(入力!$B$18<>"",入力!$B$18>F12),入力!$B$18-1,999999),IF(AND(入力!$B$19<>"",入力!$B$19>F12),入力!$B$19-1,999999),IF(AND(入力!$B$20<>"",入力!$B$20>F12),入力!$B$20-1,999999),IF(AND(入力!$J$7<>"",入力!$J$7>F12),入力!$J$7-1,999999),IFERROR(SMALL(入力!$B$86:$B$95,COUNTIF(入力!$B$86:$B$95,"<="&F12)+1)-1,999999))) | H12: =IF(F12="","",IFERROR(VLOOKUP(B12,カレンダーマスタ!$A$2:$B$301,2,0),NETWORKDAYS(B12,EOMONTH(F12,0)))) | I12: =IF(F12="","",NETWORKDAYS(F12,G12)) | J12: =IF(F12="","",IF(入力!$C$8<>"",入力!$C$8,IF(F12<入力!$J$5,IFERROR(INDEX(入力!$G$37:$G$78,MATCH(B12,入力!$A$37:$A$78,0)),入力!$J$10),入力!$J$10))) | K12: =IF(F12="","",ROUNDDOWN(INDEX(入力!$H$13:$H$20,MATCH(F12,入力!$B$13:$B$20,1))/H12+INDEX(入力!$I$13:$I$20,MATCH(F12,入力!$B$13:$B$20,1))/22,0)) | L12: =IF(F12="","",IF(J12>K12,"〇","×")) | M12: =IF(F12="","",J12*I12) | N12: =IF(F12="","",MIN(J12,K12)*I12) | O12: =IF(F12="","",M12-N12) | P12: =IF(F12="","",IFERROR(INDEX(入力!$G$37:$G$78,MATCH(B12,入力!$A$37:$A$78,0)),"")) | Q12: =IF(F12="","",IF(COUNTIFS($B$6:B12,B12,$C$6:C12,C12,$E$6:E12,E12)=1,MAX($Q$5:Q11)+1,"")) | R12: =IF(G12="","",IF(COUNTIFS(入力!$B$86:$B$95,"<="&(G12+1),入力!$C$86:$C$95,">="&(G12+1))>0,SUMIFS(入力!$C$86:$C$95,入力!$B$86:$B$95,"<="&(G12+1),入力!$C$86:$C$95,">="&(G12+1))+1,G12+1)) | S12: =IF(R12="","",IF(COUNTIFS(入力!$B$86:$B$95,"<="&(R12),入力!$C$86:$C$95,">="&(R12))>0,SUMIFS(入力!$C$86:$C$95,入力!$B$86:$B$95,"<="&(R12),入力!$C$86:$C$95,">="&(R12))+1,R12)) | U12: =IF(OR(X11="",X11>入力!$J$4+3650),"",X11) | V12: =IF(U12="","",MIN(EOMONTH(U12,0),IF(AND(入力!$B$13<>"",入力!$B$13>U12),入力!$B$13-1,999999),IF(AND(入力!$B$14<>"",入力!$B$14>U12),入力!$B$14-1,999999),IF(AND(入力!$B$15<>"",入力!$B$15>U12),入力!$B$15-1,999999),IF(AND(入力!$B$16<>"",入力!$B$16>U12),入力!$B$16-1,999999),IF(AND(入力!$B$17<>"",入力!$B$17>U12),入力!$B$17-1,999999),IF(AND(入力!$B$18<>"",入力!$B$18>U12),入力!$B$18-1,999999),IF(AND(入力!$B$19<>"",入力!$B$19>U12),入力!$B$19-1,999999),IF(AND(入力!$B$20<>"",入力!$B$20>U12),入力!$B$20-1,999999),IFERROR(SMALL(入力!$B$86:$B$95,COUNTIF(入力!$B$86:$B$95,"<="&U12)+1)-1,999999))) | W12: =IF(V12="","",IF(COUNTIFS(入力!$B$86:$B$95,"<="&(V12+1),入力!$C$86:$C$95,">="&(V12+1))>0,SUMIFS(入力!$C$86:$C$95,入力!$B$86:$B$95,"<="&(V12+1),入力!$C$86:$C$95,">="&(V12+1))+1,V12+1)) | X12: =IF(W12="","",IF(COUNTIFS(入力!$B$86:$B$95,"<="&(W12),入力!$C$86:$C$95,">="&(W12))>0,SUMIFS(入力!$C$86:$C$95,入力!$B$86:$B$95,"<="&(W12),入力!$C$86:$C$95,">="&(W12))+1,W12)) | Y12: =IF(U12="","",IFERROR(VLOOKUP(DATE(YEAR(U12),MONTH(U12),1),カレンダーマスタ!$A$2:$B$301,2,0),NETWORKDAYS(DATE(YEAR(U12),MONTH(U12),1),EOMONTH(U12,0)))) | Z12: =IF(U12="","",IF(入力!$C$8<>"",入力!$C$8,IFERROR(INDEX(入力!$G$37:$G$78,MATCH(DATE(YEAR(U12),MONTH(U12),1),入力!$A$37:$A$78,0)),0))) | AA12: =IF(U12="","",ROUNDDOWN(INDEX(入力!$H$13:$H$20,MATCH(U12,入力!$B$13:$B$20,1))/Y12+INDEX(入力!$I$13:$I$20,MATCH(U12,入力!$B$13:$B$20,1))/22,0)) | AB12: =IF(U12="",0,IF(AND(Z12>AA12,NETWORKDAYS(U12,V12)>0),1,0))
A13: =IF(F13="","",8) | B13: =IF(F13="","",DATE(YEAR(F13),MONTH(F13),1)) | C13: =IF(F13="","",MONTH(F13)) | D13: =IF(F13="","",INDEX(入力!$A$13:$A$20,MATCH(F13,入力!$B$13:$B$20,1))) | E13: =IF(F13="","",IF(G13<=入力!$J$6,"法定","附加")) | F13: =IF(G12="","",IF(G12>=入力!$J$9,"",IF(S12>入力!$J$9,"",S12))) | G13: =IF(F13="","",MIN(EOMONTH(F13,0),入力!$J$9,IF(AND(入力!$B$13<>"",入力!$B$13>F13),入力!$B$13-1,999999),IF(AND(入力!$B$14<>"",入力!$B$14>F13),入力!$B$14-1,999999),IF(AND(入力!$B$15<>"",入力!$B$15>F13),入力!$B$15-1,999999),IF(AND(入力!$B$16<>"",入力!$B$16>F13),入力!$B$16-1,999999),IF(AND(入力!$B$17<>"",入力!$B$17>F13),入力!$B$17-1,999999),IF(AND(入力!$B$18<>"",入力!$B$18>F13),入力!$B$18-1,999999),IF(AND(入力!$B$19<>"",入力!$B$19>F13),入力!$B$19-1,999999),IF(AND(入力!$B$20<>"",入力!$B$20>F13),入力!$B$20-1,999999),IF(AND(入力!$J$7<>"",入力!$J$7>F13),入力!$J$7-1,999999),IFERROR(SMALL(入力!$B$86:$B$95,COUNTIF(入力!$B$86:$B$95,"<="&F13)+1)-1,999999))) | H13: =IF(F13="","",IFERROR(VLOOKUP(B13,カレンダーマスタ!$A$2:$B$301,2,0),NETWORKDAYS(B13,EOMONTH(F13,0)))) | I13: =IF(F13="","",NETWORKDAYS(F13,G13)) | J13: =IF(F13="","",IF(入力!$C$8<>"",入力!$C$8,IF(F13<入力!$J$5,IFERROR(INDEX(入力!$G$37:$G$78,MATCH(B13,入力!$A$37:$A$78,0)),入力!$J$10),入力!$J$10))) | K13: =IF(F13="","",ROUNDDOWN(INDEX(入力!$H$13:$H$20,MATCH(F13,入力!$B$13:$B$20,1))/H13+INDEX(入力!$I$13:$I$20,MATCH(F13,入力!$B$13:$B$20,1))/22,0)) | L13: =IF(F13="","",IF(J13>K13,"〇","×")) | M13: =IF(F13="","",J13*I13) | N13: =IF(F13="","",MIN(J13,K13)*I13) | O13: =IF(F13="","",M13-N13) | P13: =IF(F13="","",IFERROR(INDEX(入力!$G$37:$G$78,MATCH(B13,入力!$A$37:$A$78,0)),"")) | Q13: =IF(F13="","",IF(COUNTIFS($B$6:B13,B13,$C$6:C13,C13,$E$6:E13,E13)=1,MAX($Q$5:Q12)+1,"")) | R13: =IF(G13="","",IF(COUNTIFS(入力!$B$86:$B$95,"<="&(G13+1),入力!$C$86:$C$95,">="&(G13+1))>0,SUMIFS(入力!$C$86:$C$95,入力!$B$86:$B$95,"<="&(G13+1),入力!$C$86:$C$95,">="&(G13+1))+1,G13+1)) | S13: =IF(R13="","",IF(COUNTIFS(入力!$B$86:$B$95,"<="&(R13),入力!$C$86:$C$95,">="&(R13))>0,SUMIFS(入力!$C$86:$C$95,入力!$B$86:$B$95,"<="&(R13),入力!$C$86:$C$95,">="&(R13))+1,R13)) | U13: =IF(OR(X12="",X12>入力!$J$4+3650),"",X12) | V13: =IF(U13="","",MIN(EOMONTH(U13,0),IF(AND(入力!$B$13<>"",入力!$B$13>U13),入力!$B$13-1,999999),IF(AND(入力!$B$14<>"",入力!$B$14>U13),入力!$B$14-1,999999),IF(AND(入力!$B$15<>"",入力!$B$15>U13),入力!$B$15-1,999999),IF(AND(入力!$B$16<>"",入力!$B$16>U13),入力!$B$16-1,999999),IF(AND(入力!$B$17<>"",入力!$B$17>U13),入力!$B$17-1,999999),IF(AND(入力!$B$18<>"",入力!$B$18>U13),入力!$B$18-1,999999),IF(AND(入力!$B$19<>"",入力!$B$19>U13),入力!$B$19-1,999999),IF(AND(入力!$B$20<>"",入力!$B$20>U13),入力!$B$20-1,999999),IFERROR(SMALL(入力!$B$86:$B$95,COUNTIF(入力!$B$86:$B$95,"<="&U13)+1)-1,999999))) | W13: =IF(V13="","",IF(COUNTIFS(入力!$B$86:$B$95,"<="&(V13+1),入力!$C$86:$C$95,">="&(V13+1))>0,SUMIFS(入力!$C$86:$C$95,入力!$B$86:$B$95,"<="&(V13+1),入力!$C$86:$C$95,">="&(V13+1))+1,V13+1)) | X13: =IF(W13="","",IF(COUNTIFS(入力!$B$86:$B$95,"<="&(W13),入力!$C$86:$C$95,">="&(W13))>0,SUMIFS(入力!$C$86:$C$95,入力!$B$86:$B$95,"<="&(W13),入力!$C$86:$C$95,">="&(W13))+1,W13)) | Y13: =IF(U13="","",IFERROR(VLOOKUP(DATE(YEAR(U13),MONTH(U13),1),カレンダーマスタ!$A$2:$B$301,2,0),NETWORKDAYS(DATE(YEAR(U13),MONTH(U13),1),EOMONTH(U13,0)))) | Z13: =IF(U13="","",IF(入力!$C$8<>"",入力!$C$8,IFERROR(INDEX(入力!$G$37:$G$78,MATCH(DATE(YEAR(U13),MONTH(U13),1),入力!$A$37:$A$78,0)),0))) | AA13: =IF(U13="","",ROUNDDOWN(INDEX(入力!$H$13:$H$20,MATCH(U13,入力!$B$13:$B$20,1))/Y13+INDEX(入力!$I$13:$I$20,MATCH(U13,入力!$B$13:$B$20,1))/22,0)) | AB13: =IF(U13="",0,IF(AND(Z13>AA13,NETWORKDAYS(U13,V13)>0),1,0))
A14: =IF(F14="","",9) | B14: =IF(F14="","",DATE(YEAR(F14),MONTH(F14),1)) | C14: =IF(F14="","",MONTH(F14)) | D14: =IF(F14="","",INDEX(入力!$A$13:$A$20,MATCH(F14,入力!$B$13:$B$20,1))) | E14: =IF(F14="","",IF(G14<=入力!$J$6,"法定","附加")) | F14: =IF(G13="","",IF(G13>=入力!$J$9,"",IF(S13>入力!$J$9,"",S13))) | G14: =IF(F14="","",MIN(EOMONTH(F14,0),入力!$J$9,IF(AND(入力!$B$13<>"",入力!$B$13>F14),入力!$B$13-1,999999),IF(AND(入力!$B$14<>"",入力!$B$14>F14),入力!$B$14-1,999999),IF(AND(入力!$B$15<>"",入力!$B$15>F14),入力!$B$15-1,999999),IF(AND(入力!$B$16<>"",入力!$B$16>F14),入力!$B$16-1,999999),IF(AND(入力!$B$17<>"",入力!$B$17>F14),入力!$B$17-1,999999),IF(AND(入力!$B$18<>"",入力!$B$18>F14),入力!$B$18-1,999999),IF(AND(入力!$B$19<>"",入力!$B$19>F14),入力!$B$19-1,999999),IF(AND(入力!$B$20<>"",入力!$B$20>F14),入力!$B$20-1,999999),IF(AND(入力!$J$7<>"",入力!$J$7>F14),入力!$J$7-1,999999),IFERROR(SMALL(入力!$B$86:$B$95,COUNTIF(入力!$B$86:$B$95,"<="&F14)+1)-1,999999))) | H14: =IF(F14="","",IFERROR(VLOOKUP(B14,カレンダーマスタ!$A$2:$B$301,2,0),NETWORKDAYS(B14,EOMONTH(F14,0)))) | I14: =IF(F14="","",NETWORKDAYS(F14,G14)) | J14: =IF(F14="","",IF(入力!$C$8<>"",入力!$C$8,IF(F14<入力!$J$5,IFERROR(INDEX(入力!$G$37:$G$78,MATCH(B14,入力!$A$37:$A$78,0)),入力!$J$10),入力!$J$10))) | K14: =IF(F14="","",ROUNDDOWN(INDEX(入力!$H$13:$H$20,MATCH(F14,入力!$B$13:$B$20,1))/H14+INDEX(入力!$I$13:$I$20,MATCH(F14,入力!$B$13:$B$20,1))/22,0)) | L14: =IF(F14="","",IF(J14>K14,"〇","×")) | M14: =IF(F14="","",J14*I14) | N14: =IF(F14="","",MIN(J14,K14)*I14) | O14: =IF(F14="","",M14-N14) | P14: =IF(F14="","",IFERROR(INDEX(入力!$G$37:$G$78,MATCH(B14,入力!$A$37:$A$78,0)),"")) | Q14: =IF(F14="","",IF(COUNTIFS($B$6:B14,B14,$C$6:C14,C14,$E$6:E14,E14)=1,MAX($Q$5:Q13)+1,"")) | R14: =IF(G14="","",IF(COUNTIFS(入力!$B$86:$B$95,"<="&(G14+1),入力!$C$86:$C$95,">="&(G14+1))>0,SUMIFS(入力!$C$86:$C$95,入力!$B$86:$B$95,"<="&(G14+1),入力!$C$86:$C$95,">="&(G14+1))+1,G14+1)) | S14: =IF(R14="","",IF(COUNTIFS(入力!$B$86:$B$95,"<="&(R14),入力!$C$86:$C$95,">="&(R14))>0,SUMIFS(入力!$C$86:$C$95,入力!$B$86:$B$95,"<="&(R14),入力!$C$86:$C$95,">="&(R14))+1,R14)) | U14: =IF(OR(X13="",X13>入力!$J$4+3650),"",X13) | V14: =IF(U14="","",MIN(EOMONTH(U14,0),IF(AND(入力!$B$13<>"",入力!$B$13>U14),入力!$B$13-1,999999),IF(AND(入力!$B$14<>"",入力!$B$14>U14),入力!$B$14-1,999999),IF(AND(入力!$B$15<>"",入力!$B$15>U14),入力!$B$15-1,999999),IF(AND(入力!$B$16<>"",入力!$B$16>U14),入力!$B$16-1,999999),IF(AND(入力!$B$17<>"",入力!$B$17>U14),入力!$B$17-1,999999),IF(AND(入力!$B$18<>"",入力!$B$18>U14),入力!$B$18-1,999999),IF(AND(入力!$B$19<>"",入力!$B$19>U14),入力!$B$19-1,999999),IF(AND(入力!$B$20<>"",入力!$B$20>U14),入力!$B$20-1,999999),IFERROR(SMALL(入力!$B$86:$B$95,COUNTIF(入力!$B$86:$B$95,"<="&U14)+1)-1,999999))) | W14: =IF(V14="","",IF(COUNTIFS(入力!$B$86:$B$95,"<="&(V14+1),入力!$C$86:$C$95,">="&(V14+1))>0,SUMIFS(入力!$C$86:$C$95,入力!$B$86:$B$95,"<="&(V14+1),入力!$C$86:$C$95,">="&(V14+1))+1,V14+1)) | X14: =IF(W14="","",IF(COUNTIFS(入力!$B$86:$B$95,"<="&(W14),入力!$C$86:$C$95,">="&(W14))>0,SUMIFS(入力!$C$86:$C$95,入力!$B$86:$B$95,"<="&(W14),入力!$C$86:$C$95,">="&(W14))+1,W14)) | Y14: =IF(U14="","",IFERROR(VLOOKUP(DATE(YEAR(U14),MONTH(U14),1),カレンダーマスタ!$A$2:$B$301,2,0),NETWORKDAYS(DATE(YEAR(U14),MONTH(U14),1),EOMONTH(U14,0)))) | Z14: =IF(U14="","",IF(入力!$C$8<>"",入力!$C$8,IFERROR(INDEX(入力!$G$37:$G$78,MATCH(DATE(YEAR(U14),MONTH(U14),1),入力!$A$37:$A$78,0)),0))) | AA14: =IF(U14="","",ROUNDDOWN(INDEX(入力!$H$13:$H$20,MATCH(U14,入力!$B$13:$B$20,1))/Y14+INDEX(入力!$I$13:$I$20,MATCH(U14,入力!$B$13:$B$20,1))/22,0)) | AB14: =IF(U14="",0,IF(AND(Z14>AA14,NETWORKDAYS(U14,V14)>0),1,0))
A15: =IF(F15="","",10) | B15: =IF(F15="","",DATE(YEAR(F15),MONTH(F15),1)) | C15: =IF(F15="","",MONTH(F15)) | D15: =IF(F15="","",INDEX(入力!$A$13:$A$20,MATCH(F15,入力!$B$13:$B$20,1))) | E15: =IF(F15="","",IF(G15<=入力!$J$6,"法定","附加")) | F15: =IF(G14="","",IF(G14>=入力!$J$9,"",IF(S14>入力!$J$9,"",S14))) | G15: =IF(F15="","",MIN(EOMONTH(F15,0),入力!$J$9,IF(AND(入力!$B$13<>"",入力!$B$13>F15),入力!$B$13-1,999999),IF(AND(入力!$B$14<>"",入力!$B$14>F15),入力!$B$14-1,999999),IF(AND(入力!$B$15<>"",入力!$B$15>F15),入力!$B$15-1,999999),IF(AND(入力!$B$16<>"",入力!$B$16>F15),入力!$B$16-1,999999),IF(AND(入力!$B$17<>"",入力!$B$17>F15),入力!$B$17-1,999999),IF(AND(入力!$B$18<>"",入力!$B$18>F15),入力!$B$18-1,999999),IF(AND(入力!$B$19<>"",入力!$B$19>F15),入力!$B$19-1,999999),IF(AND(入力!$B$20<>"",入力!$B$20>F15),入力!$B$20-1,999999),IF(AND(入力!$J$7<>"",入力!$J$7>F15),入力!$J$7-1,999999),IFERROR(SMALL(入力!$B$86:$B$95,COUNTIF(入力!$B$86:$B$95,"<="&F15)+1)-1,999999))) | H15: =IF(F15="","",IFERROR(VLOOKUP(B15,カレンダーマスタ!$A$2:$B$301,2,0),NETWORKDAYS(B15,EOMONTH(F15,0)))) | I15: =IF(F15="","",NETWORKDAYS(F15,G15)) | J15: =IF(F15="","",IF(入力!$C$8<>"",入力!$C$8,IF(F15<入力!$J$5,IFERROR(INDEX(入力!$G$37:$G$78,MATCH(B15,入力!$A$37:$A$78,0)),入力!$J$10),入力!$J$10))) | K15: =IF(F15="","",ROUNDDOWN(INDEX(入力!$H$13:$H$20,MATCH(F15,入力!$B$13:$B$20,1))/H15+INDEX(入力!$I$13:$I$20,MATCH(F15,入力!$B$13:$B$20,1))/22,0)) | L15: =IF(F15="","",IF(J15>K15,"〇","×")) | M15: =IF(F15="","",J15*I15) | N15: =IF(F15="","",MIN(J15,K15)*I15) | O15: =IF(F15="","",M15-N15) | P15: =IF(F15="","",IFERROR(INDEX(入力!$G$37:$G$78,MATCH(B15,入力!$A$37:$A$78,0)),"")) | Q15: =IF(F15="","",IF(COUNTIFS($B$6:B15,B15,$C$6:C15,C15,$E$6:E15,E15)=1,MAX($Q$5:Q14)+1,"")) | R15: =IF(G15="","",IF(COUNTIFS(入力!$B$86:$B$95,"<="&(G15+1),入力!$C$86:$C$95,">="&(G15+1))>0,SUMIFS(入力!$C$86:$C$95,入力!$B$86:$B$95,"<="&(G15+1),入力!$C$86:$C$95,">="&(G15+1))+1,G15+1)) | S15: =IF(R15="","",IF(COUNTIFS(入力!$B$86:$B$95,"<="&(R15),入力!$C$86:$C$95,">="&(R15))>0,SUMIFS(入力!$C$86:$C$95,入力!$B$86:$B$95,"<="&(R15),入力!$C$86:$C$95,">="&(R15))+1,R15)) | U15: =IF(OR(X14="",X14>入力!$J$4+3650),"",X14) | V15: =IF(U15="","",MIN(EOMONTH(U15,0),IF(AND(入力!$B$13<>"",入力!$B$13>U15),入力!$B$13-1,999999),IF(AND(入力!$B$14<>"",入力!$B$14>U15),入力!$B$14-1,999999),IF(AND(入力!$B$15<>"",入力!$B$15>U15),入力!$B$15-1,999999),IF(AND(入力!$B$16<>"",入力!$B$16>U15),入力!$B$16-1,999999),IF(AND(入力!$B$17<>"",入力!$B$17>U15),入力!$B$17-1,999999),IF(AND(入力!$B$18<>"",入力!$B$18>U15),入力!$B$18-1,999999),IF(AND(入力!$B$19<>"",入力!$B$19>U15),入力!$B$19-1,999999),IF(AND(入力!$B$20<>"",入力!$B$20>U15),入力!$B$20-1,999999),IFERROR(SMALL(入力!$B$86:$B$95,COUNTIF(入力!$B$86:$B$95,"<="&U15)+1)-1,999999))) | W15: =IF(V15="","",IF(COUNTIFS(入力!$B$86:$B$95,"<="&(V15+1),入力!$C$86:$C$95,">="&(V15+1))>0,SUMIFS(入力!$C$86:$C$95,入力!$B$86:$B$95,"<="&(V15+1),入力!$C$86:$C$95,">="&(V15+1))+1,V15+1)) | X15: =IF(W15="","",IF(COUNTIFS(入力!$B$86:$B$95,"<="&(W15),入力!$C$86:$C$95,">="&(W15))>0,SUMIFS(入力!$C$86:$C$95,入力!$B$86:$B$95,"<="&(W15),入力!$C$86:$C$95,">="&(W15))+1,W15)) | Y15: =IF(U15="","",IFERROR(VLOOKUP(DATE(YEAR(U15),MONTH(U15),1),カレンダーマスタ!$A$2:$B$301,2,0),NETWORKDAYS(DATE(YEAR(U15),MONTH(U15),1),EOMONTH(U15,0)))) | Z15: =IF(U15="","",IF(入力!$C$8<>"",入力!$C$8,IFERROR(INDEX(入力!$G$37:$G$78,MATCH(DATE(YEAR(U15),MONTH(U15),1),入力!$A$37:$A$78,0)),0))) | AA15: =IF(U15="","",ROUNDDOWN(INDEX(入力!$H$13:$H$20,MATCH(U15,入力!$B$13:$B$20,1))/Y15+INDEX(入力!$I$13:$I$20,MATCH(U15,入力!$B$13:$B$20,1))/22,0)) | AB15: =IF(U15="",0,IF(AND(Z15>AA15,NETWORKDAYS(U15,V15)>0),1,0))
A16: =IF(F16="","",11) | B16: =IF(F16="","",DATE(YEAR(F16),MONTH(F16),1)) | C16: =IF(F16="","",MONTH(F16)) | D16: =IF(F16="","",INDEX(入力!$A$13:$A$20,MATCH(F16,入力!$B$13:$B$20,1))) | E16: =IF(F16="","",IF(G16<=入力!$J$6,"法定","附加")) | F16: =IF(G15="","",IF(G15>=入力!$J$9,"",IF(S15>入力!$J$9,"",S15))) | G16: =IF(F16="","",MIN(EOMONTH(F16,0),入力!$J$9,IF(AND(入力!$B$13<>"",入力!$B$13>F16),入力!$B$13-1,999999),IF(AND(入力!$B$14<>"",入力!$B$14>F16),入力!$B$14-1,999999),IF(AND(入力!$B$15<>"",入力!$B$15>F16),入力!$B$15-1,999999),IF(AND(入力!$B$16<>"",入力!$B$16>F16),入力!$B$16-1,999999),IF(AND(入力!$B$17<>"",入力!$B$17>F16),入力!$B$17-1,999999),IF(AND(入力!$B$18<>"",入力!$B$18>F16),入力!$B$18-1,999999),IF(AND(入力!$B$19<>"",入力!$B$19>F16),入力!$B$19-1,999999),IF(AND(入力!$B$20<>"",入力!$B$20>F16),入力!$B$20-1,999999),IF(AND(入力!$J$7<>"",入力!$J$7>F16),入力!$J$7-1,999999),IFERROR(SMALL(入力!$B$86:$B$95,COUNTIF(入力!$B$86:$B$95,"<="&F16)+1)-1,999999))) | H16: =IF(F16="","",IFERROR(VLOOKUP(B16,カレンダーマスタ!$A$2:$B$301,2,0),NETWORKDAYS(B16,EOMONTH(F16,0)))) | I16: =IF(F16="","",NETWORKDAYS(F16,G16)) | J16: =IF(F16="","",IF(入力!$C$8<>"",入力!$C$8,IF(F16<入力!$J$5,IFERROR(INDEX(入力!$G$37:$G$78,MATCH(B16,入力!$A$37:$A$78,0)),入力!$J$10),入力!$J$10))) | K16: =IF(F16="","",ROUNDDOWN(INDEX(入力!$H$13:$H$20,MATCH(F16,入力!$B$13:$B$20,1))/H16+INDEX(入力!$I$13:$I$20,MATCH(F16,入力!$B$13:$B$20,1))/22,0)) | L16: =IF(F16="","",IF(J16>K16,"〇","×")) | M16: =IF(F16="","",J16*I16) | N16: =IF(F16="","",MIN(J16,K16)*I16) | O16: =IF(F16="","",M16-N16) | P16: =IF(F16="","",IFERROR(INDEX(入力!$G$37:$G$78,MATCH(B16,入力!$A$37:$A$78,0)),"")) | Q16: =IF(F16="","",IF(COUNTIFS($B$6:B16,B16,$C$6:C16,C16,$E$6:E16,E16)=1,MAX($Q$5:Q15)+1,"")) | R16: =IF(G16="","",IF(COUNTIFS(入力!$B$86:$B$95,"<="&(G16+1),入力!$C$86:$C$95,">="&(G16+1))>0,SUMIFS(入力!$C$86:$C$95,入力!$B$86:$B$95,"<="&(G16+1),入力!$C$86:$C$95,">="&(G16+1))+1,G16+1)) | S16: =IF(R16="","",IF(COUNTIFS(入力!$B$86:$B$95,"<="&(R16),入力!$C$86:$C$95,">="&(R16))>0,SUMIFS(入力!$C$86:$C$95,入力!$B$86:$B$95,"<="&(R16),入力!$C$86:$C$95,">="&(R16))+1,R16)) | U16: =IF(OR(X15="",X15>入力!$J$4+3650),"",X15) | V16: =IF(U16="","",MIN(EOMONTH(U16,0),IF(AND(入力!$B$13<>"",入力!$B$13>U16),入力!$B$13-1,999999),IF(AND(入力!$B$14<>"",入力!$B$14>U16),入力!$B$14-1,999999),IF(AND(入力!$B$15<>"",入力!$B$15>U16),入力!$B$15-1,999999),IF(AND(入力!$B$16<>"",入力!$B$16>U16),入力!$B$16-1,999999),IF(AND(入力!$B$17<>"",入力!$B$17>U16),入力!$B$17-1,999999),IF(AND(入力!$B$18<>"",入力!$B$18>U16),入力!$B$18-1,999999),IF(AND(入力!$B$19<>"",入力!$B$19>U16),入力!$B$19-1,999999),IF(AND(入力!$B$20<>"",入力!$B$20>U16),入力!$B$20-1,999999),IFERROR(SMALL(入力!$B$86:$B$95,COUNTIF(入力!$B$86:$B$95,"<="&U16)+1)-1,999999))) | W16: =IF(V16="","",IF(COUNTIFS(入力!$B$86:$B$95,"<="&(V16+1),入力!$C$86:$C$95,">="&(V16+1))>0,SUMIFS(入力!$C$86:$C$95,入力!$B$86:$B$95,"<="&(V16+1),入力!$C$86:$C$95,">="&(V16+1))+1,V16+1)) | X16: =IF(W16="","",IF(COUNTIFS(入力!$B$86:$B$95,"<="&(W16),入力!$C$86:$C$95,">="&(W16))>0,SUMIFS(入力!$C$86:$C$95,入力!$B$86:$B$95,"<="&(W16),入力!$C$86:$C$95,">="&(W16))+1,W16)) | Y16: =IF(U16="","",IFERROR(VLOOKUP(DATE(YEAR(U16),MONTH(U16),1),カレンダーマスタ!$A$2:$B$301,2,0),NETWORKDAYS(DATE(YEAR(U16),MONTH(U16),1),EOMONTH(U16,0)))) | Z16: =IF(U16="","",IF(入力!$C$8<>"",入力!$C$8,IFERROR(INDEX(入力!$G$37:$G$78,MATCH(DATE(YEAR(U16),MONTH(U16),1),入力!$A$37:$A$78,0)),0))) | AA16: =IF(U16="","",ROUNDDOWN(INDEX(入力!$H$13:$H$20,MATCH(U16,入力!$B$13:$B$20,1))/Y16+INDEX(入力!$I$13:$I$20,MATCH(U16,入力!$B$13:$B$20,1))/22,0)) | AB16: =IF(U16="",0,IF(AND(Z16>AA16,NETWORKDAYS(U16,V16)>0),1,0))
