Workbook

Sheet 使い方
B1: 決算業務（年次決算）統合ブック 使い方
B2: 基幹システムの数字を「入力」シートに貼るだけで、決算精算表・財務諸表・附属明細表・決算書P18-19・決算総括表まで自動で反映されます。
B3: =検算!B3 -> ✔ すべてOK（22項目）
B5: ◆毎年の手順
B6: ①入力シート | C6: 「会計年度」「審査日」「氏名」「統計システム確定値」を入力。基幹システムの試算表（3月分残高）を勘定科目・借方・貸方の3列で貼り付け。
B7: ②附属明細表 | C7: 未払金・未収金・未払費用などの明細（相手先・摘要・金額）を入力。この金額が決算精算表の「修正増減」に自動で入ります。
B8: ③予算額・前年度決算額 | C8: 決算書P18・P19の「事業計画額」「前年度決算額」、総括表の前年度列は、これまでどおり手入力（前年の数字を貼り付け）です。
B9: ④検算シート | C9: 「すべてOK」になるまで差の出た項目を確認。基幹の貼り付け漏れ、明細の入力ミス、科目名の不一致を検出します。
B10: ⑤印刷・提出 | C10: 決算精算表・財務諸表・附属明細表・決算書P18-19・総括表（メモなし／メモあり）を印刷。
B11: ◆数字の流れ
B12: 入力 → 決算精算表 | C12: 3月分残高（借方C列／貸方E列）：科目名で自動照合（空白・全角空白は無視）。並び順が変わっても、科目名が同じなら取り込めます。
B13: 附属明細表 → 決算精算表 | C13: 修正増減（B列／F列）：未払金・未収金・未払費用・減価償却費の明細から。当期利益金（B38）は 収益−費用 で自動計算。
B14: 決算精算表 → 財務諸表 | C14: 貸借対照表・損益計算書の全金額を決算精算表の差引残高から引用。注記の減価償却累計額も附属明細表から自動。
B15: 決算精算表 → 附属明細表 | C15: 積立金明細・利益剰余金計算書・支出実績表（支出済額・未済額）・固定資産の当期償却額を連動。
B16: 決算精算表 → 決算書P18／P19 | C16: 収入・支出の決算額、「利益剰余金の処分」の文章（万円表記）、組合員1人当たりの額（平均組合員数で自動計算）。
B17: 決算精算表 → 総括表 | C17: 業務経理の令和○年度列（K列）に自動反映。メモあり版は、メモなし版の数字を参照するようにしたので二重入力は不要です。
B18: ◆このブックでは対象外・手作業のままの箇所
B19: 他の経理 | C19: 短期・長期・保健・貸付経理の総括表の列は、各経理の決算データがないため従来どおり手入力です。業務経理のシート群（入力〜決算書）を各経理分コピーし、総括表の該当列に同じ要領でリンクすると同様に自動化できます。
B20: セルコメント | C20: 決算書P18のコメント（「35,502,843円÷19,060人」等）や総括表の増減理由メモは文章のため自動更新されません。年度ごとに書き換えてください。
B21: 過去年度の総括シート | C21: 元の総括ファイルにあった令和元年以前の年度別シート（26枚）は容量・見やすさのためこのブックに入れていません（元ファイルに残っています）。
B22: 当期損失の場合 | C22: 当期損失金の場合も決算精算表は自動で損失側に計算します。ただし決算書P19の文章は当期利益金の例文のままなので、損失用の例文（P19下部）を使ってください。
B23: 前払費用・固定資産除却損・補助金 | C23: 財務諸表の様式に行がないため、金額が出た場合は検算シートが NG になります。様式に行を追加してリンクしてください。
B24: 入力欄の見分け方 | C24: 入力シートの黄色セル、附属明細表の明細欄、決算書の予算額・前年度決算額・定款繰入額(AJ9)が人手で入れる欄です。それ以外は数式です。

Sheet 入力
A1: 入力シート（決算データはここだけに入力・貼り付けします）
A2: 黄色のセルが入力欄です。ほかのシートの数字は、ここと「附属明細表」の明細欄から自動計算されます。
A4: ■1 基本情報
A5: 会計年度（令和○年度の数字） | B5: 7 | C5: ← 令和７年度なら 7。年度表記・決算日・総括表の見出しに反映
A6: 決算精算表の審査日（例：令和８年４月２２日） | B6: 令和８年４月２２日
A7: 出納主任（氏名） | B7: 村 井 慶 子
A8: 出納役（氏名） | B8: 榎 本 聡 子
A10: ■2 統計システム確定値（決算書P18「組合員1人当たりの額」の計算に使用）
A11: 平均組合員数（短期） | B11: 19060 | C11: 出典：P18セルコメント（統計システム確定分）
A12: 平均組合員数（長期・業務・退職等年金） | B12: 12972
A13: 短期事務費決算額（円） | B13: 35502843
A14: 連合会交付金のうち退職等年金分（円） | B14: 2202654
A16: ■3 基幹システム出力（試算表）貼り付け欄 ― 勘定科目・借方残高・貸方残高
A17: 合計 | B17: =SUM(B20:B219) -> 189744039 | C17: =SUM(C20:C219) -> 189744039
A18: ※基幹システムの3月分残高（修正前）を貼り付けます。科目の並び順は問いません。
A19: 勘定科目 | B19: 借方残高（円） | C19: 貸方残高（円） | D19: 精算表への取込判定
A20: 普通預金 | B20: 72939159 | D20: =IF(A20="","",IF(SUMPRODUCT(--(SUBSTITUTE(SUBSTITUTE(決算精算表!$D$9:$D$46," ","")," ","")=SUBSTITUTE(SUBSTITUTE(A20," ","")," ","")))=0,"× 精算表に科目なし","○")) -> ○
A21: 立替金 | B21: 192064 | D21: =IF(A21="","",IF(SUMPRODUCT(--(SUBSTITUTE(SUBSTITUTE(決算精算表!$D$9:$D$46," ","")," ","")=SUBSTITUTE(SUBSTITUTE(A21," ","")," ","")))=0,"× 精算表に科目なし","○")) -> ○
A22: 器具及び備品 | B22: 383946 | D22: =IF(A22="","",IF(SUMPRODUCT(--(SUBSTITUTE(SUBSTITUTE(決算精算表!$D$9:$D$46," ","")," ","")=SUBSTITUTE(SUBSTITUTE(A22," ","")," ","")))=0,"× 精算表に科目なし","○")) -> ○
A23: 役員報酬 | B23: 33000 | D23: =IF(A23="","",IF(SUMPRODUCT(--(SUBSTITUTE(SUBSTITUTE(決算精算表!$D$9:$D$46," ","")," ","")=SUBSTITUTE(SUBSTITUTE(A23," ","")," ","")))=0,"× 精算表に科目なし","○")) -> ○
A24: 職員給与 | B24: 10082322 | D24: =IF(A24="","",IF(SUMPRODUCT(--(SUBSTITUTE(SUBSTITUTE(決算精算表!$D$9:$D$46," ","")," ","")=SUBSTITUTE(SUBSTITUTE(A24," ","")," ","")))=0,"× 精算表に科目なし","○")) -> ○
A25: 厚生費 | B25: 9702 | D25: =IF(A25="","",IF(SUMPRODUCT(--(SUBSTITUTE(SUBSTITUTE(決算精算表!$D$9:$D$46," ","")," ","")=SUBSTITUTE(SUBSTITUTE(A25," ","")," ","")))=0,"× 精算表に科目なし","○")) -> ○
A26: 旅 費 | B26: 343112 | D26: =IF(A26="","",IF(SUMPRODUCT(--(SUBSTITUTE(SUBSTITUTE(決算精算表!$D$9:$D$46," ","")," ","")=SUBSTITUTE(SUBSTITUTE(A26," ","")," ","")))=0,"× 精算表に科目なし","○")) -> ○
A27: 事務費 | B27: 13146428 | D27: =IF(A27="","",IF(SUMPRODUCT(--(SUBSTITUTE(SUBSTITUTE(決算精算表!$D$9:$D$46," ","")," ","")=SUBSTITUTE(SUBSTITUTE(A27," ","")," ","")))=0,"× 精算表に科目なし","○")) -> ○
A28: 賃金 | B28: 4221720 | D28: =IF(A28="","",IF(SUMPRODUCT(--(SUBSTITUTE(SUBSTITUTE(決算精算表!$D$9:$D$46," ","")," ","")=SUBSTITUTE(SUBSTITUTE(A28," ","")," ","")))=0,"× 精算表に科目なし","○")) -> ○
A29: 委託費 | B29: 8507933 | D29: =IF(A29="","",IF(SUMPRODUCT(--(SUBSTITUTE(SUBSTITUTE(決算精算表!$D$9:$D$46," ","")," ","")=SUBSTITUTE(SUBSTITUTE(A29," ","")," ","")))=0,"× 精算表に科目なし","○")) -> ○
A30: 光熱水料 | B30: 57384 | D30: =IF(A30="","",IF(SUMPRODUCT(--(SUBSTITUTE(SUBSTITUTE(決算精算表!$D$9:$D$46," ","")," ","")=SUBSTITUTE(SUBSTITUTE(A30," ","")," ","")))=0,"× 精算表に科目なし","○")) -> ○
A31: 修繕費 | B31: 0 | D31: =IF(A31="","",IF(SUMPRODUCT(--(SUBSTITUTE(SUBSTITUTE(決算精算表!$D$9:$D$46," ","")," ","")=SUBSTITUTE(SUBSTITUTE(A31," ","")," ","")))=0,"× 精算表に科目なし","○")) -> ○
... A36: 事務費負担金払込金 | B36: 54153000 | D36: =IF(A36="","",IF(SUMPRODUCT(--(SUBSTITUTE(SUBSTITUTE(決算精算表!$D$9:$D$46," ","")," ","")=SUBSTITUTE(SUBSTITUTE(A36," ","")," ","")))=0,"× 精算表に科目なし","○")) -> ○
A37: 預り金 | C37: 227940 | D37: =IF(A37="","",IF(SUMPRODUCT(--(SUBSTITUTE(SUBSTITUTE(決算精算表!$D$9:$D$46," ","")," ","")=SUBSTITUTE(SUBSTITUTE(A37," ","")," ","")))=0,"× 精算表に科目なし","○")) -> ○
A38: 受入保証金 | C38: 216843 | D38: =IF(A38="","",IF(SUMPRODUCT(--(SUBSTITUTE(SUBSTITUTE(決算精算表!$D$9:$D$46," ","")," ","")=SUBSTITUTE(SUBSTITUTE(A38," ","")," ","")))=0,"× 精算表に科目なし","○")) -> ○
A39: 利益剰余金 | C39: 71093911 | D39: =IF(A39="","",IF(SUMPRODUCT(--(SUBSTITUTE(SUBSTITUTE(決算精算表!$D$9:$D$46," ","")," ","")=SUBSTITUTE(SUBSTITUTE(A39," ","")," ","")))=0,"× 精算表に科目なし","○")) -> ○
A40: 負担金 | C40: 94968000 | D40: =IF(A40="","",IF(SUMPRODUCT(--(SUBSTITUTE(SUBSTITUTE(決算精算表!$D$9:$D$46," ","")," ","")=SUBSTITUTE(SUBSTITUTE(A40," ","")," ","")))=0,"× 精算表に科目なし","○")) -> ○
A41: 雑収入 | C41: 77607 | D41: =IF(A41="","",IF(SUMPRODUCT(--(SUBSTITUTE(SUBSTITUTE(決算精算表!$D$9:$D$46," ","")," ","")=SUBSTITUTE(SUBSTITUTE(A41," ","")," ","")))=0,"× 精算表に科目なし","○")) -> ○
A42: 連合会交付金 | C42: 23159738 | D42: =IF(A42="","",IF(SUMPRODUCT(--(SUBSTITUTE(SUBSTITUTE(決算精算表!$D$9:$D$46," ","")," ","")=SUBSTITUTE(SUBSTITUTE(A42," ","")," ","")))=0,"× 精算表に科目なし","○")) -> ○
D43: =IF(A43="","",IF(SUMPRODUCT(--(SUBSTITUTE(SUBSTITUTE(決算精算表!$D$9:$D$46," ","")," ","")=SUBSTITUTE(SUBSTITUTE(A43," ","")," ","")))=0,"× 精算表に科目なし","○"))
D44: =IF(A44="","",IF(SUMPRODUCT(--(SUBSTITUTE(SUBSTITUTE(決算精算表!$D$9:$D$46," ","")," ","")=SUBSTITUTE(SUBSTITUTE(A44," ","")," ","")))=0,"× 精算表に科目なし","○"))
D45: =IF(A45="","",IF(SUMPRODUCT(--(SUBSTITUTE(SUBSTITUTE(決算精算表!$D$9:$D$46," ","")," ","")=SUBSTITUTE(SUBSTITUTE(A45," ","")," ","")))=0,"× 精算表に科目なし","○"))
D46: =IF(A46="","",IF(SUMPRODUCT(--(SUBSTITUTE(SUBSTITUTE(決算精算表!$D$9:$D$46," ","")," ","")=SUBSTITUTE(SUBSTITUTE(A46," ","")," ","")))=0,"× 精算表に科目なし","○"))
D47: =IF(A47="","",IF(SUMPRODUCT(--(SUBSTITUTE(SUBSTITUTE(決算精算表!$D$9:$D$46," ","")," ","")=SUBSTITUTE(SUBSTITUTE(A47," ","")," ","")))=0,"× 精算表に科目なし","○"))
...

Sheet 検算
A1: 検算シート（入力・転記ミスのチェック）
B3: =IF(COUNTIF(F5:F26,"NG")=0,"✔ すべてOK（22項目）","✖ NGが "&COUNTIF(F5:F26,"NG")&" 件あります。差を確認してください") -> ✔ すべてOK（22項目）
A4: No | B4: チェック内容 | C4: 値１ | D4: 値２ | E4: 差 | F4: 判定
A5: 1 | B5: 基幹取込の借方合計 ＝ 決算精算表の3月分残高（借方） ※差があれば精算表に無い科目あり | C5: =入力!B17 -> 189744039 | D5: =決算精算表!C48 -> 189744039 | E5: =C5-D5 -> 0 | F5: =IF(E5=0,"OK","NG") -> OK
A6: 2 | B6: 基幹取込の貸方合計 ＝ 決算精算表の3月分残高（貸方） | C6: =入力!C17 -> 189744039 | D6: =決算精算表!E48 -> 189744039 | E6: =C6-D6 -> 0 | F6: =IF(E6=0,"OK","NG") -> OK
A7: 3 | B7: 決算精算表 差引残高：借方合計 ＝ 貸方合計 | C7: =決算精算表!A48 -> 209902719 | D7: =決算精算表!G48 -> 209902719 | E7: =C7-D7 -> 0 | F7: =IF(E7=0,"OK","NG") -> OK
A8: 4 | B8: 貸借対照表：資産合計 ＝ 負債・純資産合計 | C8: =財務諸表!D25 -> 85175250 | D8: =財務諸表!H25 -> 85175250 | E8: =C8-D8 -> 0 | F8: =IF(E8=0,"OK","NG") -> OK
A9: 5 | B9: 損益計算書：損失側合計 ＝ 利益側合計 | C9: =財務諸表!D59 -> 124727469 | D9: =財務諸表!H59 -> 124727469 | E9: =C9-D9 -> 0 | F9: =IF(E9=0,"OK","NG") -> OK
A10: 6 | B10: 貸借対照表の資産合計 ＝ 決算精算表の資産合計（前払費用等の未反映を検出） | C10: =財務諸表!D25 -> 85175250 | D10: =決算精算表!A20 -> 85175250 | E10: =C10-D10 -> 0 | F10: =IF(E10=0,"OK","NG") -> OK
A11: 7 | B11: 損益計算書の費用 ＝ 決算精算表の費用（固定資産除却損等の未反映を検出） | C11: =財務諸表!D36+財務諸表!D53 -> 121123959 | D11: =SUM(決算精算表!A21:A37) -> 121123959 | E11: =C11-D11 -> 0 | F11: =IF(E11=0,"OK","NG") -> OK
A12: 8 | B12: 損益計算書の収益 ＝ 決算精算表の収益（補助金等の未反映を検出） | C12: =財務諸表!H36+財務諸表!H46+財務諸表!H49 -> 124727469 | D12: =SUM(決算精算表!G39:G45) -> 124727469 | E12: =C12-D12 -> 0 | F12: =IF(E12=0,"OK","NG") -> OK
A13: 9 | B13: 預金明細表の合計 ＝ 基幹の普通預金残高 | C13: =附属明細表!M6 -> 72939159 | D13: =決算精算表!A9 -> 72939159 | E13: =C13-D13 -> 0 | F13: =IF(E13=0,"OK","NG") -> OK
A14: 10 | B14: 立替金明細表の合計 ＝ 基幹の立替金残高（修正後） | C14: =附属明細表!G14 -> 194420 | D14: =決算精算表!A10 -> 194420 | E14: =C14-D14 -> 0 | F14: =IF(E14=0,"OK","NG") -> OK
A15: 11 | B15: 預り金明細表の合計 ＝ 基幹の預り金残高 | C15: =附属明細表!G62 -> 227940 | D15: =決算精算表!G16 -> 227940 | E15: =C15-D15 -> 0 | F15: =IF(E15=0,"OK","NG") -> OK
A16: 12 | B16: 受入保証金明細表の合計 ＝ 基幹の受入保証金残高 | C16: =附属明細表!G69 -> 216843 | D16: =決算精算表!G17 -> 216843 | E16: =C16-D16 -> 0 | F16: =IF(E16=0,"OK","NG") -> OK
A17: 13 | B17: 固定資産明細表の差引期末残高 ＝ 貸借対照表の器具及び備品 | C17: =附属明細表!S77 -> 207390 | D17: =財務諸表!B14 -> 207390 | E17: =C17-D17 -> 0 | F17: =IF(E17=0,"OK","NG") -> OK
A18: 14 | B18: 積立金明細表の貸借対照表計上額 ＝ 貸借対照表の積立金 | C18: =附属明細表!Q92 -> 74697421 | D18: =財務諸表!F16 -> 74697421 | E18: =C18-D18 -> 0 | F18: =IF(E18=0,"OK","NG") -> OK
A19: 15 | B19: 利益剰余金計算書の積立金（期末） ＝ 貸借対照表の積立金 | C19: =附属明細表!Q139 -> 74697421 | D19: =財務諸表!F16 -> 74697421 | E19: =C19-D19 -> 0 | F19: =IF(E19=0,"OK","NG") -> OK
A20: 16 | B20: 決算書P19 支出合計 ＝ 決算精算表の費用合計 | C20: =業務経理P19!V26 -> 121123959 | D20: =SUM(決算精算表!A21:A37) -> 121123959 | E20: =C20-D20 -> 0 | F20: =IF(E20=0,"OK","NG") -> OK
A21: 17 | B21: 決算書P18 収入合計 ＝ 決算精算表の収益合計（損益除く） | C21: =業務経理P18!V32 -> 124727469 | D21: =SUM(決算精算表!G39:G45) -> 124727469 | E21: =C21-D21 -> 0 | F21: =IF(E21=0,"OK","NG") -> OK
A22: 18 | B22: 総括表（業務経理）当期収支差額 ＝ 当期利益金−当期損失金 | C22: ='〇総括 6～7（メモなし）'!K50 -> 3603510 | D22: =決算精算表!A38-決算精算表!G46 -> 3603510 | E22: =C22-D22 -> 0 | F22: =IF(E22=0,"OK","NG") -> OK
A23: 19 | B23: 総括表（業務経理）次期繰越額 ＝ 貸借対照表の積立金 | C23: ='〇総括 6～7（メモなし）'!K51 -> 74697421 | D23: =財務諸表!F16 -> 74697421 | E23: =C23-D23 -> 0 | F23: =IF(E23=0,"OK","NG") -> OK
A24: 20 | B24: 総括表 前期繰越額（前年度シートから引継） ＝ 基幹の前期繰越積立金 | C24: ='〇総括 6～7（メモなし）'!K6 -> 71093911 | D24: =決算精算表!E19 -> 71093911 | E24: =C24-D24 -> 0 | F24: =IF(E24=0,"OK","NG") -> OK
A25: 21 | B25: 総括表メモあり版の次期繰越額 ＝ メモなし版 | C25: ='総括 6～7（メモあり）'!K51 -> 74697421 | D25: ='〇総括 6～7（メモなし）'!K51 -> 74697421 | E25: =C25-D25 -> 0 | F25: =IF(E25=0,"OK","NG") -> OK
A26: 22 | B26: 総括表メモあり版の当期収入合計 ＝ メモなし版 | C26: ='総括 6～7（メモあり）'!K28 -> 124727469 | D26: ='〇総括 6～7（メモなし）'!K28 -> 124727469 | E26: =C26-D26 -> 0 | F26: =IF(E26=0,"OK","NG") -> OK

Sheet 決算精算表
C1: 決算精算表
C3: 広島市職員共済組合業務経理決算精算表
D4: ="令和"&JIS(入力!$B$5)&"年度分" -> 令和７年度分
A6: 借 方 | D6: 勘 定 科 目 | E6: 貸 方
A7: 差引残高 | B7: 修正増減 | C7: ３月分残高 | E7: ３月分残高 | F7: 修正増減 | G7: 差引残高
A8: 円 | B8: 円 | C8: 円 | E8: 円 | F8: 円 | G8: 円
A9: =SUM(B9:C9) -> 72939159 | C9: =SUMPRODUCT(--(SUBSTITUTE(SUBSTITUTE(入力!$A$20:$A$219," ","")," ","")=SUBSTITUTE(SUBSTITUTE($D9," ","")," ","")),入力!$B$20:$B$219) -> 72939159 | D9: 普通預金
A10: =SUM(B10:C10) -> 194420 | B10: =附属明細表!G38 -> 2356 | C10: =SUMPRODUCT(--(SUBSTITUTE(SUBSTITUTE(入力!$A$20:$A$219," ","")," ","")=SUBSTITUTE(SUBSTITUTE($D10," ","")," ","")),入力!$B$20:$B$219) -> 192064 | D10: 立替金
A11: =SUM(B11:C11) -> 0 | C11: =SUMPRODUCT(--(SUBSTITUTE(SUBSTITUTE(入力!$A$20:$A$219," ","")," ","")=SUBSTITUTE(SUBSTITUTE($D11," ","")," ","")),入力!$B$20:$B$219) -> 0 | D11: 前払費用
A12: =SUM(B12:C12) -> 11834281 | B12: =附属明細表!G32 -> 11834281 | C12: =SUMPRODUCT(--(SUBSTITUTE(SUBSTITUTE(入力!$A$20:$A$219," ","")," ","")=SUBSTITUTE(SUBSTITUTE($D12," ","")," ","")),入力!$B$20:$B$219) -> 0 | D12: 未収金
A13: =SUM(B13:C13)-F13 -> 207390 | C13: =SUMPRODUCT(--(SUBSTITUTE(SUBSTITUTE(入力!$A$20:$A$219," ","")," ","")=SUBSTITUTE(SUBSTITUTE($D13," ","")," ","")),入力!$B$20:$B$219) -> 383946 | D13: 器具及び備品 | F13: =附属明細表!P77 -> 176556
D14: 未払金 | E14: =SUMPRODUCT(--(SUBSTITUTE(SUBSTITUTE(入力!$A$20:$A$219," ","")," ","")=SUBSTITUTE(SUBSTITUTE($D14," ","")," ","")),入力!$C$20:$C$219) -> 0 | F14: =附属明細表!G46 -> 9597685 | G14: =SUM(E14:F14) -> 9597685
D15: 未払費用 | E15: =SUMPRODUCT(--(SUBSTITUTE(SUBSTITUTE(入力!$A$20:$A$219," ","")," ","")=SUBSTITUTE(SUBSTITUTE($D15," ","")," ","")),入力!$C$20:$C$219) -> 0 | F15: =附属明細表!G54 -> 435361 | G15: =SUM(E15:F15) -> 435361
D16: 預り金 | E16: =SUMPRODUCT(--(SUBSTITUTE(SUBSTITUTE(入力!$A$20:$A$219," ","")," ","")=SUBSTITUTE(SUBSTITUTE($D16," ","")," ","")),入力!$C$20:$C$219) -> 227940 | G16: =SUM(E16:F16) -> 227940
D17: 受入保証金 | E17: =SUMPRODUCT(--(SUBSTITUTE(SUBSTITUTE(入力!$A$20:$A$219," ","")," ","")=SUBSTITUTE(SUBSTITUTE($D17," ","")," ","")),入力!$C$20:$C$219) -> 216843 | G17: =SUM(E17:F17) -> 216843
D18: 資本剰余金 | E18: =SUMPRODUCT(--(SUBSTITUTE(SUBSTITUTE(入力!$A$20:$A$219," ","")," ","")=SUBSTITUTE(SUBSTITUTE($D18," ","")," ","")),入力!$C$20:$C$219) -> 0
B19: =B38 -> 3603510 | D19: 利益剰余金 | E19: =SUMPRODUCT(--(SUBSTITUTE(SUBSTITUTE(入力!$A$20:$A$219," ","")," ","")=SUBSTITUTE(SUBSTITUTE($D19," ","")," ","")),入力!$C$20:$C$219) -> 71093911 | F19: =A38*2-F46 -> 7207020 | G19: =E19-B19+F19 -> 74697421
A20: =SUM(A9:A19) -> 85175250 | B20: =SUM(B9:B19) -> 15440147 | C20: =SUM(C9:C19) -> 73515169 | D20: 小 計 | E20: =SUM(E9:E19) -> 71538694 | F20: =SUM(F9:F19) -> 17416622 | G20: =SUM(G9:G19) -> 85175250
A21: =SUM(B21:C21) -> 33000 | C21: =SUMPRODUCT(--(SUBSTITUTE(SUBSTITUTE(入力!$A$20:$A$219," ","")," ","")=SUBSTITUTE(SUBSTITUTE($D21," ","")," ","")),入力!$B$20:$B$219) -> 33000 | D21: 役員報酬
A22: =SUM(B22:C22)-F22 -> 10141337 | B22: =附属明細表!G52 -> 59015 | C22: =SUMPRODUCT(--(SUBSTITUTE(SUBSTITUTE(入力!$A$20:$A$219," ","")," ","")=SUBSTITUTE(SUBSTITUTE($D22," ","")," ","")),入力!$B$20:$B$219) -> 10082322 | D22: 職員給与
A23: =SUM(B23:C23) -> 9702 | C23: =SUMPRODUCT(--(SUBSTITUTE(SUBSTITUTE(入力!$A$20:$A$219," ","")," ","")=SUBSTITUTE(SUBSTITUTE($D23," ","")," ","")),入力!$B$20:$B$219) -> 9702 | D23: 厚生費
A24: =SUM(B24:C24) -> 343112 | C24: =SUMPRODUCT(--(SUBSTITUTE(SUBSTITUTE(入力!$A$20:$A$219," ","")," ","")=SUBSTITUTE(SUBSTITUTE($D24," ","")," ","")),入力!$B$20:$B$219) -> 343112 | D24: 旅 費
A25: =SUM(B25:C25) -> 13993113 | B25: =附属明細表!G39 -> 846685 | C25: =SUMPRODUCT(--(SUBSTITUTE(SUBSTITUTE(入力!$A$20:$A$219," ","")," ","")=SUBSTITUTE(SUBSTITUTE($D25," ","")," ","")),入力!$B$20:$B$219) -> 13146428 | D25: 事務費
A26: =SUM(B26:C26) -> 4598066 | B26: =附属明細表!G53 -> 376346 | C26: =SUMPRODUCT(--(SUBSTITUTE(SUBSTITUTE(入力!$A$20:$A$219," ","")," ","")=SUBSTITUTE(SUBSTITUTE($D26," ","")," ","")),入力!$B$20:$B$219) -> 4221720 | D26: 賃金
A27: =SUM(B27:C27) -> 10084438 | B27: =附属明細表!G40 -> 1576505 | C27: =SUMPRODUCT(--(SUBSTITUTE(SUBSTITUTE(入力!$A$20:$A$219," ","")," ","")=SUBSTITUTE(SUBSTITUTE($D27," ","")," ","")),入力!$B$20:$B$219) -> 8507933 | D27: 委託費
A28: =SUM(B28:C28) -> 103921 | B28: =附属明細表!G41 -> 46537 | C28: =SUMPRODUCT(--(SUBSTITUTE(SUBSTITUTE(入力!$A$20:$A$219," ","")," ","")=SUBSTITUTE(SUBSTITUTE($D28," ","")," ","")),入力!$B$20:$B$219) -> 57384 | D28: 光熱水料
A29: =SUM(B29:C29) -> 0 | C29: =SUMPRODUCT(--(SUBSTITUTE(SUBSTITUTE(入力!$A$20:$A$219," ","")," ","")=SUBSTITUTE(SUBSTITUTE($D29," ","")," ","")),入力!$B$20:$B$219) -> 0 | D29: 修繕費
A30: =SUM(B30:C30) -> 9430768 | B30: =附属明細表!G42 -> 1020091 | C30: =SUMPRODUCT(--(SUBSTITUTE(SUBSTITUTE(入力!$A$20:$A$219," ","")," ","")=SUBSTITUTE(SUBSTITUTE($D30," ","")," ","")),入力!$B$20:$B$219) -> 8410677 | D30: 賃借料
A31: =SUM(B31:C31) -> 1884714 | B31: =附属明細表!G43 -> 689790 | C31: =SUMPRODUCT(--(SUBSTITUTE(SUBSTITUTE(入力!$A$20:$A$219," ","")," ","")=SUBSTITUTE(SUBSTITUTE($D31," ","")," ","")),入力!$B$20:$B$219) -> 1194924 | D31: 普及費
A32: =SUM(B32:C32) -> 2453880 | B32: =附属明細表!G44 -> 103564 | C32: =SUMPRODUCT(--(SUBSTITUTE(SUBSTITUTE(入力!$A$20:$A$219," ","")," ","")=SUBSTITUTE(SUBSTITUTE($D32," ","")," ","")),入力!$B$20:$B$219) -> 2350316 | D32: 負担金
A33: =SUM(B33:C33) -> 13718352 | C33: =SUMPRODUCT(--(SUBSTITUTE(SUBSTITUTE(入力!$A$20:$A$219," ","")," ","")=SUBSTITUTE(SUBSTITUTE($D33," ","")," ","")),入力!$B$20:$B$219) -> 13718352 | D33: 連合会分担金
A34: =SUM(B34:C34) -> 54153000 | C34: =SUMPRODUCT(--(SUBSTITUTE(SUBSTITUTE(入力!$A$20:$A$219," ","")," ","")=SUBSTITUTE(SUBSTITUTE($D34," ","")," ","")),入力!$B$20:$B$219) -> 54153000 | D34: 事務費負担金払込金
A35: =SUM(B35:C35) -> 176556 | B35: =附属明細表!P77 -> 176556 | C35: =SUMPRODUCT(--(SUBSTITUTE(SUBSTITUTE(入力!$A$20:$A$219," ","")," ","")=SUBSTITUTE(SUBSTITUTE($D35," ","")," ","")),入力!$B$20:$B$219) -> 0 | D35: 減価償却費
A36: =SUM(B36:C36) -> 0 | C36: =SUMPRODUCT(--(SUBSTITUTE(SUBSTITUTE(入力!$A$20:$A$219," ","")," ","")=SUBSTITUTE(SUBSTITUTE($D36," ","")," ","")),入力!$B$20:$B$219) -> 0 | D36: 固定資産除却損
A37: =SUM(B37:C37) -> 0 | B37: 0 | C37: =SUMPRODUCT(--(SUBSTITUTE(SUBSTITUTE(入力!$A$20:$A$219," ","")," ","")=SUBSTITUTE(SUBSTITUTE($D37," ","")," ","")),入力!$B$20:$B$219) -> 0 | D37: 前期損益修正損
A38: =SUM(B38:C38) -> 3603510 | B38: =MAX(SUM(G39:G45)-SUM(A21:A37),0) -> 3603510 | D38: 当期利益金
B39: =附属明細表!G45 -> 5312157 | D39: 負担金 | E39: =SUMPRODUCT(--(SUBSTITUTE(SUBSTITUTE(入力!$A$20:$A$219," ","")," ","")=SUBSTITUTE(SUBSTITUTE($D39," ","")," ","")),入力!$C$20:$C$219) -> 94968000 | G39: =SUM(E39:F39)-B39 -> 89655843
D40: 雑収入 | E40: =SUMPRODUCT(--(SUBSTITUTE(SUBSTITUTE(入力!$A$20:$A$219," ","")," ","")=SUBSTITUTE(SUBSTITUTE($D40," ","")," ","")),入力!$C$20:$C$219) -> 77607 | G40: =SUM(E40:F40) -> 77607
D41: 補助金 | E41: =SUMPRODUCT(--(SUBSTITUTE(SUBSTITUTE(入力!$A$20:$A$219," ","")," ","")=SUBSTITUTE(SUBSTITUTE($D41," ","")," ","")),入力!$C$20:$C$219) -> 0 | G41: =SUM(E41:F41) -> 0
D42: 連合会交付金 | E42: =SUMPRODUCT(--(SUBSTITUTE(SUBSTITUTE(入力!$A$20:$A$219," ","")," ","")=SUBSTITUTE(SUBSTITUTE($D42," ","")," ","")),入力!$C$20:$C$219) -> 23159738 | G42: =SUM(E42:F42) -> 23159738
...

Sheet 財務諸表
D1: 業務経理
D2: 貸借対照表
G3: ="令和"&JIS(入力!$B$5+1)&"年３月３１日現在" -> 令和８年３月３１日現在
A4: 借 方 | D4: 金 額 | E4: 貸 方 | H4: 金 額
B5: 円 | C5: 円 | D5: 円 | F5: 円 | G5: 円 | H5: 円
A6: 流 動 資 産 | D6: =SUM(C7:C9) -> 84967860 | E6: 流 動 負 債 | H6: =SUM(G7:G10) -> 10477829
A7: 普通預金 | C7: =決算精算表!A9 -> 72939159 | E7: 未払金 | G7: =決算精算表!G14 -> 9597685
A8: 立替金 | C8: =決算精算表!A10 -> 194420 | E8: 未払費用 | G8: =決算精算表!G15 -> 435361
A9: 未収金 | C9: =決算精算表!A12 -> 11834281 | E9: 預り金 | G9: =決算精算表!G16 -> 227940
E10: 受入保証金 | G10: =決算精算表!G17 -> 216843
A12: 固 定 資 産 | D12: =SUM(C13) -> 207390 | E12: 負債合計 | H12: =SUM(H2:H11) -> 10477829
A13: 有形固定資産 | C13: =SUM(B14) -> 207390
A14: 器具及び備品 | B14: =決算精算表!A13 -> 207390 | E14: 剰 余 金 | H14: =SUM(G15:G16) -> 74697421
E15: 利益剰余金 | G15: =F16+F17 -> 74697421
E16: 積 立 金 | F16: =決算精算表!G19 -> 74697421
E19: 純資産合計 | H19: =SUM(H14:H18) -> 74697421
A25: 資 産 合 計 | D25: =SUM(D6:D24) -> 85175250 | E25: 負 債 ・ 純 資 産 合 計 | H25: =H12+H19 -> 85175250
A26: 別途積立金は、地方公務員等共済組合法施行規程第86条に基づき、計上している。
A28: =" （注） 固定資産の減価償却は、地方公務員等共済組合法施行規程第73条に基づき定額法により行っており、有形固定資産の減価償"&CHAR(10)&" 却累計額は、"&TEXT(附属明細表!Q116,"#,##0")&"円である。" -> （注） 固定資産の減価償却は、地方公務員等共済組合法施行規程第73条に基づき定額法により行っており、有形固定資産の減価償 却累計額は、643,460円である。
D30: 業務経理
D31: 損益計算書
G32: ="自 令和"&JIS(入力!$B$5)&"年４月 １日" -> 自 令和７年４月 １日
G33: ="至 令和"&JIS(入力!$B$5+1)&"年３月３１日" -> 至 令和８年３月３１日
A34: 損 失 | D34: 金 額 | E34: 利 益 | H34: 金 額
B35: 円 | C35: 円 | D35: 円 | F35: 円 | G35: 円 | H35: 円
A36: 経 常 費 用 | D36: =SUM(C37) -> 121123959 | E36: 経 常 収 益 | H36: =SUM(G37:G46) -> 112893188
A37: 事 業 費 用 | C37: =SUM(B38:B52) -> 121123959 | E37: 事業収益 | G37: =SUM(F38:F40) -> 89733450
A38: 役員報酬 | B38: =決算精算表!A21 -> 33000 | E38: 負担金 | F38: =決算精算表!G39 -> 89655843
A39: 職員給与 | B39: =決算精算表!A22 -> 10141337 | E39: 雑収入 | F39: =決算精算表!G40 -> 77607
A40: 厚生費 | B40: =決算精算表!A23 -> 9702
A41: 旅 費 | B41: =決算精算表!A24 -> 343112 | E41: 補助金等収入 | G41: =SUM(F42:F43) -> 23159738
A42: 事 務 費 | B42: =決算精算表!A25 -> 13993113 | E42: 連合会交付金 | F42: =決算精算表!G42 -> 23159738
A43: 賃金 | B43: =決算精算表!A26 -> 4598066 | E43: 事業外収益 | G43: =SUM(F44) -> 0
A44: 委 託 費 | B44: =決算精算表!A27 -> 10084438 | E44: 利息及び配当金 | F44: =決算精算表!G43 -> 0
A45: 光熱水料 | B45: =決算精算表!A28 -> 103921
A46: 修繕費 | B46: =決算精算表!A29 -> 0 | E46: 繰 入 金 | H46: =G47 -> 11834281
A47: 賃 借 料 | B47: =決算精算表!A30 -> 9430768 | E47: 短期経理より繰入 | G47: =決算精算表!G44 -> 11834281
A48: 普 及 費 | B48: =決算精算表!A31 -> 1884714
A49: 負 担 金 | B49: =決算精算表!A32 -> 2453880 | E49: 特 別 利 益 | H49: =SUM(G50) -> 0
A50: 連合会分担金 | B50: =決算精算表!A33 -> 13718352 | E50: 前期損益修正益 | G50: =決算精算表!G45 -> 0
...

Sheet 附属明細表
I1: 預金明細表
A3: 取引金融機関等の名称 | G3: 区 分 | M3: 金 額 | S3: 摘 要
R4: 円
A5: 広島銀行広島市役所支店 | G5: 普 通 預 金 | M5: 72939159 | S5: №０８００４６５
A6: 合 計 | M6: =SUM(M5) -> 72939159
I8: 立替金明細表
A10: 種 別 | G10: 金 額 | M10: 氏 名 | S10: 摘 要
L11: 円
A12: 立替金 | G12: 194420 | M12: 全国市町村職員共済組合連合会 | S12: 年金過払金等返還金の払込料金（4月～3月分）
A13: 過払金等返還金 | M13: 組合員１名分 | S13: 他の経理立替分
A14: 合 計 | G14: =SUM(G12:K13) -> 194420
I16: 前払費用明細表
A18: 科 目 | D18: 摘 要 | K18: 支 払 | S18: 貸借対照表 計 上 額 | V18: 備 考
K19: 年 月 日 | N19: 伝票番号 | P19: 金 額
R20: 円 | U20: 円
A21: 賃 借 料
A22: 賃 借 料
A23: 合 計 | P23: =SUM(P21:Q22) -> 0 | S23: =SUM(S21:T22) -> 0
I25: 未収金明細表
A27: 種 別 | G27: 金 額 | M27: 氏 名 | S27: 摘 要
L28: 円
A29: 負担金 | M29: 保健経理より | S29: 事務費負担金精算返納分 （特定健康診査等負担金）
A30: 負担金 | M30: 広島市福利課 | S30: 事務費負担金の精算による追加交付
A31: 短期経理より繰入 | G31: 11834281 | M31: 短期経理より | S31: 組合事務費短期分２５％
A32: 合 計 | G32: =SUM(G29:K31) -> 11834281
I34: 未払金明細表
A36: 種 別 | G36: 金 額 | M36: 氏 名 | S36: 摘 要
L37: 円
A38: 立替金 | G38: 2356 | M38: ゆうちょ銀行 | S38: 年金過払金等返還金の払込料金立替払（10月～3月分）
A39: 事務費 | G39: 846685 | M39: (一財)広島市職員互助会 外 | S39: コピー用紙等消耗品購入代分担金等
A40: 委託費 | G40: 1576505 | M40: みずほリサーチ＆テクノロジーズ（株）外 | S40: 個別番号管理システム運営及び保守費用 外
A41: 光熱水料 | G41: 46537 | M41: 広島市総務課 | S41: 電気・ガス・水道料金等10月～3月分
A42: 賃借料 | G42: 1020091 | M42: J E C C㈱ 外 | S42: 基幹システム用機器等賃貸借料 外
A43: 普及費 | G43: 689790 | M43: (一財)広島市職員互助会 | S43: 厚生だより印刷代分担金
A44: 負担金 | G44: 103564 | M44: 厚生労働省 年金局 | S44: ３月分厚生年金保険料等
A45: 負担金 | G45: 5312157 | M45: 広島市福利課 外 | S45: 事務費負担金の精算による返還 外
A46: 合 計 | G46: =SUM(G38:K45) -> 9597685
I48: 未払費用明細表
A50: 種 別 | G50: 金 額 | M50: 氏 名 | S50: 摘 要
L51: 円
...

Sheet 業務経理P18
A1: 〔７〕 業務経理
A2: １．組合の事務に要する費用に充てるため地方公共団体が負担する金額について
B3: （短期、厚生年金保険及び経過的長期分）
B4: 組合員１人当たりの額 | AU4: （単位：円）
A5: 区 分 | Y5: ="令和"&JIS(入力!$B$5-1)&"年度" -> 令和６年度 | AJ5: ="令和"&JIS(入力!$B$5)&"年度" -> 令和７年度 | AU5: 比 較 増 △ 減
D6: 事務費 （ Ａ + B + C + D ) | Y6: 4883 | AJ6: =SUM(AJ8:AT11) -> 5114 | AU6: =AJ6-Y6 -> 231
A7: 内 訳 | D7: 地方公共団体負担金（総額） | Y7: 5508 | AJ7: =ROUND(業務経理P19!V21/入力!$B$12,0)+AJ8 -> 6038 | AU7: =AJ7-Y7 -> 530
F8: 地方公共団体負担金のうち短期分 | V8: ( A ) | Y8: 1847 | AJ8: =ROUND(入力!$B$13/入力!$B$11,0) -> 1863 | AU8: =AJ8-Y8 -> 16
D9: 短期経理より繰入 | V9: ( B ) | Y9: 1570 | AJ9: 1635 | AU9: =AJ9-Y9 -> 65
D10: 連合会交付金 | V10: ( Ｃ ) | Y10: 1466 | AJ10: =ROUND((業務経理P18!V28-入力!$B$14)/入力!$B$12,0) -> 1616 | AU10: =AJ10-Y10 -> 150
D11: その他 | V11: ( Ｄ ) | Y11: 0 | AJ11: 0 | AU11: =AJ11-Y11 -> 0
A12: (注) | C12: １ 「短期経理より繰入（Ｂ）」の欄は、定款で定める組合員１人あたりの繰入額
C13: ２ 「連合会交付金（Ｃ）」の欄は、厚生年金保険及び経過的長期給付事務費に係る連合会交付金の額を
C14: 平均組合員数で割った組合員１人当たりの額
C15: ３ 「その他(D)」の欄は、業務経理の剰余金を取り崩す場合における取崩額を平均組合員数で割った組合員1人
C16: 当たりの額
A18: １－２．退職等年金給付に係る事務費について
A19: 組合員１人当たりの額 | AY19: （単位：円） | BH19: １－２．退職等年金給付に係る事務費について
A20: 区 分 | Y20: ="令和"&JIS(入力!$B$5-1)&"年度" -> 令和６年度 | AJ20: ="令和"&JIS(入力!$B$5)&"年度" -> 令和７年度 | AU20: 比較増△減 | BH20: 組合員１人当たりの額 | BN20: （単位：円）
A21: 事務費（連合会交付金） | Y21: 151 | AJ21: =ROUND(入力!$B$14/入力!$B$12,0) -> 170 | AU21: =AJ21-Y21 -> 19 | BH21: 区 分 | BL21: 年度 | BM21: 年度 | BN21: 比較増△減
A22: (注) | D22: 表中の数値は、退職等年金給付事務費に係る連合会交付金の額を平均組合員数で割った組合員１人当たりの額 | BH22: 内訳 | BI22: 連合会交付金
A23: ２．収入について
AR24: （単位：円） | BH24: （注） | BJ24: 退職等年金給付事務費に係る連合会交付金の額を平均組合員数で割った組合員
A25: 区 分 | M25: 事 業 計 画 額 | V25: 決 算 額 | AE25: 比 較 増 △ 減 | AN25: 前 年 度 決 算 額 と の 比 較 | BJ25: １人当たりの額を記入すること。
A26: 科 目 | AN26: 前年度決算額 | AW26: 比 較 増 △ 減
B27: 負担金 | M27: 94968000 | V27: =決算精算表!G39 -> 89655843 | AE27: =V27-M27 -> -5312157 | AN27: 82167559 | AW27: =V27-AN27 -> 7488284
B28: 連合会交付金 | M28: 23147000 | V28: =決算精算表!G42 -> 23159738 | AE28: =V28-M28 -> 12738 | AN28: 20856594 | AW28: =V28-AN28 -> 2303144
B29: 利息及び配当金 | M29: 0 | V29: =決算精算表!G43 -> 0 | AE29: =V29-M29 -> 0 | AN29: 0 | AW29: =V29-AN29 -> 0
B30: 短期経理より繰入 | M30: 13605000 | V30: =決算精算表!G44 -> 11834281 | AE30: =V30-M30 -> -1770719 | AN30: 11648520 | AW30: =V30-AN30 -> 185761
B31: その他 | M31: 0 | V31: =決算精算表!G40+決算精算表!G41+決算精算表!G45 -> 77607 | AE31: =V31-M31 -> 77607 | AN31: 1275345 | AW31: =V31-AN31 -> -1197738
B32: 合 計 | M32: =SUM(M27:T31) -> 131720000 | V32: =SUM(V27:AC31) -> 124727469 | AE32: =V32-M32 -> -6992531 | AN32: =SUM(AN27:AU31) -> 115948018 | AW32: =V32-AN32 -> 8779451

Sheet 業務経理P19
A1: ３．支出について
AR2: （単位：円）
A3: 区 分 | M3: 事 業 計 画 額 | V3: 決 算 額 | AE3: 比 較 増 △ 減 | AN3: 前 年 度 決 算 額 と の 比 較
A4: 科 目 | AN4: 前年度決算額 | AW4: 比 較 増 △ 減
B5: 役員報酬 | M5: 33000 | V5: =決算精算表!A21 -> 33000 | AE5: =V5-M5 -> 0 | AN5: 33000 | AW5: =V5-AN5 -> 0
B6: 職員給与 | M6: 11428000 | V6: =決算精算表!A22 -> 10141337 | AE6: =V6-M6 -> -1286663 | AN6: 9574938 | AW6: =V6-AN6 -> 566399
B7: 厚生費 | M7: 65000 | V7: =決算精算表!A23 -> 9702 | AE7: =V7-M7 -> -55298 | AN7: 8305 | AW7: =V7-AN7 -> 1397
B8: 旅費 | M8: 1675000 | V8: =決算精算表!A24 -> 343112 | AE8: =V8-M8 -> -1331888 | AN8: 560200 | AW8: =V8-AN8 -> -217088
B9: 事務費 | M9: 17717000 | V9: =決算精算表!A25 -> 13993113 | AE9: =V9-M9 -> -3723887 | AN9: 11253363 | AW9: =V9-AN9 -> 2739750
B10: 賃金 | M10: 5351000 | V10: =決算精算表!A26 -> 4598066 | AE10: =V10-M10 -> -752934 | AN10: 4198740 | AW10: =V10-AN10 -> 399326
B11: 委託費 | M11: 11829000 | V11: =決算精算表!A27 -> 10084438 | AE11: =V11-M11 -> -1744562 | AN11: 17036296 | AW11: =V11-AN11 -> -6951858
B12: 会議費 | M12: 0 | V12: 0 | AE12: =V12-M12 -> 0 | AN12: 0 | AW12: =V12-AN12 -> 0
B13: 光熱水料 | M13: 122000 | V13: =決算精算表!A28 -> 103921 | AE13: =V13-M13 -> -18079 | AN13: 123594 | AW13: =V13-AN13 -> -19673
B14: 修繕費 | M14: 0 | V14: =決算精算表!A29 -> 0 | AE14: =V14-M14 -> 0 | AN14: 0 | AW14: =V14-AN14 -> 0
B15: 賃借料 | M15: 9589000 | V15: =決算精算表!A30 -> 9430768 | AE15: =V15-M15 -> -158232 | AN15: 7576231 | AW15: =V15-AN15 -> 1854537
B16: 普及費 | M16: 2772000 | V16: =決算精算表!A31 -> 1884714 | AE16: =V16-M16 -> -887286 | AN16: 2063463 | AW16: =V16-AN16 -> -178749
B17: 諸謝金 | M17: 0 | V17: 0 | AE17: =V17-M17 -> 0 | AN17: 0 | AW17: =V17-AN17 -> 0
B18: 食糧費 | AE18: =V18-M18 -> 0 | AW18: =V18-AN18 -> 0
B19: 負担金 | M19: 2718000 | V19: =決算精算表!A32 -> 2453880 | AE19: =V19-M19 -> -264120 | AN19: 2286386 | AW19: =V19-AN19 -> 167494
B20: 連合会分担金 | M20: 14091000 | V20: =決算精算表!A33 -> 13718352 | AE20: =V20-M20 -> -372648 | AN20: 9334157 | AW20: =V20-AN20 -> 4384195
B21: 事務費負担金払込金 | M21: 54153000 | V21: =決算精算表!A34 -> 54153000 | AE21: =V21-M21 -> 0 | AN21: 47222000 | AW21: =V21-AN21 -> 6931000
B22: 雑費 | AE22: =V22-M22 -> 0 | AW22: =V22-AN22 -> 0
B23: 減価償却費 | M23: 177000 | V23: =決算精算表!A35 -> 176556 | AE23: =V23-M23 -> -444 | AN23: 176556 | AW23: =V23-AN23 -> 0
B24: 前期損益修正損 | M24: 0 | V24: =決算精算表!A37 -> 0 | AE24: =V24-M24 -> 0 | AN24: 0 | AW24: =V24-AN24 -> 0
B25: 固定資産除却損 | M25: 0 | V25: =決算精算表!A36 -> 0 | AE25: =V25-M25 -> 0 | AN25: 1 | AW25: =V25-AN25 -> -1
B26: 合 計 | M26: =SUM(M5:T25) -> 131720000 | V26: =SUM(V5:AC25) -> 121123959 | AE26: =V26-M26 -> -10596041 | AN26: =SUM(AN5:AU25) -> 111447230 | AW26: =V26-AN26 -> 9676729
A28: ４．利益剰余金の処分について | BH28: 当期利益金バージョン
A29: =" 本年度における収支決算を行った結果、当期利益金として"&IF(決算精算表!A38>=10000,TEXT(INT(決算精算表!A38/10000),"#,##0")&"万"&IF(MOD(決算精算表!A38,10000)=0,"",TEXT(MOD(決算精算表!A38,10000),"#,##0")),TEXT(決算精算表!A38,"#,##0"))&"円"&"を生じた。" -> 本年度における収支決算を行った結果、当期利益金として360万3,510円を生じた。 | BG29: 本年度における収支決算を行った結果、当期利益金として 円を生じた。
A30: =" この利益金に前年度より繰り越した積立金"&IF(決算精算表!E19>=10000,TEXT(INT(決算精算表!E19/10000),"#,##0")&"万"&IF(MOD(決算精算表!E19,10000)=0,"",TEXT(MOD(決算精算表!E19,10000),"#,##0")),TEXT(決算精算表!E19,"#,##0"))&"円"&"を合わせ、翌年度へ繰り越す積立金は、" -> この利益金に前年度より繰り越した積立金7,109万3,911円を合わせ、翌年度へ繰り越す積立金は、 | BG30: この利益金に前年度より繰り越した積立金 円を合わせ、翌年度へ繰り越す積立金は、
C31: =IF(決算精算表!G19>=10000,TEXT(INT(決算精算表!G19/10000),"#,##0")&"万"&IF(MOD(決算精算表!G19,10000)=0,"",TEXT(MOD(決算精算表!G19,10000),"#,##0")),TEXT(決算精算表!G19,"#,##0"))&"円"&"となる。" -> 7,469万7,421円となる。 | BG31: 円となる。
A36: ５.利益剰余金の処分について
B38: 本年度における収支決算を行った結果、当期利益金として 円を生じたが、こ
B39: れを次のとおり処分した。
B40: 当期処分額 | AB40: 円
C41: ○○積立金へ積立 | AB41: 円
C42: ○○積立金へ積立 | AB42: 円
B43: したがって、前年度より繰り越した積立金 円と当期利益金 円から
B44: 当期処分額 円を差し引いた額 円を合わせ、翌年度へ繰り越す積立金
B45: は、 円となる。
B47: 本年度における収支決算を行った結果、当期損失金として 円を生じたが、前
...

Sheet 〇総括　6～7（メモなし）
C1: ="令和"&JIS(入力!$B$5)&"年度決算総括表" -> 令和７年度決算総括表
S3: （単位：円）
C4: 科目 | E4: 短期経理 | H4: 長期経理 | K4: 業務経理 | N4: 保健経理 | Q4: 貸付経理
E5: =JIS(入力!$B$5)&"年度" -> ７年度 | F5: =JIS(入力!$B$5-1)&"年度" -> ６年度 | G5: 比較増減 | H5: =E5 -> ７年度 | I5: =F5 -> ６年度 | J5: 比較増減 | K5: =E5 -> ７年度 | L5: =F5 -> ６年度 | M5: 比較増減 | N5: =E5 -> ７年度 | O5: =F5 -> ６年度 | P5: 比較増減 | Q5: =E5 -> ７年度 | R5: =F5 -> ６年度 | S5: 比較増減
C6: 前期繰越額（A） | E6: =F51 -> 2237365593 | F6: 1413185083 | G6: =E6-F6 -> 824180510 | H6: =I51 -> 115269691198 | I6: 114599779620 | J6: =H6-I6 -> 669911578 | K6: =L51 -> 71093911 | L6: 66593123 | M6: =K6-L6 -> 4500788 | N6: =O51 -> 270947604 | O6: 276235825 | P6: =N6-O6 -> -5288221 | Q6: =R51 -> 1961052168 | R6: 1966406293 | S6: =Q6-R6 -> -5354125
C7: 収入の部 | D7: 負担金 | F7: 5910008304 | G7: =E7-F7 -> -5910008304 | H7: 5874630086 | I7: 10209423196 | J7: =H7-I7 -> -4334793110 | K7: =決算精算表!G39 -> 89655843 | L7: 82167559 | M7: =K7-L7 -> 7488284 | O7: 393344415 | P7: =N7-O7 -> -393344415 | S7: =Q7-R7 -> 0
D8: 掛金 | F8: 5945270515 | G8: =E8-F8 -> -5945270515 | H8: 2964516955 | I8: 6009799333 | J8: =H8-I8 -> -3045282378 | M8: =K8-L8 -> 0 | O8: 215569947 | P8: =N8-O8 -> -215569947 | S8: =Q8-R8 -> 0
D9: 利息及び配当金 | F9: 0 | G9: =E9-F9 -> 0 | H9: 1204704253 | I9: 2333415822 | J9: =H9-I9 -> -1128711569 | K9: =決算精算表!G43 -> 0 | M9: =K9-L9 -> 0 | O9: 0 | P9: =N9-O9 -> 0 | S9: =Q9-R9 -> 0
D10: 償還差益 | G10: =E10-F10 -> 0 | H10: 3820000 | I10: 14466000 | J10: =H10-I10 -> -10646000 | M10: =K10-L10 -> 0 | P10: =N10-O10 -> 0 | S10: =Q10-R10 -> 0
D11: 育児介護休業手当金 交付金 | F11: 512653248 | G11: =E11-F11 -> -512653248 | M11: =K11-L11 -> 0 | P11: =N11-O11 -> 0 | S11: =Q11-R11 -> 0
D12: 高額医療交付金 | F12: 98548000 | G12: =E12-F12 -> -98548000
D13: 災害給付交付金 | F13: 0 | G13: =E13-F13 -> 0 | M13: =K13-L13 -> 0 | P13: =N13-O13 -> 0
D14: 賠償金 | F14: 2621295 | G14: =E14-F14 -> -2621295 | M14: =K14-L14 -> 0 | P14: =N14-O14 -> 0 | S14: =Q14-R14 -> 0
D15: 退職一時金等返還金 | G15: =E15-F15 -> 0 | H15: 5464540 | I15: 11601546 | J15: =H15-I15 -> -6137006 | M15: =K15-L15 -> 0 | P15: =N15-O15 -> 0 | S15: =Q15-R15 -> 0
D16: 出産育児交付金 | F16: 7979689 | G16: =E16-F16 -> -7979689 | H16: 289600155 | I16: 639077000 | J16: =H16-I16 -> -349476845 | M16: =K16-L16 -> 0 | P16: =N16-O16 -> 0 | S16: =Q16-R16 -> 0
D17: 施設収入 | G17: =E17-F17 -> 0 | M17: =K17-L17 -> 0 | N17: 0 | O17: 0 | P17: =N17-O17 -> 0 | S17: =Q17-R17 -> 0
D18: 雑収入他 | F18: 211390 | G18: =E18-F18 -> -211390 | K18: =決算精算表!G40 -> 77607 | L18: 69345 | M18: =K18-L18 -> 8262 | P18: =N18-O18 -> 0 | S18: =Q18-R18 -> 0
D19: 連合会交付金 | G19: =E19-F19 -> 0 | K19: =決算精算表!G42 -> 23159738 | L19: 20856594 | M19: =K19-L19 -> 2303144 | P19: =N19-O19 -> 0 | R19: 44000 | S19: =Q19-R19 -> -44000
D20: 短期経理より繰入 | G20: =E20-F20 -> 0 | K20: =決算精算表!G44 -> 11834281 | L20: 11648520 | M20: =K20-L20 -> 185761 | P20: =N20-O20 -> 0 | S20: =Q20-R20 -> 0
D21: 長期経理より繰入 | G21: =E21-F21 -> 0 | M21: =K21-L21 -> 0 | P21: =N21-O21 -> 0 | S21: =Q21-R21 -> 0
D22: 組合員貸付金利息 | G22: =E22-F22 -> 0 | M22: =K22-L22 -> 0 | P22: =N22-O22 -> 0 | R22: 12712000 | S22: =Q22-R22 -> -12712000
D23: 補助金 | F23: 0 | G23: =E23-F23 -> 0 | K23: =決算精算表!G41 -> 0 | L23: 1206000 | M23: =K23-L23 -> -1206000 | P23: =N23-O23 -> 0 | S23: =Q23-R23 -> 0
D24: 寄附金 | G24: =E24-F24 -> 0 | M24: =K24-L24 -> 0 | P24: =N24-O24 -> 0
D25: 基礎年金国庫金 | G25: =E25-F25 -> 0 | M25: =K25-L25 -> 0 | P25: =N25-O25 -> 0 | S25: =Q25-R25 -> 0
D26: 前期損益修正益 | F26: 2100931 | G26: =E26-F26 -> -2100931 | K26: =決算精算表!G45 -> 0 | M26: =K26-L26 -> 0 | N26: 0 | O26: 0 | P26: =N26-O26 -> 0 | S26: =Q26-R26 -> 0
D27: 前年度繰越支払準備金 | F27: 883951850 | G27: =E27-F27 -> -883951850 | M27: =K27-L27 -> 0 | P27: =N27-O27 -> 0 | S27: =Q27-R27 -> 0
C28: 当期収入合計 （B） | E28: =SUM(E7:E27) -> 0 | F28: =SUM(F7:F27) -> 13363345222 | G28: =SUM(G7:G27) -> -13363345222 | H28: =SUM(H7:H27) -> 10342735989 | I28: =SUM(I7:I27) -> 19217782897 | J28: =SUM(J7:J27) -> -8875046908 | K28: =SUM(K7:K27) -> 124727469 | L28: =SUM(L7:L27) -> 115948018 | ... S28: =SUM(S7:S27) -> -12756000
C29: 支出の部 | D29: 保健給付 | F29: 5062957780 | G29: =E29-F29 -> -5062957780 | M29: =K29-L29 -> 0 | P29: =N29-O29 -> 0 | S29: =Q29-R29 -> 0
D30: 休業給付 | F30: 596910377 | G30: =E30-F30 -> -596910377 | M30: =K30-L30 -> 0 | P30: =N30-O30 -> 0 | S30: =Q30-R30 -> 0
D31: 災害給付 | F31: 0 | G31: =E31-F31 -> 0 | M31: =K31-L31 -> 0 | P31: =N31-O31 -> 0 | S31: =Q31-R31 -> 0
D32: 附加給付 | F32: 36121513 | G32: =E32-F32 -> -36121513 | M32: =K32-L32 -> 0 | P32: =N32-O32 -> 0 | S32: =Q32-R32 -> 0
D33: 一部負担金払戻金 | F33: 74042318 | G33: =E33-F33 -> -74042318 | M33: =K33-L33 -> 0 | P33: =N33-O33 -> 0 | S33: =Q33-R33 -> 0
D34: 拠出金・納付金 | F34: 5748963367 | G34: =E34-F34 -> -5748963367 | M34: =K34-L34 -> 0 | P34: =N34-O34 -> 0 | S34: =Q34-R34 -> 0
D35: 任意継続掛金還付金 | G35: =E35-F35 -> 0 | M35: =K35-L35 -> 0 | P35: =N35-O35 -> 0 | S35: =Q35-R35 -> 0
D36: 退職給付 | G36: =E36-F36 -> 0 | H36: 5516016459 | I36: 10787321768 | J36: =H36-I36 -> -5271305309 | M36: =K36-L36 -> 0 | P36: =N36-O36 -> 0 | S36: =Q36-R36 -> 0
D37: 障害給付 | G37: =E37-F37 -> 0 | H37: 45220684 | I37: 87548431 | J37: =H37-I37 -> -42327747 | M37: =K37-L37 -> 0 | P37: =N37-O37 -> 0 | S37: =Q37-R37 -> 0
D38: 遺族給付 | G38: =E38-F38 -> 0 | H38: 995045755 | I38: 2016533515 | J38: =H38-I38 -> -1021487760 | M38: =K38-L38 -> 0 | P38: =N38-O38 -> 0 | S38: =Q38-R38 -> 0
D39: 基礎年金拠出金負担金 | G39: =E39-F39 -> 0 | H39: 2802837274 | I39: 5376398659 | J39: =H39-I39 -> -2573561385 | M39: =K39-L39 -> 0 | P39: =N39-O39 -> 0 | S39: =Q39-R39 -> 0
D40: 雑費 | G40: =E40-F40 -> 0 | M40: =K40-L40 -> 0 | P40: =N40-O40 -> 0 | S40: =Q40-R40 -> 0
D41: 連合会払込金 | F41: 132291047 | G41: =E41-F41 -> -132291047 | H41: 26027000 | I41: 249923000 | J41: =H41-I41 -> -223896000 | M41: =K41-L41 -> 0 | P41: =N41-O41 -> 0 | S41: =Q41-R41 -> 0
...

Sheet 総括　6～7（メモあり）
C1: ='〇総括 6～7（メモなし）'!C1 -> 令和７年度決算総括表
S3: （単位：円）
C4: 科目 | E4: 短期経理 | H4: 長期経理 | K4: 業務経理 | N4: 保健経理 | Q4: 貸付経理
E5: ='〇総括 6～7（メモなし）'!E5 -> ７年度 | F5: ='〇総括 6～7（メモなし）'!F5 -> ６年度 | G5: 比較増減 | H5: =E5 -> ７年度 | I5: =F5 -> ６年度 | J5: 比較増減 | K5: =E5 -> ７年度 | L5: =F5 -> ６年度 | M5: 比較増減 | N5: =E5 -> ７年度 | O5: =F5 -> ６年度 | P5: 比較増減 | Q5: =E5 -> ７年度 | R5: =F5 -> ６年度 | S5: 比較増減
C6: 前期繰越額（A） | E6: =F51 -> 2237365593 | F6: ='〇総括 6～7（メモなし）'!F6 -> 1413185083 | G6: =E6-F6 -> 824180510 | H6: =I51 -> 115269691198 | I6: ='〇総括 6～7（メモなし）'!I6 -> 114599779620 | J6: =H6-I6 -> 669911578 | K6: =L51 -> 71093911 | L6: ='〇総括 6～7（メモなし）'!L6 -> 66593123 | M6: =K6-L6 -> 4500788 | N6: =O51 -> 270947604 | O6: ='〇総括 6～7（メモなし）'!O6 -> 276235825 | P6: =N6-O6 -> -5288221 | Q6: =R51 -> 1961052168 | R6: ='〇総括 6～7（メモなし）'!R6 -> 1966406293 | S6: =Q6-R6 -> -5354125
C7: 収入の部 | D7: 負担金 | E7: ='〇総括 6～7（メモなし）'!E7 -> 0 | F7: ='〇総括 6～7（メモなし）'!F7 -> 5910008304 | G7: =E7-F7 -> -5910008304 | H7: ='〇総括 6～7（メモなし）'!H7 -> 5874630086 | I7: ='〇総括 6～7（メモなし）'!I7 -> 10209423196 | J7: =H7-I7 -> -4334793110 | K7: ='〇総括 6～7（メモなし）'!K7 -> 89655843 | L7: ='〇総括 6～7（メモなし）'!L7 -> 82167559 | M7: =K7-L7 -> 7488284 | N7: ='〇総括 6～7（メモなし）'!N7 -> 0 | O7: ='〇総括 6～7（メモなし）'!O7 -> 393344415 | P7: =N7-O7 -> -393344415 | Q7: ='〇総括 6～7（メモなし）'!Q7 -> 0 | R7: ='〇総括 6～7（メモなし）'!R7 -> 0 | S7: =Q7-R7 -> 0
D8: 掛金 | E8: ='〇総括 6～7（メモなし）'!E8 -> 0 | F8: ='〇総括 6～7（メモなし）'!F8 -> 5945270515 | G8: =E8-F8 -> -5945270515 | H8: ='〇総括 6～7（メモなし）'!H8 -> 2964516955 | I8: ='〇総括 6～7（メモなし）'!I8 -> 6009799333 | J8: =H8-I8 -> -3045282378 | K8: ='〇総括 6～7（メモなし）'!K8 -> 0 | L8: ='〇総括 6～7（メモなし）'!L8 -> 0 | M8: =K8-L8 -> 0 | N8: ='〇総括 6～7（メモなし）'!N8 -> 0 | O8: ='〇総括 6～7（メモなし）'!O8 -> 215569947 | P8: =N8-O8 -> -215569947 | Q8: ='〇総括 6～7（メモなし）'!Q8 -> 0 | R8: ='〇総括 6～7（メモなし）'!R8 -> 0 | S8: =Q8-R8 -> 0
D9: 利息及び配当金 | E9: ='〇総括 6～7（メモなし）'!E9 -> 0 | F9: ='〇総括 6～7（メモなし）'!F9 -> 0 | G9: =E9-F9 -> 0 | H9: ='〇総括 6～7（メモなし）'!H9 -> 1204704253 | I9: ='〇総括 6～7（メモなし）'!I9 -> 2333415822 | J9: =H9-I9 -> -1128711569 | K9: ='〇総括 6～7（メモなし）'!K9 -> 0 | L9: ='〇総括 6～7（メモなし）'!L9 -> 0 | M9: =K9-L9 -> 0 | N9: ='〇総括 6～7（メモなし）'!N9 -> 0 | O9: ='〇総括 6～7（メモなし）'!O9 -> 0 | P9: =N9-O9 -> 0 | Q9: ='〇総括 6～7（メモなし）'!Q9 -> 0 | R9: ='〇総括 6～7（メモなし）'!R9 -> 0 | S9: =Q9-R9 -> 0
D10: 償還差益 | E10: ='〇総括 6～7（メモなし）'!E10 -> 0 | F10: ='〇総括 6～7（メモなし）'!F10 -> 0 | G10: =E10-F10 -> 0 | H10: ='〇総括 6～7（メモなし）'!H10 -> 3820000 | I10: ='〇総括 6～7（メモなし）'!I10 -> 14466000 | J10: =H10-I10 -> -10646000 | K10: ='〇総括 6～7（メモなし）'!K10 -> 0 | L10: ='〇総括 6～7（メモなし）'!L10 -> 0 | M10: =K10-L10 -> 0 | N10: ='〇総括 6～7（メモなし）'!N10 -> 0 | O10: ='〇総括 6～7（メモなし）'!O10 -> 0 | P10: =N10-O10 -> 0 | Q10: ='〇総括 6～7（メモなし）'!Q10 -> 0 | R10: ='〇総括 6～7（メモなし）'!R10 -> 0 | S10: =Q10-R10 -> 0
D11: 育児介護休業手当金 交付金 | E11: ='〇総括 6～7（メモなし）'!E11 -> 0 | F11: ='〇総括 6～7（メモなし）'!F11 -> 512653248 | G11: =E11-F11 -> -512653248 | H11: ='〇総括 6～7（メモなし）'!H11 -> 0 | I11: ='〇総括 6～7（メモなし）'!I11 -> 0 | K11: ='〇総括 6～7（メモなし）'!K11 -> 0 | L11: ='〇総括 6～7（メモなし）'!L11 -> 0 | M11: =K11-L11 -> 0 | N11: ='〇総括 6～7（メモなし）'!N11 -> 0 | O11: ='〇総括 6～7（メモなし）'!O11 -> 0 | P11: =N11-O11 -> 0 | Q11: ='〇総括 6～7（メモなし）'!Q11 -> 0 | R11: ='〇総括 6～7（メモなし）'!R11 -> 0 | S11: =Q11-R11 -> 0
D12: 高額医療交付金 | E12: ='〇総括 6～7（メモなし）'!E12 -> 0 | F12: ='〇総括 6～7（メモなし）'!F12 -> 98548000 | G12: =E12-F12 -> -98548000 | H12: ='〇総括 6～7（メモなし）'!H12 -> 0 | I12: ='〇総括 6～7（メモなし）'!I12 -> 0 | K12: ='〇総括 6～7（メモなし）'!K12 -> 0 | L12: ='〇総括 6～7（メモなし）'!L12 -> 0 | M12: =K12-L12 -> 0 | N12: ='〇総括 6～7（メモなし）'!N12 -> 0 | O12: ='〇総括 6～7（メモなし）'!O12 -> 0 | P12: =N12-O12 -> 0 | Q12: ='〇総括 6～7（メモなし）'!Q12 -> 0 | R12: ='〇総括 6～7（メモなし）'!R12 -> 0 | S12: =AE11-R12 -> 0
D13: 災害給付交付金 | E13: ='〇総括 6～7（メモなし）'!E13 -> 0 | F13: ='〇総括 6～7（メモなし）'!F13 -> 0 | G13: =E13-F13 -> 0 | H13: ='〇総括 6～7（メモなし）'!H13 -> 0 | I13: ='〇総括 6～7（メモなし）'!I13 -> 0 | K13: ='〇総括 6～7（メモなし）'!K13 -> 0 | L13: ='〇総括 6～7（メモなし）'!L13 -> 0 | N13: ='〇総括 6～7（メモなし）'!N13 -> 0 | O13: ='〇総括 6～7（メモなし）'!O13 -> 0 | Q13: ='〇総括 6～7（メモなし）'!Q13 -> 0 | R13: ='〇総括 6～7（メモなし）'!R13 -> 0
D14: 賠償金 | E14: ='〇総括 6～7（メモなし）'!E14 -> 0 | F14: ='〇総括 6～7（メモなし）'!F14 -> 2621295 | G14: =E14-F14 -> -2621295 | H14: ='〇総括 6～7（メモなし）'!H14 -> 0 | I14: ='〇総括 6～7（メモなし）'!I14 -> 0 | K14: ='〇総括 6～7（メモなし）'!K14 -> 0 | L14: ='〇総括 6～7（メモなし）'!L14 -> 0 | M14: =K14-L14 -> 0 | N14: ='〇総括 6～7（メモなし）'!N14 -> 0 | O14: ='〇総括 6～7（メモなし）'!O14 -> 0 | P14: =N14-O14 -> 0 | Q14: ='〇総括 6～7（メモなし）'!Q14 -> 0 | R14: ='〇総括 6～7（メモなし）'!R14 -> 0 | S14: =Q14-R14 -> 0
D15: 退職一時金等返還金 | E15: ='〇総括 6～7（メモなし）'!E15 -> 0 | F15: ='〇総括 6～7（メモなし）'!F15 -> 0 | G15: =E15-F15 -> 0 | H15: ='〇総括 6～7（メモなし）'!H15 -> 5464540 | I15: ='〇総括 6～7（メモなし）'!I15 -> 11601546 | J15: =H15-I15 -> -6137006 | K15: ='〇総括 6～7（メモなし）'!K15 -> 0 | L15: ='〇総括 6～7（メモなし）'!L15 -> 0 | M15: =K15-L15 -> 0 | N15: ='〇総括 6～7（メモなし）'!N15 -> 0 | O15: ='〇総括 6～7（メモなし）'!O15 -> 0 | P15: =N15-O15 -> 0 | Q15: ='〇総括 6～7（メモなし）'!Q15 -> 0 | R15: ='〇総括 6～7（メモなし）'!R15 -> 0 | S15: =Q15-R15 -> 0
D16: 出産育児交付金 | E16: ='〇総括 6～7（メモなし）'!E16 -> 0 | F16: ='〇総括 6～7（メモなし）'!F16 -> 7979689 | G16: =E16-F16 -> -7979689 | H16: ='〇総括 6～7（メモなし）'!H16 -> 289600155 | I16: ='〇総括 6～7（メモなし）'!I16 -> 639077000 | J16: =H16-I16 -> -349476845 | K16: ='〇総括 6～7（メモなし）'!K16 -> 0 | L16: ='〇総括 6～7（メモなし）'!L16 -> 0 | M16: =K16-L16 -> 0 | N16: ='〇総括 6～7（メモなし）'!N16 -> 0 | O16: ='〇総括 6～7（メモなし）'!O16 -> 0 | P16: =N16-O16 -> 0 | Q16: ='〇総括 6～7（メモなし）'!Q16 -> 0 | R16: ='〇総括 6～7（メモなし）'!R16 -> 0 | S16: =Q16-R16 -> 0
D17: 施設収入 | E17: ='〇総括 6～7（メモなし）'!E17 -> 0 | F17: ='〇総括 6～7（メモなし）'!F17 -> 0 | G17: =E17-F17 -> 0 | H17: ='〇総括 6～7（メモなし）'!H17 -> 0 | I17: ='〇総括 6～7（メモなし）'!I17 -> 0 | K17: ='〇総括 6～7（メモなし）'!K17 -> 0 | L17: ='〇総括 6～7（メモなし）'!L17 -> 0 | M17: =K17-L17 -> 0 | N17: ='〇総括 6～7（メモなし）'!N17 -> 0 | O17: ='〇総括 6～7（メモなし）'!O17 -> 0 | P17: =N17-O17 -> 0 | Q17: ='〇総括 6～7（メモなし）'!Q17 -> 0 | R17: ='〇総括 6～7（メモなし）'!R17 -> 0 | S17: =Q17-R17 -> 0
D18: 雑収入他 | E18: ='〇総括 6～7（メモなし）'!E18 -> 0 | F18: ='〇総括 6～7（メモなし）'!F18 -> 211390 | G18: =E18-F18 -> -211390 | H18: ='〇総括 6～7（メモなし）'!H18 -> 0 | I18: ='〇総括 6～7（メモなし）'!I18 -> 0 | K18: ='〇総括 6～7（メモなし）'!K18 -> 77607 | L18: ='〇総括 6～7（メモなし）'!L18 -> 69345 | M18: =K18-L18 -> 8262 | N18: ='〇総括 6～7（メモなし）'!N18 -> 0 | O18: ='〇総括 6～7（メモなし）'!O18 -> 0 | P18: =N18-O18 -> 0 | Q18: ='〇総括 6～7（メモなし）'!Q18 -> 0 | R18: ='〇総括 6～7（メモなし）'!R18 -> 0 | S18: =Q18-AE18 -> 0
D19: 連合会交付金 | E19: ='〇総括 6～7（メモなし）'!E19 -> 0 | F19: ='〇総括 6～7（メモなし）'!F19 -> 0 | G19: =E19-F19 -> 0 | H19: ='〇総括 6～7（メモなし）'!H19 -> 0 | I19: ='〇総括 6～7（メモなし）'!I19 -> 0 | K19: ='〇総括 6～7（メモなし）'!K19 -> 23159738 | L19: ='〇総括 6～7（メモなし）'!L19 -> 20856594 | M19: =K19-L19 -> 2303144 | N19: ='〇総括 6～7（メモなし）'!N19 -> 0 | O19: ='〇総括 6～7（メモなし）'!O19 -> 0 | P19: =N19-O19 -> 0 | Q19: ='〇総括 6～7（メモなし）'!Q19 -> 0 | R19: ='〇総括 6～7（メモなし）'!R19 -> 44000 | S19: =Q19-R19 -> -44000
D20: 短期経理より繰入 | E20: ='〇総括 6～7（メモなし）'!E20 -> 0 | F20: ='〇総括 6～7（メモなし）'!F20 -> 0 | G20: =E20-F20 -> 0 | H20: ='〇総括 6～7（メモなし）'!H20 -> 0 | I20: ='〇総括 6～7（メモなし）'!I20 -> 0 | K20: ='〇総括 6～7（メモなし）'!K20 -> 11834281 | L20: ='〇総括 6～7（メモなし）'!L20 -> 11648520 | M20: =K20-L20 -> 185761 | N20: ='〇総括 6～7（メモなし）'!N20 -> 0 | O20: ='〇総括 6～7（メモなし）'!O20 -> 0 | P20: =N20-O20 -> 0 | Q20: ='〇総括 6～7（メモなし）'!Q20 -> 0 | R20: ='〇総括 6～7（メモなし）'!R20 -> 0 | S20: =Q20-R20 -> 0
D21: 長期経理より繰入 | E21: ='〇総括 6～7（メモなし）'!E21 -> 0 | F21: ='〇総括 6～7（メモなし）'!F21 -> 0 | G21: =E21-F21 -> 0 | H21: ='〇総括 6～7（メモなし）'!H21 -> 0 | I21: ='〇総括 6～7（メモなし）'!I21 -> 0 | K21: ='〇総括 6～7（メモなし）'!K21 -> 0 | L21: ='〇総括 6～7（メモなし）'!L21 -> 0 | M21: =K21-L21 -> 0 | N21: ='〇総括 6～7（メモなし）'!N21 -> 0 | O21: ='〇総括 6～7（メモなし）'!O21 -> 0 | P21: =N21-O21 -> 0 | Q21: ='〇総括 6～7（メモなし）'!Q21 -> 0 | R21: ='〇総括 6～7（メモなし）'!R21 -> 0 | S21: =Q21-R21 -> 0
D22: 組合員貸付金利息 | E22: ='〇総括 6～7（メモなし）'!E22 -> 0 | F22: ='〇総括 6～7（メモなし）'!F22 -> 0 | G22: =E22-F22 -> 0 | H22: ='〇総括 6～7（メモなし）'!H22 -> 0 | I22: ='〇総括 6～7（メモなし）'!I22 -> 0 | K22: ='〇総括 6～7（メモなし）'!K22 -> 0 | L22: ='〇総括 6～7（メモなし）'!L22 -> 0 | M22: =K22-L22 -> 0 | N22: ='〇総括 6～7（メモなし）'!N22 -> 0 | O22: ='〇総括 6～7（メモなし）'!O22 -> 0 | P22: =N22-O22 -> 0 | Q22: ='〇総括 6～7（メモなし）'!Q22 -> 0 | R22: ='〇総括 6～7（メモなし）'!R22 -> 12712000 | S22: =Q22-R22 -> -12712000
D23: 補助金 | E23: ='〇総括 6～7（メモなし）'!E23 -> 0 | F23: ='〇総括 6～7（メモなし）'!F23 -> 0 | G23: =E23-F23 -> 0 | H23: ='〇総括 6～7（メモなし）'!H23 -> 0 | I23: ='〇総括 6～7（メモなし）'!I23 -> 0 | K23: ='〇総括 6～7（メモなし）'!K23 -> 0 | L23: ='〇総括 6～7（メモなし）'!L23 -> 1206000 | M23: =K23-L23 -> -1206000 | N23: ='〇総括 6～7（メモなし）'!N23 -> 0 | O23: ='〇総括 6～7（メモなし）'!O23 -> 0 | P23: =N23-O23 -> 0 | Q23: ='〇総括 6～7（メモなし）'!Q23 -> 0 | R23: ='〇総括 6～7（メモなし）'!R23 -> 0 | S23: =Q23-R23 -> 0
D24: 寄附金 | E24: ='〇総括 6～7（メモなし）'!E24 -> 0 | F24: ='〇総括 6～7（メモなし）'!F24 -> 0 | G24: =E24-F24 -> 0 | H24: ='〇総括 6～7（メモなし）'!H24 -> 0 | I24: ='〇総括 6～7（メモなし）'!I24 -> 0 | K24: ='〇総括 6～7（メモなし）'!K24 -> 0 | L24: ='〇総括 6～7（メモなし）'!L24 -> 0 | M24: =K24-L24 -> 0 | N24: ='〇総括 6～7（メモなし）'!N24 -> 0 | O24: ='〇総括 6～7（メモなし）'!O24 -> 0 | P24: =N24-O24 -> 0 | Q24: ='〇総括 6～7（メモなし）'!Q24 -> 0 | R24: ='〇総括 6～7（メモなし）'!R24 -> 0 | S24: =Q24-R24 -> 0
D25: 基礎年金国庫金 | E25: ='〇総括 6～7（メモなし）'!E25 -> 0 | F25: ='〇総括 6～7（メモなし）'!F25 -> 0 | G25: =E25-F25 -> 0 | H25: ='〇総括 6～7（メモなし）'!H25 -> 0 | I25: ='〇総括 6～7（メモなし）'!I25 -> 0 | K25: ='〇総括 6～7（メモなし）'!K25 -> 0 | L25: ='〇総括 6～7（メモなし）'!L25 -> 0 | M25: =K25-L25 -> 0 | N25: ='〇総括 6～7（メモなし）'!N25 -> 0 | O25: ='〇総括 6～7（メモなし）'!O25 -> 0 | P25: =N25-O25 -> 0 | Q25: ='〇総括 6～7（メモなし）'!Q25 -> 0 | R25: ='〇総括 6～7（メモなし）'!R25 -> 0 | S25: =Q25-R25 -> 0
D26: 前期損益修正益 | E26: ='〇総括 6～7（メモなし）'!E26 -> 0 | F26: ='〇総括 6～7（メモなし）'!F26 -> 2100931 | G26: =E26-F26 -> -2100931 | H26: ='〇総括 6～7（メモなし）'!H26 -> 0 | I26: ='〇総括 6～7（メモなし）'!I26 -> 0 | K26: ='〇総括 6～7（メモなし）'!K26 -> 0 | L26: ='〇総括 6～7（メモなし）'!L26 -> 0 | M26: =K26-L26 -> 0 | N26: ='〇総括 6～7（メモなし）'!N26 -> 0 | O26: ='〇総括 6～7（メモなし）'!O26 -> 0 | P26: =N26-O26 -> 0 | Q26: ='〇総括 6～7（メモなし）'!Q26 -> 0 | R26: ='〇総括 6～7（メモなし）'!R26 -> 0 | S26: =Q26-R26 -> 0
D27: 前年度繰越支払準備金 | E27: ='〇総括 6～7（メモなし）'!E27 -> 0 | F27: ='〇総括 6～7（メモなし）'!F27 -> 883951850 | G27: =E27-F27 -> -883951850 | H27: ='〇総括 6～7（メモなし）'!H27 -> 0 | I27: ='〇総括 6～7（メモなし）'!I27 -> 0 | K27: ='〇総括 6～7（メモなし）'!K27 -> 0 | L27: ='〇総括 6～7（メモなし）'!L27 -> 0 | M27: =K27-L27 -> 0 | N27: ='〇総括 6～7（メモなし）'!N27 -> 0 | O27: ='〇総括 6～7（メモなし）'!O27 -> 0 | P27: =N27-O27 -> 0 | Q27: ='〇総括 6～7（メモなし）'!Q27 -> 0 | R27: ='〇総括 6～7（メモなし）'!R27 -> 0 | S27: =Q27-R27 -> 0
C28: 当期収入合計 （B） | E28: =SUM(E7:E27) -> 0 | F28: =SUM(F7:F27) -> 13363345222 | G28: =SUM(G7:G27) -> -13363345222 | H28: =SUM(H7:H27) -> 10342735989 | I28: =SUM(I7:I27) -> 19217782897 | J28: =SUM(J7:J27) -> -8875046908 | K28: =SUM(K7:K27) -> 124727469 | L28: =SUM(L7:L27) -> 115948018 | ... S28: =SUM(S7:S27) -> -12756000
C29: 支出の部 | D29: 保健給付 | E29: ='〇総括 6～7（メモなし）'!E29 -> 0 | F29: ='〇総括 6～7（メモなし）'!F29 -> 5062957780 | G29: =E29-F29 -> -5062957780 | H29: ='〇総括 6～7（メモなし）'!H29 -> 0 | I29: ='〇総括 6～7（メモなし）'!I29 -> 0 | K29: ='〇総括 6～7（メモなし）'!K29 -> 0 | L29: ='〇総括 6～7（メモなし）'!L29 -> 0 | M29: =K29-L29 -> 0 | N29: ='〇総括 6～7（メモなし）'!N29 -> 0 | O29: ='〇総括 6～7（メモなし）'!O29 -> 0 | P29: =N29-O29 -> 0 | Q29: ='〇総括 6～7（メモなし）'!Q29 -> 0 | R29: ='〇総括 6～7（メモなし）'!R29 -> 0 | S29: =Q29-R29 -> 0
D30: 休業給付 | E30: ='〇総括 6～7（メモなし）'!E30 -> 0 | F30: ='〇総括 6～7（メモなし）'!F30 -> 596910377 | G30: =E30-F30 -> -596910377 | H30: ='〇総括 6～7（メモなし）'!H30 -> 0 | I30: ='〇総括 6～7（メモなし）'!I30 -> 0 | K30: ='〇総括 6～7（メモなし）'!K30 -> 0 | L30: ='〇総括 6～7（メモなし）'!L30 -> 0 | M30: =K30-L30 -> 0 | N30: ='〇総括 6～7（メモなし）'!N30 -> 0 | O30: ='〇総括 6～7（メモなし）'!O30 -> 0 | P30: =N30-O30 -> 0 | Q30: ='〇総括 6～7（メモなし）'!Q30 -> 0 | R30: ='〇総括 6～7（メモなし）'!R30 -> 0 | S30: =Q30-R30 -> 0
D31: 災害給付 | E31: ='〇総括 6～7（メモなし）'!E31 -> 0 | F31: ='〇総括 6～7（メモなし）'!F31 -> 0 | G31: =E31-F31 -> 0 | H31: ='〇総括 6～7（メモなし）'!H31 -> 0 | I31: ='〇総括 6～7（メモなし）'!I31 -> 0 | K31: ='〇総括 6～7（メモなし）'!K31 -> 0 | L31: ='〇総括 6～7（メモなし）'!L31 -> 0 | M31: =K31-L31 -> 0 | N31: ='〇総括 6～7（メモなし）'!N31 -> 0 | O31: ='〇総括 6～7（メモなし）'!O31 -> 0 | P31: =N31-O31 -> 0 | Q31: ='〇総括 6～7（メモなし）'!Q31 -> 0 | R31: ='〇総括 6～7（メモなし）'!R31 -> 0 | S31: =Q31-R31 -> 0
D32: 附加給付 | E32: ='〇総括 6～7（メモなし）'!E32 -> 0 | F32: ='〇総括 6～7（メモなし）'!F32 -> 36121513 | G32: =E32-F32 -> -36121513 | H32: ='〇総括 6～7（メモなし）'!H32 -> 0 | I32: ='〇総括 6～7（メモなし）'!I32 -> 0 | K32: ='〇総括 6～7（メモなし）'!K32 -> 0 | L32: ='〇総括 6～7（メモなし）'!L32 -> 0 | M32: =K32-L32 -> 0 | N32: ='〇総括 6～7（メモなし）'!N32 -> 0 | O32: ='〇総括 6～7（メモなし）'!O32 -> 0 | P32: =N32-O32 -> 0 | Q32: ='〇総括 6～7（メモなし）'!Q32 -> 0 | R32: ='〇総括 6～7（メモなし）'!R32 -> 0 | S32: =Q32-R32 -> 0
D33: 一部負担金払戻金 | E33: ='〇総括 6～7（メモなし）'!E33 -> 0 | F33: ='〇総括 6～7（メモなし）'!F33 -> 74042318 | G33: =E33-F33 -> -74042318 | H33: ='〇総括 6～7（メモなし）'!H33 -> 0 | I33: ='〇総括 6～7（メモなし）'!I33 -> 0 | K33: ='〇総括 6～7（メモなし）'!K33 -> 0 | L33: ='〇総括 6～7（メモなし）'!L33 -> 0 | M33: =K33-L33 -> 0 | N33: ='〇総括 6～7（メモなし）'!N33 -> 0 | O33: ='〇総括 6～7（メモなし）'!O33 -> 0 | P33: =N33-O33 -> 0 | Q33: ='〇総括 6～7（メモなし）'!Q33 -> 0 | R33: ='〇総括 6～7（メモなし）'!R33 -> 0 | S33: =Q33-R33 -> 0
D34: 拠出金・納付金 | E34: ='〇総括 6～7（メモなし）'!E34 -> 0 | F34: ='〇総括 6～7（メモなし）'!F34 -> 5748963367 | G34: =E34-F34 -> -5748963367 | H34: ='〇総括 6～7（メモなし）'!H34 -> 0 | I34: ='〇総括 6～7（メモなし）'!I34 -> 0 | K34: ='〇総括 6～7（メモなし）'!K34 -> 0 | L34: ='〇総括 6～7（メモなし）'!L34 -> 0 | M34: =K34-L34 -> 0 | N34: ='〇総括 6～7（メモなし）'!N34 -> 0 | O34: ='〇総括 6～7（メモなし）'!O34 -> 0 | P34: =N34-O34 -> 0 | Q34: ='〇総括 6～7（メモなし）'!Q34 -> 0 | R34: ='〇総括 6～7（メモなし）'!R34 -> 0 | S34: =Q34-R34 -> 0
D35: 任意継続掛金還付金 | E35: ='〇総括 6～7（メモなし）'!E35 -> 0 | F35: ='〇総括 6～7（メモなし）'!F35 -> 0 | G35: =E35-F35 -> 0 | H35: ='〇総括 6～7（メモなし）'!H35 -> 0 | I35: ='〇総括 6～7（メモなし）'!I35 -> 0 | K35: ='〇総括 6～7（メモなし）'!K35 -> 0 | L35: ='〇総括 6～7（メモなし）'!L35 -> 0 | M35: =K35-L35 -> 0 | N35: ='〇総括 6～7（メモなし）'!N35 -> 0 | O35: ='〇総括 6～7（メモなし）'!O35 -> 0 | P35: =N35-O35 -> 0 | Q35: ='〇総括 6～7（メモなし）'!Q35 -> 0 | R35: ='〇総括 6～7（メモなし）'!R35 -> 0 | S35: =Q35-R35 -> 0
D36: 退職給付 | E36: ='〇総括 6～7（メモなし）'!E36 -> 0 | F36: ='〇総括 6～7（メモなし）'!F36 -> 0 | G36: =E36-F36 -> 0 | H36: ='〇総括 6～7（メモなし）'!H36 -> 5516016459 | I36: ='〇総括 6～7（メモなし）'!I36 -> 10787321768 | J36: =H36-I36 -> -5271305309 | K36: ='〇総括 6～7（メモなし）'!K36 -> 0 | L36: ='〇総括 6～7（メモなし）'!L36 -> 0 | M36: =K36-L36 -> 0 | N36: ='〇総括 6～7（メモなし）'!N36 -> 0 | O36: ='〇総括 6～7（メモなし）'!O36 -> 0 | P36: =N36-O36 -> 0 | Q36: ='〇総括 6～7（メモなし）'!Q36 -> 0 | R36: ='〇総括 6～7（メモなし）'!R36 -> 0 | S36: =Q36-R36 -> 0
D37: 障害給付 | E37: ='〇総括 6～7（メモなし）'!E37 -> 0 | F37: ='〇総括 6～7（メモなし）'!F37 -> 0 | G37: =E37-F37 -> 0 | H37: ='〇総括 6～7（メモなし）'!H37 -> 45220684 | I37: ='〇総括 6～7（メモなし）'!I37 -> 87548431 | J37: =H37-I37 -> -42327747 | K37: ='〇総括 6～7（メモなし）'!K37 -> 0 | L37: ='〇総括 6～7（メモなし）'!L37 -> 0 | M37: =K37-L37 -> 0 | N37: ='〇総括 6～7（メモなし）'!N37 -> 0 | O37: ='〇総括 6～7（メモなし）'!O37 -> 0 | P37: =N37-O37 -> 0 | Q37: ='〇総括 6～7（メモなし）'!Q37 -> 0 | R37: ='〇総括 6～7（メモなし）'!R37 -> 0 | S37: =Q37-R37 -> 0
D38: 遺族給付 | E38: ='〇総括 6～7（メモなし）'!E38 -> 0 | F38: ='〇総括 6～7（メモなし）'!F38 -> 0 | G38: =E38-F38 -> 0 | H38: ='〇総括 6～7（メモなし）'!H38 -> 995045755 | I38: ='〇総括 6～7（メモなし）'!I38 -> 2016533515 | J38: =H38-I38 -> -1021487760 | K38: ='〇総括 6～7（メモなし）'!K38 -> 0 | L38: ='〇総括 6～7（メモなし）'!L38 -> 0 | M38: =K38-L38 -> 0 | N38: ='〇総括 6～7（メモなし）'!N38 -> 0 | O38: ='〇総括 6～7（メモなし）'!O38 -> 0 | P38: =N38-O38 -> 0 | Q38: ='〇総括 6～7（メモなし）'!Q38 -> 0 | R38: ='〇総括 6～7（メモなし）'!R38 -> 0 | S38: =Q38-R38 -> 0
D39: 基礎年金拠出金負担金 | E39: ='〇総括 6～7（メモなし）'!E39 -> 0 | F39: ='〇総括 6～7（メモなし）'!F39 -> 0 | G39: =E39-F39 -> 0 | H39: ='〇総括 6～7（メモなし）'!H39 -> 2802837274 | I39: ='〇総括 6～7（メモなし）'!I39 -> 5376398659 | J39: =H39-I39 -> -2573561385 | K39: ='〇総括 6～7（メモなし）'!K39 -> 0 | L39: ='〇総括 6～7（メモなし）'!L39 -> 0 | M39: =K39-L39 -> 0 | N39: ='〇総括 6～7（メモなし）'!N39 -> 0 | O39: ='〇総括 6～7（メモなし）'!O39 -> 0 | P39: =N39-O39 -> 0 | Q39: ='〇総括 6～7（メモなし）'!Q39 -> 0 | R39: ='〇総括 6～7（メモなし）'!R39 -> 0 | S39: =Q39-R39 -> 0
D40: 雑費 | E40: ='〇総括 6～7（メモなし）'!E40 -> 0 | F40: ='〇総括 6～7（メモなし）'!F40 -> 0 | G40: =E40-F40 -> 0 | H40: ='〇総括 6～7（メモなし）'!H40 -> 0 | I40: ='〇総括 6～7（メモなし）'!I40 -> 0 | K40: ='〇総括 6～7（メモなし）'!K40 -> 0 | L40: ='〇総括 6～7（メモなし）'!L40 -> 0 | M40: =K40-L40 -> 0 | N40: ='〇総括 6～7（メモなし）'!N40 -> 0 | O40: ='〇総括 6～7（メモなし）'!O40 -> 0 | P40: =N40-O40 -> 0 | Q40: ='〇総括 6～7（メモなし）'!Q40 -> 0 | R40: ='〇総括 6～7（メモなし）'!R40 -> 0 | S40: =Q40-R40 -> 0
D41: 連合会払込金 | E41: ='〇総括 6～7（メモなし）'!E41 -> 0 | F41: ='〇総括 6～7（メモなし）'!F41 -> 132291047 | G41: =E41-F41 -> -132291047 | H41: ='〇総括 6～7（メモなし）'!H41 -> 26027000 | I41: ='〇総括 6～7（メモなし）'!I41 -> 249923000 | J41: =H41-I41 -> -223896000 | K41: ='〇総括 6～7（メモなし）'!K41 -> 0 | L41: ='〇総括 6～7（メモなし）'!L41 -> 0 | M41: =K41-L41 -> 0 | N41: ='〇総括 6～7（メモなし）'!N41 -> 0 | O41: ='〇総括 6～7（メモなし）'!O41 -> 0 | P41: =N41-O41 -> 0 | Q41: ='〇総括 6～7（メモなし）'!Q41 -> 0 | R41: ='〇総括 6～7（メモなし）'!R41 -> 0 | S41: =Q41-R41 -> 0
...
