Workbook

Sheet 使い方
B1: 貸付申込シミュレーター 使い方
B2: 共済組合の貸付(普通・特別・住宅・災害)について、申込者ご自身で「必要書類」「申込可能額」「償還額・償還期間」などを確認するためのExcelです。
B4: このExcelでできること
B5: 1. 申込可能額 | C5: 貸付区分・給料月額・組合員期間などから、貸付限度額と「償還額が給料月額・年収額の30%以内」となる範囲を同時に判定し、申込可能額を表示します(手計算・仮入力が不要)。
B6: 2. 償還額・償還期間 | C6: 償還回数(または毎月償還額)を入力すると、毎月償還額・ボーナス償還額・返済総額・償還開始/終了年月を表示します。『償還表』に月別の明細、『早見表』に金額×回数の一覧があります。
B7: 3. 必要書類 | C7: 貸付区分(住宅は事由別)に応じて、申込時の提出書類と貸付金交付後の提出書類を自動表示します。提出先・申込締切日・交付日も表示します。
B8: 4. 添書 | C8: 『添書』シートに、申込内容に応じた添書(提出書類のチェックリスト付き)を自動作成します。1件ずつ手作成する必要がありません。印刷してそのまま使えます。
B9: 5. 借入状況の確認 | C9: 借入状況等申告書の(A)〜(M)と同じ計算(E÷K、L÷M)を自動で行い、30%超を○×で判定します。
B10: 使い方
B11: 手順 | C11: ①『申込シミュレーション』の黄色いセルに入力(青字・黄色セルが入力欄。入力例が入っています) → ②右側の判定結果・⑤判定の内訳を確認 → ③必要書類・日程を確認 → ④『添書』を印刷。
B12: 色の意味 | C12: 青字+黄色=入力するセル / 黒字=自動計算(触らない)。判定は ○=適合、×=不適合、△=要確認、－=対象外。
B13: 利率・数値の改定 | C13: 利率・限度額・書類表・締切日などはすべて『マスタ』シートの値を参照します。改定時はマスタを直すだけで、全シートに反映されます。祝日は毎年追加してください。
B14: 出典 | C14: 広島市職員共済組合ハンドブック(令和8年度改訂版)p.40〜45、貸付金借用証書(様式第4号)、借入状況等申告書(様式)。利率は令和8年4月1日現在(普通・特別・住宅 年1.26%、災害 年0.93%、在宅介護対応住宅加算部分 年1.00%)。
B15: 前提・注意(必ずお読みください)
B16: 試算であること | C16: 実際の貸付可否は共済組合の審査によります。償還額は元利均等の概算で、実際の償還表(円未満の端数処理)と数円の差が出る場合があります。確定額は貸付決定通知で確認してください。
B17: ボーナス併用償還 | C17: 6月・12月に償還するものとし、半年あたりの利率は月利を6か月複利換算、基本部分に充てるものとして計算しています。
B18: 要確認としている点 | C18: ①災害家財貸付の申込単位(5万円)と償還回数上限(360回)はハンドブックの災害貸付の記載を準用 ②災害住宅貸付で組合員期間1年未満の月数・最低保障額は最下段を適用 ③在宅介護対応住宅(加算部分)の利率を災害貸付と併用する場合の取扱い ④住宅貸付の貸付決定時期(ハンドブックの「締切日の同月10日頃」の記載)。いずれも共済組合に確認のうえ、必要ならマスタを修正してください。
B19: 対象外のもの | C19: 自動車購入貸付で既に貸付残がある場合(一括償還が必要)、同一貸付対象について複数申込できない取扱い、育児・介護休業中の償還猶予、修学貸付の修学期間中の利息のみの償還、任期のある職員の償還期間(任期末まで)は自動判定していません。個別に共済組合へご相談ください。
B20: お問合せ | C20: 広島市職員共済組合 庶務係 ☎082-504-2061(内線 81-2361,2362)

Sheet 申込シミュレーション
B1: 貸付申込シミュレーター(広島市職員共済組合 貸付)
B2: 黄色のセルに入力してください(入力例が入っています。上書きして使います)。結果は右側に自動表示されます。
B3: ※試算用です。実際の貸付可否・償還額は共済組合の審査・償還表によります。利率・限度額などの根拠は「マスタ」シートにあります。
B5: ① 申込者・貸付の内容 | F5: ③ 判定結果
B6: 所属区分 | C6: 市長事務部局(給与支給の派遣職員を含む) | D6: 提出先の案内に使います | F6: 総合判定 | G6: =計算過程!$B$108 -> 申込可能
B7: 所属名 | C7: ○○局○○課 | D7: 添書の宛名に使います | F7: 区分群 | G7: =計算過程!$B$5 -> 普通貸付
B8: 氏名 | C8: 広島 太郎 | D8: 添書の宛名に使います | F8: 組合員期間 | G8: =計算過程!$B$27 -> 14年7か月 | H8: 資格取得日〜申込予定日
B9: 貸付区分 ※プルダウン | C9: 普通貸付:自動車購入 | D9: 貸付の種類を選びます | F9: 適用利率(年) | G9: =計算過程!$B$24 -> 0.0126 | H9: 変動利率(令和8年4月1日現在)
B10: 申込予定日 | C10: 46328 | D10: 締切日・交付日・組合員期間の判定に使います | F10: 貸付限度額(基本) | G10: =計算過程!$B$33 -> 1740000 | H10: 給料月額×月数、最低保障額などから計算
B11: 組合員資格取得日 | C11: 41000 | D11: 組合員期間の計算に使います | F11: 在宅介護対応の加算限度 | G11: =計算過程!$B$34 -> 0
B12: 給料月額(円) | C12: 290000 | D12: 手当等は含めない(部分休業等で減額中は減額後) | F12: 返済能力から見た借入上限 | G12: =計算過程!$B$43 -> 3312812.4 | H12: ="毎月償還額の上限 "&TEXT(計算過程!$B$41,"#,##0")&"円(今回分)で試算" -> 毎月償還額の上限 57,000円(今回分)で試算
B13: 事由発生(予定)日 | D13: =IFERROR("基準日:"&計算過程!$B$16&"("&計算過程!$B$15&")","") -> 基準日:自動車の登録(予定)日(自動車登録(名義変更)前で代金支払前) | F13: ★ 申込可能額 | G13: =計算過程!$B$44 -> 1740000 | H13: ="決定要因:"&計算過程!$B$45 -> 決定要因:貸付限度額
B14: 給与の差押さえ等 | C14: 無 | D14: 有・無 | F14: 試算に用いた申込額 | G14: =計算過程!$B$46 -> 1500000 | H14: 申込希望金額を入力するとその金額で試算
B15: 無給休職(育児休業を除く) | C15: 無 | D15: 有・無 | F15: 償還回数 | G15: =計算過程!$B$51 -> 60 | H15: ="償還期間 "&計算過程!$B$73 -> 償還期間 5年0か月
B16: 修学月数(修学貸付のみ) | D16: 学年単位・修業年限以内。1か月15万円 | F16: 毎月償還額 | G16: =計算過程!$B$54 -> 25809 | H16: 元利均等・給与控除(概算)
B17: 申込希望金額(万円) | C17: 150 | D17: 空欄なら申込可能額で試算します | F17: ボーナス償還額(1回) | G17: =計算過程!$B$57 -> 0 | H17: 6月・12月
B18: 償還回数(回) | C18: 60 | D18: 回数か毎月償還額のどちらかを設定 | F18: 償還開始 | G18: =計算過程!$B$71 -> 46357 | H18: 貸付を受けた月の翌月から
B19: 毎月償還額の希望(円) | D19: 回数が空欄のとき、返済できる回数を逆算 | F19: 償還終了予定 | G19: =計算過程!$B$72 -> 48153
B20: ボーナス併用償還 | C20: 無 | D20: 住宅系で申込300万円以上の場合のみ | F20: 返済総額 | G20: =計算過程!$B$58 -> 1548540
B21: ボーナス償還分の元金(万円) | D21: 100万円以上・貸付金額の1/2以内・5万円単位 | F21: うち利息 | G21: =計算過程!$B$59 -> 48540
B22: ボーナス償還回数(回) | D22: 60回以内(6月・12月の計)
B23: 在宅介護対応住宅の該当部分(万円) | D23: 住宅系のみ。300万円を限度に加算 | F23: ④ 償還額の割合(借入状況等申告書の計算)
B24: 住宅書類の区分 ※災害住宅・再貸付のみ | D24: 必要書類(住宅〔表1〕)の判定に使います | F24: 毎月の償還額(E)=A+B+C+D | G24: =計算過程!$B$60 -> 55809 | H24: D=今回の貸付の毎月償還額
F25: ボーナス償還額(J)=F+G+H+I | G25: =計算過程!$B$61 -> 0
B26: ② 他の借入・共済組合の既貸付(借入状況等申告書の項目) | F26: 給料月額(K) | G26: =計算過程!$B$62 -> 290000
B27: (A)他の金融機関等 既借入 毎月償還額(円) | C27: 18000 | D27: 他の金融機関等の返済がなければ0。裏面の記入上の注意に従い、予定分も含めます。 | F27: 毎月償還額の割合 E÷K | G27: =計算過程!$B$63 -> 0.19244483 | H27: =IF(計算過程!$B$96=1,"○ 30%以内","× 30%超") -> ○ 30%以内
B28: (F)同上 ボーナス償還額(円/回) | C28: 0 | F28: 年間償還額(L)=E×12+J×2 | G28: =計算過程!$B$64 -> 669708
B29: (B)他の金融機関等 新規借入 毎月償還額(円) | C29: 0 | F29: 年収額(M)=K×12+K×4 | G29: =計算過程!$B$65 -> 4640000
B30: (G)同上 ボーナス償還額(円/回) | C30: 0 | F30: 年間償還額の割合 L÷M | G30: =計算過程!$B$66 -> 0.14433362 | H30: =IF(計算過程!$B$98=1,"○ 30%以内","× 30%超") -> ○ 30%以内
B31: (C)共済組合 既貸付 毎月償還額(円) | C31: 12000
B32: (H)共済組合 既貸付 ボーナス償還額(円/回) | C32: 0 | F32: ⑤ 判定の内訳(○=適合 ×=不適合 △=要確認 －=対象外)
F33: 貸付区分 | G33: =CHOOSE(計算過程!$B$76+1,"×","○","△","－") -> ○ | H33: =計算過程!$B$77 -> 貸付区分:普通貸付:自動車購入
B34: ⑦ 申込時の提出書類(貸付区分に応じて自動表示) | F34: 給料月額 | G34: =CHOOSE(計算過程!$B$78+1,"×","○","△","－") -> ○ | H34: =計算過程!$B$79 -> 給料月額(手当等を含まない・部分休業等による減額後)
B35: =IF(計算過程!$A$128="","","□ "&計算過程!$A$128) -> □ 貸付申込書 | F35: 借受資格(組合員期間) | G35: =CHOOSE(計算過程!$B$80+1,"×","○","△","－") -> ○ | H35: =計算過程!$B$81 -> 組合員資格取得日から借受可(現在14年7か月)
B36: =IF(計算過程!$A$129="","","□ "&計算過程!$A$129) -> □ 貸付金借用証書(様式第4号・共済組合で配布) | F36: 給与の差押さえ等 | G36: =CHOOSE(計算過程!$B$82+1,"×","○","△","－") -> ○ | H36: =計算過程!$B$83 -> 貸付制限に該当しない
B37: =IF(計算過程!$A$130="","","□ "&計算過程!$A$130) -> □ 印鑑登録証明書(貸付金交付日前3か月以内に発行されたもの) | F37: 無給休職 | G37: =CHOOSE(計算過程!$B$84+1,"×","○","△","－") -> ○ | H37: =計算過程!$B$85 -> 無給休職でない(育児休業は除く)
B38: =IF(計算過程!$A$131="","","□ "&計算過程!$A$131) -> □ 給与支払明細書(直近のもの) | F38: 申込時期 | G38: =CHOOSE(計算過程!$B$86+1,"×","○","△","－") -> － | H38: =計算過程!$B$87 -> 申込時期:自動車登録(名義変更)前で代金支払前
B39: =IF(計算過程!$A$132="","","□ "&計算過程!$A$132) -> □ 借入状況等申告書 | F39: 修学月数 | G39: =CHOOSE(計算過程!$B$88+1,"×","○","△","－") -> － | H39: =計算過程!$B$89 -> 修学貸付のみ対象
B40: =IF(計算過程!$A$133="","","□ "&計算過程!$A$133) -> □ 【事由別】注文書(写)又は発注書(写)(見積書は不可) | F40: 申込金額の下限・単位 | G40: =CHOOSE(計算過程!$B$90+1,"×","○","△","－") -> ○ | H40: =計算過程!$B$91 -> 申込金額は10万円以上・1万円単位(試算額:1,500,000円)
B41: =IF(計算過程!$A$134="","","□ "&計算過程!$A$134) | F41: 貸付限度額 | G41: =CHOOSE(計算過程!$B$92+1,"×","○","△","－") -> ○ | H41: =計算過程!$B$93 -> 貸付限度額 1,740,000円(うち在宅介護加算 0円)
...

Sheet 添書
B1: 添書(自動作成)― 申込シミュレーションの入力内容から作成します。印刷してそのまま使えます。
B3: ="令和"&(YEAR(TODAY())-2018)&"年"&MONTH(TODAY())&"月"&DAY(TODAY())&"日" -> 令和8年10月19日
B5: =IF(申込シミュレーション!$C$7="","(所属名)",申込シミュレーション!$C$7)&" "&IF(申込シミュレーション!$C$8="","(氏名)",申込シミュレーション!$C$8)&" 様" -> ○○局○○課 広島 太郎 様
B7: 広島市職員共済組合
B8: (庶務係 ☎082-504-2061 / 内線 81-2361,2362)
B10: ="貸付申込書類の送付について("&申込シミュレーション!$C$9&")" -> 貸付申込書類の送付について(普通貸付:自動車購入)
B12: 標記について、貸付申込書類を送付します。下記の書類を添えて、申込締切日までにお申込みください。
B14: 記
B15: 1 申込内容
B16: 貸付区分 | C16: =申込シミュレーション!$C$9 -> 普通貸付:自動車購入
B17: 申込金額(試算) | C17: =TEXT(計算過程!$B$46,"#,##0")&"円" -> 1,500,000円
B18: 適用利率(年) | C18: =TEXT(計算過程!$B$24,"0.00%")&"(変動利率)" -> 1.26%(変動利率)
B19: 償還回数・期間 | C19: =計算過程!$B$51&"回("&計算過程!$B$73&")" -> 60回(5年0か月)
B20: 毎月償還額(概算) | C20: =TEXT(計算過程!$B$54,"#,##0")&"円"&IF(計算過程!$B$57>0," / ボーナス償還額(1回) "&TEXT(計算過程!$B$57,"#,##0")&"円","") -> 25,809円
B21: 償還開始 | C21: =IF(計算過程!$B$71="","","令和"&(YEAR(計算過程!$B$71)-2018)&"年"&MONTH(計算過程!$B$71)&"月分の給与から") -> 令和8年12月分の給与から
B23: 2 申込締切日・提出先
B24: 申込締切日 | C24: =IF(計算過程!$B$69="","","令和"&(YEAR(計算過程!$B$69)-2018)&"年"&MONTH(計算過程!$B$69)&"月"&DAY(計算過程!$B$69)&"日") -> 令和8年11月5日
B25: 提出先 | C25: =IFERROR(INDEX(マスタ!$B$85:$B$87,MATCH(申込シミュレーション!$C$6,マスタ!$A$85:$A$87,0)),"") -> 共済組合(庶務係)へ直接提出してください。
B26: 貸付金交付予定日 | C26: =IF(計算過程!$B$70="","","令和"&(YEAR(計算過程!$B$70)-2018)&"年"&MONTH(計算過程!$B$70)&"月"&DAY(計算過程!$B$70)&"日") -> 令和8年11月30日
B28: 3 申込時の提出書類(□にチェックしてください)
B29: =IF(計算過程!$A$128="","","□ "&計算過程!$A$128) -> □ 貸付申込書
B30: =IF(計算過程!$A$129="","","□ "&計算過程!$A$129) -> □ 貸付金借用証書(様式第4号・共済組合で配布)
B31: =IF(計算過程!$A$130="","","□ "&計算過程!$A$130) -> □ 印鑑登録証明書(貸付金交付日前3か月以内に発行されたもの)
B32: =IF(計算過程!$A$131="","","□ "&計算過程!$A$131) -> □ 給与支払明細書(直近のもの)
B33: =IF(計算過程!$A$132="","","□ "&計算過程!$A$132) -> □ 借入状況等申告書
B34: =IF(計算過程!$A$133="","","□ "&計算過程!$A$133) -> □ 【事由別】注文書(写)又は発注書(写)(見積書は不可)
B35: =IF(計算過程!$A$134="","","□ "&計算過程!$A$134)
B36: =IF(計算過程!$A$135="","","□ "&計算過程!$A$135)
B37: =IF(計算過程!$A$136="","","□ "&計算過程!$A$136)
B38: =IF(計算過程!$A$137="","","□ "&計算過程!$A$137)
B39: =IF(計算過程!$A$138="","","□ "&計算過程!$A$138)
B40: =IF(計算過程!$A$139="","","□ "&計算過程!$A$139)
B41: =IF(計算過程!$A$140="","","□ "&計算過程!$A$140)
B42: =IF(計算過程!$A$141="","","□ "&計算過程!$A$141)
B43: =IF(計算過程!$A$142="","","□ "&計算過程!$A$142)
B44: =IF(計算過程!$A$143="","","□ "&計算過程!$A$143)
B46: 4 貸付金交付後の提出書類
B47: =IF(計算過程!$A$156="","","□ "&計算過程!$A$156) -> □ 完了届(自動車検査証(写)及び自動車検査証記録事項(写)を添付)
B48: =IF(計算過程!$A$157="","","□ "&計算過程!$A$157)
B49: =IF(計算過程!$A$158="","","□ "&計算過程!$A$158)
...

Sheet 償還表
A1: 償還表(試算)― 申込シミュレーションの内容から自動作成
A2: ="貸付区分:"&申込シミュレーション!$C$9&" 申込額:"&TEXT(計算過程!$B$46,"#,##0")&"円 利率:"&TEXT(計算過程!$B$24,"0.00%")&" 毎月償還:"&計算過程!$B$51&"回" -> 貸付区分:普通貸付:自動車購入 申込額:1,500,000円 利率:1.26% 毎月償還:60回
A3: 元利均等返済の概算です。円未満の端数処理が実際の償還表と異なるため、数円の差が出る場合があります。ボーナス償還は6月・12月に償還するものとして計算しています。
A5: 合計 | C5: =SUM(C8:C367) -> 1548540 | D5: =SUM(D8:D367) -> 48535 | E5: =SUM(E8:E367) -> 1500005 | J5: =SUM(J8:J367) -> 0 | K5: =SUM(K8:K367) -> 0 | L5: =SUM(L8:L367) -> 0 | N5: =SUM(N8:N367) -> 1548540
A6: 回 | B6: 償還年月 | C6: 毎月償還額 | D6: うち利息 | E6: うち元金 | F6: 残高(基本部分) | G6: 残高(在宅介護部分) | H6: 残高(毎月分) | I6: ボーナス回次 | J6: ボーナス償還額 | K6: うち利息 | L6: うち元金 | M6: ボーナス分残高 | N6: 償還額合計 | O6: 残高合計
A7: 0 | B7: 開始時 | F7: =計算過程!$B$48-計算過程!$B$49 -> 1500000 | G7: =計算過程!$B$47 -> 0 | H7: =F7+G7 -> 1500000 | I7: 0 | M7: =計算過程!$B$49 -> 0 | O7: =H7+M7 -> 1500000
A8: =IF(ROWS($A$8:A8)<=計算過程!$B$51,ROWS($A$8:A8),"") -> 1 | B8: =IF(A8="","",EDATE(計算過程!$B$71,A8-1)) -> 46357 | C8: =IF(A8="","",計算過程!$B$54) -> 25809 | D8: =IF(A8="","",ROUND(F7*計算過程!$B$24/12+G7*計算過程!$B$25/12,0)) -> 1575 | E8: =IF(A8="","",C8-D8) -> 24234 | F8: =IF(A8="","",MAX(0,F7*(1+計算過程!$B$24/12)-計算過程!$B$52)) -> 1475766.1 | G8: =IF(A8="","",MAX(0,G7*(1+計算過程!$B$25/12)-計算過程!$B$53)) -> 0 | H8: =IF(A8="","",F8+G8) -> 1475766.1 | I8: =IF(A8="","",IF(AND(OR(MONTH(B8)=6,MONTH(B8)=12),I7<計算過程!$B$50),I7+1,I7)) -> 0 | J8: =IF(A8="","",IF(I8>I7,計算過程!$B$57,0)) -> 0 | K8: =IF(A8="","",IF(I8>I7,ROUND(M7*計算過程!$B$55,0),0)) -> 0 | L8: =IF(A8="","",J8-K8) -> 0 | M8: =IF(A8="","",IF(I8>I7,MAX(0,M7*(1+計算過程!$B$55)-計算過程!$B$56),M7)) -> 0 | N8: =IF(A8="","",C8+J8) -> 25809 | O8: =IF(A8="","",H8+M8) -> 1475766.1
A9: =IF(ROWS($A$8:A9)<=計算過程!$B$51,ROWS($A$8:A9),"") -> 2 | B9: =IF(A9="","",EDATE(計算過程!$B$71,A9-1)) -> 46388 | C9: =IF(A9="","",計算過程!$B$54) -> 25809 | D9: =IF(A9="","",ROUND(F8*計算過程!$B$24/12+G8*計算過程!$B$25/12,0)) -> 1550 | E9: =IF(A9="","",C9-D9) -> 24259 | F9: =IF(A9="","",MAX(0,F8*(1+計算過程!$B$24/12)-計算過程!$B$52)) -> 1451506.8 | G9: =IF(A9="","",MAX(0,G8*(1+計算過程!$B$25/12)-計算過程!$B$53)) -> 0 | H9: =IF(A9="","",F9+G9) -> 1451506.8 | I9: =IF(A9="","",IF(AND(OR(MONTH(B9)=6,MONTH(B9)=12),I8<計算過程!$B$50),I8+1,I8)) -> 0 | J9: =IF(A9="","",IF(I9>I8,計算過程!$B$57,0)) -> 0 | K9: =IF(A9="","",IF(I9>I8,ROUND(M8*計算過程!$B$55,0),0)) -> 0 | L9: =IF(A9="","",J9-K9) -> 0 | M9: =IF(A9="","",IF(I9>I8,MAX(0,M8*(1+計算過程!$B$55)-計算過程!$B$56),M8)) -> 0 | N9: =IF(A9="","",C9+J9) -> 25809 | O9: =IF(A9="","",H9+M9) -> 1451506.8
A10: =IF(ROWS($A$8:A10)<=計算過程!$B$51,ROWS($A$8:A10),"") -> 3 | B10: =IF(A10="","",EDATE(計算過程!$B$71,A10-1)) -> 46419 | C10: =IF(A10="","",計算過程!$B$54) -> 25809 | D10: =IF(A10="","",ROUND(F9*計算過程!$B$24/12+G9*計算過程!$B$25/12,0)) -> 1524 | E10: =IF(A10="","",C10-D10) -> 24285 | F10: =IF(A10="","",MAX(0,F9*(1+計算過程!$B$24/12)-計算過程!$B$52)) -> 1427222 | G10: =IF(A10="","",MAX(0,G9*(1+計算過程!$B$25/12)-計算過程!$B$53)) -> 0 | H10: =IF(A10="","",F10+G10) -> 1427222 | I10: =IF(A10="","",IF(AND(OR(MONTH(B10)=6,MONTH(B10)=12),I9<計算過程!$B$50),I9+1,I9)) -> 0 | J10: =IF(A10="","",IF(I10>I9,計算過程!$B$57,0)) -> 0 | K10: =IF(A10="","",IF(I10>I9,ROUND(M9*計算過程!$B$55,0),0)) -> 0 | L10: =IF(A10="","",J10-K10) -> 0 | M10: =IF(A10="","",IF(I10>I9,MAX(0,M9*(1+計算過程!$B$55)-計算過程!$B$56),M9)) -> 0 | N10: =IF(A10="","",C10+J10) -> 25809 | O10: =IF(A10="","",H10+M10) -> 1427222
A11: =IF(ROWS($A$8:A11)<=計算過程!$B$51,ROWS($A$8:A11),"") -> 4 | B11: =IF(A11="","",EDATE(計算過程!$B$71,A11-1)) -> 46447 | C11: =IF(A11="","",計算過程!$B$54) -> 25809 | D11: =IF(A11="","",ROUND(F10*計算過程!$B$24/12+G10*計算過程!$B$25/12,0)) -> 1499 | E11: =IF(A11="","",C11-D11) -> 24310 | F11: =IF(A11="","",MAX(0,F10*(1+計算過程!$B$24/12)-計算過程!$B$52)) -> 1402911.7 | G11: =IF(A11="","",MAX(0,G10*(1+計算過程!$B$25/12)-計算過程!$B$53)) -> 0 | H11: =IF(A11="","",F11+G11) -> 1402911.7 | I11: =IF(A11="","",IF(AND(OR(MONTH(B11)=6,MONTH(B11)=12),I10<計算過程!$B$50),I10+1,I10)) -> 0 | J11: =IF(A11="","",IF(I11>I10,計算過程!$B$57,0)) -> 0 | K11: =IF(A11="","",IF(I11>I10,ROUND(M10*計算過程!$B$55,0),0)) -> 0 | L11: =IF(A11="","",J11-K11) -> 0 | M11: =IF(A11="","",IF(I11>I10,MAX(0,M10*(1+計算過程!$B$55)-計算過程!$B$56),M10)) -> 0 | N11: =IF(A11="","",C11+J11) -> 25809 | O11: =IF(A11="","",H11+M11) -> 1402911.7
A12: =IF(ROWS($A$8:A12)<=計算過程!$B$51,ROWS($A$8:A12),"") -> 5 | B12: =IF(A12="","",EDATE(計算過程!$B$71,A12-1)) -> 46478 | C12: =IF(A12="","",計算過程!$B$54) -> 25809 | D12: =IF(A12="","",ROUND(F11*計算過程!$B$24/12+G11*計算過程!$B$25/12,0)) -> 1473 | E12: =IF(A12="","",C12-D12) -> 24336 | F12: =IF(A12="","",MAX(0,F11*(1+計算過程!$B$24/12)-計算過程!$B$52)) -> 1378575.8 | G12: =IF(A12="","",MAX(0,G11*(1+計算過程!$B$25/12)-計算過程!$B$53)) -> 0 | H12: =IF(A12="","",F12+G12) -> 1378575.8 | I12: =IF(A12="","",IF(AND(OR(MONTH(B12)=6,MONTH(B12)=12),I11<計算過程!$B$50),I11+1,I11)) -> 0 | J12: =IF(A12="","",IF(I12>I11,計算過程!$B$57,0)) -> 0 | K12: =IF(A12="","",IF(I12>I11,ROUND(M11*計算過程!$B$55,0),0)) -> 0 | L12: =IF(A12="","",J12-K12) -> 0 | M12: =IF(A12="","",IF(I12>I11,MAX(0,M11*(1+計算過程!$B$55)-計算過程!$B$56),M11)) -> 0 | N12: =IF(A12="","",C12+J12) -> 25809 | O12: =IF(A12="","",H12+M12) -> 1378575.8
A13: =IF(ROWS($A$8:A13)<=計算過程!$B$51,ROWS($A$8:A13),"") -> 6 | B13: =IF(A13="","",EDATE(計算過程!$B$71,A13-1)) -> 46508 | C13: =IF(A13="","",計算過程!$B$54) -> 25809 | D13: =IF(A13="","",ROUND(F12*計算過程!$B$24/12+G12*計算過程!$B$25/12,0)) -> 1448 | E13: =IF(A13="","",C13-D13) -> 24361 | F13: =IF(A13="","",MAX(0,F12*(1+計算過程!$B$24/12)-計算過程!$B$52)) -> 1354214.5 | G13: =IF(A13="","",MAX(0,G12*(1+計算過程!$B$25/12)-計算過程!$B$53)) -> 0 | H13: =IF(A13="","",F13+G13) -> 1354214.5 | I13: =IF(A13="","",IF(AND(OR(MONTH(B13)=6,MONTH(B13)=12),I12<計算過程!$B$50),I12+1,I12)) -> 0 | J13: =IF(A13="","",IF(I13>I12,計算過程!$B$57,0)) -> 0 | K13: =IF(A13="","",IF(I13>I12,ROUND(M12*計算過程!$B$55,0),0)) -> 0 | L13: =IF(A13="","",J13-K13) -> 0 | M13: =IF(A13="","",IF(I13>I12,MAX(0,M12*(1+計算過程!$B$55)-計算過程!$B$56),M12)) -> 0 | N13: =IF(A13="","",C13+J13) -> 25809 | O13: =IF(A13="","",H13+M13) -> 1354214.5
A14: =IF(ROWS($A$8:A14)<=計算過程!$B$51,ROWS($A$8:A14),"") -> 7 | B14: =IF(A14="","",EDATE(計算過程!$B$71,A14-1)) -> 46539 | C14: =IF(A14="","",計算過程!$B$54) -> 25809 | D14: =IF(A14="","",ROUND(F13*計算過程!$B$24/12+G13*計算過程!$B$25/12,0)) -> 1422 | E14: =IF(A14="","",C14-D14) -> 24387 | F14: =IF(A14="","",MAX(0,F13*(1+計算過程!$B$24/12)-計算過程!$B$52)) -> 1329827.5 | G14: =IF(A14="","",MAX(0,G13*(1+計算過程!$B$25/12)-計算過程!$B$53)) -> 0 | H14: =IF(A14="","",F14+G14) -> 1329827.5 | I14: =IF(A14="","",IF(AND(OR(MONTH(B14)=6,MONTH(B14)=12),I13<計算過程!$B$50),I13+1,I13)) -> 0 | J14: =IF(A14="","",IF(I14>I13,計算過程!$B$57,0)) -> 0 | K14: =IF(A14="","",IF(I14>I13,ROUND(M13*計算過程!$B$55,0),0)) -> 0 | L14: =IF(A14="","",J14-K14) -> 0 | M14: =IF(A14="","",IF(I14>I13,MAX(0,M13*(1+計算過程!$B$55)-計算過程!$B$56),M13)) -> 0 | N14: =IF(A14="","",C14+J14) -> 25809 | O14: =IF(A14="","",H14+M14) -> 1329827.5
A15: =IF(ROWS($A$8:A15)<=計算過程!$B$51,ROWS($A$8:A15),"") -> 8 | B15: =IF(A15="","",EDATE(計算過程!$B$71,A15-1)) -> 46569 | C15: =IF(A15="","",計算過程!$B$54) -> 25809 | D15: =IF(A15="","",ROUND(F14*計算過程!$B$24/12+G14*計算過程!$B$25/12,0)) -> 1396 | E15: =IF(A15="","",C15-D15) -> 24413 | F15: =IF(A15="","",MAX(0,F14*(1+計算過程!$B$24/12)-計算過程!$B$52)) -> 1305414.9 | G15: =IF(A15="","",MAX(0,G14*(1+計算過程!$B$25/12)-計算過程!$B$53)) -> 0 | H15: =IF(A15="","",F15+G15) -> 1305414.9 | I15: =IF(A15="","",IF(AND(OR(MONTH(B15)=6,MONTH(B15)=12),I14<計算過程!$B$50),I14+1,I14)) -> 0 | J15: =IF(A15="","",IF(I15>I14,計算過程!$B$57,0)) -> 0 | K15: =IF(A15="","",IF(I15>I14,ROUND(M14*計算過程!$B$55,0),0)) -> 0 | L15: =IF(A15="","",J15-K15) -> 0 | M15: =IF(A15="","",IF(I15>I14,MAX(0,M14*(1+計算過程!$B$55)-計算過程!$B$56),M14)) -> 0 | N15: =IF(A15="","",C15+J15) -> 25809 | O15: =IF(A15="","",H15+M15) -> 1305414.9
A16: =IF(ROWS($A$8:A16)<=計算過程!$B$51,ROWS($A$8:A16),"") -> 9 | B16: =IF(A16="","",EDATE(計算過程!$B$71,A16-1)) -> 46600 | C16: =IF(A16="","",計算過程!$B$54) -> 25809 | D16: =IF(A16="","",ROUND(F15*計算過程!$B$24/12+G15*計算過程!$B$25/12,0)) -> 1371 | E16: =IF(A16="","",C16-D16) -> 24438 | F16: =IF(A16="","",MAX(0,F15*(1+計算過程!$B$24/12)-計算過程!$B$52)) -> 1280976.7 | G16: =IF(A16="","",MAX(0,G15*(1+計算過程!$B$25/12)-計算過程!$B$53)) -> 0 | H16: =IF(A16="","",F16+G16) -> 1280976.7 | I16: =IF(A16="","",IF(AND(OR(MONTH(B16)=6,MONTH(B16)=12),I15<計算過程!$B$50),I15+1,I15)) -> 0 | J16: =IF(A16="","",IF(I16>I15,計算過程!$B$57,0)) -> 0 | K16: =IF(A16="","",IF(I16>I15,ROUND(M15*計算過程!$B$55,0),0)) -> 0 | L16: =IF(A16="","",J16-K16) -> 0 | M16: =IF(A16="","",IF(I16>I15,MAX(0,M15*(1+計算過程!$B$55)-計算過程!$B$56),M15)) -> 0 | N16: =IF(A16="","",C16+J16) -> 25809 | O16: =IF(A16="","",H16+M16) -> 1280976.7
A17: =IF(ROWS($A$8:A17)<=計算過程!$B$51,ROWS($A$8:A17),"") -> 10 | B17: =IF(A17="","",EDATE(計算過程!$B$71,A17-1)) -> 46631 | C17: =IF(A17="","",計算過程!$B$54) -> 25809 | D17: =IF(A17="","",ROUND(F16*計算過程!$B$24/12+G16*計算過程!$B$25/12,0)) -> 1345 | E17: =IF(A17="","",C17-D17) -> 24464 | F17: =IF(A17="","",MAX(0,F16*(1+計算過程!$B$24/12)-計算過程!$B$52)) -> 1256512.9 | G17: =IF(A17="","",MAX(0,G16*(1+計算過程!$B$25/12)-計算過程!$B$53)) -> 0 | H17: =IF(A17="","",F17+G17) -> 1256512.9 | I17: =IF(A17="","",IF(AND(OR(MONTH(B17)=6,MONTH(B17)=12),I16<計算過程!$B$50),I16+1,I16)) -> 0 | J17: =IF(A17="","",IF(I17>I16,計算過程!$B$57,0)) -> 0 | K17: =IF(A17="","",IF(I17>I16,ROUND(M16*計算過程!$B$55,0),0)) -> 0 | L17: =IF(A17="","",J17-K17) -> 0 | M17: =IF(A17="","",IF(I17>I16,MAX(0,M16*(1+計算過程!$B$55)-計算過程!$B$56),M16)) -> 0 | N17: =IF(A17="","",C17+J17) -> 25809 | O17: =IF(A17="","",H17+M17) -> 1256512.9
A18: =IF(ROWS($A$8:A18)<=計算過程!$B$51,ROWS($A$8:A18),"") -> 11 | B18: =IF(A18="","",EDATE(計算過程!$B$71,A18-1)) -> 46661 | C18: =IF(A18="","",計算過程!$B$54) -> 25809 | D18: =IF(A18="","",ROUND(F17*計算過程!$B$24/12+G17*計算過程!$B$25/12,0)) -> 1319 | E18: =IF(A18="","",C18-D18) -> 24490 | F18: =IF(A18="","",MAX(0,F17*(1+計算過程!$B$24/12)-計算過程!$B$52)) -> 1232023.3 | G18: =IF(A18="","",MAX(0,G17*(1+計算過程!$B$25/12)-計算過程!$B$53)) -> 0 | H18: =IF(A18="","",F18+G18) -> 1232023.3 | I18: =IF(A18="","",IF(AND(OR(MONTH(B18)=6,MONTH(B18)=12),I17<計算過程!$B$50),I17+1,I17)) -> 0 | J18: =IF(A18="","",IF(I18>I17,計算過程!$B$57,0)) -> 0 | K18: =IF(A18="","",IF(I18>I17,ROUND(M17*計算過程!$B$55,0),0)) -> 0 | L18: =IF(A18="","",J18-K18) -> 0 | M18: =IF(A18="","",IF(I18>I17,MAX(0,M17*(1+計算過程!$B$55)-計算過程!$B$56),M17)) -> 0 | N18: =IF(A18="","",C18+J18) -> 25809 | O18: =IF(A18="","",H18+M18) -> 1232023.3
A19: =IF(ROWS($A$8:A19)<=計算過程!$B$51,ROWS($A$8:A19),"") -> 12 | B19: =IF(A19="","",EDATE(計算過程!$B$71,A19-1)) -> 46692 | C19: =IF(A19="","",計算過程!$B$54) -> 25809 | D19: =IF(A19="","",ROUND(F18*計算過程!$B$24/12+G18*計算過程!$B$25/12,0)) -> 1294 | E19: =IF(A19="","",C19-D19) -> 24515 | F19: =IF(A19="","",MAX(0,F18*(1+計算過程!$B$24/12)-計算過程!$B$52)) -> 1207508.1 | G19: =IF(A19="","",MAX(0,G18*(1+計算過程!$B$25/12)-計算過程!$B$53)) -> 0 | H19: =IF(A19="","",F19+G19) -> 1207508.1 | I19: =IF(A19="","",IF(AND(OR(MONTH(B19)=6,MONTH(B19)=12),I18<計算過程!$B$50),I18+1,I18)) -> 0 | J19: =IF(A19="","",IF(I19>I18,計算過程!$B$57,0)) -> 0 | K19: =IF(A19="","",IF(I19>I18,ROUND(M18*計算過程!$B$55,0),0)) -> 0 | L19: =IF(A19="","",J19-K19) -> 0 | M19: =IF(A19="","",IF(I19>I18,MAX(0,M18*(1+計算過程!$B$55)-計算過程!$B$56),M18)) -> 0 | N19: =IF(A19="","",C19+J19) -> 25809 | O19: =IF(A19="","",H19+M19) -> 1207508.1
... A367: =IF(ROWS($A$8:A367)<=計算過程!$B$51,ROWS($A$8:A367),"") | B367: =IF(A367="","",EDATE(計算過程!$B$71,A367-1)) | C367: =IF(A367="","",計算過程!$B$54) | D367: =IF(A367="","",ROUND(F366*計算過程!$B$24/12+G366*計算過程!$B$25/12,0)) | E367: =IF(A367="","",C367-D367) | F367: =IF(A367="","",MAX(0,F366*(1+計算過程!$B$24/12)-計算過程!$B$52)) | G367: =IF(A367="","",MAX(0,G366*(1+計算過程!$B$25/12)-計算過程!$B$53)) | H367: =IF(A367="","",F367+G367) | I367: =IF(A367="","",IF(AND(OR(MONTH(B367)=6,MONTH(B367)=12),I366<計算過程!$B$50),I366+1,I366)) | J367: =IF(A367="","",IF(I367>I366,計算過程!$B$57,0)) | K367: =IF(A367="","",IF(I367>I366,ROUND(M366*計算過程!$B$55,0),0)) | L367: =IF(A367="","",J367-K367) | M367: =IF(A367="","",IF(I367>I366,MAX(0,M366*(1+計算過程!$B$55)-計算過程!$B$56),M366)) | N367: =IF(A367="","",C367+J367) | O367: =IF(A367="","",H367+M367)

Sheet 早見表
B1: 毎月償還額 早見表(元利均等・円)― 利率はマスタの値を使用、改定すると自動で変わります
B2: 概算です。ボーナス併用なし。実際の償還表と数円の差が出る場合があります。
B4: ="普通貸付・特別貸付(年利 "&TEXT(マスタ!$B$4,"0.00%")&")" -> 普通貸付・特別貸付(年利 1.26%)
B5: 申込金額＼償還回数 | C5: 12 | D5: 24 | E5: 36 | F5: 48 | G5: 60 | H5: 72 | I5: 84 | J5: 96 | K5: 108 | L5: 120
B6: 10 | C6: =ROUND(PMT(マスタ!$B$4/12,C$5,-$B6*10000),0) -> 8390 | D6: =ROUND(PMT(マスタ!$B$4/12,D$5,-$B6*10000),0) -> 4222 | E6: =ROUND(PMT(マスタ!$B$4/12,E$5,-$B6*10000),0) -> 2832 | F6: =ROUND(PMT(マスタ!$B$4/12,F$5,-$B6*10000),0) -> 2137 | G6: =ROUND(PMT(マスタ!$B$4/12,G$5,-$B6*10000),0) -> 1721 | H6: =ROUND(PMT(マスタ!$B$4/12,H$5,-$B6*10000),0) -> 1443 | I6: =ROUND(PMT(マスタ!$B$4/12,I$5,-$B6*10000),0) -> 1244 | J6: =ROUND(PMT(マスタ!$B$4/12,J$5,-$B6*10000),0) -> 1096 | ... L6: =ROUND(PMT(マスタ!$B$4/12,L$5,-$B6*10000),0) -> 887
B7: 20 | C7: =ROUND(PMT(マスタ!$B$4/12,C$5,-$B7*10000),0) -> 16781 | D7: =ROUND(PMT(マスタ!$B$4/12,D$5,-$B7*10000),0) -> 8443 | E7: =ROUND(PMT(マスタ!$B$4/12,E$5,-$B7*10000),0) -> 5664 | F7: =ROUND(PMT(マスタ!$B$4/12,F$5,-$B7*10000),0) -> 4275 | G7: =ROUND(PMT(マスタ!$B$4/12,G$5,-$B7*10000),0) -> 3441 | H7: =ROUND(PMT(マスタ!$B$4/12,H$5,-$B7*10000),0) -> 2886 | I7: =ROUND(PMT(マスタ!$B$4/12,I$5,-$B7*10000),0) -> 2489 | J7: =ROUND(PMT(マスタ!$B$4/12,J$5,-$B7*10000),0) -> 2191 | ... L7: =ROUND(PMT(マスタ!$B$4/12,L$5,-$B7*10000),0) -> 1775
B8: 30 | C8: =ROUND(PMT(マスタ!$B$4/12,C$5,-$B8*10000),0) -> 25171 | D8: =ROUND(PMT(マスタ!$B$4/12,D$5,-$B8*10000),0) -> 12665 | E8: =ROUND(PMT(マスタ!$B$4/12,E$5,-$B8*10000),0) -> 8496 | F8: =ROUND(PMT(マスタ!$B$4/12,F$5,-$B8*10000),0) -> 6412 | G8: =ROUND(PMT(マスタ!$B$4/12,G$5,-$B8*10000),0) -> 5162 | H8: =ROUND(PMT(マスタ!$B$4/12,H$5,-$B8*10000),0) -> 4328 | I8: =ROUND(PMT(マスタ!$B$4/12,I$5,-$B8*10000),0) -> 3733 | J8: =ROUND(PMT(マスタ!$B$4/12,J$5,-$B8*10000),0) -> 3287 | ... L8: =ROUND(PMT(マスタ!$B$4/12,L$5,-$B8*10000),0) -> 2662
B9: 40 | C9: =ROUND(PMT(マスタ!$B$4/12,C$5,-$B9*10000),0) -> 33561 | D9: =ROUND(PMT(マスタ!$B$4/12,D$5,-$B9*10000),0) -> 16886 | E9: =ROUND(PMT(マスタ!$B$4/12,E$5,-$B9*10000),0) -> 11328 | F9: =ROUND(PMT(マスタ!$B$4/12,F$5,-$B9*10000),0) -> 8549 | G9: =ROUND(PMT(マスタ!$B$4/12,G$5,-$B9*10000),0) -> 6882 | H9: =ROUND(PMT(マスタ!$B$4/12,H$5,-$B9*10000),0) -> 5771 | I9: =ROUND(PMT(マスタ!$B$4/12,I$5,-$B9*10000),0) -> 4977 | J9: =ROUND(PMT(マスタ!$B$4/12,J$5,-$B9*10000),0) -> 4382 | ... L9: =ROUND(PMT(マスタ!$B$4/12,L$5,-$B9*10000),0) -> 3549
B10: 50 | C10: =ROUND(PMT(マスタ!$B$4/12,C$5,-$B10*10000),0) -> 41952 | D10: =ROUND(PMT(マスタ!$B$4/12,D$5,-$B10*10000),0) -> 21108 | E10: =ROUND(PMT(マスタ!$B$4/12,E$5,-$B10*10000),0) -> 14160 | F10: =ROUND(PMT(マスタ!$B$4/12,F$5,-$B10*10000),0) -> 10687 | G10: =ROUND(PMT(マスタ!$B$4/12,G$5,-$B10*10000),0) -> 8603 | H10: =ROUND(PMT(マスタ!$B$4/12,H$5,-$B10*10000),0) -> 7214 | I10: =ROUND(PMT(マスタ!$B$4/12,I$5,-$B10*10000),0) -> 6222 | J10: =ROUND(PMT(マスタ!$B$4/12,J$5,-$B10*10000),0) -> 5478 | ... L10: =ROUND(PMT(マスタ!$B$4/12,L$5,-$B10*10000),0) -> 4437
B11: 60 | C11: =ROUND(PMT(マスタ!$B$4/12,C$5,-$B11*10000),0) -> 50342 | D11: =ROUND(PMT(マスタ!$B$4/12,D$5,-$B11*10000),0) -> 25329 | E11: =ROUND(PMT(マスタ!$B$4/12,E$5,-$B11*10000),0) -> 16992 | F11: =ROUND(PMT(マスタ!$B$4/12,F$5,-$B11*10000),0) -> 12824 | G11: =ROUND(PMT(マスタ!$B$4/12,G$5,-$B11*10000),0) -> 10324 | H11: =ROUND(PMT(マスタ!$B$4/12,H$5,-$B11*10000),0) -> 8657 | I11: =ROUND(PMT(マスタ!$B$4/12,I$5,-$B11*10000),0) -> 7466 | J11: =ROUND(PMT(マスタ!$B$4/12,J$5,-$B11*10000),0) -> 6574 | ... L11: =ROUND(PMT(マスタ!$B$4/12,L$5,-$B11*10000),0) -> 5324
B12: 70 | C12: =ROUND(PMT(マスタ!$B$4/12,C$5,-$B12*10000),0) -> 58732 | D12: =ROUND(PMT(マスタ!$B$4/12,D$5,-$B12*10000),0) -> 29551 | E12: =ROUND(PMT(マスタ!$B$4/12,E$5,-$B12*10000),0) -> 19824 | F12: =ROUND(PMT(マスタ!$B$4/12,F$5,-$B12*10000),0) -> 14962 | G12: =ROUND(PMT(マスタ!$B$4/12,G$5,-$B12*10000),0) -> 12044 | H12: =ROUND(PMT(マスタ!$B$4/12,H$5,-$B12*10000),0) -> 10099 | I12: =ROUND(PMT(マスタ!$B$4/12,I$5,-$B12*10000),0) -> 8711 | J12: =ROUND(PMT(マスタ!$B$4/12,J$5,-$B12*10000),0) -> 7669 | ... L12: =ROUND(PMT(マスタ!$B$4/12,L$5,-$B12*10000),0) -> 6212
B13: 80 | C13: =ROUND(PMT(マスタ!$B$4/12,C$5,-$B13*10000),0) -> 67123 | D13: =ROUND(PMT(マスタ!$B$4/12,D$5,-$B13*10000),0) -> 33773 | E13: =ROUND(PMT(マスタ!$B$4/12,E$5,-$B13*10000),0) -> 22657 | F13: =ROUND(PMT(マスタ!$B$4/12,F$5,-$B13*10000),0) -> 17099 | G13: =ROUND(PMT(マスタ!$B$4/12,G$5,-$B13*10000),0) -> 13765 | H13: =ROUND(PMT(マスタ!$B$4/12,H$5,-$B13*10000),0) -> 11542 | I13: =ROUND(PMT(マスタ!$B$4/12,I$5,-$B13*10000),0) -> 9955 | J13: =ROUND(PMT(マスタ!$B$4/12,J$5,-$B13*10000),0) -> 8765 | ... L13: =ROUND(PMT(マスタ!$B$4/12,L$5,-$B13*10000),0) -> 7099
B14: 90 | C14: =ROUND(PMT(マスタ!$B$4/12,C$5,-$B14*10000),0) -> 75513 | D14: =ROUND(PMT(マスタ!$B$4/12,D$5,-$B14*10000),0) -> 37994 | E14: =ROUND(PMT(マスタ!$B$4/12,E$5,-$B14*10000),0) -> 25489 | F14: =ROUND(PMT(マスタ!$B$4/12,F$5,-$B14*10000),0) -> 19236 | G14: =ROUND(PMT(マスタ!$B$4/12,G$5,-$B14*10000),0) -> 15485 | H14: =ROUND(PMT(マスタ!$B$4/12,H$5,-$B14*10000),0) -> 12985 | I14: =ROUND(PMT(マスタ!$B$4/12,I$5,-$B14*10000),0) -> 11199 | J14: =ROUND(PMT(マスタ!$B$4/12,J$5,-$B14*10000),0) -> 9860 | ... L14: =ROUND(PMT(マスタ!$B$4/12,L$5,-$B14*10000),0) -> 7986
B15: 100 | C15: =ROUND(PMT(マスタ!$B$4/12,C$5,-$B15*10000),0) -> 83903 | D15: =ROUND(PMT(マスタ!$B$4/12,D$5,-$B15*10000),0) -> 42216 | E15: =ROUND(PMT(マスタ!$B$4/12,E$5,-$B15*10000),0) -> 28321 | F15: =ROUND(PMT(マスタ!$B$4/12,F$5,-$B15*10000),0) -> 21374 | G15: =ROUND(PMT(マスタ!$B$4/12,G$5,-$B15*10000),0) -> 17206 | H15: =ROUND(PMT(マスタ!$B$4/12,H$5,-$B15*10000),0) -> 14428 | I15: =ROUND(PMT(マスタ!$B$4/12,I$5,-$B15*10000),0) -> 12444 | J15: =ROUND(PMT(マスタ!$B$4/12,J$5,-$B15*10000),0) -> 10956 | ... L15: =ROUND(PMT(マスタ!$B$4/12,L$5,-$B15*10000),0) -> 8874
B16: 110 | C16: =ROUND(PMT(マスタ!$B$4/12,C$5,-$B16*10000),0) -> 92293 | D16: =ROUND(PMT(マスタ!$B$4/12,D$5,-$B16*10000),0) -> 46437 | E16: =ROUND(PMT(マスタ!$B$4/12,E$5,-$B16*10000),0) -> 31153 | F16: =ROUND(PMT(マスタ!$B$4/12,F$5,-$B16*10000),0) -> 23511 | G16: =ROUND(PMT(マスタ!$B$4/12,G$5,-$B16*10000),0) -> 18927 | H16: =ROUND(PMT(マスタ!$B$4/12,H$5,-$B16*10000),0) -> 15871 | I16: =ROUND(PMT(マスタ!$B$4/12,I$5,-$B16*10000),0) -> 13688 | J16: =ROUND(PMT(マスタ!$B$4/12,J$5,-$B16*10000),0) -> 12052 | ... L16: =ROUND(PMT(マスタ!$B$4/12,L$5,-$B16*10000),0) -> 9761
B17: 120 | C17: =ROUND(PMT(マスタ!$B$4/12,C$5,-$B17*10000),0) -> 100684 | D17: =ROUND(PMT(マスタ!$B$4/12,D$5,-$B17*10000),0) -> 50659 | E17: =ROUND(PMT(マスタ!$B$4/12,E$5,-$B17*10000),0) -> 33985 | F17: =ROUND(PMT(マスタ!$B$4/12,F$5,-$B17*10000),0) -> 25648 | G17: =ROUND(PMT(マスタ!$B$4/12,G$5,-$B17*10000),0) -> 20647 | H17: =ROUND(PMT(マスタ!$B$4/12,H$5,-$B17*10000),0) -> 17313 | I17: =ROUND(PMT(マスタ!$B$4/12,I$5,-$B17*10000),0) -> 14932 | J17: =ROUND(PMT(マスタ!$B$4/12,J$5,-$B17*10000),0) -> 13147 | ... L17: =ROUND(PMT(マスタ!$B$4/12,L$5,-$B17*10000),0) -> 10648
... B25: 200 | C25: =ROUND(PMT(マスタ!$B$4/12,C$5,-$B25*10000),0) -> 167806 | D25: =ROUND(PMT(マスタ!$B$4/12,D$5,-$B25*10000),0) -> 84431 | E25: =ROUND(PMT(マスタ!$B$4/12,E$5,-$B25*10000),0) -> 56641 | F25: =ROUND(PMT(マスタ!$B$4/12,F$5,-$B25*10000),0) -> 42747 | G25: =ROUND(PMT(マスタ!$B$4/12,G$5,-$B25*10000),0) -> 34412 | H25: =ROUND(PMT(マスタ!$B$4/12,H$5,-$B25*10000),0) -> 28856 | I25: =ROUND(PMT(マスタ!$B$4/12,I$5,-$B25*10000),0) -> 24887 | J25: =ROUND(PMT(マスタ!$B$4/12,J$5,-$B25*10000),0) -> 21912 | ... L25: =ROUND(PMT(マスタ!$B$4/12,L$5,-$B25*10000),0) -> 17747
B28: ="住宅貸付(年利 "&TEXT(マスタ!$B$5,"0.00%")&")" -> 住宅貸付(年利 1.26%)
B29: 申込金額＼償還回数 | C29: 60 | D29: 120 | E29: 180 | F29: 240 | G29: 300 | H29: 360
B30: 100 | C30: =ROUND(PMT(マスタ!$B$5/12,C$29,-$B30*10000),0) -> 17206 | D30: =ROUND(PMT(マスタ!$B$5/12,D$29,-$B30*10000),0) -> 8874 | E30: =ROUND(PMT(マスタ!$B$5/12,E$29,-$B30*10000),0) -> 6100 | F30: =ROUND(PMT(マスタ!$B$5/12,F$29,-$B30*10000),0) -> 4716 | G30: =ROUND(PMT(マスタ!$B$5/12,G$29,-$B30*10000),0) -> 3888 | H30: =ROUND(PMT(マスタ!$B$5/12,H$29,-$B30*10000),0) -> 3337
B31: 200 | C31: =ROUND(PMT(マスタ!$B$5/12,C$29,-$B31*10000),0) -> 34412 | D31: =ROUND(PMT(マスタ!$B$5/12,D$29,-$B31*10000),0) -> 17747 | E31: =ROUND(PMT(マスタ!$B$5/12,E$29,-$B31*10000),0) -> 12200 | F31: =ROUND(PMT(マスタ!$B$5/12,F$29,-$B31*10000),0) -> 9432 | G31: =ROUND(PMT(マスタ!$B$5/12,G$29,-$B31*10000),0) -> 7775 | H31: =ROUND(PMT(マスタ!$B$5/12,H$29,-$B31*10000),0) -> 6674
B32: 300 | C32: =ROUND(PMT(マスタ!$B$5/12,C$29,-$B32*10000),0) -> 51618 | D32: =ROUND(PMT(マスタ!$B$5/12,D$29,-$B32*10000),0) -> 26621 | E32: =ROUND(PMT(マスタ!$B$5/12,E$29,-$B32*10000),0) -> 18300 | F32: =ROUND(PMT(マスタ!$B$5/12,F$29,-$B32*10000),0) -> 14148 | G32: =ROUND(PMT(マスタ!$B$5/12,G$29,-$B32*10000),0) -> 11663 | H32: =ROUND(PMT(マスタ!$B$5/12,H$29,-$B32*10000),0) -> 10012
B33: 400 | C33: =ROUND(PMT(マスタ!$B$5/12,C$29,-$B33*10000),0) -> 68824 | D33: =ROUND(PMT(マスタ!$B$5/12,D$29,-$B33*10000),0) -> 35495 | E33: =ROUND(PMT(マスタ!$B$5/12,E$29,-$B33*10000),0) -> 24400 | F33: =ROUND(PMT(マスタ!$B$5/12,F$29,-$B33*10000),0) -> 18863 | G33: =ROUND(PMT(マスタ!$B$5/12,G$29,-$B33*10000),0) -> 15550 | H33: =ROUND(PMT(マスタ!$B$5/12,H$29,-$B33*10000),0) -> 13349
B34: 500 | C34: =ROUND(PMT(マスタ!$B$5/12,C$29,-$B34*10000),0) -> 86030 | D34: =ROUND(PMT(マスタ!$B$5/12,D$29,-$B34*10000),0) -> 44369 | E34: =ROUND(PMT(マスタ!$B$5/12,E$29,-$B34*10000),0) -> 30500 | F34: =ROUND(PMT(マスタ!$B$5/12,F$29,-$B34*10000),0) -> 23579 | G34: =ROUND(PMT(マスタ!$B$5/12,G$29,-$B34*10000),0) -> 19438 | H34: =ROUND(PMT(マスタ!$B$5/12,H$29,-$B34*10000),0) -> 16686
B35: 600 | C35: =ROUND(PMT(マスタ!$B$5/12,C$29,-$B35*10000),0) -> 103236 | D35: =ROUND(PMT(マスタ!$B$5/12,D$29,-$B35*10000),0) -> 53242 | E35: =ROUND(PMT(マスタ!$B$5/12,E$29,-$B35*10000),0) -> 36600 | F35: =ROUND(PMT(マスタ!$B$5/12,F$29,-$B35*10000),0) -> 28295 | G35: =ROUND(PMT(マスタ!$B$5/12,G$29,-$B35*10000),0) -> 23326 | H35: =ROUND(PMT(マスタ!$B$5/12,H$29,-$B35*10000),0) -> 20023
B36: 700 | C36: =ROUND(PMT(マスタ!$B$5/12,C$29,-$B36*10000),0) -> 120441 | D36: =ROUND(PMT(マスタ!$B$5/12,D$29,-$B36*10000),0) -> 62116 | E36: =ROUND(PMT(マスタ!$B$5/12,E$29,-$B36*10000),0) -> 42700 | F36: =ROUND(PMT(マスタ!$B$5/12,F$29,-$B36*10000),0) -> 33011 | G36: =ROUND(PMT(マスタ!$B$5/12,G$29,-$B36*10000),0) -> 27213 | H36: =ROUND(PMT(マスタ!$B$5/12,H$29,-$B36*10000),0) -> 23361
B37: 800 | C37: =ROUND(PMT(マスタ!$B$5/12,C$29,-$B37*10000),0) -> 137647 | D37: =ROUND(PMT(マスタ!$B$5/12,D$29,-$B37*10000),0) -> 70990 | E37: =ROUND(PMT(マスタ!$B$5/12,E$29,-$B37*10000),0) -> 48800 | F37: =ROUND(PMT(マスタ!$B$5/12,F$29,-$B37*10000),0) -> 37727 | G37: =ROUND(PMT(マスタ!$B$5/12,G$29,-$B37*10000),0) -> 31101 | H37: =ROUND(PMT(マスタ!$B$5/12,H$29,-$B37*10000),0) -> 26698
B38: 900 | C38: =ROUND(PMT(マスタ!$B$5/12,C$29,-$B38*10000),0) -> 154853 | D38: =ROUND(PMT(マスタ!$B$5/12,D$29,-$B38*10000),0) -> 79864 | E38: =ROUND(PMT(マスタ!$B$5/12,E$29,-$B38*10000),0) -> 54900 | F38: =ROUND(PMT(マスタ!$B$5/12,F$29,-$B38*10000),0) -> 42443 | G38: =ROUND(PMT(マスタ!$B$5/12,G$29,-$B38*10000),0) -> 34988 | H38: =ROUND(PMT(マスタ!$B$5/12,H$29,-$B38*10000),0) -> 30035
B39: 1000 | C39: =ROUND(PMT(マスタ!$B$5/12,C$29,-$B39*10000),0) -> 172059 | D39: =ROUND(PMT(マスタ!$B$5/12,D$29,-$B39*10000),0) -> 88737 | E39: =ROUND(PMT(マスタ!$B$5/12,E$29,-$B39*10000),0) -> 61000 | F39: =ROUND(PMT(マスタ!$B$5/12,F$29,-$B39*10000),0) -> 47159 | G39: =ROUND(PMT(マスタ!$B$5/12,G$29,-$B39*10000),0) -> 38876 | H39: =ROUND(PMT(マスタ!$B$5/12,H$29,-$B39*10000),0) -> 33372
B40: 1100 | C40: =ROUND(PMT(マスタ!$B$5/12,C$29,-$B40*10000),0) -> 189265 | D40: =ROUND(PMT(マスタ!$B$5/12,D$29,-$B40*10000),0) -> 97611 | E40: =ROUND(PMT(マスタ!$B$5/12,E$29,-$B40*10000),0) -> 67100 | F40: =ROUND(PMT(マスタ!$B$5/12,F$29,-$B40*10000),0) -> 51875 | G40: =ROUND(PMT(マスタ!$B$5/12,G$29,-$B40*10000),0) -> 42763 | H40: =ROUND(PMT(マスタ!$B$5/12,H$29,-$B40*10000),0) -> 36709
B41: 1200 | C41: =ROUND(PMT(マスタ!$B$5/12,C$29,-$B41*10000),0) -> 206471 | D41: =ROUND(PMT(マスタ!$B$5/12,D$29,-$B41*10000),0) -> 106485 | E41: =ROUND(PMT(マスタ!$B$5/12,E$29,-$B41*10000),0) -> 73200 | F41: =ROUND(PMT(マスタ!$B$5/12,F$29,-$B41*10000),0) -> 56590 | G41: =ROUND(PMT(マスタ!$B$5/12,G$29,-$B41*10000),0) -> 46651 | H41: =ROUND(PMT(マスタ!$B$5/12,H$29,-$B41*10000),0) -> 40047
... B47: 1800 | C47: =ROUND(PMT(マスタ!$B$5/12,C$29,-$B47*10000),0) -> 309707 | D47: =ROUND(PMT(マスタ!$B$5/12,D$29,-$B47*10000),0) -> 159727 | E47: =ROUND(PMT(マスタ!$B$5/12,E$29,-$B47*10000),0) -> 109800 | F47: =ROUND(PMT(マスタ!$B$5/12,F$29,-$B47*10000),0) -> 84886 | G47: =ROUND(PMT(マスタ!$B$5/12,G$29,-$B47*10000),0) -> 69977 | H47: =ROUND(PMT(マスタ!$B$5/12,H$29,-$B47*10000),0) -> 60070
B50: ="災害貸付(年利 "&TEXT(マスタ!$B$6,"0.00%")&")" -> 災害貸付(年利 0.93%)
B51: 申込金額＼償還回数 | C51: 60 | D51: 120 | E51: 180 | F51: 240 | G51: 300 | H51: 360
B52: 100 | C52: =ROUND(PMT(マスタ!$B$6/12,C$51,-$B52*10000),0) -> 17064 | D52: =ROUND(PMT(マスタ!$B$6/12,D$51,-$B52*10000),0) -> 8730 | E52: =ROUND(PMT(マスタ!$B$6/12,E$51,-$B52*10000),0) -> 5954 | F52: =ROUND(PMT(マスタ!$B$6/12,F$51,-$B52*10000),0) -> 4568 | G52: =ROUND(PMT(マスタ!$B$6/12,G$51,-$B52*10000),0) -> 3737 | H52: =ROUND(PMT(マスタ!$B$6/12,H$51,-$B52*10000),0) -> 3184
B53: 200 | C53: =ROUND(PMT(マスタ!$B$6/12,C$51,-$B53*10000),0) -> 34127 | D53: =ROUND(PMT(マスタ!$B$6/12,D$51,-$B53*10000),0) -> 17460 | E53: =ROUND(PMT(マスタ!$B$6/12,E$51,-$B53*10000),0) -> 11908 | F53: =ROUND(PMT(マスタ!$B$6/12,F$51,-$B53*10000),0) -> 9136 | G53: =ROUND(PMT(マスタ!$B$6/12,G$51,-$B53*10000),0) -> 7474 | H53: =ROUND(PMT(マスタ!$B$6/12,H$51,-$B53*10000),0) -> 6369
B54: 300 | C54: =ROUND(PMT(マスタ!$B$6/12,C$51,-$B54*10000),0) -> 51191 | D54: =ROUND(PMT(マスタ!$B$6/12,D$51,-$B54*10000),0) -> 26190 | E54: =ROUND(PMT(マスタ!$B$6/12,E$51,-$B54*10000),0) -> 17863 | F54: =ROUND(PMT(マスタ!$B$6/12,F$51,-$B54*10000),0) -> 13703 | G54: =ROUND(PMT(マスタ!$B$6/12,G$51,-$B54*10000),0) -> 11211 | H54: =ROUND(PMT(マスタ!$B$6/12,H$51,-$B54*10000),0) -> 9553
B55: 400 | C55: =ROUND(PMT(マスタ!$B$6/12,C$51,-$B55*10000),0) -> 68255 | D55: =ROUND(PMT(マスタ!$B$6/12,D$51,-$B55*10000),0) -> 34920 | E55: =ROUND(PMT(マスタ!$B$6/12,E$51,-$B55*10000),0) -> 23817 | F55: =ROUND(PMT(マスタ!$B$6/12,F$51,-$B55*10000),0) -> 18271 | G55: =ROUND(PMT(マスタ!$B$6/12,G$51,-$B55*10000),0) -> 14948 | H55: =ROUND(PMT(マスタ!$B$6/12,H$51,-$B55*10000),0) -> 12737
B56: 500 | C56: =ROUND(PMT(マスタ!$B$6/12,C$51,-$B56*10000),0) -> 85318 | D56: =ROUND(PMT(マスタ!$B$6/12,D$51,-$B56*10000),0) -> 43650 | E56: =ROUND(PMT(マスタ!$B$6/12,E$51,-$B56*10000),0) -> 29771 | F56: =ROUND(PMT(マスタ!$B$6/12,F$51,-$B56*10000),0) -> 22839 | G56: =ROUND(PMT(マスタ!$B$6/12,G$51,-$B56*10000),0) -> 18686 | H56: =ROUND(PMT(マスタ!$B$6/12,H$51,-$B56*10000),0) -> 15922
B57: 600 | C57: =ROUND(PMT(マスタ!$B$6/12,C$51,-$B57*10000),0) -> 102382 | D57: =ROUND(PMT(マスタ!$B$6/12,D$51,-$B57*10000),0) -> 52380 | E57: =ROUND(PMT(マスタ!$B$6/12,E$51,-$B57*10000),0) -> 35725 | F57: =ROUND(PMT(マスタ!$B$6/12,F$51,-$B57*10000),0) -> 27407 | G57: =ROUND(PMT(マスタ!$B$6/12,G$51,-$B57*10000),0) -> 22423 | H57: =ROUND(PMT(マスタ!$B$6/12,H$51,-$B57*10000),0) -> 19106
...

Sheet マスタ
A1: マスタ(制度の数値・書類表)― 制度改正・利率改定時はここだけ修正します
A2: 青字=入力値(制度から転記した値)。出典:広島市職員共済組合ハンドブック(令和8年度改訂版)p.40〜45、貸付金借用証書(様式第4号)、借入状況等申告書
A3: 1. 利率・基準値(令和8年4月1日現在)
A4: 普通貸付・特別貸付の利率(年) | B4: 0.0126 | C4: ハンドブックp.41 変動利率
A5: 住宅貸付の利率(年) | B5: 0.0126 | C5: ハンドブックp.42 変動利率
A6: 災害貸付の利率(年) | B6: 0.0093 | C6: ハンドブックp.45 変動利率
A7: 在宅介護対応住宅(加算部分)の利率差 | B7: 0.0026 | C7: 住宅貸付の利率より年0.26%低い(借用証書では年1.00%)
A8: 償還額割合の上限(給料月額・年収額) | B8: 0.3 | C8: 他の金融機関等を含む。30%超は貸付不可
A9: 年収額の算定に用いるボーナス月数 | B9: 4 | C9: 借入状況等申告書「｛Ｋ×12＋Ｋ×4｝」より
A10: 申込金額の下限(万円) | B10: 10 | C10: 全貸付共通(10万円以上)
A11: 在宅介護対応住宅の加算限度額(万円) | B11: 300 | C11: 該当部分の金額に対し300万円を限度に加算
A12: ボーナス併用:申込金額の下限(万円) | B12: 300 | C12: 申込金額が300万円以上の場合
A13: ボーナス償還分の下限(万円) | B13: 100 | C13: 100万円以上
A14: ボーナス償還分の上限(貸付金額に対する割合) | B14: 0.5 | C14: 貸付金額の1/2以内
A15: ボーナス償還分の単位(万円) | B15: 5 | C15: 5万円単位
... A18: 修学貸付:1か月あたりの貸付額(万円) | B18: 15 | C18: 1か月につき15万円(学年単位、修業年限以内)
A20: 2. 貸付区分表(区分ごとの限度額・単位・償還回数・書類・日程のルール)
A21: 貸付区分 | B21: 区分群 | C21: 限度額の計算方式 | D21: 給料月数 | E21: 上限額(万円) | F21: 申込単位(万円) | G21: 償還回数の上限 | H21: 利率種別 | I21: 申込締切日(毎月○日) | J21: 住宅書類の列No | K21: 事由別の添付書類 | L21: 申込時期 | M21: 基準日の名称 | N21: 申込可能期間:基準日の何か月前から | O21: 申込可能期間:基準日の何か月後まで | P21: 貸付金交付後の提出書類 | Q21: 交付後の提出期限(月) | R21: 期限の起算 | S21: 貸付決定(目安)
A22: 普通貸付:自動車購入 | B22: 普通貸付 | C22: 月数 | D22: 6 | E22: 200 | F22: 1 | G22: 120 | H22: 通常 | I22: 5 | J22: 0 | K22: 注文書(写)又は発注書(写)(見積書は不可) | L22: 自動車登録(名義変更)前で代金支払前 | M22: 自動車の登録(予定)日 | P22: 完了届(自動車検査証(写)及び自動車検査証記録事項(写)を添付) | Q22: 2 | R22: 交付日 | S22: 締切日の同月10日頃
A23: 普通貸付:出産 | B23: 普通貸付 | C23: 月数 | D23: 6 | E23: 20 | F23: 1 | G23: 120 | H23: 通常 | I23: 5 | J23: 0 | K23: 母子手帳(写)又は出産証明書 | L23: 出産日(又は予定日)の前後3か月以内 | M23: 出産日(予定日) | N23: 3 | O23: 3 | S23: 締切日の同月10日頃
A24: 特別貸付:入学(大学等) | B24: 特別貸付 | C24: 月数 | D24: 6 | E24: 200 | F24: 1 | G24: 120 | H24: 通常 | I24: 5 | J24: 0 | K24: 合格通知書(写)又は入学許可書(写) | L24: 合格の時から入学後2か月以内 | M24: 入学日 | O24: 2 | P24: 在学証明書(入学後の申込みは貸付金交付後1か月以内) | Q24: 1 | R24: 入学 | S24: 締切日の同月10日頃
A25: 特別貸付:入学(高校) | B25: 特別貸付 | C25: 月数 | D25: 6 | E25: 30 | F25: 1 | G25: 120 | H25: 通常 | I25: 5 | J25: 0 | K25: 合格通知書(写)又は入学許可書(写) | L25: 合格の時から入学後2か月以内 | M25: 入学日 | O25: 2 | P25: 在学証明書(入学後の申込みは貸付金交付後1か月以内) | Q25: 1 | R25: 入学 | S25: 締切日の同月10日頃
A26: 特別貸付:修学 | B26: 特別貸付 | C26: 修学 | F26: 1 | G26: 150 | H26: 通常 | I26: 5 | J26: 0 | K26: 在学証明書(写) ※入学前は合格通知書(写)又は入学許可書(写) | L26: 修学期間中 | M26: 修学期間の開始日 | P26: 新年度の在学証明書 | Q26: 2 | R26: 交付日 | S26: 締切日の同月10日頃
A27: 特別貸付:結婚 | B27: 特別貸付 | C27: 月数 | D27: 6 | E27: 200 | F27: 1 | G27: 120 | H27: 通常 | I27: 5 | J27: 0 | K27: [婚姻前]案内状又は媒酌人等の証明 / [婚姻後]婚姻を証明する書類(戸籍抄本等) | L27: 婚姻前6か月以内・婚姻後3か月以内 | M27: 婚姻日(予定日) | N27: 6 | O27: 3 | P27: 婚姻を証明する書類(戸籍抄本) | Q27: 1 | R27: 事由日 | S27: 締切日の同月10日頃
A28: 特別貸付:葬祭 | B28: 特別貸付 | C28: 月数 | D28: 6 | E28: 200 | F28: 1 | G28: 120 | H28: 通常 | I28: 5 | J28: 0 | K28: 死亡診断書(写)又は埋火葬許可書(写)/続柄の確認できるもの/請求書(写)等 | L28: 葬祭の日から3か月以内 | M28: 葬祭日 | N28: 0 | O28: 3 | S28: 締切日の同月10日頃
A29: 特別貸付:医療 | B29: 特別貸付 | C29: 月数 | D29: 6 | E29: 100 | F29: 1 | G29: 120 | H29: 通常 | I29: 5 | J29: 0 | K29: 診断書等(病名・術式・費用・療養期間等を明示したもの) | L29: 療養期間中 | M29: 療養開始日 | S29: 締切日の同月10日頃
A30: 住宅貸付:土地付住宅購入(新築物件) | B30: 住宅貸付 | C30: 住宅 | E30: 1800 | F30: 5 | G30: 360 | H30: 住宅 | I30: 20 | J30: 1 | K30: (表1) | L30: 物件購入(引渡し及び登記)前 | M30: 引渡し予定日 | Q30: 6 | R30: 交付日 | S30: ハンドブックには「締切日の同月10日頃」と記載(要確認)
A31: 住宅貸付:土地付住宅購入(中古物件) | B31: 住宅貸付 | C31: 住宅 | E31: 1800 | F31: 5 | G31: 360 | H31: 住宅 | I31: 20 | J31: 2 | K31: (表1) | L31: 物件購入(引渡し及び登記)前 | M31: 引渡し予定日 | Q31: 6 | R31: 交付日 | S31: ハンドブックには「締切日の同月10日頃」と記載(要確認)
A32: 住宅貸付:土地購入 | B32: 住宅貸付 | C32: 住宅 | E32: 1800 | F32: 5 | G32: 360 | H32: 住宅 | I32: 20 | J32: 3 | K32: (表1) | L32: 物件購入(引渡し及び登記)前 | M32: 引渡し予定日 | Q32: 6 | R32: 交付日 | S32: ハンドブックには「締切日の同月10日頃」と記載(要確認)
A33: 住宅貸付:土地購入・住宅の新築 | B33: 住宅貸付 | C33: 住宅 | E33: 1800 | F33: 5 | G33: 360 | H33: 住宅 | I33: 20 | J33: 4 | K33: (表1) | L33: 物件購入(引渡し及び登記)前 | M33: 引渡し予定日 | Q33: 6 | R33: 交付日 | S33: ハンドブックには「締切日の同月10日頃」と記載(要確認)
A34: 住宅貸付:住宅の新築 | B34: 住宅貸付 | C34: 住宅 | E34: 1800 | F34: 5 | G34: 360 | H34: 住宅 | I34: 20 | J34: 5 | K34: (表1) | L34: 工事完了前 | M34: 工事完了予定日 | Q34: 6 | R34: 交付日 | S34: ハンドブックには「締切日の同月10日頃」と記載(要確認)
A35: 住宅貸付:住宅の増築・改築 | B35: 住宅貸付 | C35: 住宅 | E35: 1800 | F35: 5 | G35: 360 | H35: 住宅 | I35: 20 | J35: 6 | K35: (表1) | L35: 工事完了前 | M35: 工事完了予定日 | Q35: 6 | R35: 交付日 | S35: ハンドブックには「締切日の同月10日頃」と記載(要確認)
A36: 住宅貸付:修理 | B36: 住宅貸付 | C36: 住宅 | E36: 1800 | F36: 5 | G36: 360 | H36: 住宅 | I36: 20 | J36: 7 | K36: (表1) | L36: 工事完了前 | M36: 工事完了予定日 | Q36: 6 | R36: 交付日 | S36: ハンドブックには「締切日の同月10日頃」と記載(要確認)
A37: 災害貸付:災害家財 | B37: 災害貸付 | C37: 月数 | D37: 6 | E37: 200 | F37: 5 | G37: 360 | H37: 災害 | I37: 5 | J37: 0 | K37: り災証明書及び被害が確認できる写真(状況により他の書類) | L37: 災害発生後6か月以内 | M37: 災害発生日 | N37: 0 | O37: 6 | S37: 締切日の同月10日頃
A38: 災害貸付:災害住宅 | B38: 災害貸付 | C38: 住宅 | E38: 1800 | F38: 5 | G38: 360 | H38: 災害 | I38: 5 | J38: 0 | K38: り災証明書及び被害が確認できる写真(状況により他の書類) | L38: 災害発生後6か月以内 | M38: 災害発生日 | N38: 0 | O38: 6 | Q38: 6 | R38: 交付日 | S38: 締切日の同月10日頃
A39: 災害貸付:災害再貸付 | B39: 災害貸付 | C39: 再貸付 | E39: 1900 | F39: 5 | G39: 360 | H39: 災害 | I39: 5 | J39: 0 | K39: り災証明書及び被害が確認できる写真(状況により他の書類) | L39: 災害発生後6か月以内 | M39: 災害発生日 | N39: 0 | O39: 6 | Q39: 6 | R39: 交付日 | S39: 締切日の同月10日頃
A41: 3. 組合員期間別の月数・最低保障額(住宅貸付・災害住宅貸付・災害再貸付)
A42: 組合員期間の下限(月数) | B42: 区分表示 | C42: 給料月額に乗じる月数 | E42: 組合員期間の下限(月数) | F42: 区分表示 | G42: 最低保障額(住宅)(万円) | H42: 最低保障額(災害再貸付)(万円)
A43: 12 | B43: 1年以上6年未満 | C43: 7 | E43: 12 | F43: 1年以上3年未満(災害は3年未満) | G43: 100 | H43: 150
A44: 72 | B44: 6年以上11年未満 | C44: 15 | E44: 36 | F44: 3年以上7年未満 | G44: 400 | H44: 450
...

Sheet 計算過程
A1: 計算過程(中間計算・書類判定)― 通常は触らないでください
A2: 申込シミュレーションの結果は、すべてこのシートの数式から表示しています。
A3: 項目 | B3: 値 | C3: 計算の考え方
A4: 貸付区分表の行番号 | B4: =IFERROR(MATCH(申込シミュレーション!$C$9,マスタ!$A$22:$A$39,0),1) -> 1 | C4: 貸付区分の選択位置(未選択のときは1行目で仮計算し、判定は×)
A5: 区分群 | B5: =INDEX(マスタ!$B$22:$B$39,計算過程!$B$4)&"" -> 普通貸付
A6: 限度額の計算方式 | B6: =INDEX(マスタ!$C$22:$C$39,計算過程!$B$4)&"" -> 月数
A7: 給料月数(月数方式) | B7: =N(INDEX(マスタ!$D$22:$D$39,計算過程!$B$4)) -> 6
A8: 上限額(万円) | B8: =N(INDEX(マスタ!$E$22:$E$39,計算過程!$B$4)) -> 200
A9: 申込単位(万円) | B9: =N(INDEX(マスタ!$F$22:$F$39,計算過程!$B$4)) -> 1
A10: 償還回数の上限 | B10: =N(INDEX(マスタ!$G$22:$G$39,計算過程!$B$4)) -> 120
A11: 利率種別 | B11: =INDEX(マスタ!$H$22:$H$39,計算過程!$B$4)&"" -> 通常
A12: 申込締切日(日) | B12: =N(INDEX(マスタ!$I$22:$I$39,計算過程!$B$4)) -> 5
A13: 住宅書類の列No(住宅貸付) | B13: =N(INDEX(マスタ!$J$22:$J$39,計算過程!$B$4)) -> 0
A14: 事由別の添付書類 | B14: =INDEX(マスタ!$K$22:$K$39,計算過程!$B$4)&"" -> 注文書(写)又は発注書(写)(見積書は不可)
A15: 申込時期 | B15: =INDEX(マスタ!$L$22:$L$39,計算過程!$B$4)&"" -> 自動車登録(名義変更)前で代金支払前
A16: 基準日の名称 | B16: =INDEX(マスタ!$M$22:$M$39,計算過程!$B$4)&"" -> 自動車の登録(予定)日
A17: 申込可能期間:基準日の何か月前(空白=制限なし) | B17: =INDEX(マスタ!$N$22:$N$39,計算過程!$B$4)&""
A18: 申込可能期間:基準日の何か月後(空白=制限なし) | B18: =INDEX(マスタ!$O$22:$O$39,計算過程!$B$4)&""
A19: 交付後の提出書類(住宅以外) | B19: =INDEX(マスタ!$P$22:$P$39,計算過程!$B$4)&"" -> 完了届(自動車検査証(写)及び自動車検査証記録事項(写)を添付)
A20: 交付後の提出期限(月) | B20: =INDEX(マスタ!$Q$22:$Q$39,計算過程!$B$4)&"" -> 2
A21: 期限の起算 | B21: =INDEX(マスタ!$R$22:$R$39,計算過程!$B$4)&"" -> 交付日
A22: 貸付決定(目安) | B22: =INDEX(マスタ!$S$22:$S$39,計算過程!$B$4)&"" -> 締切日の同月10日頃
A23: 住宅系(住宅・災害住宅・災害再貸付)=1 | B23: =IF(OR(計算過程!$B$6="住宅",計算過程!$B$6="再貸付"),1,0) -> 0
A24: 適用利率(年) | B24: =IF(計算過程!$B$11="災害",マスタ!$B$6,IF(計算過程!$B$11="住宅",マスタ!$B$5,マスタ!$B$4)) -> 0.0126
A25: 在宅介護対応(加算部分)の利率(年) | B25: =MAX(0,計算過程!$B$24-マスタ!$B$7) -> 0.01 | C25: 住宅貸付の利率-0.26%(災害貸付との併用は要確認)
A26: 組合員期間(月数) | B26: =IF(OR(申込シミュレーション!$C$11="",申込シミュレーション!$C$10=""),0,IFERROR(DATEDIF(申込シミュレーション!$C$11,申込シミュレーション!$C$10,"m"),0)) -> 175 | C26: 資格取得日〜申込予定日
A27: 組合員期間(表示) | B27: =INT(計算過程!$B$26/12)&"年"&MOD(計算過程!$B$26,12)&"か月" -> 14年7か月
A28: 月数表の区分位置 | B28: =IFERROR(MATCH(計算過程!$B$26,マスタ!$A$43:$A$49,1),1) -> 3 | C28: 1年未満は最下段を適用(災害住宅貸付のみ貸付可)
A29: 最低保障額表の区分位置 | B29: =IFERROR(MATCH(計算過程!$B$26,マスタ!$E$43:$E$47,1),1) -> 4
A30: 住宅:給料月額に乗じる月数 | B30: =INDEX(マスタ!$C$43:$C$49,計算過程!$B$28) -> 22
A31: 住宅:最低保障額(万円) | B31: =INDEX(マスタ!$G$43:$G$47,計算過程!$B$29) -> 900
A32: 災害再貸付:最低保障額(万円) | B32: =INDEX(マスタ!$H$43:$H$47,計算過程!$B$29) -> 950
A33: 貸付限度額(基本・円) | B33: =IF(計算過程!$B$6="月数",MIN(申込シミュレーション!$C$12*計算過程!$B$7,計算過程!$B$8*10000),IF(計算過程!$B$6="修学",マスタ!$B$18*10000*N(申込シミュレーション!$C$16),IF(計算過程!$B$6="住宅",MIN(MAX(申込シミュレーション!$C$12*計算過程!$B$30,計算過程!$B$31*10000),計算過程!$B$8*10000),IF(計算過程!$B$6="再貸付",MIN(MAX(申込シミュレーション!$C$12*計算過程!$B$30*2,計算過程!$B$32*10000),計算過程!$B$8*10000),0)))) -> 1740000 | C33: 月数方式=給料月額×月数(上限あり) / 修学=月額×修学月数 / 住宅=(給料月額×月数)と最低保障額の高い方 / 再貸付=月数を2倍
A34: 在宅介護対応住宅の加算限度(円) | B34: =IF(計算過程!$B$23=1,MIN(MAX(N(申込シミュレーション!$C$23),0)*10000,マスタ!$B$11*10000),0) -> 0 | C34: 入力した該当部分の金額(300万円まで)を限度額に加算
A35: 貸付限度額(合計・円) | B35: =計算過程!$B$33+計算過程!$B$34 -> 1740000
A36: 申込単位(円) | B36: =計算過程!$B$9*10000 -> 10000
A37: 申込金額の下限(円) | B37: =マスタ!$B$10*10000 -> 100000
A38: 他の借入等の毎月償還額 A+B+C | B38: =N(申込シミュレーション!$C$27)+N(申込シミュレーション!$C$29)+N(申込シミュレーション!$C$31) -> 30000
A39: 他の借入等のボーナス償還額 F+G+H | B39: =N(申込シミュレーション!$C$28)+N(申込シミュレーション!$C$30)+N(申込シミュレーション!$C$32) -> 0
A40: 毎月償還額(E)の上限 | B40: =MAX(0,MIN(マスタ!$B$8*申込シミュレーション!$C$12,(マスタ!$B$8*申込シミュレーション!$C$12*(12+マスタ!$B$9)-2*計算過程!$B$39)/12)) -> 87000 | C40: ①給料月額の30% ②年収額(給料月額×16)の30%から年間ボーナス償還を差し引いた月額、の小さい方
...
