Workbook

Sheet 年度
A2: 5 | B2: 年度

Sheet 全伝票
I1: 179962946555 | J1: 0 | K1: 0 | L1: 1408906 | M1: 537718 | N1: 44539401683 | O1: 4535078073 | P1: 130886520175 | Q1: 0
A2: 事業 | B2: 予算コード | C2: 予算コード | D2: 款 | E2: 項 | F2: 目 | G2: 節 | H2: 細節 | I2: 執行額 | J2: 課税 | O2: 非課税 | P2: 不課税
J3: 3 | K3: 5 | L3: 8 | M3: 8 | N3: 10 | O3: 21 | P3: 31
A4: 1 | B4: 1120110 | C4: 112011010 | D4: 資本的収入 | E4: 企業債 | F4: 建設企業債 | G4: 公共下水道事業債 | H4: 一般債 | I4: 8822500000 | J4: 0 | K4: 0 | L4: 0 | M4: 0 | N4: 0 | O4: 0 | P4: 8822500000 | Q4: 0
A5: 1 | B5: 1120110 | C5: 112011011 | D5: 資本的収入 | E5: 企業債 | F5: 建設企業債 | G5: 公共下水道事業債 | H5: 特別債 | I5: 0 | J5: 0 | K5: 0 | L5: 0 | M5: 0 | N5: 0 | O5: 0 | P5: 0 | Q5: 0
A6: 1 | B6: 1120110 | C6: 112011012 | D6: 資本的収入 | E6: 企業債 | F6: 建設企業債 | G6: 公共下水道事業債 | H6: 一般債（復興関連） | I6: 0 | J6: 0 | K6: 0 | L6: 0 | M6: 0 | N6: 0 | O6: 0 | P6: 0 | Q6: 0
A7: 1 | B7: 1120111 | C7: 112011100 | D7: 資本的収入 | E7: 企業債 | F7: 建設企業債 | G7: 特定資金公共事業債 | I7: 0 | J7: 0 | K7: 0 | L7: 0 | M7: 0 | N7: 0 | O7: 0 | P7: 0 | Q7: 0
A8: 1 | B8: 1120112 | C8: 112011200 | D8: 資本的収入 | E8: 企業債 | F8: 建設企業債 | G8: 流域下水道事業債 | I8: 120200000 | J8: 0 | K8: 0 | L8: 0 | M8: 0 | N8: 0 | O8: 0 | P8: 120200000 | Q8: 0
A9: 1 | B9: 1120113 | C9: 112011300 | D9: 資本的収入 | E9: 企業債 | F9: 建設企業債 | G9: 資本費平準化債 | I9: 5632100000 | J9: 0 | K9: 0 | L9: 0 | M9: 0 | N9: 0 | O9: 0 | P9: 5632100000 | Q9: 0
A10: 1 | B10: 1120114 | C10: 112011400 | D10: 資本的収入 | E10: 企業債 | F10: 建設企業債 | G10: その他事業債 | I10: 0 | J10: 0 | K10: 0 | L10: 0 | M10: 0 | N10: 0 | O10: 0 | P10: 0 | Q10: 0
A11: 1 | B11: 1120116 | C11: 112011600 | D11: 資本的収入 | E11: 企業債 | F11: 建設企業債 | G11: 災害復旧事業債 | I11: 0 | J11: 0 | K11: 0 | L11: 0 | M11: 0 | N11: 0 | O11: 0 | P11: 0 | Q11: 0
A12: 1 | B12: 1120210 | C12: 112021000 | D12: 資本的収入 | E12: 企業債 | F12: 借換債 | G12: 公共下水道事業借換債 | I12: 0 | J12: 0 | K12: 0 | L12: 0 | M12: 0 | N12: 0 | O12: 0 | P12: 0 | Q12: 0
A13: 1 | B13: 1120220 | C13: 112022000 | D13: 資本的収入 | E13: 企業債 | F13: 借換債 | G13: 公営企業借換債 | I13: 0 | J13: 0 | K13: 0 | L13: 0 | M13: 0 | N13: 0 | O13: 0 | P13: 0 | Q13: 0
A14: 1 | B14: 1120230 | C14: 112023000 | D14: 資本的収入 | E14: 企業債 | F14: 借換債 | G14: 補償金免除繰上償還借換債 | I14: 0 | J14: 0 | K14: 0 | L14: 0 | M14: 0 | N14: 0 | O14: 0 | P14: 0 | Q14: 0
A15: 1 | B15: 1120240 | C15: 112024000 | D15: 資本的収入 | E15: 企業債 | F15: 借換債 | G15: 資本費平準化債（拡大分）借換債 | I15: 17007700000 | J15: 0 | K15: 0 | L15: 0 | M15: 0 | N15: 0 | O15: 0 | P15: 17007700000 | Q15: 0
A16: 1 | B16: 1120310 | C16: 112031000 | D16: 資本的収入 | E16: 企業債 | F16: 出資債 | G16: 公営企業出資債 | I16: 0 | J16: 0 | K16: 0 | L16: 0 | M16: 0 | N16: 0 | O16: 0 | P16: 0 | Q16: 0
A17: 1 | B17: 1140303 | C17: 114030300 | D17: 資本的収入 | E17: 長期借入金 | F17: 一般会計借入金 | G17: 一般会計借入金 | I17: 0 | J17: 0 | K17: 0 | L17: 0 | M17: 0 | N17: 0 | O17: 0 | P17: 0 | Q17: 0
A18: 1 | B18: 1160101 | C18: 116010100 | D18: 資本的収入 | E18: 一般会計出資金 | F18: 下水道建設費出資金 | G18: 下水道建設費出資金 | I18: 3566242000 | J18: 0 | K18: 0 | L18: 0 | M18: 0 | N18: 0 | O18: 0 | P18: 3566242000 | Q18: 0
A19: 1 | B19: 1160202 | C19: 116020200 | D19: 資本的収入 | E19: 一般会計出資金 | F19: その他出資金 | G19: その他出資金 | I19: 0 | J19: 0 | K19: 0 | L19: 0 | M19: 0 | N19: 0 | O19: 0 | P19: 0 | Q19: 0
A20: 1 | B20: 1180401 | C20: 118040101 | D20: 資本的収入 | E20: 国庫補助金 | F20: 国庫補助金 | G20: 公共下水道整備国庫補助金 | H20: 公共下水道整備国庫補助金 | I20: 5683800000 | J20: 0 | K20: 0 | L20: 0 | M20: 0 | N20: 0 | O20: 0 | P20: 5683800000 | Q20: 0
A21: 1 | B21: 1180401 | C21: 118040102 | D21: 資本的収入 | E21: 国庫補助金 | F21: 国庫補助金 | G21: 公共下水道整備国庫補助金 | H21: 公共下水道整備国庫補助金（復興関連） | I21: 0 | J21: 0 | K21: 0 | L21: 0 | M21: 0 | N21: 0 | O21: 0 | P21: 0 | Q21: 0
A22: 1 | B22: 1180402 | C22: 118040200 | D22: 資本的収入 | E22: 国庫補助金 | F22: 国庫補助金 | G22: その他国庫補助金 | I22: 0 | J22: 0 | K22: 0 | L22: 0 | M22: 0 | N22: 0 | O22: 0 | P22: 0 | Q22: 0
A23: 1 | B23: 1200630 | C23: 120063000 | D23: 資本的収入 | E23: 国庫委託金 | F23: 国庫委託金 | G23: 国庫委託金 | I23: 0 | J23: 0 | K23: 0 | L23: 0 | M23: 0 | N23: 0 | O23: 0 | P23: 0 | Q23: 0
A24: 1 | B24: 1300831 | C24: 130083100 | D24: 資本的収入 | E24: 県委託金 | F24: 県委託金 | G24: 県委託金 | I24: 0 | J24: 0 | K24: 0 | L24: 0 | M24: 0 | N24: 0 | O24: 0 | P24: 0 | Q24: 0
A25: 1 | B25: 1401010 | C25: 140101000 | D25: 資本的収入 | E25: 一般会計補助金 | F25: 一般会計補助金 | G25: 一般会計補助金 | I25: 0 | J25: 0 | K25: 0 | L25: 0 | M25: 0 | N25: 0 | O25: 0 | P25: 0 | Q25: 0
A26: 1 | B26: 1600101 | C26: 160010100 | D26: 資本的収入 | E26: 工事受託金 | F26: 工事受託金 | G26: 工事受託金 | I26: 24373083 | J26: 0 | K26: 0 | L26: 0 | M26: 0 | N26: 24373083 | O26: 0 | P26: 0 | Q26: 0
A27: 1 | B27: 1800606 | C27: 180060600 | D27: 資本的収入 | E27: 負担金 | F27: 受益者負担金 | G27: 受益者負担金 | I27: 8799605 | J27: 0 | K27: 0 | L27: 0 | M27: 0 | N27: 0 | O27: 0 | P27: 8799605 | Q27: 0
A28: 1 | B28: 1800808 | C28: 180080800 | D28: 資本的収入 | E28: 負担金 | F28: 工事負担金 | G28: 工事負担金 | I28: 530286509 | J28: 0 | K28: 0 | L28: 0 | M28: 0 | N28: 15318327 | O28: 0 | P28: 514968182 | Q28: 0
A29: 1 | B29: 1820101 | C29: 182010100 | D29: 資本的収入 | E29: 寄附金 | F29: 建設費寄附金 | G29: 建設費寄附金 | I29: 0 | J29: 0 | K29: 0 | L29: 0 | M29: 0 | N29: 0 | O29: 0 | P29: 0 | Q29: 0
A30: 1 | B30: 1840102 | C30: 184010200 | D30: 資本的収入 | E30: 水洗化貸付事業収入 | F30: 貸付企業債 | G30: 水洗便所貸付資金事業債 | I30: 0 | J30: 0 | K30: 0 | L30: 0 | M30: 0 | N30: 0 | O30: 0 | P30: 0 | Q30: 0
A31: 1 | B31: 1840304 | C31: 184030400 | D31: 資本的収入 | E31: 水洗化貸付事業収入 | F31: 一般会計借入金 | G31: 水洗便所改造資金貸付借入金 | I31: 0 | J31: 0 | K31: 0 | L31: 0 | M31: 0 | N31: 0 | O31: 0 | P31: 0 | Q31: 0
A32: 1 | B32: 1840305 | C32: 184030500 | D32: 資本的収入 | E32: 水洗化貸付事業収入 | F32: 一般会計借入金 | G32: し尿浄化槽廃止資金貸付借入金 | I32: 0 | J32: 0 | K32: 0 | L32: 0 | M32: 0 | N32: 0 | O32: 0 | P32: 0 | Q32: 0
A33: 1 | B33: 1840306 | C33: 184030600 | D33: 資本的収入 | E33: 水洗化貸付事業収入 | F33: 一般会計借入金 | G33: 排水設備改修資金貸付借入金 | I33: 0 | J33: 0 | K33: 0 | L33: 0 | M33: 0 | N33: 0 | O33: 0 | P33: 0 | Q33: 0
... A43: 1 | B43: 4810202 | C43: 481020200 | D43: 下水道事業収益 | E43: 営業収益 | F43: 下水道使用料 | G43: 下水道使用料 | I43: 20339840861 | J43: 0 | K43: 0 | L43: 0 | M43: 0 | N43: 20339840861 | O43: 0 | P43: 0 | Q43: 0
A44: 1 | B44: 4810404 | C44: 481040411 | D44: 下水道事業収益 | E44: 営業収益 | F44: 一般会計負担金 | G44: 雨水処理負担金 | H44: 維持管理費分 | I44: 2754671000 | J44: 0 | K44: 0 | L44: 0 | M44: 0 | N44: 0 | O44: 0 | P44: 2754671000 | Q44: 0
A45: 1 | B45: 4810404 | C45: 481040412 | D45: 下水道事業収益 | E45: 営業収益 | F45: 一般会計負担金 | G45: 雨水処理負担金 | H45: 減価償却費分 | I45: 7912710000 | J45: 0 | K45: 0 | L45: 0 | M45: 0 | N45: 0 | O45: 0 | P45: 7912710000 | Q45: 0
A46: 1 | B46: 4810404 | C46: 481040413 | D46: 下水道事業収益 | E46: 営業収益 | F46: 一般会計負担金 | G46: 雨水処理負担金 | H46: 支払利息分 | I46: 2138644000 | J46: 0 | K46: 0 | L46: 0 | M46: 0 | N46: 0 | O46: 0 | P46: 2138644000 | Q46: 0
A47: 1 | B47: 4810404 | C47: 481040415 | D47: 下水道事業収益 | E47: 営業収益 | F47: 一般会計負担金 | G47: 雨水処理負担金 | H47: 災害復旧応援分 | I47: 0 | J47: 0 | K47: 0 | L47: 0 | M47: 0 | N47: 0 | O47: 0 | P47: 0 | Q47: 0
A48: 1 | B48: 4810406 | C48: 481040600 | D48: 下水道事業収益 | E48: 営業収益 | F48: 一般会計負担金 | G48: 水質指導費負担金 | I48: 61778000 | J48: 0 | K48: 0 | L48: 0 | M48: 0 | N48: 0 | O48: 0 | P48: 61778000 | Q48: 0
A49: 1 | B49: 4810408 | C49: 481040800 | D49: 下水道事業収益 | E49: 営業収益 | F49: 一般会計負担金 | G49: 普及促進費負担金 | I49: 40039000 | J49: 0 | K49: 0 | L49: 0 | M49: 0 | N49: 0 | O49: 0 | P49: 40039000 | Q49: 0
...

Sheet 災害伝票
R1: 集計表（全体）
AU2: 1 | AV2: 現年分 | AW2: 税率別税込額 | BC2: 4 | BD2: 事故繰分 | BE2: 税率別税込額
Y3: 執行額 | AU3: 3 | AV3: 5 | AW3: 8 | AX3: 8 | AY3: 10 | AZ3: 非課税 | BA3: 不課税 | BB3: 計 | BC3: 3 | BD3: 5 | BE3: 8 | BF3: 8 | BG3: 10 | BH3: 非課税 | BI3: 不課税 | BJ3: 計 | BK3: チェック
N4: 1 | O4: 下水道事業費用 | P4: 営業費用 | Q4: 管きょ費 | Y4: =+SUMIFS(Y$15:Y$47,$Q$15:$Q$47,$Q4) -> 0 | AU4: =+SUMIFS($Y$15:$Y$47,$Q$15:$Q$47,$Q4,$AT$15:$AT$47,AU$3,$M$15:$M$47,$AU$2) -> 0 | AV4: =+SUMIFS($Y$15:$Y$47,$Q$15:$Q$47,$Q4,$AT$15:$AT$47,AV$3,$M$15:$M$47,$AU$2) -> 0 | AW4: =+SUMIFS($Y$15:$Y$47,$Q$15:$Q$47,$Q4,$AT$15:$AT$47,AW$3,$M$15:$M$47,$AU$2) -> 0 | AX4: =+SUMIFS($Y$15:$Y$47,$Q$15:$Q$47,$Q4,$AT$15:$AT$47,AX$3,$M$15:$M$47,$AU$2) -> 0 | AY4: =+SUMIFS($Y$15:$Y$47,$Q$15:$Q$47,$Q4,$AT$15:$AT$47,AY$3,$M$15:$M$47,$AU$2) -> 0 | AZ4: =+SUMIFS($Y$15:$Y$47,$Q$15:$Q$47,$Q4,$AT$15:$AT$47,AZ$3,$M$15:$M$47,$AU$2) -> 0 | BA4: =+SUMIFS($Y$15:$Y$47,$Q$15:$Q$47,$Q4,$AT$15:$AT$47,BA$3,$M$15:$M$47,$AU$2) -> 0 | BB4: =SUM(AU4:BA4) -> 0 | BC4: =+SUMIFS($Y$15:$Y$47,$Q$15:$Q$47,$Q4,$AT$15:$AT$47,BC$3,$M$15:$M$47,$BC$2) -> 0 | BD4: =+SUMIFS($Y$15:$Y$47,$Q$15:$Q$47,$Q4,$AT$15:$AT$47,BD$3,$M$15:$M$47,$BC$2) -> 0 | BE4: =+SUMIFS($Y$15:$Y$47,$Q$15:$Q$47,$Q4,$AT$15:$AT$47,BE$3,$M$15:$M$47,$BC$2)-BF4 -> 0 | BF4: =+SUMIFS($Y$15:$Y$47,$Q$15:$Q$47,$Q4,$AT$15:$AT$47,BF$3,$M$15:$M$47,$BC$2) -> 0 | BG4: =+SUMIFS($Y$15:$Y$47,$Q$15:$Q$47,$Q4,$AT$15:$AT$47,BG$3,$M$15:$M$47,$BC$2) -> 0 | BH4: =+SUMIFS($Y$15:$Y$47,$Q$15:$Q$47,$Q4,$AT$15:$AT$47,BH$3,$M$15:$M$47,$BC$2) -> 0 | BI4: =+SUMIFS($Y$15:$Y$47,$Q$15:$Q$47,$Q4,$AT$15:$AT$47,BI$3,$M$15:$M$47,$BC$2) -> 0 | BJ4: =SUM(BC4:BI4) -> 0 | BK4: =+IF(Y4=(BB4+BJ4),"OK","エラー") -> OK
N5: 1 | O5: 下水道事業費用 | P5: 営業費用 | Q5: ポンプ場費 | Y5: =+SUMIFS(Y$15:Y$47,$Q$15:$Q$47,$Q5) -> 0 | AU5: =+SUMIFS($Y$15:$Y$47,$Q$15:$Q$47,$Q5,$AT$15:$AT$47,AU$3,$M$15:$M$47,$AU$2) -> 0 | AV5: =+SUMIFS($Y$15:$Y$47,$Q$15:$Q$47,$Q5,$AT$15:$AT$47,AV$3,$M$15:$M$47,$AU$2) -> 0 | AW5: =+SUMIFS($Y$15:$Y$47,$Q$15:$Q$47,$Q5,$AT$15:$AT$47,AW$3,$M$15:$M$47,$AU$2) -> 0 | AX5: =+SUMIFS($Y$15:$Y$47,$Q$15:$Q$47,$Q5,$AT$15:$AT$47,AX$3,$M$15:$M$47,$AU$2) -> 0 | AY5: =+SUMIFS($Y$15:$Y$47,$Q$15:$Q$47,$Q5,$AT$15:$AT$47,AY$3,$M$15:$M$47,$AU$2) -> 0 | AZ5: =+SUMIFS($Y$15:$Y$47,$Q$15:$Q$47,$Q5,$AT$15:$AT$47,AZ$3,$M$15:$M$47,$AU$2) -> 0 | BA5: =+SUMIFS($Y$15:$Y$47,$Q$15:$Q$47,$Q5,$AT$15:$AT$47,BA$3,$M$15:$M$47,$AU$2) -> 0 | BB5: =SUM(AU5:BA5) -> 0 | BC5: =+SUMIFS($Y$15:$Y$47,$Q$15:$Q$47,$Q5,$AT$15:$AT$47,BC$3,$M$15:$M$47,$BC$2) -> 0 | BD5: =+SUMIFS($Y$15:$Y$47,$Q$15:$Q$47,$Q5,$AT$15:$AT$47,BD$3,$M$15:$M$47,$BC$2) -> 0 | BE5: =+SUMIFS($Y$15:$Y$47,$Q$15:$Q$47,$Q5,$AT$15:$AT$47,BE$3,$M$15:$M$47,$BC$2)-BF5 -> 0 | BF5: =+SUMIFS($Y$15:$Y$47,$Q$15:$Q$47,$Q5,$AT$15:$AT$47,BF$3,$M$15:$M$47,$BC$2) -> 0 | BG5: =+SUMIFS($Y$15:$Y$47,$Q$15:$Q$47,$Q5,$AT$15:$AT$47,BG$3,$M$15:$M$47,$BC$2) -> 0 | BH5: =+SUMIFS($Y$15:$Y$47,$Q$15:$Q$47,$Q5,$AT$15:$AT$47,BH$3,$M$15:$M$47,$BC$2) -> 0 | BI5: =+SUMIFS($Y$15:$Y$47,$Q$15:$Q$47,$Q5,$AT$15:$AT$47,BI$3,$M$15:$M$47,$BC$2) -> 0 | BJ5: =SUM(BC5:BI5) -> 0 | BK5: =+IF(Y5=(BB5+BJ5),"OK","エラー") -> OK
N6: 1 | O6: 下水道事業費用 | P6: 営業費用 | Q6: 処理場費 | Y6: =+SUMIFS(Y$15:Y$47,$Q$15:$Q$47,$Q6) -> 0 | AU6: =+SUMIFS($Y$15:$Y$47,$Q$15:$Q$47,$Q6,$AT$15:$AT$47,AU$3,$M$15:$M$47,$AU$2) -> 0 | AV6: =+SUMIFS($Y$15:$Y$47,$Q$15:$Q$47,$Q6,$AT$15:$AT$47,AV$3,$M$15:$M$47,$AU$2) -> 0 | AW6: =+SUMIFS($Y$15:$Y$47,$Q$15:$Q$47,$Q6,$AT$15:$AT$47,AW$3,$M$15:$M$47,$AU$2) -> 0 | AX6: =+SUMIFS($Y$15:$Y$47,$Q$15:$Q$47,$Q6,$AT$15:$AT$47,AX$3,$M$15:$M$47,$AU$2) -> 0 | AY6: =+SUMIFS($Y$15:$Y$47,$Q$15:$Q$47,$Q6,$AT$15:$AT$47,AY$3,$M$15:$M$47,$AU$2) -> 0 | AZ6: =+SUMIFS($Y$15:$Y$47,$Q$15:$Q$47,$Q6,$AT$15:$AT$47,AZ$3,$M$15:$M$47,$AU$2) -> 0 | BA6: =+SUMIFS($Y$15:$Y$47,$Q$15:$Q$47,$Q6,$AT$15:$AT$47,BA$3,$M$15:$M$47,$AU$2) -> 0 | BB6: =SUM(AU6:BA6) -> 0 | BC6: =+SUMIFS($Y$15:$Y$47,$Q$15:$Q$47,$Q6,$AT$15:$AT$47,BC$3,$M$15:$M$47,$BC$2) -> 0 | BD6: =+SUMIFS($Y$15:$Y$47,$Q$15:$Q$47,$Q6,$AT$15:$AT$47,BD$3,$M$15:$M$47,$BC$2) -> 0 | BE6: =+SUMIFS($Y$15:$Y$47,$Q$15:$Q$47,$Q6,$AT$15:$AT$47,BE$3,$M$15:$M$47,$BC$2)-BF6 -> 0 | BF6: =+SUMIFS($Y$15:$Y$47,$Q$15:$Q$47,$Q6,$AT$15:$AT$47,BF$3,$M$15:$M$47,$BC$2) -> 0 | BG6: =+SUMIFS($Y$15:$Y$47,$Q$15:$Q$47,$Q6,$AT$15:$AT$47,BG$3,$M$15:$M$47,$BC$2) -> 0 | BH6: =+SUMIFS($Y$15:$Y$47,$Q$15:$Q$47,$Q6,$AT$15:$AT$47,BH$3,$M$15:$M$47,$BC$2) -> 0 | BI6: =+SUMIFS($Y$15:$Y$47,$Q$15:$Q$47,$Q6,$AT$15:$AT$47,BI$3,$M$15:$M$47,$BC$2) -> 0 | BJ6: =SUM(BC6:BI6) -> 0 | BK6: =+IF(Y6=(BB6+BJ6),"OK","エラー") -> OK
N7: 2 | O7: 下水道事業費用 | P7: 営業費用 | Q7: 特環公共下水道費 | Y7: =+SUMIFS(Y$15:Y$47,$Q$15:$Q$47,$Q7) -> 0 | AU7: =+SUMIFS($Y$15:$Y$47,$Q$15:$Q$47,$Q7,$AT$15:$AT$47,AU$3,$M$15:$M$47,$AU$2) -> 0 | AV7: =+SUMIFS($Y$15:$Y$47,$Q$15:$Q$47,$Q7,$AT$15:$AT$47,AV$3,$M$15:$M$47,$AU$2) -> 0 | AW7: =+SUMIFS($Y$15:$Y$47,$Q$15:$Q$47,$Q7,$AT$15:$AT$47,AW$3,$M$15:$M$47,$AU$2) -> 0 | AX7: =+SUMIFS($Y$15:$Y$47,$Q$15:$Q$47,$Q7,$AT$15:$AT$47,AX$3,$M$15:$M$47,$AU$2) -> 0 | AY7: =+SUMIFS($Y$15:$Y$47,$Q$15:$Q$47,$Q7,$AT$15:$AT$47,AY$3,$M$15:$M$47,$AU$2) -> 0 | AZ7: =+SUMIFS($Y$15:$Y$47,$Q$15:$Q$47,$Q7,$AT$15:$AT$47,AZ$3,$M$15:$M$47,$AU$2) -> 0 | BA7: =+SUMIFS($Y$15:$Y$47,$Q$15:$Q$47,$Q7,$AT$15:$AT$47,BA$3,$M$15:$M$47,$AU$2) -> 0 | BB7: =SUM(AU7:BA7) -> 0 | BC7: =+SUMIFS($Y$15:$Y$47,$Q$15:$Q$47,$Q7,$AT$15:$AT$47,BC$3,$M$15:$M$47,$BC$2) -> 0 | BD7: =+SUMIFS($Y$15:$Y$47,$Q$15:$Q$47,$Q7,$AT$15:$AT$47,BD$3,$M$15:$M$47,$BC$2) -> 0 | BE7: =+SUMIFS($Y$15:$Y$47,$Q$15:$Q$47,$Q7,$AT$15:$AT$47,BE$3,$M$15:$M$47,$BC$2)-BF7 -> 0 | BF7: =+SUMIFS($Y$15:$Y$47,$Q$15:$Q$47,$Q7,$AT$15:$AT$47,BF$3,$M$15:$M$47,$BC$2) -> 0 | BG7: =+SUMIFS($Y$15:$Y$47,$Q$15:$Q$47,$Q7,$AT$15:$AT$47,BG$3,$M$15:$M$47,$BC$2) -> 0 | BH7: =+SUMIFS($Y$15:$Y$47,$Q$15:$Q$47,$Q7,$AT$15:$AT$47,BH$3,$M$15:$M$47,$BC$2) -> 0 | BI7: =+SUMIFS($Y$15:$Y$47,$Q$15:$Q$47,$Q7,$AT$15:$AT$47,BI$3,$M$15:$M$47,$BC$2) -> 0 | BJ7: =SUM(BC7:BI7) -> 0 | BK7: =+IF(Y7=(BB7+BJ7),"OK","エラー") -> OK
N8: 3 | O8: 下水道事業費用 | P8: 営業費用 | Q8: 農業集落排水費 | Y8: =+SUMIFS(Y$15:Y$47,$Q$15:$Q$47,$Q8) -> 0 | AU8: =+SUMIFS($Y$15:$Y$47,$Q$15:$Q$47,$Q8,$AT$15:$AT$47,AU$3,$M$15:$M$47,$AU$2) -> 0 | AV8: =+SUMIFS($Y$15:$Y$47,$Q$15:$Q$47,$Q8,$AT$15:$AT$47,AV$3,$M$15:$M$47,$AU$2) -> 0 | AW8: =+SUMIFS($Y$15:$Y$47,$Q$15:$Q$47,$Q8,$AT$15:$AT$47,AW$3,$M$15:$M$47,$AU$2) -> 0 | AX8: =+SUMIFS($Y$15:$Y$47,$Q$15:$Q$47,$Q8,$AT$15:$AT$47,AX$3,$M$15:$M$47,$AU$2) -> 0 | AY8: =+SUMIFS($Y$15:$Y$47,$Q$15:$Q$47,$Q8,$AT$15:$AT$47,AY$3,$M$15:$M$47,$AU$2) -> 0 | AZ8: =+SUMIFS($Y$15:$Y$47,$Q$15:$Q$47,$Q8,$AT$15:$AT$47,AZ$3,$M$15:$M$47,$AU$2) -> 0 | BA8: =+SUMIFS($Y$15:$Y$47,$Q$15:$Q$47,$Q8,$AT$15:$AT$47,BA$3,$M$15:$M$47,$AU$2) -> 0 | BB8: =SUM(AU8:BA8) -> 0 | BC8: =+SUMIFS($Y$15:$Y$47,$Q$15:$Q$47,$Q8,$AT$15:$AT$47,BC$3,$M$15:$M$47,$BC$2) -> 0 | BD8: =+SUMIFS($Y$15:$Y$47,$Q$15:$Q$47,$Q8,$AT$15:$AT$47,BD$3,$M$15:$M$47,$BC$2) -> 0 | BE8: =+SUMIFS($Y$15:$Y$47,$Q$15:$Q$47,$Q8,$AT$15:$AT$47,BE$3,$M$15:$M$47,$BC$2)-BF8 -> 0 | BF8: =+SUMIFS($Y$15:$Y$47,$Q$15:$Q$47,$Q8,$AT$15:$AT$47,BF$3,$M$15:$M$47,$BC$2) -> 0 | BG8: =+SUMIFS($Y$15:$Y$47,$Q$15:$Q$47,$Q8,$AT$15:$AT$47,BG$3,$M$15:$M$47,$BC$2) -> 0 | BH8: =+SUMIFS($Y$15:$Y$47,$Q$15:$Q$47,$Q8,$AT$15:$AT$47,BH$3,$M$15:$M$47,$BC$2) -> 0 | BI8: =+SUMIFS($Y$15:$Y$47,$Q$15:$Q$47,$Q8,$AT$15:$AT$47,BI$3,$M$15:$M$47,$BC$2) -> 0 | BJ8: =SUM(BC8:BI8) -> 0 | BK8: =+IF(Y8=(BB8+BJ8),"OK","エラー") -> OK
N9: 4 | O9: 下水道事業費用 | P9: 営業費用 | Q9: 浄化槽費 | Y9: =+SUMIFS(Y$15:Y$47,$Q$15:$Q$47,$Q9) -> 0 | AU9: =+SUMIFS($Y$15:$Y$47,$Q$15:$Q$47,$Q9,$AT$15:$AT$47,AU$3,$M$15:$M$47,$AU$2) -> 0 | AV9: =+SUMIFS($Y$15:$Y$47,$Q$15:$Q$47,$Q9,$AT$15:$AT$47,AV$3,$M$15:$M$47,$AU$2) -> 0 | AW9: =+SUMIFS($Y$15:$Y$47,$Q$15:$Q$47,$Q9,$AT$15:$AT$47,AW$3,$M$15:$M$47,$AU$2) -> 0 | AX9: =+SUMIFS($Y$15:$Y$47,$Q$15:$Q$47,$Q9,$AT$15:$AT$47,AX$3,$M$15:$M$47,$AU$2) -> 0 | AY9: =+SUMIFS($Y$15:$Y$47,$Q$15:$Q$47,$Q9,$AT$15:$AT$47,AY$3,$M$15:$M$47,$AU$2) -> 0 | AZ9: =+SUMIFS($Y$15:$Y$47,$Q$15:$Q$47,$Q9,$AT$15:$AT$47,AZ$3,$M$15:$M$47,$AU$2) -> 0 | BA9: =+SUMIFS($Y$15:$Y$47,$Q$15:$Q$47,$Q9,$AT$15:$AT$47,BA$3,$M$15:$M$47,$AU$2) -> 0 | BB9: =SUM(AU9:BA9) -> 0 | BC9: =+SUMIFS($Y$15:$Y$47,$Q$15:$Q$47,$Q9,$AT$15:$AT$47,BC$3,$M$15:$M$47,$BC$2) -> 0 | BD9: =+SUMIFS($Y$15:$Y$47,$Q$15:$Q$47,$Q9,$AT$15:$AT$47,BD$3,$M$15:$M$47,$BC$2) -> 0 | BE9: =+SUMIFS($Y$15:$Y$47,$Q$15:$Q$47,$Q9,$AT$15:$AT$47,BE$3,$M$15:$M$47,$BC$2)-BF9 -> 0 | BF9: =+SUMIFS($Y$15:$Y$47,$Q$15:$Q$47,$Q9,$AT$15:$AT$47,BF$3,$M$15:$M$47,$BC$2) -> 0 | BG9: =+SUMIFS($Y$15:$Y$47,$Q$15:$Q$47,$Q9,$AT$15:$AT$47,BG$3,$M$15:$M$47,$BC$2) -> 0 | BH9: =+SUMIFS($Y$15:$Y$47,$Q$15:$Q$47,$Q9,$AT$15:$AT$47,BH$3,$M$15:$M$47,$BC$2) -> 0 | BI9: =+SUMIFS($Y$15:$Y$47,$Q$15:$Q$47,$Q9,$AT$15:$AT$47,BI$3,$M$15:$M$47,$BC$2) -> 0 | BJ9: =SUM(BC9:BI9) -> 0 | BK9: =+IF(Y9=(BB9+BJ9),"OK","エラー") -> OK
Y10: =SUM(Y4:Y9) -> 0
AL14: ---- | AS14: 0 | AT14: 0
A15: 事業区分 | B15: 所属 | C15: 所属名 | D15: 主管課 | E15: 主管課名 | F15: 年月日 | G15: 振替年月日 | H15: 事項 | I15: 種別 | J15: 伝票番号 | K15: 枝番 | L15: 内訳番号 | M15: 現繰 | N15: 予算科目 | O15: 款名称 | P15: 項名称 | Q15: 目名称 | R15: 節名称 | S15: 細節名称 | T15: 事業コード | U15: 事業名 | V15: 予算額 | W15: 概算額 | X15: 確定額 | Y15: 執行額 | Z15: 借方勘定 | AA15: 借方勘定科目 | AB15: 借方金額 | AC15: 貸方勘定 | AD15: 貸方勘定科目 | AE15: 貸方金額 | AF15: 税区分 | AG15: 税率 | AH15: 税額 | AI15: 税抜金額 | AJ15: 債権者 | AL15: 複合伝票番号 | AM15: 1 | AN15: 0 | AO15: 0 | AP15: 0 | AQ15: 重複 | AS15: 集計用課税区分 | AT15: 集計用税率 | AV15: 雨 区域内 | AW15: 雨 区域外 | AX15: 雨 一般行政 | AY15: 雨水 計 | AZ15: 汚 基準内 | BA15: 汚 基準外 | BB15: 汚水 計 | BC15: 合計 | BD15: チェック | BE15: 備考 | BG15: 雨汚水分け対象1 | BH15: 雨汚水分け対象2 | BI15: 雨汚水分け対象3 | BJ15: 判定

Sheet 3条支出
D1: =+CONCATENATE("令和",DBCS(年度!A2),"年度決算 消費税算出資料") -> 令和５年度決算 消費税算出資料
D2: 【３条支出総括】
A3: 事業 | B3: 節 | C3: 細節 | D3: 費目 | E3: 税込決算額 | F3: 課税支出 | L3: 非課税支出 | M3: 不課税支出 | N3: 消費税 | T3: 税抜決算額 | U3: 消費税 端数確認 | Z3: 消費税端数調整ランク | AE3: 消費税 調整額
F4: 3 | G4: 5 | H4: 8 | I4: 8 | J4: 10 | K4: 計 | N4: 3 | O4: 5 | P4: 8 | Q4: 8 | R4: 10 | S4: 計 | U4: 3 | V4: 5 | W4: 8 | X4: 8 | Y4: 10 | Z4: 3 | AA4: 5 | AB4: 8 | AC4: 8 | AD4: 10 | AE4: 3 | AF4: 5 | AG4: 8 | AH4: 8 | AI4: 10
D5: 営業費用 | E5: =+SUM(E6:E20) -> 38667489041 | F5: =+SUM(F6:F20) -> 0 | G5: =+SUM(G6:G20) -> 0 | H5: =+SUM(H6:H20) -> 1196802 | I5: =+SUM(I6:I20) -> 500878 | J5: =+SUM(J6:J20) -> 9029006226 | K5: =+SUM(K6:K20) -> 9030703906 | L5: =+SUM(L6:L20) -> 417951500 | ... T5: =+SUM(T6:T20) -> 37846544540
D6: 管きょ費 | E6: =+管!E36 -> 611819957 | F6: =+管!F36 -> 0 | G6: =+管!G36 -> 0 | H6: =+管!H36 -> 678402 | I6: =+管!I36 -> 0 | J6: =+管!J36 -> 518156070 | K6: =+管!K36 -> 518834472 | L6: =+管!L36 -> 20454735 | M6: =+管!M36 -> 72530750 | N6: =+ROUND(F6*F$4/(100+F$4),0)+AE6 -> 0 | O6: =+ROUND(G6*G$4/(100+G$4),0)+AF6 -> 0 | P6: =+ROUND(H6*H$4/(100+H$4),0)+AG6 -> 50252 | Q6: =+ROUND(I6*I$4/(100+I$4),0)+AH6 -> 0 | R6: =+ROUND(J6*J$4/(100+J$4),0)+AI6 -> 47105097 | S6: =SUM(N6:R6) -> 47155349 | T6: =+E6-S6 -> 564664608 | U6: =N6-F6*F$4/(100+F$4) -> 0 | V6: =O6-G6*G$4/(100+G$4) -> 0 | W6: =P6-H6*H$4/(100+H$4) -> 0 | X6: =Q6-I6*I$4/(100+I$4) -> 0 | Y6: =R6-J6*J$4/(100+J$4) -> -0.27272727 | Z6: =+IF(N$43=0,0,IF(N$43<0,-RANK(U6,U$5:U$40,0),RANK(U6,U$5:U$40,1))) -> 0 | AA6: =+IF(O$43=0,0,IF(O$43<0,-RANK(V6,V$5:V$40,0),RANK(V6,V$5:V$40,1))) -> 0 | AB6: =+IF(P$43=0,0,IF(P$43<0,-RANK(W6,W$5:W$40,0),RANK(W6,W$5:W$40,1))) -> 0 | AC6: =+IF(Q$43=0,0,IF(Q$43<0,-RANK(X6,X$5:X$40,0),RANK(X6,X$5:X$40,1))) -> 0 | AD6: =+IF(R$43=0,0,IF(R$43<0,-RANK(Y6,Y$5:Y$40,0),RANK(Y6,Y$5:Y$40,1))) -> 0
D7: 水質指導費 | E7: =+水質!E36 -> 52443869 | F7: =+水質!F36 -> 0 | G7: =+水質!G36 -> 0 | H7: =+水質!H36 -> 0 | I7: =+水質!I36 -> 0 | J7: =+水質!J36 -> 12436317 | K7: =+水質!K36 -> 12436317 | L7: =+水質!L36 -> 6197563 | M7: =+水質!M36 -> 33809989 | N7: =+ROUND(F7*F$4/(100+F$4),0)+AE7 -> 0 | O7: =+ROUND(G7*G$4/(100+G$4),0)+AF7 -> 0 | P7: =+ROUND(H7*H$4/(100+H$4),0)+AG7 -> 0 | Q7: =+ROUND(I7*I$4/(100+I$4),0)+AH7 -> 0 | R7: =+ROUND(J7*J$4/(100+J$4),0)+AI7 -> 1130574 | S7: =SUM(N7:R7) -> 1130574 | T7: =+E7-S7 -> 51313295 | U7: =N7-F7*F$4/(100+F$4)-AE7 -> 0 | V7: =O7-G7*G$4/(100+G$4)-AF7 -> 0 | W7: =P7-H7*H$4/(100+H$4)-AG7 -> 0 | X7: =Q7-I7*I$4/(100+I$4)-AH7 -> 0 | Y7: =R7-J7*J$4/(100+J$4)-AI7 -> -0.27272727 | Z7: =+IF(N$43=0,0,IF(N$43<0,-RANK(U7,U$5:U$40,0),RANK(U7,U$5:U$40,1))) -> 0 | AA7: =+IF(O$43=0,0,IF(O$43<0,-RANK(V7,V$5:V$40,0),RANK(V7,V$5:V$40,1))) -> 0 | AB7: =+IF(P$43=0,0,IF(P$43<0,-RANK(W7,W$5:W$40,0),RANK(W7,W$5:W$40,1))) -> 0 | AC7: =+IF(Q$43=0,0,IF(Q$43<0,-RANK(X7,X$5:X$40,0),RANK(X7,X$5:X$40,1))) -> 0 | AD7: =+IF(R$43=0,0,IF(R$43<0,-RANK(Y7,Y$5:Y$40,0),RANK(Y7,Y$5:Y$40,1))) -> 0
D8: ポンプ場費 | E8: =+ポ!E36 -> 2356040225 | F8: =+ポ!F36 -> 0 | G8: =+ポ!G36 -> 0 | H8: =+ポ!H36 -> 0 | I8: =+ポ!I36 -> 30357 | J8: =+ポ!J36 -> 1148180103 | K8: =+ポ!K36 -> 1148210460 | L8: =+ポ!L36 -> 188585576 | M8: =+ポ!M36 -> 1019244189 | N8: =+ROUND(F8*F$4/(100+F$4),0)+AE8 -> 0 | O8: =+ROUND(G8*G$4/(100+G$4),0)+AF8 -> 0 | P8: =+ROUND(H8*H$4/(100+H$4),0)+AG8 -> 0 | Q8: =+ROUND(I8*I$4/(100+I$4),0)+AH8 -> 2249 | R8: =+ROUND(J8*J$4/(100+J$4),0)+AI8 -> 104380009 | S8: =SUM(N8:R8) -> 104382258 | T8: =+E8-S8 -> 2251657967 | U8: =N8-F8*F$4/(100+F$4)-AE8 -> 0 | V8: =O8-G8*G$4/(100+G$4)-AF8 -> 0 | W8: =P8-H8*H$4/(100+H$4)-AG8 -> 0 | X8: =Q8-I8*I$4/(100+I$4)-AH8 -> 0.33333333 | Y8: =R8-J8*J$4/(100+J$4)-AI8 -> -0.36363636 | Z8: =+IF(N$43=0,0,IF(N$43<0,-RANK(U8,U$5:U$40,0),RANK(U8,U$5:U$40,1))) -> 0 | AA8: =+IF(O$43=0,0,IF(O$43<0,-RANK(V8,V$5:V$40,0),RANK(V8,V$5:V$40,1))) -> 0 | AB8: =+IF(P$43=0,0,IF(P$43<0,-RANK(W8,W$5:W$40,0),RANK(W8,W$5:W$40,1))) -> 0 | AC8: =+IF(Q$43=0,0,IF(Q$43<0,-RANK(X8,X$5:X$40,0),RANK(X8,X$5:X$40,1))) -> 0 | AD8: =+IF(R$43=0,0,IF(R$43<0,-RANK(Y8,Y$5:Y$40,0),RANK(Y8,Y$5:Y$40,1))) -> 0
D9: 処理場費 | E9: =+処!E36 -> 6557703864 | F9: =+処!F36 -> 0 | G9: =+処!G36 -> 0 | H9: =+処!H36 -> 518400 | I9: =+処!I36 -> 144600 | J9: =+処!J36 -> 5718291420 | K9: =+処!K36 -> 5718954420 | L9: =+処!L36 -> 130669187 | M9: =+処!M36 -> 708080257 | N9: =+ROUND(F9*F$4/(100+F$4),0)+AE9 -> 0 | O9: =+ROUND(G9*G$4/(100+G$4),0)+AF9 -> 0 | P9: =+ROUND(H9*H$4/(100+H$4),0)+AG9 -> 38400 | Q9: =+ROUND(I9*I$4/(100+I$4),0)+AH9 -> 10711 | R9: =+ROUND(J9*J$4/(100+J$4),0)+AI9 -> 519844675 | S9: =SUM(N9:R9) -> 519893786 | T9: =+E9-S9 -> 6037810078 | U9: =N9-F9*F$4/(100+F$4)-AE9 -> 0 | V9: =O9-G9*G$4/(100+G$4)-AF9 -> 0 | W9: =P9-H9*H$4/(100+H$4)-AG9 -> 0 | X9: =Q9-I9*I$4/(100+I$4)-AH9 -> -0.11111111 | Y9: =R9-J9*J$4/(100+J$4)-AI9 -> 0.45454544 | Z9: =+IF(N$43=0,0,IF(N$43<0,-RANK(U9,U$5:U$40,0),RANK(U9,U$5:U$40,1))) -> 0 | AA9: =+IF(O$43=0,0,IF(O$43<0,-RANK(V9,V$5:V$40,0),RANK(V9,V$5:V$40,1))) -> 0 | AB9: =+IF(P$43=0,0,IF(P$43<0,-RANK(W9,W$5:W$40,0),RANK(W9,W$5:W$40,1))) -> 0 | AC9: =+IF(Q$43=0,0,IF(Q$43<0,-RANK(X9,X$5:X$40,0),RANK(X9,X$5:X$40,1))) -> 0 | AD9: =+IF(R$43=0,0,IF(R$43<0,-RANK(Y9,Y$5:Y$40,0),RANK(Y9,Y$5:Y$40,1))) -> 0
D10: 受託工事費 | E10: =+受工!E36 -> 0 | F10: =+受工!F36 -> 0 | G10: =+受工!G36 -> 0 | H10: =+受工!H36 -> 0 | I10: =+受工!I36 -> 0 | J10: =+受工!J36 -> 0 | K10: =+受工!K36 -> 0 | L10: =+受工!L36 -> 0 | M10: =+受工!M36 -> 0 | N10: =+ROUND(F10*F$4/(100+F$4),0)+AE10 -> 0 | O10: =+ROUND(G10*G$4/(100+G$4),0)+AF10 -> 0 | P10: =+ROUND(H10*H$4/(100+H$4),0)+AG10 -> 0 | Q10: =+ROUND(I10*I$4/(100+I$4),0)+AH10 -> 0 | R10: =+ROUND(J10*J$4/(100+J$4),0)+AI10 -> 0 | S10: =SUM(N10:R10) -> 0 | T10: =+E10-S10 -> 0 | U10: =N10-F10*F$4/(100+F$4)-AE10 -> 0 | V10: =O10-G10*G$4/(100+G$4)-AF10 -> 0 | W10: =P10-H10*H$4/(100+H$4)-AG10 -> 0 | X10: =Q10-I10*I$4/(100+I$4)-AH10 -> 0 | Y10: =R10-J10*J$4/(100+J$4)-AI10 -> 0 | Z10: =+IF(N$43=0,0,IF(N$43<0,-RANK(U10,U$5:U$40,0),RANK(U10,U$5:U$40,1))) -> 0 | AA10: =+IF(O$43=0,0,IF(O$43<0,-RANK(V10,V$5:V$40,0),RANK(V10,V$5:V$40,1))) -> 0 | AB10: =+IF(P$43=0,0,IF(P$43<0,-RANK(W10,W$5:W$40,0),RANK(W10,W$5:W$40,1))) -> 0 | AC10: =+IF(Q$43=0,0,IF(Q$43<0,-RANK(X10,X$5:X$40,0),RANK(X10,X$5:X$40,1))) -> 0 | AD10: =+IF(R$43=0,0,IF(R$43<0,-RANK(Y10,Y$5:Y$40,0),RANK(Y10,Y$5:Y$40,1))) -> 0
D11: 普及促進費 | E11: =+普及!E36 -> 88849549 | F11: =+普及!F36 -> 0 | G11: =+普及!G36 -> 0 | H11: =+普及!H36 -> 0 | I11: =+普及!I36 -> 0 | J11: =+普及!J36 -> 18870469 | K11: =+普及!K36 -> 18870469 | L11: =+普及!L36 -> 9614092 | M11: =+普及!M36 -> 60364988 | N11: =+ROUND(F11*F$4/(100+F$4),0)+AE11 -> 0 | O11: =+ROUND(G11*G$4/(100+G$4),0)+AF11 -> 0 | P11: =+ROUND(H11*H$4/(100+H$4),0)+AG11 -> 0 | Q11: =+ROUND(I11*I$4/(100+I$4),0)+AH11 -> 0 | R11: =+ROUND(J11*J$4/(100+J$4),0)+AI11 -> 1715497 | S11: =SUM(N11:R11) -> 1715497 | T11: =+E11-S11 -> 87134052 | U11: =N11-F11*F$4/(100+F$4)-AE11 -> 0 | V11: =O11-G11*G$4/(100+G$4)-AF11 -> 0 | W11: =P11-H11*H$4/(100+H$4)-AG11 -> 0 | X11: =Q11-I11*I$4/(100+I$4)-AH11 -> 0 | Y11: =R11-J11*J$4/(100+J$4)-AI11 -> -0.18181818 | Z11: =+IF(N$43=0,0,IF(N$43<0,-RANK(U11,U$5:U$40,0),RANK(U11,U$5:U$40,1))) -> 0 | AA11: =+IF(O$43=0,0,IF(O$43<0,-RANK(V11,V$5:V$40,0),RANK(V11,V$5:V$40,1))) -> 0 | AB11: =+IF(P$43=0,0,IF(P$43<0,-RANK(W11,W$5:W$40,0),RANK(W11,W$5:W$40,1))) -> 0 | AC11: =+IF(Q$43=0,0,IF(Q$43<0,-RANK(X11,X$5:X$40,0),RANK(X11,X$5:X$40,1))) -> 0 | AD11: =+IF(R$43=0,0,IF(R$43<0,-RANK(Y11,Y$5:Y$40,0),RANK(Y11,Y$5:Y$40,1))) -> 0
D12: 水洗化貸付事業費 | E12: =+貸付!E36 -> 10483859 | F12: =+貸付!F36 -> 0 | G12: =+貸付!G36 -> 0 | H12: =+貸付!H36 -> 0 | I12: =+貸付!I36 -> 0 | J12: =+貸付!J36 -> 963485 | K12: =+貸付!K36 -> 963485 | L12: =+貸付!L36 -> 1672623 | M12: =+貸付!M36 -> 7847751 | N12: =+ROUND(F12*F$4/(100+F$4),0)+AE12 -> 0 | O12: =+ROUND(G12*G$4/(100+G$4),0)+AF12 -> 0 | P12: =+ROUND(H12*H$4/(100+H$4),0)+AG12 -> 0 | Q12: =+ROUND(I12*I$4/(100+I$4),0)+AH12 -> 0 | R12: =+ROUND(J12*J$4/(100+J$4),0)+AI12 -> 87589 | S12: =SUM(N12:R12) -> 87589 | T12: =+E12-S12 -> 10396270 | U12: =N12-F12*F$4/(100+F$4)-AE12 -> 0 | V12: =O12-G12*G$4/(100+G$4)-AF12 -> 0 | W12: =P12-H12*H$4/(100+H$4)-AG12 -> 0 | X12: =Q12-I12*I$4/(100+I$4)-AH12 -> 0 | Y12: =R12-J12*J$4/(100+J$4)-AI12 -> 0.45454545 | Z12: =+IF(N$43=0,0,IF(N$43<0,-RANK(U12,U$5:U$40,0),RANK(U12,U$5:U$40,1))) -> 0 | AA12: =+IF(O$43=0,0,IF(O$43<0,-RANK(V12,V$5:V$40,0),RANK(V12,V$5:V$40,1))) -> 0 | AB12: =+IF(P$43=0,0,IF(P$43<0,-RANK(W12,W$5:W$40,0),RANK(W12,W$5:W$40,1))) -> 0 | AC12: =+IF(Q$43=0,0,IF(Q$43<0,-RANK(X12,X$5:X$40,0),RANK(X12,X$5:X$40,1))) -> 0 | AD12: =+IF(R$43=0,0,IF(R$43<0,-RANK(Y12,Y$5:Y$40,0),RANK(Y12,Y$5:Y$40,1))) -> 0 | AI12: -1
D13: 業務費 | E13: =+業務!E36 -> 1019945143 | F13: =+業務!F36 -> 0 | G13: =+業務!G36 -> 0 | H13: =+業務!H36 -> 0 | I13: =+業務!I36 -> 0 | J13: =+業務!J36 -> 992787715 | K13: =+業務!K36 -> 992787715 | L13: =+業務!L36 -> 4195233 | M13: =+業務!M36 -> 22962195 | N13: =+ROUND(F13*F$4/(100+F$4),0)+AE13 -> 0 | O13: =+ROUND(G13*G$4/(100+G$4),0)+AF13 -> 0 | P13: =+ROUND(H13*H$4/(100+H$4),0)+AG13 -> 0 | Q13: =+ROUND(I13*I$4/(100+I$4),0)+AH13 -> 0 | R13: =+ROUND(J13*J$4/(100+J$4),0)+AI13 -> 90253429 | S13: =SUM(N13:R13) -> 90253429 | T13: =+E13-S13 -> 929691714 | U13: =N13-F13*F$4/(100+F$4)-AE13 -> 0 | V13: =O13-G13*G$4/(100+G$4)-AF13 -> 0 | W13: =P13-H13*H$4/(100+H$4)-AG13 -> 0 | X13: =Q13-I13*I$4/(100+I$4)-AH13 -> 0 | Y13: =R13-J13*J$4/(100+J$4)-AI13 -> 0.36363636 | Z13: =+IF(N$43=0,0,IF(N$43<0,-RANK(U13,U$5:U$40,0),RANK(U13,U$5:U$40,1))) -> 0 | AA13: =+IF(O$43=0,0,IF(O$43<0,-RANK(V13,V$5:V$40,0),RANK(V13,V$5:V$40,1))) -> 0 | AB13: =+IF(P$43=0,0,IF(P$43<0,-RANK(W13,W$5:W$40,0),RANK(W13,W$5:W$40,1))) -> 0 | AC13: =+IF(Q$43=0,0,IF(Q$43<0,-RANK(X13,X$5:X$40,0),RANK(X13,X$5:X$40,1))) -> 0 | AD13: =+IF(R$43=0,0,IF(R$43<0,-RANK(Y13,Y$5:Y$40,0),RANK(Y13,Y$5:Y$40,1))) -> 0
D14: 総係費 | E14: =+総係!E37 -> 483965214 | F14: =+総係!F37 -> 0 | G14: =+総係!G37 -> 0 | H14: =+総係!H37 -> 0 | I14: =+総係!I37 -> 317198 | J14: =+総係!J37 -> 194208395 | K14: =+総係!K37 -> 194525593 | L14: =+総係!L37 -> 50827352 | M14: =+総係!M37 -> 238612269 | N14: =+ROUND(F14*F$4/(100+F$4),0)+AE14 -> 0 | O14: =+ROUND(G14*G$4/(100+G$4),0)+AF14 -> 0 | P14: =+ROUND(H14*H$4/(100+H$4),0)+AG14 -> 0 | Q14: =+ROUND(I14*I$4/(100+I$4),0)+AH14 -> 23496 | R14: =+ROUND(J14*J$4/(100+J$4),0)+AI14 -> 17655309 | S14: =SUM(N14:R14) -> 17678805 | T14: =+E14-S14 -> 466286409 | U14: =N14-F14*F$4/(100+F$4)-AE14 -> 0 | V14: =O14-G14*G$4/(100+G$4)-AF14 -> 0 | W14: =P14-H14*H$4/(100+H$4)-AG14 -> 0 | X14: =Q14-I14*I$4/(100+I$4)-AH14 -> -0.14814815 | Y14: =R14-J14*J$4/(100+J$4)-AI14 -> 0.36363636 | Z14: =+IF(N$43=0,0,IF(N$43<0,-RANK(U14,U$5:U$40,0),RANK(U14,U$5:U$40,1))) -> 0 | AA14: =+IF(O$43=0,0,IF(O$43<0,-RANK(V14,V$5:V$40,0),RANK(V14,V$5:V$40,1))) -> 0 | AB14: =+IF(P$43=0,0,IF(P$43<0,-RANK(W14,W$5:W$40,0),RANK(W14,W$5:W$40,1))) -> 0 | AC14: =+IF(Q$43=0,0,IF(Q$43<0,-RANK(X14,X$5:X$40,0),RANK(X14,X$5:X$40,1))) -> 0 | AD14: =+IF(R$43=0,0,IF(R$43<0,-RANK(Y14,Y$5:Y$40,0),RANK(Y14,Y$5:Y$40,1))) -> 0
D15: 特環費 | E15: =+特環!E37 -> 106990906 | F15: =+特環!F37 -> 0 | G15: =+特環!G37 -> 0 | H15: =+特環!H37 -> 0 | I15: =+特環!I37 -> 2121 | J15: =+特環!J37 -> 106852098 | K15: =+特環!K37 -> 106854219 | L15: =+特環!L37 -> 104407 | M15: =+特環!M37 -> 32280 | N15: =+ROUND(F15*F$4/(100+F$4),0)+AE15 -> 0 | O15: =+ROUND(G15*G$4/(100+G$4),0)+AF15 -> 0 | P15: =+ROUND(H15*H$4/(100+H$4),0)+AG15 -> 0 | Q15: =+ROUND(I15*I$4/(100+I$4),0)+AH15 -> 157 | R15: =+ROUND(J15*J$4/(100+J$4),0)+AI15 -> 9713827 | S15: =SUM(N15:R15) -> 9713984 | T15: =+E15-S15 -> 97276922
D16: 農集費 | E16: =+農集!E37 -> 247654024 | F16: =+農集!F37 -> 0 | G16: =+農集!G37 -> 0 | H16: =+農集!H37 -> 0 | I16: =+農集!I37 -> 5073 | J16: =+農集!J37 -> 247344387 | K16: =+農集!K37 -> 247349460 | L16: =+農集!L37 -> 182965 | M16: =+農集!M37 -> 121599 | N16: =+ROUND(F16*F$4/(100+F$4),0)+AE16 -> 0 | O16: =+ROUND(G16*G$4/(100+G$4),0)+AF16 -> 0 | P16: =+ROUND(H16*H$4/(100+H$4),0)+AG16 -> 0 | Q16: =+ROUND(I16*I$4/(100+I$4),0)+AH16 -> 376 | R16: =+ROUND(J16*J$4/(100+J$4),0)+AI16 -> 22485853 | S16: =SUM(N16:R16) -> 22486229 | T16: =+E16-S16 -> 225167795
D17: 浄化槽費 | E17: =+浄化!E37 -> 76388330 | F17: =+浄化!F37 -> 0 | G17: =+浄化!G37 -> 0 | H17: =+浄化!H37 -> 0 | I17: =+浄化!I37 -> 1529 | J17: =+浄化!J37 -> 70915767 | K17: =+浄化!K37 -> 70917296 | L17: =+浄化!L37 -> 5447767 | M17: =+浄化!M37 -> 23267 | N17: =+ROUND(F17*F$4/(100+F$4),0)+AE17 -> 0 | O17: =+ROUND(G17*G$4/(100+G$4),0)+AF17 -> 0 | P17: =+ROUND(H17*H$4/(100+H$4),0)+AG17 -> 0 | Q17: =+ROUND(I17*I$4/(100+I$4),0)+AH17 -> 113 | R17: =+ROUND(J17*J$4/(100+J$4),0)+AI17 -> 6446888 | S17: =SUM(N17:R17) -> 6447001 | T17: =+E17-S17 -> 69941329
D18: 災害復旧費 | E18: =+災!E36 -> 0 | F18: =+災!F36 -> 0 | G18: =+災!G36 -> 0 | H18: =+災!H36 -> 0 | I18: =+災!I36 -> 0 | J18: =+災!J36 -> 0 | K18: =+災!K36 -> 0 | L18: =+災!L36 -> 0 | M18: =+災!M36 -> 0 | N18: =+ROUND(F18*F$4/(100+F$4),0)+AE18 -> 0 | O18: =+ROUND(G18*G$4/(100+G$4),0)+AF18 -> 0 | P18: =+ROUND(H18*H$4/(100+H$4),0)+AG18 -> 0 | Q18: =+ROUND(I18*I$4/(100+I$4),0)+AH18 -> 0 | R18: =+ROUND(J18*J$4/(100+J$4),0)+AI18 -> 0 | S18: =SUM(N18:R18) -> 0 | T18: =+E18-S18 -> 0 | U18: =N18-F18*F$4/(100+F$4)-AE18 -> 0 | V18: =O18-G18*G$4/(100+G$4)-AF18 -> 0 | W18: =P18-H18*H$4/(100+H$4)-AG18 -> 0 | X18: =Q18-I18*I$4/(100+I$4)-AH18 -> 0 | Y18: =R18-J18*J$4/(100+J$4)-AI18 -> 0 | Z18: =+IF(N$43=0,0,IF(N$43<0,-RANK(U18,U$5:U$40,0),RANK(U18,U$5:U$40,1))) -> 0 | AA18: =+IF(O$43=0,0,IF(O$43<0,-RANK(V18,V$5:V$40,0),RANK(V18,V$5:V$40,1))) -> 0 | AB18: =+IF(P$43=0,0,IF(P$43<0,-RANK(W18,W$5:W$40,0),RANK(W18,W$5:W$40,1))) -> 0 | AC18: =+IF(Q$43=0,0,IF(Q$43<0,-RANK(X18,X$5:X$40,0),RANK(X18,X$5:X$40,1))) -> 0 | AD18: =+IF(R$43=0,0,IF(R$43<0,-RANK(Y18,Y$5:Y$40,0),RANK(Y18,Y$5:Y$40,1))) -> 0
D19: 減価償却費 | E19: =+減価!E36 -> 26551442230 | F19: =+減価!F36 -> 0 | G19: =+減価!G36 -> 0 | H19: =+減価!H36 -> 0 | I19: =+減価!I36 -> 0 | J19: =+減価!J36 -> 0 | K19: =+減価!K36 -> 0 | L19: =+減価!L36 -> 0 | M19: =+減価!M36 -> 26551442230 | N19: =+ROUND(F19*F$4/(100+F$4),0)+AE19 -> 0 | O19: =+ROUND(G19*G$4/(100+G$4),0)+AF19 -> 0 | P19: =+ROUND(H19*H$4/(100+H$4),0)+AG19 -> 0 | Q19: =+ROUND(I19*I$4/(100+I$4),0)+AH19 -> 0 | R19: =+ROUND(J19*J$4/(100+J$4),0)+AI19 -> 0 | S19: =SUM(N19:R19) -> 0 | T19: =+E19-S19 -> 26551442230 | U19: =N19-F19*F$4/(100+F$4)-AE19 -> 0 | V19: =O19-G19*G$4/(100+G$4)-AF19 -> 0 | W19: =P19-H19*H$4/(100+H$4)-AG19 -> 0 | X19: =Q19-I19*I$4/(100+I$4)-AH19 -> 0 | Y19: =R19-J19*J$4/(100+J$4)-AI19 -> 0 | Z19: =+IF(N$43=0,0,IF(N$43<0,-RANK(U19,U$5:U$40,0),RANK(U19,U$5:U$40,1))) -> 0 | AA19: =+IF(O$43=0,0,IF(O$43<0,-RANK(V19,V$5:V$40,0),RANK(V19,V$5:V$40,1))) -> 0 | AB19: =+IF(P$43=0,0,IF(P$43<0,-RANK(W19,W$5:W$40,0),RANK(W19,W$5:W$40,1))) -> 0 | AC19: =+IF(Q$43=0,0,IF(Q$43<0,-RANK(X19,X$5:X$40,0),RANK(X19,X$5:X$40,1))) -> 0 | AD19: =+IF(R$43=0,0,IF(R$43<0,-RANK(Y19,Y$5:Y$40,0),RANK(Y19,Y$5:Y$40,1))) -> 0
D20: 資産減耗費 | E20: =+減耗!E36 -> 503761871 | F20: =+減耗!F36 -> 0 | G20: =+減耗!G36 -> 0 | H20: =+減耗!H36 -> 0 | I20: =+減耗!I36 -> 0 | J20: =+減耗!J36 -> 0 | K20: =+減耗!K36 -> 0 | L20: =+減耗!L36 -> 0 | M20: =+減耗!M36 -> 503761871 | N20: =+ROUND(F20*F$4/(100+F$4),0)+AE20 -> 0 | O20: =+ROUND(G20*G$4/(100+G$4),0)+AF20 -> 0 | P20: =+ROUND(H20*H$4/(100+H$4),0)+AG20 -> 0 | Q20: =+ROUND(I20*I$4/(100+I$4),0)+AH20 -> 0 | R20: =+ROUND(J20*J$4/(100+J$4),0)+AI20 -> 0 | S20: =SUM(N20:R20) -> 0 | T20: =+E20-S20 -> 503761871 | U20: =N20-F20*F$4/(100+F$4)-AE20 -> 0 | V20: =O20-G20*G$4/(100+G$4)-AF20 -> 0 | W20: =P20-H20*H$4/(100+H$4)-AG20 -> 0 | X20: =Q20-I20*I$4/(100+I$4)-AH20 -> 0 | Y20: =R20-J20*J$4/(100+J$4)-AI20 -> 0 | Z20: =+IF(N$43=0,0,IF(N$43<0,-RANK(U20,U$5:U$40,0),RANK(U20,U$5:U$40,1))) -> 0 | AA20: =+IF(O$43=0,0,IF(O$43<0,-RANK(V20,V$5:V$40,0),RANK(V20,V$5:V$40,1))) -> 0 | AB20: =+IF(P$43=0,0,IF(P$43<0,-RANK(W20,W$5:W$40,0),RANK(W20,W$5:W$40,1))) -> 0 | AC20: =+IF(Q$43=0,0,IF(Q$43<0,-RANK(X20,X$5:X$40,0),RANK(X20,X$5:X$40,1))) -> 0 | AD20: =+IF(R$43=0,0,IF(R$43<0,-RANK(Y20,Y$5:Y$40,0),RANK(Y20,Y$5:Y$40,1))) -> 0
D22: 営業外費用 | E22: =+SUM(E23:E25) -> 3955185318 | F22: =+SUM(F23:F25) -> 0 | G22: =+SUM(G23:G25) -> 0 | H22: =+SUM(H23:H25) -> 23932 | I22: =+SUM(I23:I25) -> 0 | J22: =+SUM(J23:J25) -> 67182291 | K22: =+SUM(K23:K25) -> 67206223 | L22: =+SUM(L23:L25) -> 3884147396 | ... T22: =+SUM(T23:T25) -> 4161563541 | U22: =N22-F22*F$4/(100+F$4)-AE22 -> 0 | V22: =O22-G22*G$4/(100+G$4)-AF22 -> 0 | W22: =P22-H22*H$4/(100+H$4)-AG22 -> 0.25925926 | X22: =Q22-I22*I$4/(100+I$4)-AH22 -> 0 | Y22: =R22-J22*J$4/(100+J$4)-AI22 -> 0 | Z22: =+IF(N$43=0,0,IF(N$43<0,-RANK(U22,U$5:U$40,0),RANK(U22,U$5:U$40,1))) -> 0 | AA22: =+IF(O$43=0,0,IF(O$43<0,-RANK(V22,V$5:V$40,0),RANK(V22,V$5:V$40,1))) -> 0 | AB22: =+IF(P$43=0,0,IF(P$43<0,-RANK(W22,W$5:W$40,0),RANK(W22,W$5:W$40,1))) -> 0 | AC22: =+IF(Q$43=0,0,IF(Q$43<0,-RANK(X22,X$5:X$40,0),RANK(X22,X$5:X$40,1))) -> 0 | AD22: =+IF(R$43=0,0,IF(R$43<0,-RANK(Y22,Y$5:Y$40,0),RANK(Y22,Y$5:Y$40,1))) -> 0
D23: 支払利息・取扱費 | E23: =+営外!E5 -> 3945961149 | F23: =+営外!F5 -> 0 | G23: =+営外!G5 -> 0 | H23: =+営外!H5 -> 0 | I23: =+営外!I5 -> 0 | J23: =+営外!J5 -> 61813753 | K23: =+営外!K5 -> 61813753 | L23: =+営外!L5 -> 3884147396 | M23: =+営外!M5 -> 0 | N23: =+ROUND(F23*F$4/(100+F$4),0)+AE23 -> 0 | O23: =+ROUND(G23*G$4/(100+G$4),0)+AF23 -> 0 | P23: =+ROUND(H23*H$4/(100+H$4),0)+AG23 -> 0 | Q23: =+ROUND(I23*I$4/(100+I$4),0)+AH23 -> 0 | R23: =+ROUND(J23*J$4/(100+J$4),0)+AI23 -> 5619432 | S23: =SUM(N23:R23) -> 5619432 | T23: =+E23-S23 -> 3940341717 | U23: =N23-F23*F$4/(100+F$4)-AE23 -> 0 | V23: =O23-G23*G$4/(100+G$4)-AF23 -> 0 | W23: =P23-H23*H$4/(100+H$4)-AG23 -> 0 | X23: =Q23-I23*I$4/(100+I$4)-AH23 -> 0 | Y23: =R23-J23*J$4/(100+J$4)-AI23 -> -0.090909091 | Z23: =+IF(N$43=0,0,IF(N$43<0,-RANK(U23,U$5:U$40,0),RANK(U23,U$5:U$40,1))) -> 0 | AA23: =+IF(O$43=0,0,IF(O$43<0,-RANK(V23,V$5:V$40,0),RANK(V23,V$5:V$40,1))) -> 0 | AB23: =+IF(P$43=0,0,IF(P$43<0,-RANK(W23,W$5:W$40,0),RANK(W23,W$5:W$40,1))) -> 0 | AC23: =+IF(Q$43=0,0,IF(Q$43<0,-RANK(X23,X$5:X$40,0),RANK(X23,X$5:X$40,1))) -> 0 | AD23: =+IF(R$43=0,0,IF(R$43<0,-RANK(Y23,Y$5:Y$40,0),RANK(Y23,Y$5:Y$40,1))) -> 0
D24: 雑支出 | E24: =+営外!E14 -> 9224169 | F24: =+営外!F14 -> 0 | G24: =+営外!G14 -> 0 | H24: =+営外!H14 -> 23932 | I24: =+営外!I14 -> 0 | J24: =+営外!J14 -> 5368538 | K24: =+営外!K14 -> 5392470 | L24: =+営外!L14 -> 0 | M24: =+営外!M14 -> 3831699 | N24: =+ROUND(F24*F$4/(100+F$4),0)+AE24 -> 0 | O24: =+ROUND(G24*G$4/(100+G$4),0)+AF24 -> 0 | P24: =+ROUND(H24*H$4/(100+H$4),0)+AG24 -> 1773 | Q24: =+ROUND(I24*I$4/(100+I$4),0)+AH24 -> 0 | R24: =+ROUND(J24*J$4/(100+J$4),0)+AI24 -> 488049 | S24: =SUM(N24:R24) -> 489822 | T24: =+E24-S24 -> 8734347 | U24: =N24-F24*F$4/(100+F$4)-AE24 -> 0 | V24: =O24-G24*G$4/(100+G$4)-AF24 -> 0 | W24: =P24-H24*H$4/(100+H$4)-AG24 -> 0.25925926 | X24: =Q24-I24*I$4/(100+I$4)-AH24 -> 0 | Y24: =R24-J24*J$4/(100+J$4)-AI24 -> 0.090909091 | Z24: =+IF(N$43=0,0,IF(N$43<0,-RANK(U24,U$5:U$40,0),RANK(U24,U$5:U$40,1))) -> 0 | AA24: =+IF(O$43=0,0,IF(O$43<0,-RANK(V24,V$5:V$40,0),RANK(V24,V$5:V$40,1))) -> 0 | AB24: =+IF(P$43=0,0,IF(P$43<0,-RANK(W24,W$5:W$40,0),RANK(W24,W$5:W$40,1))) -> 0 | AC24: =+IF(Q$43=0,0,IF(Q$43<0,-RANK(X24,X$5:X$40,0),RANK(X24,X$5:X$40,1))) -> 0 | AD24: =+IF(R$43=0,0,IF(R$43<0,-RANK(Y24,Y$5:Y$40,0),RANK(Y24,Y$5:Y$40,1))) -> 0
D25: 消費税雑支出 | T25: =+SUM(営外!T17:T19) -> 212487477
D27: 特別損失 | E27: =+SUM(E28:E31) -> 20995298 | F27: =+SUM(F28:F31) -> 0 | G27: =+SUM(G28:G31) -> 0 | H27: =+SUM(H28:H31) -> 15407 | I27: =+SUM(I28:I31) -> 0 | J27: =+SUM(J28:J31) -> 10640333 | K27: =+SUM(K28:K31) -> 10655740 | L27: =+SUM(L28:L31) -> 6023 | ... T27: =+SUM(T28:T31) -> 20026854 | U27: =N27-F27*F$4/(100+F$4)-AE27 -> 0 | V27: =O27-G27*G$4/(100+G$4)-AF27 -> 0 | W27: =P27-H27*H$4/(100+H$4)-AG27 -> -0.25925926 | X27: =Q27-I27*I$4/(100+I$4)-AH27 -> 0 | Y27: =R27-J27*J$4/(100+J$4)-AI27 -> 0
D28: 過年度損益修正損 | E28: =+特損!E5 -> 10679943 | F28: =+特損!F5 -> 0 | G28: =+特損!G5 -> 0 | H28: =+特損!H5 -> 15407 | I28: =+特損!I5 -> 0 | J28: =+特損!J5 -> 10640333 | K28: =+特損!K5 -> 10655740 | L28: =+特損!L5 -> 6023 | M28: =+特損!M5 -> 18180 | N28: =+ROUND(F28*F$4/(100+F$4),0)+AE28 -> 0 | O28: =+ROUND(G28*G$4/(100+G$4),0)+AF28 -> 0 | P28: =+ROUND(H28*H$4/(100+H$4),0)+AG28 -> 1141 | Q28: =+ROUND(I28*I$4/(100+I$4),0)+AH28 -> 0 | R28: =+ROUND(J28*J$4/(100+J$4),0)+AI28 -> 967303 | S28: =SUM(N28:R28) -> 968444 | T28: =+E28-S28 -> 9711499 | U28: =N28-F28*F$4/(100+F$4)-AE28 -> 0 | V28: =O28-G28*G$4/(100+G$4)-AF28 -> 0 | W28: =P28-H28*H$4/(100+H$4)-AG28 -> -0.25925926 | X28: =Q28-I28*I$4/(100+I$4)-AH28 -> 0 | Y28: =R28-J28*J$4/(100+J$4)-AI28 -> 0 | Z28: =+IF(N$43=0,0,IF(N$43<0,-RANK(U28,U$5:U$40,0),RANK(U28,U$5:U$40,1))) -> 0 | AA28: =+IF(O$43=0,0,IF(O$43<0,-RANK(V28,V$5:V$40,0),RANK(V28,V$5:V$40,1))) -> 0 | AB28: =+IF(P$43=0,0,IF(P$43<0,-RANK(W28,W$5:W$40,0),RANK(W28,W$5:W$40,1))) -> 0 | AC28: =+IF(Q$43=0,0,IF(Q$43<0,-RANK(X28,X$5:X$40,0),RANK(X28,X$5:X$40,1))) -> 0 | AD28: =+IF(R$43=0,0,IF(R$43<0,-RANK(Y28,Y$5:Y$40,0),RANK(Y28,Y$5:Y$40,1))) -> 0
D29: その他特別損失 | E29: =+特損!E14 -> 0 | F29: =+特損!F14 -> 0 | G29: =+特損!G14 -> 0 | H29: =+特損!H14 -> 0 | I29: =+特損!I14 -> 0 | J29: =+特損!J14 -> 0 | K29: =+特損!K14 -> 0 | L29: =+特損!L14 -> 0 | M29: =+特損!M14 -> 0 | N29: =+ROUND(F29*F$4/(100+F$4),0)+AE29 -> 0 | O29: =+ROUND(G29*G$4/(100+G$4),0)+AF29 -> 0 | P29: =+ROUND(H29*H$4/(100+H$4),0)+AG29 -> 0 | Q29: =+ROUND(I29*I$4/(100+I$4),0)+AH29 -> 0 | R29: =+ROUND(J29*J$4/(100+J$4),0)+AI29 -> 0 | S29: =SUM(N29:R29) -> 0 | T29: =+E29-S29 -> 0 | U29: =N29-F29*F$4/(100+F$4)-AE29 -> 0 | V29: =O29-G29*G$4/(100+G$4)-AF29 -> 0 | W29: =P29-H29*H$4/(100+H$4)-AG29 -> 0 | X29: =Q29-I29*I$4/(100+I$4)-AH29 -> 0 | Y29: =R29-J29*J$4/(100+J$4)-AI29 -> 0 | Z29: =+IF(N$43=0,0,IF(N$43<0,-RANK(U29,U$5:U$40,0),RANK(U29,U$5:U$40,1))) -> 0 | AA29: =+IF(O$43=0,0,IF(O$43<0,-RANK(V29,V$5:V$40,0),RANK(V29,V$5:V$40,1))) -> 0 | AB29: =+IF(P$43=0,0,IF(P$43<0,-RANK(W29,W$5:W$40,0),RANK(W29,W$5:W$40,1))) -> 0 | AC29: =+IF(Q$43=0,0,IF(Q$43<0,-RANK(X29,X$5:X$40,0),RANK(X29,X$5:X$40,1))) -> 0 | AD29: =+IF(R$43=0,0,IF(R$43<0,-RANK(Y29,Y$5:Y$40,0),RANK(Y29,Y$5:Y$40,1))) -> 0
D30: 固定資産売却損 | E30: =+特損!E32 -> 10315355 | F30: =+特損!F32 -> 0 | G30: =+特損!G32 -> 0 | H30: =+特損!H32 -> 0 | I30: =+特損!I32 -> 0 | J30: =+特損!J32 -> 0 | K30: =+特損!K32 -> 0 | L30: =+特損!L32 -> 0 | M30: =+特損!M32 -> 10315355 | N30: =+ROUND(F30*F$4/(100+F$4),0)+AE30 -> 0 | O30: =+ROUND(G30*G$4/(100+G$4),0)+AF30 -> 0 | P30: =+ROUND(H30*H$4/(100+H$4),0)+AG30 -> 0 | Q30: =+ROUND(I30*I$4/(100+I$4),0)+AH30 -> 0 | R30: =+ROUND(J30*J$4/(100+J$4),0)+AI30 -> 0 | S30: =SUM(N30:R30) -> 0 | T30: =+E30-S30 -> 10315355 | U30: =N30-F30*F$4/(100+F$4)-AE30 -> 0 | V30: =O30-G30*G$4/(100+G$4)-AF30 -> 0 | W30: =P30-H30*H$4/(100+H$4)-AG30 -> 0 | X30: =Q30-I30*I$4/(100+I$4)-AH30 -> 0 | Y30: =R30-J30*J$4/(100+J$4)-AI30 -> 0 | Z30: =+IF(N$43=0,0,IF(N$43<0,-RANK(U30,U$5:U$40,0),RANK(U30,U$5:U$40,1))) -> 0 | AA30: =+IF(O$43=0,0,IF(O$43<0,-RANK(V30,V$5:V$40,0),RANK(V30,V$5:V$40,1))) -> 0 | AB30: =+IF(P$43=0,0,IF(P$43<0,-RANK(W30,W$5:W$40,0),RANK(W30,W$5:W$40,1))) -> 0 | AC30: =+IF(Q$43=0,0,IF(Q$43<0,-RANK(X30,X$5:X$40,0),RANK(X30,X$5:X$40,1))) -> 0 | AD30: =+IF(R$43=0,0,IF(R$43<0,-RANK(Y30,Y$5:Y$40,0),RANK(Y30,Y$5:Y$40,1))) -> 0
D31: 減損損失 | E31: =+特損!E34 -> 0 | F31: =+特損!F34 -> 0 | G31: =+特損!G34 -> 0 | H31: =+特損!H34 -> 0 | I31: =+特損!I34 -> 0 | J31: =+特損!J34 -> 0 | K31: =+特損!K34 -> 0 | L31: =+特損!L34 -> 0 | M31: =+特損!M34 -> 0 | N31: =+ROUND(F31*F$4/(100+F$4),0)+AE31 -> 0 | O31: =+ROUND(G31*G$4/(100+G$4),0)+AF31 -> 0 | P31: =+ROUND(H31*H$4/(100+H$4),0)+AG31 -> 0 | Q31: =+ROUND(I31*I$4/(100+I$4),0)+AH31 -> 0 | R31: =+ROUND(J31*J$4/(100+J$4),0)+AI31 -> 0 | S31: =SUM(N31:R31) -> 0 | T31: =+E31-S31 -> 0 | U31: =N31-F31*F$4/(100+F$4)-AE31 -> 0 | V31: =O31-G31*G$4/(100+G$4)-AF31 -> 0 | W31: =P31-H31*H$4/(100+H$4)-AG31 -> 0 | X31: =Q31-I31*I$4/(100+I$4)-AH31 -> 0 | Y31: =R31-J31*J$4/(100+J$4)-AI31 -> 0 | Z31: =+IF(N$43=0,0,IF(N$43<0,-RANK(U31,U$5:U$40,0),RANK(U31,U$5:U$40,1))) -> 0 | AA31: =+IF(O$43=0,0,IF(O$43<0,-RANK(V31,V$5:V$40,0),RANK(V31,V$5:V$40,1))) -> 0 | AB31: =+IF(P$43=0,0,IF(P$43<0,-RANK(W31,W$5:W$40,0),RANK(W31,W$5:W$40,1))) -> 0 | AC31: =+IF(Q$43=0,0,IF(Q$43<0,-RANK(X31,X$5:X$40,0),RANK(X31,X$5:X$40,1))) -> 0 | AD31: =+IF(R$43=0,0,IF(R$43<0,-RANK(Y31,Y$5:Y$40,0),RANK(Y31,Y$5:Y$40,1))) -> 0
U36: =+IF(F36=0,"",ROUND(F36*F$4/(100+F$4),7)-N36) | V36: =+IF(G36=0,"",ROUND(G36*G$4/(100+G$4),7)-O36) | Y36: =+IF(J36=0,"",ROUND(J36*J$4/(100+J$4),7)-R36) | AB36: =+IF(SUM(U36:Y36)=0,"",SUM(U36:Y36))
U37: =+IF(F37=0,"",ROUND(F37*F$4/(100+F$4),7)-N37) | V37: =+IF(G37=0,"",ROUND(G37*G$4/(100+G$4),7)-O37)
U38: =+IF(F38=0,"",ROUND(F38*F$4/(100+F$4),7)-N38) | V38: =+IF(G38=0,"",ROUND(G38*G$4/(100+G$4),7)-O38) | W38: =+IF(H38=0,"",ROUND(H38*H$4/(100+H$4),7)-P38) | Y38: =+IF(J38=0,"",ROUND(J38*J$4/(100+J$4),7)-R38) | AB38: =+IF(SUM(U38:Y38)=0,"",SUM(U38:Y38))
U39: =+IF(F39=0,"",ROUND(F39*F$4/(100+F$4),7)-N39) | V39: =+IF(G39=0,"",ROUND(G39*G$4/(100+G$4),7)-O39) | W39: =+IF(H39=0,"",ROUND(H39*H$4/(100+H$4),7)-P39) | Y39: =+IF(J39=0,"",ROUND(J39*J$4/(100+J$4),7)-R39) | AB39: =+IF(SUM(U39:Y39)=0,"",SUM(U39:Y39))
U40: =+IF(F40=0,"",ROUND(F40*F$4/(100+F$4),7)-N40)
D41: 計 | E41: =+SUM(E5,E22,E27) -> 42643669657 | F41: =+SUM(F5,F22,F27) -> 0 | G41: =+SUM(G5,G22,G27) -> 0 | H41: =+SUM(H5,H22,H27) -> 1236141 | I41: =+SUM(I5,I22,I27) -> 500878 | J41: =+SUM(J5,J22,J27) -> 9106828850 | K41: =+SUM(K5,K22,K27) -> 9108565869 | L41: =+SUM(L5,L22,L27) -> 4302104919 | ... T41: =+SUM(T5,T22,T27) -> 42028134935
D42: 総額検算 | E42: =+E41 -> 42643669657 | F42: =+F41 -> 0 | G42: =+G41 -> 0 | H42: =+H41 -> 1236141 | I42: =+I41 -> 500878 | J42: =+J41 -> 9106828850 | K42: =SUM(F42:J42) -> 9108565869 | L42: =+L41 -> 4302104919 | M42: =+M41 -> 29232998869 | N42: =+ROUNDDOWN(F42*F$4/(100+F$4),0) -> 0 | O42: =+ROUNDDOWN(G42*G$4/(100+G$4),0) -> 0 | P42: =+ROUNDDOWN(H42*H$4/(100+H$4),0) -> 91566 | Q42: =+ROUNDDOWN(I42*I$4/(100+I$4),0) -> 37102 | R42: =+ROUNDDOWN(J42*J$4/(100+J$4),0) -> 827893531 | S42: =SUM(N42:R42) -> 828022199 | T42: =+E42-S42 -> 41815647458
E43: =+E42-E41 -> 0 | F43: =+F42-F41 -> 0 | G43: =+G42-G41 -> 0 | H43: =+H42-H41 -> 0 | I43: =+I42-I41 -> 0 | J43: =+J42-J41 -> 0 | K43: =+K42-K41 -> 0 | L43: =+L42-L41 -> 0 | ... T43: =+T42-T41 -> -212487477
D45: 消費税及び地方消費税 | E45: =[1]消費税!$Z$118+[1]消費税!$AF$118 -> 343538729 | F45: 消費税中間 | G45: =+営外!E39 -> 42630200 | P45: 仕入税額控除不可消費税 | S45: ='[2]3条収入'!AH69 -> 210253123
D46: 税込決算額 | E46: =+E41+E45 -> 42987208386 | S46: =S42 -> 828022199 | T46: =T41+S46 -> 42856157134
T47: =E41-T46+S45 -> -2234354 | U47: ←仕入控除税額の算定にあたり、仮払消費税額×課税売上割合しか計上できないことにより控除できない額（マイナス表示）
...

Sheet 管
D1: =+'3条支出'!D1 -> 令和５年度決算 消費税算出資料
D2: 【管きょ費】
A3: 事業 | B3: 節 | C3: 細節 | D3: 費目 | E3: 税込決算額 | F3: 課税支出 | L3: 非課税支出 | M3: 不課税支出 | N3: 消費税 | T3: 税抜決算額 | U3: 消費税 端数確認 | Z3: 消費税端数調整ランク | AE3: 消費税 調整額
F4: 3 | G4: 5 | H4: 8 | I4: 8 | J4: 10 | K4: 計 | N4: 3 | O4: 5 | P4: 8 | Q4: 8 | R4: 10 | S4: 計 | U4: 3 | V4: 5 | W4: 8 | X4: 8 | Y4: 10 | Z4: 3 | AA4: 5 | AB4: 8 | AC4: 8 | AD4: 10 | AE4: 3 | AF4: 5 | AG4: 8 | AH4: 8 | AI4: 10
A5: 1 | B5: 8830201 | D5: 報酬 | E5: =+IF($A5="",IF($C5="",SUMIFS(全伝票!I:I,全伝票!$B:$B,$B5),SUMIFS(全伝票!I:I,全伝票!$C:$C,$C5)),IF($C5="",SUMIFS(全伝票!I:I,全伝票!$A:$A,$A5,全伝票!$B:$B,$B5),SUMIFS(全伝票!I:I,全伝票!$A:$A,$A5,全伝票!$C:$C,$C5))) -> 0 | F5: =+IF($A5="",IF($C5="",SUMIFS(全伝票!J:J,全伝票!$B:$B,$B5),SUMIFS(全伝票!J:J,全伝票!$C:$C,$C5)),IF($C5="",SUMIFS(全伝票!J:J,全伝票!$A:$A,$A5,全伝票!$B:$B,$B5),SUMIFS(全伝票!J:J,全伝票!$A:$A,$A5,全伝票!$C:$C,$C5))) -> 0 | G5: =+IF($A5="",IF($C5="",SUMIFS(全伝票!K:K,全伝票!$B:$B,$B5),SUMIFS(全伝票!K:K,全伝票!$C:$C,$C5)),IF($C5="",SUMIFS(全伝票!K:K,全伝票!$A:$A,$A5,全伝票!$B:$B,$B5),SUMIFS(全伝票!K:K,全伝票!$A:$A,$A5,全伝票!$C:$C,$C5))) -> 0 | H5: =+IF($A5="",IF($C5="",SUMIFS(全伝票!L:L,全伝票!$B:$B,$B5),SUMIFS(全伝票!L:L,全伝票!$C:$C,$C5)),IF($C5="",SUMIFS(全伝票!L:L,全伝票!$A:$A,$A5,全伝票!$B:$B,$B5),SUMIFS(全伝票!L:L,全伝票!$A:$A,$A5,全伝票!$C:$C,$C5))) -> 0 | I5: =+IF($A5="",IF($C5="",SUMIFS(全伝票!M:M,全伝票!$B:$B,$B5),SUMIFS(全伝票!M:M,全伝票!$C:$C,$C5)),IF($C5="",SUMIFS(全伝票!M:M,全伝票!$A:$A,$A5,全伝票!$B:$B,$B5),SUMIFS(全伝票!M:M,全伝票!$A:$A,$A5,全伝票!$C:$C,$C5))) -> 0 | J5: =+IF($A5="",IF($C5="",SUMIFS(全伝票!N:N,全伝票!$B:$B,$B5),SUMIFS(全伝票!N:N,全伝票!$C:$C,$C5)),IF($C5="",SUMIFS(全伝票!N:N,全伝票!$A:$A,$A5,全伝票!$B:$B,$B5),SUMIFS(全伝票!N:N,全伝票!$A:$A,$A5,全伝票!$C:$C,$C5))) -> 0 | K5: =SUM(F5:J5) -> 0 | L5: =+IF($A5="",IF($C5="",SUMIFS(全伝票!O:O,全伝票!$B:$B,$B5),SUMIFS(全伝票!O:O,全伝票!$C:$C,$C5)),IF($C5="",SUMIFS(全伝票!O:O,全伝票!$A:$A,$A5,全伝票!$B:$B,$B5),SUMIFS(全伝票!O:O,全伝票!$A:$A,$A5,全伝票!$C:$C,$C5))) -> 0 | M5: =+IF($A5="",IF($C5="",SUMIFS(全伝票!P:P,全伝票!$B:$B,$B5),SUMIFS(全伝票!P:P,全伝票!$C:$C,$C5)),IF($C5="",SUMIFS(全伝票!P:P,全伝票!$A:$A,$A5,全伝票!$B:$B,$B5),SUMIFS(全伝票!P:P,全伝票!$A:$A,$A5,全伝票!$C:$C,$C5))) -> 0 | N5: =+ROUND(F5*F$4/(100+F$4),0)+AE5 -> 0 | O5: =+ROUND(G5*G$4/(100+G$4),0)+AF5 -> 0 | P5: =+ROUND(H5*H$4/(100+H$4),0)+AG5 -> 0 | Q5: =+ROUND(I5*I$4/(100+I$4),0)+AH5 -> 0 | R5: =+ROUND(J5*J$4/(100+J$4),0)+AI5 -> 0 | S5: =SUM(N5:R5) -> 0 | T5: =+E5-S5 -> 0 | U5: =N5-F5*F$4/(100+F$4) -> 0 | V5: =O5-G5*G$4/(100+G$4) -> 0 | W5: =P5-H5*H$4/(100+H$4) -> 0 | X5: =Q5-I5*I$4/(100+I$4) -> 0 | Y5: =R5-J5*J$4/(100+J$4) -> 0 | Z5: =+IF(N$38=0,0,IF(N$38<0,-RANK(U5,U$5:U$35,0),RANK(U5,U$5:U$35,1))) -> 0 | AA5: =+IF(O$38=0,0,IF(O$38<0,-RANK(V5,V$5:V$35,0),RANK(V5,V$5:V$35,1))) -> 0 | AB5: =+IF(P$38=0,0,IF(P$38<0,-RANK(W5,W$5:W$35,0),RANK(W5,W$5:W$35,1))) -> 0 | AC5: =+IF(Q$38=0,0,IF(Q$38<0,-RANK(X5,X$5:X$35,0),RANK(X5,X$5:X$35,1))) -> 0 | AD5: =+IF(R$38=0,0,IF(R$38<0,-RANK(Y5,Y$5:Y$35,0),RANK(Y5,Y$5:Y$35,1))) -> 0
A6: 1 | B6: 8830202 | D6: 給料 | E6: =+IF($A6="",IF($C6="",SUMIFS(全伝票!I:I,全伝票!$B:$B,$B6),SUMIFS(全伝票!I:I,全伝票!$C:$C,$C6)),IF($C6="",SUMIFS(全伝票!I:I,全伝票!$A:$A,$A6,全伝票!$B:$B,$B6),SUMIFS(全伝票!I:I,全伝票!$A:$A,$A6,全伝票!$C:$C,$C6))) -> 39580800 | F6: =+IF($A6="",IF($C6="",SUMIFS(全伝票!J:J,全伝票!$B:$B,$B6),SUMIFS(全伝票!J:J,全伝票!$C:$C,$C6)),IF($C6="",SUMIFS(全伝票!J:J,全伝票!$A:$A,$A6,全伝票!$B:$B,$B6),SUMIFS(全伝票!J:J,全伝票!$A:$A,$A6,全伝票!$C:$C,$C6))) -> 0 | G6: =+IF($A6="",IF($C6="",SUMIFS(全伝票!K:K,全伝票!$B:$B,$B6),SUMIFS(全伝票!K:K,全伝票!$C:$C,$C6)),IF($C6="",SUMIFS(全伝票!K:K,全伝票!$A:$A,$A6,全伝票!$B:$B,$B6),SUMIFS(全伝票!K:K,全伝票!$A:$A,$A6,全伝票!$C:$C,$C6))) -> 0 | H6: =+IF($A6="",IF($C6="",SUMIFS(全伝票!L:L,全伝票!$B:$B,$B6),SUMIFS(全伝票!L:L,全伝票!$C:$C,$C6)),IF($C6="",SUMIFS(全伝票!L:L,全伝票!$A:$A,$A6,全伝票!$B:$B,$B6),SUMIFS(全伝票!L:L,全伝票!$A:$A,$A6,全伝票!$C:$C,$C6))) -> 0 | I6: =+IF($A6="",IF($C6="",SUMIFS(全伝票!M:M,全伝票!$B:$B,$B6),SUMIFS(全伝票!M:M,全伝票!$C:$C,$C6)),IF($C6="",SUMIFS(全伝票!M:M,全伝票!$A:$A,$A6,全伝票!$B:$B,$B6),SUMIFS(全伝票!M:M,全伝票!$A:$A,$A6,全伝票!$C:$C,$C6))) -> 0 | J6: =+IF($A6="",IF($C6="",SUMIFS(全伝票!N:N,全伝票!$B:$B,$B6),SUMIFS(全伝票!N:N,全伝票!$C:$C,$C6)),IF($C6="",SUMIFS(全伝票!N:N,全伝票!$A:$A,$A6,全伝票!$B:$B,$B6),SUMIFS(全伝票!N:N,全伝票!$A:$A,$A6,全伝票!$C:$C,$C6))) -> 0 | K6: =SUM(F6:J6) -> 0 | L6: =+IF($A6="",IF($C6="",SUMIFS(全伝票!O:O,全伝票!$B:$B,$B6),SUMIFS(全伝票!O:O,全伝票!$C:$C,$C6)),IF($C6="",SUMIFS(全伝票!O:O,全伝票!$A:$A,$A6,全伝票!$B:$B,$B6),SUMIFS(全伝票!O:O,全伝票!$A:$A,$A6,全伝票!$C:$C,$C6))) -> 0 | M6: =+IF($A6="",IF($C6="",SUMIFS(全伝票!P:P,全伝票!$B:$B,$B6),SUMIFS(全伝票!P:P,全伝票!$C:$C,$C6)),IF($C6="",SUMIFS(全伝票!P:P,全伝票!$A:$A,$A6,全伝票!$B:$B,$B6),SUMIFS(全伝票!P:P,全伝票!$A:$A,$A6,全伝票!$C:$C,$C6))) -> 39580800 | N6: =+ROUND(F6*F$4/(100+F$4),0)+AE6 -> 0 | O6: =+ROUND(G6*G$4/(100+G$4),0)+AF6 -> 0 | P6: =+ROUND(H6*H$4/(100+H$4),0)+AG6 -> 0 | Q6: =+ROUND(I6*I$4/(100+I$4),0)+AH6 -> 0 | R6: =+ROUND(J6*J$4/(100+J$4),0)+AI6 -> 0 | S6: =SUM(N6:R6) -> 0 | T6: =+E6-S6 -> 39580800 | U6: =N6-F6*F$4/(100+F$4) -> 0 | V6: =O6-G6*G$4/(100+G$4) -> 0 | W6: =P6-H6*H$4/(100+H$4) -> 0 | X6: =Q6-I6*I$4/(100+I$4) -> 0 | Y6: =R6-J6*J$4/(100+J$4) -> 0 | Z6: =+IF(N$38=0,0,IF(N$38<0,-RANK(U6,U$5:U$35,0),RANK(U6,U$5:U$35,1))) -> 0 | AA6: =+IF(O$38=0,0,IF(O$38<0,-RANK(V6,V$5:V$35,0),RANK(V6,V$5:V$35,1))) -> 0 | AB6: =+IF(P$38=0,0,IF(P$38<0,-RANK(W6,W$5:W$35,0),RANK(W6,W$5:W$35,1))) -> 0 | AC6: =+IF(Q$38=0,0,IF(Q$38<0,-RANK(X6,X$5:X$35,0),RANK(X6,X$5:X$35,1))) -> 0 | AD6: =+IF(R$38=0,0,IF(R$38<0,-RANK(Y6,Y$5:Y$35,0),RANK(Y6,Y$5:Y$35,1))) -> 0
A7: 1 | B7: 8830203 | D7: 手当等 | E7: =+IF($A7="",IF($C7="",SUMIFS(全伝票!I:I,全伝票!$B:$B,$B7),SUMIFS(全伝票!I:I,全伝票!$C:$C,$C7)),IF($C7="",SUMIFS(全伝票!I:I,全伝票!$A:$A,$A7,全伝票!$B:$B,$B7),SUMIFS(全伝票!I:I,全伝票!$A:$A,$A7,全伝票!$C:$C,$C7))) -> 28582995 | F7: =+IF($A7="",IF($C7="",SUMIFS(全伝票!J:J,全伝票!$B:$B,$B7),SUMIFS(全伝票!J:J,全伝票!$C:$C,$C7)),IF($C7="",SUMIFS(全伝票!J:J,全伝票!$A:$A,$A7,全伝票!$B:$B,$B7),SUMIFS(全伝票!J:J,全伝票!$A:$A,$A7,全伝票!$C:$C,$C7))) -> 0 | G7: =+IF($A7="",IF($C7="",SUMIFS(全伝票!K:K,全伝票!$B:$B,$B7),SUMIFS(全伝票!K:K,全伝票!$C:$C,$C7)),IF($C7="",SUMIFS(全伝票!K:K,全伝票!$A:$A,$A7,全伝票!$B:$B,$B7),SUMIFS(全伝票!K:K,全伝票!$A:$A,$A7,全伝票!$C:$C,$C7))) -> 0 | H7: =+IF($A7="",IF($C7="",SUMIFS(全伝票!L:L,全伝票!$B:$B,$B7),SUMIFS(全伝票!L:L,全伝票!$C:$C,$C7)),IF($C7="",SUMIFS(全伝票!L:L,全伝票!$A:$A,$A7,全伝票!$B:$B,$B7),SUMIFS(全伝票!L:L,全伝票!$A:$A,$A7,全伝票!$C:$C,$C7))) -> 0 | I7: =+IF($A7="",IF($C7="",SUMIFS(全伝票!M:M,全伝票!$B:$B,$B7),SUMIFS(全伝票!M:M,全伝票!$C:$C,$C7)),IF($C7="",SUMIFS(全伝票!M:M,全伝票!$A:$A,$A7,全伝票!$B:$B,$B7),SUMIFS(全伝票!M:M,全伝票!$A:$A,$A7,全伝票!$C:$C,$C7))) -> 0 | J7: =+IF($A7="",IF($C7="",SUMIFS(全伝票!N:N,全伝票!$B:$B,$B7),SUMIFS(全伝票!N:N,全伝票!$C:$C,$C7)),IF($C7="",SUMIFS(全伝票!N:N,全伝票!$A:$A,$A7,全伝票!$B:$B,$B7),SUMIFS(全伝票!N:N,全伝票!$A:$A,$A7,全伝票!$C:$C,$C7))) -> 1117260 | K7: =SUM(F7:J7) -> 1117260 | L7: =+IF($A7="",IF($C7="",SUMIFS(全伝票!O:O,全伝票!$B:$B,$B7),SUMIFS(全伝票!O:O,全伝票!$C:$C,$C7)),IF($C7="",SUMIFS(全伝票!O:O,全伝票!$A:$A,$A7,全伝票!$B:$B,$B7),SUMIFS(全伝票!O:O,全伝票!$A:$A,$A7,全伝票!$C:$C,$C7))) -> 0 | M7: =+IF($A7="",IF($C7="",SUMIFS(全伝票!P:P,全伝票!$B:$B,$B7),SUMIFS(全伝票!P:P,全伝票!$C:$C,$C7)),IF($C7="",SUMIFS(全伝票!P:P,全伝票!$A:$A,$A7,全伝票!$B:$B,$B7),SUMIFS(全伝票!P:P,全伝票!$A:$A,$A7,全伝票!$C:$C,$C7))) -> 27465735 | N7: =+ROUND(F7*F$4/(100+F$4),0)+AE7 -> 0 | O7: =+ROUND(G7*G$4/(100+G$4),0)+AF7 -> 0 | P7: =+ROUND(H7*H$4/(100+H$4),0)+AG7 -> 0 | Q7: =+ROUND(I7*I$4/(100+I$4),0)+AH7 -> 0 | R7: =+ROUND(J7*J$4/(100+J$4),0)+AI7 -> 101569 | S7: =SUM(N7:R7) -> 101569 | T7: =+E7-S7 -> 28481426 | U7: =N7-F7*F$4/(100+F$4) -> 0 | V7: =O7-G7*G$4/(100+G$4) -> 0 | W7: =P7-H7*H$4/(100+H$4) -> 0 | X7: =Q7-I7*I$4/(100+I$4) -> 0 | Y7: =R7-J7*J$4/(100+J$4) -> -0.090909091 | Z7: =+IF(N$38=0,0,IF(N$38<0,-RANK(U7,U$5:U$35,0),RANK(U7,U$5:U$35,1))) -> 0 | AA7: =+IF(O$38=0,0,IF(O$38<0,-RANK(V7,V$5:V$35,0),RANK(V7,V$5:V$35,1))) -> 0 | AB7: =+IF(P$38=0,0,IF(P$38<0,-RANK(W7,W$5:W$35,0),RANK(W7,W$5:W$35,1))) -> 0 | AC7: =+IF(Q$38=0,0,IF(Q$38<0,-RANK(X7,X$5:X$35,0),RANK(X7,X$5:X$35,1))) -> 0 | AD7: =+IF(R$38=0,0,IF(R$38<0,-RANK(Y7,Y$5:Y$35,0),RANK(Y7,Y$5:Y$35,1))) -> 0
A8: 1 | B8: 8830204 | D8: 法定福利費 | E8: =+IF($A8="",IF($C8="",SUMIFS(全伝票!I:I,全伝票!$B:$B,$B8),SUMIFS(全伝票!I:I,全伝票!$C:$C,$C8)),IF($C8="",SUMIFS(全伝票!I:I,全伝票!$A:$A,$A8,全伝票!$B:$B,$B8),SUMIFS(全伝票!I:I,全伝票!$A:$A,$A8,全伝票!$C:$C,$C8))) -> 13837163 | F8: =+IF($A8="",IF($C8="",SUMIFS(全伝票!J:J,全伝票!$B:$B,$B8),SUMIFS(全伝票!J:J,全伝票!$C:$C,$C8)),IF($C8="",SUMIFS(全伝票!J:J,全伝票!$A:$A,$A8,全伝票!$B:$B,$B8),SUMIFS(全伝票!J:J,全伝票!$A:$A,$A8,全伝票!$C:$C,$C8))) -> 0 | G8: =+IF($A8="",IF($C8="",SUMIFS(全伝票!K:K,全伝票!$B:$B,$B8),SUMIFS(全伝票!K:K,全伝票!$C:$C,$C8)),IF($C8="",SUMIFS(全伝票!K:K,全伝票!$A:$A,$A8,全伝票!$B:$B,$B8),SUMIFS(全伝票!K:K,全伝票!$A:$A,$A8,全伝票!$C:$C,$C8))) -> 0 | H8: =+IF($A8="",IF($C8="",SUMIFS(全伝票!L:L,全伝票!$B:$B,$B8),SUMIFS(全伝票!L:L,全伝票!$C:$C,$C8)),IF($C8="",SUMIFS(全伝票!L:L,全伝票!$A:$A,$A8,全伝票!$B:$B,$B8),SUMIFS(全伝票!L:L,全伝票!$A:$A,$A8,全伝票!$C:$C,$C8))) -> 0 | I8: =+IF($A8="",IF($C8="",SUMIFS(全伝票!M:M,全伝票!$B:$B,$B8),SUMIFS(全伝票!M:M,全伝票!$C:$C,$C8)),IF($C8="",SUMIFS(全伝票!M:M,全伝票!$A:$A,$A8,全伝票!$B:$B,$B8),SUMIFS(全伝票!M:M,全伝票!$A:$A,$A8,全伝票!$C:$C,$C8))) -> 0 | J8: =+IF($A8="",IF($C8="",SUMIFS(全伝票!N:N,全伝票!$B:$B,$B8),SUMIFS(全伝票!N:N,全伝票!$C:$C,$C8)),IF($C8="",SUMIFS(全伝票!N:N,全伝票!$A:$A,$A8,全伝票!$B:$B,$B8),SUMIFS(全伝票!N:N,全伝票!$A:$A,$A8,全伝票!$C:$C,$C8))) -> 0 | K8: =SUM(F8:J8) -> 0 | L8: =+IF($A8="",IF($C8="",SUMIFS(全伝票!O:O,全伝票!$B:$B,$B8),SUMIFS(全伝票!O:O,全伝票!$C:$C,$C8)),IF($C8="",SUMIFS(全伝票!O:O,全伝票!$A:$A,$A8,全伝票!$B:$B,$B8),SUMIFS(全伝票!O:O,全伝票!$A:$A,$A8,全伝票!$C:$C,$C8))) -> 13772507 | M8: =+IF($A8="",IF($C8="",SUMIFS(全伝票!P:P,全伝票!$B:$B,$B8),SUMIFS(全伝票!P:P,全伝票!$C:$C,$C8)),IF($C8="",SUMIFS(全伝票!P:P,全伝票!$A:$A,$A8,全伝票!$B:$B,$B8),SUMIFS(全伝票!P:P,全伝票!$A:$A,$A8,全伝票!$C:$C,$C8))) -> 64656 | N8: =+ROUND(F8*F$4/(100+F$4),0)+AE8 -> 0 | O8: =+ROUND(G8*G$4/(100+G$4),0)+AF8 -> 0 | P8: =+ROUND(H8*H$4/(100+H$4),0)+AG8 -> 0 | Q8: =+ROUND(I8*I$4/(100+I$4),0)+AH8 -> 0 | R8: =+ROUND(J8*J$4/(100+J$4),0)+AI8 -> 0 | S8: =SUM(N8:R8) -> 0 | T8: =+E8-S8 -> 13837163 | U8: =N8-F8*F$4/(100+F$4) -> 0 | V8: =O8-G8*G$4/(100+G$4) -> 0 | W8: =P8-H8*H$4/(100+H$4) -> 0 | X8: =Q8-I8*I$4/(100+I$4) -> 0 | Y8: =R8-J8*J$4/(100+J$4) -> 0 | Z8: =+IF(N$38=0,0,IF(N$38<0,-RANK(U8,U$5:U$35,0),RANK(U8,U$5:U$35,1))) -> 0 | AA8: =+IF(O$38=0,0,IF(O$38<0,-RANK(V8,V$5:V$35,0),RANK(V8,V$5:V$35,1))) -> 0 | AB8: =+IF(P$38=0,0,IF(P$38<0,-RANK(W8,W$5:W$35,0),RANK(W8,W$5:W$35,1))) -> 0 | AC8: =+IF(Q$38=0,0,IF(Q$38<0,-RANK(X8,X$5:X$35,0),RANK(X8,X$5:X$35,1))) -> 0 | AD8: =+IF(R$38=0,0,IF(R$38<0,-RANK(Y8,Y$5:Y$35,0),RANK(Y8,Y$5:Y$35,1))) -> 0
A9: 1 | B9: 8830205 | D9: 災害補償費 | E9: =+IF($A9="",IF($C9="",SUMIFS(全伝票!I:I,全伝票!$B:$B,$B9),SUMIFS(全伝票!I:I,全伝票!$C:$C,$C9)),IF($C9="",SUMIFS(全伝票!I:I,全伝票!$A:$A,$A9,全伝票!$B:$B,$B9),SUMIFS(全伝票!I:I,全伝票!$A:$A,$A9,全伝票!$C:$C,$C9))) -> 0 | F9: =+IF($A9="",IF($C9="",SUMIFS(全伝票!J:J,全伝票!$B:$B,$B9),SUMIFS(全伝票!J:J,全伝票!$C:$C,$C9)),IF($C9="",SUMIFS(全伝票!J:J,全伝票!$A:$A,$A9,全伝票!$B:$B,$B9),SUMIFS(全伝票!J:J,全伝票!$A:$A,$A9,全伝票!$C:$C,$C9))) -> 0 | G9: =+IF($A9="",IF($C9="",SUMIFS(全伝票!K:K,全伝票!$B:$B,$B9),SUMIFS(全伝票!K:K,全伝票!$C:$C,$C9)),IF($C9="",SUMIFS(全伝票!K:K,全伝票!$A:$A,$A9,全伝票!$B:$B,$B9),SUMIFS(全伝票!K:K,全伝票!$A:$A,$A9,全伝票!$C:$C,$C9))) -> 0 | H9: =+IF($A9="",IF($C9="",SUMIFS(全伝票!L:L,全伝票!$B:$B,$B9),SUMIFS(全伝票!L:L,全伝票!$C:$C,$C9)),IF($C9="",SUMIFS(全伝票!L:L,全伝票!$A:$A,$A9,全伝票!$B:$B,$B9),SUMIFS(全伝票!L:L,全伝票!$A:$A,$A9,全伝票!$C:$C,$C9))) -> 0 | I9: =+IF($A9="",IF($C9="",SUMIFS(全伝票!M:M,全伝票!$B:$B,$B9),SUMIFS(全伝票!M:M,全伝票!$C:$C,$C9)),IF($C9="",SUMIFS(全伝票!M:M,全伝票!$A:$A,$A9,全伝票!$B:$B,$B9),SUMIFS(全伝票!M:M,全伝票!$A:$A,$A9,全伝票!$C:$C,$C9))) -> 0 | J9: =+IF($A9="",IF($C9="",SUMIFS(全伝票!N:N,全伝票!$B:$B,$B9),SUMIFS(全伝票!N:N,全伝票!$C:$C,$C9)),IF($C9="",SUMIFS(全伝票!N:N,全伝票!$A:$A,$A9,全伝票!$B:$B,$B9),SUMIFS(全伝票!N:N,全伝票!$A:$A,$A9,全伝票!$C:$C,$C9))) -> 0 | K9: =SUM(F9:J9) -> 0 | L9: =+IF($A9="",IF($C9="",SUMIFS(全伝票!O:O,全伝票!$B:$B,$B9),SUMIFS(全伝票!O:O,全伝票!$C:$C,$C9)),IF($C9="",SUMIFS(全伝票!O:O,全伝票!$A:$A,$A9,全伝票!$B:$B,$B9),SUMIFS(全伝票!O:O,全伝票!$A:$A,$A9,全伝票!$C:$C,$C9))) -> 0 | M9: =+IF($A9="",IF($C9="",SUMIFS(全伝票!P:P,全伝票!$B:$B,$B9),SUMIFS(全伝票!P:P,全伝票!$C:$C,$C9)),IF($C9="",SUMIFS(全伝票!P:P,全伝票!$A:$A,$A9,全伝票!$B:$B,$B9),SUMIFS(全伝票!P:P,全伝票!$A:$A,$A9,全伝票!$C:$C,$C9))) -> 0 | N9: =+ROUND(F9*F$4/(100+F$4),0)+AE9 -> 0 | O9: =+ROUND(G9*G$4/(100+G$4),0)+AF9 -> 0 | P9: =+ROUND(H9*H$4/(100+H$4),0)+AG9 -> 0 | Q9: =+ROUND(I9*I$4/(100+I$4),0)+AH9 -> 0 | R9: =+ROUND(J9*J$4/(100+J$4),0)+AI9 -> 0 | S9: =SUM(N9:R9) -> 0 | T9: =+E9-S9 -> 0 | U9: =N9-F9*F$4/(100+F$4) -> 0 | V9: =O9-G9*G$4/(100+G$4) -> 0 | W9: =P9-H9*H$4/(100+H$4) -> 0 | X9: =Q9-I9*I$4/(100+I$4) -> 0 | Y9: =R9-J9*J$4/(100+J$4) -> 0 | Z9: =+IF(N$38=0,0,IF(N$38<0,-RANK(U9,U$5:U$35,0),RANK(U9,U$5:U$35,1))) -> 0 | AA9: =+IF(O$38=0,0,IF(O$38<0,-RANK(V9,V$5:V$35,0),RANK(V9,V$5:V$35,1))) -> 0 | AB9: =+IF(P$38=0,0,IF(P$38<0,-RANK(W9,W$5:W$35,0),RANK(W9,W$5:W$35,1))) -> 0 | AC9: =+IF(Q$38=0,0,IF(Q$38<0,-RANK(X9,X$5:X$35,0),RANK(X9,X$5:X$35,1))) -> 0 | AD9: =+IF(R$38=0,0,IF(R$38<0,-RANK(Y9,Y$5:Y$35,0),RANK(Y9,Y$5:Y$35,1))) -> 0
A10: 1 | B10: 8830207 | D10: 賃金 | E10: =+IF($A10="",IF($C10="",SUMIFS(全伝票!I:I,全伝票!$B:$B,$B10),SUMIFS(全伝票!I:I,全伝票!$C:$C,$C10)),IF($C10="",SUMIFS(全伝票!I:I,全伝票!$A:$A,$A10,全伝票!$B:$B,$B10),SUMIFS(全伝票!I:I,全伝票!$A:$A,$A10,全伝票!$C:$C,$C10))) -> 0 | F10: =+IF($A10="",IF($C10="",SUMIFS(全伝票!J:J,全伝票!$B:$B,$B10),SUMIFS(全伝票!J:J,全伝票!$C:$C,$C10)),IF($C10="",SUMIFS(全伝票!J:J,全伝票!$A:$A,$A10,全伝票!$B:$B,$B10),SUMIFS(全伝票!J:J,全伝票!$A:$A,$A10,全伝票!$C:$C,$C10))) -> 0 | G10: =+IF($A10="",IF($C10="",SUMIFS(全伝票!K:K,全伝票!$B:$B,$B10),SUMIFS(全伝票!K:K,全伝票!$C:$C,$C10)),IF($C10="",SUMIFS(全伝票!K:K,全伝票!$A:$A,$A10,全伝票!$B:$B,$B10),SUMIFS(全伝票!K:K,全伝票!$A:$A,$A10,全伝票!$C:$C,$C10))) -> 0 | H10: =+IF($A10="",IF($C10="",SUMIFS(全伝票!L:L,全伝票!$B:$B,$B10),SUMIFS(全伝票!L:L,全伝票!$C:$C,$C10)),IF($C10="",SUMIFS(全伝票!L:L,全伝票!$A:$A,$A10,全伝票!$B:$B,$B10),SUMIFS(全伝票!L:L,全伝票!$A:$A,$A10,全伝票!$C:$C,$C10))) -> 0 | I10: =+IF($A10="",IF($C10="",SUMIFS(全伝票!M:M,全伝票!$B:$B,$B10),SUMIFS(全伝票!M:M,全伝票!$C:$C,$C10)),IF($C10="",SUMIFS(全伝票!M:M,全伝票!$A:$A,$A10,全伝票!$B:$B,$B10),SUMIFS(全伝票!M:M,全伝票!$A:$A,$A10,全伝票!$C:$C,$C10))) -> 0 | J10: =+IF($A10="",IF($C10="",SUMIFS(全伝票!N:N,全伝票!$B:$B,$B10),SUMIFS(全伝票!N:N,全伝票!$C:$C,$C10)),IF($C10="",SUMIFS(全伝票!N:N,全伝票!$A:$A,$A10,全伝票!$B:$B,$B10),SUMIFS(全伝票!N:N,全伝票!$A:$A,$A10,全伝票!$C:$C,$C10))) -> 0 | K10: =SUM(F10:J10) -> 0 | L10: =+IF($A10="",IF($C10="",SUMIFS(全伝票!O:O,全伝票!$B:$B,$B10),SUMIFS(全伝票!O:O,全伝票!$C:$C,$C10)),IF($C10="",SUMIFS(全伝票!O:O,全伝票!$A:$A,$A10,全伝票!$B:$B,$B10),SUMIFS(全伝票!O:O,全伝票!$A:$A,$A10,全伝票!$C:$C,$C10))) -> 0 | M10: =+IF($A10="",IF($C10="",SUMIFS(全伝票!P:P,全伝票!$B:$B,$B10),SUMIFS(全伝票!P:P,全伝票!$C:$C,$C10)),IF($C10="",SUMIFS(全伝票!P:P,全伝票!$A:$A,$A10,全伝票!$B:$B,$B10),SUMIFS(全伝票!P:P,全伝票!$A:$A,$A10,全伝票!$C:$C,$C10))) -> 0 | N10: =+ROUND(F10*F$4/(100+F$4),0)+AE10 -> 0 | O10: =+ROUND(G10*G$4/(100+G$4),0)+AF10 -> 0 | P10: =+ROUND(H10*H$4/(100+H$4),0)+AG10 -> 0 | Q10: =+ROUND(I10*I$4/(100+I$4),0)+AH10 -> 0 | R10: =+ROUND(J10*J$4/(100+J$4),0)+AI10 -> 0 | S10: =SUM(N10:R10) -> 0 | T10: =+E10-S10 -> 0 | U10: =N10-F10*F$4/(100+F$4) -> 0 | V10: =O10-G10*G$4/(100+G$4) -> 0 | W10: =P10-H10*H$4/(100+H$4) -> 0 | X10: =Q10-I10*I$4/(100+I$4) -> 0 | Y10: =R10-J10*J$4/(100+J$4) -> 0 | Z10: =+IF(N$38=0,0,IF(N$38<0,-RANK(U10,U$5:U$35,0),RANK(U10,U$5:U$35,1))) -> 0 | AA10: =+IF(O$38=0,0,IF(O$38<0,-RANK(V10,V$5:V$35,0),RANK(V10,V$5:V$35,1))) -> 0 | AB10: =+IF(P$38=0,0,IF(P$38<0,-RANK(W10,W$5:W$35,0),RANK(W10,W$5:W$35,1))) -> 0 | AC10: =+IF(Q$38=0,0,IF(Q$38<0,-RANK(X10,X$5:X$35,0),RANK(X10,X$5:X$35,1))) -> 0 | AD10: =+IF(R$38=0,0,IF(R$38<0,-RANK(Y10,Y$5:Y$35,0),RANK(Y10,Y$5:Y$35,1))) -> 0
