Workbook

Sheet 3条収入
D1: =+'[1]3条支出'!$D$1 -> 令和５年度決算 消費税算出資料
D2: 【３条収入内訳】
A3: 事業 | B3: 節 | C3: 細節 | D3: 費目 | E3: 税込決算額 | F3: 課税売上げ | L3: 非課税 売上げ | M3: 免税 売上げ | N3: 不課税収入（資産の譲渡等の対価以外の収入（対価性のない収入）） | W3: 仮受消費税 | AC3: 特定収入に係る課税仕入れ等に係る消費税額 | AI3: 税抜決算額 | AY3: 課税支出に係る特定収入に係る消費税の調整
N4: 特定収入 | U4: 特定収入以外 の不課税収入
N5: 課税仕入れ等に係る特定収入 | T5: 課税仕入れ等に係る特定収入以外 | V5: 計 | AJ5: 消費税 端数確認 | AO5: 消費税端数調整ランク | AT5: 消費税 調整額 | AY5: 消費税 端数確認 | BD5: 消費税端数調整ランク | BI5: 消費税 調整額
F6: 3 | G6: 5 | H6: 8 | I6: 8 | J6: 10 | K6: 計 | N6: 3 | O6: 5 | P6: 8 | Q6: 8 | R6: 10 | S6: 計 | W6: 3 | X6: 5 | Y6: 8 | Z6: 8 | AA6: 10 | AB6: 計 | AC6: 3 | AD6: 5 | AE6: 8 | AF6: 8 | AG6: 10 | AH6: 計 | AJ6: 3 | AK6: 5 | AL6: 8 | AM6: 8 | AN6: 10 | AO6: 3 | AP6: 5 | AQ6: 8 | AR6: 8 | AS6: 10 | AT6: 3 | AU6: 5 | AV6: 8 | AW6: 8 | AX6: 10 | AY6: 3 | AZ6: 5 | BA6: 8 | BB6: 8 | BC6: 10 | BD6: 3 | BE6: 5 | BF6: 8 | BG6: 8 | BH6: 10 | BI6: 3 | BJ6: 5 | BK6: 8 | BL6: 8 | BM6: 10
D7: 下水道使用料 | E7: =+E8 -> 20488962528 | F7: =+F8 -> 0 | G7: =+G8 -> 0 | H7: =+H8 -> 0 | I7: =+I8 -> 0 | J7: =+J8 -> 20488875668 | K7: =+K8 -> 20488875668 | L7: =+L8 -> 0 | ... AI7: =+AI8 -> 18626337467
C8: 481020200 | D8: 下水道使用料 | E8: =+SUMIFS([1]全伝票!I:I,[1]全伝票!$C:$C,$C8) -> 20488962528 | F8: =+SUMIFS([1]全伝票!J:J,[1]全伝票!$C:$C,$C8) -> 0 | G8: =+SUMIFS([1]全伝票!K:K,[1]全伝票!$C:$C,$C8) -> 0 | H8: =+SUMIFS([1]全伝票!L:L,[1]全伝票!$C:$C,$C8) -> 0 | I8: =+SUMIFS([1]全伝票!M:M,[1]全伝票!$C:$C,$C8) -> 0 | J8: =+SUMIFS([1]全伝票!N:N,[1]全伝票!$C:$C,$C8)-M8 -> 20488875668 | K8: =SUM(F8:J8) -> 20488875668 | L8: =+SUMIFS([1]全伝票!O:O,[1]全伝票!$C:$C,$C8) -> 0 | M8: 86860 | S8: =SUM(N8:R8) -> 0 | U8: =+V8-SUM(N8:T8) -> 0 | V8: =+SUMIFS([1]全伝票!P:P,[1]全伝票!$C:$C,$C8) -> 0 | W8: =+ROUND(F8*F$6/(100+F$6),0)+AT8 -> 0 | X8: =+ROUND(G8*G$6/(100+G$6),0)+AU8 -> 0 | Y8: =+ROUND(H8*H$6/(100+H$6),0)+AV8 -> 0 | Z8: =+ROUND(I8*I$6/(100+I$6),0)+AW8 -> 0 | AA8: =+ROUND(J8*J$6/(100+J$6),0)+AX8 -> 1862625061 | AB8: =SUM(W8:AA8) -> 1862625061 | AC8: =+ROUND(N8*AC$6/(100+AC$6),0)+BI8 -> 0 | AD8: =+ROUND(O8*AD$6/(100+AD$6),0)+BJ8 -> 0 | AE8: =+ROUND(P8*AE$6/(100+AE$6),0)+BK8 -> 0 | AF8: =+ROUND(Q8*AF$6/(100+AF$6),0)+BL8 -> 0 | AG8: =+ROUND(R8*AG$6/(100+AG$6),0)+BM8 -> 0 | AH8: =SUM(AC8:AG8) -> 0 | AI8: =+E8-AB8 -> 18626337467 | AJ8: =W8-F8*W$6/(100+W$6) -> 0 | AK8: =X8-G8*X$6/(100+X$6) -> 0 | AL8: =Y8-H8*Y$6/(100+Y$6) -> 0 | AM8: =Z8-I8*Z$6/(100+Z$6) -> 0 | AN8: =AA8-J8*AA$6/(100+AA$6) -> 0.27272725 | AO8: =+IF(W$71=0,0,IF(W$71<0,-RANK(AJ8,AJ$7:AJ$68,0),RANK(AJ8,AJ$7:AJ$68,1))) -> 0 | AP8: =+IF(X$71=0,0,IF(X$71<0,-RANK(AK8,AK$7:AK$68,0),RANK(AK8,AK$7:AK$68,1))) -> 0 | AQ8: =+IF(Y$71=0,0,IF(Y$71<0,-RANK(AL8,AL$7:AL$68,0),RANK(AL8,AL$7:AL$68,1))) -> 0 | AR8: =+IF(Z$71=0,0,IF(Z$71<0,-RANK(AM8,AM$7:AM$68,0),RANK(AM8,AM$7:AM$68,1))) -> 0 | AS8: =+IF(AA$71=0,0,IF(AA$71<0,-RANK(AN8,AN$7:AN$68,0),RANK(AN8,AN$7:AN$68,1))) -> 0
D9: 一般会計負担金 | E9: =+SUM(E10,E14:E16) -> 14187102335 | F9: =+SUM(F10,F14:F16) -> 0 | G9: =+SUM(G10,G14:G16) -> 0 | H9: =+SUM(H10,H14:H16) -> 0 | I9: =+SUM(I10,I14:I16) -> 0 | J9: =+SUM(J10,J14:J16) -> 0 | K9: =+SUM(K10,K14:K16) -> 0 | L9: =+SUM(L10,L14:L16) -> 0 | ... AI9: =+SUM(AI10,AI14:AI16) -> 14187102335
D10: 雨水処理負担金 | E10: =+SUM(E11:E13) -> 14079749832 | F10: =+SUM(F11:F13) -> 0 | G10: =+SUM(G11:G13) -> 0 | H10: =+SUM(H11:H13) -> 0 | I10: =+SUM(I11:I13) -> 0 | J10: =+SUM(J11:J13) -> 0 | K10: =+SUM(K11:K13) -> 0 | L10: =+SUM(L11:L13) -> 0 | ... AI10: =+SUM(AI11:AI13) -> 14079749832
C11: 481040411 | D11: 維持管理費分 | E11: =+[2]雨汚水!E111 -> 3591522898 | K11: =SUM(F11:J11) -> 0 | P11: =+'[3]3条一般会計'!L$11 -> 455357 | Q11: =+'[3]3条一般会計'!M$11 -> 130554 | R11: =+'[3]3条一般会計'!N$11 -> 2256510197 | S11: =SUM(N11:R11) -> 2257096108 | T11: =+'[3]3条一般会計'!$I$10 -> 1126582233 | U11: =+V11-SUM(S11:T11) -> 207844557 | V11: =+E11 -> 3591522898 | W11: =+ROUND(F11*F$6/(100+F$6),0)+AT11 -> 0 | X11: =+ROUND(G11*G$6/(100+G$6),0)+AU11 -> 0 | Y11: =+ROUND(H11*H$6/(100+H$6),0)+AV11 -> 0 | Z11: =+ROUND(I11*I$6/(100+I$6),0)+AW11 -> 0 | AA11: =+ROUND(J11*J$6/(100+J$6),0)+AX11 -> 0 | AB11: =SUM(W11:AA11) -> 0 | AC11: =+ROUND(N11*AC$6/(100+AC$6),0)+BI11 -> 0 | AD11: =+ROUND(O11*AD$6/(100+AD$6),0)+BJ11 -> 0 | AE11: =+ROUND(P11*AE$6/(100+AE$6),0)+BK11 -> 33729 | AF11: =+ROUND(Q11*AF$6/(100+AF$6),0)+BL11 -> 9670 | AG11: =+ROUND(R11*AG$6/(100+AG$6),0)+BM11 -> 205137291 | AH11: =SUM(AC11:AG11) -> 205180690 | AI11: =+E11-AB11 -> 3591522898 | AY11: =AC11-N11*AC$6/(100+AC$6) -> 0 | AZ11: =AD11-O11*AD$6/(100+AD$6) -> 0 | BA11: =AE11-P11*AE$6/(100+AE$6) -> -1.1481481 | BB11: =AF11-Q11*AF$6/(100+AF$6) -> -0.66666667 | BC11: =AG11-R11*AG$6/(100+AG$6) -> 0.36363637 | BD11: =+IF(AC$71=0,0,IF(AC$71<0,-RANK(AY11,AY$7:AY$68,0),RANK(AY11,AY$7:AY$68,1))) -> 0 | BE11: =+IF(AD$71=0,0,IF(AD$71<0,-RANK(AZ11,AZ$7:AZ$68,0),RANK(AZ11,AZ$7:AZ$68,1))) -> 0 | BF11: =+IF(AE$71=0,0,IF(AE$71<0,-RANK(BA11,BA$7:BA$68,0),RANK(BA11,BA$7:BA$68,1))) -> 0 | BG11: =+IF(AF$71=0,0,IF(AF$71<0,-RANK(BB11,BB$7:BB$68,0),RANK(BB11,BB$7:BB$68,1))) -> 0 | BH11: =+IF(AG$71=0,0,IF(AG$71<0,-RANK(BC11,BC$7:BC$68,0),RANK(BC11,BC$7:BC$68,1))) -> 0 | BK11: -1 | BL11: -1
C12: 481040412 | D12: 減価償却費分 | E12: =+[2]雨汚水!E112 -> 8476549651 | K12: =SUM(F12:J12) -> 0 | S12: =SUM(N12:R12) -> 0 | T12: =+'[3]3条一般会計'!I12 -> 8476549651 | U12: =+V12-SUM(S12:T12) -> 0 | V12: =+E12 -> 8476549651 | W12: =+ROUND(F12*F$6/(100+F$6),0)+AT12 -> 0 | X12: =+ROUND(G12*G$6/(100+G$6),0)+AU12 -> 0 | Y12: =+ROUND(H12*H$6/(100+H$6),0)+AV12 -> 0 | Z12: =+ROUND(I12*I$6/(100+I$6),0)+AW12 -> 0 | AA12: =+ROUND(J12*J$6/(100+J$6),0)+AX12 -> 0 | AB12: =SUM(W12:AA12) -> 0 | AC12: =+ROUND(N12*AC$6/(100+AC$6),0)+BI12 -> 0 | AD12: =+ROUND(O12*AD$6/(100+AD$6),0)+BJ12 -> 0 | AE12: =+ROUND(P12*AE$6/(100+AE$6),0)+BK12 -> 0 | AF12: =+ROUND(Q12*AF$6/(100+AF$6),0)+BL12 -> 0 | AG12: =+ROUND(R12*AG$6/(100+AG$6),0)+BM12 -> 0 | AH12: =SUM(AC12:AG12) -> 0 | AI12: =+E12-AB12 -> 8476549651 | AY12: =AC12-N12*AC$6/(100+AC$6) -> 0 | AZ12: =AD12-O12*AD$6/(100+AD$6) -> 0 | BA12: =AE12-P12*AE$6/(100+AE$6) -> 0 | BB12: =AF12-Q12*AF$6/(100+AF$6) -> 0 | BC12: =AG12-R12*AG$6/(100+AG$6) -> 0 | BD12: =+IF(AC$71=0,0,IF(AC$71<0,-RANK(AY12,AY$7:AY$68,0),RANK(AY12,AY$7:AY$68,1))) -> 0 | BE12: =+IF(AD$71=0,0,IF(AD$71<0,-RANK(AZ12,AZ$7:AZ$68,0),RANK(AZ12,AZ$7:AZ$68,1))) -> 0 | BF12: =+IF(AE$71=0,0,IF(AE$71<0,-RANK(BA12,BA$7:BA$68,0),RANK(BA12,BA$7:BA$68,1))) -> 0 | BG12: =+IF(AF$71=0,0,IF(AF$71<0,-RANK(BB12,BB$7:BB$68,0),RANK(BB12,BB$7:BB$68,1))) -> 0 | BH12: =+IF(AG$71=0,0,IF(AG$71<0,-RANK(BC12,BC$7:BC$68,0),RANK(BC12,BC$7:BC$68,1))) -> 0
C13: 481040413 | D13: 支払利息分 | E13: =+[2]雨汚水!E113 -> 2011677283 | K13: =SUM(F13:J13) -> 0 | P13: =+'[3]3条一般会計'!L$15 -> 0 | Q13: =+'[3]3条一般会計'!M$15 -> 0 | R13: =+'[3]3条一般会計'!N$15 -> 27794733 | S13: =SUM(N13:R13) -> 27794733 | T13: =+'[3]3条一般会計'!$I$18 -> 1981328911 | U13: =+V13-SUM(S13:T13) -> 2553639 | V13: =+E13 -> 2011677283 | W13: =+ROUND(F13*F$6/(100+F$6),0)+AT13 -> 0 | X13: =+ROUND(G13*G$6/(100+G$6),0)+AU13 -> 0 | Y13: =+ROUND(H13*H$6/(100+H$6),0)+AV13 -> 0 | Z13: =+ROUND(I13*I$6/(100+I$6),0)+AW13 -> 0 | AA13: =+ROUND(J13*J$6/(100+J$6),0)+AX13 -> 0 | AB13: =SUM(W13:AA13) -> 0 | AC13: =+ROUND(N13*AC$6/(100+AC$6),0)+BI13 -> 0 | AD13: =+ROUND(O13*AD$6/(100+AD$6),0)+BJ13 -> 0 | AE13: =+ROUND(P13*AE$6/(100+AE$6),0)+BK13 -> 0 | AF13: =+ROUND(Q13*AF$6/(100+AF$6),0)+BL13 -> 0 | AG13: =+ROUND(R13*AG$6/(100+AG$6),0)+BM13 -> 2526794 | AH13: =SUM(AC13:AG13) -> 2526794 | AI13: =+E13-AB13 -> 2011677283 | AY13: =AC13-N13*AC$6/(100+AC$6) -> 0 | AZ13: =AD13-O13*AD$6/(100+AD$6) -> 0 | BA13: =AE13-P13*AE$6/(100+AE$6) -> 0 | BB13: =AF13-Q13*AF$6/(100+AF$6) -> 0 | BC13: =AG13-R13*AG$6/(100+AG$6) -> 0.090909091 | BD13: =+IF(AC$71=0,0,IF(AC$71<0,-RANK(AY13,AY$7:AY$68,0),RANK(AY13,AY$7:AY$68,1))) -> 0 | BE13: =+IF(AD$71=0,0,IF(AD$71<0,-RANK(AZ13,AZ$7:AZ$68,0),RANK(AZ13,AZ$7:AZ$68,1))) -> 0 | BF13: =+IF(AE$71=0,0,IF(AE$71<0,-RANK(BA13,BA$7:BA$68,0),RANK(BA13,BA$7:BA$68,1))) -> 0 | BG13: =+IF(AF$71=0,0,IF(AF$71<0,-RANK(BB13,BB$7:BB$68,0),RANK(BB13,BB$7:BB$68,1))) -> 0 | BH13: =+IF(AG$71=0,0,IF(AG$71<0,-RANK(BC13,BC$7:BC$68,0),RANK(BC13,BC$7:BC$68,1))) -> 0
C14: 481040600 | D14: 水質指導費負担金 | E14: =+[2]雨汚水!E116 -> 52443869 | K14: =SUM(F14:J14) -> 0 | P14: =+'[3]3条一般会計'!L$21 -> 0 | Q14: =+'[3]3条一般会計'!M$21 -> 0 | R14: =+'[3]3条一般会計'!N$21 -> 12168217 | S14: =SUM(N14:R14) -> 12168217 | T14: =+'[3]3条一般会計'!$I$20 -> 39145078 | U14: =+V14-SUM(S14:T14) -> 1130574 | V14: =+E14 -> 52443869 | W14: =+ROUND(F14*F$6/(100+F$6),0)+AT14 -> 0 | X14: =+ROUND(G14*G$6/(100+G$6),0)+AU14 -> 0 | Y14: =+ROUND(H14*H$6/(100+H$6),0)+AV14 -> 0 | Z14: =+ROUND(I14*I$6/(100+I$6),0)+AW14 -> 0 | AA14: =+ROUND(J14*J$6/(100+J$6),0)+AX14 -> 0 | AB14: =SUM(W14:AA14) -> 0 | AC14: =+ROUND(N14*AC$6/(100+AC$6),0)+BI14 -> 0 | AD14: =+ROUND(O14*AD$6/(100+AD$6),0)+BJ14 -> 0 | AE14: =+ROUND(P14*AE$6/(100+AE$6),0)+BK14 -> 0 | AF14: =+ROUND(Q14*AF$6/(100+AF$6),0)+BL14 -> 0 | AG14: =+ROUND(R14*AG$6/(100+AG$6),0)+BM14 -> 1106201 | AH14: =SUM(AC14:AG14) -> 1106201 | AI14: =+E14-AB14 -> 52443869 | AY14: =AC14-N14*AC$6/(100+AC$6) -> 0 | AZ14: =AD14-O14*AD$6/(100+AD$6) -> 0 | BA14: =AE14-P14*AE$6/(100+AE$6) -> 0 | BB14: =AF14-Q14*AF$6/(100+AF$6) -> 0 | BC14: =AG14-R14*AG$6/(100+AG$6) -> -0.54545455 | BD14: =+IF(AC$71=0,0,IF(AC$71<0,-RANK(AY14,AY$7:AY$68,0),RANK(AY14,AY$7:AY$68,1))) -> 0 | BE14: =+IF(AD$71=0,0,IF(AD$71<0,-RANK(AZ14,AZ$7:AZ$68,0),RANK(AZ14,AZ$7:AZ$68,1))) -> 0 | BF14: =+IF(AE$71=0,0,IF(AE$71<0,-RANK(BA14,BA$7:BA$68,0),RANK(BA14,BA$7:BA$68,1))) -> 0 | BG14: =+IF(AF$71=0,0,IF(AF$71<0,-RANK(BB14,BB$7:BB$68,0),RANK(BB14,BB$7:BB$68,1))) -> 0 | BH14: =+IF(AG$71=0,0,IF(AG$71<0,-RANK(BC14,BC$7:BC$68,0),RANK(BC14,BC$7:BC$68,1))) -> 0 | BM14: -1
C15: 481040800 | D15: 普及促進費負担金 | E15: =+[2]雨汚水!E117 -> 44424775 | K15: =SUM(F15:J15) -> 0 | P15: =+'[3]3条一般会計'!L$23 -> 0 | Q15: =+'[3]3条一般会計'!M$23 -> 0 | R15: =+'[3]3条一般会計'!N$23 -> 9253060 | S15: =SUM(N15:R15) -> 9253060 | T15: =+'[3]3条一般会計'!$I$22 -> 34313966 | U15: =+V15-SUM(S15:T15) -> 857749 | V15: =+E15 -> 44424775 | W15: =+ROUND(F15*F$6/(100+F$6),0)+AT15 -> 0 | X15: =+ROUND(G15*G$6/(100+G$6),0)+AU15 -> 0 | Y15: =+ROUND(H15*H$6/(100+H$6),0)+AV15 -> 0 | Z15: =+ROUND(I15*I$6/(100+I$6),0)+AW15 -> 0 | AA15: =+ROUND(J15*J$6/(100+J$6),0)+AX15 -> 0 | AB15: =SUM(W15:AA15) -> 0 | AC15: =+ROUND(N15*AC$6/(100+AC$6),0)+BI15 -> 0 | AD15: =+ROUND(O15*AD$6/(100+AD$6),0)+BJ15 -> 0 | AE15: =+ROUND(P15*AE$6/(100+AE$6),0)+BK15 -> 0 | AF15: =+ROUND(Q15*AF$6/(100+AF$6),0)+BL15 -> 0 | AG15: =+ROUND(R15*AG$6/(100+AG$6),0)+BM15 -> 841187 | AH15: =SUM(AC15:AG15) -> 841187 | AI15: =+E15-AB15 -> 44424775 | AY15: =AC15-N15*AC$6/(100+AC$6) -> 0 | AZ15: =AD15-O15*AD$6/(100+AD$6) -> 0 | BA15: =AE15-P15*AE$6/(100+AE$6) -> 0 | BB15: =AF15-Q15*AF$6/(100+AF$6) -> 0 | BC15: =AG15-R15*AG$6/(100+AG$6) -> -0.27272727 | BD15: =+IF(AC$71=0,0,IF(AC$71<0,-RANK(AY15,AY$7:AY$68,0),RANK(AY15,AY$7:AY$68,1))) -> 0 | BE15: =+IF(AD$71=0,0,IF(AD$71<0,-RANK(AZ15,AZ$7:AZ$68,0),RANK(AZ15,AZ$7:AZ$68,1))) -> 0 | BF15: =+IF(AE$71=0,0,IF(AE$71<0,-RANK(BA15,BA$7:BA$68,0),RANK(BA15,BA$7:BA$68,1))) -> 0 | BG15: =+IF(AF$71=0,0,IF(AF$71<0,-RANK(BB15,BB$7:BB$68,0),RANK(BB15,BB$7:BB$68,1))) -> 0 | BH15: =+IF(AG$71=0,0,IF(AG$71<0,-RANK(BC15,BC$7:BC$68,0),RANK(BC15,BC$7:BC$68,1))) -> 0
C16: 481040900 | D16: 貸付事業費負担金 | E16: =+[2]雨汚水!E118 -> 10483859 | K16: =SUM(F16:J16) -> 0 | P16: =+'[3]3条一般会計'!L$25 -> 0 | Q16: =+'[3]3条一般会計'!M$25 -> 0 | R16: =+'[3]3条一般会計'!N$25 -> 955435 | S16: =SUM(N16:R16) -> 955435 | T16: =+'[3]3条一般会計'!$I$24 -> 9440835 | U16: =+V16-SUM(S16:T16) -> 87589 | V16: =+E16 -> 10483859 | W16: =+ROUND(F16*F$6/(100+F$6),0)+AT16 -> 0 | X16: =+ROUND(G16*G$6/(100+G$6),0)+AU16 -> 0 | Y16: =+ROUND(H16*H$6/(100+H$6),0)+AV16 -> 0 | Z16: =+ROUND(I16*I$6/(100+I$6),0)+AW16 -> 0 | AA16: =+ROUND(J16*J$6/(100+J$6),0)+AX16 -> 0 | AB16: =SUM(W16:AA16) -> 0 | AC16: =+ROUND(N16*AC$6/(100+AC$6),0)+BI16 -> 0 | AD16: =+ROUND(O16*AD$6/(100+AD$6),0)+BJ16 -> 0 | AE16: =+ROUND(P16*AE$6/(100+AE$6),0)+BK16 -> 0 | AF16: =+ROUND(Q16*AF$6/(100+AF$6),0)+BL16 -> 0 | AG16: =+ROUND(R16*AG$6/(100+AG$6),0)+BM16 -> 86858 | AH16: =SUM(AC16:AG16) -> 86858 | AI16: =+E16-AB16 -> 10483859 | AY16: =AC16-N16*AC$6/(100+AC$6) -> 0 | AZ16: =AD16-O16*AD$6/(100+AD$6) -> 0 | BA16: =AE16-P16*AE$6/(100+AE$6) -> 0 | BB16: =AF16-Q16*AF$6/(100+AF$6) -> 0 | BC16: =AG16-R16*AG$6/(100+AG$6) -> 0.27272727 | BD16: =+IF(AC$71=0,0,IF(AC$71<0,-RANK(AY16,AY$7:AY$68,0),RANK(AY16,AY$7:AY$68,1))) -> 0 | BE16: =+IF(AD$71=0,0,IF(AD$71<0,-RANK(AZ16,AZ$7:AZ$68,0),RANK(AZ16,AZ$7:AZ$68,1))) -> 0 | BF16: =+IF(AE$71=0,0,IF(AE$71<0,-RANK(BA16,BA$7:BA$68,0),RANK(BA16,BA$7:BA$68,1))) -> 0 | BG16: =+IF(AF$71=0,0,IF(AF$71<0,-RANK(BB16,BB$7:BB$68,0),RANK(BB16,BB$7:BB$68,1))) -> 0 | BH16: =+IF(AG$71=0,0,IF(AG$71<0,-RANK(BC16,BC$7:BC$68,0),RANK(BC16,BC$7:BC$68,1))) -> 0
D17: 受託工事収益 | E17: =+E18 -> 0 | F17: =+F18 -> 0 | G17: =+G18 -> 0 | H17: =+H18 -> 0 | I17: =+I18 -> 0 | J17: =+J18 -> 0 | K17: =+K18 -> 0 | L17: =+L18 -> 0 | ... AI17: =+AI18 -> 0
C18: 481121400 | D18: 受託工事収益 | E18: =+SUMIFS([1]全伝票!I:I,[1]全伝票!$C:$C,$C18) -> 0 | F18: =+SUMIFS([1]全伝票!J:J,[1]全伝票!$C:$C,$C18) -> 0 | G18: =+SUMIFS([1]全伝票!K:K,[1]全伝票!$C:$C,$C18) -> 0 | H18: =+SUMIFS([1]全伝票!L:L,[1]全伝票!$C:$C,$C18) -> 0 | I18: =+SUMIFS([1]全伝票!M:M,[1]全伝票!$C:$C,$C18) -> 0 | J18: =+SUMIFS([1]全伝票!N:N,[1]全伝票!$C:$C,$C18) -> 0 | K18: =SUM(F18:J18) -> 0 | L18: =+SUMIFS([1]全伝票!O:O,[1]全伝票!$C:$C,$C18) -> 0 | S18: =SUM(N18:R18) -> 0 | U18: =+V18-SUM(S18:T18) -> 0 | V18: =+SUMIFS([1]全伝票!P:P,[1]全伝票!$C:$C,$C18) -> 0 | W18: =+ROUND(F18*F$6/(100+F$6),0)+AT18 -> 0 | X18: =+ROUND(G18*G$6/(100+G$6),0)+AU18 -> 0 | Y18: =+ROUND(H18*H$6/(100+H$6),0)+AV18 -> 0 | Z18: =+ROUND(I18*I$6/(100+I$6),0)+AW18 -> 0 | AA18: =+ROUND(J18*J$6/(100+J$6),0)+AX18 -> 0 | AB18: =SUM(W18:AA18) -> 0 | AC18: =+ROUND(N18*AC$6/(100+AC$6),0)+BI18 -> 0 | AD18: =+ROUND(O18*AD$6/(100+AD$6),0)+BJ18 -> 0 | AE18: =+ROUND(P18*AE$6/(100+AE$6),0)+BK18 -> 0 | AF18: =+ROUND(Q18*AF$6/(100+AF$6),0)+BL18 -> 0 | AG18: =+ROUND(R18*AG$6/(100+AG$6),0)+BM18 -> 0 | AH18: =SUM(AC18:AG18) -> 0 | AI18: =+E18-AB18 -> 0 | AJ18: =W18-F18*N$6/(100+N$6) -> 0 | AK18: =X18-G18*O$6/(100+O$6) -> 0 | AL18: =Y18-H18*P$6/(100+P$6) -> 0 | AM18: =Z18-I18*Q$6/(100+Q$6) -> 0 | AN18: =AA18-J18*R$6/(100+R$6) -> 0 | AO18: =+IF(W$71=0,0,IF(W$71<0,-RANK(AJ18,AJ$7:AJ$68,0),RANK(AJ18,AJ$7:AJ$68,1))) -> 0 | AP18: =+IF(X$71=0,0,IF(X$71<0,-RANK(AK18,AK$7:AK$68,0),RANK(AK18,AK$7:AK$68,1))) -> 0 | AQ18: =+IF(Y$71=0,0,IF(Y$71<0,-RANK(AL18,AL$7:AL$68,0),RANK(AL18,AL$7:AL$68,1))) -> 0 | AR18: =+IF(Z$71=0,0,IF(Z$71<0,-RANK(AM18,AM$7:AM$68,0),RANK(AM18,AM$7:AM$68,1))) -> 0 | AS18: =+IF(AA$71=0,0,IF(AA$71<0,-RANK(AN18,AN$7:AN$68,0),RANK(AN18,AN$7:AN$68,1))) -> 0 | AY18: =AC18-N18*AC$6/(100+AC$6) -> 0 | AZ18: =AD18-O18*AD$6/(100+AD$6) -> 0 | BA18: =AE18-P18*AE$6/(100+AE$6) -> 0 | BB18: =AF18-Q18*AF$6/(100+AF$6) -> 0 | BC18: =AG18-R18*AG$6/(100+AG$6) -> 0 | BD18: =+IF(AC$71=0,0,IF(AC$71<0,-RANK(AY18,AY$7:AY$68,0),RANK(AY18,AY$7:AY$68,1))) -> 0 | BE18: =+IF(AD$71=0,0,IF(AD$71<0,-RANK(AZ18,AZ$7:AZ$68,0),RANK(AZ18,AZ$7:AZ$68,1))) -> 0 | BF18: =+IF(AE$71=0,0,IF(AE$71<0,-RANK(BA18,BA$7:BA$68,0),RANK(BA18,BA$7:BA$68,1))) -> 0 | BG18: =+IF(AF$71=0,0,IF(AF$71<0,-RANK(BB18,BB$7:BB$68,0),RANK(BB18,BB$7:BB$68,1))) -> 0 | BH18: =+IF(AG$71=0,0,IF(AG$71<0,-RANK(BC18,BC$7:BC$68,0),RANK(BC18,BC$7:BC$68,1))) -> 0
D19: その他営業収益 | E19: =+SUM(E20:E22,E26) -> 189846869 | F19: =+SUM(F20:F22,F26) -> 0 | G19: =+SUM(G20:G22,G26) -> 0 | H19: =+SUM(H20:H22,H26) -> 0 | I19: =+SUM(I20:I22,I26) -> 0 | J19: =+SUM(J20:J22,J26) -> 189235899 | K19: =+SUM(K20:K22,K26) -> 189235899 | L19: =+SUM(L20:L22,L26) -> 610970 | ... AI19: =+SUM(AI20:AI22,AI26) -> 172643606
C20: 481141500 | D20: 産物売却代金 | E20: =+SUMIFS([1]全伝票!I:I,[1]全伝票!$C:$C,$C20) -> 187826166 | F20: =+SUMIFS([1]全伝票!J:J,[1]全伝票!$C:$C,$C20) -> 0 | G20: =+SUMIFS([1]全伝票!K:K,[1]全伝票!$C:$C,$C20) -> 0 | H20: =+SUMIFS([1]全伝票!L:L,[1]全伝票!$C:$C,$C20) -> 0 | I20: =+SUMIFS([1]全伝票!M:M,[1]全伝票!$C:$C,$C20) -> 0 | J20: =+SUMIFS([1]全伝票!N:N,[1]全伝票!$C:$C,$C20) -> 187826166 | K20: =SUM(F20:J20) -> 187826166 | L20: =+SUMIFS([1]全伝票!O:O,[1]全伝票!$C:$C,$C20) -> 0 | S20: =SUM(N20:R20) -> 0 | U20: =+V20-SUM(S20:T20) -> 0 | V20: =+SUMIFS([1]全伝票!P:P,[1]全伝票!$C:$C,$C20) -> 0 | W20: =+ROUND(F20*F$6/(100+F$6),0)+AT20 -> 0 | X20: =+ROUND(G20*G$6/(100+G$6),0)+AU20 -> 0 | Y20: =+ROUND(H20*H$6/(100+H$6),0)+AV20 -> 0 | Z20: =+ROUND(I20*I$6/(100+I$6),0)+AW20 -> 0 | AA20: =+ROUND(J20*J$6/(100+J$6),0)+AX20 -> 17075106 | AB20: =SUM(W20:AA20) -> 17075106 | AC20: =+ROUND(N20*AC$6/(100+AC$6),0)+BI20 -> 0 | AD20: =+ROUND(O20*AD$6/(100+AD$6),0)+BJ20 -> 0 | AE20: =+ROUND(P20*AE$6/(100+AE$6),0)+BK20 -> 0 | AF20: =+ROUND(Q20*AF$6/(100+AF$6),0)+BL20 -> 0 | AG20: =+ROUND(R20*AG$6/(100+AG$6),0)+BM20 -> 0 | AH20: =SUM(AC20:AG20) -> 0 | AI20: =+E20-AB20 -> 170751060 | AJ20: =W20-F20*W$6/(100+W$6) -> 0 | AK20: =X20-G20*X$6/(100+X$6) -> 0 | AL20: =Y20-H20*Y$6/(100+Y$6) -> 0 | AM20: =Z20-I20*Z$6/(100+Z$6) -> 0 | AN20: =AA20-J20*AA$6/(100+AA$6) -> 0 | AO20: =+IF(W$71=0,0,IF(W$71<0,-RANK(AJ20,AJ$7:AJ$68,0),RANK(AJ20,AJ$7:AJ$68,1))) -> 0 | AP20: =+IF(X$71=0,0,IF(X$71<0,-RANK(AK20,AK$7:AK$68,0),RANK(AK20,AK$7:AK$68,1))) -> 0 | AQ20: =+IF(Y$71=0,0,IF(Y$71<0,-RANK(AL20,AL$7:AL$68,0),RANK(AL20,AL$7:AL$68,1))) -> 0 | AR20: =+IF(Z$71=0,0,IF(Z$71<0,-RANK(AM20,AM$7:AM$68,0),RANK(AM20,AM$7:AM$68,1))) -> 0 | AS20: =+IF(AA$71=0,0,IF(AA$71<0,-RANK(AN20,AN$7:AN$68,0),RANK(AN20,AN$7:AN$68,1))) -> 0 | AY20: =AC20-N20*AC$6/(100+AC$6) -> 0 | AZ20: =AD20-O20*AD$6/(100+AD$6) -> 0 | BA20: =AE20-P20*AE$6/(100+AE$6) -> 0 | BB20: =AF20-Q20*AF$6/(100+AF$6) -> 0 | BC20: =AG20-R20*AG$6/(100+AG$6) -> 0 | BD20: =+IF(AC$71=0,0,IF(AC$71<0,-RANK(AY20,AY$7:AY$68,0),RANK(AY20,AY$7:AY$68,1))) -> 0 | BE20: =+IF(AD$71=0,0,IF(AD$71<0,-RANK(AZ20,AZ$7:AZ$68,0),RANK(AZ20,AZ$7:AZ$68,1))) -> 0 | BF20: =+IF(AE$71=0,0,IF(AE$71<0,-RANK(BA20,BA$7:BA$68,0),RANK(BA20,BA$7:BA$68,1))) -> 0 | BG20: =+IF(AF$71=0,0,IF(AF$71<0,-RANK(BB20,BB$7:BB$68,0),RANK(BB20,BB$7:BB$68,1))) -> 0 | BH20: =+IF(AG$71=0,0,IF(AG$71<0,-RANK(BC20,BC$7:BC$68,0),RANK(BC20,BC$7:BC$68,1))) -> 0
C21: 481141700 | D21: 業務受託収益 | E21: =+SUMIFS([1]全伝票!I:I,[1]全伝票!$C:$C,$C21) -> 1409733 | F21: =+SUMIFS([1]全伝票!J:J,[1]全伝票!$C:$C,$C21) -> 0 | G21: =+SUMIFS([1]全伝票!K:K,[1]全伝票!$C:$C,$C21) -> 0 | H21: =+SUMIFS([1]全伝票!L:L,[1]全伝票!$C:$C,$C21) -> 0 | I21: =+SUMIFS([1]全伝票!M:M,[1]全伝票!$C:$C,$C21) -> 0 | J21: =+SUMIFS([1]全伝票!N:N,[1]全伝票!$C:$C,$C21) -> 1409733 | K21: =SUM(F21:J21) -> 1409733 | L21: =+SUMIFS([1]全伝票!O:O,[1]全伝票!$C:$C,$C21) -> 0 | S21: =SUM(N21:R21) -> 0 | U21: =+V21-SUM(S21:T21) -> 0 | V21: =+SUMIFS([1]全伝票!P:P,[1]全伝票!$C:$C,$C21) -> 0 | W21: =+ROUND(F21*F$6/(100+F$6),0)+AT21 -> 0 | X21: =+ROUND(G21*G$6/(100+G$6),0)+AU21 -> 0 | Y21: =+ROUND(H21*H$6/(100+H$6),0)+AV21 -> 0 | Z21: =+ROUND(I21*I$6/(100+I$6),0)+AW21 -> 0 | AA21: =+ROUND(J21*J$6/(100+J$6),0)+AX21 -> 128157 | AB21: =SUM(W21:AA21) -> 128157 | AC21: =+ROUND(N21*AC$6/(100+AC$6),0)+BI21 -> 0 | AD21: =+ROUND(O21*AD$6/(100+AD$6),0)+BJ21 -> 0 | AE21: =+ROUND(P21*AE$6/(100+AE$6),0)+BK21 -> 0 | AF21: =+ROUND(Q21*AF$6/(100+AF$6),0)+BL21 -> 0 | AG21: =+ROUND(R21*AG$6/(100+AG$6),0)+BM21 -> 0 | AH21: =SUM(AC21:AG21) -> 0 | AI21: =+E21-AB21 -> 1281576 | AJ21: =W21-F21*W$6/(100+W$6) -> 0 | AK21: =X21-G21*X$6/(100+X$6) -> 0 | AL21: =Y21-H21*Y$6/(100+Y$6) -> 0 | AM21: =Z21-I21*Z$6/(100+Z$6) -> 0 | AN21: =AA21-J21*AA$6/(100+AA$6) -> -0.54545455 | AO21: =+IF(W$71=0,0,IF(W$71<0,-RANK(AJ21,AJ$7:AJ$68,0),RANK(AJ21,AJ$7:AJ$68,1))) -> 0 | AP21: =+IF(X$71=0,0,IF(X$71<0,-RANK(AK21,AK$7:AK$68,0),RANK(AK21,AK$7:AK$68,1))) -> 0 | AQ21: =+IF(Y$71=0,0,IF(Y$71<0,-RANK(AL21,AL$7:AL$68,0),RANK(AL21,AL$7:AL$68,1))) -> 0 | AR21: =+IF(Z$71=0,0,IF(Z$71<0,-RANK(AM21,AM$7:AM$68,0),RANK(AM21,AM$7:AM$68,1))) -> 0 | AS21: =+IF(AA$71=0,0,IF(AA$71<0,-RANK(AN21,AN$7:AN$68,0),RANK(AN21,AN$7:AN$68,1))) -> 0 | AX21: -1 | AY21: =AC21-N21*AC$6/(100+AC$6) -> 0 | AZ21: =AD21-O21*AD$6/(100+AD$6) -> 0 | BA21: =AE21-P21*AE$6/(100+AE$6) -> 0 | BB21: =AF21-Q21*AF$6/(100+AF$6) -> 0 | BC21: =AG21-R21*AG$6/(100+AG$6) -> 0 | BD21: =+IF(AC$71=0,0,IF(AC$71<0,-RANK(AY21,AY$7:AY$68,0),RANK(AY21,AY$7:AY$68,1))) -> 0 | BE21: =+IF(AD$71=0,0,IF(AD$71<0,-RANK(AZ21,AZ$7:AZ$68,0),RANK(AZ21,AZ$7:AZ$68,1))) -> 0 | BF21: =+IF(AE$71=0,0,IF(AE$71<0,-RANK(BA21,BA$7:BA$68,0),RANK(BA21,BA$7:BA$68,1))) -> 0 | BG21: =+IF(AF$71=0,0,IF(AF$71<0,-RANK(BB21,BB$7:BB$68,0),RANK(BB21,BB$7:BB$68,1))) -> 0 | BH21: =+IF(AG$71=0,0,IF(AG$71<0,-RANK(BC21,BC$7:BC$68,0),RANK(BC21,BC$7:BC$68,1))) -> 0
D22: 手数料 | E22: =+SUM(E23:E25) -> 610970 | F22: =+SUM(F23:F25) -> 0 | G22: =+SUM(G23:G25) -> 0 | H22: =+SUM(H23:H25) -> 0 | I22: =+SUM(I23:I25) -> 0 | J22: =+SUM(J23:J25) -> 0 | K22: =+SUM(K23:K25) -> 0 | L22: =+SUM(L23:L25) -> 610970 | ... AI22: =+SUM(AI23:AI25) -> 610970
C23: 481141915 | D23: 証明手数料 | E23: =+SUMIFS([1]全伝票!I:I,[1]全伝票!$C:$C,$C23) -> 71970 | F23: =+SUMIFS([1]全伝票!J:J,[1]全伝票!$C:$C,$C23) -> 0 | G23: =+SUMIFS([1]全伝票!K:K,[1]全伝票!$C:$C,$C23) -> 0 | H23: =+SUMIFS([1]全伝票!L:L,[1]全伝票!$C:$C,$C23) -> 0 | I23: =+SUMIFS([1]全伝票!M:M,[1]全伝票!$C:$C,$C23) -> 0 | J23: =+SUMIFS([1]全伝票!N:N,[1]全伝票!$C:$C,$C23) -> 0 | K23: =SUM(F23:J23) -> 0 | L23: =+SUMIFS([1]全伝票!O:O,[1]全伝票!$C:$C,$C23) -> 71970 | S23: =SUM(N23:R23) -> 0 | U23: =+V23-SUM(S23:T23) -> 0 | V23: =+SUMIFS([1]全伝票!P:P,[1]全伝票!$C:$C,$C23) -> 0 | W23: =+ROUND(F23*F$6/(100+F$6),0)+AT23 -> 0 | X23: =+ROUND(G23*G$6/(100+G$6),0)+AU23 -> 0 | Y23: =+ROUND(H23*H$6/(100+H$6),0)+AV23 -> 0 | Z23: =+ROUND(I23*I$6/(100+I$6),0)+AW23 -> 0 | AA23: =+ROUND(J23*J$6/(100+J$6),0)+AX23 -> 0 | AB23: =SUM(W23:AA23) -> 0 | AC23: =+ROUND(N23*AC$6/(100+AC$6),0)+BI23 -> 0 | AD23: =+ROUND(O23*AD$6/(100+AD$6),0)+BJ23 -> 0 | AE23: =+ROUND(P23*AE$6/(100+AE$6),0)+BK23 -> 0 | AF23: =+ROUND(Q23*AF$6/(100+AF$6),0)+BL23 -> 0 | AG23: =+ROUND(R23*AG$6/(100+AG$6),0)+BM23 -> 0 | AH23: =SUM(AC23:AG23) -> 0 | AI23: =+E23-AB23 -> 71970 | AJ23: =W23-F23*W$6/(100+W$6) -> 0 | AK23: =X23-G23*X$6/(100+X$6) -> 0 | AL23: =Y23-H23*Y$6/(100+Y$6) -> 0 | AM23: =Z23-I23*Z$6/(100+Z$6) -> 0 | AN23: =AA23-J23*AA$6/(100+AA$6) -> 0 | AO23: =+IF(W$71=0,0,IF(W$71<0,-RANK(AJ23,AJ$7:AJ$68,0),RANK(AJ23,AJ$7:AJ$68,1))) -> 0 | AP23: =+IF(X$71=0,0,IF(X$71<0,-RANK(AK23,AK$7:AK$68,0),RANK(AK23,AK$7:AK$68,1))) -> 0 | AQ23: =+IF(Y$71=0,0,IF(Y$71<0,-RANK(AL23,AL$7:AL$68,0),RANK(AL23,AL$7:AL$68,1))) -> 0 | AR23: =+IF(Z$71=0,0,IF(Z$71<0,-RANK(AM23,AM$7:AM$68,0),RANK(AM23,AM$7:AM$68,1))) -> 0 | AS23: =+IF(AA$71=0,0,IF(AA$71<0,-RANK(AN23,AN$7:AN$68,0),RANK(AN23,AN$7:AN$68,1))) -> 0 | AY23: =AC23-N23*AC$6/(100+AC$6) -> 0 | AZ23: =AD23-O23*AD$6/(100+AD$6) -> 0 | BA23: =AE23-P23*AE$6/(100+AE$6) -> 0 | BB23: =AF23-Q23*AF$6/(100+AF$6) -> 0 | BC23: =AG23-R23*AG$6/(100+AG$6) -> 0 | BD23: =+IF(AC$71=0,0,IF(AC$71<0,-RANK(AY23,AY$7:AY$68,0),RANK(AY23,AY$7:AY$68,1))) -> 0 | BE23: =+IF(AD$71=0,0,IF(AD$71<0,-RANK(AZ23,AZ$7:AZ$68,0),RANK(AZ23,AZ$7:AZ$68,1))) -> 0 | BF23: =+IF(AE$71=0,0,IF(AE$71<0,-RANK(BA23,BA$7:BA$68,0),RANK(BA23,BA$7:BA$68,1))) -> 0 | BG23: =+IF(AF$71=0,0,IF(AF$71<0,-RANK(BB23,BB$7:BB$68,0),RANK(BB23,BB$7:BB$68,1))) -> 0 | BH23: =+IF(AG$71=0,0,IF(AG$71<0,-RANK(BC23,BC$7:BC$68,0),RANK(BC23,BC$7:BC$68,1))) -> 0
C24: 481141916 | D24: 指定業者登録等手数料 | E24: =+SUMIFS([1]全伝票!I:I,[1]全伝票!$C:$C,$C24) -> 539000 | F24: =+SUMIFS([1]全伝票!J:J,[1]全伝票!$C:$C,$C24) -> 0 | G24: =+SUMIFS([1]全伝票!K:K,[1]全伝票!$C:$C,$C24) -> 0 | H24: =+SUMIFS([1]全伝票!L:L,[1]全伝票!$C:$C,$C24) -> 0 | I24: =+SUMIFS([1]全伝票!M:M,[1]全伝票!$C:$C,$C24) -> 0 | J24: =+SUMIFS([1]全伝票!N:N,[1]全伝票!$C:$C,$C24) -> 0 | K24: =SUM(F24:J24) -> 0 | L24: =+SUMIFS([1]全伝票!O:O,[1]全伝票!$C:$C,$C24) -> 539000 | S24: =SUM(N24:R24) -> 0 | U24: =+V24-SUM(S24:T24) -> 0 | V24: =+SUMIFS([1]全伝票!P:P,[1]全伝票!$C:$C,$C24) -> 0 | W24: =+ROUND(F24*F$6/(100+F$6),0)+AT24 -> 0 | X24: =+ROUND(G24*G$6/(100+G$6),0)+AU24 -> 0 | Y24: =+ROUND(H24*H$6/(100+H$6),0)+AV24 -> 0 | Z24: =+ROUND(I24*I$6/(100+I$6),0)+AW24 -> 0 | AA24: =+ROUND(J24*J$6/(100+J$6),0)+AX24 -> 0 | AB24: =SUM(W24:AA24) -> 0 | AC24: =+ROUND(N24*AC$6/(100+AC$6),0)+BI24 -> 0 | AD24: =+ROUND(O24*AD$6/(100+AD$6),0)+BJ24 -> 0 | AE24: =+ROUND(P24*AE$6/(100+AE$6),0)+BK24 -> 0 | AF24: =+ROUND(Q24*AF$6/(100+AF$6),0)+BL24 -> 0 | AG24: =+ROUND(R24*AG$6/(100+AG$6),0)+BM24 -> 0 | AH24: =SUM(AC24:AG24) -> 0 | AI24: =+E24-AB24 -> 539000 | AJ24: =W24-F24*W$6/(100+W$6) -> 0 | AK24: =X24-G24*X$6/(100+X$6) -> 0 | AL24: =Y24-H24*Y$6/(100+Y$6) -> 0 | AM24: =Z24-I24*Z$6/(100+Z$6) -> 0 | AN24: =AA24-J24*AA$6/(100+AA$6) -> 0 | AO24: =+IF(W$71=0,0,IF(W$71<0,-RANK(AJ24,AJ$7:AJ$68,0),RANK(AJ24,AJ$7:AJ$68,1))) -> 0 | AP24: =+IF(X$71=0,0,IF(X$71<0,-RANK(AK24,AK$7:AK$68,0),RANK(AK24,AK$7:AK$68,1))) -> 0 | AQ24: =+IF(Y$71=0,0,IF(Y$71<0,-RANK(AL24,AL$7:AL$68,0),RANK(AL24,AL$7:AL$68,1))) -> 0 | AR24: =+IF(Z$71=0,0,IF(Z$71<0,-RANK(AM24,AM$7:AM$68,0),RANK(AM24,AM$7:AM$68,1))) -> 0 | AS24: =+IF(AA$71=0,0,IF(AA$71<0,-RANK(AN24,AN$7:AN$68,0),RANK(AN24,AN$7:AN$68,1))) -> 0 | AY24: =AC24-N24*AC$6/(100+AC$6) -> 0 | AZ24: =AD24-O24*AD$6/(100+AD$6) -> 0 | BA24: =AE24-P24*AE$6/(100+AE$6) -> 0 | BB24: =AF24-Q24*AF$6/(100+AF$6) -> 0 | BC24: =AG24-R24*AG$6/(100+AG$6) -> 0 | BD24: =+IF(AC$71=0,0,IF(AC$71<0,-RANK(AY24,AY$7:AY$68,0),RANK(AY24,AY$7:AY$68,1))) -> 0 | BE24: =+IF(AD$71=0,0,IF(AD$71<0,-RANK(AZ24,AZ$7:AZ$68,0),RANK(AZ24,AZ$7:AZ$68,1))) -> 0 | BF24: =+IF(AE$71=0,0,IF(AE$71<0,-RANK(BA24,BA$7:BA$68,0),RANK(BA24,BA$7:BA$68,1))) -> 0 | BG24: =+IF(AF$71=0,0,IF(AF$71<0,-RANK(BB24,BB$7:BB$68,0),RANK(BB24,BB$7:BB$68,1))) -> 0 | BH24: =+IF(AG$71=0,0,IF(AG$71<0,-RANK(BC24,BC$7:BC$68,0),RANK(BC24,BC$7:BC$68,1))) -> 0
C25: 481141917 | D25: その他手数料 | E25: =+SUMIFS([1]全伝票!I:I,[1]全伝票!$C:$C,$C25) -> 0 | F25: =+SUMIFS([1]全伝票!J:J,[1]全伝票!$C:$C,$C25) -> 0 | G25: =+SUMIFS([1]全伝票!K:K,[1]全伝票!$C:$C,$C25) -> 0 | H25: =+SUMIFS([1]全伝票!L:L,[1]全伝票!$C:$C,$C25) -> 0 | I25: =+SUMIFS([1]全伝票!M:M,[1]全伝票!$C:$C,$C25) -> 0 | J25: =+SUMIFS([1]全伝票!N:N,[1]全伝票!$C:$C,$C25) -> 0 | K25: =SUM(F25:J25) -> 0 | L25: =+SUMIFS([1]全伝票!O:O,[1]全伝票!$C:$C,$C25) -> 0 | S25: =SUM(N25:R25) -> 0 | U25: =+V25-SUM(S25:T25) -> 0 | V25: =+SUMIFS([1]全伝票!P:P,[1]全伝票!$C:$C,$C25) -> 0 | W25: =+ROUND(F25*F$6/(100+F$6),0)+AT25 -> 0 | X25: =+ROUND(G25*G$6/(100+G$6),0)+AU25 -> 0 | Y25: =+ROUND(H25*H$6/(100+H$6),0)+AV25 -> 0 | Z25: =+ROUND(I25*I$6/(100+I$6),0)+AW25 -> 0 | AA25: =+ROUND(J25*J$6/(100+J$6),0)+AX25 -> 0 | AB25: =SUM(W25:AA25) -> 0 | AC25: =+ROUND(N25*AC$6/(100+AC$6),0)+BI25 -> 0 | AD25: =+ROUND(O25*AD$6/(100+AD$6),0)+BJ25 -> 0 | AE25: =+ROUND(P25*AE$6/(100+AE$6),0)+BK25 -> 0 | AF25: =+ROUND(Q25*AF$6/(100+AF$6),0)+BL25 -> 0 | AG25: =+ROUND(R25*AG$6/(100+AG$6),0)+BM25 -> 0 | AH25: =SUM(AC25:AG25) -> 0 | AI25: =+E25-AB25 -> 0 | AJ25: =W25-F25*W$6/(100+W$6) -> 0 | AK25: =X25-G25*X$6/(100+X$6) -> 0 | AL25: =Y25-H25*Y$6/(100+Y$6) -> 0 | AM25: =Z25-I25*Z$6/(100+Z$6) -> 0 | AN25: =AA25-J25*AA$6/(100+AA$6) -> 0 | AO25: =+IF(W$71=0,0,IF(W$71<0,-RANK(AJ25,AJ$7:AJ$68,0),RANK(AJ25,AJ$7:AJ$68,1))) -> 0 | AP25: =+IF(X$71=0,0,IF(X$71<0,-RANK(AK25,AK$7:AK$68,0),RANK(AK25,AK$7:AK$68,1))) -> 0 | AQ25: =+IF(Y$71=0,0,IF(Y$71<0,-RANK(AL25,AL$7:AL$68,0),RANK(AL25,AL$7:AL$68,1))) -> 0 | AR25: =+IF(Z$71=0,0,IF(Z$71<0,-RANK(AM25,AM$7:AM$68,0),RANK(AM25,AM$7:AM$68,1))) -> 0 | AS25: =+IF(AA$71=0,0,IF(AA$71<0,-RANK(AN25,AN$7:AN$68,0),RANK(AN25,AN$7:AN$68,1))) -> 0 | AY25: =AC25-N25*AC$6/(100+AC$6) -> 0 | AZ25: =AD25-O25*AD$6/(100+AD$6) -> 0 | BA25: =AE25-P25*AE$6/(100+AE$6) -> 0 | BB25: =AF25-Q25*AF$6/(100+AF$6) -> 0 | BC25: =AG25-R25*AG$6/(100+AG$6) -> 0 | BD25: =+IF(AC$71=0,0,IF(AC$71<0,-RANK(AY25,AY$7:AY$68,0),RANK(AY25,AY$7:AY$68,1))) -> 0 | BE25: =+IF(AD$71=0,0,IF(AD$71<0,-RANK(AZ25,AZ$7:AZ$68,0),RANK(AZ25,AZ$7:AZ$68,1))) -> 0 | BF25: =+IF(AE$71=0,0,IF(AE$71<0,-RANK(BA25,BA$7:BA$68,0),RANK(BA25,BA$7:BA$68,1))) -> 0 | BG25: =+IF(AF$71=0,0,IF(AF$71<0,-RANK(BB25,BB$7:BB$68,0),RANK(BB25,BB$7:BB$68,1))) -> 0 | BH25: =+IF(AG$71=0,0,IF(AG$71<0,-RANK(BC25,BC$7:BC$68,0),RANK(BC25,BC$7:BC$68,1))) -> 0
C26: 481142000 | D26: 雑収益 | E26: =+SUMIFS([1]全伝票!I:I,[1]全伝票!$C:$C,$C26) -> 0 | F26: =+SUMIFS([1]全伝票!J:J,[1]全伝票!$C:$C,$C26) -> 0 | G26: =+SUMIFS([1]全伝票!K:K,[1]全伝票!$C:$C,$C26) -> 0 | H26: =+SUMIFS([1]全伝票!L:L,[1]全伝票!$C:$C,$C26) -> 0 | I26: =+SUMIFS([1]全伝票!M:M,[1]全伝票!$C:$C,$C26) -> 0 | J26: =+SUMIFS([1]全伝票!N:N,[1]全伝票!$C:$C,$C26) -> 0 | K26: =SUM(F26:J26) -> 0 | L26: =+SUMIFS([1]全伝票!O:O,[1]全伝票!$C:$C,$C26) -> 0 | S26: =SUM(N26:R26) -> 0 | U26: =+V26-SUM(S26:T26) -> 0 | V26: =+SUMIFS([1]全伝票!P:P,[1]全伝票!$C:$C,$C26) -> 0 | W26: =+ROUND(F26*F$6/(100+F$6),0)+AT26 -> 0 | X26: =+ROUND(G26*G$6/(100+G$6),0)+AU26 -> 0 | Y26: =+ROUND(H26*H$6/(100+H$6),0)+AV26 -> 0 | Z26: =+ROUND(I26*I$6/(100+I$6),0)+AW26 -> 0 | AA26: =+ROUND(J26*J$6/(100+J$6),0)+AX26 -> 0 | AB26: =SUM(W26:AA26) -> 0 | AC26: =+ROUND(N26*AC$6/(100+AC$6),0)+BI26 -> 0 | AD26: =+ROUND(O26*AD$6/(100+AD$6),0)+BJ26 -> 0 | AE26: =+ROUND(P26*AE$6/(100+AE$6),0)+BK26 -> 0 | AF26: =+ROUND(Q26*AF$6/(100+AF$6),0)+BL26 -> 0 | AG26: =+ROUND(R26*AG$6/(100+AG$6),0)+BM26 -> 0 | AH26: =SUM(AC26:AG26) -> 0 | AI26: =+E26-AB26 -> 0 | AJ26: =W26-F26*W$6/(100+W$6) -> 0 | AK26: =X26-G26*X$6/(100+X$6) -> 0 | AL26: =Y26-H26*Y$6/(100+Y$6) -> 0 | AM26: =Z26-I26*Z$6/(100+Z$6) -> 0 | AN26: =AA26-J26*AA$6/(100+AA$6) -> 0 | AO26: =+IF(W$71=0,0,IF(W$71<0,-RANK(AJ26,AJ$7:AJ$68,0),RANK(AJ26,AJ$7:AJ$68,1))) -> 0 | AP26: =+IF(X$71=0,0,IF(X$71<0,-RANK(AK26,AK$7:AK$68,0),RANK(AK26,AK$7:AK$68,1))) -> 0 | AQ26: =+IF(Y$71=0,0,IF(Y$71<0,-RANK(AL26,AL$7:AL$68,0),RANK(AL26,AL$7:AL$68,1))) -> 0 | AR26: =+IF(Z$71=0,0,IF(Z$71<0,-RANK(AM26,AM$7:AM$68,0),RANK(AM26,AM$7:AM$68,1))) -> 0 | AS26: =+IF(AA$71=0,0,IF(AA$71<0,-RANK(AN26,AN$7:AN$68,0),RANK(AN26,AN$7:AN$68,1))) -> 0 | AY26: =AC26-N26*AC$6/(100+AC$6) -> 0 | AZ26: =AD26-O26*AD$6/(100+AD$6) -> 0 | BA26: =AE26-P26*AE$6/(100+AE$6) -> 0 | BB26: =AF26-Q26*AF$6/(100+AF$6) -> 0 | BC26: =AG26-R26*AG$6/(100+AG$6) -> 0 | BD26: =+IF(AC$71=0,0,IF(AC$71<0,-RANK(AY26,AY$7:AY$68,0),RANK(AY26,AY$7:AY$68,1))) -> 0 | BE26: =+IF(AD$71=0,0,IF(AD$71<0,-RANK(AZ26,AZ$7:AZ$68,0),RANK(AZ26,AZ$7:AZ$68,1))) -> 0 | BF26: =+IF(AE$71=0,0,IF(AE$71<0,-RANK(BA26,BA$7:BA$68,0),RANK(BA26,BA$7:BA$68,1))) -> 0 | BG26: =+IF(AF$71=0,0,IF(AF$71<0,-RANK(BB26,BB$7:BB$68,0),RANK(BB26,BB$7:BB$68,1))) -> 0 | BH26: =+IF(AG$71=0,0,IF(AG$71<0,-RANK(BC26,BC$7:BC$68,0),RANK(BC26,BC$7:BC$68,1))) -> 0
D27: 営業収益 | E27: =+SUM(E7,E9,E17,E19) -> 34865911732 | F27: =+SUM(F7,F9,F17,F19) -> 0 | G27: =+SUM(G7,G9,G17,G19) -> 0 | H27: =+SUM(H7,H9,H17,H19) -> 0 | I27: =+SUM(I7,I9,I17,I19) -> 0 | J27: =+SUM(J7,J9,J17,J19) -> 20678111567 | K27: =+SUM(K7,K9,K17,K19) -> 20678111567 | L27: =+SUM(L7,L9,L17,L19) -> 610970 | ... AI27: =+SUM(AI7,AI9,AI17,AI19) -> 32986083408
D28: 受取利息 | E28: =+SUM(E29:E31) -> 88770 | F28: =+SUM(F29:F31) -> 0 | G28: =+SUM(G29:G31) -> 0 | H28: =+SUM(H29:H31) -> 0 | I28: =+SUM(I29:I31) -> 0 | J28: =+SUM(J29:J31) -> 0 | K28: =+SUM(K29:K31) -> 0 | L28: =+SUM(L29:L31) -> 88770 | ... AI28: =+SUM(AI29:AI31) -> 88770
C29: 482022100 | D29: 預金利息 | E29: =+SUMIFS([1]全伝票!I:I,[1]全伝票!$C:$C,$C29) -> 88770 | F29: =+SUMIFS([1]全伝票!J:J,[1]全伝票!$C:$C,$C29) -> 0 | G29: =+SUMIFS([1]全伝票!K:K,[1]全伝票!$C:$C,$C29) -> 0 | H29: =+SUMIFS([1]全伝票!L:L,[1]全伝票!$C:$C,$C29) -> 0 | I29: =+SUMIFS([1]全伝票!M:M,[1]全伝票!$C:$C,$C29) -> 0 | J29: =+SUMIFS([1]全伝票!N:N,[1]全伝票!$C:$C,$C29) -> 0 | K29: =SUM(F29:J29) -> 0 | L29: =+SUMIFS([1]全伝票!O:O,[1]全伝票!$C:$C,$C29) -> 88770 | S29: =SUM(N29:R29) -> 0 | U29: =+V29-SUM(S29:T29) -> 0 | V29: =+SUMIFS([1]全伝票!P:P,[1]全伝票!$C:$C,$C29) -> 0 | W29: =+ROUND(F29*F$6/(100+F$6),0)+AT29 -> 0 | X29: =+ROUND(G29*G$6/(100+G$6),0)+AU29 -> 0 | Y29: =+ROUND(H29*H$6/(100+H$6),0)+AV29 -> 0 | Z29: =+ROUND(I29*I$6/(100+I$6),0)+AW29 -> 0 | AA29: =+ROUND(J29*J$6/(100+J$6),0)+AX29 -> 0 | AB29: =SUM(W29:AA29) -> 0 | AC29: =+ROUND(N29*AC$6/(100+AC$6),0)+BI29 -> 0 | AD29: =+ROUND(O29*AD$6/(100+AD$6),0)+BJ29 -> 0 | AE29: =+ROUND(P29*AE$6/(100+AE$6),0)+BK29 -> 0 | AF29: =+ROUND(Q29*AF$6/(100+AF$6),0)+BL29 -> 0 | AG29: =+ROUND(R29*AG$6/(100+AG$6),0)+BM29 -> 0 | AH29: =SUM(AC29:AG29) -> 0 | AI29: =+E29-AB29 -> 88770
C30: 482022200 | D30: 貸付金利息 | E30: =+SUMIFS([1]全伝票!I:I,[1]全伝票!$C:$C,$C30) -> 0 | F30: =+SUMIFS([1]全伝票!J:J,[1]全伝票!$C:$C,$C30) -> 0 | G30: =+SUMIFS([1]全伝票!K:K,[1]全伝票!$C:$C,$C30) -> 0 | H30: =+SUMIFS([1]全伝票!L:L,[1]全伝票!$C:$C,$C30) -> 0 | I30: =+SUMIFS([1]全伝票!M:M,[1]全伝票!$C:$C,$C30) -> 0 | J30: =+SUMIFS([1]全伝票!N:N,[1]全伝票!$C:$C,$C30) -> 0 | K30: =SUM(F30:J30) -> 0 | L30: =+SUMIFS([1]全伝票!O:O,[1]全伝票!$C:$C,$C30) -> 0 | S30: =SUM(N30:R30) -> 0 | U30: =+V30-SUM(S30:T30) -> 0 | V30: =+SUMIFS([1]全伝票!P:P,[1]全伝票!$C:$C,$C30) -> 0 | W30: =+ROUND(F30*F$6/(100+F$6),0)+AT30 -> 0 | X30: =+ROUND(G30*G$6/(100+G$6),0)+AU30 -> 0 | Y30: =+ROUND(H30*H$6/(100+H$6),0)+AV30 -> 0 | Z30: =+ROUND(I30*I$6/(100+I$6),0)+AW30 -> 0 | AA30: =+ROUND(J30*J$6/(100+J$6),0)+AX30 -> 0 | AB30: =SUM(W30:AA30) -> 0 | AC30: =+ROUND(N30*AC$6/(100+AC$6),0)+BI30 -> 0 | AD30: =+ROUND(O30*AD$6/(100+AD$6),0)+BJ30 -> 0 | AE30: =+ROUND(P30*AE$6/(100+AE$6),0)+BK30 -> 0 | AF30: =+ROUND(Q30*AF$6/(100+AF$6),0)+BL30 -> 0 | AG30: =+ROUND(R30*AG$6/(100+AG$6),0)+BM30 -> 0 | AH30: =SUM(AC30:AG30) -> 0 | AI30: =+E30-AB30 -> 0
C31: 482022400 | D31: 有価証券利息 | E31: =+SUMIFS([1]全伝票!I:I,[1]全伝票!$C:$C,$C31) -> 0 | F31: =+SUMIFS([1]全伝票!J:J,[1]全伝票!$C:$C,$C31) -> 0 | G31: =+SUMIFS([1]全伝票!K:K,[1]全伝票!$C:$C,$C31) -> 0 | H31: =+SUMIFS([1]全伝票!L:L,[1]全伝票!$C:$C,$C31) -> 0 | I31: =+SUMIFS([1]全伝票!M:M,[1]全伝票!$C:$C,$C31) -> 0 | J31: =+SUMIFS([1]全伝票!N:N,[1]全伝票!$C:$C,$C31) -> 0 | K31: =SUM(F31:J31) -> 0 | L31: =+SUMIFS([1]全伝票!O:O,[1]全伝票!$C:$C,$C31) -> 0 | S31: =SUM(N31:R31) -> 0 | U31: =+V31-SUM(S31:T31) -> 0 | V31: =+SUMIFS([1]全伝票!P:P,[1]全伝票!$C:$C,$C31) -> 0 | W31: =+ROUND(F31*F$6/(100+F$6),0)+AT31 -> 0 | X31: =+ROUND(G31*G$6/(100+G$6),0)+AU31 -> 0 | Y31: =+ROUND(H31*H$6/(100+H$6),0)+AV31 -> 0 | Z31: =+ROUND(I31*I$6/(100+I$6),0)+AW31 -> 0 | AA31: =+ROUND(J31*J$6/(100+J$6),0)+AX31 -> 0 | AB31: =SUM(W31:AA31) -> 0 | AC31: =+ROUND(N31*AC$6/(100+AC$6),0)+BI31 -> 0 | AD31: =+ROUND(O31*AD$6/(100+AD$6),0)+BJ31 -> 0 | AE31: =+ROUND(P31*AE$6/(100+AE$6),0)+BK31 -> 0 | AF31: =+ROUND(Q31*AF$6/(100+AF$6),0)+BL31 -> 0 | AG31: =+ROUND(R31*AG$6/(100+AG$6),0)+BM31 -> 0 | AH31: =SUM(AC31:AG31) -> 0 | AI31: =+E31-AB31 -> 0
D32: 国庫補助金 | E32: =+SUM(E33:E34) -> 0 | F32: =+SUM(F33:F34) -> 0 | G32: =+SUM(G33:G34) -> 0 | H32: =+SUM(H33:H34) -> 0 | I32: =+SUM(I33:I34) -> 0 | J32: =+SUM(J33:J34) -> 0 | K32: =+SUM(K33:K34) -> 0 | L32: =+SUM(L33:L34) -> 0 | ... AI32: =+SUM(AI33:AI34) -> 0
C33: 482042700 | D33: 下水緊急整備国庫補助金 | E33: =+SUMIFS([1]全伝票!I:I,[1]全伝票!$C:$C,$C33) -> 0 | F33: =+SUMIFS([1]全伝票!J:J,[1]全伝票!$C:$C,$C33) -> 0 | G33: =+SUMIFS([1]全伝票!K:K,[1]全伝票!$C:$C,$C33) -> 0 | H33: =+SUMIFS([1]全伝票!L:L,[1]全伝票!$C:$C,$C33) -> 0 | I33: =+SUMIFS([1]全伝票!M:M,[1]全伝票!$C:$C,$C33) -> 0 | J33: =+SUMIFS([1]全伝票!N:N,[1]全伝票!$C:$C,$C33) -> 0 | K33: =SUM(F33:J33) -> 0 | L33: =+SUMIFS([1]全伝票!O:O,[1]全伝票!$C:$C,$C33) -> 0 | S33: =SUM(N33:R33) -> 0 | U33: =+V33-SUM(S33:T33) -> 0 | V33: =+SUMIFS([1]全伝票!P:P,[1]全伝票!$C:$C,$C33) -> 0 | W33: =+ROUND(F33*F$6/(100+F$6),0)+AT33 -> 0 | X33: =+ROUND(G33*G$6/(100+G$6),0)+AU33 -> 0 | Y33: =+ROUND(H33*H$6/(100+H$6),0)+AV33 -> 0 | Z33: =+ROUND(I33*I$6/(100+I$6),0)+AW33 -> 0 | AA33: =+ROUND(J33*J$6/(100+J$6),0)+AX33 -> 0 | AB33: =SUM(W33:AA33) -> 0 | AC33: =+ROUND(N33*AC$6/(100+AC$6),0)+BI33 -> 0 | AD33: =+ROUND(O33*AD$6/(100+AD$6),0)+BJ33 -> 0 | AE33: =+ROUND(P33*AE$6/(100+AE$6),0)+BK33 -> 0 | AF33: =+ROUND(Q33*AF$6/(100+AF$6),0)+BL33 -> 0 | AG33: =+ROUND(R33*AG$6/(100+AG$6),0)+BM33 -> 0 | AH33: =SUM(AC33:AG33) -> 0 | AI33: =+E33-AB33 -> 0
D34: その他国庫補助金(災害) | E34: =SUM(E35:E38) -> 0 | F34: =SUM(F35:F38) -> 0 | G34: =SUM(G35:G38) -> 0 | H34: =SUM(H35:H38) -> 0 | I34: =SUM(I35:I38) -> 0 | J34: =SUM(J35:J38) -> 0 | K34: =SUM(K35:K38) -> 0 | L34: =SUM(L35:L38) -> 0 | M34: =SUM(M35:M38) -> 0 | O34: =SUM(O35:O38) -> 0 | P34: =SUM(P35:P38) -> 0 | Q34: =SUM(Q35:Q38) -> 0 | R34: =SUM(R35:R38) -> 0 | S34: =SUM(S35:S38) -> 0 | T34: =SUM(T35:T38) -> 0 | U34: =SUM(U35:U38) -> 0 | V34: =SUM(V35:V38) -> 0 | ... AI34: =SUM(AI35:AI38) -> 0 | AY34: =AC34-N34*AC$6/(100+AC$6) -> 0 | AZ34: =AD34-O34*AD$6/(100+AD$6) -> 0 | BA34: =AE34-P34*AE$6/(100+AE$6) -> 0 | BB34: =AF34-Q34*AF$6/(100+AF$6) -> 0 | BC34: =AG34-R34*AG$6/(100+AG$6) -> 0 | BD34: =+IF(AC$71=0,0,IF(AC$71<0,-RANK(AY34,AY$7:AY$68,0),RANK(AY34,AY$7:AY$68,1))) -> 0 | BE34: =+IF(AD$71=0,0,IF(AD$71<0,-RANK(AZ34,AZ$7:AZ$68,0),RANK(AZ34,AZ$7:AZ$68,1))) -> 0 | BF34: =+IF(AE$71=0,0,IF(AE$71<0,-RANK(BA34,BA$7:BA$68,0),RANK(BA34,BA$7:BA$68,1))) -> 0 | BG34: =+IF(AF$71=0,0,IF(AF$71<0,-RANK(BB34,BB$7:BB$68,0),RANK(BB34,BB$7:BB$68,1))) -> 0 | BH34: =+IF(AG$71=0,0,IF(AG$71<0,-RANK(BC34,BC$7:BC$68,0),RANK(BC34,BC$7:BC$68,1))) -> 0
A35: 1 | C35: 482042900 | D35: 公共 | E35: =+SUMIFS([1]全伝票!I:I,[1]全伝票!$C:$C,$C35,[1]全伝票!$A:$A,$A35) -> 0 | F35: =+SUMIFS([1]全伝票!J:J,[1]全伝票!$C:$C,$C35) -> 0 | G35: =+SUMIFS([1]全伝票!K:K,[1]全伝票!$C:$C,$C35) -> 0 | H35: =+SUMIFS([1]全伝票!L:L,[1]全伝票!$C:$C,$C35) -> 0 | I35: =+SUMIFS([1]全伝票!M:M,[1]全伝票!$C:$C,$C35) -> 0 | J35: =+SUMIFS([1]全伝票!N:N,[1]全伝票!$C:$C,$C35) -> 0 | K35: =SUM(F35:J35) -> 0 | L35: =+SUMIFS([1]全伝票!O:O,[1]全伝票!$C:$C,$C35) -> 0 | P35: ='[3]3条災害補助'!L$9 -> 0 | Q35: ='[3]3条災害補助'!M$9 -> 0 | R35: ='[3]3条災害補助'!N$9 -> 0 | S35: =SUM(N35:R35) -> 0 | T35: ='[3]3条災害補助'!I$8 -> 0 | U35: =+V35-SUM(S35:T35) -> 0 | V35: =SUMIFS([1]全伝票!P:P,[1]全伝票!$C:$C,$C35,[1]全伝票!$A:$A,$A35) -> 0 | W35: =+ROUND(F35*F$6/(100+F$6),0)+AT35 -> 0 | X35: =+ROUND(G35*G$6/(100+G$6),0)+AU35 -> 0 | Y35: =+ROUND(H35*H$6/(100+H$6),0)+AV35 -> 0 | Z35: =+ROUND(I35*I$6/(100+I$6),0)+AW35 -> 0 | AA35: =+ROUND(J35*J$6/(100+J$6),0)+AX35 -> 0 | AB35: =SUM(W35:AA35) -> 0 | AC35: =+ROUND(N35*AC$6/(100+AC$6),0)+BI35 -> 0 | AD35: =+ROUND(O35*AD$6/(100+AD$6),0)+BJ35 -> 0 | AE35: =+ROUND(P35*AE$6/(100+AE$6),0)+BK35 -> 0 | AF35: =+ROUND(Q35*AF$6/(100+AF$6),0)+BL35 -> 0 | AG35: =+ROUND(R35*AG$6/(100+AG$6),0)+BM35 -> 0 | AH35: =SUM(AC35:AG35) -> 0 | AI35: =+E35-AB35 -> 0 | AY35: =AC35-N35*AC$6/(100+AC$6) -> 0 | AZ35: =AD35-O35*AD$6/(100+AD$6) -> 0 | BA35: =AE35-P35*AE$6/(100+AE$6) -> 0 | BB35: =AF35-Q35*AF$6/(100+AF$6) -> 0 | BC35: =AG35-R35*AG$6/(100+AG$6) -> 0 | BD35: =+IF(AC$71=0,0,IF(AC$71<0,-RANK(AY35,AY$7:AY$68,0),RANK(AY35,AY$7:AY$68,1))) -> 0 | BE35: =+IF(AD$71=0,0,IF(AD$71<0,-RANK(AZ35,AZ$7:AZ$68,0),RANK(AZ35,AZ$7:AZ$68,1))) -> 0 | BF35: =+IF(AE$71=0,0,IF(AE$71<0,-RANK(BA35,BA$7:BA$68,0),RANK(BA35,BA$7:BA$68,1))) -> 0 | BG35: =+IF(AF$71=0,0,IF(AF$71<0,-RANK(BB35,BB$7:BB$68,0),RANK(BB35,BB$7:BB$68,1))) -> 0 | BH35: =+IF(AG$71=0,0,IF(AG$71<0,-RANK(BC35,BC$7:BC$68,0),RANK(BC35,BC$7:BC$68,1))) -> 0
A36: 2 | C36: 482042900 | D36: 特環 | E36: =+SUMIFS([1]全伝票!I:I,[1]全伝票!$C:$C,$C36,[1]全伝票!$A:$A,$A36) -> 0 | F36: =+SUMIFS([1]全伝票!J:J,[1]全伝票!$C:$C,$C36) -> 0 | G36: =+SUMIFS([1]全伝票!K:K,[1]全伝票!$C:$C,$C36) -> 0 | H36: =+SUMIFS([1]全伝票!L:L,[1]全伝票!$C:$C,$C36) -> 0 | I36: =+SUMIFS([1]全伝票!M:M,[1]全伝票!$C:$C,$C36) -> 0 | J36: =+SUMIFS([1]全伝票!N:N,[1]全伝票!$C:$C,$C36) -> 0 | K36: =SUM(F36:J36) -> 0 | L36: =+SUMIFS([1]全伝票!O:O,[1]全伝票!$C:$C,$C36) -> 0 | P36: ='[3]3条災害補助'!L$23 -> 0 | Q36: ='[3]3条災害補助'!M$23 -> 0 | R36: ='[3]3条災害補助'!N$23 -> 0 | S36: =SUM(N36:R36) -> 0 | T36: ='[3]3条災害補助'!I$22 -> 0 | U36: =+V36-SUM(S36:T36) -> 0 | V36: =SUMIFS([1]全伝票!P:P,[1]全伝票!$C:$C,$C36,[1]全伝票!$A:$A,$A36) -> 0 | W36: =+ROUND(F36*F$6/(100+F$6),0)+AT36 -> 0 | X36: =+ROUND(G36*G$6/(100+G$6),0)+AU36 -> 0 | Y36: =+ROUND(H36*H$6/(100+H$6),0)+AV36 -> 0 | Z36: =+ROUND(I36*I$6/(100+I$6),0)+AW36 -> 0 | AA36: =+ROUND(J36*J$6/(100+J$6),0)+AX36 -> 0 | AB36: =SUM(W36:AA36) -> 0 | AC36: =+ROUND(N36*AC$6/(100+AC$6),0)+BI36 -> 0 | AD36: =+ROUND(O36*AD$6/(100+AD$6),0)+BJ36 -> 0 | AE36: =+ROUND(P36*AE$6/(100+AE$6),0)+BK36 -> 0 | AF36: =+ROUND(Q36*AF$6/(100+AF$6),0)+BL36 -> 0 | AG36: =+ROUND(R36*AG$6/(100+AG$6),0)+BM36 -> 0 | AH36: =SUM(AC36:AG36) -> 0 | AI36: =+E36-AB36 -> 0 | AY36: =AC36-N36*AC$6/(100+AC$6) -> 0 | AZ36: =AD36-O36*AD$6/(100+AD$6) -> 0 | BA36: =AE36-P36*AE$6/(100+AE$6) -> 0 | BB36: =AF36-Q36*AF$6/(100+AF$6) -> 0 | BC36: =AG36-R36*AG$6/(100+AG$6) -> 0 | BD36: =+IF(AC$71=0,0,IF(AC$71<0,-RANK(AY36,AY$7:AY$68,0),RANK(AY36,AY$7:AY$68,1))) -> 0 | BE36: =+IF(AD$71=0,0,IF(AD$71<0,-RANK(AZ36,AZ$7:AZ$68,0),RANK(AZ36,AZ$7:AZ$68,1))) -> 0 | BF36: =+IF(AE$71=0,0,IF(AE$71<0,-RANK(BA36,BA$7:BA$68,0),RANK(BA36,BA$7:BA$68,1))) -> 0 | BG36: =+IF(AF$71=0,0,IF(AF$71<0,-RANK(BB36,BB$7:BB$68,0),RANK(BB36,BB$7:BB$68,1))) -> 0 | BH36: =+IF(AG$71=0,0,IF(AG$71<0,-RANK(BC36,BC$7:BC$68,0),RANK(BC36,BC$7:BC$68,1))) -> 0
A37: 3 | C37: 482042900 | D37: 農集 | E37: =+SUMIFS([1]全伝票!I:I,[1]全伝票!$C:$C,$C37,[1]全伝票!$A:$A,$A37) -> 0 | F37: =+SUMIFS([1]全伝票!J:J,[1]全伝票!$C:$C,$C37) -> 0 | G37: =+SUMIFS([1]全伝票!K:K,[1]全伝票!$C:$C,$C37) -> 0 | H37: =+SUMIFS([1]全伝票!L:L,[1]全伝票!$C:$C,$C37) -> 0 | I37: =+SUMIFS([1]全伝票!M:M,[1]全伝票!$C:$C,$C37) -> 0 | J37: =+SUMIFS([1]全伝票!N:N,[1]全伝票!$C:$C,$C37) -> 0 | K37: =SUM(F37:J37) -> 0 | L37: =+SUMIFS([1]全伝票!O:O,[1]全伝票!$C:$C,$C37) -> 0 | P37: ='[3]3条災害補助'!L$37 -> 0 | Q37: ='[3]3条災害補助'!M$37 -> 0 | R37: ='[3]3条災害補助'!N$37 -> 0 | S37: =SUM(N37:R37) -> 0 | T37: ='[3]3条災害補助'!I$36 -> 0 | U37: =+V37-SUM(S37:T37) -> 0 | V37: =SUMIFS([1]全伝票!P:P,[1]全伝票!$C:$C,$C37,[1]全伝票!$A:$A,$A37) -> 0 | W37: =+ROUND(F37*F$6/(100+F$6),0)+AT37 -> 0 | X37: =+ROUND(G37*G$6/(100+G$6),0)+AU37 -> 0 | Y37: =+ROUND(H37*H$6/(100+H$6),0)+AV37 -> 0 | Z37: =+ROUND(I37*I$6/(100+I$6),0)+AW37 -> 0 | AA37: =+ROUND(J37*J$6/(100+J$6),0)+AX37 -> 0 | AB37: =SUM(W37:AA37) -> 0 | AC37: =+ROUND(N37*AC$6/(100+AC$6),0)+BI37 -> 0 | AD37: =+ROUND(O37*AD$6/(100+AD$6),0)+BJ37 -> 0 | AE37: =+ROUND(P37*AE$6/(100+AE$6),0)+BK37 -> 0 | AF37: =+ROUND(Q37*AF$6/(100+AF$6),0)+BL37 -> 0 | AG37: =+ROUND(R37*AG$6/(100+AG$6),0)+BM37 -> 0 | AH37: =SUM(AC37:AG37) -> 0 | AI37: =+E37-AB37 -> 0 | AY37: =AC37-N37*AC$6/(100+AC$6) -> 0 | AZ37: =AD37-O37*AD$6/(100+AD$6) -> 0 | BA37: =AE37-P37*AE$6/(100+AE$6) -> 0 | BB37: =AF37-Q37*AF$6/(100+AF$6) -> 0 | BC37: =AG37-R37*AG$6/(100+AG$6) -> 0 | BD37: =+IF(AC$71=0,0,IF(AC$71<0,-RANK(AY37,AY$7:AY$68,0),RANK(AY37,AY$7:AY$68,1))) -> 0 | BE37: =+IF(AD$71=0,0,IF(AD$71<0,-RANK(AZ37,AZ$7:AZ$68,0),RANK(AZ37,AZ$7:AZ$68,1))) -> 0 | BF37: =+IF(AE$71=0,0,IF(AE$71<0,-RANK(BA37,BA$7:BA$68,0),RANK(BA37,BA$7:BA$68,1))) -> 0 | BG37: =+IF(AF$71=0,0,IF(AF$71<0,-RANK(BB37,BB$7:BB$68,0),RANK(BB37,BB$7:BB$68,1))) -> 0 | BH37: =+IF(AG$71=0,0,IF(AG$71<0,-RANK(BC37,BC$7:BC$68,0),RANK(BC37,BC$7:BC$68,1))) -> 0
A38: 4 | C38: 482042900 | D38: 浄化槽 | E38: =+SUMIFS([1]全伝票!I:I,[1]全伝票!$C:$C,$C38,[1]全伝票!$A:$A,$A38) -> 0 | F38: =+SUMIFS([1]全伝票!J:J,[1]全伝票!$C:$C,$C38) -> 0 | G38: =+SUMIFS([1]全伝票!K:K,[1]全伝票!$C:$C,$C38) -> 0 | H38: =+SUMIFS([1]全伝票!L:L,[1]全伝票!$C:$C,$C38) -> 0 | I38: =+SUMIFS([1]全伝票!M:M,[1]全伝票!$C:$C,$C38) -> 0 | J38: =+SUMIFS([1]全伝票!N:N,[1]全伝票!$C:$C,$C38) -> 0 | K38: =SUM(F38:J38) -> 0 | L38: =+SUMIFS([1]全伝票!O:O,[1]全伝票!$C:$C,$C38) -> 0 | P38: ='[3]3条災害補助'!L$51 -> 0 | Q38: ='[3]3条災害補助'!M$51 -> 0 | R38: ='[3]3条災害補助'!N$51 -> 0 | S38: =SUM(N38:R38) -> 0 | T38: ='[3]3条災害補助'!I$50 -> 0 | U38: =+V38-SUM(S38:T38) -> 0 | V38: =SUMIFS([1]全伝票!P:P,[1]全伝票!$C:$C,$C38,[1]全伝票!$A:$A,$A38) -> 0 | W38: =+ROUND(F38*F$6/(100+F$6),0)+AT38 -> 0 | X38: =+ROUND(G38*G$6/(100+G$6),0)+AU38 -> 0 | Y38: =+ROUND(H38*H$6/(100+H$6),0)+AV38 -> 0 | Z38: =+ROUND(I38*I$6/(100+I$6),0)+AW38 -> 0 | AA38: =+ROUND(J38*J$6/(100+J$6),0)+AX38 -> 0 | AB38: =SUM(W38:AA38) -> 0 | AC38: =+ROUND(N38*AC$6/(100+AC$6),0)+BI38 -> 0 | AD38: =+ROUND(O38*AD$6/(100+AD$6),0)+BJ38 -> 0 | AE38: =+ROUND(P38*AE$6/(100+AE$6),0)+BK38 -> 0 | AF38: =+ROUND(Q38*AF$6/(100+AF$6),0)+BL38 -> 0 | AG38: =+ROUND(R38*AG$6/(100+AG$6),0)+BM38 -> 0 | AH38: =SUM(AC38:AG38) -> 0 | AI38: =+E38-AB38 -> 0 | AY38: =AC38-N38*AC$6/(100+AC$6) -> 0 | AZ38: =AD38-O38*AD$6/(100+AD$6) -> 0 | BA38: =AE38-P38*AE$6/(100+AE$6) -> 0 | BB38: =AF38-Q38*AF$6/(100+AF$6) -> 0 | BC38: =AG38-R38*AG$6/(100+AG$6) -> 0 | BD38: =+IF(AC$71=0,0,IF(AC$71<0,-RANK(AY38,AY$7:AY$68,0),RANK(AY38,AY$7:AY$68,1))) -> 0 | BE38: =+IF(AD$71=0,0,IF(AD$71<0,-RANK(AZ38,AZ$7:AZ$68,0),RANK(AZ38,AZ$7:AZ$68,1))) -> 0 | BF38: =+IF(AE$71=0,0,IF(AE$71<0,-RANK(BA38,BA$7:BA$68,0),RANK(BA38,BA$7:BA$68,1))) -> 0 | BG38: =+IF(AF$71=0,0,IF(AF$71<0,-RANK(BB38,BB$7:BB$68,0),RANK(BB38,BB$7:BB$68,1))) -> 0 | BH38: =+IF(AG$71=0,0,IF(AG$71<0,-RANK(BC38,BC$7:BC$68,0),RANK(BC38,BC$7:BC$68,1))) -> 0
D39: 負担金 | E39: =+SUM(E40:E41) -> 53493193 | F39: =+SUM(F40:F41) -> 0 | G39: =+SUM(G40:G41) -> 0 | H39: =+SUM(H40:H41) -> 0 | I39: =+SUM(I40:I41) -> 0 | J39: =+SUM(J40:J41) -> 37016600 | K39: =+SUM(K40:K41) -> 37016600 | L39: =+SUM(L40:L41) -> 0 | ... AI39: =+SUM(AI40:AI41) -> 50128048
C40: 482093200 | D40: 施設管理負担金 | E40: =+SUMIFS([1]全伝票!I:I,[1]全伝票!$C:$C,$C40) -> 37016600 | F40: =+SUMIFS([1]全伝票!J:J,[1]全伝票!$C:$C,$C40) -> 0 | G40: =+SUMIFS([1]全伝票!K:K,[1]全伝票!$C:$C,$C40) -> 0 | H40: =+SUMIFS([1]全伝票!L:L,[1]全伝票!$C:$C,$C40) -> 0 | I40: =+SUMIFS([1]全伝票!M:M,[1]全伝票!$C:$C,$C40) -> 0 | J40: =+SUMIFS([1]全伝票!N:N,[1]全伝票!$C:$C,$C40) -> 37016600 | K40: =SUM(F40:J40) -> 37016600 | L40: =+SUMIFS([1]全伝票!O:O,[1]全伝票!$C:$C,$C40) -> 0 | S40: =SUM(N40:R40) -> 0 | U40: =+V40-SUM(S40:T40) -> 0 | V40: =+SUMIFS([1]全伝票!P:P,[1]全伝票!$C:$C,$C40) -> 0 | W40: =+ROUND(F40*F$6/(100+F$6),0)+AT40 -> 0 | X40: =+ROUND(G40*G$6/(100+G$6),0)+AU40 -> 0 | Y40: =+ROUND(H40*H$6/(100+H$6),0)+AV40 -> 0 | Z40: =+ROUND(I40*I$6/(100+I$6),0)+AW40 -> 0 | AA40: =+ROUND(J40*J$6/(100+J$6),0)+AX40 -> 3365145 | AB40: =SUM(W40:AA40) -> 3365145 | AC40: =+ROUND(N40*AC$6/(100+AC$6),0)+BI40 -> 0 | AD40: =+ROUND(O40*AD$6/(100+AD$6),0)+BJ40 -> 0 | AE40: =+ROUND(P40*AE$6/(100+AE$6),0)+BK40 -> 0 | AF40: =+ROUND(Q40*AF$6/(100+AF$6),0)+BL40 -> 0 | AG40: =+ROUND(R40*AG$6/(100+AG$6),0)+BM40 -> 0 | AH40: =SUM(AC40:AG40) -> 0 | AI40: =+E40-AB40 -> 33651455 | AJ40: =W40-F40*W$6/(100+W$6) -> 0 | AK40: =X40-G40*X$6/(100+X$6) -> 0 | AL40: =Y40-H40*Y$6/(100+Y$6) -> 0 | AM40: =Z40-I40*Z$6/(100+Z$6) -> 0 | AN40: =AA40-J40*AA$6/(100+AA$6) -> -0.45454545 | AO40: =+IF(W$71=0,0,IF(W$71<0,-RANK(AJ40,AJ$7:AJ$68,0),RANK(AJ40,AJ$7:AJ$68,1))) -> 0 | AP40: =+IF(X$71=0,0,IF(X$71<0,-RANK(AK40,AK$7:AK$68,0),RANK(AK40,AK$7:AK$68,1))) -> 0 | AQ40: =+IF(Y$71=0,0,IF(Y$71<0,-RANK(AL40,AL$7:AL$68,0),RANK(AL40,AL$7:AL$68,1))) -> 0 | AR40: =+IF(Z$71=0,0,IF(Z$71<0,-RANK(AM40,AM$7:AM$68,0),RANK(AM40,AM$7:AM$68,1))) -> 0 | AS40: =+IF(AA$71=0,0,IF(AA$71<0,-RANK(AN40,AN$7:AN$68,0),RANK(AN40,AN$7:AN$68,1))) -> 0 | AY40: =AC40-N40*AC$6/(100+AC$6) -> 0 | AZ40: =AD40-O40*AD$6/(100+AD$6) -> 0 | BA40: =AE40-P40*AE$6/(100+AE$6) -> 0 | BB40: =AF40-Q40*AF$6/(100+AF$6) -> 0 | BC40: =AG40-R40*AG$6/(100+AG$6) -> 0 | BD40: =+IF(AC$71=0,0,IF(AC$71<0,-RANK(AY40,AY$7:AY$68,0),RANK(AY40,AY$7:AY$68,1))) -> 0 | BE40: =+IF(AD$71=0,0,IF(AD$71<0,-RANK(AZ40,AZ$7:AZ$68,0),RANK(AZ40,AZ$7:AZ$68,1))) -> 0 | BF40: =+IF(AE$71=0,0,IF(AE$71<0,-RANK(BA40,BA$7:BA$68,0),RANK(BA40,BA$7:BA$68,1))) -> 0 | BG40: =+IF(AF$71=0,0,IF(AF$71<0,-RANK(BB40,BB$7:BB$68,0),RANK(BB40,BB$7:BB$68,1))) -> 0 | BH40: =+IF(AG$71=0,0,IF(AG$71<0,-RANK(BC40,BC$7:BC$68,0),RANK(BC40,BC$7:BC$68,1))) -> 0
...
