Workbook

Sheet 4条支出
D1: =+'[1]3条支出'!$D$1 -> 令和５年度決算 消費税算出資料
D2: 【４条支出総括】
A3: 事業 | B3: 節 | C3: 細節 | D3: 費目 | E3: 税込決算額 | F3: 課税支出 | L3: 非課税支出 | M3: 不課税支出 | N3: 消費税 | T3: 税抜決算額 | U3: 消費税 端数確認 | Z3: 消費税端数調整ランク | AE3: 消費税 調整額
F4: 3 | G4: 5 | H4: 8 | I4: 8 | J4: 10 | K4: 計 | N4: 3 | O4: 5 | P4: 8 | Q4: 8 | R4: 10 | S4: 計 | U4: 3 | V4: 5 | W4: 8 | X4: 8 | Y4: 10 | Z4: 3 | AA4: 5 | AB4: 8 | AC4: 8 | AD4: 10 | AE4: 3 | AF4: 5 | AG4: 8 | AH4: 8 | AI4: 10
D5: 建設改良費 | E5: =+SUM(E6:E11,E15:E16) -> 17250555070 | F5: =+SUM(F6:F11,F15:F16) -> 0 | G5: =+SUM(G6:G11,G15:G16) -> 0 | H5: =+SUM(H6:H11,H15:H16) -> 125712 | I5: =+SUM(I6:I11,I15:I16) -> 36840 | J5: =+SUM(J6:J11,J15:J16) -> 16278736624 | K5: =+SUM(K6:K11,K15:K16) -> 16278899176 | L5: =+SUM(L6:L11,L15:L16) -> 164380201 | ... T5: =+SUM(T6:T11,T15:T16) -> 15770657883
D6: 公共下水道整備費 | E6: =+公整!E41 -> 15677649564 | F6: =+公整!F41 -> 0 | G6: =+公整!G41 -> 0 | H6: =+公整!H41 -> 125712 | I6: =+公整!I41 -> 36840 | J6: =+公整!J41 -> 14917070964 | K6: =+公整!K41 -> 14917233516 | L6: =+公整!L41 -> 120272797 | M6: =+公整!M41 -> 640143251 | N6: =+ROUND(F6*F$4/(100+F$4),0)+AE6 -> 0 | O6: =+ROUND(G6*G$4/(100+G$4),0)+AF6 -> 0 | P6: =+ROUND(H6*H$4/(100+H$4),0)+AG6 -> 9312 | Q6: =+ROUND(I6*I$4/(100+I$4),0)+AH6 -> 2728 | R6: =+ROUND(J6*J$4/(100+J$4),0)+AI6 -> 1356097360 | S6: =SUM(N6:R6) -> 1356109400 | T6: =+E6-S6 -> 14321540164 | U6: =N6-F6*F$4/(100+F$4) -> 0 | V6: =O6-G6*G$4/(100+G$4) -> 0 | W6: =P6-H6*H$4/(100+H$4) -> 0 | X6: =Q6-I6*I$4/(100+I$4) -> -0.88888889 | Y6: =R6-J6*J$4/(100+J$4) -> -0.36363626 | Z6: =+IF(N$43=0,0,IF(N$43<0,-RANK(U6,U$5:U$40,0),RANK(U6,U$5:U$40,1))) -> 0 | AA6: =+IF(O$43=0,0,IF(O$43<0,-RANK(V6,V$5:V$40,0),RANK(V6,V$5:V$40,1))) -> 0 | AB6: =+IF(P$43=0,0,IF(P$43<0,-RANK(W6,W$5:W$40,0),RANK(W6,W$5:W$40,1))) -> 0 | AC6: =+IF(Q$43=0,0,IF(Q$43<0,-RANK(X6,X$5:X$40,0),RANK(X6,X$5:X$40,1))) -> 0 | AD6: =+IF(R$43=0,0,IF(R$43<0,-RANK(Y6,Y$5:Y$40,0),RANK(Y6,Y$5:Y$40,1))) -> 0 | AH6: -1
D7: 受益者負担金業務費 | E7: =+受益!E41 -> 15860357 | F7: =+受益!F41 -> 0 | G7: =+受益!G41 -> 0 | H7: =+受益!H41 -> 0 | I7: =+受益!I41 -> 0 | J7: =+受益!J41 -> 5973775 | K7: =+受益!K41 -> 5973775 | L7: =+受益!L41 -> 1647233 | M7: =+受益!M41 -> 8239349 | N7: =+ROUND(F7*F$4/(100+F$4),0)+AE7 -> 0 | O7: =+ROUND(G7*G$4/(100+G$4),0)+AF7 -> 0 | P7: =+ROUND(H7*H$4/(100+H$4),0)+AG7 -> 0 | Q7: =+ROUND(I7*I$4/(100+I$4),0)+AH7 -> 0 | R7: =+ROUND(J7*J$4/(100+J$4),0)+AI7 -> 543071 | S7: =SUM(N7:R7) -> 543071 | T7: =+E7-S7 -> 15317286 | U7: =N7-F7*F$4/(100+F$4) -> 0 | V7: =O7-G7*G$4/(100+G$4) -> 0 | W7: =P7-H7*H$4/(100+H$4) -> 0 | X7: =Q7-I7*I$4/(100+I$4) -> 0 | Y7: =R7-J7*J$4/(100+J$4) -> 0.54545455 | Z7: =+IF(N$43=0,0,IF(N$43<0,-RANK(U7,U$5:U$40,0),RANK(U7,U$5:U$40,1))) -> 0 | AA7: =+IF(O$43=0,0,IF(O$43<0,-RANK(V7,V$5:V$40,0),RANK(V7,V$5:V$40,1))) -> 0 | AB7: =+IF(P$43=0,0,IF(P$43<0,-RANK(W7,W$5:W$40,0),RANK(W7,W$5:W$40,1))) -> 0 | AC7: =+IF(Q$43=0,0,IF(Q$43<0,-RANK(X7,X$5:X$40,0),RANK(X7,X$5:X$40,1))) -> 0 | AD7: =+IF(R$43=0,0,IF(R$43<0,-RANK(Y7,Y$5:Y$40,0),RANK(Y7,Y$5:Y$40,1))) -> 0 | AI7: 1
D8: 排水設備整備費 | E8: =+排水!E41 -> 665100151 | F8: =+排水!F41 -> 0 | G8: =+排水!G41 -> 0 | H8: =+排水!H41 -> 0 | I8: =+排水!I41 -> 0 | J8: =+排水!J41 -> 518619849 | K8: =+排水!K41 -> 518619849 | L8: =+排水!L41 -> 24850691 | M8: =+排水!M41 -> 121629611 | N8: =+ROUND(F8*F$4/(100+F$4),0)+AE8 -> 0 | O8: =+ROUND(G8*G$4/(100+G$4),0)+AF8 -> 0 | P8: =+ROUND(H8*H$4/(100+H$4),0)+AG8 -> 0 | Q8: =+ROUND(I8*I$4/(100+I$4),0)+AH8 -> 0 | R8: =+ROUND(J8*J$4/(100+J$4),0)+AI8 -> 47147259 | S8: =SUM(N8:R8) -> 47147259 | T8: =+E8-S8 -> 617952892 | U8: =N8-F8*F$4/(100+F$4) -> 0 | V8: =O8-G8*G$4/(100+G$4) -> 0 | W8: =P8-H8*H$4/(100+H$4) -> 0 | X8: =Q8-I8*I$4/(100+I$4) -> 0 | Y8: =R8-J8*J$4/(100+J$4) -> 0 | Z8: =+IF(N$43=0,0,IF(N$43<0,-RANK(U8,U$5:U$40,0),RANK(U8,U$5:U$40,1))) -> 0 | AA8: =+IF(O$43=0,0,IF(O$43<0,-RANK(V8,V$5:V$40,0),RANK(V8,V$5:V$40,1))) -> 0 | AB8: =+IF(P$43=0,0,IF(P$43<0,-RANK(W8,W$5:W$40,0),RANK(W8,W$5:W$40,1))) -> 0 | AC8: =+IF(Q$43=0,0,IF(Q$43<0,-RANK(X8,X$5:X$40,0),RANK(X8,X$5:X$40,1))) -> 0 | AD8: =+IF(R$43=0,0,IF(R$43<0,-RANK(Y8,Y$5:Y$40,0),RANK(Y8,Y$5:Y$40,1))) -> 0
D9: 都市下水路整備費 | E9: =+都下!E41 -> 0 | F9: =+都下!F41 -> 0 | G9: =+都下!G41 -> 0 | H9: =+都下!H41 -> 0 | I9: =+都下!I41 -> 0 | J9: =+都下!J41 -> 0 | K9: =+都下!K41 -> 0 | L9: =+都下!L41 -> 0 | M9: =+都下!M41 -> 0 | N9: =+ROUND(F9*F$4/(100+F$4),0)+AE9 -> 0 | O9: =+ROUND(G9*G$4/(100+G$4),0)+AF9 -> 0 | P9: =+ROUND(H9*H$4/(100+H$4),0)+AG9 -> 0 | Q9: =+ROUND(I9*I$4/(100+I$4),0)+AH9 -> 0 | R9: =+ROUND(J9*J$4/(100+J$4),0)+AI9 -> 0 | S9: =SUM(N9:R9) -> 0 | T9: =+E9-S9 -> 0 | U9: =N9-F9*F$4/(100+F$4) -> 0 | V9: =O9-G9*G$4/(100+G$4) -> 0 | W9: =P9-H9*H$4/(100+H$4) -> 0 | X9: =Q9-I9*I$4/(100+I$4) -> 0 | Y9: =R9-J9*J$4/(100+J$4) -> 0 | Z9: =+IF(N$43=0,0,IF(N$43<0,-RANK(U9,U$5:U$40,0),RANK(U9,U$5:U$40,1))) -> 0 | AA9: =+IF(O$43=0,0,IF(O$43<0,-RANK(V9,V$5:V$40,0),RANK(V9,V$5:V$40,1))) -> 0 | AB9: =+IF(P$43=0,0,IF(P$43<0,-RANK(W9,W$5:W$40,0),RANK(W9,W$5:W$40,1))) -> 0 | AC9: =+IF(Q$43=0,0,IF(Q$43<0,-RANK(X9,X$5:X$40,0),RANK(X9,X$5:X$40,1))) -> 0 | AD9: =+IF(R$43=0,0,IF(R$43<0,-RANK(Y9,Y$5:Y$40,0),RANK(Y9,Y$5:Y$40,1))) -> 0
D10: 流域下水道整備費 | E10: =+流下!E41 -> 131921564 | F10: =+流下!F41 -> 0 | G10: =+流下!G41 -> 0 | H10: =+流下!H41 -> 0 | I10: =+流下!I41 -> 0 | J10: =+流下!J41 -> 121228564 | K10: =+流下!K41 -> 121228564 | L10: =+流下!L41 -> 0 | M10: =+流下!M41 -> 10693000 | N10: =+ROUND(F10*F$4/(100+F$4),0)+AE10 -> 0 | O10: =+ROUND(G10*G$4/(100+G$4),0)+AF10 -> 0 | P10: =+ROUND(H10*H$4/(100+H$4),0)+AG10 -> 0 | Q10: =+ROUND(I10*I$4/(100+I$4),0)+AH10 -> 0 | R10: =+ROUND(J10*J$4/(100+J$4),0)+AI10 -> 11020779 | S10: =SUM(N10:R10) -> 11020779 | T10: =+E10-S10 -> 120900785 | U10: =N10-F10*F$4/(100+F$4) -> 0 | V10: =O10-G10*G$4/(100+G$4) -> 0 | W10: =P10-H10*H$4/(100+H$4) -> 0 | X10: =Q10-I10*I$4/(100+I$4) -> 0 | Y10: =R10-J10*J$4/(100+J$4) -> 0.45454546 | Z10: =+IF(N$43=0,0,IF(N$43<0,-RANK(U10,U$5:U$40,0),RANK(U10,U$5:U$40,1))) -> 0 | AA10: =+IF(O$43=0,0,IF(O$43<0,-RANK(V10,V$5:V$40,0),RANK(V10,V$5:V$40,1))) -> 0 | AB10: =+IF(P$43=0,0,IF(P$43<0,-RANK(W10,W$5:W$40,0),RANK(W10,W$5:W$40,1))) -> 0 | AC10: =+IF(Q$43=0,0,IF(Q$43<0,-RANK(X10,X$5:X$40,0),RANK(X10,X$5:X$40,1))) -> 0 | AD10: =+IF(R$43=0,0,IF(R$43<0,-RANK(Y10,Y$5:Y$40,0),RANK(Y10,Y$5:Y$40,1))) -> 0
D11: 諸設備新設改良費 | E11: =+SUM(E12:E14) -> 59178010 | F11: =+SUM(F12:F14) -> 0 | G11: =+SUM(G12:G14) -> 0 | H11: =+SUM(H12:H14) -> 0 | I11: =+SUM(I12:I14) -> 0 | J11: =+SUM(J12:J14) -> 59178010 | K11: =+SUM(K12:K14) -> 59178010 | L11: =+SUM(L12:L14) -> 0 | ... R11: =+SUM(R12:R14) -> 5379819 | S11: =SUM(N11:R11) -> 5379819 | T11: =+E11-S11 -> 53798191
D12: 公共 | E12: =+諸公!E41 -> 59178010 | F12: =+諸公!F41 -> 0 | G12: =+諸公!G41 -> 0 | H12: =+諸公!H41 -> 0 | I12: =+諸公!I41 -> 0 | J12: =+諸公!J41 -> 59178010 | K12: =+諸公!K41 -> 59178010 | L12: =+諸公!L41 -> 0 | M12: =+諸公!M41 -> 0 | N12: =+ROUND(F12*F$4/(100+F$4),0)+AE12 -> 0 | O12: =+ROUND(G12*G$4/(100+G$4),0)+AF12 -> 0 | P12: =+ROUND(H12*H$4/(100+H$4),0)+AG12 -> 0 | Q12: =+ROUND(I12*I$4/(100+I$4),0)+AH12 -> 0 | R12: =+ROUND(J12*J$4/(100+J$4),0)+AI12 -> 5379819 | S12: =SUM(N12:R12) -> 5379819 | T12: =+E12-S12 -> 53798191 | U12: =N12-F12*F$4/(100+F$4) -> 0 | V12: =O12-G12*G$4/(100+G$4) -> 0 | W12: =P12-H12*H$4/(100+H$4) -> 0 | X12: =Q12-I12*I$4/(100+I$4) -> 0 | Y12: =R12-J12*J$4/(100+J$4) -> -0.090909091 | Z12: =+IF(N$43=0,0,IF(N$43<0,-RANK(U12,U$5:U$40,0),RANK(U12,U$5:U$40,1))) -> 0 | AA12: =+IF(O$43=0,0,IF(O$43<0,-RANK(V12,V$5:V$40,0),RANK(V12,V$5:V$40,1))) -> 0 | AB12: =+IF(P$43=0,0,IF(P$43<0,-RANK(W12,W$5:W$40,0),RANK(W12,W$5:W$40,1))) -> 0 | AC12: =+IF(Q$43=0,0,IF(Q$43<0,-RANK(X12,X$5:X$40,0),RANK(X12,X$5:X$40,1))) -> 0 | AD12: =+IF(R$43=0,0,IF(R$43<0,-RANK(Y12,Y$5:Y$40,0),RANK(Y12,Y$5:Y$40,1))) -> 0
D13: 特環 | E13: =+諸特!E41 -> 0 | F13: =+諸特!F41 -> 0 | G13: =+諸特!G41 -> 0 | H13: =+諸特!H41 -> 0 | I13: =+諸特!I41 -> 0 | J13: =+諸特!J41 -> 0 | K13: =+諸特!K41 -> 0 | L13: =+諸特!L41 -> 0 | M13: =+諸特!M41 -> 0 | N13: =+ROUND(F13*F$4/(100+F$4),0)+AE13 -> 0 | O13: =+ROUND(G13*G$4/(100+G$4),0)+AF13 -> 0 | P13: =+ROUND(H13*H$4/(100+H$4),0)+AG13 -> 0 | Q13: =+ROUND(I13*I$4/(100+I$4),0)+AH13 -> 0 | R13: =+ROUND(J13*J$4/(100+J$4),0)+AI13 -> 0 | S13: =SUM(N13:R13) -> 0 | T13: =+E13-S13 -> 0
D14: 農集 | E14: =+諸農!E41 -> 0 | F14: =+諸農!F41 -> 0 | G14: =+諸農!G41 -> 0 | H14: =+諸農!H41 -> 0 | I14: =+諸農!I41 -> 0 | J14: =+諸農!J41 -> 0 | K14: =+諸農!K41 -> 0 | L14: =+諸農!L41 -> 0 | M14: =+諸農!M41 -> 0 | N14: =+ROUND(F14*F$4/(100+F$4),0)+AE14 -> 0 | O14: =+ROUND(G14*G$4/(100+G$4),0)+AF14 -> 0 | P14: =+ROUND(H14*H$4/(100+H$4),0)+AG14 -> 0 | Q14: =+ROUND(I14*I$4/(100+I$4),0)+AH14 -> 0 | R14: =+ROUND(J14*J$4/(100+J$4),0)+AI14 -> 0 | S14: =SUM(N14:R14) -> 0 | T14: =+E14-S14 -> 0
D15: 建設利息 | E15: =+建利!E41 -> 12600000 | F15: =+建利!F41 -> 0 | G15: =+建利!G41 -> 0 | H15: =+建利!H41 -> 0 | I15: =+建利!I41 -> 0 | J15: =+建利!J41 -> 0 | K15: =+建利!K41 -> 0 | L15: =+建利!L41 -> 12600000 | M15: =+建利!M41 -> 0 | N15: =+ROUND(F15*F$4/(100+F$4),0)+AE15 -> 0 | O15: =+ROUND(G15*G$4/(100+G$4),0)+AF15 -> 0 | P15: =+ROUND(H15*H$4/(100+H$4),0)+AG15 -> 0 | Q15: =+ROUND(I15*I$4/(100+I$4),0)+AH15 -> 0 | R15: =+ROUND(J15*J$4/(100+J$4),0)+AI15 -> 0 | S15: =SUM(N15:R15) -> 0 | T15: =+E15-S15 -> 12600000
D16: 市街化区域外整備費 | E16: =+SUM(E17:E19) -> 688245424 | F16: =+SUM(F17:F19) -> 0 | G16: =+SUM(G17:G19) -> 0 | H16: =+SUM(H17:H19) -> 0 | I16: =+SUM(I17:I19) -> 0 | J16: =+SUM(J17:J19) -> 656665462 | K16: =+SUM(K17:K19) -> 656665462 | L16: =+SUM(L17:L19) -> 5009480 | ... R16: =+SUM(R17:R19) -> 59696859 | S16: =SUM(N16:R16) -> 59696859 | T16: =+SUM(T17:T19) -> 628548565
D17: 特環 | E17: =+特整!E41 -> 453738774 | F17: =+特整!F41 -> 0 | G17: =+特整!G41 -> 0 | H17: =+特整!H41 -> 0 | I17: =+特整!I41 -> 0 | J17: =+特整!J41 -> 440688000 | K17: =+特整!K41 -> 440688000 | L17: =+特整!L41 -> 1712617 | M17: =+特整!M41 -> 11338157 | N17: =+ROUND(F17*F$4/(100+F$4),0)+AE17 -> 0 | O17: =+ROUND(G17*G$4/(100+G$4),0)+AF17 -> 0 | P17: =+ROUND(H17*H$4/(100+H$4),0)+AG17 -> 0 | Q17: =+ROUND(I17*I$4/(100+I$4),0)+AH17 -> 0 | R17: =+ROUND(J17*J$4/(100+J$4),0)+AI17 -> 40062545 | S17: =SUM(N17:R17) -> 40062545 | T17: =+E17-S17 -> 413676229
D18: 農集 | E18: =+農整!E41 -> 146106803 | F18: =+農整!F41 -> 0 | G18: =+農整!G41 -> 0 | H18: =+農整!H41 -> 0 | I18: =+農整!I41 -> 0 | J18: =+農整!J41 -> 136580009 | K18: =+農整!K41 -> 136580009 | L18: =+農整!L41 -> 1942679 | M18: =+農整!M41 -> 7584115 | N18: =+ROUND(F18*F$4/(100+F$4),0)+AE18 -> 0 | O18: =+ROUND(G18*G$4/(100+G$4),0)+AF18 -> 0 | P18: =+ROUND(H18*H$4/(100+H$4),0)+AG18 -> 0 | Q18: =+ROUND(I18*I$4/(100+I$4),0)+AH18 -> 0 | R18: =+ROUND(J18*J$4/(100+J$4),0)+AI18 -> 12416364 | S18: =SUM(N18:R18) -> 12416364 | T18: =+E18-S18 -> 133690439
D19: 浄化槽 | E19: =+浄整!E41 -> 88399847 | F19: =+浄整!F41 -> 0 | G19: =+浄整!G41 -> 0 | H19: =+浄整!H41 -> 0 | I19: =+浄整!I41 -> 0 | J19: =+浄整!J41 -> 79397453 | K19: =+浄整!K41 -> 79397453 | L19: =+浄整!L41 -> 1354184 | M19: =+浄整!M41 -> 7648210 | N19: =+ROUND(F19*F$4/(100+F$4),0)+AE19 -> 0 | O19: =+ROUND(G19*G$4/(100+G$4),0)+AF19 -> 0 | P19: =+ROUND(H19*H$4/(100+H$4),0)+AG19 -> 0 | Q19: =+ROUND(I19*I$4/(100+I$4),0)+AH19 -> 0 | R19: =+ROUND(J19*J$4/(100+J$4),0)+AI19 -> 7217950 | S19: =SUM(N19:R19) -> 7217950 | T19: =+E19-S19 -> 81181897
D21: 企業債償還金 | E21: =+償還!E41 -> 44621240467 | F21: =+償還!F41 -> 0 | G21: =+償還!G41 -> 0 | H21: =+償還!H41 -> 0 | I21: =+償還!I41 -> 0 | J21: =+償還!J41 -> 0 | K21: =+償還!K41 -> 0 | L21: =+償還!L41 -> 0 | M21: =+償還!M41 -> 44621240467 | N21: =+ROUND(F21*F$4/(100+F$4),0)+AE21 -> 0 | O21: =+ROUND(G21*G$4/(100+G$4),0)+AF21 -> 0 | P21: =+ROUND(H21*H$4/(100+H$4),0)+AG21 -> 0 | Q21: =+ROUND(I21*I$4/(100+I$4),0)+AH21 -> 0 | R21: =+ROUND(J21*J$4/(100+J$4),0)+AI21 -> 0 | S21: =SUM(N21:R21) -> 0 | T21: =+E21-S21 -> 44621240467
S22: =SUM(N22:R22) -> 0 | T22: =+E22-S22 -> 0
D23: 水洗化貸付事業費 | E23: =+SUM(E24:E26) -> 4182000 | F23: =+SUM(F24:F26) -> 0 | G23: =+SUM(G24:G26) -> 0 | H23: =+SUM(H24:H26) -> 0 | I23: =+SUM(I24:I26) -> 0 | J23: =+SUM(J24:J26) -> 0 | K23: =+SUM(K24:K26) -> 0 | L23: =+SUM(L24:L26) -> 0 | ... R23: =+SUM(R24:R26) -> 0 | S23: =SUM(N23:R23) -> 0 | T23: =+E23-S23 -> 4182000
D24: 貸付金 | E24: =+水洗!E5 -> 3759000 | F24: =+水洗!F5 -> 0 | G24: =+水洗!G5 -> 0 | H24: =+水洗!H5 -> 0 | I24: =+水洗!I5 -> 0 | J24: =+水洗!J5 -> 0 | K24: =+水洗!K5 -> 0 | L24: =+水洗!L5 -> 0 | M24: =+水洗!M5 -> 3759000 | N24: =+ROUND(F24*F$4/(100+F$4),0)+AE24 -> 0 | O24: =+ROUND(G24*G$4/(100+G$4),0)+AF24 -> 0 | P24: =+ROUND(H24*H$4/(100+H$4),0)+AG24 -> 0 | Q24: =+ROUND(I24*I$4/(100+I$4),0)+AH24 -> 0 | R24: =+ROUND(J24*J$4/(100+J$4),0)+AI24 -> 0 | S24: =SUM(N24:R24) -> 0 | T24: =+E24-S24 -> 3759000
D25: 貸付資金企業債償還金 | E25: =+水洗!E24 -> 0 | F25: =+水洗!F24 -> 0 | G25: =+水洗!G24 -> 0 | H25: =+水洗!H24 -> 0 | I25: =+水洗!I24 -> 0 | J25: =+水洗!J24 -> 0 | K25: =+水洗!K24 -> 0 | L25: =+水洗!L24 -> 0 | M25: =+水洗!M24 -> 0 | N25: =+ROUND(F25*F$4/(100+F$4),0)+AE25 -> 0 | O25: =+ROUND(G25*G$4/(100+G$4),0)+AF25 -> 0 | P25: =+ROUND(H25*H$4/(100+H$4),0)+AG25 -> 0 | Q25: =+ROUND(I25*I$4/(100+I$4),0)+AH25 -> 0 | R25: =+ROUND(J25*J$4/(100+J$4),0)+AI25 -> 0 | S25: =SUM(N25:R25) -> 0 | T25: =+E25-S25 -> 0
D26: 一般会計借入金償還金 | E26: =+水洗!E26 -> 423000 | F26: =+水洗!F26 -> 0 | G26: =+水洗!G26 -> 0 | H26: =+水洗!H26 -> 0 | I26: =+水洗!I26 -> 0 | J26: =+水洗!J26 -> 0 | K26: =+水洗!K26 -> 0 | L26: =+水洗!L26 -> 0 | M26: =+水洗!M26 -> 423000 | N26: =+ROUND(F26*F$4/(100+F$4),0)+AE26 -> 0 | O26: =+ROUND(G26*G$4/(100+G$4),0)+AF26 -> 0 | P26: =+ROUND(H26*H$4/(100+H$4),0)+AG26 -> 0 | Q26: =+ROUND(I26*I$4/(100+I$4),0)+AH26 -> 0 | R26: =+ROUND(J26*J$4/(100+J$4),0)+AI26 -> 0 | S26: =SUM(N26:R26) -> 0 | T26: =+E26-S26 -> 423000
D28: 返還金 | E28: =+返還!E28 -> 0 | F28: =+返還!F28 -> 0 | G28: =+返還!G28 -> 0 | H28: =+返還!H28 -> 0 | I28: =+返還!I28 -> 0 | J28: =+返還!J28 -> 0 | K28: =+返還!K28 -> 0 | L28: =+返還!L28 -> 0 | M28: =+返還!M28 -> 0 | N28: =+ROUND(F28*F$4/(100+F$4),0)+AE28 -> 0 | O28: =+ROUND(G28*G$4/(100+G$4),0)+AF28 -> 0 | P28: =+ROUND(H28*H$4/(100+H$4),0)+AG28 -> 0 | Q28: =+ROUND(I28*I$4/(100+I$4),0)+AH28 -> 0 | R28: =+ROUND(J28*J$4/(100+J$4),0)+AI28 -> 0 | S28: =SUM(N28:R28) -> 0 | T28: =+E28-S28 -> 0
D41: 計 | E41: =SUM(E5,E21,E23,E28) -> 61875977537 | F41: =SUM(F5,F21,F23,F28) -> 0 | G41: =SUM(G5,G21,G23,G28) -> 0 | H41: =SUM(H5,H21,H23,H28) -> 125712 | I41: =SUM(I5,I21,I23,I28) -> 36840 | J41: =SUM(J5,J21,J23,J28) -> 16278736624 | K41: =SUM(K5,K21,K23,K28) -> 16278899176 | L41: =SUM(L5,L21,L23,L28) -> 164380201 | ... T41: =SUM(T5,T21,T23,T28) -> 60396080350
D42: 総額検算 | E42: =+E41 -> 61875977537 | F42: =+F41 -> 0 | G42: =+G41 -> 0 | H42: =+H41 -> 125712 | I42: =+I41 -> 36840 | J42: =+J41 -> 16278736624 | K42: =+K41 -> 16278899176 | L42: =+L41 -> 164380201 | M42: =+M41 -> 45432698160 | N42: =+ROUNDDOWN(F42*F$4/(100+F$4),0) -> 0 | O42: =+ROUNDDOWN(G42*G$4/(100+G$4),0) -> 0 | P42: =+ROUNDDOWN(H42*H$4/(100+H$4),0) -> 9312 | Q42: =+ROUNDDOWN(I42*I$4/(100+I$4),0) -> 2728 | R42: =+ROUNDDOWN(J42*J$4/(100+J$4),0) -> 1479885147 | S42: =SUM(N42:R42) -> 1479897187 | T42: =+E42-S42 -> 60396080350
E43: =+E42-E41 -> 0 | F43: =+F42-F41 -> 0 | G43: =+G42-G41 -> 0 | H43: =+H42-H41 -> 0 | I43: =+I42-I41 -> 0 | J43: =+J42-J41 -> 0 | K43: =+K42-K41 -> 0 | L43: =+L42-L41 -> 0 | ... T43: =+T42-T41 -> 0

Sheet 公整
D1: =+'4条支出'!D1 -> 令和５年度決算 消費税算出資料
D2: 【公共下水道整備費】
A3: 事業 | B3: 節 | C3: 細節 | D3: 費目 | E3: 税込決算額 | F3: 課税支出 | L3: 非課税支出 | M3: 不課税支出 | N3: 消費税 | T3: 税抜決算額 | U3: 消費税 端数確認 | Z3: 消費税端数調整ランク | AE3: 消費税 調整額
F4: 3 | G4: 5 | H4: 8 | I4: 8 | J4: 10 | K4: 計 | N4: 3 | O4: 5 | P4: 8 | Q4: 8 | R4: 10 | S4: 計 | U4: 3 | V4: 5 | W4: 8 | X4: 8 | Y4: 10 | Z4: 3 | AA4: 5 | AB4: 8 | AC4: 8 | AD4: 10 | AE4: 3 | AF4: 5 | AG4: 8 | AH4: 8 | AI4: 10
A5: 1 | B5: 6153201 | D5: 報酬 | E5: =+IF($A5="",IF($C5="",SUMIFS([1]全伝票!I:I,[1]全伝票!$B:$B,$B5),SUMIFS([1]全伝票!I:I,[1]全伝票!$C:$C,$C5)),IF($C5="",SUMIFS([1]全伝票!I:I,[1]全伝票!$A:$A,$A5,[1]全伝票!$B:$B,$B5),SUMIFS([1]全伝票!I:I,[1]全伝票!$A:$A,$A5,[1]全伝票!$C:$C,$C5))) -> 13722776 | F5: =+IF($A5="",IF($C5="",SUMIFS([1]全伝票!J:J,[1]全伝票!$B:$B,$B5),SUMIFS([1]全伝票!J:J,[1]全伝票!$C:$C,$C5)),IF($C5="",SUMIFS([1]全伝票!J:J,[1]全伝票!$A:$A,$A5,[1]全伝票!$B:$B,$B5),SUMIFS([1]全伝票!J:J,[1]全伝票!$A:$A,$A5,[1]全伝票!$C:$C,$C5))) -> 0 | G5: =+IF($A5="",IF($C5="",SUMIFS([1]全伝票!K:K,[1]全伝票!$B:$B,$B5),SUMIFS([1]全伝票!K:K,[1]全伝票!$C:$C,$C5)),IF($C5="",SUMIFS([1]全伝票!K:K,[1]全伝票!$A:$A,$A5,[1]全伝票!$B:$B,$B5),SUMIFS([1]全伝票!K:K,[1]全伝票!$A:$A,$A5,[1]全伝票!$C:$C,$C5))) -> 0 | H5: =+IF($A5="",IF($C5="",SUMIFS([1]全伝票!L:L,[1]全伝票!$B:$B,$B5),SUMIFS([1]全伝票!L:L,[1]全伝票!$C:$C,$C5)),IF($C5="",SUMIFS([1]全伝票!L:L,[1]全伝票!$A:$A,$A5,[1]全伝票!$B:$B,$B5),SUMIFS([1]全伝票!L:L,[1]全伝票!$A:$A,$A5,[1]全伝票!$C:$C,$C5))) -> 0 | I5: =+IF($A5="",IF($C5="",SUMIFS([1]全伝票!M:M,[1]全伝票!$B:$B,$B5),SUMIFS([1]全伝票!M:M,[1]全伝票!$C:$C,$C5)),IF($C5="",SUMIFS([1]全伝票!M:M,[1]全伝票!$A:$A,$A5,[1]全伝票!$B:$B,$B5),SUMIFS([1]全伝票!M:M,[1]全伝票!$A:$A,$A5,[1]全伝票!$C:$C,$C5))) -> 0 | J5: =+IF($A5="",IF($C5="",SUMIFS([1]全伝票!N:N,[1]全伝票!$B:$B,$B5),SUMIFS([1]全伝票!N:N,[1]全伝票!$C:$C,$C5)),IF($C5="",SUMIFS([1]全伝票!N:N,[1]全伝票!$A:$A,$A5,[1]全伝票!$B:$B,$B5),SUMIFS([1]全伝票!N:N,[1]全伝票!$A:$A,$A5,[1]全伝票!$C:$C,$C5))) -> 0 | K5: =SUM(F5:J5) -> 0 | L5: =+IF($A5="",IF($C5="",SUMIFS([1]全伝票!O:O,[1]全伝票!$B:$B,$B5),SUMIFS([1]全伝票!O:O,[1]全伝票!$C:$C,$C5)),IF($C5="",SUMIFS([1]全伝票!O:O,[1]全伝票!$A:$A,$A5,[1]全伝票!$B:$B,$B5),SUMIFS([1]全伝票!O:O,[1]全伝票!$A:$A,$A5,[1]全伝票!$C:$C,$C5))) -> 0 | M5: =+IF($A5="",IF($C5="",SUMIFS([1]全伝票!P:P,[1]全伝票!$B:$B,$B5),SUMIFS([1]全伝票!P:P,[1]全伝票!$C:$C,$C5)),IF($C5="",SUMIFS([1]全伝票!P:P,[1]全伝票!$A:$A,$A5,[1]全伝票!$B:$B,$B5),SUMIFS([1]全伝票!P:P,[1]全伝票!$A:$A,$A5,[1]全伝票!$C:$C,$C5))) -> 13722776 | N5: =+ROUND(F5*F$4/(100+F$4),0)+AE5 -> 0 | O5: =+ROUND(G5*G$4/(100+G$4),0)+AF5 -> 0 | P5: =+ROUND(H5*H$4/(100+H$4),0)+AG5 -> 0 | Q5: =+ROUND(I5*I$4/(100+I$4),0)+AH5 -> 0 | R5: =+ROUND(J5*J$4/(100+J$4),0)+AI5 -> 0 | S5: =SUM(N5:R5) -> 0 | T5: =+E5-S5 -> 13722776 | U5: =N5-F5*F$4/(100+F$4) -> 0 | V5: =O5-G5*G$4/(100+G$4) -> 0 | W5: =P5-H5*H$4/(100+H$4) -> 0 | X5: =Q5-I5*I$4/(100+I$4) -> 0 | Y5: =R5-J5*J$4/(100+J$4) -> 0 | Z5: =+IF(N$43=0,0,IF(N$43<0,-RANK(U5,U$5:U$40,0),RANK(U5,U$5:U$40,1))) -> 0 | AA5: =+IF(O$43=0,0,IF(O$43<0,-RANK(V5,V$5:V$40,0),RANK(V5,V$5:V$40,1))) -> 0 | AB5: =+IF(P$43=0,0,IF(P$43<0,-RANK(W5,W$5:W$40,0),RANK(W5,W$5:W$40,1))) -> 0 | AC5: =+IF(Q$43=0,0,IF(Q$43<0,-RANK(X5,X$5:X$40,0),RANK(X5,X$5:X$40,1))) -> 0 | AD5: =+IF(R$43=0,0,IF(R$43<0,-RANK(Y5,Y$5:Y$40,0),RANK(Y5,Y$5:Y$40,1))) -> 0
A6: 1 | B6: 6153202 | D6: 給料 | E6: =+IF($A6="",IF($C6="",SUMIFS([1]全伝票!I:I,[1]全伝票!$B:$B,$B6),SUMIFS([1]全伝票!I:I,[1]全伝票!$C:$C,$C6)),IF($C6="",SUMIFS([1]全伝票!I:I,[1]全伝票!$A:$A,$A6,[1]全伝票!$B:$B,$B6),SUMIFS([1]全伝票!I:I,[1]全伝票!$A:$A,$A6,[1]全伝票!$C:$C,$C6))) -> 285882615 | F6: =+IF($A6="",IF($C6="",SUMIFS([1]全伝票!J:J,[1]全伝票!$B:$B,$B6),SUMIFS([1]全伝票!J:J,[1]全伝票!$C:$C,$C6)),IF($C6="",SUMIFS([1]全伝票!J:J,[1]全伝票!$A:$A,$A6,[1]全伝票!$B:$B,$B6),SUMIFS([1]全伝票!J:J,[1]全伝票!$A:$A,$A6,[1]全伝票!$C:$C,$C6))) -> 0 | G6: =+IF($A6="",IF($C6="",SUMIFS([1]全伝票!K:K,[1]全伝票!$B:$B,$B6),SUMIFS([1]全伝票!K:K,[1]全伝票!$C:$C,$C6)),IF($C6="",SUMIFS([1]全伝票!K:K,[1]全伝票!$A:$A,$A6,[1]全伝票!$B:$B,$B6),SUMIFS([1]全伝票!K:K,[1]全伝票!$A:$A,$A6,[1]全伝票!$C:$C,$C6))) -> 0 | H6: =+IF($A6="",IF($C6="",SUMIFS([1]全伝票!L:L,[1]全伝票!$B:$B,$B6),SUMIFS([1]全伝票!L:L,[1]全伝票!$C:$C,$C6)),IF($C6="",SUMIFS([1]全伝票!L:L,[1]全伝票!$A:$A,$A6,[1]全伝票!$B:$B,$B6),SUMIFS([1]全伝票!L:L,[1]全伝票!$A:$A,$A6,[1]全伝票!$C:$C,$C6))) -> 0 | I6: =+IF($A6="",IF($C6="",SUMIFS([1]全伝票!M:M,[1]全伝票!$B:$B,$B6),SUMIFS([1]全伝票!M:M,[1]全伝票!$C:$C,$C6)),IF($C6="",SUMIFS([1]全伝票!M:M,[1]全伝票!$A:$A,$A6,[1]全伝票!$B:$B,$B6),SUMIFS([1]全伝票!M:M,[1]全伝票!$A:$A,$A6,[1]全伝票!$C:$C,$C6))) -> 0 | J6: =+IF($A6="",IF($C6="",SUMIFS([1]全伝票!N:N,[1]全伝票!$B:$B,$B6),SUMIFS([1]全伝票!N:N,[1]全伝票!$C:$C,$C6)),IF($C6="",SUMIFS([1]全伝票!N:N,[1]全伝票!$A:$A,$A6,[1]全伝票!$B:$B,$B6),SUMIFS([1]全伝票!N:N,[1]全伝票!$A:$A,$A6,[1]全伝票!$C:$C,$C6))) -> 0 | K6: =SUM(F6:J6) -> 0 | L6: =+IF($A6="",IF($C6="",SUMIFS([1]全伝票!O:O,[1]全伝票!$B:$B,$B6),SUMIFS([1]全伝票!O:O,[1]全伝票!$C:$C,$C6)),IF($C6="",SUMIFS([1]全伝票!O:O,[1]全伝票!$A:$A,$A6,[1]全伝票!$B:$B,$B6),SUMIFS([1]全伝票!O:O,[1]全伝票!$A:$A,$A6,[1]全伝票!$C:$C,$C6))) -> 0 | M6: =+IF($A6="",IF($C6="",SUMIFS([1]全伝票!P:P,[1]全伝票!$B:$B,$B6),SUMIFS([1]全伝票!P:P,[1]全伝票!$C:$C,$C6)),IF($C6="",SUMIFS([1]全伝票!P:P,[1]全伝票!$A:$A,$A6,[1]全伝票!$B:$B,$B6),SUMIFS([1]全伝票!P:P,[1]全伝票!$A:$A,$A6,[1]全伝票!$C:$C,$C6))) -> 285882615 | N6: =+ROUND(F6*F$4/(100+F$4),0)+AE6 -> 0 | O6: =+ROUND(G6*G$4/(100+G$4),0)+AF6 -> 0 | P6: =+ROUND(H6*H$4/(100+H$4),0)+AG6 -> 0 | Q6: =+ROUND(I6*I$4/(100+I$4),0)+AH6 -> 0 | R6: =+ROUND(J6*J$4/(100+J$4),0)+AI6 -> 0 | S6: =SUM(N6:R6) -> 0 | T6: =+E6-S6 -> 285882615 | U6: =N6-F6*F$4/(100+F$4) -> 0 | V6: =O6-G6*G$4/(100+G$4) -> 0 | W6: =P6-H6*H$4/(100+H$4) -> 0 | X6: =Q6-I6*I$4/(100+I$4) -> 0 | Y6: =R6-J6*J$4/(100+J$4) -> 0 | Z6: =+IF(N$43=0,0,IF(N$43<0,-RANK(U6,U$5:U$40,0),RANK(U6,U$5:U$40,1))) -> 0 | AA6: =+IF(O$43=0,0,IF(O$43<0,-RANK(V6,V$5:V$40,0),RANK(V6,V$5:V$40,1))) -> 0 | AB6: =+IF(P$43=0,0,IF(P$43<0,-RANK(W6,W$5:W$40,0),RANK(W6,W$5:W$40,1))) -> 0 | AC6: =+IF(Q$43=0,0,IF(Q$43<0,-RANK(X6,X$5:X$40,0),RANK(X6,X$5:X$40,1))) -> 0 | AD6: =+IF(R$43=0,0,IF(R$43<0,-RANK(Y6,Y$5:Y$40,0),RANK(Y6,Y$5:Y$40,1))) -> 0
A7: 1 | B7: 6153203 | D7: 手当等 | E7: =+IF($A7="",IF($C7="",SUMIFS([1]全伝票!I:I,[1]全伝票!$B:$B,$B7),SUMIFS([1]全伝票!I:I,[1]全伝票!$C:$C,$C7)),IF($C7="",SUMIFS([1]全伝票!I:I,[1]全伝票!$A:$A,$A7,[1]全伝票!$B:$B,$B7),SUMIFS([1]全伝票!I:I,[1]全伝票!$A:$A,$A7,[1]全伝票!$C:$C,$C7))) -> 254254313 | F7: =+IF($A7="",IF($C7="",SUMIFS([1]全伝票!J:J,[1]全伝票!$B:$B,$B7),SUMIFS([1]全伝票!J:J,[1]全伝票!$C:$C,$C7)),IF($C7="",SUMIFS([1]全伝票!J:J,[1]全伝票!$A:$A,$A7,[1]全伝票!$B:$B,$B7),SUMIFS([1]全伝票!J:J,[1]全伝票!$A:$A,$A7,[1]全伝票!$C:$C,$C7))) -> 0 | G7: =+IF($A7="",IF($C7="",SUMIFS([1]全伝票!K:K,[1]全伝票!$B:$B,$B7),SUMIFS([1]全伝票!K:K,[1]全伝票!$C:$C,$C7)),IF($C7="",SUMIFS([1]全伝票!K:K,[1]全伝票!$A:$A,$A7,[1]全伝票!$B:$B,$B7),SUMIFS([1]全伝票!K:K,[1]全伝票!$A:$A,$A7,[1]全伝票!$C:$C,$C7))) -> 0 | H7: =+IF($A7="",IF($C7="",SUMIFS([1]全伝票!L:L,[1]全伝票!$B:$B,$B7),SUMIFS([1]全伝票!L:L,[1]全伝票!$C:$C,$C7)),IF($C7="",SUMIFS([1]全伝票!L:L,[1]全伝票!$A:$A,$A7,[1]全伝票!$B:$B,$B7),SUMIFS([1]全伝票!L:L,[1]全伝票!$A:$A,$A7,[1]全伝票!$C:$C,$C7))) -> 0 | I7: =+IF($A7="",IF($C7="",SUMIFS([1]全伝票!M:M,[1]全伝票!$B:$B,$B7),SUMIFS([1]全伝票!M:M,[1]全伝票!$C:$C,$C7)),IF($C7="",SUMIFS([1]全伝票!M:M,[1]全伝票!$A:$A,$A7,[1]全伝票!$B:$B,$B7),SUMIFS([1]全伝票!M:M,[1]全伝票!$A:$A,$A7,[1]全伝票!$C:$C,$C7))) -> 0 | J7: =+IF($A7="",IF($C7="",SUMIFS([1]全伝票!N:N,[1]全伝票!$B:$B,$B7),SUMIFS([1]全伝票!N:N,[1]全伝票!$C:$C,$C7)),IF($C7="",SUMIFS([1]全伝票!N:N,[1]全伝票!$A:$A,$A7,[1]全伝票!$B:$B,$B7),SUMIFS([1]全伝票!N:N,[1]全伝票!$A:$A,$A7,[1]全伝票!$C:$C,$C7))) -> 8735510 | K7: =SUM(F7:J7) -> 8735510 | L7: =+IF($A7="",IF($C7="",SUMIFS([1]全伝票!O:O,[1]全伝票!$B:$B,$B7),SUMIFS([1]全伝票!O:O,[1]全伝票!$C:$C,$C7)),IF($C7="",SUMIFS([1]全伝票!O:O,[1]全伝票!$A:$A,$A7,[1]全伝票!$B:$B,$B7),SUMIFS([1]全伝票!O:O,[1]全伝票!$A:$A,$A7,[1]全伝票!$C:$C,$C7))) -> 0 | M7: =+IF($A7="",IF($C7="",SUMIFS([1]全伝票!P:P,[1]全伝票!$B:$B,$B7),SUMIFS([1]全伝票!P:P,[1]全伝票!$C:$C,$C7)),IF($C7="",SUMIFS([1]全伝票!P:P,[1]全伝票!$A:$A,$A7,[1]全伝票!$B:$B,$B7),SUMIFS([1]全伝票!P:P,[1]全伝票!$A:$A,$A7,[1]全伝票!$C:$C,$C7))) -> 245518803 | N7: =+ROUND(F7*F$4/(100+F$4),0)+AE7 -> 0 | O7: =+ROUND(G7*G$4/(100+G$4),0)+AF7 -> 0 | P7: =+ROUND(H7*H$4/(100+H$4),0)+AG7 -> 0 | Q7: =+ROUND(I7*I$4/(100+I$4),0)+AH7 -> 0 | R7: =+ROUND(J7*J$4/(100+J$4),0)+AI7 -> 794137 | S7: =SUM(N7:R7) -> 794137 | T7: =+E7-S7 -> 253460176 | U7: =N7-F7*F$4/(100+F$4) -> 0 | V7: =O7-G7*G$4/(100+G$4) -> 0 | W7: =P7-H7*H$4/(100+H$4) -> 0 | X7: =Q7-I7*I$4/(100+I$4) -> 0 | Y7: =R7-J7*J$4/(100+J$4) -> -0.27272727 | Z7: =+IF(N$43=0,0,IF(N$43<0,-RANK(U7,U$5:U$40,0),RANK(U7,U$5:U$40,1))) -> 0 | AA7: =+IF(O$43=0,0,IF(O$43<0,-RANK(V7,V$5:V$40,0),RANK(V7,V$5:V$40,1))) -> 0 | AB7: =+IF(P$43=0,0,IF(P$43<0,-RANK(W7,W$5:W$40,0),RANK(W7,W$5:W$40,1))) -> 0 | AC7: =+IF(Q$43=0,0,IF(Q$43<0,-RANK(X7,X$5:X$40,0),RANK(X7,X$5:X$40,1))) -> 0 | AD7: =+IF(R$43=0,0,IF(R$43<0,-RANK(Y7,Y$5:Y$40,0),RANK(Y7,Y$5:Y$40,1))) -> 0
A8: 1 | B8: 6153204 | D8: 法定福利費 | E8: =+IF($A8="",IF($C8="",SUMIFS([1]全伝票!I:I,[1]全伝票!$B:$B,$B8),SUMIFS([1]全伝票!I:I,[1]全伝票!$C:$C,$C8)),IF($C8="",SUMIFS([1]全伝票!I:I,[1]全伝票!$A:$A,$A8,[1]全伝票!$B:$B,$B8),SUMIFS([1]全伝票!I:I,[1]全伝票!$A:$A,$A8,[1]全伝票!$C:$C,$C8))) -> 107621114 | F8: =+IF($A8="",IF($C8="",SUMIFS([1]全伝票!J:J,[1]全伝票!$B:$B,$B8),SUMIFS([1]全伝票!J:J,[1]全伝票!$C:$C,$C8)),IF($C8="",SUMIFS([1]全伝票!J:J,[1]全伝票!$A:$A,$A8,[1]全伝票!$B:$B,$B8),SUMIFS([1]全伝票!J:J,[1]全伝票!$A:$A,$A8,[1]全伝票!$C:$C,$C8))) -> 0 | G8: =+IF($A8="",IF($C8="",SUMIFS([1]全伝票!K:K,[1]全伝票!$B:$B,$B8),SUMIFS([1]全伝票!K:K,[1]全伝票!$C:$C,$C8)),IF($C8="",SUMIFS([1]全伝票!K:K,[1]全伝票!$A:$A,$A8,[1]全伝票!$B:$B,$B8),SUMIFS([1]全伝票!K:K,[1]全伝票!$A:$A,$A8,[1]全伝票!$C:$C,$C8))) -> 0 | H8: =+IF($A8="",IF($C8="",SUMIFS([1]全伝票!L:L,[1]全伝票!$B:$B,$B8),SUMIFS([1]全伝票!L:L,[1]全伝票!$C:$C,$C8)),IF($C8="",SUMIFS([1]全伝票!L:L,[1]全伝票!$A:$A,$A8,[1]全伝票!$B:$B,$B8),SUMIFS([1]全伝票!L:L,[1]全伝票!$A:$A,$A8,[1]全伝票!$C:$C,$C8))) -> 0 | I8: =+IF($A8="",IF($C8="",SUMIFS([1]全伝票!M:M,[1]全伝票!$B:$B,$B8),SUMIFS([1]全伝票!M:M,[1]全伝票!$C:$C,$C8)),IF($C8="",SUMIFS([1]全伝票!M:M,[1]全伝票!$A:$A,$A8,[1]全伝票!$B:$B,$B8),SUMIFS([1]全伝票!M:M,[1]全伝票!$A:$A,$A8,[1]全伝票!$C:$C,$C8))) -> 0 | J8: =+IF($A8="",IF($C8="",SUMIFS([1]全伝票!N:N,[1]全伝票!$B:$B,$B8),SUMIFS([1]全伝票!N:N,[1]全伝票!$C:$C,$C8)),IF($C8="",SUMIFS([1]全伝票!N:N,[1]全伝票!$A:$A,$A8,[1]全伝票!$B:$B,$B8),SUMIFS([1]全伝票!N:N,[1]全伝票!$A:$A,$A8,[1]全伝票!$C:$C,$C8))) -> 0 | K8: =SUM(F8:J8) -> 0 | L8: =+IF($A8="",IF($C8="",SUMIFS([1]全伝票!O:O,[1]全伝票!$B:$B,$B8),SUMIFS([1]全伝票!O:O,[1]全伝票!$C:$C,$C8)),IF($C8="",SUMIFS([1]全伝票!O:O,[1]全伝票!$A:$A,$A8,[1]全伝票!$B:$B,$B8),SUMIFS([1]全伝票!O:O,[1]全伝票!$A:$A,$A8,[1]全伝票!$C:$C,$C8))) -> 107176226 | M8: =+IF($A8="",IF($C8="",SUMIFS([1]全伝票!P:P,[1]全伝票!$B:$B,$B8),SUMIFS([1]全伝票!P:P,[1]全伝票!$C:$C,$C8)),IF($C8="",SUMIFS([1]全伝票!P:P,[1]全伝票!$A:$A,$A8,[1]全伝票!$B:$B,$B8),SUMIFS([1]全伝票!P:P,[1]全伝票!$A:$A,$A8,[1]全伝票!$C:$C,$C8))) -> 444888 | N8: =+ROUND(F8*F$4/(100+F$4),0)+AE8 -> 0 | O8: =+ROUND(G8*G$4/(100+G$4),0)+AF8 -> 0 | P8: =+ROUND(H8*H$4/(100+H$4),0)+AG8 -> 0 | Q8: =+ROUND(I8*I$4/(100+I$4),0)+AH8 -> 0 | R8: =+ROUND(J8*J$4/(100+J$4),0)+AI8 -> 0 | S8: =SUM(N8:R8) -> 0 | T8: =+E8-S8 -> 107621114 | U8: =N8-F8*F$4/(100+F$4) -> 0 | V8: =O8-G8*G$4/(100+G$4) -> 0 | W8: =P8-H8*H$4/(100+H$4) -> 0 | X8: =Q8-I8*I$4/(100+I$4) -> 0 | Y8: =R8-J8*J$4/(100+J$4) -> 0 | Z8: =+IF(N$43=0,0,IF(N$43<0,-RANK(U8,U$5:U$40,0),RANK(U8,U$5:U$40,1))) -> 0 | AA8: =+IF(O$43=0,0,IF(O$43<0,-RANK(V8,V$5:V$40,0),RANK(V8,V$5:V$40,1))) -> 0 | AB8: =+IF(P$43=0,0,IF(P$43<0,-RANK(W8,W$5:W$40,0),RANK(W8,W$5:W$40,1))) -> 0 | AC8: =+IF(Q$43=0,0,IF(Q$43<0,-RANK(X8,X$5:X$40,0),RANK(X8,X$5:X$40,1))) -> 0 | AD8: =+IF(R$43=0,0,IF(R$43<0,-RANK(Y8,Y$5:Y$40,0),RANK(Y8,Y$5:Y$40,1))) -> 0
A9: 1 | B9: 6153205 | D9: 災害補償費 | E9: =+IF($A9="",IF($C9="",SUMIFS([1]全伝票!I:I,[1]全伝票!$B:$B,$B9),SUMIFS([1]全伝票!I:I,[1]全伝票!$C:$C,$C9)),IF($C9="",SUMIFS([1]全伝票!I:I,[1]全伝票!$A:$A,$A9,[1]全伝票!$B:$B,$B9),SUMIFS([1]全伝票!I:I,[1]全伝票!$A:$A,$A9,[1]全伝票!$C:$C,$C9))) -> 0 | F9: =+IF($A9="",IF($C9="",SUMIFS([1]全伝票!J:J,[1]全伝票!$B:$B,$B9),SUMIFS([1]全伝票!J:J,[1]全伝票!$C:$C,$C9)),IF($C9="",SUMIFS([1]全伝票!J:J,[1]全伝票!$A:$A,$A9,[1]全伝票!$B:$B,$B9),SUMIFS([1]全伝票!J:J,[1]全伝票!$A:$A,$A9,[1]全伝票!$C:$C,$C9))) -> 0 | G9: =+IF($A9="",IF($C9="",SUMIFS([1]全伝票!K:K,[1]全伝票!$B:$B,$B9),SUMIFS([1]全伝票!K:K,[1]全伝票!$C:$C,$C9)),IF($C9="",SUMIFS([1]全伝票!K:K,[1]全伝票!$A:$A,$A9,[1]全伝票!$B:$B,$B9),SUMIFS([1]全伝票!K:K,[1]全伝票!$A:$A,$A9,[1]全伝票!$C:$C,$C9))) -> 0 | H9: =+IF($A9="",IF($C9="",SUMIFS([1]全伝票!L:L,[1]全伝票!$B:$B,$B9),SUMIFS([1]全伝票!L:L,[1]全伝票!$C:$C,$C9)),IF($C9="",SUMIFS([1]全伝票!L:L,[1]全伝票!$A:$A,$A9,[1]全伝票!$B:$B,$B9),SUMIFS([1]全伝票!L:L,[1]全伝票!$A:$A,$A9,[1]全伝票!$C:$C,$C9))) -> 0 | I9: =+IF($A9="",IF($C9="",SUMIFS([1]全伝票!M:M,[1]全伝票!$B:$B,$B9),SUMIFS([1]全伝票!M:M,[1]全伝票!$C:$C,$C9)),IF($C9="",SUMIFS([1]全伝票!M:M,[1]全伝票!$A:$A,$A9,[1]全伝票!$B:$B,$B9),SUMIFS([1]全伝票!M:M,[1]全伝票!$A:$A,$A9,[1]全伝票!$C:$C,$C9))) -> 0 | J9: =+IF($A9="",IF($C9="",SUMIFS([1]全伝票!N:N,[1]全伝票!$B:$B,$B9),SUMIFS([1]全伝票!N:N,[1]全伝票!$C:$C,$C9)),IF($C9="",SUMIFS([1]全伝票!N:N,[1]全伝票!$A:$A,$A9,[1]全伝票!$B:$B,$B9),SUMIFS([1]全伝票!N:N,[1]全伝票!$A:$A,$A9,[1]全伝票!$C:$C,$C9))) -> 0 | K9: =SUM(F9:J9) -> 0 | L9: =+IF($A9="",IF($C9="",SUMIFS([1]全伝票!O:O,[1]全伝票!$B:$B,$B9),SUMIFS([1]全伝票!O:O,[1]全伝票!$C:$C,$C9)),IF($C9="",SUMIFS([1]全伝票!O:O,[1]全伝票!$A:$A,$A9,[1]全伝票!$B:$B,$B9),SUMIFS([1]全伝票!O:O,[1]全伝票!$A:$A,$A9,[1]全伝票!$C:$C,$C9))) -> 0 | M9: =+IF($A9="",IF($C9="",SUMIFS([1]全伝票!P:P,[1]全伝票!$B:$B,$B9),SUMIFS([1]全伝票!P:P,[1]全伝票!$C:$C,$C9)),IF($C9="",SUMIFS([1]全伝票!P:P,[1]全伝票!$A:$A,$A9,[1]全伝票!$B:$B,$B9),SUMIFS([1]全伝票!P:P,[1]全伝票!$A:$A,$A9,[1]全伝票!$C:$C,$C9))) -> 0 | N9: =+ROUND(F9*F$4/(100+F$4),0)+AE9 -> 0 | O9: =+ROUND(G9*G$4/(100+G$4),0)+AF9 -> 0 | P9: =+ROUND(H9*H$4/(100+H$4),0)+AG9 -> 0 | Q9: =+ROUND(I9*I$4/(100+I$4),0)+AH9 -> 0 | R9: =+ROUND(J9*J$4/(100+J$4),0)+AI9 -> 0 | S9: =SUM(N9:R9) -> 0 | T9: =+E9-S9 -> 0 | U9: =N9-F9*F$4/(100+F$4) -> 0 | V9: =O9-G9*G$4/(100+G$4) -> 0 | W9: =P9-H9*H$4/(100+H$4) -> 0 | X9: =Q9-I9*I$4/(100+I$4) -> 0 | Y9: =R9-J9*J$4/(100+J$4) -> 0 | Z9: =+IF(N$43=0,0,IF(N$43<0,-RANK(U9,U$5:U$40,0),RANK(U9,U$5:U$40,1))) -> 0 | AA9: =+IF(O$43=0,0,IF(O$43<0,-RANK(V9,V$5:V$40,0),RANK(V9,V$5:V$40,1))) -> 0 | AB9: =+IF(P$43=0,0,IF(P$43<0,-RANK(W9,W$5:W$40,0),RANK(W9,W$5:W$40,1))) -> 0 | AC9: =+IF(Q$43=0,0,IF(Q$43<0,-RANK(X9,X$5:X$40,0),RANK(X9,X$5:X$40,1))) -> 0 | AD9: =+IF(R$43=0,0,IF(R$43<0,-RANK(Y9,Y$5:Y$40,0),RANK(Y9,Y$5:Y$40,1))) -> 0
A10: 1 | B10: 6153207 | D10: 賃金 | E10: =+IF($A10="",IF($C10="",SUMIFS([1]全伝票!I:I,[1]全伝票!$B:$B,$B10),SUMIFS([1]全伝票!I:I,[1]全伝票!$C:$C,$C10)),IF($C10="",SUMIFS([1]全伝票!I:I,[1]全伝票!$A:$A,$A10,[1]全伝票!$B:$B,$B10),SUMIFS([1]全伝票!I:I,[1]全伝票!$A:$A,$A10,[1]全伝票!$C:$C,$C10))) -> 0 | F10: =+IF($A10="",IF($C10="",SUMIFS([1]全伝票!J:J,[1]全伝票!$B:$B,$B10),SUMIFS([1]全伝票!J:J,[1]全伝票!$C:$C,$C10)),IF($C10="",SUMIFS([1]全伝票!J:J,[1]全伝票!$A:$A,$A10,[1]全伝票!$B:$B,$B10),SUMIFS([1]全伝票!J:J,[1]全伝票!$A:$A,$A10,[1]全伝票!$C:$C,$C10))) -> 0 | G10: =+IF($A10="",IF($C10="",SUMIFS([1]全伝票!K:K,[1]全伝票!$B:$B,$B10),SUMIFS([1]全伝票!K:K,[1]全伝票!$C:$C,$C10)),IF($C10="",SUMIFS([1]全伝票!K:K,[1]全伝票!$A:$A,$A10,[1]全伝票!$B:$B,$B10),SUMIFS([1]全伝票!K:K,[1]全伝票!$A:$A,$A10,[1]全伝票!$C:$C,$C10))) -> 0 | H10: =+IF($A10="",IF($C10="",SUMIFS([1]全伝票!L:L,[1]全伝票!$B:$B,$B10),SUMIFS([1]全伝票!L:L,[1]全伝票!$C:$C,$C10)),IF($C10="",SUMIFS([1]全伝票!L:L,[1]全伝票!$A:$A,$A10,[1]全伝票!$B:$B,$B10),SUMIFS([1]全伝票!L:L,[1]全伝票!$A:$A,$A10,[1]全伝票!$C:$C,$C10))) -> 0 | I10: =+IF($A10="",IF($C10="",SUMIFS([1]全伝票!M:M,[1]全伝票!$B:$B,$B10),SUMIFS([1]全伝票!M:M,[1]全伝票!$C:$C,$C10)),IF($C10="",SUMIFS([1]全伝票!M:M,[1]全伝票!$A:$A,$A10,[1]全伝票!$B:$B,$B10),SUMIFS([1]全伝票!M:M,[1]全伝票!$A:$A,$A10,[1]全伝票!$C:$C,$C10))) -> 0 | J10: =+IF($A10="",IF($C10="",SUMIFS([1]全伝票!N:N,[1]全伝票!$B:$B,$B10),SUMIFS([1]全伝票!N:N,[1]全伝票!$C:$C,$C10)),IF($C10="",SUMIFS([1]全伝票!N:N,[1]全伝票!$A:$A,$A10,[1]全伝票!$B:$B,$B10),SUMIFS([1]全伝票!N:N,[1]全伝票!$A:$A,$A10,[1]全伝票!$C:$C,$C10))) -> 0 | K10: =SUM(F10:J10) -> 0 | L10: =+IF($A10="",IF($C10="",SUMIFS([1]全伝票!O:O,[1]全伝票!$B:$B,$B10),SUMIFS([1]全伝票!O:O,[1]全伝票!$C:$C,$C10)),IF($C10="",SUMIFS([1]全伝票!O:O,[1]全伝票!$A:$A,$A10,[1]全伝票!$B:$B,$B10),SUMIFS([1]全伝票!O:O,[1]全伝票!$A:$A,$A10,[1]全伝票!$C:$C,$C10))) -> 0 | M10: =+IF($A10="",IF($C10="",SUMIFS([1]全伝票!P:P,[1]全伝票!$B:$B,$B10),SUMIFS([1]全伝票!P:P,[1]全伝票!$C:$C,$C10)),IF($C10="",SUMIFS([1]全伝票!P:P,[1]全伝票!$A:$A,$A10,[1]全伝票!$B:$B,$B10),SUMIFS([1]全伝票!P:P,[1]全伝票!$A:$A,$A10,[1]全伝票!$C:$C,$C10))) -> 0 | N10: =+ROUND(F10*F$4/(100+F$4),0)+AE10 -> 0 | O10: =+ROUND(G10*G$4/(100+G$4),0)+AF10 -> 0 | P10: =+ROUND(H10*H$4/(100+H$4),0)+AG10 -> 0 | Q10: =+ROUND(I10*I$4/(100+I$4),0)+AH10 -> 0 | R10: =+ROUND(J10*J$4/(100+J$4),0)+AI10 -> 0 | S10: =SUM(N10:R10) -> 0 | T10: =+E10-S10 -> 0 | U10: =N10-F10*F$4/(100+F$4) -> 0 | V10: =O10-G10*G$4/(100+G$4) -> 0 | W10: =P10-H10*H$4/(100+H$4) -> 0 | X10: =Q10-I10*I$4/(100+I$4) -> 0 | Y10: =R10-J10*J$4/(100+J$4) -> 0 | Z10: =+IF(N$43=0,0,IF(N$43<0,-RANK(U10,U$5:U$40,0),RANK(U10,U$5:U$40,1))) -> 0 | AA10: =+IF(O$43=0,0,IF(O$43<0,-RANK(V10,V$5:V$40,0),RANK(V10,V$5:V$40,1))) -> 0 | AB10: =+IF(P$43=0,0,IF(P$43<0,-RANK(W10,W$5:W$40,0),RANK(W10,W$5:W$40,1))) -> 0 | AC10: =+IF(Q$43=0,0,IF(Q$43<0,-RANK(X10,X$5:X$40,0),RANK(X10,X$5:X$40,1))) -> 0 | AD10: =+IF(R$43=0,0,IF(R$43<0,-RANK(Y10,Y$5:Y$40,0),RANK(Y10,Y$5:Y$40,1))) -> 0
A11: 1 | B11: 6153208 | D11: 報償費 | E11: =+IF($A11="",IF($C11="",SUMIFS([1]全伝票!I:I,[1]全伝票!$B:$B,$B11),SUMIFS([1]全伝票!I:I,[1]全伝票!$C:$C,$C11)),IF($C11="",SUMIFS([1]全伝票!I:I,[1]全伝票!$A:$A,$A11,[1]全伝票!$B:$B,$B11),SUMIFS([1]全伝票!I:I,[1]全伝票!$A:$A,$A11,[1]全伝票!$C:$C,$C11))) -> 0 | F11: =+IF($A11="",IF($C11="",SUMIFS([1]全伝票!J:J,[1]全伝票!$B:$B,$B11),SUMIFS([1]全伝票!J:J,[1]全伝票!$C:$C,$C11)),IF($C11="",SUMIFS([1]全伝票!J:J,[1]全伝票!$A:$A,$A11,[1]全伝票!$B:$B,$B11),SUMIFS([1]全伝票!J:J,[1]全伝票!$A:$A,$A11,[1]全伝票!$C:$C,$C11))) -> 0 | G11: =+IF($A11="",IF($C11="",SUMIFS([1]全伝票!K:K,[1]全伝票!$B:$B,$B11),SUMIFS([1]全伝票!K:K,[1]全伝票!$C:$C,$C11)),IF($C11="",SUMIFS([1]全伝票!K:K,[1]全伝票!$A:$A,$A11,[1]全伝票!$B:$B,$B11),SUMIFS([1]全伝票!K:K,[1]全伝票!$A:$A,$A11,[1]全伝票!$C:$C,$C11))) -> 0 | H11: =+IF($A11="",IF($C11="",SUMIFS([1]全伝票!L:L,[1]全伝票!$B:$B,$B11),SUMIFS([1]全伝票!L:L,[1]全伝票!$C:$C,$C11)),IF($C11="",SUMIFS([1]全伝票!L:L,[1]全伝票!$A:$A,$A11,[1]全伝票!$B:$B,$B11),SUMIFS([1]全伝票!L:L,[1]全伝票!$A:$A,$A11,[1]全伝票!$C:$C,$C11))) -> 0 | I11: =+IF($A11="",IF($C11="",SUMIFS([1]全伝票!M:M,[1]全伝票!$B:$B,$B11),SUMIFS([1]全伝票!M:M,[1]全伝票!$C:$C,$C11)),IF($C11="",SUMIFS([1]全伝票!M:M,[1]全伝票!$A:$A,$A11,[1]全伝票!$B:$B,$B11),SUMIFS([1]全伝票!M:M,[1]全伝票!$A:$A,$A11,[1]全伝票!$C:$C,$C11))) -> 0 | J11: =+IF($A11="",IF($C11="",SUMIFS([1]全伝票!N:N,[1]全伝票!$B:$B,$B11),SUMIFS([1]全伝票!N:N,[1]全伝票!$C:$C,$C11)),IF($C11="",SUMIFS([1]全伝票!N:N,[1]全伝票!$A:$A,$A11,[1]全伝票!$B:$B,$B11),SUMIFS([1]全伝票!N:N,[1]全伝票!$A:$A,$A11,[1]全伝票!$C:$C,$C11))) -> 0 | K11: =SUM(F11:J11) -> 0 | L11: =+IF($A11="",IF($C11="",SUMIFS([1]全伝票!O:O,[1]全伝票!$B:$B,$B11),SUMIFS([1]全伝票!O:O,[1]全伝票!$C:$C,$C11)),IF($C11="",SUMIFS([1]全伝票!O:O,[1]全伝票!$A:$A,$A11,[1]全伝票!$B:$B,$B11),SUMIFS([1]全伝票!O:O,[1]全伝票!$A:$A,$A11,[1]全伝票!$C:$C,$C11))) -> 0 | M11: =+IF($A11="",IF($C11="",SUMIFS([1]全伝票!P:P,[1]全伝票!$B:$B,$B11),SUMIFS([1]全伝票!P:P,[1]全伝票!$C:$C,$C11)),IF($C11="",SUMIFS([1]全伝票!P:P,[1]全伝票!$A:$A,$A11,[1]全伝票!$B:$B,$B11),SUMIFS([1]全伝票!P:P,[1]全伝票!$A:$A,$A11,[1]全伝票!$C:$C,$C11))) -> 0 | N11: =+ROUND(F11*F$4/(100+F$4),0)+AE11 -> 0 | O11: =+ROUND(G11*G$4/(100+G$4),0)+AF11 -> 0 | P11: =+ROUND(H11*H$4/(100+H$4),0)+AG11 -> 0 | Q11: =+ROUND(I11*I$4/(100+I$4),0)+AH11 -> 0 | R11: =+ROUND(J11*J$4/(100+J$4),0)+AI11 -> 0 | S11: =SUM(N11:R11) -> 0 | T11: =+E11-S11 -> 0 | U11: =N11-F11*F$4/(100+F$4) -> 0 | V11: =O11-G11*G$4/(100+G$4) -> 0 | W11: =P11-H11*H$4/(100+H$4) -> 0 | X11: =Q11-I11*I$4/(100+I$4) -> 0 | Y11: =R11-J11*J$4/(100+J$4) -> 0 | Z11: =+IF(N$43=0,0,IF(N$43<0,-RANK(U11,U$5:U$40,0),RANK(U11,U$5:U$40,1))) -> 0 | AA11: =+IF(O$43=0,0,IF(O$43<0,-RANK(V11,V$5:V$40,0),RANK(V11,V$5:V$40,1))) -> 0 | AB11: =+IF(P$43=0,0,IF(P$43<0,-RANK(W11,W$5:W$40,0),RANK(W11,W$5:W$40,1))) -> 0 | AC11: =+IF(Q$43=0,0,IF(Q$43<0,-RANK(X11,X$5:X$40,0),RANK(X11,X$5:X$40,1))) -> 0 | AD11: =+IF(R$43=0,0,IF(R$43<0,-RANK(Y11,Y$5:Y$40,0),RANK(Y11,Y$5:Y$40,1))) -> 0
A12: 1 | B12: 6153210 | C12: 615321001 | D12: 普通旅費 | E12: =+IF($A12="",IF($C12="",SUMIFS([1]全伝票!I:I,[1]全伝票!$B:$B,$B12),SUMIFS([1]全伝票!I:I,[1]全伝票!$C:$C,$C12)),IF($C12="",SUMIFS([1]全伝票!I:I,[1]全伝票!$A:$A,$A12,[1]全伝票!$B:$B,$B12),SUMIFS([1]全伝票!I:I,[1]全伝票!$A:$A,$A12,[1]全伝票!$C:$C,$C12))) -> 2021074 | F12: =+IF($A12="",IF($C12="",SUMIFS([1]全伝票!J:J,[1]全伝票!$B:$B,$B12),SUMIFS([1]全伝票!J:J,[1]全伝票!$C:$C,$C12)),IF($C12="",SUMIFS([1]全伝票!J:J,[1]全伝票!$A:$A,$A12,[1]全伝票!$B:$B,$B12),SUMIFS([1]全伝票!J:J,[1]全伝票!$A:$A,$A12,[1]全伝票!$C:$C,$C12))) -> 0 | G12: =+IF($A12="",IF($C12="",SUMIFS([1]全伝票!K:K,[1]全伝票!$B:$B,$B12),SUMIFS([1]全伝票!K:K,[1]全伝票!$C:$C,$C12)),IF($C12="",SUMIFS([1]全伝票!K:K,[1]全伝票!$A:$A,$A12,[1]全伝票!$B:$B,$B12),SUMIFS([1]全伝票!K:K,[1]全伝票!$A:$A,$A12,[1]全伝票!$C:$C,$C12))) -> 0 | H12: =+IF($A12="",IF($C12="",SUMIFS([1]全伝票!L:L,[1]全伝票!$B:$B,$B12),SUMIFS([1]全伝票!L:L,[1]全伝票!$C:$C,$C12)),IF($C12="",SUMIFS([1]全伝票!L:L,[1]全伝票!$A:$A,$A12,[1]全伝票!$B:$B,$B12),SUMIFS([1]全伝票!L:L,[1]全伝票!$A:$A,$A12,[1]全伝票!$C:$C,$C12))) -> 0 | I12: =+IF($A12="",IF($C12="",SUMIFS([1]全伝票!M:M,[1]全伝票!$B:$B,$B12),SUMIFS([1]全伝票!M:M,[1]全伝票!$C:$C,$C12)),IF($C12="",SUMIFS([1]全伝票!M:M,[1]全伝票!$A:$A,$A12,[1]全伝票!$B:$B,$B12),SUMIFS([1]全伝票!M:M,[1]全伝票!$A:$A,$A12,[1]全伝票!$C:$C,$C12))) -> 0 | J12: =+IF($A12="",IF($C12="",SUMIFS([1]全伝票!N:N,[1]全伝票!$B:$B,$B12),SUMIFS([1]全伝票!N:N,[1]全伝票!$C:$C,$C12)),IF($C12="",SUMIFS([1]全伝票!N:N,[1]全伝票!$A:$A,$A12,[1]全伝票!$B:$B,$B12),SUMIFS([1]全伝票!N:N,[1]全伝票!$A:$A,$A12,[1]全伝票!$C:$C,$C12))) -> 2021074 | K12: =SUM(F12:J12) -> 2021074 | L12: =+IF($A12="",IF($C12="",SUMIFS([1]全伝票!O:O,[1]全伝票!$B:$B,$B12),SUMIFS([1]全伝票!O:O,[1]全伝票!$C:$C,$C12)),IF($C12="",SUMIFS([1]全伝票!O:O,[1]全伝票!$A:$A,$A12,[1]全伝票!$B:$B,$B12),SUMIFS([1]全伝票!O:O,[1]全伝票!$A:$A,$A12,[1]全伝票!$C:$C,$C12))) -> 0 | M12: =+IF($A12="",IF($C12="",SUMIFS([1]全伝票!P:P,[1]全伝票!$B:$B,$B12),SUMIFS([1]全伝票!P:P,[1]全伝票!$C:$C,$C12)),IF($C12="",SUMIFS([1]全伝票!P:P,[1]全伝票!$A:$A,$A12,[1]全伝票!$B:$B,$B12),SUMIFS([1]全伝票!P:P,[1]全伝票!$A:$A,$A12,[1]全伝票!$C:$C,$C12))) -> 0 | N12: =+ROUND(F12*F$4/(100+F$4),0)+AE12 -> 0 | O12: =+ROUND(G12*G$4/(100+G$4),0)+AF12 -> 0 | P12: =+ROUND(H12*H$4/(100+H$4),0)+AG12 -> 0 | Q12: =+ROUND(I12*I$4/(100+I$4),0)+AH12 -> 0 | R12: =+ROUND(J12*J$4/(100+J$4),0)+AI12 -> 183734 | S12: =SUM(N12:R12) -> 183734 | T12: =+E12-S12 -> 1837340 | U12: =N12-F12*F$4/(100+F$4) -> 0 | V12: =O12-G12*G$4/(100+G$4) -> 0 | W12: =P12-H12*H$4/(100+H$4) -> 0 | X12: =Q12-I12*I$4/(100+I$4) -> 0 | Y12: =R12-J12*J$4/(100+J$4) -> 0 | Z12: =+IF(N$43=0,0,IF(N$43<0,-RANK(U12,U$5:U$40,0),RANK(U12,U$5:U$40,1))) -> 0 | AA12: =+IF(O$43=0,0,IF(O$43<0,-RANK(V12,V$5:V$40,0),RANK(V12,V$5:V$40,1))) -> 0 | AB12: =+IF(P$43=0,0,IF(P$43<0,-RANK(W12,W$5:W$40,0),RANK(W12,W$5:W$40,1))) -> 0 | AC12: =+IF(Q$43=0,0,IF(Q$43<0,-RANK(X12,X$5:X$40,0),RANK(X12,X$5:X$40,1))) -> 0 | AD12: =+IF(R$43=0,0,IF(R$43<0,-RANK(Y12,Y$5:Y$40,0),RANK(Y12,Y$5:Y$40,1))) -> 0
A13: 1 | B13: 6153210 | C13: 615321002 | D13: 特別旅費 | E13: =+IF($A13="",IF($C13="",SUMIFS([1]全伝票!I:I,[1]全伝票!$B:$B,$B13),SUMIFS([1]全伝票!I:I,[1]全伝票!$C:$C,$C13)),IF($C13="",SUMIFS([1]全伝票!I:I,[1]全伝票!$A:$A,$A13,[1]全伝票!$B:$B,$B13),SUMIFS([1]全伝票!I:I,[1]全伝票!$A:$A,$A13,[1]全伝票!$C:$C,$C13))) -> 0 | F13: =+IF($A13="",IF($C13="",SUMIFS([1]全伝票!J:J,[1]全伝票!$B:$B,$B13),SUMIFS([1]全伝票!J:J,[1]全伝票!$C:$C,$C13)),IF($C13="",SUMIFS([1]全伝票!J:J,[1]全伝票!$A:$A,$A13,[1]全伝票!$B:$B,$B13),SUMIFS([1]全伝票!J:J,[1]全伝票!$A:$A,$A13,[1]全伝票!$C:$C,$C13))) -> 0 | G13: =+IF($A13="",IF($C13="",SUMIFS([1]全伝票!K:K,[1]全伝票!$B:$B,$B13),SUMIFS([1]全伝票!K:K,[1]全伝票!$C:$C,$C13)),IF($C13="",SUMIFS([1]全伝票!K:K,[1]全伝票!$A:$A,$A13,[1]全伝票!$B:$B,$B13),SUMIFS([1]全伝票!K:K,[1]全伝票!$A:$A,$A13,[1]全伝票!$C:$C,$C13))) -> 0 | H13: =+IF($A13="",IF($C13="",SUMIFS([1]全伝票!L:L,[1]全伝票!$B:$B,$B13),SUMIFS([1]全伝票!L:L,[1]全伝票!$C:$C,$C13)),IF($C13="",SUMIFS([1]全伝票!L:L,[1]全伝票!$A:$A,$A13,[1]全伝票!$B:$B,$B13),SUMIFS([1]全伝票!L:L,[1]全伝票!$A:$A,$A13,[1]全伝票!$C:$C,$C13))) -> 0 | I13: =+IF($A13="",IF($C13="",SUMIFS([1]全伝票!M:M,[1]全伝票!$B:$B,$B13),SUMIFS([1]全伝票!M:M,[1]全伝票!$C:$C,$C13)),IF($C13="",SUMIFS([1]全伝票!M:M,[1]全伝票!$A:$A,$A13,[1]全伝票!$B:$B,$B13),SUMIFS([1]全伝票!M:M,[1]全伝票!$A:$A,$A13,[1]全伝票!$C:$C,$C13))) -> 0 | J13: =+IF($A13="",IF($C13="",SUMIFS([1]全伝票!N:N,[1]全伝票!$B:$B,$B13),SUMIFS([1]全伝票!N:N,[1]全伝票!$C:$C,$C13)),IF($C13="",SUMIFS([1]全伝票!N:N,[1]全伝票!$A:$A,$A13,[1]全伝票!$B:$B,$B13),SUMIFS([1]全伝票!N:N,[1]全伝票!$A:$A,$A13,[1]全伝票!$C:$C,$C13))) -> 0 | K13: =SUM(F13:J13) -> 0 | L13: =+IF($A13="",IF($C13="",SUMIFS([1]全伝票!O:O,[1]全伝票!$B:$B,$B13),SUMIFS([1]全伝票!O:O,[1]全伝票!$C:$C,$C13)),IF($C13="",SUMIFS([1]全伝票!O:O,[1]全伝票!$A:$A,$A13,[1]全伝票!$B:$B,$B13),SUMIFS([1]全伝票!O:O,[1]全伝票!$A:$A,$A13,[1]全伝票!$C:$C,$C13))) -> 0 | M13: =+IF($A13="",IF($C13="",SUMIFS([1]全伝票!P:P,[1]全伝票!$B:$B,$B13),SUMIFS([1]全伝票!P:P,[1]全伝票!$C:$C,$C13)),IF($C13="",SUMIFS([1]全伝票!P:P,[1]全伝票!$A:$A,$A13,[1]全伝票!$B:$B,$B13),SUMIFS([1]全伝票!P:P,[1]全伝票!$A:$A,$A13,[1]全伝票!$C:$C,$C13))) -> 0 | N13: =+ROUND(F13*F$4/(100+F$4),0)+AE13 -> 0 | O13: =+ROUND(G13*G$4/(100+G$4),0)+AF13 -> 0 | P13: =+ROUND(H13*H$4/(100+H$4),0)+AG13 -> 0 | Q13: =+ROUND(I13*I$4/(100+I$4),0)+AH13 -> 0 | R13: =+ROUND(J13*J$4/(100+J$4),0)+AI13 -> 0 | S13: =SUM(N13:R13) -> 0 | T13: =+E13-S13 -> 0 | U13: =N13-F13*F$4/(100+F$4) -> 0 | V13: =O13-G13*G$4/(100+G$4) -> 0 | W13: =P13-H13*H$4/(100+H$4) -> 0 | X13: =Q13-I13*I$4/(100+I$4) -> 0 | Y13: =R13-J13*J$4/(100+J$4) -> 0 | Z13: =+IF(N$43=0,0,IF(N$43<0,-RANK(U13,U$5:U$40,0),RANK(U13,U$5:U$40,1))) -> 0 | AA13: =+IF(O$43=0,0,IF(O$43<0,-RANK(V13,V$5:V$40,0),RANK(V13,V$5:V$40,1))) -> 0 | AB13: =+IF(P$43=0,0,IF(P$43<0,-RANK(W13,W$5:W$40,0),RANK(W13,W$5:W$40,1))) -> 0 | AC13: =+IF(Q$43=0,0,IF(Q$43<0,-RANK(X13,X$5:X$40,0),RANK(X13,X$5:X$40,1))) -> 0 | AD13: =+IF(R$43=0,0,IF(R$43<0,-RANK(Y13,Y$5:Y$40,0),RANK(Y13,Y$5:Y$40,1))) -> 0
A14: 1 | B14: 6153213 | D14: 備消品費 | E14: =+IF($A14="",IF($C14="",SUMIFS([1]全伝票!I:I,[1]全伝票!$B:$B,$B14),SUMIFS([1]全伝票!I:I,[1]全伝票!$C:$C,$C14)),IF($C14="",SUMIFS([1]全伝票!I:I,[1]全伝票!$A:$A,$A14,[1]全伝票!$B:$B,$B14),SUMIFS([1]全伝票!I:I,[1]全伝票!$A:$A,$A14,[1]全伝票!$C:$C,$C14))) -> 10417060 | F14: =+IF($A14="",IF($C14="",SUMIFS([1]全伝票!J:J,[1]全伝票!$B:$B,$B14),SUMIFS([1]全伝票!J:J,[1]全伝票!$C:$C,$C14)),IF($C14="",SUMIFS([1]全伝票!J:J,[1]全伝票!$A:$A,$A14,[1]全伝票!$B:$B,$B14),SUMIFS([1]全伝票!J:J,[1]全伝票!$A:$A,$A14,[1]全伝票!$C:$C,$C14))) -> 0 | G14: =+IF($A14="",IF($C14="",SUMIFS([1]全伝票!K:K,[1]全伝票!$B:$B,$B14),SUMIFS([1]全伝票!K:K,[1]全伝票!$C:$C,$C14)),IF($C14="",SUMIFS([1]全伝票!K:K,[1]全伝票!$A:$A,$A14,[1]全伝票!$B:$B,$B14),SUMIFS([1]全伝票!K:K,[1]全伝票!$A:$A,$A14,[1]全伝票!$C:$C,$C14))) -> 0 | H14: =+IF($A14="",IF($C14="",SUMIFS([1]全伝票!L:L,[1]全伝票!$B:$B,$B14),SUMIFS([1]全伝票!L:L,[1]全伝票!$C:$C,$C14)),IF($C14="",SUMIFS([1]全伝票!L:L,[1]全伝票!$A:$A,$A14,[1]全伝票!$B:$B,$B14),SUMIFS([1]全伝票!L:L,[1]全伝票!$A:$A,$A14,[1]全伝票!$C:$C,$C14))) -> 0 | I14: =+IF($A14="",IF($C14="",SUMIFS([1]全伝票!M:M,[1]全伝票!$B:$B,$B14),SUMIFS([1]全伝票!M:M,[1]全伝票!$C:$C,$C14)),IF($C14="",SUMIFS([1]全伝票!M:M,[1]全伝票!$A:$A,$A14,[1]全伝票!$B:$B,$B14),SUMIFS([1]全伝票!M:M,[1]全伝票!$A:$A,$A14,[1]全伝票!$C:$C,$C14))) -> 36840 | J14: =+IF($A14="",IF($C14="",SUMIFS([1]全伝票!N:N,[1]全伝票!$B:$B,$B14),SUMIFS([1]全伝票!N:N,[1]全伝票!$C:$C,$C14)),IF($C14="",SUMIFS([1]全伝票!N:N,[1]全伝票!$A:$A,$A14,[1]全伝票!$B:$B,$B14),SUMIFS([1]全伝票!N:N,[1]全伝票!$A:$A,$A14,[1]全伝票!$C:$C,$C14))) -> 10380220 | K14: =SUM(F14:J14) -> 10417060 | L14: =+IF($A14="",IF($C14="",SUMIFS([1]全伝票!O:O,[1]全伝票!$B:$B,$B14),SUMIFS([1]全伝票!O:O,[1]全伝票!$C:$C,$C14)),IF($C14="",SUMIFS([1]全伝票!O:O,[1]全伝票!$A:$A,$A14,[1]全伝票!$B:$B,$B14),SUMIFS([1]全伝票!O:O,[1]全伝票!$A:$A,$A14,[1]全伝票!$C:$C,$C14))) -> 0 | M14: =+IF($A14="",IF($C14="",SUMIFS([1]全伝票!P:P,[1]全伝票!$B:$B,$B14),SUMIFS([1]全伝票!P:P,[1]全伝票!$C:$C,$C14)),IF($C14="",SUMIFS([1]全伝票!P:P,[1]全伝票!$A:$A,$A14,[1]全伝票!$B:$B,$B14),SUMIFS([1]全伝票!P:P,[1]全伝票!$A:$A,$A14,[1]全伝票!$C:$C,$C14))) -> 0 | N14: =+ROUND(F14*F$4/(100+F$4),0)+AE14 -> 0 | O14: =+ROUND(G14*G$4/(100+G$4),0)+AF14 -> 0 | P14: =+ROUND(H14*H$4/(100+H$4),0)+AG14 -> 0 | Q14: =+ROUND(I14*I$4/(100+I$4),0)+AH14 -> 2728 | R14: =+ROUND(J14*J$4/(100+J$4),0)+AI14 -> 943656 | S14: =SUM(N14:R14) -> 946384 | T14: =+E14-S14 -> 9470676 | U14: =N14-F14*F$4/(100+F$4) -> 0 | V14: =O14-G14*G$4/(100+G$4) -> 0 | W14: =P14-H14*H$4/(100+H$4) -> 0 | X14: =Q14-I14*I$4/(100+I$4) -> -0.88888889 | Y14: =R14-J14*J$4/(100+J$4) -> -0.36363636 | Z14: =+IF(N$43=0,0,IF(N$43<0,-RANK(U14,U$5:U$40,0),RANK(U14,U$5:U$40,1))) -> 0 | AA14: =+IF(O$43=0,0,IF(O$43<0,-RANK(V14,V$5:V$40,0),RANK(V14,V$5:V$40,1))) -> 0 | AB14: =+IF(P$43=0,0,IF(P$43<0,-RANK(W14,W$5:W$40,0),RANK(W14,W$5:W$40,1))) -> 0 | AC14: =+IF(Q$43=0,0,IF(Q$43<0,-RANK(X14,X$5:X$40,0),RANK(X14,X$5:X$40,1))) -> 0 | AD14: =+IF(R$43=0,0,IF(R$43<0,-RANK(Y14,Y$5:Y$40,0),RANK(Y14,Y$5:Y$40,1))) -> 0 | AH14: -1
A15: 1 | B15: 6153214 | D15: 燃料費 | E15: =+IF($A15="",IF($C15="",SUMIFS([1]全伝票!I:I,[1]全伝票!$B:$B,$B15),SUMIFS([1]全伝票!I:I,[1]全伝票!$C:$C,$C15)),IF($C15="",SUMIFS([1]全伝票!I:I,[1]全伝票!$A:$A,$A15,[1]全伝票!$B:$B,$B15),SUMIFS([1]全伝票!I:I,[1]全伝票!$A:$A,$A15,[1]全伝票!$C:$C,$C15))) -> 1053838 | F15: =+IF($A15="",IF($C15="",SUMIFS([1]全伝票!J:J,[1]全伝票!$B:$B,$B15),SUMIFS([1]全伝票!J:J,[1]全伝票!$C:$C,$C15)),IF($C15="",SUMIFS([1]全伝票!J:J,[1]全伝票!$A:$A,$A15,[1]全伝票!$B:$B,$B15),SUMIFS([1]全伝票!J:J,[1]全伝票!$A:$A,$A15,[1]全伝票!$C:$C,$C15))) -> 0 | G15: =+IF($A15="",IF($C15="",SUMIFS([1]全伝票!K:K,[1]全伝票!$B:$B,$B15),SUMIFS([1]全伝票!K:K,[1]全伝票!$C:$C,$C15)),IF($C15="",SUMIFS([1]全伝票!K:K,[1]全伝票!$A:$A,$A15,[1]全伝票!$B:$B,$B15),SUMIFS([1]全伝票!K:K,[1]全伝票!$A:$A,$A15,[1]全伝票!$C:$C,$C15))) -> 0 | H15: =+IF($A15="",IF($C15="",SUMIFS([1]全伝票!L:L,[1]全伝票!$B:$B,$B15),SUMIFS([1]全伝票!L:L,[1]全伝票!$C:$C,$C15)),IF($C15="",SUMIFS([1]全伝票!L:L,[1]全伝票!$A:$A,$A15,[1]全伝票!$B:$B,$B15),SUMIFS([1]全伝票!L:L,[1]全伝票!$A:$A,$A15,[1]全伝票!$C:$C,$C15))) -> 0 | I15: =+IF($A15="",IF($C15="",SUMIFS([1]全伝票!M:M,[1]全伝票!$B:$B,$B15),SUMIFS([1]全伝票!M:M,[1]全伝票!$C:$C,$C15)),IF($C15="",SUMIFS([1]全伝票!M:M,[1]全伝票!$A:$A,$A15,[1]全伝票!$B:$B,$B15),SUMIFS([1]全伝票!M:M,[1]全伝票!$A:$A,$A15,[1]全伝票!$C:$C,$C15))) -> 0 | J15: =+IF($A15="",IF($C15="",SUMIFS([1]全伝票!N:N,[1]全伝票!$B:$B,$B15),SUMIFS([1]全伝票!N:N,[1]全伝票!$C:$C,$C15)),IF($C15="",SUMIFS([1]全伝票!N:N,[1]全伝票!$A:$A,$A15,[1]全伝票!$B:$B,$B15),SUMIFS([1]全伝票!N:N,[1]全伝票!$A:$A,$A15,[1]全伝票!$C:$C,$C15))) -> 1053838 | K15: =SUM(F15:J15) -> 1053838 | L15: =+IF($A15="",IF($C15="",SUMIFS([1]全伝票!O:O,[1]全伝票!$B:$B,$B15),SUMIFS([1]全伝票!O:O,[1]全伝票!$C:$C,$C15)),IF($C15="",SUMIFS([1]全伝票!O:O,[1]全伝票!$A:$A,$A15,[1]全伝票!$B:$B,$B15),SUMIFS([1]全伝票!O:O,[1]全伝票!$A:$A,$A15,[1]全伝票!$C:$C,$C15))) -> 0 | M15: =+IF($A15="",IF($C15="",SUMIFS([1]全伝票!P:P,[1]全伝票!$B:$B,$B15),SUMIFS([1]全伝票!P:P,[1]全伝票!$C:$C,$C15)),IF($C15="",SUMIFS([1]全伝票!P:P,[1]全伝票!$A:$A,$A15,[1]全伝票!$B:$B,$B15),SUMIFS([1]全伝票!P:P,[1]全伝票!$A:$A,$A15,[1]全伝票!$C:$C,$C15))) -> 0 | N15: =+ROUND(F15*F$4/(100+F$4),0)+AE15 -> 0 | O15: =+ROUND(G15*G$4/(100+G$4),0)+AF15 -> 0 | P15: =+ROUND(H15*H$4/(100+H$4),0)+AG15 -> 0 | Q15: =+ROUND(I15*I$4/(100+I$4),0)+AH15 -> 0 | R15: =+ROUND(J15*J$4/(100+J$4),0)+AI15 -> 95804 | S15: =SUM(N15:R15) -> 95804 | T15: =+E15-S15 -> 958034 | U15: =N15-F15*F$4/(100+F$4) -> 0 | V15: =O15-G15*G$4/(100+G$4) -> 0 | W15: =P15-H15*H$4/(100+H$4) -> 0 | X15: =Q15-I15*I$4/(100+I$4) -> 0 | Y15: =R15-J15*J$4/(100+J$4) -> 0.54545455 | Z15: =+IF(N$43=0,0,IF(N$43<0,-RANK(U15,U$5:U$40,0),RANK(U15,U$5:U$40,1))) -> 0 | AA15: =+IF(O$43=0,0,IF(O$43<0,-RANK(V15,V$5:V$40,0),RANK(V15,V$5:V$40,1))) -> 0 | AB15: =+IF(P$43=0,0,IF(P$43<0,-RANK(W15,W$5:W$40,0),RANK(W15,W$5:W$40,1))) -> 0 | AC15: =+IF(Q$43=0,0,IF(Q$43<0,-RANK(X15,X$5:X$40,0),RANK(X15,X$5:X$40,1))) -> 0 | AD15: =+IF(R$43=0,0,IF(R$43<0,-RANK(Y15,Y$5:Y$40,0),RANK(Y15,Y$5:Y$40,1))) -> 0 | AI15: 1
A16: 1 | B16: 6153215 | D16: 光熱水費 | E16: =+IF($A16="",IF($C16="",SUMIFS([1]全伝票!I:I,[1]全伝票!$B:$B,$B16),SUMIFS([1]全伝票!I:I,[1]全伝票!$C:$C,$C16)),IF($C16="",SUMIFS([1]全伝票!I:I,[1]全伝票!$A:$A,$A16,[1]全伝票!$B:$B,$B16),SUMIFS([1]全伝票!I:I,[1]全伝票!$A:$A,$A16,[1]全伝票!$C:$C,$C16))) -> 0 | F16: =+IF($A16="",IF($C16="",SUMIFS([1]全伝票!J:J,[1]全伝票!$B:$B,$B16),SUMIFS([1]全伝票!J:J,[1]全伝票!$C:$C,$C16)),IF($C16="",SUMIFS([1]全伝票!J:J,[1]全伝票!$A:$A,$A16,[1]全伝票!$B:$B,$B16),SUMIFS([1]全伝票!J:J,[1]全伝票!$A:$A,$A16,[1]全伝票!$C:$C,$C16))) -> 0 | G16: =+IF($A16="",IF($C16="",SUMIFS([1]全伝票!K:K,[1]全伝票!$B:$B,$B16),SUMIFS([1]全伝票!K:K,[1]全伝票!$C:$C,$C16)),IF($C16="",SUMIFS([1]全伝票!K:K,[1]全伝票!$A:$A,$A16,[1]全伝票!$B:$B,$B16),SUMIFS([1]全伝票!K:K,[1]全伝票!$A:$A,$A16,[1]全伝票!$C:$C,$C16))) -> 0 | H16: =+IF($A16="",IF($C16="",SUMIFS([1]全伝票!L:L,[1]全伝票!$B:$B,$B16),SUMIFS([1]全伝票!L:L,[1]全伝票!$C:$C,$C16)),IF($C16="",SUMIFS([1]全伝票!L:L,[1]全伝票!$A:$A,$A16,[1]全伝票!$B:$B,$B16),SUMIFS([1]全伝票!L:L,[1]全伝票!$A:$A,$A16,[1]全伝票!$C:$C,$C16))) -> 0 | I16: =+IF($A16="",IF($C16="",SUMIFS([1]全伝票!M:M,[1]全伝票!$B:$B,$B16),SUMIFS([1]全伝票!M:M,[1]全伝票!$C:$C,$C16)),IF($C16="",SUMIFS([1]全伝票!M:M,[1]全伝票!$A:$A,$A16,[1]全伝票!$B:$B,$B16),SUMIFS([1]全伝票!M:M,[1]全伝票!$A:$A,$A16,[1]全伝票!$C:$C,$C16))) -> 0 | J16: =+IF($A16="",IF($C16="",SUMIFS([1]全伝票!N:N,[1]全伝票!$B:$B,$B16),SUMIFS([1]全伝票!N:N,[1]全伝票!$C:$C,$C16)),IF($C16="",SUMIFS([1]全伝票!N:N,[1]全伝票!$A:$A,$A16,[1]全伝票!$B:$B,$B16),SUMIFS([1]全伝票!N:N,[1]全伝票!$A:$A,$A16,[1]全伝票!$C:$C,$C16))) -> 0 | K16: =SUM(F16:J16) -> 0 | L16: =+IF($A16="",IF($C16="",SUMIFS([1]全伝票!O:O,[1]全伝票!$B:$B,$B16),SUMIFS([1]全伝票!O:O,[1]全伝票!$C:$C,$C16)),IF($C16="",SUMIFS([1]全伝票!O:O,[1]全伝票!$A:$A,$A16,[1]全伝票!$B:$B,$B16),SUMIFS([1]全伝票!O:O,[1]全伝票!$A:$A,$A16,[1]全伝票!$C:$C,$C16))) -> 0 | M16: =+IF($A16="",IF($C16="",SUMIFS([1]全伝票!P:P,[1]全伝票!$B:$B,$B16),SUMIFS([1]全伝票!P:P,[1]全伝票!$C:$C,$C16)),IF($C16="",SUMIFS([1]全伝票!P:P,[1]全伝票!$A:$A,$A16,[1]全伝票!$B:$B,$B16),SUMIFS([1]全伝票!P:P,[1]全伝票!$A:$A,$A16,[1]全伝票!$C:$C,$C16))) -> 0 | N16: =+ROUND(F16*F$4/(100+F$4),0)+AE16 -> 0 | O16: =+ROUND(G16*G$4/(100+G$4),0)+AF16 -> 0 | P16: =+ROUND(H16*H$4/(100+H$4),0)+AG16 -> 0 | Q16: =+ROUND(I16*I$4/(100+I$4),0)+AH16 -> 0 | R16: =+ROUND(J16*J$4/(100+J$4),0)+AI16 -> 0 | S16: =SUM(N16:R16) -> 0 | T16: =+E16-S16 -> 0 | U16: =N16-F16*F$4/(100+F$4) -> 0 | V16: =O16-G16*G$4/(100+G$4) -> 0 | W16: =P16-H16*H$4/(100+H$4) -> 0 | X16: =Q16-I16*I$4/(100+I$4) -> 0 | Y16: =R16-J16*J$4/(100+J$4) -> 0 | Z16: =+IF(N$43=0,0,IF(N$43<0,-RANK(U16,U$5:U$40,0),RANK(U16,U$5:U$40,1))) -> 0 | AA16: =+IF(O$43=0,0,IF(O$43<0,-RANK(V16,V$5:V$40,0),RANK(V16,V$5:V$40,1))) -> 0 | AB16: =+IF(P$43=0,0,IF(P$43<0,-RANK(W16,W$5:W$40,0),RANK(W16,W$5:W$40,1))) -> 0 | AC16: =+IF(Q$43=0,0,IF(Q$43<0,-RANK(X16,X$5:X$40,0),RANK(X16,X$5:X$40,1))) -> 0 | AD16: =+IF(R$43=0,0,IF(R$43<0,-RANK(Y16,Y$5:Y$40,0),RANK(Y16,Y$5:Y$40,1))) -> 0
A17: 1 | B17: 6153217 | D17: 通信運搬費 | E17: =+IF($A17="",IF($C17="",SUMIFS([1]全伝票!I:I,[1]全伝票!$B:$B,$B17),SUMIFS([1]全伝票!I:I,[1]全伝票!$C:$C,$C17)),IF($C17="",SUMIFS([1]全伝票!I:I,[1]全伝票!$A:$A,$A17,[1]全伝票!$B:$B,$B17),SUMIFS([1]全伝票!I:I,[1]全伝票!$A:$A,$A17,[1]全伝票!$C:$C,$C17))) -> 2423102 | F17: =+IF($A17="",IF($C17="",SUMIFS([1]全伝票!J:J,[1]全伝票!$B:$B,$B17),SUMIFS([1]全伝票!J:J,[1]全伝票!$C:$C,$C17)),IF($C17="",SUMIFS([1]全伝票!J:J,[1]全伝票!$A:$A,$A17,[1]全伝票!$B:$B,$B17),SUMIFS([1]全伝票!J:J,[1]全伝票!$A:$A,$A17,[1]全伝票!$C:$C,$C17))) -> 0 | G17: =+IF($A17="",IF($C17="",SUMIFS([1]全伝票!K:K,[1]全伝票!$B:$B,$B17),SUMIFS([1]全伝票!K:K,[1]全伝票!$C:$C,$C17)),IF($C17="",SUMIFS([1]全伝票!K:K,[1]全伝票!$A:$A,$A17,[1]全伝票!$B:$B,$B17),SUMIFS([1]全伝票!K:K,[1]全伝票!$A:$A,$A17,[1]全伝票!$C:$C,$C17))) -> 0 | H17: =+IF($A17="",IF($C17="",SUMIFS([1]全伝票!L:L,[1]全伝票!$B:$B,$B17),SUMIFS([1]全伝票!L:L,[1]全伝票!$C:$C,$C17)),IF($C17="",SUMIFS([1]全伝票!L:L,[1]全伝票!$A:$A,$A17,[1]全伝票!$B:$B,$B17),SUMIFS([1]全伝票!L:L,[1]全伝票!$A:$A,$A17,[1]全伝票!$C:$C,$C17))) -> 0 | I17: =+IF($A17="",IF($C17="",SUMIFS([1]全伝票!M:M,[1]全伝票!$B:$B,$B17),SUMIFS([1]全伝票!M:M,[1]全伝票!$C:$C,$C17)),IF($C17="",SUMIFS([1]全伝票!M:M,[1]全伝票!$A:$A,$A17,[1]全伝票!$B:$B,$B17),SUMIFS([1]全伝票!M:M,[1]全伝票!$A:$A,$A17,[1]全伝票!$C:$C,$C17))) -> 0 | J17: =+IF($A17="",IF($C17="",SUMIFS([1]全伝票!N:N,[1]全伝票!$B:$B,$B17),SUMIFS([1]全伝票!N:N,[1]全伝票!$C:$C,$C17)),IF($C17="",SUMIFS([1]全伝票!N:N,[1]全伝票!$A:$A,$A17,[1]全伝票!$B:$B,$B17),SUMIFS([1]全伝票!N:N,[1]全伝票!$A:$A,$A17,[1]全伝票!$C:$C,$C17))) -> 2423102 | K17: =SUM(F17:J17) -> 2423102 | L17: =+IF($A17="",IF($C17="",SUMIFS([1]全伝票!O:O,[1]全伝票!$B:$B,$B17),SUMIFS([1]全伝票!O:O,[1]全伝票!$C:$C,$C17)),IF($C17="",SUMIFS([1]全伝票!O:O,[1]全伝票!$A:$A,$A17,[1]全伝票!$B:$B,$B17),SUMIFS([1]全伝票!O:O,[1]全伝票!$A:$A,$A17,[1]全伝票!$C:$C,$C17))) -> 0 | M17: =+IF($A17="",IF($C17="",SUMIFS([1]全伝票!P:P,[1]全伝票!$B:$B,$B17),SUMIFS([1]全伝票!P:P,[1]全伝票!$C:$C,$C17)),IF($C17="",SUMIFS([1]全伝票!P:P,[1]全伝票!$A:$A,$A17,[1]全伝票!$B:$B,$B17),SUMIFS([1]全伝票!P:P,[1]全伝票!$A:$A,$A17,[1]全伝票!$C:$C,$C17))) -> 0 | N17: =+ROUND(F17*F$4/(100+F$4),0)+AE17 -> 0 | O17: =+ROUND(G17*G$4/(100+G$4),0)+AF17 -> 0 | P17: =+ROUND(H17*H$4/(100+H$4),0)+AG17 -> 0 | Q17: =+ROUND(I17*I$4/(100+I$4),0)+AH17 -> 0 | R17: =+ROUND(J17*J$4/(100+J$4),0)+AI17 -> 220282 | S17: =SUM(N17:R17) -> 220282 | T17: =+E17-S17 -> 2202820 | U17: =N17-F17*F$4/(100+F$4) -> 0 | V17: =O17-G17*G$4/(100+G$4) -> 0 | W17: =P17-H17*H$4/(100+H$4) -> 0 | X17: =Q17-I17*I$4/(100+I$4) -> 0 | Y17: =R17-J17*J$4/(100+J$4) -> 0 | Z17: =+IF(N$43=0,0,IF(N$43<0,-RANK(U17,U$5:U$40,0),RANK(U17,U$5:U$40,1))) -> 0 | AA17: =+IF(O$43=0,0,IF(O$43<0,-RANK(V17,V$5:V$40,0),RANK(V17,V$5:V$40,1))) -> 0 | AB17: =+IF(P$43=0,0,IF(P$43<0,-RANK(W17,W$5:W$40,0),RANK(W17,W$5:W$40,1))) -> 0 | AC17: =+IF(Q$43=0,0,IF(Q$43<0,-RANK(X17,X$5:X$40,0),RANK(X17,X$5:X$40,1))) -> 0 | AD17: =+IF(R$43=0,0,IF(R$43<0,-RANK(Y17,Y$5:Y$40,0),RANK(Y17,Y$5:Y$40,1))) -> 0
A18: 1 | B18: 6153219 | D18: 手数料 | E18: =+IF($A18="",IF($C18="",SUMIFS([1]全伝票!I:I,[1]全伝票!$B:$B,$B18),SUMIFS([1]全伝票!I:I,[1]全伝票!$C:$C,$C18)),IF($C18="",SUMIFS([1]全伝票!I:I,[1]全伝票!$A:$A,$A18,[1]全伝票!$B:$B,$B18),SUMIFS([1]全伝票!I:I,[1]全伝票!$A:$A,$A18,[1]全伝票!$C:$C,$C18))) -> 357250 | F18: =+IF($A18="",IF($C18="",SUMIFS([1]全伝票!J:J,[1]全伝票!$B:$B,$B18),SUMIFS([1]全伝票!J:J,[1]全伝票!$C:$C,$C18)),IF($C18="",SUMIFS([1]全伝票!J:J,[1]全伝票!$A:$A,$A18,[1]全伝票!$B:$B,$B18),SUMIFS([1]全伝票!J:J,[1]全伝票!$A:$A,$A18,[1]全伝票!$C:$C,$C18))) -> 0 | G18: =+IF($A18="",IF($C18="",SUMIFS([1]全伝票!K:K,[1]全伝票!$B:$B,$B18),SUMIFS([1]全伝票!K:K,[1]全伝票!$C:$C,$C18)),IF($C18="",SUMIFS([1]全伝票!K:K,[1]全伝票!$A:$A,$A18,[1]全伝票!$B:$B,$B18),SUMIFS([1]全伝票!K:K,[1]全伝票!$A:$A,$A18,[1]全伝票!$C:$C,$C18))) -> 0 | H18: =+IF($A18="",IF($C18="",SUMIFS([1]全伝票!L:L,[1]全伝票!$B:$B,$B18),SUMIFS([1]全伝票!L:L,[1]全伝票!$C:$C,$C18)),IF($C18="",SUMIFS([1]全伝票!L:L,[1]全伝票!$A:$A,$A18,[1]全伝票!$B:$B,$B18),SUMIFS([1]全伝票!L:L,[1]全伝票!$A:$A,$A18,[1]全伝票!$C:$C,$C18))) -> 0 | I18: =+IF($A18="",IF($C18="",SUMIFS([1]全伝票!M:M,[1]全伝票!$B:$B,$B18),SUMIFS([1]全伝票!M:M,[1]全伝票!$C:$C,$C18)),IF($C18="",SUMIFS([1]全伝票!M:M,[1]全伝票!$A:$A,$A18,[1]全伝票!$B:$B,$B18),SUMIFS([1]全伝票!M:M,[1]全伝票!$A:$A,$A18,[1]全伝票!$C:$C,$C18))) -> 0 | J18: =+IF($A18="",IF($C18="",SUMIFS([1]全伝票!N:N,[1]全伝票!$B:$B,$B18),SUMIFS([1]全伝票!N:N,[1]全伝票!$C:$C,$C18)),IF($C18="",SUMIFS([1]全伝票!N:N,[1]全伝票!$A:$A,$A18,[1]全伝票!$B:$B,$B18),SUMIFS([1]全伝票!N:N,[1]全伝票!$A:$A,$A18,[1]全伝票!$C:$C,$C18))) -> 290850 | K18: =SUM(F18:J18) -> 290850 | L18: =+IF($A18="",IF($C18="",SUMIFS([1]全伝票!O:O,[1]全伝票!$B:$B,$B18),SUMIFS([1]全伝票!O:O,[1]全伝票!$C:$C,$C18)),IF($C18="",SUMIFS([1]全伝票!O:O,[1]全伝票!$A:$A,$A18,[1]全伝票!$B:$B,$B18),SUMIFS([1]全伝票!O:O,[1]全伝票!$A:$A,$A18,[1]全伝票!$C:$C,$C18))) -> 66400 | M18: =+IF($A18="",IF($C18="",SUMIFS([1]全伝票!P:P,[1]全伝票!$B:$B,$B18),SUMIFS([1]全伝票!P:P,[1]全伝票!$C:$C,$C18)),IF($C18="",SUMIFS([1]全伝票!P:P,[1]全伝票!$A:$A,$A18,[1]全伝票!$B:$B,$B18),SUMIFS([1]全伝票!P:P,[1]全伝票!$A:$A,$A18,[1]全伝票!$C:$C,$C18))) -> 0 | N18: =+ROUND(F18*F$4/(100+F$4),0)+AE18 -> 0 | O18: =+ROUND(G18*G$4/(100+G$4),0)+AF18 -> 0 | P18: =+ROUND(H18*H$4/(100+H$4),0)+AG18 -> 0 | Q18: =+ROUND(I18*I$4/(100+I$4),0)+AH18 -> 0 | R18: =+ROUND(J18*J$4/(100+J$4),0)+AI18 -> 26441 | S18: =SUM(N18:R18) -> 26441 | T18: =+E18-S18 -> 330809 | U18: =N18-F18*F$4/(100+F$4) -> 0 | V18: =O18-G18*G$4/(100+G$4) -> 0 | W18: =P18-H18*H$4/(100+H$4) -> 0 | X18: =Q18-I18*I$4/(100+I$4) -> 0 | Y18: =R18-J18*J$4/(100+J$4) -> 0.090909091 | Z18: =+IF(N$43=0,0,IF(N$43<0,-RANK(U18,U$5:U$40,0),RANK(U18,U$5:U$40,1))) -> 0 | AA18: =+IF(O$43=0,0,IF(O$43<0,-RANK(V18,V$5:V$40,0),RANK(V18,V$5:V$40,1))) -> 0 | AB18: =+IF(P$43=0,0,IF(P$43<0,-RANK(W18,W$5:W$40,0),RANK(W18,W$5:W$40,1))) -> 0 | AC18: =+IF(Q$43=0,0,IF(Q$43<0,-RANK(X18,X$5:X$40,0),RANK(X18,X$5:X$40,1))) -> 0 | AD18: =+IF(R$43=0,0,IF(R$43<0,-RANK(Y18,Y$5:Y$40,0),RANK(Y18,Y$5:Y$40,1))) -> 0
A19: 1 | B19: 6153220 | D19: 賃借料 | E19: =+IF($A19="",IF($C19="",SUMIFS([1]全伝票!I:I,[1]全伝票!$B:$B,$B19),SUMIFS([1]全伝票!I:I,[1]全伝票!$C:$C,$C19)),IF($C19="",SUMIFS([1]全伝票!I:I,[1]全伝票!$A:$A,$A19,[1]全伝票!$B:$B,$B19),SUMIFS([1]全伝票!I:I,[1]全伝票!$A:$A,$A19,[1]全伝票!$C:$C,$C19))) -> 13483332 | F19: =+IF($A19="",IF($C19="",SUMIFS([1]全伝票!J:J,[1]全伝票!$B:$B,$B19),SUMIFS([1]全伝票!J:J,[1]全伝票!$C:$C,$C19)),IF($C19="",SUMIFS([1]全伝票!J:J,[1]全伝票!$A:$A,$A19,[1]全伝票!$B:$B,$B19),SUMIFS([1]全伝票!J:J,[1]全伝票!$A:$A,$A19,[1]全伝票!$C:$C,$C19))) -> 0 | G19: =+IF($A19="",IF($C19="",SUMIFS([1]全伝票!K:K,[1]全伝票!$B:$B,$B19),SUMIFS([1]全伝票!K:K,[1]全伝票!$C:$C,$C19)),IF($C19="",SUMIFS([1]全伝票!K:K,[1]全伝票!$A:$A,$A19,[1]全伝票!$B:$B,$B19),SUMIFS([1]全伝票!K:K,[1]全伝票!$A:$A,$A19,[1]全伝票!$C:$C,$C19))) -> 0 | H19: =+IF($A19="",IF($C19="",SUMIFS([1]全伝票!L:L,[1]全伝票!$B:$B,$B19),SUMIFS([1]全伝票!L:L,[1]全伝票!$C:$C,$C19)),IF($C19="",SUMIFS([1]全伝票!L:L,[1]全伝票!$A:$A,$A19,[1]全伝票!$B:$B,$B19),SUMIFS([1]全伝票!L:L,[1]全伝票!$A:$A,$A19,[1]全伝票!$C:$C,$C19))) -> 125712 | I19: =+IF($A19="",IF($C19="",SUMIFS([1]全伝票!M:M,[1]全伝票!$B:$B,$B19),SUMIFS([1]全伝票!M:M,[1]全伝票!$C:$C,$C19)),IF($C19="",SUMIFS([1]全伝票!M:M,[1]全伝票!$A:$A,$A19,[1]全伝票!$B:$B,$B19),SUMIFS([1]全伝票!M:M,[1]全伝票!$A:$A,$A19,[1]全伝票!$C:$C,$C19))) -> 0 | J19: =+IF($A19="",IF($C19="",SUMIFS([1]全伝票!N:N,[1]全伝票!$B:$B,$B19),SUMIFS([1]全伝票!N:N,[1]全伝票!$C:$C,$C19)),IF($C19="",SUMIFS([1]全伝票!N:N,[1]全伝票!$A:$A,$A19,[1]全伝票!$B:$B,$B19),SUMIFS([1]全伝票!N:N,[1]全伝票!$A:$A,$A19,[1]全伝票!$C:$C,$C19))) -> 7866081 | K19: =SUM(F19:J19) -> 7991793 | L19: =+IF($A19="",IF($C19="",SUMIFS([1]全伝票!O:O,[1]全伝票!$B:$B,$B19),SUMIFS([1]全伝票!O:O,[1]全伝票!$C:$C,$C19)),IF($C19="",SUMIFS([1]全伝票!O:O,[1]全伝票!$A:$A,$A19,[1]全伝票!$B:$B,$B19),SUMIFS([1]全伝票!O:O,[1]全伝票!$A:$A,$A19,[1]全伝票!$C:$C,$C19))) -> 5491539 | M19: =+IF($A19="",IF($C19="",SUMIFS([1]全伝票!P:P,[1]全伝票!$B:$B,$B19),SUMIFS([1]全伝票!P:P,[1]全伝票!$C:$C,$C19)),IF($C19="",SUMIFS([1]全伝票!P:P,[1]全伝票!$A:$A,$A19,[1]全伝票!$B:$B,$B19),SUMIFS([1]全伝票!P:P,[1]全伝票!$A:$A,$A19,[1]全伝票!$C:$C,$C19))) -> 0 | N19: =+ROUND(F19*F$4/(100+F$4),0)+AE19 -> 0 | O19: =+ROUND(G19*G$4/(100+G$4),0)+AF19 -> 0 | P19: =+ROUND(H19*H$4/(100+H$4),0)+AG19 -> 9312 | Q19: =+ROUND(I19*I$4/(100+I$4),0)+AH19 -> 0 | R19: =+ROUND(J19*J$4/(100+J$4),0)+AI19 -> 715098 | S19: =SUM(N19:R19) -> 724410 | T19: =+E19-S19 -> 12758922 | U19: =N19-F19*F$4/(100+F$4) -> 0 | V19: =O19-G19*G$4/(100+G$4) -> 0 | W19: =P19-H19*H$4/(100+H$4) -> 0 | X19: =Q19-I19*I$4/(100+I$4) -> 0 | Y19: =R19-J19*J$4/(100+J$4) -> -0.27272727 | Z19: =+IF(N$43=0,0,IF(N$43<0,-RANK(U19,U$5:U$40,0),RANK(U19,U$5:U$40,1))) -> 0 | AA19: =+IF(O$43=0,0,IF(O$43<0,-RANK(V19,V$5:V$40,0),RANK(V19,V$5:V$40,1))) -> 0 | AB19: =+IF(P$43=0,0,IF(P$43<0,-RANK(W19,W$5:W$40,0),RANK(W19,W$5:W$40,1))) -> 0 | AC19: =+IF(Q$43=0,0,IF(Q$43<0,-RANK(X19,X$5:X$40,0),RANK(X19,X$5:X$40,1))) -> 0 | AD19: =+IF(R$43=0,0,IF(R$43<0,-RANK(Y19,Y$5:Y$40,0),RANK(Y19,Y$5:Y$40,1))) -> 0
A20: 1 | B20: 6153221 | D20: 委託料 | E20: =+IF($A20="",IF($C20="",SUMIFS([1]全伝票!I:I,[1]全伝票!$B:$B,$B20),SUMIFS([1]全伝票!I:I,[1]全伝票!$C:$C,$C20)),IF($C20="",SUMIFS([1]全伝票!I:I,[1]全伝票!$A:$A,$A20,[1]全伝票!$B:$B,$B20),SUMIFS([1]全伝票!I:I,[1]全伝票!$A:$A,$A20,[1]全伝票!$C:$C,$C20))) -> 85827500 | F20: =+IF($A20="",IF($C20="",SUMIFS([1]全伝票!J:J,[1]全伝票!$B:$B,$B20),SUMIFS([1]全伝票!J:J,[1]全伝票!$C:$C,$C20)),IF($C20="",SUMIFS([1]全伝票!J:J,[1]全伝票!$A:$A,$A20,[1]全伝票!$B:$B,$B20),SUMIFS([1]全伝票!J:J,[1]全伝票!$A:$A,$A20,[1]全伝票!$C:$C,$C20))) -> 0 | G20: =+IF($A20="",IF($C20="",SUMIFS([1]全伝票!K:K,[1]全伝票!$B:$B,$B20),SUMIFS([1]全伝票!K:K,[1]全伝票!$C:$C,$C20)),IF($C20="",SUMIFS([1]全伝票!K:K,[1]全伝票!$A:$A,$A20,[1]全伝票!$B:$B,$B20),SUMIFS([1]全伝票!K:K,[1]全伝票!$A:$A,$A20,[1]全伝票!$C:$C,$C20))) -> 0 | H20: =+IF($A20="",IF($C20="",SUMIFS([1]全伝票!L:L,[1]全伝票!$B:$B,$B20),SUMIFS([1]全伝票!L:L,[1]全伝票!$C:$C,$C20)),IF($C20="",SUMIFS([1]全伝票!L:L,[1]全伝票!$A:$A,$A20,[1]全伝票!$B:$B,$B20),SUMIFS([1]全伝票!L:L,[1]全伝票!$A:$A,$A20,[1]全伝票!$C:$C,$C20))) -> 0 | I20: =+IF($A20="",IF($C20="",SUMIFS([1]全伝票!M:M,[1]全伝票!$B:$B,$B20),SUMIFS([1]全伝票!M:M,[1]全伝票!$C:$C,$C20)),IF($C20="",SUMIFS([1]全伝票!M:M,[1]全伝票!$A:$A,$A20,[1]全伝票!$B:$B,$B20),SUMIFS([1]全伝票!M:M,[1]全伝票!$A:$A,$A20,[1]全伝票!$C:$C,$C20))) -> 0 | J20: =+IF($A20="",IF($C20="",SUMIFS([1]全伝票!N:N,[1]全伝票!$B:$B,$B20),SUMIFS([1]全伝票!N:N,[1]全伝票!$C:$C,$C20)),IF($C20="",SUMIFS([1]全伝票!N:N,[1]全伝票!$A:$A,$A20,[1]全伝票!$B:$B,$B20),SUMIFS([1]全伝票!N:N,[1]全伝票!$A:$A,$A20,[1]全伝票!$C:$C,$C20))) -> 85827500 | K20: =SUM(F20:J20) -> 85827500 | L20: =+IF($A20="",IF($C20="",SUMIFS([1]全伝票!O:O,[1]全伝票!$B:$B,$B20),SUMIFS([1]全伝票!O:O,[1]全伝票!$C:$C,$C20)),IF($C20="",SUMIFS([1]全伝票!O:O,[1]全伝票!$A:$A,$A20,[1]全伝票!$B:$B,$B20),SUMIFS([1]全伝票!O:O,[1]全伝票!$A:$A,$A20,[1]全伝票!$C:$C,$C20))) -> 0 | M20: =+IF($A20="",IF($C20="",SUMIFS([1]全伝票!P:P,[1]全伝票!$B:$B,$B20),SUMIFS([1]全伝票!P:P,[1]全伝票!$C:$C,$C20)),IF($C20="",SUMIFS([1]全伝票!P:P,[1]全伝票!$A:$A,$A20,[1]全伝票!$B:$B,$B20),SUMIFS([1]全伝票!P:P,[1]全伝票!$A:$A,$A20,[1]全伝票!$C:$C,$C20))) -> 0 | N20: =+ROUND(F20*F$4/(100+F$4),0)+AE20 -> 0 | O20: =+ROUND(G20*G$4/(100+G$4),0)+AF20 -> 0 | P20: =+ROUND(H20*H$4/(100+H$4),0)+AG20 -> 0 | Q20: =+ROUND(I20*I$4/(100+I$4),0)+AH20 -> 0 | R20: =+ROUND(J20*J$4/(100+J$4),0)+AI20 -> 7802500 | S20: =SUM(N20:R20) -> 7802500 | T20: =+E20-S20 -> 78025000 | U20: =N20-F20*F$4/(100+F$4) -> 0 | V20: =O20-G20*G$4/(100+G$4) -> 0 | W20: =P20-H20*H$4/(100+H$4) -> 0 | X20: =Q20-I20*I$4/(100+I$4) -> 0 | Y20: =R20-J20*J$4/(100+J$4) -> 0 | Z20: =+IF(N$43=0,0,IF(N$43<0,-RANK(U20,U$5:U$40,0),RANK(U20,U$5:U$40,1))) -> 0 | AA20: =+IF(O$43=0,0,IF(O$43<0,-RANK(V20,V$5:V$40,0),RANK(V20,V$5:V$40,1))) -> 0 | AB20: =+IF(P$43=0,0,IF(P$43<0,-RANK(W20,W$5:W$40,0),RANK(W20,W$5:W$40,1))) -> 0 | AC20: =+IF(Q$43=0,0,IF(Q$43<0,-RANK(X20,X$5:X$40,0),RANK(X20,X$5:X$40,1))) -> 0 | AD20: =+IF(R$43=0,0,IF(R$43<0,-RANK(Y20,Y$5:Y$40,0),RANK(Y20,Y$5:Y$40,1))) -> 0
