Workbook

Sheet 4条収入
D1: =+'[1]3条支出'!$D$1 -> 令和５年度決算 消費税算出資料
D2: 【４条収入内訳】
A3: 事業 | B3: 節 | C3: 細節 | D3: 費目 | E3: 税込決算額 | F3: 課税売上げ | L3: 非課税 売上げ | M3: 免税 売上げ | N3: 不課税収入（資産の譲渡等の対価以外の収入（対価性のない収入）） | W3: 仮受消費税 | AC3: 特定収入に係る課税仕入れ等に係る消費税額 | AI3: 税抜決算額 | AJ3: 仮受け消費税の調整 | AY3: 課税支出に係る特定収入に係る消費税の調整
N4: 特定収入 | U4: 特定収入以外 の不課税収入
N5: 課税仕入れ等に係る特定収入 | T5: 課税仕入れ等に係る特定収入以外 | V5: 計 | AJ5: 消費税 端数確認 | AO5: 消費税端数調整ランク | AT5: 消費税 調整額 | AY5: 消費税 端数確認 | BD5: 消費税端数調整ランク | BI5: 消費税 調整額
F6: 3 | G6: 5 | H6: 8 | I6: 8 | J6: 10 | K6: 計 | N6: 3 | O6: 5 | P6: 8 | Q6: 8 | R6: 10 | S6: 計 | W6: 3 | X6: 5 | Y6: 8 | Z6: 8 | AA6: 10 | AB6: 計 | AC6: 3 | AD6: 5 | AE6: 8 | AF6: 8 | AG6: 10 | AH6: 計 | AJ6: 3 | AK6: 5 | AL6: 8 | AM6: 8 | AN6: 10 | AO6: 3 | AP6: 5 | AQ6: 8 | AR6: 8 | AS6: 10 | AT6: 3 | AU6: 5 | AV6: 8 | AW6: 8 | AX6: 10 | AY6: 3 | AZ6: 5 | BA6: 8 | BB6: 8 | BC6: 10 | BD6: 3 | BE6: 5 | BF6: 8 | BG6: 8 | BH6: 10 | BI6: 3 | BJ6: 5 | BK6: 8 | BL6: 8 | BM6: 10
D7: 企業債 | E7: =+SUM(E8,E16,E20) -> 32373300000 | F7: =+SUM(F8,F16,F20) -> 0 | G7: =+SUM(G8,G16,G20) -> 0 | H7: =+SUM(H8,H16,H20) -> 0 | I7: =+SUM(I8,I16,I20) -> 0 | J7: =+SUM(J8,J16,J20) -> 0 | K7: =+SUM(K8,K16,K20) -> 0 | L7: =+SUM(L8,L16,L20) -> 0 | ... AI7: =+SUM(AI8,AI16,AI20) -> 32373300000
D8: 建設企業債 | E8: =+SUM(E9,E12:E15) -> 15365600000 | F8: =+SUM(F9,F12:F15) -> 0 | G8: =+SUM(G9,G12:G15) -> 0 | H8: =+SUM(H9,H12:H15) -> 0 | I8: =+SUM(I9,I12:I15) -> 0 | J8: =+SUM(J9,J12:J15) -> 0 | K8: =+SUM(K9,K12:K15) -> 0 | L8: =+SUM(L9,L12:L15) -> 0 | ... AI8: =+SUM(AI9,AI12:AI15) -> 15365600000
D9: 公共下水道事業債 | E9: =+SUM(E10:E11) -> 8822500000 | F9: =+SUM(F10:F11) -> 0 | G9: =+SUM(G10:G11) -> 0 | H9: =+SUM(H10:H11) -> 0 | I9: =+SUM(I10:I11) -> 0 | J9: =+SUM(J10:J11) -> 0 | K9: =+SUM(K10:K11) -> 0 | L9: =+SUM(L10:L11) -> 0 | ... AI9: =+SUM(AI10:AI11) -> 8822500000
C10: 112011010 | D10: 一般債 | E10: =+SUMIFS([1]全伝票!I:I,[1]全伝票!$C:$C,$C10) -> 8822500000 | K10: =SUM(F10:J10) -> 0 | S10: =SUM(N10:R10) -> 0 | U10: =+V10-SUM(S10:T10) -> 8822500000 | V10: =+SUMIFS([1]全伝票!P:P,[1]全伝票!$C:$C,$C10) -> 8822500000 | W10: =+ROUND(F10*F$6/(100+F$6),0)+AT10 -> 0 | X10: =+ROUND(G10*G$6/(100+G$6),0)+AU10 -> 0 | Y10: =+ROUND(H10*H$6/(100+H$6),0)+AV10 -> 0 | Z10: =+ROUND(I10*I$6/(100+I$6),0)+AW10 -> 0 | AA10: =+ROUND(J10*J$6/(100+J$6),0)+AX10 -> 0 | AB10: =SUM(W10:AA10) -> 0 | AC10: =+ROUND(N10*AC$6/(100+AC$6),0)+BI10 -> 0 | AD10: =+ROUND(O10*AD$6/(100+AD$6),0)+BJ10 -> 0 | AE10: =+ROUND(P10*AE$6/(100+AE$6),0)+BK10 -> 0 | AF10: =+ROUND(Q10*AF$6/(100+AF$6),0)+BL10 -> 0 | AG10: =+ROUND(R10*AG$6/(100+AG$6),0)+BM10 -> 0 | AH10: =SUM(AC10:AG10) -> 0 | AI10: =+E10-AB10 -> 8822500000
C11: 112011011 | D11: 特別債 | E11: =+SUMIFS([1]全伝票!I:I,[1]全伝票!$C:$C,$C11) -> 0 | K11: =SUM(F11:J11) -> 0 | S11: =SUM(N11:R11) -> 0 | U11: =+V11-SUM(S11:T11) -> 0 | V11: =+SUMIFS([1]全伝票!P:P,[1]全伝票!$C:$C,$C11) -> 0 | W11: =+ROUND(F11*F$6/(100+F$6),0)+AT11 -> 0 | X11: =+ROUND(G11*G$6/(100+G$6),0)+AU11 -> 0 | Y11: =+ROUND(H11*H$6/(100+H$6),0)+AV11 -> 0 | Z11: =+ROUND(I11*I$6/(100+I$6),0)+AW11 -> 0 | AA11: =+ROUND(J11*J$6/(100+J$6),0)+AX11 -> 0 | AB11: =SUM(W11:AA11) -> 0 | AC11: =+ROUND(N11*AC$6/(100+AC$6),0)+BI11 -> 0 | AD11: =+ROUND(O11*AD$6/(100+AD$6),0)+BJ11 -> 0 | AE11: =+ROUND(P11*AE$6/(100+AE$6),0)+BK11 -> 0 | AF11: =+ROUND(Q11*AF$6/(100+AF$6),0)+BL11 -> 0 | AG11: =+ROUND(R11*AG$6/(100+AG$6),0)+BM11 -> 0 | AH11: =SUM(AC11:AG11) -> 0 | AI11: =+E11-AB11 -> 0
C12: 112011500 | D12: 市街化区域外事業債 | E12: =+SUMIFS([1]全伝票!I:I,[1]全伝票!$C:$C,$C12) -> 493400000 | K12: =SUM(F12:J12) -> 0 | S12: =SUM(N12:R12) -> 0 | U12: =+V12-SUM(S12:T12) -> 493400000 | V12: =+SUMIFS([1]全伝票!P:P,[1]全伝票!$C:$C,$C12) -> 493400000 | W12: =+ROUND(F12*F$6/(100+F$6),0)+AT12 -> 0 | X12: =+ROUND(G12*G$6/(100+G$6),0)+AU12 -> 0 | Y12: =+ROUND(H12*H$6/(100+H$6),0)+AV12 -> 0 | Z12: =+ROUND(I12*I$6/(100+I$6),0)+AW12 -> 0 | AA12: =+ROUND(J12*J$6/(100+J$6),0)+AX12 -> 0 | AB12: =SUM(W12:AA12) -> 0 | AC12: =+ROUND(N12*AC$6/(100+AC$6),0)+BI12 -> 0 | AD12: =+ROUND(O12*AD$6/(100+AD$6),0)+BJ12 -> 0 | AE12: =+ROUND(P12*AE$6/(100+AE$6),0)+BK12 -> 0 | AF12: =+ROUND(Q12*AF$6/(100+AF$6),0)+BL12 -> 0 | AG12: =+ROUND(R12*AG$6/(100+AG$6),0)+BM12 -> 0 | AH12: =SUM(AC12:AG12) -> 0 | AI12: =+E12-AB12 -> 493400000
C13: 112011200 | D13: 流域下水道事業債 | E13: =+SUMIFS([1]全伝票!I:I,[1]全伝票!$C:$C,$C13) -> 120200000 | K13: =SUM(F13:J13) -> 0 | S13: =SUM(N13:R13) -> 0 | U13: =+V13-SUM(S13:T13) -> 120200000 | V13: =+SUMIFS([1]全伝票!P:P,[1]全伝票!$C:$C,$C13) -> 120200000 | W13: =+ROUND(F13*F$6/(100+F$6),0)+AT13 -> 0 | X13: =+ROUND(G13*G$6/(100+G$6),0)+AU13 -> 0 | Y13: =+ROUND(H13*H$6/(100+H$6),0)+AV13 -> 0 | Z13: =+ROUND(I13*I$6/(100+I$6),0)+AW13 -> 0 | AA13: =+ROUND(J13*J$6/(100+J$6),0)+AX13 -> 0 | AB13: =SUM(W13:AA13) -> 0 | AC13: =+ROUND(N13*AC$6/(100+AC$6),0)+BI13 -> 0 | AD13: =+ROUND(O13*AD$6/(100+AD$6),0)+BJ13 -> 0 | AE13: =+ROUND(P13*AE$6/(100+AE$6),0)+BK13 -> 0 | AF13: =+ROUND(Q13*AF$6/(100+AF$6),0)+BL13 -> 0 | AG13: =+ROUND(R13*AG$6/(100+AG$6),0)+BM13 -> 0 | AH13: =SUM(AC13:AG13) -> 0 | AI13: =+E13-AB13 -> 120200000
C14: 112011300 | D14: 資本費平準化債 | E14: =+SUMIFS([1]全伝票!I:I,[1]全伝票!$C:$C,$C14) -> 5929500000 | K14: =SUM(F14:J14) -> 0 | S14: =SUM(N14:R14) -> 0 | U14: =+V14-SUM(S14:T14) -> 5929500000 | V14: =+SUMIFS([1]全伝票!P:P,[1]全伝票!$C:$C,$C14) -> 5929500000 | W14: =+ROUND(F14*F$6/(100+F$6),0)+AT14 -> 0 | X14: =+ROUND(G14*G$6/(100+G$6),0)+AU14 -> 0 | Y14: =+ROUND(H14*H$6/(100+H$6),0)+AV14 -> 0 | Z14: =+ROUND(I14*I$6/(100+I$6),0)+AW14 -> 0 | AA14: =+ROUND(J14*J$6/(100+J$6),0)+AX14 -> 0 | AB14: =SUM(W14:AA14) -> 0 | AC14: =+ROUND(N14*AC$6/(100+AC$6),0)+BI14 -> 0 | AD14: =+ROUND(O14*AD$6/(100+AD$6),0)+BJ14 -> 0 | AE14: =+ROUND(P14*AE$6/(100+AE$6),0)+BK14 -> 0 | AF14: =+ROUND(Q14*AF$6/(100+AF$6),0)+BL14 -> 0 | AG14: =+ROUND(R14*AG$6/(100+AG$6),0)+BM14 -> 0 | AH14: =SUM(AC14:AG14) -> 0 | AI14: =+E14-AB14 -> 5929500000
C15: 112011600 | D15: 災害復旧事業債 | E15: =+SUMIFS([1]全伝票!I:I,[1]全伝票!$C:$C,$C15) -> 0 | K15: =SUM(F15:J15) -> 0 | S15: =SUM(N15:R15) -> 0 | U15: =+V15-SUM(S15:T15) -> 0 | V15: =+SUMIFS([1]全伝票!P:P,[1]全伝票!$C:$C,$C15) -> 0 | W15: =+ROUND(F15*F$6/(100+F$6),0)+AT15 -> 0 | X15: =+ROUND(G15*G$6/(100+G$6),0)+AU15 -> 0 | Y15: =+ROUND(H15*H$6/(100+H$6),0)+AV15 -> 0 | Z15: =+ROUND(I15*I$6/(100+I$6),0)+AW15 -> 0 | AA15: =+ROUND(J15*J$6/(100+J$6),0)+AX15 -> 0 | AB15: =SUM(W15:AA15) -> 0 | AC15: =+ROUND(N15*AC$6/(100+AC$6),0)+BI15 -> 0 | AD15: =+ROUND(O15*AD$6/(100+AD$6),0)+BJ15 -> 0 | AE15: =+ROUND(P15*AE$6/(100+AE$6),0)+BK15 -> 0 | AF15: =+ROUND(Q15*AF$6/(100+AF$6),0)+BL15 -> 0 | AG15: =+ROUND(R15*AG$6/(100+AG$6),0)+BM15 -> 0 | AH15: =SUM(AC15:AG15) -> 0 | AI15: =+E15-AB15 -> 0
D16: 公共下水道事業借換債 | E16: =+SUM(E17:E19) -> 17007700000 | F16: =+SUM(F17:F19) -> 0 | G16: =+SUM(G17:G19) -> 0 | H16: =+SUM(H17:H19) -> 0 | I16: =+SUM(I17:I19) -> 0 | J16: =+SUM(J17:J19) -> 0 | K16: =+SUM(K17:K19) -> 0 | L16: =+SUM(L17:L19) -> 0 | ... AI16: =+SUM(AI17:AI19) -> 17007700000
C17: 112021000 | D17: 公共下水道事業借換債 | E17: =+SUMIFS([1]全伝票!I:I,[1]全伝票!$C:$C,$C17) -> 0 | K17: =SUM(F17:J17) -> 0 | S17: =SUM(N17:R17) -> 0 | U17: =+V17-SUM(S17:T17) -> 0 | V17: =+SUMIFS([1]全伝票!P:P,[1]全伝票!$C:$C,$C17) -> 0 | W17: =+ROUND(F17*F$6/(100+F$6),0)+AT17 -> 0 | X17: =+ROUND(G17*G$6/(100+G$6),0)+AU17 -> 0 | Y17: =+ROUND(H17*H$6/(100+H$6),0)+AV17 -> 0 | Z17: =+ROUND(I17*I$6/(100+I$6),0)+AW17 -> 0 | AA17: =+ROUND(J17*J$6/(100+J$6),0)+AX17 -> 0 | AB17: =SUM(W17:AA17) -> 0 | AC17: =+ROUND(N17*AC$6/(100+AC$6),0)+BI17 -> 0 | AD17: =+ROUND(O17*AD$6/(100+AD$6),0)+BJ17 -> 0 | AE17: =+ROUND(P17*AE$6/(100+AE$6),0)+BK17 -> 0 | AF17: =+ROUND(Q17*AF$6/(100+AF$6),0)+BL17 -> 0 | AG17: =+ROUND(R17*AG$6/(100+AG$6),0)+BM17 -> 0 | AH17: =SUM(AC17:AG17) -> 0 | AI17: =+E17-AB17 -> 0
C18: 112023000 | D18: 補償金免除繰上償還借換債 | E18: =+SUMIFS([1]全伝票!I:I,[1]全伝票!$C:$C,$C18) -> 0 | K18: =SUM(F18:J18) -> 0 | S18: =SUM(N18:R18) -> 0 | U18: =+V18-SUM(S18:T18) -> 0 | V18: =+SUMIFS([1]全伝票!P:P,[1]全伝票!$C:$C,$C18) -> 0 | W18: =+ROUND(F18*F$6/(100+F$6),0)+AT18 -> 0 | X18: =+ROUND(G18*G$6/(100+G$6),0)+AU18 -> 0 | Y18: =+ROUND(H18*H$6/(100+H$6),0)+AV18 -> 0 | Z18: =+ROUND(I18*I$6/(100+I$6),0)+AW18 -> 0 | AA18: =+ROUND(J18*J$6/(100+J$6),0)+AX18 -> 0 | AB18: =SUM(W18:AA18) -> 0 | AC18: =+ROUND(N18*AC$6/(100+AC$6),0)+BI18 -> 0 | AD18: =+ROUND(O18*AD$6/(100+AD$6),0)+BJ18 -> 0 | AE18: =+ROUND(P18*AE$6/(100+AE$6),0)+BK18 -> 0 | AF18: =+ROUND(Q18*AF$6/(100+AF$6),0)+BL18 -> 0 | AG18: =+ROUND(R18*AG$6/(100+AG$6),0)+BM18 -> 0 | AH18: =SUM(AC18:AG18) -> 0 | AI18: =+E18-AB18 -> 0
C19: 112024000 | D19: 資本費平準化債(拡大分)借換債 | E19: =+SUMIFS([1]全伝票!I:I,[1]全伝票!$C:$C,$C19) -> 17007700000 | K19: =SUM(F19:J19) -> 0 | S19: =SUM(N19:R19) -> 0 | U19: =+V19-SUM(S19:T19) -> 17007700000 | V19: =+SUMIFS([1]全伝票!P:P,[1]全伝票!$C:$C,$C19) -> 17007700000 | W19: =+ROUND(F19*F$6/(100+F$6),0)+AT19 -> 0 | X19: =+ROUND(G19*G$6/(100+G$6),0)+AU19 -> 0 | Y19: =+ROUND(H19*H$6/(100+H$6),0)+AV19 -> 0 | Z19: =+ROUND(I19*I$6/(100+I$6),0)+AW19 -> 0 | AA19: =+ROUND(J19*J$6/(100+J$6),0)+AX19 -> 0 | AB19: =SUM(W19:AA19) -> 0 | AC19: =+ROUND(N19*AC$6/(100+AC$6),0)+BI19 -> 0 | AD19: =+ROUND(O19*AD$6/(100+AD$6),0)+BJ19 -> 0 | AE19: =+ROUND(P19*AE$6/(100+AE$6),0)+BK19 -> 0 | AF19: =+ROUND(Q19*AF$6/(100+AF$6),0)+BL19 -> 0 | AG19: =+ROUND(R19*AG$6/(100+AG$6),0)+BM19 -> 0 | AH19: =SUM(AC19:AG19) -> 0 | AI19: =+E19-AB19 -> 17007700000
C20: 112031000 | D20: 出資債 | E20: =+SUMIFS([1]全伝票!I:I,[1]全伝票!$C:$C,$C20) -> 0 | K20: =SUM(F20:J20) -> 0 | S20: =SUM(N20:R20) -> 0 | U20: =+V20-SUM(S20:T20) -> 0 | V20: =+SUMIFS([1]全伝票!P:P,[1]全伝票!$C:$C,$C20) -> 0 | W20: =+ROUND(F20*F$6/(100+F$6),0)+AT20 -> 0 | X20: =+ROUND(G20*G$6/(100+G$6),0)+AU20 -> 0 | Y20: =+ROUND(H20*H$6/(100+H$6),0)+AV20 -> 0 | Z20: =+ROUND(I20*I$6/(100+I$6),0)+AW20 -> 0 | AA20: =+ROUND(J20*J$6/(100+J$6),0)+AX20 -> 0 | AB20: =SUM(W20:AA20) -> 0 | AC20: =+ROUND(N20*AC$6/(100+AC$6),0)+BI20 -> 0 | AD20: =+ROUND(O20*AD$6/(100+AD$6),0)+BJ20 -> 0 | AE20: =+ROUND(P20*AE$6/(100+AE$6),0)+BK20 -> 0 | AF20: =+ROUND(Q20*AF$6/(100+AF$6),0)+BL20 -> 0 | AG20: =+ROUND(R20*AG$6/(100+AG$6),0)+BM20 -> 0 | AH20: =SUM(AC20:AG20) -> 0 | AI20: =+E20-AB20 -> 0
D21: 一般会計出資金 | E21: =+E22 -> 3285504551 | F21: =+F22 -> 0 | G21: =+G22 -> 0 | H21: =+H22 -> 0 | I21: =+I22 -> 0 | J21: =+J22 -> 0 | K21: =+K22 -> 0 | L21: =+L22 -> 0 | ... AI21: =+AI22 -> 3285504551
C22: 116010100 | D22: 下水道建設費出資金 | E22: =+'[2](繰)案'!E39 -> 3285504551 | K22: =SUM(F22:J22) -> 0 | S22: =SUM(N22:R22) -> 0 | U22: =+V22-SUM(S22:T22) -> 3285504551 | V22: =+E22 -> 3285504551 | W22: =+ROUND(F22*F$6/(100+F$6),0)+AT22 -> 0 | X22: =+ROUND(G22*G$6/(100+G$6),0)+AU22 -> 0 | Y22: =+ROUND(H22*H$6/(100+H$6),0)+AV22 -> 0 | Z22: =+ROUND(I22*I$6/(100+I$6),0)+AW22 -> 0 | AA22: =+ROUND(J22*J$6/(100+J$6),0)+AX22 -> 0 | AB22: =SUM(W22:AA22) -> 0 | AC22: =+ROUND(N22*AC$6/(100+AC$6),0)+BI22 -> 0 | AD22: =+ROUND(O22*AD$6/(100+AD$6),0)+BJ22 -> 0 | AE22: =+ROUND(P22*AE$6/(100+AE$6),0)+BK22 -> 0 | AF22: =+ROUND(Q22*AF$6/(100+AF$6),0)+BL22 -> 0 | AG22: =+ROUND(R22*AG$6/(100+AG$6),0)+BM22 -> 0 | AH22: =SUM(AC22:AG22) -> 0 | AI22: =+E22-AB22 -> 3285504551
D23: 国庫補助金 | E23: =+E24 -> 5717788000 | F23: =+F24 -> 0 | G23: =+G24 -> 0 | H23: =+H24 -> 0 | I23: =+I24 -> 0 | J23: =+J24 -> 0 | K23: =+K24 -> 0 | L23: =+L24 -> 0 | ... AI23: =+AI24 -> 5717788000
D24: 国庫補助金 | E24: =SUM(E25:E26,E31) -> 5717788000 | F24: =SUM(F25:F26,F31) -> 0 | G24: =SUM(G25:G26,G31) -> 0 | H24: =SUM(H25:H26,H31) -> 0 | I24: =SUM(I25:I26,I31) -> 0 | J24: =SUM(J25:J26,J31) -> 0 | K24: =SUM(K25:K26,K31) -> 0 | L24: =SUM(L25:L26,L31) -> 0 | ... AI24: =SUM(AI25:AI26,AI31) -> 5717788000
C25: 118040101 | D25: 公共下水道事整備国庫補助金 | E25: =+SUMIFS([1]全伝票!I:I,[1]全伝票!$C:$C,$C25) -> 5683800000 | K25: =SUM(F25:J25) -> 0 | L25: =+SUMIFS([1]全伝票!O:O,[1]全伝票!$C:$C,$C25) -> 0 | O25: =+'[3]4条補助（公）'!K$6 -> 0 | P25: =+'[3]4条補助（公）'!L$6 -> 0 | Q25: =+'[3]4条補助（公）'!M$6 -> 0 | R25: =+'[3]4条補助（公）'!N$6 -> 5678297006 | S25: =SUM(N25:R25) -> 5678297006 | T25: =SUM('[3]4条補助（公）'!$I$6) -> 5502994 | U25: =+V25-SUM(S25:T25) -> 0 | V25: =+SUMIFS([1]全伝票!P:P,[1]全伝票!$C:$C,$C25) -> 5683800000 | W25: =+ROUND(F25*F$6/(100+F$6),0)+AT25 -> 0 | X25: =+ROUND(G25*G$6/(100+G$6),0)+AU25 -> 0 | Y25: =+ROUND(H25*H$6/(100+H$6),0)+AV25 -> 0 | Z25: =+ROUND(I25*I$6/(100+I$6),0)+AW25 -> 0 | AA25: =+ROUND(J25*J$6/(100+J$6),0)+AX25 -> 0 | AB25: =SUM(W25:AA25) -> 0 | AC25: =+ROUND(N25*AC$6/(100+AC$6),0)+BI25 -> 0 | AD25: =+ROUND(O25*AD$6/(100+AD$6),0)+BJ25 -> 0 | AE25: =+ROUND(P25*AE$6/(100+AE$6),0)+BK25 -> 0 | AF25: =+ROUND(Q25*AF$6/(100+AF$6),0)+BL25 -> 0 | AG25: =+ROUND(R25*AG$6/(100+AG$6),0)+BM25 -> 516208819 | AH25: =SUM(AC25:AG25) -> 516208819 | AI25: =+E25-AB25 -> 5683800000 | AY25: =AC25-N25*AC$6/(100+AC$6) -> 0 | AZ25: =AD25-O25*AD$6/(100+AD$6) -> 0 | BA25: =AE25-P25*AE$6/(100+AE$6) -> 0 | BB25: =AF25-Q25*AF$6/(100+AF$6) -> 0 | BC25: =AG25-R25*AG$6/(100+AG$6) -> 0.27272725 | BD25: =+IF(AC$93=0,0,IF(AC$93<0,-RANK(AY25,AY$7:AY$90,0),RANK(AY25,AY$7:AY$90,1))) -> 0 | BE25: =+IF(AD$93=0,0,IF(AD$93<0,-RANK(AZ25,AZ$7:AZ$90,0),RANK(AZ25,AZ$7:AZ$90,1))) -> 0 | BF25: =+IF(AE$93=0,0,IF(AE$93<0,-RANK(BA25,BA$7:BA$90,0),RANK(BA25,BA$7:BA$90,1))) -> 0 | BG25: =+IF(AF$93=0,0,IF(AF$93<0,-RANK(BB25,BB$7:BB$90,0),RANK(BB25,BB$7:BB$90,1))) -> 0 | BH25: =+IF(AG$93=0,0,IF(AG$93<0,-RANK(BC25,BC$7:BC$90,0),RANK(BC25,BC$7:BC$90,1))) -> 0
D26: その他国庫補助金 | E26: =SUM(E27:E30) -> 0 | K26: =SUM(K27:K30) -> 0 | L26: =SUM(L27:L30) -> 0 | M26: =SUM(M27:M30) -> 0 | N26: =SUM(N27:N30) -> 0 | O26: =SUM(O27:O30) -> 0 | P26: =SUM(P27:P30) -> 0 | Q26: =SUM(Q27:Q30) -> 0 | R26: =SUM(R27:R30) -> 0 | ... AA26: =SUM(AA27:AA30) -> 0 | AB26: =SUM(W26:AA26) -> 0 | AC26: =SUM(AC27:AC30) -> 0 | AD26: =SUM(AD27:AD30) -> 0 | AE26: =SUM(AE27:AE30) -> 0 | AF26: =SUM(AF27:AF30) -> 0 | AG26: =SUM(AG27:AG30) -> 0 | AH26: =SUM(AC26:AG26) -> 0 | AI26: =SUM(AI27:AI30) -> 0
A27: 1 | C27: 118040200 | D27: 公共 | E27: =SUMIFS([1]全伝票!I:I,[1]全伝票!$C:$C,$C27,[1]全伝票!$A:$A,$A27) -> 0 | K27: =SUM(F27:J27) -> 0 | O27: ='[3]4条その他'!K$9 -> 0 | P27: ='[3]4条その他'!L$9 -> 0 | Q27: ='[3]4条その他'!M$9 -> 0 | R27: ='[3]4条その他'!N$9 -> 0 | S27: =SUM(N27:R27) -> 0 | T27: ='[3]4条その他'!I$8 -> 0 | U27: =+V27-SUM(S27:T27) -> 0 | V27: =SUMIFS([1]全伝票!P:P,[1]全伝票!$C:$C,$C27,[1]全伝票!$A:$A,$A27) -> 0 | W27: =+ROUND(F27*F$6/(100+F$6),0)+AT27 -> 0 | X27: =+ROUND(G27*G$6/(100+G$6),0)+AU27 -> 0 | Y27: =+ROUND(H27*H$6/(100+H$6),0)+AV27 -> 0 | Z27: =+ROUND(I27*I$6/(100+I$6),0)+AW27 -> 0 | AA27: =+ROUND(J27*J$6/(100+J$6),0)+AX27 -> 0 | AB27: =SUM(W27:AA27) -> 0 | AC27: =+ROUND(N27*AC$6/(100+AC$6),0)+BI27 -> 0 | AD27: =+ROUND(O27*AD$6/(100+AD$6),0)+BJ27 -> 0 | AE27: =+ROUND(P27*AE$6/(100+AE$6),0)+BK27 -> 0 | AF27: =+ROUND(Q27*AF$6/(100+AF$6),0)+BL27 -> 0 | AG27: =+ROUND(R27*AG$6/(100+AG$6),0)+BM27 -> 0 | AH27: =SUM(AC27:AG27) -> 0 | AI27: =+E27-AB27 -> 0 | AY27: =AC27-N27*AC$6/(100+AC$6) -> 0 | AZ27: =AD27-O27*AD$6/(100+AD$6) -> 0 | BA27: =AE27-P27*AE$6/(100+AE$6) -> 0 | BB27: =AF27-Q27*AF$6/(100+AF$6) -> 0 | BC27: =AG27-R27*AG$6/(100+AG$6) -> 0 | BD27: =+IF(AC$93=0,0,IF(AC$93<0,-RANK(AY27,AY$7:AY$90,0),RANK(AY27,AY$7:AY$90,1))) -> 0 | BE27: =+IF(AD$93=0,0,IF(AD$93<0,-RANK(AZ27,AZ$7:AZ$90,0),RANK(AZ27,AZ$7:AZ$90,1))) -> 0 | BF27: =+IF(AE$93=0,0,IF(AE$93<0,-RANK(BA27,BA$7:BA$90,0),RANK(BA27,BA$7:BA$90,1))) -> 0 | BG27: =+IF(AF$93=0,0,IF(AF$93<0,-RANK(BB27,BB$7:BB$90,0),RANK(BB27,BB$7:BB$90,1))) -> 0 | BH27: =+IF(AG$93=0,0,IF(AG$93<0,-RANK(BC27,BC$7:BC$90,0),RANK(BC27,BC$7:BC$90,1))) -> 0
A28: 2 | C28: 118040200 | D28: 特環 | E28: =SUMIFS([1]全伝票!I:I,[1]全伝票!$C:$C,$C28,[1]全伝票!$A:$A,$A28) -> 0 | K28: =SUM(F28:J28) -> 0 | O28: ='[3]4条その他'!K$23 -> 0 | P28: ='[3]4条その他'!L$23 -> 0 | Q28: ='[3]4条その他'!M$23 -> 0 | R28: ='[3]4条その他'!N$23 -> 0 | S28: =SUM(N28:R28) -> 0 | T28: ='[3]4条その他'!I$22 -> 0 | U28: =+V28-SUM(S28:T28) -> 0 | V28: =SUMIFS([1]全伝票!P:P,[1]全伝票!$C:$C,$C28,[1]全伝票!$A:$A,$A28) -> 0 | W28: =+ROUND(F28*F$6/(100+F$6),0)+AT28 -> 0 | X28: =+ROUND(G28*G$6/(100+G$6),0)+AU28 -> 0 | Y28: =+ROUND(H28*H$6/(100+H$6),0)+AV28 -> 0 | Z28: =+ROUND(I28*I$6/(100+I$6),0)+AW28 -> 0 | AA28: =+ROUND(J28*J$6/(100+J$6),0)+AX28 -> 0 | AB28: =SUM(W28:AA28) -> 0 | AC28: =+ROUND(N28*AC$6/(100+AC$6),0)+BI28 -> 0 | AD28: =+ROUND(O28*AD$6/(100+AD$6),0)+BJ28 -> 0 | AE28: =+ROUND(P28*AE$6/(100+AE$6),0)+BK28 -> 0 | AF28: =+ROUND(Q28*AF$6/(100+AF$6),0)+BL28 -> 0 | AG28: =+ROUND(R28*AG$6/(100+AG$6),0)+BM28 -> 0 | AH28: =SUM(AC28:AG28) -> 0 | AI28: =+E28-AB28 -> 0 | AY28: =AC28-N28*AC$6/(100+AC$6) -> 0 | AZ28: =AD28-O28*AD$6/(100+AD$6) -> 0 | BA28: =AE28-P28*AE$6/(100+AE$6) -> 0 | BB28: =AF28-Q28*AF$6/(100+AF$6) -> 0 | BC28: =AG28-R28*AG$6/(100+AG$6) -> 0 | BD28: =+IF(AC$93=0,0,IF(AC$93<0,-RANK(AY28,AY$7:AY$90,0),RANK(AY28,AY$7:AY$90,1))) -> 0 | BE28: =+IF(AD$93=0,0,IF(AD$93<0,-RANK(AZ28,AZ$7:AZ$90,0),RANK(AZ28,AZ$7:AZ$90,1))) -> 0 | BF28: =+IF(AE$93=0,0,IF(AE$93<0,-RANK(BA28,BA$7:BA$90,0),RANK(BA28,BA$7:BA$90,1))) -> 0 | BG28: =+IF(AF$93=0,0,IF(AF$93<0,-RANK(BB28,BB$7:BB$90,0),RANK(BB28,BB$7:BB$90,1))) -> 0 | BH28: =+IF(AG$93=0,0,IF(AG$93<0,-RANK(BC28,BC$7:BC$90,0),RANK(BC28,BC$7:BC$90,1))) -> 0
A29: 3 | C29: 118040200 | D29: 農集 | E29: =SUMIFS([1]全伝票!I:I,[1]全伝票!$C:$C,$C29,[1]全伝票!$A:$A,$A29) -> 0 | K29: =SUM(F29:J29) -> 0 | O29: ='[3]4条その他'!K$37 -> 0 | P29: ='[3]4条その他'!L$37 -> 0 | Q29: ='[3]4条その他'!M$37 -> 0 | R29: ='[3]4条その他'!N$37 -> 0 | S29: =SUM(N29:R29) -> 0 | T29: ='[3]4条その他'!I$36 -> 0 | U29: =+V29-SUM(S29:T29) -> 0 | V29: =SUMIFS([1]全伝票!P:P,[1]全伝票!$C:$C,$C29,[1]全伝票!$A:$A,$A29) -> 0 | W29: =+ROUND(F29*F$6/(100+F$6),0)+AT29 -> 0 | X29: =+ROUND(G29*G$6/(100+G$6),0)+AU29 -> 0 | Y29: =+ROUND(H29*H$6/(100+H$6),0)+AV29 -> 0 | Z29: =+ROUND(I29*I$6/(100+I$6),0)+AW29 -> 0 | AA29: =+ROUND(J29*J$6/(100+J$6),0)+AX29 -> 0 | AB29: =SUM(W29:AA29) -> 0 | AC29: =+ROUND(N29*AC$6/(100+AC$6),0)+BI29 -> 0 | AD29: =+ROUND(O29*AD$6/(100+AD$6),0)+BJ29 -> 0 | AE29: =+ROUND(P29*AE$6/(100+AE$6),0)+BK29 -> 0 | AF29: =+ROUND(Q29*AF$6/(100+AF$6),0)+BL29 -> 0 | AG29: =+ROUND(R29*AG$6/(100+AG$6),0)+BM29 -> 0 | AH29: =SUM(AC29:AG29) -> 0 | AI29: =+E29-AB29 -> 0 | AY29: =AC29-N29*AC$6/(100+AC$6) -> 0 | AZ29: =AD29-O29*AD$6/(100+AD$6) -> 0 | BA29: =AE29-P29*AE$6/(100+AE$6) -> 0 | BB29: =AF29-Q29*AF$6/(100+AF$6) -> 0 | BC29: =AG29-R29*AG$6/(100+AG$6) -> 0 | BD29: =+IF(AC$93=0,0,IF(AC$93<0,-RANK(AY29,AY$7:AY$90,0),RANK(AY29,AY$7:AY$90,1))) -> 0 | BE29: =+IF(AD$93=0,0,IF(AD$93<0,-RANK(AZ29,AZ$7:AZ$90,0),RANK(AZ29,AZ$7:AZ$90,1))) -> 0 | BF29: =+IF(AE$93=0,0,IF(AE$93<0,-RANK(BA29,BA$7:BA$90,0),RANK(BA29,BA$7:BA$90,1))) -> 0 | BG29: =+IF(AF$93=0,0,IF(AF$93<0,-RANK(BB29,BB$7:BB$90,0),RANK(BB29,BB$7:BB$90,1))) -> 0 | BH29: =+IF(AG$93=0,0,IF(AG$93<0,-RANK(BC29,BC$7:BC$90,0),RANK(BC29,BC$7:BC$90,1))) -> 0
A30: 4 | C30: 118040200 | D30: 浄化槽 | E30: =SUMIFS([1]全伝票!I:I,[1]全伝票!$C:$C,$C30,[1]全伝票!$A:$A,$A30) -> 0 | K30: =SUM(F30:J30) -> 0 | O30: ='[3]4条その他'!K$51 -> 0 | P30: ='[3]4条その他'!L$51 -> 0 | Q30: ='[3]4条その他'!M$51 -> 0 | R30: ='[3]4条その他'!N$51 -> 0 | S30: =SUM(N30:R30) -> 0 | T30: ='[3]4条その他'!I$50 -> 0 | U30: =+V30-SUM(S30:T30) -> 0 | V30: =SUMIFS([1]全伝票!P:P,[1]全伝票!$C:$C,$C30,[1]全伝票!$A:$A,$A30) -> 0 | W30: =+ROUND(F30*F$6/(100+F$6),0)+AT30 -> 0 | X30: =+ROUND(G30*G$6/(100+G$6),0)+AU30 -> 0 | Y30: =+ROUND(H30*H$6/(100+H$6),0)+AV30 -> 0 | Z30: =+ROUND(I30*I$6/(100+I$6),0)+AW30 -> 0 | AA30: =+ROUND(J30*J$6/(100+J$6),0)+AX30 -> 0 | AB30: =SUM(W30:AA30) -> 0 | AC30: =+ROUND(N30*AC$6/(100+AC$6),0)+BI30 -> 0 | AD30: =+ROUND(O30*AD$6/(100+AD$6),0)+BJ30 -> 0 | AE30: =+ROUND(P30*AE$6/(100+AE$6),0)+BK30 -> 0 | AF30: =+ROUND(Q30*AF$6/(100+AF$6),0)+BL30 -> 0 | AG30: =+ROUND(R30*AG$6/(100+AG$6),0)+BM30 -> 0 | AH30: =SUM(AC30:AG30) -> 0 | AI30: =+E30-AB30 -> 0 | AY30: =AC30-N30*AC$6/(100+AC$6) -> 0 | AZ30: =AD30-O30*AD$6/(100+AD$6) -> 0 | BA30: =AE30-P30*AE$6/(100+AE$6) -> 0 | BB30: =AF30-Q30*AF$6/(100+AF$6) -> 0 | BC30: =AG30-R30*AG$6/(100+AG$6) -> 0 | BD30: =+IF(AC$93=0,0,IF(AC$93<0,-RANK(AY30,AY$7:AY$90,0),RANK(AY30,AY$7:AY$90,1))) -> 0 | BE30: =+IF(AD$93=0,0,IF(AD$93<0,-RANK(AZ30,AZ$7:AZ$90,0),RANK(AZ30,AZ$7:AZ$90,1))) -> 0 | BF30: =+IF(AE$93=0,0,IF(AE$93<0,-RANK(BA30,BA$7:BA$90,0),RANK(BA30,BA$7:BA$90,1))) -> 0 | BG30: =+IF(AF$93=0,0,IF(AF$93<0,-RANK(BB30,BB$7:BB$90,0),RANK(BB30,BB$7:BB$90,1))) -> 0 | BH30: =+IF(AG$93=0,0,IF(AG$93<0,-RANK(BC30,BC$7:BC$90,0),RANK(BC30,BC$7:BC$90,1))) -> 0
D31: 公共下水道事整備国庫補助金ほか | E31: =+SUM(E32:E34) -> 33988000 | F31: =+SUM(F32:F34) -> 0 | G31: =+SUM(G32:G34) -> 0 | H31: =+SUM(H32:H34) -> 0 | I31: =+SUM(I32:I34) -> 0 | J31: =+SUM(J32:J34) -> 0 | K31: =+SUM(K32:K34) -> 0 | L31: =+SUM(L32:L34) -> 0 | ... V31: =+SUM(V32:V34) -> 33988000 | W31: =+ROUND(F31*F$6/(100+F$6),0)+AT31 -> 0 | X31: =+ROUND(G31*G$6/(100+G$6),0)+AU31 -> 0 | Y31: =+ROUND(H31*H$6/(100+H$6),0)+AV31 -> 0 | Z31: =+ROUND(I31*I$6/(100+I$6),0)+AW31 -> 0 | AA31: =+ROUND(J31*J$6/(100+J$6),0)+AX31 -> 0 | AB31: =SUM(W31:AA31) -> 0 | AC31: =+SUM(AC32:AC34) -> 0 | AD31: =+SUM(AD32:AD34) -> 0 | AE31: =+SUM(AE32:AE34) -> 0 | AF31: =+SUM(AF32:AF34) -> 0 | AG31: =+SUM(AG32:AG34) -> 3089818 | AH31: =SUM(AC31:AG31) -> 3089818 | AI31: =+E31-AB31 -> 33988000
A32: 2 | C32: 118040103 | D32: 特環 | E32: =+SUMIFS([1]全伝票!I:I,[1]全伝票!$C:$C,$C32,[1]全伝票!$A:$A,'4条収入'!$A32) -> 30500000 | K32: =SUM(F32:J32) -> 0 | O32: =+'[3]4条補助（特）'!K$6 -> 0 | P32: =+'[3]4条補助（特）'!L$6 -> 0 | Q32: =+'[3]4条補助（特）'!M$6 -> 0 | R32: =+'[3]4条補助（特）'!N$6 -> 30500000 | S32: =SUM(N32:R32) -> 30500000 | T32: =+'[3]4条補助（特）'!$I$6 -> 0 | U32: =+V32-SUM(S32:T32) -> 0 | V32: =+SUMIFS([1]全伝票!P:P,[1]全伝票!$C:$C,$C32,[1]全伝票!$A:$A,'4条収入'!$A32) -> 30500000 | W32: =+ROUND(F32*F$6/(100+F$6),0)+AT32 -> 0 | X32: =+ROUND(G32*G$6/(100+G$6),0)+AU32 -> 0 | Y32: =+ROUND(H32*H$6/(100+H$6),0)+AV32 -> 0 | Z32: =+ROUND(I32*I$6/(100+I$6),0)+AW32 -> 0 | AA32: =+ROUND(J32*J$6/(100+J$6),0)+AX32 -> 0 | AB32: =SUM(W32:AA32) -> 0 | AC32: =+ROUND(N32*AC$6/(100+AC$6),0)+BI32 -> 0 | AD32: =+ROUND(O32*AD$6/(100+AD$6),0)+BJ32 -> 0 | AE32: =+ROUND(P32*AE$6/(100+AE$6),0)+BK32 -> 0 | AF32: =+ROUND(Q32*AF$6/(100+AF$6),0)+BL32 -> 0 | AG32: =+ROUND(R32*AG$6/(100+AG$6),0)+BM32 -> 2772727 | AH32: =SUM(AC32:AG32) -> 2772727 | AI32: =+E32-AB32 -> 30500000
A33: 3 | C33: 118040400 | D33: 農集 | E33: =+SUMIFS([1]全伝票!I:I,[1]全伝票!$C:$C,$C33,[1]全伝票!$A:$A,'4条収入'!$A33) -> 0 | K33: =SUM(F33:J33) -> 0 | O33: =+'[3]4条補助（農）'!K$6 -> 0 | P33: =+'[3]4条補助（農）'!L$6 -> 0 | Q33: =+'[3]4条補助（農）'!M$6 -> 0 | R33: =+'[3]4条補助（農）'!N$6 -> 0 | S33: =SUM(N33:R33) -> 0 | T33: =+'[3]4条補助（農）'!$I$6 -> 0 | U33: =+V33-SUM(S33:T33) -> 0 | V33: =+SUMIFS([1]全伝票!P:P,[1]全伝票!$C:$C,$C33,[1]全伝票!$A:$A,'4条収入'!$A33) -> 0 | W33: =+ROUND(F33*F$6/(100+F$6),0)+AT33 -> 0 | X33: =+ROUND(G33*G$6/(100+G$6),0)+AU33 -> 0 | Y33: =+ROUND(H33*H$6/(100+H$6),0)+AV33 -> 0 | Z33: =+ROUND(I33*I$6/(100+I$6),0)+AW33 -> 0 | AA33: =+ROUND(J33*J$6/(100+J$6),0)+AX33 -> 0 | AB33: =SUM(W33:AA33) -> 0 | AC33: =+ROUND(N33*AC$6/(100+AC$6),0)+BI33 -> 0 | AD33: =+ROUND(O33*AD$6/(100+AD$6),0)+BJ33 -> 0 | AE33: =+ROUND(P33*AE$6/(100+AE$6),0)+BK33 -> 0 | AF33: =+ROUND(Q33*AF$6/(100+AF$6),0)+BL33 -> 0 | AG33: =+ROUND(R33*AG$6/(100+AG$6),0)+BM33 -> 0 | AH33: =SUM(AC33:AG33) -> 0 | AI33: =+E33-AB33 -> 0
A34: 4 | C34: 118040400 | D34: 浄化槽 | E34: =+SUMIFS([1]全伝票!I:I,[1]全伝票!$C:$C,$C34,[1]全伝票!$A:$A,'4条収入'!$A34) -> 3488000 | K34: =SUM(F34:J34) -> 0 | O34: =+'[3]4条補助（浄）'!K$6 -> 0 | P34: =+'[3]4条補助（浄）'!L$6 -> 0 | Q34: =+'[3]4条補助（浄）'!M$6 -> 0 | R34: =+'[3]4条補助（浄）'!N$6 -> 3488000 | S34: =SUM(N34:R34) -> 3488000 | T34: =+'[3]4条補助（浄）'!$I$6 -> 0 | U34: =+V34-SUM(S34:T34) -> 0 | V34: =+SUMIFS([1]全伝票!P:P,[1]全伝票!$C:$C,$C34,[1]全伝票!$A:$A,'4条収入'!$A34) -> 3488000 | W34: =+ROUND(F34*F$6/(100+F$6),0)+AT34 -> 0 | X34: =+ROUND(G34*G$6/(100+G$6),0)+AU34 -> 0 | Y34: =+ROUND(H34*H$6/(100+H$6),0)+AV34 -> 0 | Z34: =+ROUND(I34*I$6/(100+I$6),0)+AW34 -> 0 | AA34: =+ROUND(J34*J$6/(100+J$6),0)+AX34 -> 0 | AB34: =SUM(W34:AA34) -> 0 | AC34: =+ROUND(N34*AC$6/(100+AC$6),0)+BI34 -> 0 | AD34: =+ROUND(O34*AD$6/(100+AD$6),0)+BJ34 -> 0 | AE34: =+ROUND(P34*AE$6/(100+AE$6),0)+BK34 -> 0 | AF34: =+ROUND(Q34*AF$6/(100+AF$6),0)+BL34 -> 0 | AG34: =+ROUND(R34*AG$6/(100+AG$6),0)+BM34 -> 317091 | AH34: =SUM(AC34:AG34) -> 317091 | AI34: =+E34-AB34 -> 3488000
D35: 県補助金 | E35: =+E36 -> 0 | F35: =+F36 -> 0 | G35: =+G36 -> 0 | H35: =+H36 -> 0 | I35: =+I36 -> 0 | J35: =+J36 -> 0 | K35: =+K36 -> 0 | L35: =+L36 -> 0 | ... AI35: =+AI36 -> 0
C36: 119040100 | D36: 県補助金 | E36: =+SUMIFS([1]全伝票!I:I,[1]全伝票!$C:$C,$C36) -> 0 | K36: =SUM(F36:J36) -> 0 | S36: =SUM(N36:R36) -> 0 | U36: =+V36-SUM(S36:T36) -> 0 | V36: =+SUMIFS([1]全伝票!P:P,[1]全伝票!$C:$C,$C36) -> 0 | W36: =+ROUND(F36*F$6/(100+F$6),0)+AT36 -> 0 | X36: =+ROUND(G36*G$6/(100+G$6),0)+AU36 -> 0 | Y36: =+ROUND(H36*H$6/(100+H$6),0)+AV36 -> 0 | Z36: =+ROUND(I36*I$6/(100+I$6),0)+AW36 -> 0 | AA36: =+ROUND(J36*J$6/(100+J$6),0)+AX36 -> 0 | AB36: =SUM(W36:AA36) -> 0 | AC36: =+ROUND(N36*AC$6/(100+AC$6),0)+BI36 -> 0 | AD36: =+ROUND(O36*AD$6/(100+AD$6),0)+BJ36 -> 0 | AE36: =+ROUND(P36*AE$6/(100+AE$6),0)+BK36 -> 0 | AF36: =+ROUND(Q36*AF$6/(100+AF$6),0)+BL36 -> 0 | AG36: =+ROUND(R36*AG$6/(100+AG$6),0)+BM36 -> 0 | AH36: =SUM(AC36:AG36) -> 0 | AI36: =+E36-AB36 -> 0 | AY36: =AC36-N36*AC$6/(100+AC$6) -> 0 | AZ36: =AD36-O36*AD$6/(100+AD$6) -> 0 | BA36: =AE36-P36*AE$6/(100+AE$6) -> 0 | BB36: =AF36-Q36*AF$6/(100+AF$6) -> 0 | BC36: =AG36-R36*AG$6/(100+AG$6) -> 0 | BD36: =+IF(AC$93=0,0,IF(AC$93<0,-RANK(AY36,AY$7:AY$90,0),RANK(AY36,AY$7:AY$90,1))) -> 0 | BE36: =+IF(AD$93=0,0,IF(AD$93<0,-RANK(AZ36,AZ$7:AZ$90,0),RANK(AZ36,AZ$7:AZ$90,1))) -> 0 | BF36: =+IF(AE$93=0,0,IF(AE$93<0,-RANK(BA36,BA$7:BA$90,0),RANK(BA36,BA$7:BA$90,1))) -> 0 | BG36: =+IF(AF$93=0,0,IF(AF$93<0,-RANK(BB36,BB$7:BB$90,0),RANK(BB36,BB$7:BB$90,1))) -> 0 | BH36: =+IF(AG$93=0,0,IF(AG$93<0,-RANK(BC36,BC$7:BC$90,0),RANK(BC36,BC$7:BC$90,1))) -> 0
D37: 工事受託金 | E37: =+E38 -> 24373083 | F37: =+F38 -> 0 | G37: =+G38 -> 0 | H37: =+H38 -> 0 | I37: =+I38 -> 0 | J37: =+J38 -> 24373083 | K37: =+K38 -> 24373083 | L37: =+L38 -> 0 | ... AI37: =+AI38 -> 22157348
D38: 工事受託金 | E38: =+SUM(E39:E41) -> 24373083 | F38: =+SUM(F39:F41) -> 0 | G38: =+SUM(G39:G41) -> 0 | H38: =+SUM(H39:H41) -> 0 | I38: =+SUM(I39:I41) -> 0 | J38: =+SUM(J39:J41) -> 24373083 | K38: =+SUM(K39:K41) -> 24373083 | L38: =+SUM(L39:L41) -> 0 | ... AA38: =+SUM(AA39:AA41) -> 2215735 | AB38: =SUM(W38:AA38) -> 2215735 | AC38: =+ROUND(N38*AC$6/(100+AC$6),0)+BI38 -> 0 | AD38: =+ROUND(O38*AD$6/(100+AD$6),0)+BJ38 -> 0 | AE38: =+ROUND(P38*AE$6/(100+AE$6),0)+BK38 -> 0 | AF38: =+ROUND(Q38*AF$6/(100+AF$6),0)+BL38 -> 0 | AG38: =+ROUND(R38*AG$6/(100+AG$6),0)+BM38 -> 0 | AH38: =SUM(AC38:AG38) -> 0 | AI38: =+E38-AB38 -> 22157348
A39: 1 | C39: 160010100 | D39: 公共 | E39: =+SUMIFS([1]全伝票!I:I,[1]全伝票!$C:$C,$C39,[1]全伝票!$A:$A,$A39) -> 24373083 | F39: =+SUMIFS([1]全伝票!J:J,[1]全伝票!$C:$C,$C39,[1]全伝票!$A:$A,$A39) -> 0 | G39: =+SUMIFS([1]全伝票!K:K,[1]全伝票!$C:$C,$C39,[1]全伝票!$A:$A,$A39) -> 0 | H39: =+SUMIFS([1]全伝票!L:L,[1]全伝票!$C:$C,$C39,[1]全伝票!$A:$A,$A39) -> 0 | I39: =+SUMIFS([1]全伝票!M:M,[1]全伝票!$C:$C,$C39,[1]全伝票!$A:$A,$A39) -> 0 | J39: =+SUMIFS([1]全伝票!N:N,[1]全伝票!$C:$C,$C39,[1]全伝票!$A:$A,$A39) -> 24373083 | K39: =SUM(F39:J39) -> 24373083 | L39: =+SUMIFS([1]全伝票!O:O,[1]全伝票!$C:$C,$C39,[1]全伝票!$A:$A,$A39) -> 0 | S39: =SUM(N39:R39) -> 0 | U39: =+V39-SUM(S39:T39) -> 0 | V39: =+SUMIFS([1]全伝票!P:P,[1]全伝票!$C:$C,$C39,[1]全伝票!$A:$A,'4条収入'!$A39) -> 0 | W39: =+ROUND(F39*F$6/(100+F$6),0)+AT39 -> 0 | X39: =+ROUND(G39*G$6/(100+G$6),0)+AU39 -> 0 | Y39: =+ROUND(H39*H$6/(100+H$6),0)+AV39 -> 0 | Z39: =+ROUND(I39*I$6/(100+I$6),0)+AW39 -> 0 | AA39: =+ROUND(J39*J$6/(100+J$6),0)+AX39 -> 2215735 | AB39: =SUM(W39:AA39) -> 2215735 | AC39: =+ROUND(N39*AC$6/(100+AC$6),0)+BI39 -> 0 | AD39: =+ROUND(O39*AD$6/(100+AD$6),0)+BJ39 -> 0 | AE39: =+ROUND(P39*AE$6/(100+AE$6),0)+BK39 -> 0 | AF39: =+ROUND(Q39*AF$6/(100+AF$6),0)+BL39 -> 0 | AG39: =+ROUND(R39*AG$6/(100+AG$6),0)+BM39 -> 0 | AH39: =SUM(AC39:AG39) -> 0 | AI39: =+E39-AB39 -> 22157348 | AJ39: =W39-F39*W$6/(100+W$6) -> 0 | AK39: =X39-G39*X$6/(100+X$6) -> 0 | AL39: =Y39-H39*Y$6/(100+Y$6) -> 0 | AM39: =Z39-I39*Z$6/(100+Z$6) -> 0 | AN39: =AA39-J39*AA$6/(100+AA$6) -> 0.18181818 | AO39: =+IF(W$93=0,0,IF(W$93<0,-RANK(AJ39,AJ$7:AJ$90,0),RANK(AJ39,AJ$7:AJ$90,1))) -> 0 | AP39: =+IF(X$93=0,0,IF(X$93<0,-RANK(AK39,AK$7:AK$90,0),RANK(AK39,AK$7:AK$90,1))) -> 0 | AQ39: =+IF(Y$93=0,0,IF(Y$93<0,-RANK(AL39,AL$7:AL$90,0),RANK(AL39,AL$7:AL$90,1))) -> 0 | AR39: =+IF(Z$93=0,0,IF(Z$93<0,-RANK(AM39,AM$7:AM$90,0),RANK(AM39,AM$7:AM$90,1))) -> 0 | AS39: =+IF(AA$93=0,0,IF(AA$93<0,-RANK(AN39,AN$7:AN$90,0),RANK(AN39,AN$7:AN$90,1))) -> 0 | AY39: =AC39-N39*AC$6/(100+AC$6) -> 0 | AZ39: =AD39-O39*AD$6/(100+AD$6) -> 0 | BA39: =AE39-P39*AE$6/(100+AE$6) -> 0 | BB39: =AF39-Q39*AF$6/(100+AF$6) -> 0 | BC39: =AG39-R39*AG$6/(100+AG$6) -> 0 | BD39: =+IF(AC$93=0,0,IF(AC$93<0,-RANK(AY39,AY$7:AY$90,0),RANK(AY39,AY$7:AY$90,1))) -> 0 | BE39: =+IF(AD$93=0,0,IF(AD$93<0,-RANK(AZ39,AZ$7:AZ$90,0),RANK(AZ39,AZ$7:AZ$90,1))) -> 0 | BF39: =+IF(AE$93=0,0,IF(AE$93<0,-RANK(BA39,BA$7:BA$90,0),RANK(BA39,BA$7:BA$90,1))) -> 0 | BG39: =+IF(AF$93=0,0,IF(AF$93<0,-RANK(BB39,BB$7:BB$90,0),RANK(BB39,BB$7:BB$90,1))) -> 0 | BH39: =+IF(AG$93=0,0,IF(AG$93<0,-RANK(BC39,BC$7:BC$90,0),RANK(BC39,BC$7:BC$90,1))) -> 0
A40: 2 | C40: 160010100 | D40: 特環 | E40: =+SUMIFS([1]全伝票!I:I,[1]全伝票!$C:$C,$C40,[1]全伝票!$A:$A,$A40) -> 0 | F40: =+SUMIFS([1]全伝票!J:J,[1]全伝票!$C:$C,$C40,[1]全伝票!$A:$A,$A40) -> 0 | G40: =+SUMIFS([1]全伝票!K:K,[1]全伝票!$C:$C,$C40,[1]全伝票!$A:$A,$A40) -> 0 | H40: =+SUMIFS([1]全伝票!L:L,[1]全伝票!$C:$C,$C40,[1]全伝票!$A:$A,$A40) -> 0 | I40: =+SUMIFS([1]全伝票!M:M,[1]全伝票!$C:$C,$C40,[1]全伝票!$A:$A,$A40) -> 0 | J40: =+SUMIFS([1]全伝票!N:N,[1]全伝票!$C:$C,$C40,[1]全伝票!$A:$A,$A40) -> 0 | K40: =SUM(F40:J40) -> 0 | L40: =+SUMIFS([1]全伝票!O:O,[1]全伝票!$C:$C,$C40,[1]全伝票!$A:$A,$A40) -> 0 | S40: =SUM(N40:R40) -> 0 | U40: =+V40-SUM(S40:T40) -> 0 | V40: =+SUMIFS([1]全伝票!P:P,[1]全伝票!$C:$C,$C40,[1]全伝票!$A:$A,'4条収入'!$A40) -> 0 | W40: =+ROUND(F40*F$6/(100+F$6),0)+AT40 -> 0 | X40: =+ROUND(G40*G$6/(100+G$6),0)+AU40 -> 0 | Y40: =+ROUND(H40*H$6/(100+H$6),0)+AV40 -> 0 | Z40: =+ROUND(I40*I$6/(100+I$6),0)+AW40 -> 0 | AA40: =+ROUND(J40*J$6/(100+J$6),0)+AX40 -> 0 | AB40: =SUM(W40:AA40) -> 0 | AC40: =+ROUND(N40*AC$6/(100+AC$6),0)+BI40 -> 0 | AD40: =+ROUND(O40*AD$6/(100+AD$6),0)+BJ40 -> 0 | AE40: =+ROUND(P40*AE$6/(100+AE$6),0)+BK40 -> 0 | AF40: =+ROUND(Q40*AF$6/(100+AF$6),0)+BL40 -> 0 | AG40: =+ROUND(R40*AG$6/(100+AG$6),0)+BM40 -> 0 | AH40: =SUM(AC40:AG40) -> 0 | AI40: =+E40-AB40 -> 0
...
