Workbook

Sheet 雨汚水
D1: =+'[1]3条支出'!$D$1 -> 令和５年度決算 消費税算出資料 | N1: =+$D$1 -> 令和５年度決算 消費税算出資料 | X1: =+$D$1 -> 令和５年度決算 消費税算出資料
D2: 【３条支出雨汚水分け表】 | M2: =+IF(COUNTIF(M7:M45,0)=COUNT(M7:M45),"","↓エラーあり") | N2: 【３条支出雨汚水分け表】 | W2: =+IF(COUNTIF(W7:W45,0)=COUNT(W7:W45),"","↓エラーあり") | X2: 【３条支出雨汚水分け表】（消費税雑支出加算後） | AL2: =+IF(COUNTIF(AL7:AL45,0)=COUNT(AL7:AL45),"","↓エラーあり")
B3: 区分 | D3: 費目 | E3: ３条支出 税込み | N3: 費目 | O3: ３条支出 税抜き | X3: 費目 | AD3: ３条支出 税抜き
E4: 税込決算額 | F4: 雨水 | J4: 汚水 | M4: チェック | O4: 税抜決算額 | P4: 雨水 | T4: 汚水 | W4: チェック | AD4: 税抜決算額 | AE4: 雨水 | AI4: 汚水 | AL4: チェック
F5: 繰出基準内 | G5: 繰出基準内 | H5: 繰出基準外 | I5: 計 | J5: 繰出基準内 | K5: 繰出基準外 | L5: 計 | P5: 繰出基準内 | Q5: 繰出基準内 | R5: 繰出基準外 | S5: 計 | T5: 繰出基準内 | U5: 繰出基準外 | V5: 計 | AE5: 繰出基準内 | AF5: 繰出基準内 | AG5: 繰出基準外 | AH5: 計 | AI5: 繰出基準内 | AJ5: 繰出基準外 | AK5: 計 | AM5: 4月決見 | AQ5: 当初予算
F6: 使用料徴収区域内 | G6: 使用料徴収区域外 | H6: 一般行政経費 | J6: 使用料徴収区域内 | K6: 使用料徴収区域内 | P6: 使用料徴収区域内 | Q6: 使用料徴収区域外 | R6: 一般行政経費 | T6: 使用料徴収区域内 | U6: 使用料徴収区域内 | AE6: 使用料徴収区域内 | AF6: 使用料徴収区域外 | AG6: 一般行政経費 | AI6: 使用料徴収区域内 | AJ6: 使用料徴収区域内 | AM6: 一般会計負担金分 | AN6: 決算見込 | AQ6: 当初予算 | AT6: 決算見込
B7: 維持 | C7: 営業 | D7: 管きょ費 | E7: =+'[1]3条支出'!E6 -> 611819957 | F7: 285727057 | G7: 60054665 | H7: 0 | I7: =+SUM(F7:H7) -> 345781722 | K7: 266038235 | L7: =+SUM(J7:K7) -> 266038235 | M7: =E7-SUM(I7,L7) -> 0 | N7: 管きょ費 | O7: =+'[1]3条支出'!T6 -> 564664608 | P7: =+IFERROR(ROUND(F7*$O7/$E7,0),0) -> 263704959 | Q7: =+IFERROR(ROUND(G7*$O7/$E7,0),0) -> 55426018 | R7: =+IFERROR(ROUND(H7*$O7/$E7,0),0) -> 0 | S7: =+SUM(P7:R7) -> 319130977 | T7: =+IFERROR(ROUND(J7*$O7/$E7,0),0) -> 0 | U7: =+O7-S7-T7 -> 245533631 | V7: =+SUM(T7:U7) -> 245533631 | W7: =O7-SUM(S7,V7) -> 0 | X7: 管きょ費 | AD7: =+O7 -> 564664608 | AE7: =+P7 -> 263704959 | AF7: =+Q7 -> 55426018 | AG7: =+R7 -> 0 | AH7: =+SUM(AE7:AG7) -> 319130977 | AI7: =+T7 -> 0 | AJ7: =+U7 -> 245533631 | AK7: =+SUM(AI7:AJ7) -> 245533631 | AL7: =AD7-SUM(AH7,AK7) -> 0 | AM7: =SUM(AE7:AG7,AI7) -> 319130977 | AN7: 336288000 | AO7: =AM7-AN7 -> -17157023 | AQ7: 345982000 | AR7: =AM7-AQ7 -> -26851023 | AT7: #=SUM('[4-04 集計表.xlsx]3条集計(税抜)'!R24:T24)
B8: 維持 | C8: 営業 | D8: 水質指導費 | E8: =+'[1]3条支出'!E7 -> 52443869 | I8: =+SUM(F8:H8) -> 0 | J8: =+E8 -> 52443869 | K8: =+E8-I8-J8 -> 0 | L8: =+SUM(J8:K8) -> 52443869 | M8: =E8-SUM(I8,L8) -> 0 | N8: 水質指導費 | O8: =+'[1]3条支出'!T7 -> 51313295 | P8: =+IFERROR(ROUND(F8*$O8/$E8,0),0) -> 0 | Q8: =+IFERROR(ROUND(G8*$O8/$E8,0),0) -> 0 | R8: =+IFERROR(ROUND(H8*$O8/$E8,0),0) -> 0 | S8: =+SUM(P8:R8) -> 0 | T8: =+IFERROR(ROUND(J8*$O8/$E8,0),0) -> 51313295 | U8: =+O8-S8-T8 -> 0 | V8: =+SUM(T8:U8) -> 51313295 | W8: =O8-SUM(S8,V8) -> 0 | X8: 水質指導費 | AD8: =+O8 -> 51313295 | AE8: =+P8 -> 0 | AF8: =+Q8 -> 0 | AG8: =+R8 -> 0 | AH8: =+SUM(AE8:AG8) -> 0 | AI8: =+T8 -> 51313295 | AJ8: =+U8 -> 0 | AK8: =+SUM(AI8:AJ8) -> 51313295 | AL8: =AD8-SUM(AH8,AK8) -> 0 | AM8: =SUM(AE8:AG8,AI8) -> 51313295 | AN8: 51456000 | AO8: =AM8-AN8 -> -142705 | AQ8: 60255000 | AR8: =AM8-AQ8 -> -8941705 | AT8: #=SUM('[4-04 集計表.xlsx]3条集計(税抜)'!R25:T25)
B9: 維持 | C9: 営業 | D9: ポンプ場費 | E9: =+'[1]3条支出'!E8 -> 2356040225 | F9: 1724925338 | G9: 55051811 | I9: =+SUM(F9:H9) -> 1779977149 | K9: 576063076 | L9: =+SUM(J9:K9) -> 576063076 | M9: =E9-SUM(I9,L9) -> 0 | N9: ポンプ場費 | O9: =+'[1]3条支出'!T8 -> 2251657967 | P9: =+IFERROR(ROUND(F9*$O9/$E9,0),0) -> 1648504061 | Q9: =+IFERROR(ROUND(G9*$O9/$E9,0),0) -> 52612790 | R9: =+IFERROR(ROUND(H9*$O9/$E9,0),0) -> 0 | S9: =+SUM(P9:R9) -> 1701116851 | T9: =+IFERROR(ROUND(J9*$O9/$E9,0),0) -> 0 | U9: =+O9-S9-T9 -> 550541116 | V9: =+SUM(T9:U9) -> 550541116 | W9: =O9-SUM(S9,V9) -> 0 | X9: ポンプ場費 | AD9: =+O9 -> 2251657967 | AE9: =+P9 -> 1648504061 | AF9: =+Q9 -> 52612790 | AG9: =+R9 -> 0 | AH9: =+SUM(AE9:AG9) -> 1701116851 | AI9: =+T9 -> 0 | AJ9: =+U9 -> 550541116 | AK9: =+SUM(AI9:AJ9) -> 550541116 | AL9: =AD9-SUM(AH9,AK9) -> 0 | AM9: =SUM(AE9:AG9,AI9) -> 1701116851 | AN9: 1645552000 | AO9: =AM9-AN9 -> 55564851 | AQ9: 1697315000 | AR9: =AM9-AQ9 -> 3801851 | AT9: #=SUM('[4-04 集計表.xlsx]3条集計(税抜)'!R26:T26)
B10: 維持 | C10: 営業 | D10: 処理場費 | E10: =+'[1]3条支出'!E9 -> 6557703864 | F10: 703775367 | G10: 144110894 | H10: 445816778 | I10: =+SUM(F10:H10) -> 1293703039 | J10: =83018974+51475850 -> 134494824 | K10: =5180981851-51475850 -> 5129506001 | L10: =+SUM(J10:K10) -> 5264000825 | M10: =E10-SUM(I10,L10) -> 0 | N10: 処理場費 | O10: =+'[1]3条支出'!T9 -> 6037810078 | P10: =+IFERROR(ROUND(F10*$O10/$E10,0),0) -> 647980161 | Q10: =+IFERROR(ROUND(G10*$O10/$E10,0),0) -> 132685804 | R10: =+IFERROR(ROUND(H10*$O10/$E10,0),0) -> 410472490 | S10: =+SUM(P10:R10) -> 1191138455 | T10: =+IFERROR(ROUND(J10*$O10/$E10,0),0) -> 123832094 | U10: =+O10-S10-T10 -> 4722839529 | V10: =+SUM(T10:U10) -> 4846671623 | W10: =O10-SUM(S10,V10) -> 0 | X10: 処理場費 | AD10: =+O10 -> 6037810078 | AE10: =+P10 -> 647980161 | AF10: =+Q10 -> 132685804 | AG10: =+R10 -> 410472490 | AH10: =+SUM(AE10:AG10) -> 1191138455 | AI10: =+T10 -> 123832094 | AJ10: =+U10 -> 4722839529 | AK10: =+SUM(AI10:AJ10) -> 4846671623 | AL10: =AD10-SUM(AH10,AK10) -> 0 | AM10: =SUM(AE10:AG10,AI10) -> 1314970549 | AN10: 1151544454 | AO10: =AM10-AN10 -> 163426095 | AQ10: 1274316000 | AR10: =AM10-AQ10 -> 40654549 | AT10: #=SUM('[4-04 集計表.xlsx]3条集計(税抜)'!R27:T27)
B11: 維持 | C11: 営業 | D11: 受託工事費 | E11: =+'[1]3条支出'!E10 -> 0 | I11: =+SUM(F11:H11) -> 0 | K11: =+E11-I11-J11 -> 0 | L11: =+SUM(J11:K11) -> 0 | M11: =E11-SUM(I11,L11) -> 0 | N11: 受託工事費 | O11: =+'[1]3条支出'!T10 -> 0 | P11: =+IFERROR(ROUND(F11*$O11/$E11,0),0) -> 0 | Q11: =+IFERROR(ROUND(G11*$O11/$E11,0),0) -> 0 | R11: =+IFERROR(ROUND(H11*$O11/$E11,0),0) -> 0 | S11: =+SUM(P11:R11) -> 0 | T11: =+IFERROR(ROUND(J11*$O11/$E11,0),0) -> 0 | U11: =+O11-S11-T11 -> 0 | V11: =+SUM(T11:U11) -> 0 | W11: =O11-SUM(S11,V11) -> 0 | X11: 受託工事費 | AD11: =+O11 -> 0 | AE11: =+P11 -> 0 | AF11: =+Q11 -> 0 | AG11: =+R11 -> 0 | AH11: =+SUM(AE11:AG11) -> 0 | AI11: =+T11 -> 0 | AJ11: =+U11 -> 0 | AK11: =+SUM(AI11:AJ11) -> 0 | AL11: =AD11-SUM(AH11,AK11) -> 0 | AM11: =SUM(AE11:AG11,AI11) -> 0 | AO11: =AM11-AN11 -> 0 | AR11: =AM11-AQ11 -> 0
B12: 維持 | C12: 営業 | D12: 普及促進費 | E12: =+'[1]3条支出'!E11 -> 88849549 | H12: =+補助補給!Y4 -> 0 | I12: =+SUM(F12:H12) -> 0 | J12: =ROUND((E12-H12)/2,0) -> 44424775 | K12: =+E12-I12-J12 -> 44424774 | L12: =+SUM(J12:K12) -> 88849549 | M12: =E12-SUM(I12,L12) -> 0 | N12: 普及促進費 | O12: =+'[1]3条支出'!T11 -> 87134052 | R12: =+補助補給!AZ4 -> 0 | S12: =+SUM(P12:R12) -> 0 | T12: =+ROUND((O12-R12)/2,0) -> 43567026 | U12: =+O12-S12-T12 -> 43567026 | V12: =+SUM(T12:U12) -> 87134052 | W12: =O12-SUM(S12,V12) -> 0 | X12: 普及促進費 | AD12: =+O12 -> 87134052 | AE12: =+P12 -> 0 | AF12: =+Q12 -> 0 | AG12: =+R12 -> 0 | AH12: =+SUM(AE12:AG12) -> 0 | AI12: =+T12 -> 43567026 | AJ12: =+U12 -> 43567026 | AK12: =+SUM(AI12:AJ12) -> 87134052 | AL12: =AD12-SUM(AH12,AK12) -> 0 | AM12: =SUM(AE12:AG12,AI12) -> 43567026 | AN12: 42873000 | AO12: =AM12-AN12 -> 694026 | AQ12: 39027000 | AR12: =AM12-AQ12 -> 4540026 | AT12: #=SUM('[4-04 集計表.xlsx]3条集計(税抜)'!R28:T28)
B13: 維持 | C13: 営業 | D13: 水洗化貸付事業費 | E13: =+'[1]3条支出'!E12 -> 10483859 | H13: =+E13 -> 10483859 | I13: =+SUM(F13:H13) -> 10483859 | K13: =+E13-I13-J13 -> 0 | L13: =+SUM(J13:K13) -> 0 | M13: =E13-SUM(I13,L13) -> 0 | N13: 水洗化貸付事業費 | O13: =+'[1]3条支出'!T12 -> 10396270 | R13: =+O13 -> 10396270 | S13: =+SUM(P13:R13) -> 10396270 | U13: =+O13-S13-T13 -> 0 | V13: =+SUM(T13:U13) -> 0 | W13: =O13-SUM(S13,V13) -> 0 | X13: 水洗化貸付事業費 | AD13: =+O13 -> 10396270 | AE13: =+P13 -> 0 | AF13: =+Q13 -> 0 | AG13: =+R13 -> 10396270 | AH13: =+SUM(AE13:AG13) -> 10396270 | AI13: =+T13 -> 0 | AJ13: =+U13 -> 0 | AK13: =+SUM(AI13:AJ13) -> 0 | AL13: =AD13-SUM(AH13,AK13) -> 0 | AM13: =SUM(AE13:AG13,AI13) -> 10396270 | AN13: 10612000 | AO13: =AM13-AN13 -> -215730 | AQ13: 14660000 | AR13: =AM13-AQ13 -> -4263730 | AT13: #=SUM('[4-04 集計表.xlsx]3条集計(税抜)'!R29:T29)
B14: 維持 | C14: 営業 | D14: 業務費 | E14: =+'[1]3条支出'!E13 -> 1019945143 | I14: =+SUM(F14:H14) -> 0 | K14: =+E14-I14-J14 -> 1019945143 | L14: =+SUM(J14:K14) -> 1019945143 | M14: =E14-SUM(I14,L14) -> 0 | N14: 業務費 | O14: =+'[1]3条支出'!T13 -> 929691714 | R14: =+IFERROR(ROUND(H14/SUM([1]業務!E5:E9,[1]業務!E34)*SUM([1]業務!T5:T9,[1]業務!T34),0),0) -> 0 | S14: =+SUM(P14:R14) -> 0 | U14: =+O14-S14-T14 -> 929691714 | V14: =+SUM(T14:U14) -> 929691714 | W14: =O14-SUM(S14,V14) -> 0 | X14: 業務費 | AD14: =+O14 -> 929691714 | AE14: =+P14 -> 0 | AF14: =+Q14 -> 0 | AG14: =+R14 -> 0 | AH14: =+SUM(AE14:AG14) -> 0 | AI14: =+T14 -> 0 | AJ14: =+U14 -> 929691714 | AK14: =+SUM(AI14:AJ14) -> 929691714 | AL14: =AD14-SUM(AH14,AK14) -> 0 | AM14: =SUM(AE14:AG14,AI14) -> 0 | AN14: 0 | AO14: =AM14-AN14 -> 0 | AQ14: 0 | AR14: =AM14-AQ14 -> 0 | AT14: #=SUM('[4-04 集計表.xlsx]3条集計(税抜)'!R30:T30)
B15: 維持 | C15: 営業 | D15: 総係費 | E15: =+'[1]3条支出'!E14 -> 483965214 | F15: =+IFERROR(ROUND(([1]総係!$E$37-[1]総係!$E$36)*SUM(F7:F14)/SUM($F$7:$H$14,$J$7:$K$14),0),0) -> 122380384 | G15: =+IFERROR(ROUND(([1]総係!$E$37-[1]総係!$E$36)*SUM(G7:G14)/SUM($F$7:$H$14,$J$7:$K$14),0),0) -> 11686854 | I15: =+SUM(F15:H15) -> 134067238 | K15: =+E15-I15-J15 -> 349897976 | L15: =+SUM(J15:K15) -> 349897976 | M15: =E15-SUM(I15,L15) -> 0 | N15: 総係費 | O15: =+'[1]3条支出'!T14 -> 466286409 | P15: =+IFERROR(ROUND(([1]総係!$T$37-[1]総係!$T$36)*SUM(P7:P14)/SUM($P$7:$R$14,$T$7:$U$14),0),0) -> 119755277 | Q15: =+IFERROR(ROUND(([1]総係!$T$37-[1]総係!$T$36)*SUM(Q7:Q14)/SUM($P$7:$R$14,$T$7:$U$14),0),0) -> 11260122 | S15: =+SUM(P15:R15) -> 131015399 | U15: =+O15-S15-T15 -> 335271010 | V15: =+SUM(T15:U15) -> 335271010 | W15: =O15-SUM(S15,V15) -> 0 | X15: 総係費 | AD15: =+O15 -> 466286409 | AE15: =+P15 -> 119755277 | AF15: =+Q15 -> 11260122 | AG15: =+R15 -> 0 | AH15: =+SUM(AE15:AG15) -> 131015399 | AI15: =+T15 -> 0 | AJ15: =+U15 -> 335271010 | AK15: =+SUM(AI15:AJ15) -> 335271010 | AL15: =AD15-SUM(AH15,AK15) -> 0 | AM15: =SUM(AE15:AG15,AI15) -> 131015399 | AN15: 121395000 | AO15: =AM15-AN15 -> 9620399 | AQ15: 135565000 | AR15: =AM15-AQ15 -> -4549601 | AT15: #=SUM('[4-04 集計表.xlsx]3条集計(税抜)'!R31:T31)
B16: 維持 | C16: 営業 | D16: 特環公共下水道費 | E16: =+'[1]3条支出'!E15 -> 106990906 | I16: =+SUM(F16:H16) -> 0 | J16: 0 | K16: =+E16-I16-J16 -> 106990906 | L16: =+SUM(J16:K16) -> 106990906 | M16: =E16-SUM(I16,L16) -> 0 | N16: 特環公共下水道費 | O16: =+'[1]3条支出'!T15 -> 97276922 | R16: =+補助補給!AZ5 -> 0 | S16: =+SUM(P16:R16) -> 0 | U16: =+O16-S16-T16 -> 97276922 | V16: =+SUM(T16:U16) -> 97276922 | W16: =O16-SUM(S16,V16) -> 0 | X16: 特環費 | AD16: =+O16 -> 97276922 | AE16: =+P16 -> 0 | AF16: =+Q16 -> 0 | AG16: =+R16 -> 0 | AH16: =+SUM(AE16:AG16) -> 0 | AI16: =+T16 -> 0 | AJ16: =+U16 -> 97276922 | AK16: =+SUM(AI16:AJ16) -> 97276922 | AL16: =AD16-SUM(AH16,AK16) -> 0 | AM16: =SUM(AE16:AG16,AI16) -> 0 | AN16: 566363 | AO16: =AM16-AN16 -> -566363 | AQ16: 0 | AR16: =AM16-AQ16 -> 0 | AT16: #=SUM('[4-04 集計表.xlsx]3条集計(税抜)'!R32:T32)
B17: 維持 | C17: 営業 | D17: 農業集落排水費 | E17: =+'[1]3条支出'!E16 -> 247654024 | I17: =+SUM(F17:H17) -> 0 | J17: 0 | K17: =+E17-I17-J17 -> 247654024 | L17: =+SUM(J17:K17) -> 247654024 | M17: =E17-SUM(I17,L17) -> 0 | N17: 農業集落排水費 | O17: =+'[1]3条支出'!T16 -> 225167795 | R17: =+補助補給!AZ6 -> 0 | S17: =+SUM(P17:R17) -> 0 | U17: =+O17-S17-T17 -> 225167795 | V17: =+SUM(T17:U17) -> 225167795 | W17: =O17-SUM(S17,V17) -> 0 | X17: 農集費 | AD17: =+O17 -> 225167795 | AE17: =+P17 -> 0 | AF17: =+Q17 -> 0 | AG17: =+R17 -> 0 | AH17: =+SUM(AE17:AG17) -> 0 | AI17: =+T17 -> 0 | AJ17: =+U17 -> 225167795 | AK17: =+SUM(AI17:AJ17) -> 225167795 | AL17: =AD17-SUM(AH17,AK17) -> 0 | AM17: =SUM(AE17:AG17,AI17) -> 0 | AN17: 3919090 | AO17: =AM17-AN17 -> -3919090 | AQ17: 0 | AR17: =AM17-AQ17 -> 0 | AT17: #=SUM('[4-04 集計表.xlsx]3条集計(税抜)'!R33:T33)
B18: 維持 | C18: 営業 | D18: 浄化槽費 | E18: =+'[1]3条支出'!E17 -> 76388330 | I18: =+SUM(F18:H18) -> 0 | K18: =+E18-I18-J18 -> 76388330 | L18: =+SUM(J18:K18) -> 76388330 | M18: =E18-SUM(I18,L18) -> 0 | N18: 浄化槽費 | O18: =+'[1]3条支出'!T17 -> 69941329 | R18: =+補助補給!AZ7 -> 0 | S18: =+SUM(P18:R18) -> 0 | U18: =+O18-S18-T18 -> 69941329 | V18: =+SUM(T18:U18) -> 69941329 | W18: =O18-SUM(S18,V18) -> 0 | X18: 浄化槽費 | AD18: =+O18 -> 69941329 | AE18: =+P18 -> 0 | AF18: =+Q18 -> 0 | AG18: =+R18 -> 0 | AH18: =+SUM(AE18:AG18) -> 0 | AI18: =+T18 -> 0 | AJ18: =+U18 -> 69941329 | AK18: =+SUM(AI18:AJ18) -> 69941329 | AL18: =AD18-SUM(AH18,AK18) -> 0 | AM18: =SUM(AE18:AG18,AI18) -> 0 | AN18: 0 | AO18: =AM18-AN18 -> 0 | AQ18: 0 | AR18: =AM18-AQ18 -> 0 | AT18: #=SUM('[4-04 集計表.xlsx]3条集計(税抜)'!R34:T34)
B19: 維持 | C19: 営業 | D19: 災害復旧費 | E19: =+'[1]3条支出'!E18 -> 0 | I19: =+SUM(F19:H19) -> 0 | K19: =+E19-I19-J19 -> 0 | L19: =+SUM(J19:K19) -> 0 | M19: =E19-SUM(I19,L19) -> 0 | N19: 災害復旧費 | O19: =+'[1]3条支出'!T18 -> 0 | S19: =+SUM(P19:R19) -> 0 | U19: =+O19-S19-T19 -> 0 | V19: =+SUM(T19:U19) -> 0 | W19: =O19-SUM(S19,V19) -> 0 | X19: 災害復旧費 | AD19: =+O19 -> 0 | AE19: =+P19 -> 0 | AF19: =+Q19 -> 0 | AG19: =+R19 -> 0 | AH19: =+SUM(AE19:AG19) -> 0 | AI19: =+T19 -> 0 | AJ19: =+U19 -> 0 | AK19: =+SUM(AI19:AJ19) -> 0 | AL19: =AD19-SUM(AH19,AK19) -> 0 | AM19: =SUM(AE19:AG19,AI19) -> 0 | AO19: =AM19-AN19 -> 0 | AR19: =AM19-AQ19 -> 0
B20: 維持 | C20: 営業 | D20: 資産減耗費（固定資産撤去費） | E20: =+[1]減耗!$E$7 -> 0 | F20: 0 | I20: =+SUM(F20:H20) -> 0 | K20: 0 | L20: =+SUM(J20:K20) -> 0 | M20: =E20-SUM(I20,L20) -> 0 | N20: 資産減耗費（固定資産撤去費） | O20: =+[1]減耗!T7 -> 0 | P20: =+IFERROR(ROUND(F20*$O20/$E20,0),0) -> 0 | Q20: =+IFERROR(ROUND(G20*$O20/$E20,0),0) -> 0 | R20: =+IFERROR(ROUND(H20*$O20/$E20,0),0) -> 0 | S20: =+SUM(P20:R20) -> 0 | T20: =+IFERROR(ROUND(J20*$O20/$E20,0),0) -> 0 | U20: =+O20-S20-T20 -> 0 | V20: =+SUM(T20:U20) -> 0 | W20: =O20-SUM(S20,V20) -> 0 | X20: 資産減耗費（固定資産撤去費） | AD20: =+O20 -> 0 | AE20: =+P20 -> 0 | AF20: =+Q20 -> 0 | AG20: =+R20 -> 0 | AH20: =+SUM(AE20:AG20) -> 0 | AI20: =+T20 -> 0 | AJ20: =+U20 -> 0 | AK20: =+SUM(AI20:AJ20) -> 0 | AL20: =AD20-SUM(AH20,AK20) -> 0 | AM20: =SUM(AE20:AG20,AI20) -> 0 | AO20: =AM20-AN20 -> 0 | AR20: =AM20-AQ20 -> 0
AM21: =SUM(AE21:AG21,AI21) -> 0 | AO21: =AM21-AN21 -> 0 | AR21: =AM21-AQ21 -> 0
B22: 維持 | C22: 営外 | D22: 一時借入金利息 | E22: =+[1]営外!E11 -> 2483 | F22: =+雨汚支出!AV3 -> 0 | G22: =+雨汚支出!AW3 -> 0 | H22: =+雨汚支出!AX3 -> 0 | I22: =+SUM(F22:H22) -> 0 | J22: =+雨汚支出!AZ3 -> 0 | K22: =+雨汚支出!BA3 -> 2483 | L22: =+SUM(J22:K22) -> 2483 | M22: =E22-SUM(I22,L22) -> 0 | N22: 一時借入金利息 | O22: =+[1]営外!T11 -> 2483 | P22: =+雨汚支出!BF3 -> 0 | Q22: =+雨汚支出!BG3 -> 0 | R22: =+雨汚支出!BH3 -> 0 | S22: =+SUM(P22:R22) -> 0 | T22: =+雨汚支出!BJ3 -> 0 | U22: =+雨汚支出!BK3 -> 2483 | V22: =+SUM(T22:U22) -> 2483 | W22: =O22-SUM(S22,V22) -> 0 | X22: 一時借入金利息 | AD22: =+O22 -> 2483 | AE22: =+P22 -> 0 | AF22: =+Q22 -> 0 | AG22: =+R22 -> 0 | AH22: =+SUM(AE22:AG22) -> 0 | AI22: =+T22 -> 0 | AJ22: =+U22 -> 2483 | AK22: =+SUM(AI22:AJ22) -> 2483 | AL22: =AD22-SUM(AH22,AK22) -> 0 | AM22: =SUM(AE22:AG22,AI22) -> 0 | AO22: =AM22-AN22 -> 0 | AR22: =AM22-AQ22 -> 0
B23: 維持 | C23: 営外 | D23: 雑支出（還付加算金+その他） | E23: =+[1]営外!E15+[1]営外!E16-E24 -> 25896 | F23: =+雨汚支出!AV4+雨汚支出!AV5-F24 -> 0 | G23: =+雨汚支出!AW4+雨汚支出!AW5-G24 -> 0 | H23: =+雨汚支出!AX4+雨汚支出!AX5-H24 -> 0 | I23: =+SUM(F23:H23) -> 0 | J23: =+雨汚支出!AZ4+雨汚支出!AZ5-J24 -> 0 | K23: =+雨汚支出!BA4+雨汚支出!BA5-K24 -> 25896 | L23: =+SUM(J23:K23) -> 25896 | M23: =E23-SUM(I23,L23) -> 0 | N23: 雑支出（還付加算金+その他） | O23: =+[1]営外!T15+[1]営外!T16-O24 -> 24123 | P23: =+雨汚支出!BF4+雨汚支出!BF5-P24 -> 0 | Q23: =+雨汚支出!BG4+雨汚支出!BG5-Q24 -> 0 | R23: =+雨汚支出!BH4+雨汚支出!BH5-R24 -> 0 | S23: =+SUM(P23:R23) -> 0 | T23: =+雨汚支出!BJ4+雨汚支出!BJ5-T24 -> 0 | U23: =+雨汚支出!BK4+雨汚支出!BK5-U24 -> 24123 | V23: =+SUM(T23:U23) -> 24123 | W23: =O23-SUM(S23,V23) -> 0 | X23: 雑支出（還付加算金+その他） | AD23: =+O23 -> 24123 | AE23: =+P23 -> 0 | AF23: =+Q23 -> 0 | AG23: =+R23 -> 0 | AH23: =+SUM(AE23:AG23) -> 0 | AI23: =+T23 -> 0 | AJ23: =+U23 -> 24123 | AK23: =+SUM(AI23:AJ23) -> 24123 | AL23: =AD23-SUM(AH23,AK23) -> 0 | AM23: =SUM(AE23:AG23,AI23) -> 0 | AO23: =AM23-AN23 -> 0 | AR23: =AM23-AQ23 -> 0
B24: 維持 | C24: 営外 | D24: 雑支出（災害支援経費等） | E24: =+[1]営外!E20 -> 9198273 | I24: =+SUM(F24:H24) -> 0 | K24: =+E24-I24-J24 -> 9198273 | L24: =+SUM(J24:K24) -> 9198273 | M24: =E24-SUM(I24,L24) -> 0 | N24: 雑支出（災害支援経費等） | O24: =+[1]営外!T20 -> 8710224 | S24: =+SUM(P24:R24) -> 0 | U24: =+O24-S24-T24 -> 8710224 | V24: =+SUM(T24:U24) -> 8710224 | W24: =O24-SUM(S24,V24) -> 0 | X24: 雑支出（災害支援経費等） | AD24: =+O24 -> 8710224 | AE24: =+P24 -> 0 | AF24: =+Q24 -> 0 | AG24: =+R24 -> 0 | AH24: =+SUM(AE24:AG24) -> 0 | AI24: =+T24 -> 0 | AJ24: =+U24 -> 8710224 | AK24: =+SUM(AI24:AJ24) -> 8710224 | AL24: =AD24-SUM(AH24,AK24) -> 0 | AM24: =SUM(AE24:AG24,AI24) -> 0 | AN24: 7273000 | AO24: =AM24-AN24 -> -7273000 | AQ24: 0 | AR24: =AM24-AQ24 -> 0 | AT24: #=SUM('[4-04 集計表.xlsx]3条集計(税抜)'!R39:T39)
B25: 維持 | C25: 営外 | D25: 雑支出（控除不可消費税等）維持費分 | I25: =+SUM(F25:H25) -> 0 | K25: =+E25-I25-J25 -> 0 | L25: =+SUM(J25:K25) -> 0 | M25: =E25-SUM(I25,L25) -> 0 | N25: 雑支出（控除不可消費税等）維持費分 | S25: =+SUM(P25:R25) -> 0 | U25: =+O25-S25-T25 -> 0 | V25: =+SUM(T25:U25) -> 0 | W25: =O25-SUM(S25,V25) -> 0 | X25: 雑支出（控除不可消費税等）維持費分 | AD25: =+AD130-AD39 -> 209933209 | AE25: =+AE130-AE39 -> 161840742 | AF25: =+AF130-AF39 -> 15449991 | AG25: =+AG130-AG39 -> 23053301 | AH25: =+SUM(AE25:AG25) -> 200344034 | AI25: =+AI130-AI39 -> 9576435 | AJ25: =+AJ130-AJ39 -> 12740 | AK25: =+SUM(AI25:AJ25) -> 9589175 | AL25: =AD25-SUM(AH25,AK25) -> 0 | AM25: =SUM(AE25:AG25,AI25) -> 209920469 | AN25: 191121651 | AO25: =AM25-AN25 -> 18798818 | AQ25: 210556000 | AR25: =AM25-AQ25 -> -635531 | AT25: #=SUM('[4-04 集計表.xlsx]3条集計(税抜)'!R40:T40)
B26: 維持 | C26: 営外 | D26: 雑支出（免税事業者に係る控除不能額） | N26: 雑支出（免税事業者に係る控除不能額） | X26: 雑支出（免税事業者に係る控除不能額） | AD26: =[1]営外!$T$19 -> 629 | AH26: =+SUM(AE26:AG26) -> 0 | AJ26: =[1]営外!$T$19 -> 629 | AK26: =+SUM(AI26:AJ26) -> 629 | AL26: =AD26-SUM(AH26,AK26) -> 0 | AM26: =SUM(AE26:AG26,AI26) -> 0 | AO26: =AM26-AN26 -> 0 | AR26: =AM26-AQ26 -> 0
AM27: =SUM(AE27:AG27,AI27) -> 0 | AO27: =AM27-AN27 -> 0 | AR27: =AM27-AQ27 -> 0
B28: 維持 | C28: 特別 | D28: 固定資産売却損 | E28: =+'[1]3条支出'!$E$30 -> 10315355 | F28: =+雨汚支出!AV6 -> 0 | G28: =+雨汚支出!AW6 -> 0 | H28: =+雨汚支出!AX6 -> 0 | I28: =+SUM(F28:H28) -> 0 | J28: =+雨汚支出!AZ6 -> 0 | K28: =+雨汚支出!BA6 -> 10315355 | L28: =+SUM(J28:K28) -> 10315355 | M28: =E28-SUM(I28,L28) -> 0 | N28: 固定資産売却損 | O28: =+'[1]3条支出'!$T$30 -> 10315355 | P28: =+F28 -> 0 | Q28: =+G28 -> 0 | S28: =+SUM(P28:R28) -> 0 | T28: =+J28 -> 0 | U28: =+O28-S28-T28 -> 10315355 | V28: =+SUM(T28:U28) -> 10315355 | W28: =O28-SUM(S28,V28) -> 0 | X28: 固定資産売却損 | AD28: =+O28 -> 10315355 | AE28: =+P28 -> 0 | AF28: =+Q28 -> 0 | AG28: =+R28 -> 0 | AH28: =+SUM(AE28:AG28) -> 0 | AI28: =+T28 -> 0 | AJ28: =+U28 -> 10315355 | AK28: =+SUM(AI28:AJ28) -> 10315355 | AL28: =AD28-SUM(AH28,AK28) -> 0 | AM28: =SUM(AE28:AG28,AI28) -> 0 | AO28: =AM28-AN28 -> 0 | AR28: =AM28-AQ28 -> 0
B29: 維持 | C29: 特別 | D29: 過年度損益修正損 | E29: =+'[1]3条支出'!$E$28-E42 -> 10679943 | F29: =+雨汚支出!AV7-F42 -> 6760 | G29: =+雨汚支出!AW7-G42 -> 0 | H29: =+雨汚支出!AX7-H42 -> 0 | I29: =+SUM(F29:H29) -> 6760 | J29: =+雨汚支出!AZ7-J42 -> 0 | K29: =+雨汚支出!BA7-K42 -> 10673183 | L29: =+SUM(J29:K29) -> 10673183 | M29: =E29-SUM(I29,L29) -> 0 | N29: 過年度損益修正損 | O29: =+'[1]3条支出'!$T$28-O42 -> 9711499 | P29: =+雨汚支出!BF7-P42 -> 6733 | Q29: =+雨汚支出!BG7-Q42 -> 0 | R29: =+雨汚支出!BH7-R42 -> 0 | S29: =+SUM(P29:R29) -> 6733 | T29: =+雨汚支出!BJ7-T42 -> 0 | U29: =+雨汚支出!BK7-U42 -> 9704766 | V29: =+SUM(T29:U29) -> 9704766 | W29: =O29-SUM(S29,V29) -> 0 | X29: 過年度損益修正損 | AD29: =+O29 -> 9711499 | AE29: =+P29 -> 6733 | AF29: =+Q29 -> 0 | AG29: =+R29 -> 0 | AH29: =+SUM(AE29:AG29) -> 6733 | AI29: =+T29 -> 0 | AJ29: =+U29 -> 9704766 | AK29: =+SUM(AI29:AJ29) -> 9704766 | AL29: =AD29-SUM(AH29,AK29) -> 0 | AM29: =SUM(AE29:AG29,AI29) -> 6733 | AO29: =AM29-AN29 -> 6733 | AR29: =AM29-AQ29 -> 6733
B30: 維持 | C30: 特別 | D30: その他特別損失 | E30: =+'[1]3条支出'!$E$29-E43 -> 0 | F30: =+雨汚支出!AV8-F43 -> 0 | G30: =+雨汚支出!AW8-G43 -> 0 | H30: =+雨汚支出!AX8-H43 -> 0 | I30: =+SUM(F30:H30) -> 0 | J30: =+雨汚支出!AZ8-J43 -> 0 | K30: =+雨汚支出!BA8-K43 -> 0 | L30: =+SUM(J30:K30) -> 0 | M30: =E30-SUM(I30,L30) -> 0 | N30: その他特別損失 | O30: =+'[1]3条支出'!$T$29-O43 -> 0 | P30: =+雨汚支出!BF8-P43 -> 0 | Q30: =+雨汚支出!BG8-Q43 -> 0 | R30: =+雨汚支出!BH8-R43 -> 0 | S30: =+SUM(P30:R30) -> 0 | T30: =+雨汚支出!BJ8-T43 -> 0 | U30: =+雨汚支出!BK8-U43 -> 0 | V30: =+SUM(T30:U30) -> 0 | W30: =O30-SUM(S30,V30) -> 0 | X30: その他特別損失 | AD30: =+O30 -> 0 | AE30: =+P30 -> 0 | AF30: =+Q30 -> 0 | AG30: =+R30 -> 0 | AH30: =+SUM(AE30:AG30) -> 0 | AI30: =+T30 -> 0 | AJ30: =+U30 -> 0 | AK30: =+SUM(AI30:AJ30) -> 0 | AL30: =AD30-SUM(AH30,AK30) -> 0 | AM30: =SUM(AE30:AG30,AI30) -> 0 | AO30: =AM30-AN30 -> 0 | AR30: =AM30-AQ30 -> 0
B31: 維持 | C31: 特別 | I31: =+SUM(F31:H31) -> 0 | K31: =+E31-I31-J31 -> 0 | L31: =+SUM(J31:K31) -> 0 | M31: =E31-SUM(I31,L31) -> 0 | S31: =+SUM(P31:R31) -> 0 | U31: =+O31-S31-T31 -> 0 | V31: =+SUM(T31:U31) -> 0 | W31: =O31-SUM(S31,V31) -> 0 | AD31: =+O31 -> 0 | AE31: =+P31 -> 0 | AF31: =+Q31 -> 0 | AG31: =+R31 -> 0 | AH31: =+SUM(AE31:AG31) -> 0 | AI31: =+T31 -> 0 | AJ31: =+U31 -> 0 | AK31: =+SUM(AI31:AJ31) -> 0 | AL31: =AD31-SUM(AH31,AK31) -> 0 | AM31: =SUM(AE31:AG31,AI31) -> 0 | AO31: =AM31-AN31 -> 0 | AR31: =AM31-AQ31 -> 0
B32: 維持 | C32: 特別 | I32: =+SUM(F32:H32) -> 0 | K32: =+E32-I32-J32 -> 0 | L32: =+SUM(J32:K32) -> 0 | M32: =E32-SUM(I32,L32) -> 0 | S32: =+SUM(P32:R32) -> 0 | U32: =+O32-S32-T32 -> 0 | V32: =+SUM(T32:U32) -> 0 | W32: =O32-SUM(S32,V32) -> 0 | AD32: =+O32 -> 0 | AE32: =+P32 -> 0 | AF32: =+Q32 -> 0 | AG32: =+R32 -> 0 | AH32: =+SUM(AE32:AG32) -> 0 | AI32: =+T32 -> 0 | AJ32: =+U32 -> 0 | AK32: =+SUM(AI32:AJ32) -> 0 | AL32: =AD32-SUM(AH32,AK32) -> 0 | AM32: =SUM(AE32:AG32,AI32) -> 0 | AO32: =AM32-AN32 -> 0 | AR32: =AM32-AQ32 -> 0
AM33: =SUM(AE33:AG33,AI33) -> 0 | AO33: =AM33-AN33 -> 0 | AR33: =AM33-AQ33 -> 0
B34: 資本 | C34: 営業 | D34: 減価償却費 | E34: ='[1]3条支出'!$E$19 -> 26551442230 | F34: 12571100990 | G34: 122404286 | I34: =+SUM(F34:H34) -> 12693505276 | J34: 17206476 | K34: =13857936954-17206476 -> 13840730478 | L34: =+SUM(J34:K34) -> 13857936954 | M34: =E34-SUM(I34,L34) -> 0 | N34: 減価償却費 | O34: =+'[1]3条支出'!$T$19 -> 26551442230 | P34: =+F34 -> 12571100990 | Q34: =+G34 -> 122404286 | R34: =+H34 -> 0 | S34: =+SUM(P34:R34) -> 12693505276 | T34: =+J34 -> 17206476 | U34: =+K34 -> 13840730478 | V34: =+SUM(T34:U34) -> 13857936954 | W34: =O34-SUM(S34,V34) -> 0 | X34: 減価償却費 | AD34: =+O34 -> 26551442230 | AE34: =+P34 -> 12571100990 | AF34: =+Q34 -> 122404286 | AG34: =+R34 -> 0 | AH34: =+SUM(AE34:AG34) -> 12693505276 | AI34: =+T34 -> 17206476 | AJ34: =+U34 -> 13840730478 | AK34: =+SUM(AI34:AJ34) -> 13857936954 | AL34: =AD34-SUM(AH34,AK34) -> 0 | AM34: =SUM(AE34:AG34,AI34) -> 12710711752 | AN34: 12722677000 | AO34: =AM34-AN34 -> -11965248 | AQ34: 12322171000 | AR34: =AM34-AQ34 -> 388540752 | AT34: #=SUM('[4-04 集計表.xlsx]3条集計(税抜)'!R42:T42)
B35: 資本 | C35: 営業 | D35: 資産減耗費（固定資産除却費） | E35: ='[1]3条支出'!$E$20-E20 -> 503761871 | F35: =+E35-L35-G35 -> 304154336 | G35: =+IFERROR(ROUND((E35-L35)*G34/I34,0),0) -> 2961538 | I35: =+SUM(F35:H35) -> 307115874 | K35: =4976419+191669578 -> 196645997 | L35: =+SUM(J35:K35) -> 196645997 | M35: =E35-SUM(I35,L35) -> 0 | N35: 資産減耗費（固定資産除却費） | O35: =+'[1]3条支出'!$T$20-O20 -> 503761871 | P35: =+F35 -> 304154336 | Q35: =+G35 -> 2961538 | S35: =+SUM(P35:R35) -> 307115874 | T35: =+J35 -> 0 | U35: =+K35 -> 196645997 | V35: =+SUM(T35:U35) -> 196645997 | W35: =O35-SUM(S35,V35) -> 0 | X35: 資産減耗費（固定資産除却費） | AD35: =+O35 -> 503761871 | AE35: =+P35 -> 304154336 | AF35: =+Q35 -> 2961538 | AG35: =+R35 -> 0 | AH35: =+SUM(AE35:AG35) -> 307115874 | AI35: =+T35 -> 0 | AJ35: =+U35 -> 196645997 | AK35: =+SUM(AI35:AJ35) -> 196645997 | AL35: =AD35-SUM(AH35,AK35) -> 0 | AM35: =SUM(AE35:AG35,AI35) -> 307115874 | AN35: 285010000 | AO35: =AM35-AN35 -> 22105874 | AQ35: 162051000 | AR35: =AM35-AQ35 -> 145064874 | AT35: #=SUM('[4-04 集計表.xlsx]3条集計(税抜)'!R43:T43)
AM36: =SUM(AE36:AG36,AI36) -> 0 | AO36: =AM36-AN36 -> 0 | AR36: =AM36-AQ36 -> 0
B37: 資本 | C37: 営外 | D37: 企業債利息 | E37: =+[1]営外!E6 -> 3884144913 | F37: 1638072143 | G37: 0 | H37: 36375158 | I37: =+SUM(F37:H37) -> 1674447301 | J37: 315322238 | K37: 1894375374 | L37: =+SUM(J37:K37) -> 2209697612 | M37: =E37-SUM(I37,L37) -> 0 | N37: 企業債利息 | O37: =+[1]営外!T6 -> 3884144913 | P37: =+F37 -> 1638072143 | Q37: =+G37 -> 0 | R37: =+H37 -> 36375158 | S37: =+SUM(P37:R37) -> 1674447301 | T37: =+J37 -> 315322238 | U37: =+O37-S37-T37 -> 1894375374 | V37: =+SUM(T37:U37) -> 2209697612 | W37: =O37-SUM(S37,V37) -> 0 | X37: 支払利息及び企業債取扱諸費 | AD37: =+O37 -> 3884144913 | AE37: =+P37 -> 1638072143 | AF37: =+Q37 -> 0 | AG37: =+R37 -> 36375158 | AH37: =+SUM(AE37:AG37) -> 1674447301 | AI37: =+T37 -> 315322238 | AJ37: =+U37 -> 1894375374 | AK37: =+SUM(AI37:AJ37) -> 2209697612 | AL37: =AD37-SUM(AH37,AK37) -> 0 | AM37: =SUM(AE37:AG37,AI37) -> 1989769539 | AN37: 1991724000 | AO37: =AM37-AN37 -> -1954461 | AQ37: 2104635000 | AR37: =AM37-AQ37 -> -114865461 | AT37: #=SUM('[4-04 集計表.xlsx]3条集計(税抜)'!R44:T44)
B38: 資本 | C38: 営外 | D38: 企業債手数料及び取扱費 | E38: =+[1]営外!E9 -> 61813753 | F38: 30574206 | I38: =+SUM(F38:H38) -> 30574206 | K38: 31239547 | L38: =+SUM(J38:K38) -> 31239547 | M38: =E38-SUM(I38,L38) -> 0 | N38: 企業債手数料及び取扱費 | O38: =+[1]営外!T9 -> 56194321 | P38: =+IFERROR(ROUND(F38*$O38/$E38,0),0) -> 27794733 | Q38: =+IFERROR(ROUND(G38*$O38/$E38,0),0) -> 0 | R38: =+IFERROR(ROUND(H38*$O38/$E38,0),0) -> 0 | S38: =+SUM(P38:R38) -> 27794733 | T38: =+IFERROR(ROUND(J38*$O38/$E38,0),0) -> 0 | U38: =+O38-S38-T38 -> 28399588 | V38: =+SUM(T38:U38) -> 28399588 | W38: =O38-SUM(S38,V38) -> 0 | X38: 企業債手数料及び取扱費 | AD38: =+O38 -> 56194321 | AE38: =+P38 -> 27794733 | AF38: =+Q38 -> 0 | AG38: =+R38 -> 0 | AH38: =+SUM(AE38:AG38) -> 27794733 | AI38: =+T38 -> 0 | AJ38: =+U38 -> 28399588 | AK38: =+SUM(AI38:AJ38) -> 28399588 | AL38: =AD38-SUM(AH38,AK38) -> 0 | AM38: =SUM(AE38:AG38,AI38) -> 27794733 | AN38: 27828000 | AO38: =AM38-AN38 -> -33267 | AQ38: 38809000 | AR38: =AM38-AQ38 -> -11014267 | AT38: #=SUM('[4-04 集計表.xlsx]3条集計(税抜)'!R45:T45)
B39: 資本 | C39: 営外 | D39: 雑支出（控除不可消費税等）資本費分 | I39: =+SUM(F39:H39) -> 0 | K39: =+E39-I39-J39 -> 0 | L39: =+SUM(J39:K39) -> 0 | M39: =E39-SUM(I39,L39) -> 0 | N39: 雑支出（控除不可消費税等）資本費分 | S39: =+SUM(P39:R39) -> 0 | U39: =+O39-S39-T39 -> 0 | V39: =+SUM(T39:U39) -> 0 | W39: =O39-SUM(S39,V39) -> 0 | X39: 雑支出（控除不可消費税等）資本費分 | AD39: =+SUM(AD113,AD124) -> 2553639 | AE39: =+SUM(AE113,AE124) -> 2553639 | AF39: =+SUM(AF113,AF124) -> 0 | AG39: =+SUM(AG113,AG124) -> 0 | AH39: =+SUM(AE39:AG39) -> 2553639 | AI39: =+SUM(AI113,AI124) -> 0 | AJ39: =+SUM(AJ113,AJ124) -> 0 | AK39: =+SUM(AI39:AJ39) -> 0 | AL39: =AD39-SUM(AH39,AK39) -> 0 | AM39: =SUM(AE39:AG39,AI39) -> 2553639 | AN39: 2774706 | AO39: =AM39-AN39 -> -221067 | AQ39: 3873000 | AR39: =AM39-AQ39 -> -1319361 | AT39: #=SUM('[4-04 集計表.xlsx]3条集計(税抜)'!R47:T47)
AM40: =SUM(AE40:AG40,AI40) -> 0 | AO40: =AM40-AN40 -> 0 | AR40: =AM40-AQ40 -> 0
...

Sheet 雨汚収入
R1: 集計表（全体）↓ | AV1: 雨水（税込） | AZ1: 汚水（税込） | BC1: 合計 （税込） | BD1: チェック | BF1: 雨水（税抜） | BJ1: 汚水（税抜） | BM1: 合計 （税抜） | BN1: 税抜き 要調整額 | BO1: 3条収入ｼｰﾄ集計値
Y2: 執行額 | AV2: 区域内 | AW2: 区域外 | AX2: 一般行政 | AY2: 計 | AZ2: 基準内 | BA2: 基準外 | BB2: 計 | BF2: 区域内 | BG2: 区域外 | BH2: 一般行政 | BI2: 計 | BJ2: 基準内 | BK2: 基準外 | BL2: 計
N3: 481121400 | O3: 下水道事業収益 | P3: 営業収益 | Q3: 受託工事収益 | R3: 受託工事収益 | Y3: =+SUMIFS(Y$69:Y$891,$N$69:$N$891,$N3) -> 0 | AV3: =+SUMIFS(AV$69:AV$894,$N$69:$N$894,$N3) -> 0 | AW3: =+SUMIFS(AW$69:AW$894,$N$69:$N$894,$N3) -> 0 | AX3: =+SUMIFS(AX$69:AX$894,$N$69:$N$894,$N3) -> 0 | AY3: =+SUMIFS(AY$69:AY$894,$N$69:$N$894,$N3) -> 0 | AZ3: =+SUMIFS(AZ$69:AZ$894,$N$69:$N$894,$N3) -> 0 | BA3: =+SUMIFS(BA$69:BA$894,$N$69:$N$894,$N3) -> 0 | BB3: =+SUMIFS(BB$69:BB$894,$N$69:$N$894,$N3) -> 0 | BC3: =+SUMIFS(BC$69:BC$894,$N$69:$N$894,$N3) -> 0 | BD3: =+SUMIFS(BD$69:BD$784,$N$69:$N$784,$N3) -> 0 | BF3: =+SUMIFS(BF$69:BF$891,$N$69:$N$891,$N3) -> 0 | BG3: =+SUMIFS(BG$69:BG$891,$N$69:$N$891,$N3) -> 0 | BH3: =+SUMIFS(BH$69:BH$891,$N$69:$N$891,$N3) -> 0 | BI3: =+SUMIFS(BI$69:BI$891,$N$69:$N$891,$N3) -> 0 | BJ3: =+SUMIFS(BJ$69:BJ$891,$N$69:$N$891,$N3) -> 0 | BK3: =+SUMIFS(BK$69:BK$891,$N$69:$N$891,$N3) -> 0 | BL3: =+SUMIFS(BL$69:BL$891,$N$69:$N$891,$N3) -> 0 | BM3: =+SUMIFS(BM$69:BM$894,$N$69:$N$894,$N3) -> 0 | BN3: =+BO3-BM3 -> 0 | BO3: =+SUMIFS('[2]3条収入'!$AI$6:$AI$70,'[2]3条収入'!$C$6:$C$70,雨汚収入!N3) -> 0
N4: 481141500 | O4: 下水道事業収益 | P4: 営業収益 | Q4: その他営業収益 | R4: 産物売却代金 | Y4: =+SUMIFS(Y$69:Y$891,$N$69:$N$891,$N4) -> 187826166 | AV4: =+SUMIFS(AV$69:AV$894,$N$69:$N$894,$N4) -> 0 | AW4: =+SUMIFS(AW$69:AW$894,$N$69:$N$894,$N4) -> 0 | AX4: =+SUMIFS(AX$69:AX$894,$N$69:$N$894,$N4) -> 37753060 | AY4: =+SUMIFS(AY$69:AY$894,$N$69:$N$894,$N4) -> 37753060 | AZ4: =+SUMIFS(AZ$69:AZ$894,$N$69:$N$894,$N4) -> 0 | BA4: =+SUMIFS(BA$69:BA$894,$N$69:$N$894,$N4) -> 150073106 | BB4: =+SUMIFS(BB$69:BB$894,$N$69:$N$894,$N4) -> 150073106 | BC4: =+SUMIFS(BC$69:BC$894,$N$69:$N$894,$N4) -> 187826166 | BD4: =+SUMIFS(BD$69:BD$784,$N$69:$N$784,$N4) -> 0 | BF4: =+SUMIFS(BF$69:BF$891,$N$69:$N$891,$N4) -> 0 | BG4: =+SUMIFS(BG$69:BG$891,$N$69:$N$891,$N4) -> 0 | BH4: =+SUMIFS(BH$69:BH$891,$N$69:$N$891,$N4) -> 34320964 | BI4: =+SUMIFS(BI$69:BI$891,$N$69:$N$891,$N4) -> 34320964 | BJ4: =+SUMIFS(BJ$69:BJ$891,$N$69:$N$891,$N4) -> 0 | BK4: =+SUMIFS(BK$69:BK$891,$N$69:$N$891,$N4) -> 136430096 | BL4: =+SUMIFS(BL$69:BL$891,$N$69:$N$891,$N4) -> 136430096 | BM4: =+SUMIFS(BM$69:BM$894,$N$69:$N$894,$N4) -> 170751060 | BN4: =+BO4-BM4 -> 0 | BO4: =+SUMIFS('[2]3条収入'!$AI$6:$AI$70,'[2]3条収入'!$C$6:$C$70,雨汚収入!N4) -> 170751060
N5: 481141700 | O5: 下水道事業収益 | P5: 営業収益 | Q5: その他営業収益 | R5: 業務受託収益 | Y5: =+SUMIFS(Y$69:Y$891,$N$69:$N$891,$N5) -> 1409733 | AV5: =+SUMIFS(AV$69:AV$894,$N$69:$N$894,$N5) -> 902422 | AW5: =+SUMIFS(AW$69:AW$894,$N$69:$N$894,$N5) -> 507311 | AX5: =+SUMIFS(AX$69:AX$894,$N$69:$N$894,$N5) -> 0 | AY5: =+SUMIFS(AY$69:AY$894,$N$69:$N$894,$N5) -> 1409733 | AZ5: =+SUMIFS(AZ$69:AZ$894,$N$69:$N$894,$N5) -> 0 | BA5: =+SUMIFS(BA$69:BA$894,$N$69:$N$894,$N5) -> 0 | BB5: =+SUMIFS(BB$69:BB$894,$N$69:$N$894,$N5) -> 0 | BC5: =+SUMIFS(BC$69:BC$894,$N$69:$N$894,$N5) -> 1409733 | BD5: =+SUMIFS(BD$69:BD$784,$N$69:$N$784,$N5) -> 0 | BF5: =+SUMIFS(BF$69:BF$891,$N$69:$N$891,$N5) -> 820384 | BG5: =+SUMIFS(BG$69:BG$891,$N$69:$N$891,$N5) -> 461192 | BH5: =+SUMIFS(BH$69:BH$891,$N$69:$N$891,$N5) -> 0 | BI5: =+SUMIFS(BI$69:BI$891,$N$69:$N$891,$N5) -> 1281576 | BJ5: =+SUMIFS(BJ$69:BJ$891,$N$69:$N$891,$N5) -> 0 | BK5: =+SUMIFS(BK$69:BK$891,$N$69:$N$891,$N5) -> 0 | BL5: =+SUMIFS(BL$69:BL$891,$N$69:$N$891,$N5) -> 0 | BM5: =+SUMIFS(BM$69:BM$894,$N$69:$N$894,$N5) -> 1281576 | BN5: =+BO5-BM5 -> 0 | BO5: =+SUMIFS('[2]3条収入'!$AI$6:$AI$70,'[2]3条収入'!$C$6:$C$70,雨汚収入!N5) -> 1281576
N6: 481141915 | O6: 下水道事業収益 | P6: 営業収益 | Q6: その他営業収益 | R6: 手数料 | S6: 証明手数料 | Y6: =+SUMIFS(Y$69:Y$891,$N$69:$N$891,$N6) -> 71970 | AV6: =+SUMIFS(AV$69:AV$894,$N$69:$N$894,$N6) -> 32943 | AW6: =+SUMIFS(AW$69:AW$894,$N$69:$N$894,$N6) -> 0 | AX6: =+SUMIFS(AX$69:AX$894,$N$69:$N$894,$N6) -> 0 | AY6: =+SUMIFS(AY$69:AY$894,$N$69:$N$894,$N6) -> 32943 | AZ6: =+SUMIFS(AZ$69:AZ$894,$N$69:$N$894,$N6) -> 0 | BA6: =+SUMIFS(BA$69:BA$894,$N$69:$N$894,$N6) -> 39027 | BB6: =+SUMIFS(BB$69:BB$894,$N$69:$N$894,$N6) -> 39027 | BC6: =+SUMIFS(BC$69:BC$894,$N$69:$N$894,$N6) -> 71970 | BD6: =+SUMIFS(BD$69:BD$784,$N$69:$N$784,$N6) -> 0 | BF6: =+SUMIFS(BF$69:BF$891,$N$69:$N$891,$N6) -> 32943 | BG6: =+SUMIFS(BG$69:BG$891,$N$69:$N$891,$N6) -> 0 | BH6: =+SUMIFS(BH$69:BH$891,$N$69:$N$891,$N6) -> 0 | BI6: =+SUMIFS(BI$69:BI$891,$N$69:$N$891,$N6) -> 32943 | BJ6: =+SUMIFS(BJ$69:BJ$891,$N$69:$N$891,$N6) -> 0 | BK6: =+SUMIFS(BK$69:BK$891,$N$69:$N$891,$N6) -> 39027 | BL6: =+SUMIFS(BL$69:BL$891,$N$69:$N$891,$N6) -> 39027 | BM6: =+SUMIFS(BM$69:BM$894,$N$69:$N$894,$N6) -> 71970 | BN6: =+BO6-BM6 -> 0 | BO6: =+SUMIFS('[2]3条収入'!$AI$6:$AI$70,'[2]3条収入'!$C$6:$C$70,雨汚収入!N6) -> 71970
N7: 481141916 | O7: 下水道事業収益 | P7: 営業収益 | Q7: その他営業収益 | R7: 手数料 | S7: 指定業者登録等手数料 | Y7: =+SUMIFS(Y$69:Y$891,$N$69:$N$891,$N7) -> 539000 | AV7: =+SUMIFS(AV$69:AV$894,$N$69:$N$894,$N7) -> 0 | AW7: =+SUMIFS(AW$69:AW$894,$N$69:$N$894,$N7) -> 0 | AX7: =+SUMIFS(AX$69:AX$894,$N$69:$N$894,$N7) -> 0 | AY7: =+SUMIFS(AY$69:AY$894,$N$69:$N$894,$N7) -> 0 | AZ7: =+SUMIFS(AZ$69:AZ$894,$N$69:$N$894,$N7) -> 269500 | BA7: =+SUMIFS(BA$69:BA$894,$N$69:$N$894,$N7) -> 269500 | BB7: =+SUMIFS(BB$69:BB$894,$N$69:$N$894,$N7) -> 539000 | BC7: =+SUMIFS(BC$69:BC$894,$N$69:$N$894,$N7) -> 539000 | BD7: =+SUMIFS(BD$69:BD$784,$N$69:$N$784,$N7) -> 0 | BF7: =+SUMIFS(BF$69:BF$891,$N$69:$N$891,$N7) -> 0 | BG7: =+SUMIFS(BG$69:BG$891,$N$69:$N$891,$N7) -> 0 | BH7: =+SUMIFS(BH$69:BH$891,$N$69:$N$891,$N7) -> 0 | BI7: =+SUMIFS(BI$69:BI$891,$N$69:$N$891,$N7) -> 0 | BJ7: =+SUMIFS(BJ$69:BJ$891,$N$69:$N$891,$N7) -> 269500 | BK7: =+SUMIFS(BK$69:BK$891,$N$69:$N$891,$N7) -> 269500 | BL7: =+SUMIFS(BL$69:BL$891,$N$69:$N$891,$N7) -> 539000 | BM7: =+SUMIFS(BM$69:BM$894,$N$69:$N$894,$N7) -> 539000 | BN7: =+BO7-BM7 -> 0 | BO7: =+SUMIFS('[2]3条収入'!$AI$6:$AI$70,'[2]3条収入'!$C$6:$C$70,雨汚収入!N7) -> 539000
N8: 481142000 | O8: 下水道事業収益 | P8: 営業外収益 | Q8: 雑収益 | Y8: =+SUMIFS(Y$69:Y$891,$N$69:$N$891,$N8) -> 0 | AV8: =+SUMIFS(AV$69:AV$894,$N$69:$N$894,$N8) -> 0 | AW8: =+SUMIFS(AW$69:AW$894,$N$69:$N$894,$N8) -> 0 | AX8: =+SUMIFS(AX$69:AX$894,$N$69:$N$894,$N8) -> 0 | AY8: =+SUMIFS(AY$69:AY$894,$N$69:$N$894,$N8) -> 0 | AZ8: =+SUMIFS(AZ$69:AZ$894,$N$69:$N$894,$N8) -> 0 | BA8: =+SUMIFS(BA$69:BA$894,$N$69:$N$894,$N8) -> 0 | BB8: =+SUMIFS(BB$69:BB$894,$N$69:$N$894,$N8) -> 0 | BC8: =+SUMIFS(BC$69:BC$894,$N$69:$N$894,$N8) -> 0 | BD8: =+SUMIFS(BD$69:BD$784,$N$69:$N$784,$N8) -> 0 | BF8: =+SUMIFS(BF$69:BF$891,$N$69:$N$891,$N8) -> 0 | BG8: =+SUMIFS(BG$69:BG$891,$N$69:$N$891,$N8) -> 0 | BH8: =+SUMIFS(BH$69:BH$891,$N$69:$N$891,$N8) -> 0 | BI8: =+SUMIFS(BI$69:BI$891,$N$69:$N$891,$N8) -> 0 | BJ8: =+SUMIFS(BJ$69:BJ$891,$N$69:$N$891,$N8) -> 0 | BK8: =+SUMIFS(BK$69:BK$891,$N$69:$N$891,$N8) -> 0 | BL8: =+SUMIFS(BL$69:BL$891,$N$69:$N$891,$N8) -> 0 | BM8: =+SUMIFS(BM$69:BM$894,$N$69:$N$894,$N8) -> 0 | BN8: =+BO8-BM8 -> 0 | BO8: =+SUMIFS('[2]3条収入'!$AI$6:$AI$70,'[2]3条収入'!$C$6:$C$70,雨汚収入!N8) -> 0
N9: 482022100 | O9: 下水道事業収益 | P9: 営業外収益 | Q9: 受取利息 | R9: 預金利息 | Y9: =+SUMIFS(Y$69:Y$891,$N$69:$N$891,$N9) -> 88770 | AV9: =+SUMIFS(AV$69:AV$894,$N$69:$N$894,$N9) -> 44385 | AW9: =+SUMIFS(AW$69:AW$894,$N$69:$N$894,$N9) -> 0 | AX9: =+SUMIFS(AX$69:AX$894,$N$69:$N$894,$N9) -> 0 | AY9: =+SUMIFS(AY$69:AY$894,$N$69:$N$894,$N9) -> 44385 | AZ9: =+SUMIFS(AZ$69:AZ$894,$N$69:$N$894,$N9) -> 0 | BA9: =+SUMIFS(BA$69:BA$894,$N$69:$N$894,$N9) -> 44385 | BB9: =+SUMIFS(BB$69:BB$894,$N$69:$N$894,$N9) -> 44385 | BC9: =+SUMIFS(BC$69:BC$894,$N$69:$N$894,$N9) -> 88770 | BD9: =+SUMIFS(BD$69:BD$784,$N$69:$N$784,$N9) -> 0 | BF9: =+SUMIFS(BF$69:BF$891,$N$69:$N$891,$N9) -> 44385 | BG9: =+SUMIFS(BG$69:BG$891,$N$69:$N$891,$N9) -> 0 | BH9: =+SUMIFS(BH$69:BH$891,$N$69:$N$891,$N9) -> 0 | BI9: =+SUMIFS(BI$69:BI$891,$N$69:$N$891,$N9) -> 44385 | BJ9: =+SUMIFS(BJ$69:BJ$891,$N$69:$N$891,$N9) -> 0 | BK9: =+SUMIFS(BK$69:BK$891,$N$69:$N$891,$N9) -> 44385 | BL9: =+SUMIFS(BL$69:BL$891,$N$69:$N$891,$N9) -> 44385 | BM9: =+SUMIFS(BM$69:BM$894,$N$69:$N$894,$N9) -> 88770 | BN9: =+BO9-BM9 -> 0 | BO9: =+SUMIFS('[2]3条収入'!$AI$6:$AI$70,'[2]3条収入'!$C$6:$C$70,雨汚収入!N9) -> 88770
N10: 482042900 | O10: 下水道事業収益 | P10: 営業外収益 | Q10: 国庫補助金 | R10: その他国庫補助金(災害) | Y10: =+SUMIFS(Y$69:Y$891,$N$69:$N$891,$N10) -> 0 | AV10: =+SUMIFS(AV$69:AV$894,$N$69:$N$894,$N10) -> 0 | AW10: =+SUMIFS(AW$69:AW$894,$N$69:$N$894,$N10) -> 0 | AX10: =+SUMIFS(AX$69:AX$894,$N$69:$N$894,$N10) -> 0 | AY10: =+SUMIFS(AY$69:AY$894,$N$69:$N$894,$N10) -> 0 | AZ10: =+SUMIFS(AZ$69:AZ$894,$N$69:$N$894,$N10) -> 0 | BA10: =+SUMIFS(BA$69:BA$894,$N$69:$N$894,$N10) -> 0 | BB10: =+SUMIFS(BB$69:BB$894,$N$69:$N$894,$N10) -> 0 | BC10: =+SUMIFS(BC$69:BC$894,$N$69:$N$894,$N10) -> 0 | BD10: =+SUMIFS(BD$69:BD$784,$N$69:$N$784,$N10) -> 0 | BF10: =+SUMIFS(BF$69:BF$891,$N$69:$N$891,$N10) -> 0 | BG10: =+SUMIFS(BG$69:BG$891,$N$69:$N$891,$N10) -> 0 | BH10: =+SUMIFS(BH$69:BH$891,$N$69:$N$891,$N10) -> 0 | BI10: =+SUMIFS(BI$69:BI$891,$N$69:$N$891,$N10) -> 0 | BJ10: =+SUMIFS(BJ$69:BJ$891,$N$69:$N$891,$N10) -> 0 | BK10: =+SUMIFS(BK$69:BK$891,$N$69:$N$891,$N10) -> 0 | BL10: =+SUMIFS(BL$69:BL$891,$N$69:$N$891,$N10) -> 0 | BM10: =+SUMIFS(BM$69:BM$894,$N$69:$N$894,$N10) -> 0 | BN10: =+BO10-BM10 -> 0 | BO10: =+SUMIFS('[2]3条収入'!$AI$6:$AI$70,'[2]3条収入'!$C$6:$C$70,雨汚収入!N10) -> 0
N11: 482093200 | O11: 下水道事業収益 | P11: 営業外収益 | Q11: 負担金 | R11: 施設管理負担金 | Y11: =+SUMIFS(Y$69:Y$891,$N$69:$N$891,$N11) -> 37016600 | AV11: =+SUMIFS(AV$69:AV$894,$N$69:$N$894,$N11) -> 36785219 | AW11: =+SUMIFS(AW$69:AW$894,$N$69:$N$894,$N11) -> 0 | AX11: =+SUMIFS(AX$69:AX$894,$N$69:$N$894,$N11) -> 0 | AY11: =+SUMIFS(AY$69:AY$894,$N$69:$N$894,$N11) -> 36785219 | AZ11: =+SUMIFS(AZ$69:AZ$894,$N$69:$N$894,$N11) -> 0 | BA11: =+SUMIFS(BA$69:BA$894,$N$69:$N$894,$N11) -> 231381 | BB11: =+SUMIFS(BB$69:BB$894,$N$69:$N$894,$N11) -> 231381 | BC11: =+SUMIFS(BC$69:BC$894,$N$69:$N$894,$N11) -> 37016600 | BD11: =+SUMIFS(BD$69:BD$784,$N$69:$N$784,$N11) -> 0 | BF11: =+SUMIFS(BF$69:BF$891,$N$69:$N$891,$N11) -> 33441108 | BG11: =+SUMIFS(BG$69:BG$891,$N$69:$N$891,$N11) -> 0 | BH11: =+SUMIFS(BH$69:BH$891,$N$69:$N$891,$N11) -> 0 | BI11: =+SUMIFS(BI$69:BI$891,$N$69:$N$891,$N11) -> 33441108 | BJ11: =+SUMIFS(BJ$69:BJ$891,$N$69:$N$891,$N11) -> 0 | BK11: =+SUMIFS(BK$69:BK$891,$N$69:$N$891,$N11) -> 210347 | BL11: =+SUMIFS(BL$69:BL$891,$N$69:$N$891,$N11) -> 210347 | BM11: =+SUMIFS(BM$69:BM$894,$N$69:$N$894,$N11) -> 33651455 | BN11: =+BO11-BM11 -> 0 | BO11: =+SUMIFS('[2]3条収入'!$AI$6:$AI$70,'[2]3条収入'!$C$6:$C$70,雨汚収入!N11) -> 33651455
N12: 482093300 | O12: 下水道事業収益 | P12: 営業外収益 | Q12: 負担金 | R12: 他会計負担金 | Y12: =+SUMIFS(Y$69:Y$891,$N$69:$N$891,$N12) -> 0 | AV12: =+SUMIFS(AV$69:AV$894,$N$69:$N$894,$N12) -> 0 | AW12: =+SUMIFS(AW$69:AW$894,$N$69:$N$894,$N12) -> 0 | AX12: =+SUMIFS(AX$69:AX$894,$N$69:$N$894,$N12) -> 0 | AY12: =+SUMIFS(AY$69:AY$894,$N$69:$N$894,$N12) -> 0 | AZ12: =+SUMIFS(AZ$69:AZ$894,$N$69:$N$894,$N12) -> 0 | BA12: =+SUMIFS(BA$69:BA$894,$N$69:$N$894,$N12) -> 0 | BB12: =+SUMIFS(BB$69:BB$894,$N$69:$N$894,$N12) -> 0 | BC12: =+SUMIFS(BC$69:BC$894,$N$69:$N$894,$N12) -> 0 | BD12: =+SUMIFS(BD$69:BD$784,$N$69:$N$784,$N12) -> 0 | BF12: =+SUMIFS(BF$69:BF$891,$N$69:$N$891,$N12) -> 0 | BG12: =+SUMIFS(BG$69:BG$891,$N$69:$N$891,$N12) -> 0 | BH12: =+SUMIFS(BH$69:BH$891,$N$69:$N$891,$N12) -> 0 | BI12: =+SUMIFS(BI$69:BI$891,$N$69:$N$891,$N12) -> 0 | BJ12: =+SUMIFS(BJ$69:BJ$891,$N$69:$N$891,$N12) -> 0 | BK12: =+SUMIFS(BK$69:BK$891,$N$69:$N$891,$N12) -> 0 | BL12: =+SUMIFS(BL$69:BL$891,$N$69:$N$891,$N12) -> 0 | BM12: =+SUMIFS(BM$69:BM$894,$N$69:$N$894,$N12) -> 0 | BN12: =+BO12-BM12 -> 16476593 | BO12: =+SUMIFS('[2]3条収入'!$AI$6:$AI$70,'[2]3条収入'!$C$6:$C$70,雨汚収入!N12) -> 16476593
N13: 482113700 | O13: 下水道事業収益 | P13: 営業外収益 | Q13: 消費税及び地方消費税還付金 | R13: 消費税及び地方消費税還付金 | Y13: =+SUMIFS(Y$69:Y$891,$N$69:$N$891,$N13) -> 0 | AV13: =+SUMIFS(AV$69:AV$894,$N$69:$N$894,$N13) -> 0 | AW13: =+SUMIFS(AW$69:AW$894,$N$69:$N$894,$N13) -> 0 | AX13: =+SUMIFS(AX$69:AX$894,$N$69:$N$894,$N13) -> 0 | AY13: =+SUMIFS(AY$69:AY$894,$N$69:$N$894,$N13) -> 0 | AZ13: =+SUMIFS(AZ$69:AZ$894,$N$69:$N$894,$N13) -> 0 | BA13: =+SUMIFS(BA$69:BA$894,$N$69:$N$894,$N13) -> 0 | BB13: =+SUMIFS(BB$69:BB$894,$N$69:$N$894,$N13) -> 0 | BC13: =+SUMIFS(BC$69:BC$894,$N$69:$N$894,$N13) -> 0 | BD13: =+SUMIFS(BD$69:BD$784,$N$69:$N$784,$N13) -> 0 | BF13: =+SUMIFS(BF$69:BF$891,$N$69:$N$891,$N13) -> 0 | BG13: =+SUMIFS(BG$69:BG$891,$N$69:$N$891,$N13) -> 0 | BH13: =+SUMIFS(BH$69:BH$891,$N$69:$N$891,$N13) -> 0 | BI13: =+SUMIFS(BI$69:BI$891,$N$69:$N$891,$N13) -> 0 | BJ13: =+SUMIFS(BJ$69:BJ$891,$N$69:$N$891,$N13) -> 0 | BK13: =+SUMIFS(BK$69:BK$891,$N$69:$N$891,$N13) -> 0 | BL13: =+SUMIFS(BL$69:BL$891,$N$69:$N$891,$N13) -> 0 | BM13: =+SUMIFS(BM$69:BM$894,$N$69:$N$894,$N13) -> 0 | BN13: =+BO13-BM13 -> 0 | BO13: =+SUMIFS('[2]3条収入'!$AI$6:$AI$70,'[2]3条収入'!$C$6:$C$70,雨汚収入!N13) -> 0
N14: 482123600 | O14: 下水道事業収益 | P14: 営業外収益 | Q14: 雑収益 | R14: 不用品売却収益 | Y14: =+SUMIFS(Y$69:Y$891,$N$69:$N$891,$N14) -> 408100 | AV14: =+SUMIFS(AV$69:AV$894,$N$69:$N$894,$N14) -> 0 | AW14: =+SUMIFS(AW$69:AW$894,$N$69:$N$894,$N14) -> 0 | AX14: =+SUMIFS(AX$69:AX$894,$N$69:$N$894,$N14) -> 408100 | AY14: =+SUMIFS(AY$69:AY$894,$N$69:$N$894,$N14) -> 408100 | AZ14: =+SUMIFS(AZ$69:AZ$894,$N$69:$N$894,$N14) -> 0 | BA14: =+SUMIFS(BA$69:BA$894,$N$69:$N$894,$N14) -> 0 | BB14: =+SUMIFS(BB$69:BB$894,$N$69:$N$894,$N14) -> 0 | BC14: =+SUMIFS(BC$69:BC$894,$N$69:$N$894,$N14) -> 408100 | BD14: =+SUMIFS(BD$69:BD$784,$N$69:$N$784,$N14) -> 0 | BF14: =+SUMIFS(BF$69:BF$891,$N$69:$N$891,$N14) -> 0 | BG14: =+SUMIFS(BG$69:BG$891,$N$69:$N$891,$N14) -> 0 | BH14: =+SUMIFS(BH$69:BH$891,$N$69:$N$891,$N14) -> 371000 | BI14: =+SUMIFS(BI$69:BI$891,$N$69:$N$891,$N14) -> 371000 | BJ14: =+SUMIFS(BJ$69:BJ$891,$N$69:$N$891,$N14) -> 0 | BK14: =+SUMIFS(BK$69:BK$891,$N$69:$N$891,$N14) -> 0 | BL14: =+SUMIFS(BL$69:BL$891,$N$69:$N$891,$N14) -> 0 | BM14: =+SUMIFS(BM$69:BM$894,$N$69:$N$894,$N14) -> 371000 | BN14: =+BO14-BM14 -> 0 | BO14: =+SUMIFS('[2]3条収入'!$AI$6:$AI$70,'[2]3条収入'!$C$6:$C$70,雨汚収入!N14) -> 371000
N15: 482124000 | O15: 下水道事業収益 | P15: 営業外収益 | Q15: 雑収益 | R15: その他雑収益 | Y15: =+SUMIFS(Y$69:Y$891,$N$69:$N$891,$N15) -> 36052234 | AV15: =+SUMIFS(AV$69:AV$894,$N$69:$N$894,$N15) -> 10360569 | AW15: =+SUMIFS(AW$69:AW$894,$N$69:$N$894,$N15) -> 0 | AX15: =+SUMIFS(AX$69:AX$894,$N$69:$N$894,$N15) -> 1399670 | AY15: =+SUMIFS(AY$69:AY$894,$N$69:$N$894,$N15) -> 11760239 | AZ15: =+SUMIFS(AZ$69:AZ$894,$N$69:$N$894,$N15) -> 0 | BA15: =+SUMIFS(BA$69:BA$894,$N$69:$N$894,$N15) -> 24291995 | BB15: =+SUMIFS(BB$69:BB$894,$N$69:$N$894,$N15) -> 24291995 | BC15: =+SUMIFS(BC$69:BC$894,$N$69:$N$894,$N15) -> 36052234 | BD15: =+SUMIFS(BD$69:BD$784,$N$69:$N$784,$N15) -> 0 | BF15: =+SUMIFS(BF$69:BF$891,$N$69:$N$891,$N15) -> 10155799 | BG15: =+SUMIFS(BG$69:BG$891,$N$69:$N$891,$N15) -> 0 | BH15: =+SUMIFS(BH$69:BH$891,$N$69:$N$891,$N15) -> 1397864 | BI15: =+SUMIFS(BI$69:BI$891,$N$69:$N$891,$N15) -> 11553663 | BJ15: =+SUMIFS(BJ$69:BJ$891,$N$69:$N$891,$N15) -> 0 | BK15: =+SUMIFS(BK$69:BK$891,$N$69:$N$891,$N15) -> 23325314 | BL15: =+SUMIFS(BL$69:BL$891,$N$69:$N$891,$N15) -> 23325314 | BM15: =+SUMIFS(BM$69:BM$894,$N$69:$N$894,$N15) -> 34878977 | BN15: =+BO15-BM15 -> 0 | BO15: =+SUMIFS('[2]3条収入'!$AI$6:$AI$70,'[2]3条収入'!$C$6:$C$70,雨汚収入!N15) -> 34878977
N16: 483020200 | O16: 下水道事業収益 | P16: 特別利益 | Q16: 固定資産売却益 | R16: 固定資産売却益 | Y16: =+SUMIFS(Y$69:Y$891,$N$69:$N$891,$N16) -> 0 | AV16: =+SUMIFS(AV$69:AV$894,$N$69:$N$894,$N16) -> 0 | AW16: =+SUMIFS(AW$69:AW$894,$N$69:$N$894,$N16) -> 0 | AX16: =+SUMIFS(AX$69:AX$894,$N$69:$N$894,$N16) -> 0 | AY16: =+SUMIFS(AY$69:AY$894,$N$69:$N$894,$N16) -> 0 | AZ16: =+SUMIFS(AZ$69:AZ$894,$N$69:$N$894,$N16) -> 0 | BA16: =+SUMIFS(BA$69:BA$894,$N$69:$N$894,$N16) -> 0 | BB16: =+SUMIFS(BB$69:BB$894,$N$69:$N$894,$N16) -> 0 | BC16: =+SUMIFS(BC$69:BC$894,$N$69:$N$894,$N16) -> 0 | BD16: =+SUMIFS(BD$69:BD$784,$N$69:$N$784,$N16) -> 0 | BF16: =+SUMIFS(BF$69:BF$891,$N$69:$N$891,$N16) -> 0 | BG16: =+SUMIFS(BG$69:BG$891,$N$69:$N$891,$N16) -> 0 | BH16: =+SUMIFS(BH$69:BH$891,$N$69:$N$891,$N16) -> 0 | BI16: =+SUMIFS(BI$69:BI$891,$N$69:$N$891,$N16) -> 0 | BJ16: =+SUMIFS(BJ$69:BJ$891,$N$69:$N$891,$N16) -> 0 | BK16: =+SUMIFS(BK$69:BK$891,$N$69:$N$891,$N16) -> 0 | BL16: =+SUMIFS(BL$69:BL$891,$N$69:$N$891,$N16) -> 0 | BM16: =+SUMIFS(BM$69:BM$894,$N$69:$N$894,$N16) -> 0 | BN16: =+BO16-BM16 -> 0 | BO16: =+SUMIFS('[2]3条収入'!$AI$6:$AI$70,'[2]3条収入'!$C$6:$C$70,雨汚収入!N16) -> 0
N17: 483040400 | O17: 下水道事業収益 | P17: 特別利益 | Q17: 過年度損益修正益 | R17: 過年度損益修正益 | Y17: =+SUMIFS(Y$69:Y$891,$N$69:$N$891,$N17) -> 2769570 | AV17: =+SUMIFS(AV$69:AV$894,$N$69:$N$894,$N17) -> 352162 | AW17: =+SUMIFS(AW$69:AW$894,$N$69:$N$894,$N17) -> 0 | AX17: =+SUMIFS(AX$69:AX$894,$N$69:$N$894,$N17) -> 487974 | AY17: =+SUMIFS(AY$69:AY$894,$N$69:$N$894,$N17) -> 840136 | AZ17: =+SUMIFS(AZ$69:AZ$894,$N$69:$N$894,$N17) -> 29260 | BA17: =+SUMIFS(BA$69:BA$894,$N$69:$N$894,$N17) -> 1900174 | BB17: =+SUMIFS(BB$69:BB$894,$N$69:$N$894,$N17) -> 1929434 | BC17: =+SUMIFS(BC$69:BC$894,$N$69:$N$894,$N17) -> 2769570 | BD17: =+SUMIFS(BD$69:BD$784,$N$69:$N$784,$N17) -> 0 | BF17: =+SUMIFS(BF$69:BF$891,$N$69:$N$891,$N17) -> 352162 | BG17: =+SUMIFS(BG$69:BG$891,$N$69:$N$891,$N17) -> 0 | BH17: =+SUMIFS(BH$69:BH$891,$N$69:$N$891,$N17) -> 487974 | BI17: =+SUMIFS(BI$69:BI$891,$N$69:$N$891,$N17) -> 840136 | BJ17: =+SUMIFS(BJ$69:BJ$891,$N$69:$N$891,$N17) -> 29260 | BK17: =+SUMIFS(BK$69:BK$891,$N$69:$N$891,$N17) -> 1754286 | BL17: =+SUMIFS(BL$69:BL$891,$N$69:$N$891,$N17) -> 1783546 | BM17: =+SUMIFS(BM$69:BM$894,$N$69:$N$894,$N17) -> 2623682 | BN17: =+BO17-BM17 -> 0 | BO17: =+SUMIFS('[2]3条収入'!$AI$6:$AI$70,'[2]3条収入'!$C$6:$C$70,雨汚収入!N17) -> 2623682
N18: 483060600 | O18: 下水道事業収益 | P18: 特別利益 | Q18: その他特別利益 | R18: その他特別利益 | Y18: =+SUMIFS(Y$69:Y$891,$N$69:$N$891,$N18) -> 864807 | AV18: =+SUMIFS(AV$69:AV$894,$N$69:$N$894,$N18) -> 588069 | AW18: =+SUMIFS(AW$69:AW$894,$N$69:$N$894,$N18) -> 0 | AX18: =+SUMIFS(AX$69:AX$894,$N$69:$N$894,$N18) -> 0 | AY18: =+SUMIFS(AY$69:AY$894,$N$69:$N$894,$N18) -> 588069 | AZ18: =+SUMIFS(AZ$69:AZ$894,$N$69:$N$894,$N18) -> 0 | BA18: =+SUMIFS(BA$69:BA$894,$N$69:$N$894,$N18) -> 276738 | BB18: =+SUMIFS(BB$69:BB$894,$N$69:$N$894,$N18) -> 276738 | BC18: =+SUMIFS(BC$69:BC$894,$N$69:$N$894,$N18) -> 864807 | BD18: =+SUMIFS(BD$69:BD$784,$N$69:$N$784,$N18) -> 0 | BF18: =+SUMIFS(BF$69:BF$891,$N$69:$N$891,$N18) -> 588069 | BG18: =+SUMIFS(BG$69:BG$891,$N$69:$N$891,$N18) -> 0 | BH18: =+SUMIFS(BH$69:BH$891,$N$69:$N$891,$N18) -> 0 | BI18: =+SUMIFS(BI$69:BI$891,$N$69:$N$891,$N18) -> 588069 | BJ18: =+SUMIFS(BJ$69:BJ$891,$N$69:$N$891,$N18) -> 0 | BK18: =+SUMIFS(BK$69:BK$891,$N$69:$N$891,$N18) -> 276738 | BL18: =+SUMIFS(BL$69:BL$891,$N$69:$N$891,$N18) -> 276738 | BM18: =+SUMIFS(BM$69:BM$894,$N$69:$N$894,$N18) -> 864807 | BN18: =+BO18-BM18 -> 0 | BO18: =+SUMIFS('[2]3条収入'!$AI$6:$AI$70,'[2]3条収入'!$C$6:$C$70,雨汚収入!N18) -> 864807
N19: 483060700 | O19: 下水道事業収益 | P19: 特別利益 | Q19: その他特別利益 | R19: 貸倒引当金戻入益 | Y19: =+SUMIFS(Y$69:Y$891,$N$69:$N$891,$N19) -> 455622 | AV19: =+SUMIFS(AV$69:AV$894,$N$69:$N$894,$N19) -> 0 | AW19: =+SUMIFS(AW$69:AW$894,$N$69:$N$894,$N19) -> 0 | AX19: =+SUMIFS(AX$69:AX$894,$N$69:$N$894,$N19) -> 16334 | AY19: =+SUMIFS(AY$69:AY$894,$N$69:$N$894,$N19) -> 16334 | AZ19: =+SUMIFS(AZ$69:AZ$894,$N$69:$N$894,$N19) -> 0 | BA19: =+SUMIFS(BA$69:BA$894,$N$69:$N$894,$N19) -> 439288 | BB19: =+SUMIFS(BB$69:BB$894,$N$69:$N$894,$N19) -> 439288 | BC19: =+SUMIFS(BC$69:BC$894,$N$69:$N$894,$N19) -> 455622 | BD19: =+SUMIFS(BD$69:BD$784,$N$69:$N$784,$N19) -> 0 | BF19: =+SUMIFS(BF$69:BF$891,$N$69:$N$891,$N19) -> 0 | BG19: =+SUMIFS(BG$69:BG$891,$N$69:$N$891,$N19) -> 0 | BH19: =+SUMIFS(BH$69:BH$891,$N$69:$N$891,$N19) -> 16334 | BI19: =+SUMIFS(BI$69:BI$891,$N$69:$N$891,$N19) -> 16334 | BJ19: =+SUMIFS(BJ$69:BJ$891,$N$69:$N$891,$N19) -> 0 | BK19: =+SUMIFS(BK$69:BK$891,$N$69:$N$891,$N19) -> 439288 | BL19: =+SUMIFS(BL$69:BL$891,$N$69:$N$891,$N19) -> 439288 | BM19: =+SUMIFS(BM$69:BM$894,$N$69:$N$894,$N19) -> 455622 | BN19: =+BO19-BM19 -> 0 | BO19: =+SUMIFS('[2]3条収入'!$AI$6:$AI$70,'[2]3条収入'!$C$6:$C$70,雨汚収入!N19) -> 455622
N20: 483060800 | O20: 下水道事業収益 | P20: 特別利益 | Q20: その他特別利益 | R20: 賞与引当金戻入益 | Y20: =+SUMIFS(Y$69:Y$891,$N$69:$N$891,$N20) -> 109000 | AV20: =+SUMIFS(AV$69:AV$894,$N$69:$N$894,$N20) -> 54500 | AW20: =+SUMIFS(AW$69:AW$894,$N$69:$N$894,$N20) -> 0 | AX20: =+SUMIFS(AX$69:AX$894,$N$69:$N$894,$N20) -> 0 | AY20: =+SUMIFS(AY$69:AY$894,$N$69:$N$894,$N20) -> 54500 | AZ20: =+SUMIFS(AZ$69:AZ$894,$N$69:$N$894,$N20) -> 0 | BA20: =+SUMIFS(BA$69:BA$894,$N$69:$N$894,$N20) -> 54500 | BB20: =+SUMIFS(BB$69:BB$894,$N$69:$N$894,$N20) -> 54500 | BC20: =+SUMIFS(BC$69:BC$894,$N$69:$N$894,$N20) -> 109000 | BD20: =+SUMIFS(BD$69:BD$784,$N$69:$N$784,$N20) -> 0 | BF20: =+SUMIFS(BF$69:BF$891,$N$69:$N$891,$N20) -> 54500 | BG20: =+SUMIFS(BG$69:BG$891,$N$69:$N$891,$N20) -> 0 | BH20: =+SUMIFS(BH$69:BH$891,$N$69:$N$891,$N20) -> 0 | BI20: =+SUMIFS(BI$69:BI$891,$N$69:$N$891,$N20) -> 54500 | BJ20: =+SUMIFS(BJ$69:BJ$891,$N$69:$N$891,$N20) -> 0 | BK20: =+SUMIFS(BK$69:BK$891,$N$69:$N$891,$N20) -> 54500 | BL20: =+SUMIFS(BL$69:BL$891,$N$69:$N$891,$N20) -> 54500 | BM20: =+SUMIFS(BM$69:BM$894,$N$69:$N$894,$N20) -> 109000 | BN20: =+BO20-BM20 -> 0 | BO20: =+SUMIFS('[2]3条収入'!$AI$6:$AI$70,'[2]3条収入'!$C$6:$C$70,雨汚収入!N20) -> 109000
R23: 集計表（うち、不課税分）↓ | AV23: 雨水（税込） | AZ23: 汚水（税込） | BC23: 合計 （税込） | BD23: チェック | BF23: 雨水（税抜） | BJ23: 汚水（税抜） | BM23: 合計 （税抜） | BN23: 税抜き 要調整額 | BO23: 3条収入ｼｰﾄ集計値
AV24: 区域内 | AW24: 区域外 | AX24: 一般行政 | AY24: 計 | AZ24: 基準内 | BA24: 基準外 | BB24: 計 | BF24: 区域内 | BG24: 区域外 | BH24: 一般行政 | BI24: 計 | BJ24: 基準内 | BK24: 基準外 | BL24: 計
N25: 481121400 | O25: 下水道事業収益 | P25: 営業収益 | Q25: 受託工事収益 | R25: 受託工事収益 | Y25: =+SUMIFS(Y$69:Y$891,$N$69:$N$891,$N25,$AS$69:$AS$891,31) -> 0 | AV25: =+SUMIFS(AV$69:AV$894,$N$69:$N$894,$N25,$AS$69:$AS$894,31) -> 0 | AW25: =+SUMIFS(AW$69:AW$894,$N$69:$N$894,$N25,$AS$69:$AS$894,31) -> 0 | AX25: =+SUMIFS(AX$69:AX$894,$N$69:$N$894,$N25,$AS$69:$AS$894,31) -> 0 | AY25: =+SUMIFS(AY$69:AY$894,$N$69:$N$894,$N25,$AS$69:$AS$894,31) -> 0 | AZ25: =+SUMIFS(AZ$69:AZ$894,$N$69:$N$894,$N25,$AS$69:$AS$894,31) -> 0 | BA25: =+SUMIFS(BA$69:BA$894,$N$69:$N$894,$N25,$AS$69:$AS$894,31) -> 0 | BB25: =+SUMIFS(BB$69:BB$894,$N$69:$N$894,$N25,$AS$69:$AS$894,31) -> 0 | BC25: =+SUMIFS(BC$69:BC$894,$N$69:$N$894,$N25,$AS$69:$AS$894,31) -> 0 | BD25: =+SUMIFS(BD$69:BD$784,$N$69:$N$784,$N25,$AS$69:$AS$784,31) -> 0 | BE25: =+SUMIFS(BE$69:BE$784,$N$69:$N$784,$N25,$AS$69:$AS$784,31) -> 0 | BF25: =+SUMIFS(BF$69:BF$891,$N$69:$N$891,$N25,$AS$69:$AS$891,31) -> 0 | BG25: =+SUMIFS(BG$69:BG$891,$N$69:$N$891,$N25,$AS$69:$AS$891,31) -> 0 | BH25: =+SUMIFS(BH$69:BH$891,$N$69:$N$891,$N25,$AS$69:$AS$891,31) -> 0 | BI25: =+SUMIFS(BI$69:BI$891,$N$69:$N$891,$N25,$AS$69:$AS$891,31) -> 0 | BJ25: =+SUMIFS(BJ$69:BJ$891,$N$69:$N$891,$N25,$AS$69:$AS$891,31) -> 0 | BK25: =+SUMIFS(BK$69:BK$891,$N$69:$N$891,$N25,$AS$69:$AS$891,31) -> 0 | BL25: =+SUMIFS(BL$69:BL$891,$N$69:$N$891,$N25,$AS$69:$AS$891,31) -> 0 | BM25: =+SUMIFS(BM$69:BM$894,$N$69:$N$894,$N25,$AS$69:$AS$894,31) -> 0 | BN25: =+SUMIFS(BN$69:BN$784,$N$69:$N$784,$N25,$AS$69:$AS$784,31) -> 0
N26: 481141500 | O26: 下水道事業収益 | P26: 営業収益 | Q26: その他営業収益 | R26: 産物売却代金 | Y26: =+SUMIFS(Y$69:Y$891,$N$69:$N$891,$N26,$AS$69:$AS$891,31) -> 0 | AV26: =+SUMIFS(AV$69:AV$894,$N$69:$N$894,$N26,$AS$69:$AS$894,31) -> 0 | AW26: =+SUMIFS(AW$69:AW$894,$N$69:$N$894,$N26,$AS$69:$AS$894,31) -> 0 | AX26: =+SUMIFS(AX$69:AX$894,$N$69:$N$894,$N26,$AS$69:$AS$894,31) -> 0 | AY26: =+SUMIFS(AY$69:AY$894,$N$69:$N$894,$N26,$AS$69:$AS$894,31) -> 0 | AZ26: =+SUMIFS(AZ$69:AZ$894,$N$69:$N$894,$N26,$AS$69:$AS$894,31) -> 0 | BA26: =+SUMIFS(BA$69:BA$894,$N$69:$N$894,$N26,$AS$69:$AS$894,31) -> 0 | BB26: =+SUMIFS(BB$69:BB$894,$N$69:$N$894,$N26,$AS$69:$AS$894,31) -> 0 | BC26: =+SUMIFS(BC$69:BC$894,$N$69:$N$894,$N26,$AS$69:$AS$894,31) -> 0 | BD26: =+SUMIFS(BD$69:BD$784,$N$69:$N$784,$N26,$AS$69:$AS$784,31) -> 0 | BE26: =+SUMIFS(BE$69:BE$784,$N$69:$N$784,$N26,$AS$69:$AS$784,31) -> 0 | BF26: =+SUMIFS(BF$69:BF$891,$N$69:$N$891,$N26,$AS$69:$AS$891,31) -> 0 | BG26: =+SUMIFS(BG$69:BG$891,$N$69:$N$891,$N26,$AS$69:$AS$891,31) -> 0 | BH26: =+SUMIFS(BH$69:BH$891,$N$69:$N$891,$N26,$AS$69:$AS$891,31) -> 0 | BI26: =+SUMIFS(BI$69:BI$891,$N$69:$N$891,$N26,$AS$69:$AS$891,31) -> 0 | BJ26: =+SUMIFS(BJ$69:BJ$891,$N$69:$N$891,$N26,$AS$69:$AS$891,31) -> 0 | BK26: =+SUMIFS(BK$69:BK$891,$N$69:$N$891,$N26,$AS$69:$AS$891,31) -> 0 | BL26: =+SUMIFS(BL$69:BL$891,$N$69:$N$891,$N26,$AS$69:$AS$891,31) -> 0 | BM26: =+SUMIFS(BM$69:BM$894,$N$69:$N$894,$N26,$AS$69:$AS$894,31) -> 0 | BN26: =+SUMIFS(BN$69:BN$784,$N$69:$N$784,$N26,$AS$69:$AS$784,31) -> 0
N27: 481141700 | O27: 下水道事業収益 | P27: 営業収益 | Q27: その他営業収益 | R27: 業務受託収益 | Y27: =+SUMIFS(Y$69:Y$891,$N$69:$N$891,$N27,$AS$69:$AS$891,31) -> 0 | AV27: =+SUMIFS(AV$69:AV$894,$N$69:$N$894,$N27,$AS$69:$AS$894,31) -> 0 | AW27: =+SUMIFS(AW$69:AW$894,$N$69:$N$894,$N27,$AS$69:$AS$894,31) -> 0 | AX27: =+SUMIFS(AX$69:AX$894,$N$69:$N$894,$N27,$AS$69:$AS$894,31) -> 0 | AY27: =+SUMIFS(AY$69:AY$894,$N$69:$N$894,$N27,$AS$69:$AS$894,31) -> 0 | AZ27: =+SUMIFS(AZ$69:AZ$894,$N$69:$N$894,$N27,$AS$69:$AS$894,31) -> 0 | BA27: =+SUMIFS(BA$69:BA$894,$N$69:$N$894,$N27,$AS$69:$AS$894,31) -> 0 | BB27: =+SUMIFS(BB$69:BB$894,$N$69:$N$894,$N27,$AS$69:$AS$894,31) -> 0 | BC27: =+SUMIFS(BC$69:BC$894,$N$69:$N$894,$N27,$AS$69:$AS$894,31) -> 0 | BD27: =+SUMIFS(BD$69:BD$784,$N$69:$N$784,$N27,$AS$69:$AS$784,31) -> 0 | BE27: =+SUMIFS(BE$69:BE$784,$N$69:$N$784,$N27,$AS$69:$AS$784,31) -> 0 | BF27: =+SUMIFS(BF$69:BF$891,$N$69:$N$891,$N27,$AS$69:$AS$891,31) -> 0 | BG27: =+SUMIFS(BG$69:BG$891,$N$69:$N$891,$N27,$AS$69:$AS$891,31) -> 0 | BH27: =+SUMIFS(BH$69:BH$891,$N$69:$N$891,$N27,$AS$69:$AS$891,31) -> 0 | BI27: =+SUMIFS(BI$69:BI$891,$N$69:$N$891,$N27,$AS$69:$AS$891,31) -> 0 | BJ27: =+SUMIFS(BJ$69:BJ$891,$N$69:$N$891,$N27,$AS$69:$AS$891,31) -> 0 | BK27: =+SUMIFS(BK$69:BK$891,$N$69:$N$891,$N27,$AS$69:$AS$891,31) -> 0 | BL27: =+SUMIFS(BL$69:BL$891,$N$69:$N$891,$N27,$AS$69:$AS$891,31) -> 0 | BM27: =+SUMIFS(BM$69:BM$894,$N$69:$N$894,$N27,$AS$69:$AS$894,31) -> 0 | BN27: =+SUMIFS(BN$69:BN$784,$N$69:$N$784,$N27,$AS$69:$AS$784,31) -> 0
N28: 481141915 | O28: 下水道事業収益 | P28: 営業収益 | Q28: その他営業収益 | R28: 手数料 | S28: 証明手数料 | Y28: =+SUMIFS(Y$69:Y$891,$N$69:$N$891,$N28,$AS$69:$AS$891,31) -> 0 | AV28: =+SUMIFS(AV$69:AV$894,$N$69:$N$894,$N28,$AS$69:$AS$894,31) -> 0 | AW28: =+SUMIFS(AW$69:AW$894,$N$69:$N$894,$N28,$AS$69:$AS$894,31) -> 0 | AX28: =+SUMIFS(AX$69:AX$894,$N$69:$N$894,$N28,$AS$69:$AS$894,31) -> 0 | AY28: =+SUMIFS(AY$69:AY$894,$N$69:$N$894,$N28,$AS$69:$AS$894,31) -> 0 | AZ28: =+SUMIFS(AZ$69:AZ$894,$N$69:$N$894,$N28,$AS$69:$AS$894,31) -> 0 | BA28: =+SUMIFS(BA$69:BA$894,$N$69:$N$894,$N28,$AS$69:$AS$894,31) -> 0 | BB28: =+SUMIFS(BB$69:BB$894,$N$69:$N$894,$N28,$AS$69:$AS$894,31) -> 0 | BC28: =+SUMIFS(BC$69:BC$894,$N$69:$N$894,$N28,$AS$69:$AS$894,31) -> 0 | BD28: =+SUMIFS(BD$69:BD$784,$N$69:$N$784,$N28,$AS$69:$AS$784,31) -> 0 | BE28: =+SUMIFS(BE$69:BE$784,$N$69:$N$784,$N28,$AS$69:$AS$784,31) -> 0 | BF28: =+SUMIFS(BF$69:BF$891,$N$69:$N$891,$N28,$AS$69:$AS$891,31) -> 0 | BG28: =+SUMIFS(BG$69:BG$891,$N$69:$N$891,$N28,$AS$69:$AS$891,31) -> 0 | BH28: =+SUMIFS(BH$69:BH$891,$N$69:$N$891,$N28,$AS$69:$AS$891,31) -> 0 | BI28: =+SUMIFS(BI$69:BI$891,$N$69:$N$891,$N28,$AS$69:$AS$891,31) -> 0 | BJ28: =+SUMIFS(BJ$69:BJ$891,$N$69:$N$891,$N28,$AS$69:$AS$891,31) -> 0 | BK28: =+SUMIFS(BK$69:BK$891,$N$69:$N$891,$N28,$AS$69:$AS$891,31) -> 0 | BL28: =+SUMIFS(BL$69:BL$891,$N$69:$N$891,$N28,$AS$69:$AS$891,31) -> 0 | BM28: =+SUMIFS(BM$69:BM$894,$N$69:$N$894,$N28,$AS$69:$AS$894,31) -> 0 | BN28: =+SUMIFS(BN$69:BN$784,$N$69:$N$784,$N28,$AS$69:$AS$784,31) -> 0
N29: 481141916 | O29: 下水道事業収益 | P29: 営業収益 | Q29: その他営業収益 | R29: 手数料 | S29: 指定業者登録等手数料 | Y29: =+SUMIFS(Y$69:Y$891,$N$69:$N$891,$N29,$AS$69:$AS$891,31) -> 0 | AV29: =+SUMIFS(AV$69:AV$894,$N$69:$N$894,$N29,$AS$69:$AS$894,31) -> 0 | AW29: =+SUMIFS(AW$69:AW$894,$N$69:$N$894,$N29,$AS$69:$AS$894,31) -> 0 | AX29: =+SUMIFS(AX$69:AX$894,$N$69:$N$894,$N29,$AS$69:$AS$894,31) -> 0 | AY29: =+SUMIFS(AY$69:AY$894,$N$69:$N$894,$N29,$AS$69:$AS$894,31) -> 0 | AZ29: =+SUMIFS(AZ$69:AZ$894,$N$69:$N$894,$N29,$AS$69:$AS$894,31) -> 0 | BA29: =+SUMIFS(BA$69:BA$894,$N$69:$N$894,$N29,$AS$69:$AS$894,31) -> 0 | BB29: =+SUMIFS(BB$69:BB$894,$N$69:$N$894,$N29,$AS$69:$AS$894,31) -> 0 | BC29: =+SUMIFS(BC$69:BC$894,$N$69:$N$894,$N29,$AS$69:$AS$894,31) -> 0 | BD29: =+SUMIFS(BD$69:BD$784,$N$69:$N$784,$N29,$AS$69:$AS$784,31) -> 0 | BE29: =+SUMIFS(BE$69:BE$784,$N$69:$N$784,$N29,$AS$69:$AS$784,31) -> 0 | BF29: =+SUMIFS(BF$69:BF$891,$N$69:$N$891,$N29,$AS$69:$AS$891,31) -> 0 | BG29: =+SUMIFS(BG$69:BG$891,$N$69:$N$891,$N29,$AS$69:$AS$891,31) -> 0 | BH29: =+SUMIFS(BH$69:BH$891,$N$69:$N$891,$N29,$AS$69:$AS$891,31) -> 0 | BI29: =+SUMIFS(BI$69:BI$891,$N$69:$N$891,$N29,$AS$69:$AS$891,31) -> 0 | BJ29: =+SUMIFS(BJ$69:BJ$891,$N$69:$N$891,$N29,$AS$69:$AS$891,31) -> 0 | BK29: =+SUMIFS(BK$69:BK$891,$N$69:$N$891,$N29,$AS$69:$AS$891,31) -> 0 | BL29: =+SUMIFS(BL$69:BL$891,$N$69:$N$891,$N29,$AS$69:$AS$891,31) -> 0 | BM29: =+SUMIFS(BM$69:BM$894,$N$69:$N$894,$N29,$AS$69:$AS$894,31) -> 0 | BN29: =+SUMIFS(BN$69:BN$784,$N$69:$N$784,$N29,$AS$69:$AS$784,31) -> 0
N30: 481142000 | O30: 下水道事業収益 | P30: 営業外収益 | Q30: 雑収益 | Y30: =+SUMIFS(Y$69:Y$891,$N$69:$N$891,$N30,$AS$69:$AS$891,31) -> 0 | AV30: =+SUMIFS(AV$69:AV$894,$N$69:$N$894,$N30,$AS$69:$AS$894,31) -> 0 | AW30: =+SUMIFS(AW$69:AW$894,$N$69:$N$894,$N30,$AS$69:$AS$894,31) -> 0 | AX30: =+SUMIFS(AX$69:AX$894,$N$69:$N$894,$N30,$AS$69:$AS$894,31) -> 0 | AY30: =+SUMIFS(AY$69:AY$894,$N$69:$N$894,$N30,$AS$69:$AS$894,31) -> 0 | AZ30: =+SUMIFS(AZ$69:AZ$894,$N$69:$N$894,$N30,$AS$69:$AS$894,31) -> 0 | BA30: =+SUMIFS(BA$69:BA$894,$N$69:$N$894,$N30,$AS$69:$AS$894,31) -> 0 | BB30: =+SUMIFS(BB$69:BB$894,$N$69:$N$894,$N30,$AS$69:$AS$894,31) -> 0 | BC30: =+SUMIFS(BC$69:BC$894,$N$69:$N$894,$N30,$AS$69:$AS$894,31) -> 0 | BD30: =+SUMIFS(BD$69:BD$784,$N$69:$N$784,$N30,$AS$69:$AS$784,31) -> 0 | BE30: =+SUMIFS(BE$69:BE$784,$N$69:$N$784,$N30,$AS$69:$AS$784,31) -> 0 | BF30: =+SUMIFS(BF$69:BF$891,$N$69:$N$891,$N30,$AS$69:$AS$891,31) -> 0 | BG30: =+SUMIFS(BG$69:BG$891,$N$69:$N$891,$N30,$AS$69:$AS$891,31) -> 0 | BH30: =+SUMIFS(BH$69:BH$891,$N$69:$N$891,$N30,$AS$69:$AS$891,31) -> 0 | BI30: =+SUMIFS(BI$69:BI$891,$N$69:$N$891,$N30,$AS$69:$AS$891,31) -> 0 | BJ30: =+SUMIFS(BJ$69:BJ$891,$N$69:$N$891,$N30,$AS$69:$AS$891,31) -> 0 | BK30: =+SUMIFS(BK$69:BK$891,$N$69:$N$891,$N30,$AS$69:$AS$891,31) -> 0 | BL30: =+SUMIFS(BL$69:BL$891,$N$69:$N$891,$N30,$AS$69:$AS$891,31) -> 0 | BM30: =+SUMIFS(BM$69:BM$894,$N$69:$N$894,$N30,$AS$69:$AS$894,31) -> 0 | BN30: =+SUMIFS(BN$69:BN$784,$N$69:$N$784,$N30,$AS$69:$AS$784,31) -> 0
N31: 482022100 | O31: 下水道事業収益 | P31: 営業外収益 | Q31: 受取利息 | R31: 預金利息 | Y31: =+SUMIFS(Y$69:Y$891,$N$69:$N$891,$N31,$AS$69:$AS$891,31) -> 0 | AV31: =+SUMIFS(AV$69:AV$894,$N$69:$N$894,$N31,$AS$69:$AS$894,31) -> 0 | AW31: =+SUMIFS(AW$69:AW$894,$N$69:$N$894,$N31,$AS$69:$AS$894,31) -> 0 | AX31: =+SUMIFS(AX$69:AX$894,$N$69:$N$894,$N31,$AS$69:$AS$894,31) -> 0 | AY31: =+SUMIFS(AY$69:AY$894,$N$69:$N$894,$N31,$AS$69:$AS$894,31) -> 0 | AZ31: =+SUMIFS(AZ$69:AZ$894,$N$69:$N$894,$N31,$AS$69:$AS$894,31) -> 0 | BA31: =+SUMIFS(BA$69:BA$894,$N$69:$N$894,$N31,$AS$69:$AS$894,31) -> 0 | BB31: =+SUMIFS(BB$69:BB$894,$N$69:$N$894,$N31,$AS$69:$AS$894,31) -> 0 | BC31: =+SUMIFS(BC$69:BC$894,$N$69:$N$894,$N31,$AS$69:$AS$894,31) -> 0 | BD31: =+SUMIFS(BD$69:BD$784,$N$69:$N$784,$N31,$AS$69:$AS$784,31) -> 0 | BE31: =+SUMIFS(BE$69:BE$784,$N$69:$N$784,$N31,$AS$69:$AS$784,31) -> 0 | BF31: =+SUMIFS(BF$69:BF$891,$N$69:$N$891,$N31,$AS$69:$AS$891,31) -> 0 | BG31: =+SUMIFS(BG$69:BG$891,$N$69:$N$891,$N31,$AS$69:$AS$891,31) -> 0 | BH31: =+SUMIFS(BH$69:BH$891,$N$69:$N$891,$N31,$AS$69:$AS$891,31) -> 0 | BI31: =+SUMIFS(BI$69:BI$891,$N$69:$N$891,$N31,$AS$69:$AS$891,31) -> 0 | BJ31: =+SUMIFS(BJ$69:BJ$891,$N$69:$N$891,$N31,$AS$69:$AS$891,31) -> 0 | BK31: =+SUMIFS(BK$69:BK$891,$N$69:$N$891,$N31,$AS$69:$AS$891,31) -> 0 | BL31: =+SUMIFS(BL$69:BL$891,$N$69:$N$891,$N31,$AS$69:$AS$891,31) -> 0 | BM31: =+SUMIFS(BM$69:BM$894,$N$69:$N$894,$N31,$AS$69:$AS$894,31) -> 0 | BN31: =+SUMIFS(BN$69:BN$784,$N$69:$N$784,$N31,$AS$69:$AS$784,31) -> 0
