Workbook

Sheet 税務署提出用
I3: (単位：円)
A4: 区分 | E4: 対象経費 | F4: 按分方法 | G4: 不課税収入額 | H4: 特定収入 | I4: 特定収入 以外
A6: 収 益 的 収 入 | B6: 一般会計負担金 | G6: =G8+G16+G18+G20 -> 13974628227 | H6: =H8+H16+H18+H20 -> 2307267553 | I6: =I8+I16+I18+I20 -> 11667360674
C8: 雨水処理負担金 | G8: =G10+G12+G14 -> 13869351636 | H8: =H10+H12+H14 -> 2284890841 | I8: =I10+I12+I14 -> 11584460795
D10: 維持管理費分 | E10: 雨水処理に係る 維持管理費分 | F10: 雨水処理に係る維持管理費 の課税支出割合 | G10: ='3条一般会計'!G10 -> 3383678341 | H10: ='3条一般会計'!H10 -> 2257096108 | I10: =G10-H10 -> 1126582233
D12: 減価償却費分 | E12: 雨水施設に係る 減価償却費分 | F12: 減価償却費に対する負担金 のため特定収入以外 | G12: ='3条一般会計'!G12 -> 8476549651 | H12: ='3条一般会計'!H12 -> 0 | I12: =G12-H12 -> 8476549651
D14: 支払利息分 | E14: 雨水施設に係る 支払利息等充当分 | F14: 課税支出である企業債 手数料（雨水分）の額 | G14: ='3条一般会計'!G18 -> 2009123644 | H14: ='3条一般会計'!H18 -> 27794733 | I14: =G14-H14 -> 1981328911
C16: 水質指導費負担金 | E16: 水質規制に係る経費 | F16: 水質規制に係る経費の 課税支出割合 | G16: ='3条一般会計'!G20 -> 51313295 | H16: ='3条一般会計'!H20 -> 12168217 | I16: =G16-H16 -> 39145078
C18: 普及促進費負担金 | E18: 水洗化普及促進に係る経費 | F18: 水洗化普及促進に係る経費 の課税支出割合 | G18: ='3条一般会計'!G22 -> 43567026 | H18: ='3条一般会計'!H22 -> 9253060 | I18: =G18-H18 -> 34313966
C20: 貸付事業費負担金 | E20: 水洗化貸付業務に係る経費 | F20: 水洗化貸付業務に係る経費 (利子を除く)の課税支出割合 | G20: ='3条一般会計'!G28 -> 10396270 | H20: ='3条一般会計'!H28 -> 955435 | I20: =G20-H20 -> 9440835
B22: 国庫補助金 | G22: =G24+G26 -> 0 | H22: =H24+H26 -> 0 | I22: =I24+I26 -> 0
C24: 下水道緊急整備費 国庫補助金 | E24: 下水道緊急整備費に 対する利子補給 | F24: 支払利息に対する補給金 のため特定収入以外 | G24: 0 | H24: 0 | I24: =G24-H24 -> 0
C26: 災害復旧費国庫補助金 | E26: 災害復旧に係る経費 に対する国庫補助金 | F26: 災害復旧に係る経費 の課税支出割合 | G26: =SUM(G28:G43) -> 0 | H26: =SUM(H28:H43) -> 0 | I26: =SUM(I28:I43) -> 0
C28: 公共 | D28: =総括表!E28 -> 公共土木施設災害 復旧事業費国庫負担金 | E28: =総括表!F28 -> 対象事業費×２／３ | F28: =総括表!G28 -> 3年度分 公共土木施設災害復旧事業費(補助事業現年分)の課税支出割合 | G28: =総括表!H28 -> 0 | H28: =総括表!I28 -> 0 | I28: =総括表!J28 -> 0
D30: =総括表!E30 -> 公共土木施設災害 復旧事業費国庫負担金 | E30: =総括表!F30 -> 対象事業費×２／３ | F30: =総括表!G30 -> 2年度分 公共土木施設災害復旧事業費(補助事業繰越分)の課税支出割合 | G30: =総括表!H30 -> 0 | H30: =総括表!I30 -> 0 | I30: =総括表!J30 -> 0
C32: 特環 | D32: =総括表!E32 -> 公共土木施設災害 復旧事業費国庫負担金 | E32: =総括表!F32 -> 対象事業費×２／３ | F32: =総括表!G32 -> 3年度分 公共土木施設災害復旧事業費(補助事業現年分)の課税支出割合 | G32: =総括表!H32 -> 0 | H32: =総括表!I32 -> 0 | I32: =総括表!J32 -> 0
D34: =総括表!E34 -> 公共土木施設災害 復旧事業費国庫負担金 | E34: =総括表!F34 -> 対象事業費×２／３ | F34: =総括表!G34 -> 2年度分 公共土木施設災害復旧事業費(補助事業繰越分)の課税支出割合 | G34: =総括表!H34 -> 0 | H34: =総括表!I34 -> 0 | I34: =総括表!J34 -> 0
C36: 農集 | D36: =総括表!E36 -> 災害関連農村生活環境 施設復旧事業国庫補助金 | E36: =総括表!F36 -> 0 | F36: =総括表!G36 -> 3年度分 災害関連農村生活環境施設復旧事業(補助事業現年分)の課税支出割合 | G36: =総括表!H36 -> 0 | H36: =総括表!I36 -> 0 | I36: =総括表!J36 -> 0
D38: =総括表!E38 -> 災害関連農村生活環境 施設復旧事業国庫補助金 | E38: =総括表!F38 -> 対象事業費×１／２ | F38: =総括表!G38 -> 2年度分 災害関連農村生活環境施設復旧事業(補助事業繰越分)の課税支出割合 | G38: =総括表!H38 -> 0 | H38: =総括表!I38 -> 0 | I38: =総括表!J38 -> 0
C40: 浄化槽 | D40: =総括表!E40 -> 0 | E40: =総括表!F40 -> 0 | F40: =総括表!G40 -> 0 | G40: =総括表!H40 -> 0 | H40: =総括表!I40 -> 0 | I40: =総括表!J40 -> 0
D42: =総括表!E42 -> 0 | E42: =総括表!F42 -> 0 | F42: =総括表!G42 -> 0 | G42: =総括表!H42 -> 0 | H42: =総括表!I42 -> 0 | I42: =総括表!J42 -> 0
B44: 負担金 | G44: =G46 -> 16476593 | H44: =H46 -> 0 | I44: =I46 -> 16476593
C46: 他会計負担金 | E46: 企業債利息償還金に 対する他町負担金 | F46: 支払利息に対する負担金 のため特定収入以外 | G46: =+'3条他会計'!G6 -> 16476593 | H46: =+'3条他会計'!H6 -> 0 | I46: =G46-H46 -> 16476593
B48: 一般会計補助金 | G48: =G50+G58 -> 9203253 | H48: =H50+H58 -> 5368538 | I48: =I50+I58 -> 3834715
C50: 汚水処理補助金 | G50: =SUM(G52:G57) -> 4980 | H50: =SUM(H52:H57) -> 0 | I50: =SUM(I52:I57) -> 4980
D52: 減価償却費分 | E52: 汚水施設に係る 減価償却費分 | F52: 減価償却費に対する負担金 のため特定収入以外 | G52: ='3条補助金'!G10 -> 0 | H52: ='3条補助金'!H10 -> 0 | I52: =G52-H52 -> 0
D54: 支払利息分 | E54: 汚水施設に係る 支払利息等充当分 | F54: 課税支出である企業債 手数料（汚水分）の額 | G54: ='3条補助金'!G16 -> 0 | H54: ='3条補助金'!H16 -> 0 | I54: =G54-H54 -> 0
D56: 使用料減免分 | E56: 下水道使用料減免分 | F56: 減価償却費・支払利息に対する 負担金のため特定収入以外 | G56: ='3条補助金'!G18 -> 4980 | H56: ='3条補助金'!H18 -> 0 | I56: =G56-H56 -> 4980
C58: その他補助金 | E58: 熊本地震被災地支援経費 に対する一般会計負担額 | F58: 被災地支援に係る経費 の課税支出割合 | G58: ='3条補助金'!G20 -> 9198273 | H58: ='3条補助金'!H20 -> 5368538 | I58: =G58-H58 -> 3829735
B60: その他の収益的収入中の不課税収入 | F60: 収益的支出の課税支出割合 | G60: =+総括表!H60 -> 9701615928 | H60: =+総括表!I60 -> 256789 | I60: =G60-H60 -> 9701359139
B62: 計 | G62: =G6+G22+G44+G48+G60 -> 23701924001 | H62: =H6+H22+H44+H48+H60 -> 2312892880 | I62: =I6+I22+I44+I48+I60 -> 21389031121
A64: 資 本 的 収 入 | B64: 国庫補助金 | G64: =G66+G94 -> 5717788000 | H64: =H66+H94 -> 5712285006 | I64: =I66+I94 -> 5502994
C66: 社会資本整備総合交付金 | G66: ='4条補助（公）'!G6 -> 5683800000 | H66: ='4条補助（公）'!H6 -> 5678297006 | I66: ='4条補助（公）'!I6 -> 5502994
C68: 公 共 下 水 道 | D68: ='4条補助（公）'!C8 -> 管路等・一般 | E68: ='4条補助（公）'!D8 -> 4,762,313.150千円×５／１０ | F68: ='4条補助（公）'!E8 -> 5年度分 公共下水道整備事業 (補助事業現年分)の 課税支出割合 | G68: ='4条補助（公）'!G8 -> 2411526000 | H68: ='4条補助（公）'!H19 -> 2527700000 | I68: ='4条補助（公）'!I19 -> 0
D70: ='4条補助（公）'!C10 -> 管路等・補助裏単市 | E70: ='4条補助（公）'!D10 -> 60,375.850千円×５／１０ | G70: ='4条補助（公）'!G10 -> 0
D72: ='4条補助（公）'!C18 -> 管路等・促進・工事国債 | E72: ='4条補助（公）'!D18 -> 0 | G72: ='4条補助（公）'!G18 -> 0
D74: ='4条補助（公）'!C20 -> 処理場・一般・高率 | E74: ='4条補助（公）'!D20 -> 191,660千円×５．５／１０ | G74: ='4条補助（公）'!G20 -> 105413000
D76: ='4条補助（公）'!C22 -> 処理場・一般・低率 | E76: ='4条補助（公）'!D22 -> 21,525千円×５／１０ | G76: ='4条補助（公）'!G22 -> 10761000
D78: ='4条補助（公）'!C30 -> 過年度補助金 | E78: ='4条補助（公）'!D30 -> 0 | G78: ='4条補助（公）'!G30 -> 0
D80: ='4条補助（公）'!C32 -> 管路等・一般(繰越分) | E80: ='4条補助（公）'!D32 -> 4,286,012.1千円×５／１０ | F80: =+'4条補助（公）'!E32 -> 4年度分 公共下水道整備事業 (補助事業繰越分)の 課税支出割合 | G80: ='4条補助（公）'!G32 -> 2201500000 | H80: ='4条補助（公）'!H37 -> 3150597006 | I80: ='4条補助（公）'!I37 -> 5502994
...

Sheet 総括表
A2: =+CONCATENATE("令和",DBCS([1]年度!$A$2),"年度決算 不課税収入区分表") -> 令和５年度決算 不課税収入区分表
J3: (単位：円)
A4: 区分 | F4: 対象経費 | G4: 按分方法 | H4: 不課税収入額 | I4: 特定収入 | J4: 特定収入 以外 | K4: 特定収入内訳（上段：課税支出額、下段特定収入の按分）
K5: 0.03 | L5: 0.05 | M5: 0.08 | N5: 0.08 | O5: 0.1
A6: 収 益 的 収 入 | B6: 一般会計負担金 | H6: =H8+H16+H18+H20 -> 13974628227 | I6: =I8+I16+I18+I20 -> 2307267553 | J6: =J8+J16+J18+J20 -> 11667360674
C8: 雨水処理負担金 | H8: =H10+H12+H14 -> 13869351636 | I8: =I10+I12+I14 -> 2284890841 | J8: =J10+J12+J14 -> 11584460795
D10: 維持管理費分 | F10: 雨水処理に係る 維持管理費分 | G10: 雨水処理に係る維持管理費 の課税支出割合 | H10: ='3条一般会計'!G10 -> 3383678341 | I10: ='3条一般会計'!H10 -> 2257096108 | J10: =H10-I10 -> 1126582233
D12: 減価償却費分 | F12: 雨水施設に係る 減価償却費分 | G12: 減価償却費に対する負担金 のため特定収入以外 | H12: ='3条一般会計'!G12 -> 8476549651 | I12: ='3条一般会計'!H12 -> 0 | J12: =H12-I12 -> 8476549651
D14: 支払利息分 | F14: 雨水施設に係る 支払利息等充当分 | G14: 課税支出である企業債 手数料（雨水分）の額 | H14: ='3条一般会計'!G18 -> 2009123644 | I14: ='3条一般会計'!H18 -> 27794733 | J14: =H14-I14 -> 1981328911
C16: 水質指導費負担金 | F16: 水質規制に係る経費 | G16: 水質規制に係る経費の 課税支出割合 | H16: ='3条一般会計'!G20 -> 51313295 | I16: ='3条一般会計'!H20 -> 12168217 | J16: =H16-I16 -> 39145078
C18: 普及促進費負担金 | F18: 水洗化普及促進に係る経費 | G18: 水洗化普及促進に係る経費 の課税支出割合 | H18: ='3条一般会計'!G22 -> 43567026 | I18: ='3条一般会計'!H22 -> 9253060 | J18: =H18-I18 -> 34313966
C20: 貸付事業費負担金 | F20: 水洗化貸付業務に係る経費 | G20: 水洗化貸付業務に係る経費 (利子を除く)の課税支出割合 | H20: ='3条一般会計'!G28 -> 10396270 | I20: ='3条一般会計'!H28 -> 955435 | J20: =H20-I20 -> 9440835
B22: 国庫補助金 | H22: =H24+H26 -> 0 | I22: =I24+I26 -> 0 | J22: =J24+J26 -> 0
C24: 下水道緊急整備費 国庫補助金 | F24: 下水道緊急整備費に 対する利子補給 | G24: 支払利息に対する補給金 のため特定収入以外 | H24: 0 | I24: 0 | J24: =H24-I24 -> 0
C26: 災害復旧費国庫補助金 | F26: 災害復旧に係る経費 に対する国庫補助金 | G26: 災害復旧に係る経費 の課税支出割合 | H26: =SUM(H28:H43) -> 0 | I26: =SUM(I28:I43) -> 0 | J26: =SUM(J28:J43) -> 0
D28: 公共 | E28: =+'3条災害補助'!$C$10 -> 公共土木施設災害 復旧事業費国庫負担金 | F28: =+'3条災害補助'!$D$10 -> 対象事業費×２／３ | G28: =+'3条災害補助'!$E$10 -> 3年度分 公共土木施設災害復旧事業費(補助事業現年分)の課税支出割合 | H28: =+'3条災害補助'!$G$10 -> 0 | I28: =+'3条災害補助'!H$12 -> 0 | J28: =+'3条災害補助'!I$12 -> 0
E30: =+'3条災害補助'!$C$16 -> 公共土木施設災害 復旧事業費国庫負担金 | F30: =+'3条災害補助'!$D$16 -> 対象事業費×２／３ | G30: =+'3条災害補助'!$E$16 -> 2年度分 公共土木施設災害復旧事業費(補助事業繰越分)の課税支出割合 | H30: =+'3条災害補助'!$G$16 -> 0 | I30: =+'3条災害補助'!H$18 -> 0 | J30: =+'3条災害補助'!I$18 -> 0
D32: 特環 | E32: =+'3条災害補助'!$C$24 -> 公共土木施設災害 復旧事業費国庫負担金 | F32: =+'3条災害補助'!$D$24 -> 対象事業費×２／３ | G32: =+'3条災害補助'!$E$24 -> 3年度分 公共土木施設災害復旧事業費(補助事業現年分)の課税支出割合 | H32: =+'3条災害補助'!$G$24 -> 0 | I32: =+'3条災害補助'!H$26 -> 0 | J32: =+'3条災害補助'!I$26 -> 0
E34: =+'3条災害補助'!$C$30 -> 公共土木施設災害 復旧事業費国庫負担金 | F34: =+'3条災害補助'!$D$30 -> 対象事業費×２／３ | G34: =+'3条災害補助'!$E$30 -> 2年度分 公共土木施設災害復旧事業費(補助事業繰越分)の課税支出割合 | H34: =+'3条災害補助'!$G$30 -> 0 | I34: =+'3条災害補助'!H$32 -> 0 | J34: =+'3条災害補助'!I$32 -> 0
D36: 農集 | E36: =+'3条災害補助'!$C$38 -> 災害関連農村生活環境 施設復旧事業国庫補助金 | F36: =+'3条災害補助'!$D$38 -> 0 | G36: =+'3条災害補助'!$E$38 -> 3年度分 災害関連農村生活環境施設復旧事業(補助事業現年分)の課税支出割合 | H36: =+'3条災害補助'!$G$38 -> 0 | I36: =+'3条災害補助'!H$40 -> 0 | J36: =+'3条災害補助'!I$40 -> 0
E38: =+'3条災害補助'!$C$44 -> 災害関連農村生活環境 施設復旧事業国庫補助金 | F38: =+'3条災害補助'!$D$44 -> 対象事業費×１／２ | G38: =+'3条災害補助'!$E$44 -> 2年度分 災害関連農村生活環境施設復旧事業(補助事業繰越分)の課税支出割合 | H38: =+'3条災害補助'!$G$44 -> 0 | I38: =+'3条災害補助'!H$46 -> 0 | J38: =+'3条災害補助'!I$46 -> 0
D40: 浄化槽 | E40: =+'3条災害補助'!$C$52 -> 0 | F40: =+'3条災害補助'!$D$52 -> 0 | G40: =+'3条災害補助'!$E$52 -> 0 | H40: =+'3条災害補助'!$G$52 -> 0 | I40: =+'3条災害補助'!H$54 -> 0 | J40: =+'3条災害補助'!I$54 -> 0
E42: =+'3条災害補助'!$C$58 -> 0 | F42: =+'3条災害補助'!$D$58 -> 0 | G42: =+'3条災害補助'!$E$58 -> 0 | H42: =+'3条災害補助'!$G$58 -> 0 | I42: =+'3条災害補助'!H$60 -> 0 | J42: =+'3条災害補助'!I$60 -> 0
B44: 負担金 | H44: =H46 -> 16476593 | I44: =I46 -> 0 | J44: =J46 -> 16476593
C46: 他会計負担金 | F46: 企業債利息償還金に 対する他町負担金 | G46: 支払利息に対する負担金 のため特定収入以外 | H46: =+'3条他会計'!G6 -> 16476593 | I46: =+'3条他会計'!H8 -> 0 | J46: =H46-I46 -> 16476593
B48: 一般会計補助金 | H48: =H50+H58 -> 9203253 | I48: =I50+I58 -> 5368538 | J48: =J50+J58 -> 3834715
C50: 汚水処理補助金 | H50: =SUM(H52:H57) -> 4980 | I50: =SUM(I52:I57) -> 0 | J50: =SUM(J52:J57) -> 4980
D52: 減価償却費分 | F52: 汚水施設に係る 減価償却費分 | G52: 減価償却費に対する負担金 のため特定収入以外 | H52: ='3条補助金'!G10 -> 0 | I52: ='3条補助金'!H10 -> 0 | J52: =H52-I52 -> 0
D54: 支払利息分 | F54: 汚水施設に係る 支払利息等充当分 | G54: 課税支出である企業債 手数料（汚水分）の額 | H54: ='3条補助金'!G16 -> 0 | I54: ='3条補助金'!H16 -> 0 | J54: =H54-I54 -> 0
D56: 使用料減免分 | F56: 下水道使用料減免分 | G56: 減価償却費・支払利息に対する 負担金のため特定収入以外 | H56: ='3条補助金'!G18 -> 4980 | I56: ='3条補助金'!H18 -> 0 | J56: =H56-I56 -> 4980
C58: その他補助金 | F58: 熊本地震被災地支援経費 に対する一般会計負担額 | G58: 被災地支援に係る経費 の課税支出割合 | H58: =+'3条補助金'!G20 -> 9198273 | I58: =+'3条補助金'!H20 -> 5368538 | J58: =H58-I58 -> 3829735
B60: その他の収益的収入中の不課税収入 | G60: 収益的支出の課税支出割合 | H60: =+'3条その他'!G6+'[2]3条収入'!$U$69 -> 9701615928 | I60: =+'3条その他'!H6 -> 256789 | J60: =H60-I60 -> 9701359139
B62: 計 | H62: =H6+H22+H44+H48+H60 -> 23701924001 | I62: =I6+I22+I44+I48+I60 -> 2312892880 | J62: =J6+J22+J44+J48+J60 -> 21389031121 | K62: =+SUM('3条一般会計:3条災害補助'!J6) -> 0 | L62: =+SUM('3条一般会計:3条災害補助'!K6) -> 0 | M62: =+SUM('3条一般会計:3条災害補助'!L6) -> 455392 | N62: =+SUM('3条一般会計:3条災害補助'!M6) -> 130568 | O62: =+SUM('3条一般会計:3条災害補助'!N6) -> 2312306920
A64: 資 本 的 収 入 | B64: 国庫補助金 | H64: =H66+H104 -> 5717788000 | I64: =I66+I104 -> 5712285006 | J64: =J66+J104 -> 5502994
C66: 社会資本整備総合交付金 | H66: ='4条補助（公）'!G6 -> 5683800000 | I66: ='4条補助（公）'!H6 -> 5678297006 | J66: ='4条補助（公）'!I6 -> 5502994
D68: 公 共 下 水 道 | E68: 管路等・一般 | F68: ='4条補助（公）'!D8 -> 4,762,313.150千円×５／１０ | G68: ='4条補助（公）'!E8 -> 5年度分 公共下水道整備事業 (補助事業現年分)の 課税支出割合 | H68: ='4条補助（公）'!G8 -> 2411526000 | I68: ='4条補助（公）'!H19 -> 2527700000 | J68: ='4条補助（公）'!I19 -> 0
E70: 管路等・一般 | F70: ='4条補助（公）'!D10 -> 60,375.850千円×５／１０
E72: 管路等・用地国債 | F72: ='4条補助（公）'!D12 -> 0 | H72: ='4条補助（公）'!G12 -> 0
E74: 管路等・特債 | F74: ='4条補助（公）'!D14 -> 0 | H74: ='4条補助（公）'!G14 -> 0
E76: 管路等・都市水 | F76: ='4条補助（公）'!D16 -> 0 | H76: ='4条補助（公）'!G16 -> 0
...

Sheet 3条一般会計
A1: =+"令和"&MID(総括表!A2,3,1)&"年度決算 不課税収入区分表(一般会計負担金)" -> 令和５年度決算 不課税収入区分表(一般会計負担金)
I3: (単位：円)
A4: 区分 | D4: 対象経費 | E4: 按分方法 | F4: 課税支出額 | G4: 不課税収入額 | H4: 特定収入 | I4: 特定収入 以外 | J4: 特定収入内訳（上段：課税支出額、下段特定収入の按分）
F5: 支出額合計 | J5: 0.03 | K5: 0.05 | L5: 0.08 | M5: 0.08 | N5: 0.1
A6: 一般会計負担金 | G6: =G8+G20+G22+G28 -> 13974628227 | H6: =H8+H20+H22+H28 -> 2307267553 | I6: =I8+I20+I22+I28 -> 11667360674 | J6: =+SUM(J11,J15,J21,J23,J25) -> 0 | K6: =+SUM(K11,K15,K21,K23,K25) -> 0 | L6: =+SUM(L11,L15,L21,L23,L25) -> 455357 | M6: =+SUM(M11,M15,M21,M23,M25) -> 130554 | N6: =+SUM(N11,N15,N21,N23,N25) -> 2306681642
B8: 雨水処理負担金 | G8: =G10+G12+G18 -> 13869351636 | H8: =H10+H12+H18 -> 2284890841 | I8: =I10+I12+I18 -> 11584460795
C10: 維持管理費分 | D10: 雨水処理に係る 維持管理費分 | E10: 雨水処理に係る維持管理費 の課税支出割合 | F10: =+'[1]3条支出'!$K$53 -> 2460111073 | G10: =+[3]雨汚水!$O$111 -> 3383678341 | H10: =IFERROR(ROUND((G10)*F10/F11,0),0) -> 2257096108 | I10: =G10-H10 -> 1126582233 | L10: =+'[1]3条支出'!F$53+'[1]3条支出'!G$53+'[1]3条支出'!H$53 -> 496314 | M10: =+'[1]3条支出'!I$53 -> 142297 | N10: =+'[1]3条支出'!J$53 -> 2459472462
F11: ='[1]3条支出'!$E$53 -> 3688023972 | L11: =+H10-SUM(J11:K11,M11:N11) -> 455357 | M11: =IFERROR(ROUND(M10/$F10*$H10,0),0) -> 130554 | N11: =IFERROR(ROUND(N10/$F10*$H10,0),0) -> 2256510197
C12: 減価償却費分 | D12: 雨水施設に係る 減価償却費分 | E12: 減価償却費に対する負担金 のため特定収入以外 | G12: =+[3]雨汚水!$O$112 -> 8476549651 | H12: =IFERROR(ROUND((G12)*F12/F13,0),0) -> 0 | I12: =G12-H12 -> 8476549651
C14: 支払利息分 | D14: 雨水施設に係る 支払利息等充当分 | E14: 課税支出である企業債手数料 （雨水分）の額 | F14: =+[1]営外!$K$9 -> 61813753 | G14: =+[3]雨汚水!$O$115 -> 27794733 | H14: =G14 -> 27794733 | I14: =G14-H14 -> 0 | L14: =+[1]営外!F$9+[1]営外!G$9+[1]営外!H$9 -> 0 | M14: =+[1]営外!I$9 -> 0 | N14: =+[1]営外!J$9 -> 61813753
F15: =+[1]営外!$E$9 -> 61813753 | L15: =+H14-SUM(J15:K15,M15:N15) -> 0 | M15: =IFERROR(ROUND(M14/$F14*$H14,0),0) -> 0 | N15: =IFERROR(ROUND(N14/$F14*$H14,0),0) -> 27794733
E16: その他(特定収入以外) | G16: =+[3]雨汚水!$O$114 -> 1981328911 | H16: =IFERROR(ROUND((G16)*F16/F17,0),0) -> 0 | I16: =G16-H16 -> 1981328911
E18: 小 計 | G18: =G14+G16 -> 2009123644 | H18: =H14+H16 -> 27794733 | I18: =I14+I16 -> 1981328911
B20: 水質指導費負担金 | D20: 水質規制に係る経費 | E20: 水質規制に係る経費の 課税支出割合 | F20: =+'[1]3条支出'!$K$7 -> 12436317 | G20: =+[3]雨汚水!$O$116 -> 51313295 | H20: =IFERROR(ROUND((G20)*F20/F21,0),0) -> 12168217 | I20: =G20-H20 -> 39145078 | L20: =+'[1]3条支出'!F$7+'[1]3条支出'!G$7+'[1]3条支出'!H$7 -> 0 | M20: =+'[1]3条支出'!I$7 -> 0 | N20: =+'[1]3条支出'!J$7 -> 12436317
F21: =+'[1]3条支出'!$E$7 -> 52443869 | L21: =+H20-SUM(J21:K21,M21:N21) -> 0 | M21: =IFERROR(ROUND(M20/$F20*$H20,0),0) -> 0 | N21: =IFERROR(ROUND(N20/$F20*$H20,0),0) -> 12168217
B22: 普及促進費負担金 | D22: 水洗化普及促進に係る経費 | E22: 水洗化普及促進に係る経費 の課税支出割合 | F22: =+'[1]3条支出'!$K$11 -> 18870469 | G22: =+[3]雨汚水!$O$117 -> 43567026 | H22: =IFERROR(ROUND((G22)*F22/F23,0),0) -> 9253060 | I22: =G22-H22 -> 34313966 | L22: =+'[1]3条支出'!F$11+'[1]3条支出'!G$11+'[1]3条支出'!H$11 -> 0 | M22: =+'[1]3条支出'!I$11 -> 0 | N22: =+'[1]3条支出'!J$11 -> 18870469
F23: =+'[1]3条支出'!$E$11 -> 88849549 | L23: =+H22-SUM(J23:K23,M23:N23) -> 0 | M23: =IFERROR(ROUND(M22/$F22*$H22,0),0) -> 0 | N23: =IFERROR(ROUND(N22/$F22*$H22,0),0) -> 9253060
B24: 貸付事業費負担金 | D24: 水洗化貸付業務に係る経費 | E24: 水洗化貸付業務に係る経費 (利子を除く)の課税支出割合 | F24: =+'[1]3条支出'!$K$12 -> 963485 | G24: =+[3]雨汚水!$O$118 -> 10396270 | H24: =IFERROR(ROUND((G24)*F24/F25,0),0) -> 955435 | I24: =G24-H24 -> 9440835 | L24: =+'[1]3条支出'!F$12+'[1]3条支出'!G$12+'[1]3条支出'!H$12 -> 0 | M24: =+'[1]3条支出'!I$12 -> 0 | N24: =+'[1]3条支出'!J$12 -> 963485
F25: =+'[1]3条支出'!$E$12 -> 10483859 | L25: =+H24-SUM(J25:K25,M25:N25) -> 0 | M25: =IFERROR(ROUND(M24/$F24*$H24,0),0) -> 0 | N25: =IFERROR(ROUND(N24/$F24*$H24,0),0) -> 955435
E26: 支払利息分〈特定収入以外〉 | G26: =G28-G24 -> 0 | H26: =IFERROR(ROUND((G26)*F26/F27,0),0) -> 0 | I26: =G26-H26 -> 0
E28: 小 計 | G28: =+G24 -> 10396270 | H28: =H24+H26 -> 955435 | I28: =I24+I26 -> 9440835
F30: 雨汚水シート 一般会計繰入金 税抜き決算額 （控除不可消費税等の雑支出の配分前） | G30: =+[3]雨汚水!$O$109 -> 13974628227
F31: チェック | G31: =+G6-G30 -> 0

Sheet 3条補助金
A1: =+"令和"&MID(総括表!A2,3,1)&"年度決算 不課税収入区分表(一般会計補助金)" -> 令和５年度決算 不課税収入区分表(一般会計補助金)
I3: (単位：円)
A4: 区分 | D4: 対象経費 | E4: 按分方法 | F4: 課税支出額 | G4: 不課税収入額 | H4: 特定収入 | I4: 特定収入 以外 | J4: 特定収入内訳（上段：課税支出額、下段特定収入の按分）
F5: 支出額合計 | J5: 0.03 | K5: 0.05 | L5: 0.08 | M5: 0.08 | N5: 0.1
A6: 一般会計補助金 | G6: =G8+G20 -> 9203253 | H6: =H8+H20 -> 5368538 | I6: =I8+I20 -> 3834715 | J6: =+J13+J21 -> 0 | K6: =+K13+K21 -> 0 | L6: =+L13+L21 -> 0 | M6: =+M13+M21 -> 0 | N6: =+N13+N21 -> 5368538
B8: 汚水処理補助金 | G8: =G10+G16+G18 -> 4980 | H8: =H10+H16+H18 -> 0 | I8: =I10+I16+I18 -> 4980
C10: 減価償却費分 | D10: 汚水施設に係る 減価償却費分 | E10: 減価償却費に対する負担金 のため特定収入以外 | G10: =+[3]雨汚水!$O$123 -> 0 | H10: =IFERROR(ROUND((G10)*F10/F11,0),0) -> 0 | I10: =G10-H10 -> 0
C12: 支払利息分 | D12: 汚水施設に係る 支払利息等充当分 | E12: 課税支出である企業債手数料 （汚水分）に対する一般会計 補助金の支払利息充当割合 | F12: =+[1]営外!$K$9 -> 61813753 | G12: 0 | H12: =IFERROR(ROUND((G12)*F12/F13,0),0) -> 0 | I12: =G12-H12 -> 0 | L12: =+[1]営外!F$9+[1]営外!G$9+[1]営外!H$9 -> 0 | M12: =+[1]営外!I$9 -> 0 | N12: =+[1]営外!J$9 -> 61813753
F13: =+[1]営外!$E$9 -> 61813753 | L13: =+H12-SUM(J13:K13,M13:N13) -> 0 | M13: =IFERROR(ROUND(M12/$F12*$H12,0),0) -> 0 | N13: =IFERROR(ROUND(N12/$F12*$H12,0),0) -> 0
E14: その他(特定収入以外) | G14: =G16-G12 -> 0 | H14: =IFERROR(ROUND((G14)*F14/F15,0),0) -> 0 | I14: =G14-H14 -> 0
E16: 小 計 | G16: =+[3]雨汚水!$O$124 -> 0 | H16: =H12+H14 -> 0 | I16: =I12+I14 -> 0
C18: 使用料減免分 | D18: 下水道使用料減免分 | E18: 減価償却費・支払利息に対する 負担金のため特定収入以外 | G18: =+[3]雨汚水!$O$125 -> 4980 | H18: =IFERROR(ROUND((G18)*F18/F19,0),0) -> 0 | I18: =G18-H18 -> 4980
B20: その他補助金 | D20: 能登半島地震被災地支援経費 に対する一般会計負担額 | E20: 被災地支援に係る経費 の課税支出割合 | F20: =+[1]営外!$K$20 -> 5368538 | G20: =+[3]雨汚水!$O$126 -> 9198273 | H20: =IFERROR(ROUND((G20)*F20/F21,0),0) -> 5368538 | I20: =G20-H20 -> 3829735 | L20: =+[1]営外!$F$20+[1]営外!$F$20+[1]営外!$F$20 -> 0 | M20: =+[1]営外!$F$20 -> 0 | N20: =+[1]営外!$F$20 -> 0
F21: =+[1]営外!$E$20 -> 9198273 | L21: =+H20-SUM(J21:K21,M21:N21) -> 0 | M21: =IFERROR(ROUND(M20/$F20*$H20,0),0) -> 0 | N21: 5368538
F22: 雨汚水シート 一般会計繰入金 税抜き決算額 （控除不可消費税等の雑支出の配分前） | G22: =+[3]雨汚水!$O$120 -> 9203253
F23: チェック | G23: =+G6-G22 -> 0

Sheet 3条他会計
A1: =+"令和"&MID(総括表!A2,3,1)&"年度決算 不課税収入区分表(他会計負担金)" -> 令和５年度決算 不課税収入区分表(他会計負担金)
I3: (単位：円)
A4: 区分 | D4: 対象経費 | E4: 按分方法 | F4: 課税支出額 | G4: 不課税収入額 | H4: 特定収入 | I4: 特定収入 以外 | J4: 特定収入内訳（上段：課税支出額、下段特定収入の按分）
F5: 支出額合計 | J5: 0.03 | K5: 0.05 | L5: 0.08 | M5: 0.08 | N5: 0.1
A6: 負担金 | G6: =+SUM(G8:G11) -> 16476593 | H6: =+SUM(H8:H11) -> 0 | I6: =+SUM(I8:I11) -> 16476593
B8: 他会計負担金 | D8: 企業債利息償還金に 対する他町負担金 | E8: 支払利息に対する負担金 のため特定収入以外 | G8: =+[3]雨汚水!$E$88 -> 16476593 | H8: =IFERROR(ROUND((G8)*F8/F9,0),0) -> 0 | I8: =G8-H8 -> 16476593
B10: 他会計負担金 | D10: 下水道使用料減免分 | E10: 減価償却費・支払利息に対する 負担金のため特定収入以外 | G10: =+[3]雨汚水!$E$89 -> 0 | H10: =IFERROR(ROUND((G10)*F10/F11,0),0) -> 0 | I10: =G10-H10 -> 0
F12: 3条収入シート 他会計負担金 | G12: =+'[2]3条収入'!$V$41 -> 16476593
F13: チェック | G13: =G6-G12 -> 0

Sheet 3条その他
A1: =+"令和"&MID(総括表!A2,3,1)&"年度決算(その他の収入)" -> 令和５年度決算(その他の収入) | K1: =+IFERROR(VLOOKUP($E1,$P$2:$W$5,5,0),"-") -> - | L1: =+IFERROR(VLOOKUP($E1,$P$2:$W$5,6,0),"-") -> - | M1: =+IFERROR(VLOOKUP($E1,$P$2:$W$5,7,0),"-") -> - | N1: =+IFERROR(VLOOKUP($E1,$P$2:$W$5,8,0),"-") -> - | O1: ←コピペ用数式 | P1: 按分方法 | Q1: 課税支出額 | R1: 支出額合計 | S1: 0.03 | T1: 0.05 | U1: 0.08 | V1: 0.08 | W1: 0.1
P2: 収益的支出の 課税支出割合 | Q2: =+'[1]3条支出'!$K$41 -> 9108565869 | R2: =+'[1]3条支出'!$E$41 -> 42643669657 | S2: 0 | T2: 0 | U2: =+SUM('[1]3条支出'!$F$41:$G$41)+'[1]3条支出'!H$41 -> 1236141 | V2: =+'[1]3条支出'!I$41 -> 500878 | W2: =+'[1]3条支出'!J$41 -> 9106828850
I3: (単位：円) | P3: 課税支出に対応する不課税収入のため特定収入 | Q3: 1 | R3: 1 | S3: - | T3: - | U3: 該当税率に「1」 | V3: 該当税率に「1」 | W3: 該当税率に「1」
A4: 区分 | D4: 対象経費 | E4: 按分方法 | F4: 課税支出額 | G4: 不課税収入額 | H4: 特定収入 | I4: 特定収入 以外 | J4: 特定収入内訳（上段：課税支出額、下段特定収入の按分） | P4: 不課税支出に対応する不課税収入のため特定収入以外 | Q4: - | R4: - | S4: - | T4: - | U4: - | V4: - | W4: -
F5: 支出額合計 | J5: 0.03 | K5: 0.05 | L5: 0.08 | M5: 0.08 | N5: 0.1 | P5: 特定収入以外 | Q5: - | R5: - | S5: - | T5: - | U5: - | V5: - | W5: -
A6: その他の収入 | G6: =+G18+G32+G48 -> 3786818 | H6: =+H18+H32+H48 -> 256789 | I6: =+I18+I32+I48 -> 3530029 | L6: =+SUM(L19,L33,L21,L49) -> 35 | M6: =+SUM(M19,M33,M21,M49) -> 14 | N6: =+SUM(N19,N33,N21,N49) -> 256740
A8: その他雑収益 | B8: 自動車損害共済 共済金 | E8: 収益的支出の 課税支出割合 | F8: =+IFERROR(VLOOKUP($E8,$P$2:$W$5,2,0),"-") -> 9108565869 | G8: 1202214 | H8: =IFERROR(ROUND((G8)*F8/F9,0),0) -> 256789 | I8: =G8-H8 -> 945425 | L8: =+IFERROR(VLOOKUP($E8,$P$2:$W$5,6,0),"-") -> 1236141 | M8: =+IFERROR(VLOOKUP($E8,$P$2:$W$5,7,0),"-") -> 500878 | N8: =+IFERROR(VLOOKUP($E8,$P$2:$W$5,8,0),"-") -> 9106828850
F9: =+IFERROR(VLOOKUP($E8,$P$2:$W$5,3,0),"-") -> 42643669657 | L9: =+H8-SUM(J9:K9,M9:N9) -> 35 | M9: =IFERROR(ROUND(M8/$F8*$H8,0),0) -> 14 | N9: =IFERROR(ROUND(N8/$F8*$H8,0),0) -> 256740
B10: 建物損害共済 共済金 | E10: 収益的支出の 課税支出割合 | F10: =+IFERROR(VLOOKUP($E10,$P$2:$W$5,2,0),"-") -> 9108565869 | G10: 0 | H10: =IFERROR(ROUND((G10)*F10/F11,0),0) -> 0 | I10: =G10-H10 -> 0 | L10: =+IFERROR(VLOOKUP($E10,$P$2:$W$5,6,0),"-") -> 1236141 | M10: =+IFERROR(VLOOKUP($E10,$P$2:$W$5,7,0),"-") -> 500878 | N10: =+IFERROR(VLOOKUP($E10,$P$2:$W$5,8,0),"-") -> 9106828850
F11: =+IFERROR(VLOOKUP($E10,$P$2:$W$5,3,0),"-") -> 42643669657 | L11: =+H10-SUM(J11:K11,M11:N11) -> 0 | M11: =IFERROR(ROUND(M10/$F10*$H10,0),0) -> 0 | N11: =IFERROR(ROUND(N10/$F10*$H10,0),0) -> 0
B12: 下水道損害賠償保険 保険金 | E12: 収益的支出の 課税支出割合 | F12: =+IFERROR(VLOOKUP($E12,$P$2:$W$5,2,0),"-") -> 9108565869 | G12: 0 | H12: =IFERROR(ROUND((G12)*F12/F13,0),0) -> 0 | I12: =G12-H12 -> 0 | L12: =+IFERROR(VLOOKUP($E12,$P$2:$W$5,6,0),"-") -> 1236141 | M12: =+IFERROR(VLOOKUP($E12,$P$2:$W$5,7,0),"-") -> 500878 | N12: =+IFERROR(VLOOKUP($E12,$P$2:$W$5,8,0),"-") -> 9106828850
F13: =+IFERROR(VLOOKUP($E12,$P$2:$W$5,3,0),"-") -> 42643669657 | L13: =+H12-SUM(J13:K13,M13:N13) -> 0 | M13: =IFERROR(ROUND(M12/$F12*$H12,0),0) -> 0 | N13: =IFERROR(ROUND(N12/$F12*$H12,0),0) -> 0
B14: 消費税還付に伴う還付加算金 | E14: 特定収入以外 | F14: =+IFERROR(VLOOKUP($E14,$P$2:$W$5,2,0),"-") -> - | G14: 0 | H14: =IFERROR(ROUND((G14)*F14/F15,0),0) -> 0 | I14: =G14-H14 -> 0 | L14: =+IFERROR(VLOOKUP($E14,$P$2:$W$5,6,0),"-") -> - | M14: =+IFERROR(VLOOKUP($E14,$P$2:$W$5,7,0),"-") -> - | N14: =+IFERROR(VLOOKUP($E14,$P$2:$W$5,8,0),"-") -> -
F15: =+IFERROR(VLOOKUP($E14,$P$2:$W$5,3,0),"-") -> - | L15: =+H14-SUM(J15:K15,M15:N15) -> 0 | M15: =IFERROR(ROUND(M14/$F14*$H14,0),0) -> 0 | N15: =IFERROR(ROUND(N14/$F14*$H14,0),0) -> 0
B16: 支障公共施設の移転に関する補償金 | E16: 不課税支出に対応する不課税収入のため特定収入以外 | F16: =+IFERROR(VLOOKUP($E16,$P$2:$W$5,2,0),"-") -> - | G16: 0 | H16: =IFERROR(ROUND((G16)*F16/F17,0),0) -> 0 | I16: =G16-H16 -> 0 | L16: =+IFERROR(VLOOKUP($E16,$P$2:$W$5,6,0),"-") -> - | M16: =+IFERROR(VLOOKUP($E16,$P$2:$W$5,7,0),"-") -> - | N16: =+IFERROR(VLOOKUP($E16,$P$2:$W$5,8,0),"-") -> -
F17: =+IFERROR(VLOOKUP($E16,$P$2:$W$5,3,0),"-") -> - | L17: =+H16-SUM(J17:K17,M17:N17) -> 0 | M17: =IFERROR(ROUND(M16/$F16*$H16,0),0) -> 0 | N17: =IFERROR(ROUND(N16/$F16*$H16,0),0) -> 0
B18: 計 | G18: =SUM(G8:G17) -> 1202214 | H18: =+SUM(H8:H17) -> 256789 | I18: =G18-H18 -> 945425
L19: =+SUM(L9,L11,L13,L15,L17) -> 35 | M19: =+SUM(M9,M11,M13,M15,M17) -> 14 | N19: =+SUM(N9,N11,N13,N15,N17) -> 256740
A20: 消費税及び地方消費税 還付金 | E20: 特定収入以外 | F20: =+IFERROR(VLOOKUP($E20,$P$2:$W$5,2,0),"-") -> - | G20: =+'[2]3条収入'!$E$50 -> 0 | H20: =IFERROR(ROUND((G20)*F20/F21,0),0) -> 0 | I20: =G20-H20 -> 0 | L20: =+IFERROR(VLOOKUP($E20,$P$2:$W$5,6,0),"-") -> - | M20: =+IFERROR(VLOOKUP($E20,$P$2:$W$5,7,0),"-") -> - | N20: =+IFERROR(VLOOKUP($E20,$P$2:$W$5,8,0),"-") -> -
F21: =+IFERROR(VLOOKUP($E20,$P$2:$W$5,3,0),"-") -> - | L21: =+H20-SUM(J21:K21,M21:N21) -> 0 | M21: =IFERROR(ROUND(M20/$F20*$H20,0),0) -> 0 | N21: =IFERROR(ROUND(N20/$F20*$H20,0),0) -> 0
A22: 過年度損益修正益 | B22: 過年度分手当等の戻入 | D22: 過年度手当等支出の返還 | E22: 不課税支出に対応する不課税収入のため特定収入以外 | F22: =+IFERROR(VLOOKUP($E22,$P$2:$W$5,2,0),"-") -> - | G22: 820795 | H22: =IFERROR(ROUND((G22)*F22/F23,0),0) -> 0 | I22: =G22-H22 -> 820795 | L22: =+IFERROR(VLOOKUP($E22,$P$2:$W$5,6,0),"-") -> - | M22: =+IFERROR(VLOOKUP($E22,$P$2:$W$5,7,0),"-") -> - | N22: =+IFERROR(VLOOKUP($E22,$P$2:$W$5,8,0),"-") -> -
F23: =+IFERROR(VLOOKUP($E22,$P$2:$W$5,3,0),"-") -> - | L23: =+H22-SUM(J23:K23,M23:N23) -> 0 | M23: =IFERROR(ROUND(M22/$F22*$H22,0),0) -> 0 | N23: =IFERROR(ROUND(N22/$F22*$H22,0),0) -> 0
B24: 消費税算出額と申告額の差額 | E24: 特定収入以外 | F24: =+IFERROR(VLOOKUP($E24,$P$2:$W$5,2,0),"-") -> - | G24: 160 | H24: =IFERROR(ROUND((G24)*F24/F25,0),0) -> 0 | I24: =G24-H24 -> 160 | L24: =+IFERROR(VLOOKUP($E24,$P$2:$W$5,6,0),"-") -> - | M24: =+IFERROR(VLOOKUP($E24,$P$2:$W$5,7,0),"-") -> - | N24: =+IFERROR(VLOOKUP($E24,$P$2:$W$5,8,0),"-") -> -
F25: =+IFERROR(VLOOKUP($E24,$P$2:$W$5,3,0),"-") -> - | L25: =+H24-SUM(J25:K25,M25:N25) -> 0 | M25: =IFERROR(ROUND(M24/$F24*$H24,0),0) -> 0 | N25: =IFERROR(ROUND(N24/$F24*$H24,0),0) -> 0
B26: 未収金貸倒引当金の更正に伴う特別利益 | E26: 不課税支出に対応する不課税収入のため特定収入以外 | F26: =+IFERROR(VLOOKUP($E26,$P$2:$W$5,2,0),"-") -> - | G26: 0 | H26: =IFERROR(ROUND((G26)*F26/F27,0),0) -> 0 | I26: =G26-H26 -> 0 | L26: =+IFERROR(VLOOKUP($E26,$P$2:$W$5,6,0),"-") -> - | M26: =+IFERROR(VLOOKUP($E26,$P$2:$W$5,7,0),"-") -> - | N26: =+IFERROR(VLOOKUP($E26,$P$2:$W$5,7,0),"-") -> -
F27: =+IFERROR(VLOOKUP($E26,$P$2:$W$5,3,0),"-") -> - | L27: =+H26-SUM(J27:K27,N27) -> 0 | M27: =IFERROR(ROUND(M26/E26*G26,0),0) -> 0 | N27: =IFERROR(ROUND(N26/F26*H26,0),0) -> 0
B28: 過年度に購入した固定資産の取得に伴う振替 | E28: 特定収入以外 | F28: =+IFERROR(VLOOKUP($E28,$P$2:$W$5,2,0),"-") -> - | G28: 334220 | H28: =IFERROR(ROUND((G28)*F28/F29,0),0) -> 0 | I28: =G28-H28 -> 334220 | L28: =+IFERROR(VLOOKUP($E28,$P$2:$W$5,6,0),"-") -> - | M28: =+IFERROR(VLOOKUP($E28,$P$2:$W$5,7,0),"-") -> - | N28: =+IFERROR(VLOOKUP($E28,$P$2:$W$5,7,0),"-") -> -
F29: =+IFERROR(VLOOKUP($E28,$P$2:$W$5,3,0),"-") -> - | L29: =+H28-SUM(J29:K29,N29) -> 0 | M29: =IFERROR(ROUND(M28/E28*G28,0),0) -> 0 | N29: =IFERROR(ROUND(N28/F28*H28,0),0) -> 0
F30: =+IFERROR(VLOOKUP($E30,$P$2:$W$5,2,0),"-") -> - | H30: =IFERROR(ROUND((G30)*F30/F31,0),0) -> 0 | I30: =G30-H30 -> 0 | L30: =+IFERROR(VLOOKUP($E30,$P$2:$W$5,6,0),"-") -> - | M30: =+IFERROR(VLOOKUP($E30,$P$2:$W$5,7,0),"-") -> - | N30: =+IFERROR(VLOOKUP($E30,$P$2:$W$5,7,0),"-") -> -
F31: =+IFERROR(VLOOKUP($E30,$P$2:$W$5,3,0),"-") -> - | L31: =+H30-SUM(J31:K31,N31) -> 0 | M31: =IFERROR(ROUND(M30/E30*G30,0),0) -> 0 | N31: =IFERROR(ROUND(N30/F30*H30,0),0) -> 0
B32: 計 | G32: =SUM(G22:G31) -> 1155175 | H32: =+SUM(H22:H31) -> 0 | I32: =G32-H32 -> 1155175
L33: =+SUM(L23,L25,L27,L29,L31) -> 0 | M33: =+SUM(M23,M25,M27,M29,M31) -> 0 | N33: =+SUM(N23,N25,N27,N29,N31) -> 0
A34: その他特別利益 | B34: 手当等の戻入 | E34: 不課税支出に対応する不課税収入のため特定収入以外 | F34: =+IFERROR(VLOOKUP($E34,$P$2:$W$5,2,0),"-") -> - | G34: 0 | H34: =IFERROR(ROUND((G34)*F34/F35,0),0) -> 0 | I34: =G34-H34 -> 0 | L34: =+IFERROR(VLOOKUP($E34,$P$2:$W$5,6,0),"-") -> - | M34: =+IFERROR(VLOOKUP($E34,$P$2:$W$5,7,0),"-") -> - | N34: =+IFERROR(VLOOKUP($E34,$P$2:$W$5,8,0),"-") -> -
F35: =+IFERROR(VLOOKUP($E34,$P$2:$W$5,3,0),"-") -> - | L35: =+H34-SUM(J35:K35,M35:N35) -> 0 | M35: =IFERROR(ROUND(M34/$F34*$H34,0),0) -> 0 | N35: =IFERROR(ROUND(N34/$F34*$H34,0),0) -> 0
B36: 契約解除に伴う履行保証保険金 | E36: 特定収入以外 | F36: =+IFERROR(VLOOKUP($E36,$P$2:$W$5,2,0),"-") -> - | G36: 0 | H36: =IFERROR(ROUND((G36)*F36/F37,0),0) -> 0 | I36: =G36-H36 -> 0 | L36: =+IFERROR(VLOOKUP($E36,$P$2:$W$5,6,0),"-") -> - | M36: =+IFERROR(VLOOKUP($E36,$P$2:$W$5,7,0),"-") -> - | N36: =+IFERROR(VLOOKUP($E36,$P$2:$W$5,8,0),"-") -> -
F37: =+IFERROR(VLOOKUP($E36,$P$2:$W$5,3,0),"-") -> - | L37: =+H36-SUM(J37:K37,M37:N37) -> 0 | M37: =IFERROR(ROUND(M36/$F36*$H36,0),0) -> 0 | N37: =IFERROR(ROUND(N36/$F36*$H36,0),0) -> 0
B38: 契約解除違約金 | E38: 特定収入以外 | F38: =+IFERROR(VLOOKUP($E38,$P$2:$W$5,2,0),"-") -> - | G38: 0 | H38: =IFERROR(ROUND((G38)*F38/F39,0),0) -> 0 | I38: =G38-H38 -> 0 | L38: =+IFERROR(VLOOKUP($E38,$P$2:$W$5,6,0),"-") -> - | M38: =+IFERROR(VLOOKUP($E38,$P$2:$W$5,7,0),"-") -> - | N38: =+IFERROR(VLOOKUP($E38,$P$2:$W$5,8,0),"-") -> -
F39: =+IFERROR(VLOOKUP($E38,$P$2:$W$5,3,0),"-") -> - | L39: =+H38-SUM(J39:K39,M39:N39) -> 0 | M39: =IFERROR(ROUND(M38/$F38*$H38,0),0) -> 0 | N39: =IFERROR(ROUND(N38/$F38*$H38,0),0) -> 0
B40: 償却資産の所管替えに伴う除却損相当額 | E40: 特定収入以外 | G40: 864807 | H40: =IFERROR(ROUND((G40)*F40/F41,0),0) -> 0 | I40: =G40-H40 -> 864807 | L40: =+IFERROR(VLOOKUP($E40,$P$2:$W$5,6,0),"-") -> - | M40: =+IFERROR(VLOOKUP($E40,$P$2:$W$5,7,0),"-") -> - | N40: =+IFERROR(VLOOKUP($E40,$P$2:$W$5,8,0),"-") -> -
L41: =+H40-SUM(J41:K41,M41:N41) -> 0 | M41: =IFERROR(ROUND(M40/$F40*$H40,0),0) -> 0 | N41: =IFERROR(ROUND(N40/$F40*$H40,0),0) -> 0
...

Sheet 3条災害補助
A1: =+"令和"&MID(総括表!A2,3,1)&"年度決算 不課税収入区分表（国庫補助金〔３条〕）" -> 令和５年度決算 不課税収入区分表（国庫補助金〔３条〕）
I3: (単位：円)
A4: 区分 | D4: 対象経費 | E4: 按分方法 | F4: 課税支出額 | G4: 不課税収入額 | H4: 特定収入 | I4: 特定収入 以外 | J4: 特定収入内訳（上段：課税支出額、下段特定収入の按分）
F5: 支出額合計 | J5: 0.03 | K5: 0.05 | L5: 0.08 | M5: 0.08 | N5: 0.1
A6: その他国庫補助金 | G6: =SUM(G8,G22,G36,G50) -> 0 | H6: =SUM(H8,H22,H36,H50) -> 0 | I6: =SUM(I8,I22,I36,I50) -> 0 | J6: =SUM(J9,J23,J37,J51) -> 0 | K6: =SUM(K9,K23,K37,K51) -> 0 | L6: =SUM(L9,L23,L37,L51) -> 0 | M6: =SUM(M9,M23,M37,M51) -> 0 | N6: =SUM(N9,N23,N37,N51) -> 0
B8: その他国庫補助金(公共） | G8: =SUM(G10:G21) -> 0 | H8: =SUM(H10:H21) -> 0 | I8: =SUM(I10:I21) -> 0
L9: =+L13+L19 -> 0 | M9: =+M13+M19 -> 0 | N9: =+N13+N19 -> 0
B10: 公共下水道事業 | C10: 公共土木施設災害 復旧事業費国庫負担金 | D10: 対象事業費×２／３ | E10: 3年度分 公共土木施設災害復旧事業費(補助事業現年分)の課税支出割合 | G10: 0
F12: =+SUM('[1]3条支出'!$K$88:$K$90) -> 0 | H12: =IFERROR(ROUND(SUM(G10:G15)*F12/F13,0),0) -> 0 | I12: =SUM(G10:G15)-H12 -> 0 | L12: =SUM('[1]3条支出'!$F$88:$G$90)+SUM('[1]3条支出'!H88:H90) -> 0 | M12: =SUM('[1]3条支出'!I88:I90) -> 0 | N12: =SUM('[1]3条支出'!J88:J90) -> 0
F13: =+SUM('[1]3条支出'!$E$88:$E$90) -> 0 | L13: =+H12-SUM(J13:K13,M13:N13) -> 0 | M13: =IFERROR(ROUND(M12/F12*H12,0),0) -> 0 | N13: =IFERROR(ROUND(N12/F12*H12,0),0) -> 0
C16: 公共土木施設災害 復旧事業費国庫負担金 | D16: 対象事業費×２／３ | E16: 2年度分 公共土木施設災害復旧事業費(補助事業繰越分)の課税支出割合
F18: =+SUM('[1]3条支出'!$K$101:$K$103) -> 0 | H18: =IFERROR(ROUND(SUM(G16:G21)*F18/F19,0),0) -> 0 | I18: =SUM(G16:G21)-H18 -> 0 | L18: =SUM('[1]3条支出'!$F$101:$G$103)+SUM('[1]3条支出'!H101:H103) -> 0 | M18: =SUM('[1]3条支出'!I101:I103) -> 0 | N18: =SUM('[1]3条支出'!J101:J103) -> 0
F19: =+SUM('[1]3条支出'!$E$101:$E$103) -> 0 | L19: =+H18-SUM(J19:K19,M19:N19) -> 0 | M19: =IFERROR(ROUND(M18/F18*H18,0),0) -> 0 | N19: =IFERROR(ROUND(N18/F18*H18,0),0) -> 0
B22: その他国庫補助金(特環） | G22: =SUM(G24:G35) -> 0 | H22: =SUM(H24:H35) -> 0 | I22: =SUM(I24:I35) -> 0
L23: =+L27+L33 -> 0 | M23: =+M27+M33 -> 0 | N23: =+N27+N33 -> 0
B24: 特定環境保全公共下水道 | C24: 公共土木施設災害 復旧事業費国庫負担金 | D24: 対象事業費×２／３ | E24: =+E10 -> 3年度分 公共土木施設災害復旧事業費(補助事業現年分)の課税支出割合 | G24: 0
F26: =+'[1]3条支出'!$K$91 -> 0 | H26: =IFERROR(ROUND(SUM(G24:G29)*F26/F27,0),0) -> 0 | I26: =SUM(G24:G29)-H26 -> 0 | L26: =SUM('[1]3条支出'!$F$91:$G$91)+SUM('[1]3条支出'!H91) -> 0 | M26: =SUM('[1]3条支出'!I91) -> 0 | N26: =SUM('[1]3条支出'!J91) -> 0
F27: =+'[1]3条支出'!$E$91 -> 0 | L27: =+H26-SUM(J27:K27,M27:N27) -> 0 | M27: =IFERROR(ROUND(M26/F26*H26,0),0) -> 0 | N27: =IFERROR(ROUND(N26/F26*H26,0),0) -> 0
C30: 公共土木施設災害 復旧事業費国庫負担金 | D30: 対象事業費×２／３ | E30: =+E16 -> 2年度分 公共土木施設災害復旧事業費(補助事業繰越分)の課税支出割合
F32: =+'[1]3条支出'!$K$104 -> 0 | H32: =IFERROR(ROUND(SUM(G30:G35)*F32/F33,0),0) -> 0 | I32: =SUM(G30:G35)-H32 -> 0 | L32: =SUM('[1]3条支出'!$F$104:$G$104)+SUM('[1]3条支出'!H104) -> 0 | M32: =SUM('[1]3条支出'!I104) -> 0 | N32: =SUM('[1]3条支出'!J104) -> 0
F33: =+'[1]3条支出'!$E$104 -> 0 | L33: =+H32-SUM(J33:K33,M33:N33) -> 0 | M33: =IFERROR(ROUND(M32/F32*H32,0),0) -> 0 | N33: =IFERROR(ROUND(N32/F32*H32,0),0) -> 0
B36: その他国庫補助金(農集） | G36: =SUM(G38:G49) -> 0 | H36: =SUM(H38:H49) -> 0 | I36: =SUM(I38:I49) -> 0
L37: =+L41+L47 -> 0 | M37: =+M41+M47 -> 0 | N37: =+N41+N47 -> 0
B38: 農業集落排水事業 | C38: 災害関連農村生活環境 施設復旧事業国庫補助金 | E38: 3年度分 災害関連農村生活環境施設復旧事業(補助事業現年分)の課税支出割合
F40: =+'[1]3条支出'!$K$92 -> 0 | H40: =IFERROR(ROUND(SUM(G38:G43)*F40/F41,0),0) -> 0 | I40: =SUM(G38:G43)-H40 -> 0 | L40: =SUM('[1]3条支出'!$F$92:$G$92)+SUM('[1]3条支出'!H92) -> 0 | M40: =SUM('[1]3条支出'!I92) -> 0 | N40: =SUM('[1]3条支出'!J92) -> 0
F41: =+'[1]3条支出'!$E$92 -> 0 | L41: =+H40-SUM(J41:K41,M41:N41) -> 0 | M41: =IFERROR(ROUND(M40/F40*H40,0),0) -> 0 | N41: =IFERROR(ROUND(N40/F40*H40,0),0) -> 0
C44: 災害関連農村生活環境 施設復旧事業国庫補助金 | D44: 対象事業費×１／２ | E44: 2年度分 災害関連農村生活環境施設復旧事業(補助事業繰越分)の課税支出割合
F46: =+'[1]3条支出'!$K$105 -> 0 | H46: =IFERROR(ROUND(SUM(G44:G49)*F46/F47,0),0) -> 0 | I46: =SUM(G44:G49)-H46 -> 0 | L46: =SUM('[1]3条支出'!$F$105:$G$105)+SUM('[1]3条支出'!H105) -> 0 | M46: =SUM('[1]3条支出'!I105) -> 0 | N46: =SUM('[1]3条支出'!J105) -> 0
F47: =+'[1]3条支出'!$E$105 -> 0 | L47: =+H46-SUM(J47:K47,M47:N47) -> 0 | M47: =IFERROR(ROUND(M46/F46*H46,0),0) -> 0 | N47: =IFERROR(ROUND(N46/F46*H46,0),0) -> 0
B50: その他国庫補助金(浄化槽） | G50: =SUM(G52:G63) -> 0 | H50: =SUM(H52:H63) -> 0 | I50: =SUM(I52:I63) -> 0
L51: =+L55+L61 -> 0 | M51: =+M55+M61 -> 0 | N51: =+N55+N61 -> 0
B52: 市営浄化槽事業
F54: =+'[1]3条支出'!$K$93 -> 0 | H54: =IFERROR(ROUND(SUM(G52:G57)*F54/F55,0),0) -> 0 | I54: =SUM(G52:G57)-H54 -> 0 | L54: =SUM('[1]3条支出'!$F$93:$G$93)+SUM('[1]3条支出'!H93) -> 0 | M54: =SUM('[1]3条支出'!I93) -> 0 | N54: =SUM('[1]3条支出'!J93) -> 0
F55: =+'[1]3条支出'!$E$93 -> 0 | L55: =+H54-SUM(J55:K55,M55:N55) -> 0 | M55: =IFERROR(ROUND(M54/F54*H54,0),0) -> 0 | N55: =IFERROR(ROUND(N54/F54*H54,0),0) -> 0
F60: =+'[1]3条支出'!$K$106 -> 0 | H60: =IFERROR(ROUND(SUM(G58:G63)*F60/F61,0),0) -> 0 | I60: =SUM(G58:G63)-H60 -> 0 | L60: =SUM('[1]3条支出'!$F$106:$G$106)+SUM('[1]3条支出'!H106) -> 0 | M60: =SUM('[1]3条支出'!I106) -> 0 | N60: =SUM('[1]3条支出'!J106) -> 0
F61: =+'[1]3条支出'!$E$106 -> 0 | L61: =+H60-SUM(J61:K61,M61:N61) -> 0 | M61: =IFERROR(ROUND(M60/F60*H60,0),0) -> 0 | N61: =IFERROR(ROUND(N60/F60*H60,0),0) -> 0
F64: 3条収入シート その他国庫補助金（災害） | G64: =+'[2]3条収入'!$E$34 -> 0
F65: チェック | G65: =+G6-G64 -> 0

Sheet 4条補助（公）
A1: =+"令和"&MID(総括表!A2,3,1)&"年度決算 不課税収入区分表(公共下水道整備国庫補助金)" -> 令和５年度決算 不課税収入区分表(公共下水道整備国庫補助金)
I3: (単位：円)
A4: 区分 | D4: 対象経費 | E4: 按分方法 | F4: 課税支出額 | G4: 不課税収入額 | H4: 特定収入 | I4: 特定収入 以外 | J4: 特定収入内訳（上段：課税支出額、下段特定収入の按分） | P4: 特定収入に係る課税仕入れ等に係る消費税額
F5: 支出額合計 | J5: 0.03 | K5: 0.05 | L5: 0.08 | M5: 0.08 | N5: 0.1 | P5: 0.05 | Q5: 0.08 | R5: 0.08 | S5: 0.1 | T5: 計 | U5: ④４条収入とのチェック
A6: 国庫補助金 | G6: =SUM(G8:G43) -> 5683800000 | H6: =H19+H37 -> 5678297006 | I6: =I19+I37 -> 5502994 | J6: =+J20+J38 -> 0 | K6: =+K20+K38 -> 0 | L6: =+L20+L38 -> 0 | M6: =+M20+M38 -> 0 | N6: =+N20+N38 -> 5678297006 | P6: =+P20+P38 -> 0 | Q6: =+Q20+Q38 -> 0 | R6: =+R20+R38 -> 0 | S6: =+S20+S38 -> 516208819 | T6: =+T20+T38 -> 516208819 | U6: =+T6-'[4]4条収入'!$AH$25 -> 0
B8: 公 共 下 水 道 | C8: 管路等・一般 | D8: 4,762,313.150千円×５／１０ | E8: 5年度分 公共下水道整備事業 (補助事業現年分)の 課税支出割合 | G8: =4762313.15*1000*5/10+60735.85*1000*5/10+1500 -> 2411526000
C10: 管路等・補助裏単市 | D10: 60,375.850千円×５／１０
C12: 管路等・工事国債
C14: 管路等・特債
C16: 管路等・都市水
C18: 管路等・促進・工事国債
F19: 5036234000 | H19: =IFERROR(ROUND(SUM(G8:G31)*F19/F20,0),0) -> 2527700000 | I19: =SUM(G8:G31)-H19 -> 0 | L19: 0 | N19: =F19-SUM(L19:M19) -> 5036234000
C20: 処理場・一般・高率 | D20: 191,660千円×５．５／１０ | F20: 5036234000 | G20: =191660*1000*5.5/10 -> 105413000 | L20: =+H19-SUM(J20:K20,M20:N20) -> 0 | M20: =IFERROR(ROUND(M19/F19*H19,0),0) -> 0 | N20: =IFERROR(ROUND(N19/F19*H19,0),0) -> 2527700000 | P20: =+ROUND(K20*P$5/(1+P$5),0) -> 0 | Q20: =+ROUND(L20*Q$5/(1+Q$5),0) -> 0 | R20: =+ROUND(M20*R$5/(1+R$5),0) -> 0 | S20: =+ROUND(N20*S$5/(1+S$5),0) -> 229790909 | T20: =SUM(P20:S20) -> 229790909
C22: 処理場・一般・低率 | D22: 21,525千円×５／１０ | G22: =21525*1000*5/10-1500 -> 10761000
C24: 処理場・用地国債
C26: 処理場・特債・高率
C28: 処理場・特債・低率
C30: 過年度補助金
C32: 管路等・一般(繰越分) | D32: 4,286,012.1千円×５／１０ | E32: 4年度分 公共下水道整備事業 (補助事業繰越分)の 課税支出割合 | G32: =(3089012.1+103800+1197000)*1000*5/10+13187900*5/10 -> 2201500000
C34: 管路等・補助裏単市 （繰越分） | D34: 13,187.9千円×５／１０
C36: 管路等・一般(高率分)
F37: 6172219286 | H37: =IFERROR(ROUND(SUM(G32:G43)*F37/F38,0),0) -> 3150597006 | I37: =SUM(G32:G43)-H37 -> 5502994 | L37: 0 | M37: 0 | N37: =F37-SUM(L37:M37) -> 6172219286
C38: 処理場・一般・高率 (繰越分) | D38: 1,292,000千円×５．５／１０ | F38: 6183000000 | G38: =(1142500+149500)*1000*5.5/10 -> 710600000 | L38: =+H37-SUM(J38:K38,M38:N38) -> 0 | M38: =IFERROR(ROUND(M37/F37*H37,0),0) -> 0 | N38: =IFERROR(ROUND(N37/F37*H37,0),0) -> 3150597006 | P38: =+ROUND(K38*P$5/(1+P$5),0) -> 0 | Q38: =+ROUND(L38*Q$5/(1+Q$5),0) -> 0 | R38: =+ROUND(M38*R$5/(1+R$5),0) -> 0 | S38: =+ROUND(N38*S$5/(1+S$5),0) -> 286417910 | T38: =SUM(P38:S38) -> 286417910
C40: 処理場・一般・低率 (繰越分) | D40: 488,000千円×５／１０ | G40: =488000000*5/10 -> 244000000
C42: 処理場・特債・高率 (繰越分)

Sheet 4条補助（特）
A1: =+"令和"&MID(総括表!A2,3,1)&"年度決算 不課税収入区分表(汚水処理施設整備交付金)（特環）" -> 令和５年度決算 不課税収入区分表(汚水処理施設整備交付金)（特環）
I3: (単位：円)
A4: 区分 | D4: 対象経費 | E4: 按分方法 | F4: 課税支出額 | G4: 不課税収入額 | H4: 特定収入 | I4: 特定収入 以外 | J4: 特定収入内訳（上段：課税支出額、下段特定収入の按分） | P4: 特定収入に係る課税仕入れ等に係る消費税額
F5: 支出額合計 | J5: 0.03 | K5: 0.05 | L5: 0.08 | M5: 0.08 | N5: 0.1 | P5: 0.05 | Q5: 0.08 | R5: 0.08 | S5: 0.1 | T5: 計 | U5: ④４条収入とのチェック
A6: 国庫補助金 | G6: =SUM(G8:G43) -> 30500000 | H6: =H19+H37 -> 30500000 | I6: =I19+I37 -> 0 | J6: =+J20+J38 -> 0 | K6: =+K20+K38 -> 0 | L6: =+L20+L38 -> 0 | M6: =+M20+M38 -> 0 | N6: =+N20+N38 -> 30500000 | P6: =+P20+P38 -> 0 | Q6: =+Q20+Q38 -> 0 | R6: =+R20+R38 -> 0 | S6: =+S20+S38 -> 2772727 | T6: =+T20+T38 -> 2772727 | U6: =+T6-'[4]4条収入'!$AH$32 -> 0
B8: 特 定 環 境 保 全 公 共 下 水 道 | C8: 管路等・一般 | D8: 25,200千円×５／１０ | E8: 5年度分 特定環境保全公共下水道整備事業 (補助事業現年分)の 課税支出割合 | G8: =659000+11941000 -> 12600000
C10: 管路等・一般
C12: 管路等・用地国債
C14: 管路等・特債
C16: 管路等・都市水
C18: 管路等・促進・工事国債
F19: 25200000 | H19: =IFERROR(ROUND(SUM(G8:G21)*F19/F20,0),0) -> 12600000 | I19: =SUM(G8:G31)-H19 -> 0 | L19: 0 | M19: 0 | N19: =F19-SUM(L19:M19) -> 25200000
C20: 処理場・一般 | F20: 25200000 | L20: =+H19-SUM(J20:K20,M20:N20) -> 0 | M20: =IFERROR(ROUND(M19/F19*H19,0),0) -> 0 | N20: =IFERROR(ROUND(N19/F19*H19,0),0) -> 12600000 | P20: =+ROUND(K20*P$5/(1+P$5),0) -> 0 | Q20: =+ROUND(L20*Q$5/(1+Q$5),0) -> 0 | R20: =+ROUND(M20*R$5/(1+R$5),0) -> 0 | S20: =+ROUND(N20*S$5/(1+S$5),0)-1 -> 1145454 | T20: =SUM(P20:S20) -> 1145454
C22: 処理場・一般
C24: 処理場・用地国債
C26: 処理場・特債・高率
C28: 処理場・特債・低率
C30: 過年度補助金
C32: 管路等・一般(繰越分) | D32: 5,000千円×５／１０ | E32: 4年度分 特定環境保全公共下水道整備事業 (補助事業繰越分)の 課税支出割合 | G32: 2500000
C34: 管路等・都市水
C36: 管路等・特債(繰越分）
F37: 33015490 | H37: =IFERROR(ROUND(SUM(G32:G39)*F37/F38,0),0) -> 17900000 | I37: =SUM(G32:G43)-H37 -> 0 | L37: 0 | M37: 0 | N37: =F37-SUM(L37:M37) -> 33015490
C38: 処理場・一般・高率 (繰越分) | D38: 28,000千円×５．５／１０ | F38: 33015490 | G38: 15400000 | L38: =+H37-SUM(J38:K38,M38:N38) -> 0 | M38: =IFERROR(ROUND(M37/F37*H37,0),0) -> 0 | N38: =IFERROR(ROUND(N37/F37*H37,0),0) -> 17900000 | P38: =+ROUND(K38*P$5/(1+P$5),0) -> 0 | Q38: =+ROUND(L38*Q$5/(1+Q$5),0) -> 0 | R38: =+ROUND(M38*R$5/(1+R$5),0) -> 0 | S38: =+ROUND(N38*S$5/(1+S$5),0) -> 1627273 | T38: =SUM(P38:S38) -> 1627273
C40: 処理場・一般・低率 (繰越分)
C42: 処理場・特債・高率 (繰越分)

Sheet 4条補助（農）
A1: =+"令和"&MID(総括表!A2,3,1)&"年度決算 不課税収入区分表(汚水処理施設整備交付金)（農集）" -> 令和５年度決算 不課税収入区分表(汚水処理施設整備交付金)（農集）
I3: (単位：円)
A4: 区分 | D4: 対象経費 | E4: 按分方法 | F4: 課税支出額 | G4: 不課税収入額 | H4: 特定収入 | I4: 特定収入 以外 | J4: 特定収入内訳（上段：課税支出額、下段特定収入の按分） | P4: 特定収入に係る課税仕入れ等に係る消費税額
F5: 支出額合計 | J5: 0.03 | K5: 0.05 | L5: 0.08 | M5: 0.08 | N5: 0.1 | P5: 0.05 | Q5: 0.08 | R5: 0.08 | S5: 0.1 | T5: 計 | U5: ④４条収入とのチェック
A6: 国庫補助金 | G6: =SUM(G8:G43) -> 0 | H6: =H19+H37 -> 0 | I6: =I19+I37 -> 0 | J6: =+J20+J38 -> 0 | K6: =+K20+K38 -> 0 | L6: =+L20+L38 -> 0 | M6: =+M20+M38 -> 0 | N6: =+N20+N38 -> 0 | P6: =+P20+P38 -> 0 | Q6: =+Q20+Q38 -> 0 | R6: =+R20+R38 -> 0 | S6: =+S20+S38 -> 0 | T6: =+T20+T38 -> 0 | U6: =+T6-'[4]4条収入'!$AH$33 -> 0
B8: 農 業 集 落 排 水 | C8: 管路等・一般 | E8: 5年度分 農業集落排水事業 (補助事業現年分)の 課税支出割合
C10: 管路等・一般 | D10: ●千円×１０／１０
C12: 管路等・用地国債
C14: 管路等・特債
C16: 管路等・都市水
C18: 管路等・促進・工事国債
H19: =IFERROR(ROUND(SUM(G8:G21)*F19/F20,0),0) -> 0 | I19: =SUM(G8:G31)-H19 -> 0 | L19: 0 | M19: 0 | N19: =F19-SUM(L19:M19) -> 0
C20: 処理場・一般 | L20: =+H19-SUM(J20:K20,M20:N20) -> 0 | M20: =IFERROR(ROUND(M19/F19*H19,0),0) -> 0 | N20: =IFERROR(ROUND(N19/F19*H19,0),0) -> 0 | P20: =+ROUND(K20*P$5/(1+P$5),0) -> 0 | Q20: =+ROUND(L20*Q$5/(1+Q$5),0) -> 0 | R20: =+ROUND(M20*R$5/(1+R$5),0) -> 0 | S20: =+ROUND(N20*S$5/(1+S$5),0) -> 0 | T20: =SUM(P20:S20) -> 0
C22: 処理場・一般
C24: 処理場・用地国債
C26: 処理場・特債・高率
C28: 処理場・特債・低率
C30: 過年度補助金
C32: 管路等・一般(繰越分) | D32: 75,000千円×５／１０ | E32: 4年度分 農業集落排水事業 (補助事業繰越分)の 課税支出割合
C34: 管路等高率
C36: 管路等・特債(繰越分）
H37: =IFERROR(ROUND(SUM(G32:G39)*F37/F38,0),0) -> 0 | I37: =SUM(G32:G43)-H37 -> 0 | L37: 0 | M37: 0 | N37: =F37-SUM(L37:M37) -> 0
C38: 処理場・一般 (繰越分) | L38: =+H37-SUM(J38:K38,M38:N38) -> 0 | M38: =IFERROR(ROUND(M37/F37*H37,0),0) -> 0 | N38: =IFERROR(ROUND(N37/F37*H37,0),0) -> 0 | P38: =+ROUND(K38*P$5/(1+P$5),0) -> 0 | Q38: =+ROUND(L38*Q$5/(1+Q$5),0) -> 0 | R38: =+ROUND(M38*R$5/(1+R$5),0) -> 0 | S38: =+ROUND(N38*S$5/(1+S$5),0) -> 0 | T38: =SUM(P38:S38) -> 0
C40: 処理場・一般 (繰越分) | D40: ●千円×５／１０
C42: 処理場・特債・高率 (繰越分)

Sheet 4条補助（浄）
A1: =+"令和"&MID(総括表!A2,3,1)&"年度決算 不課税収入区分表(汚水処理施設整備交付金)（浄化槽）" -> 令和５年度決算 不課税収入区分表(汚水処理施設整備交付金)（浄化槽）
I3: (単位：円)
A4: 区分 | D4: 対象経費 | E4: 按分方法 | F4: 課税支出額 | G4: 不課税収入額 | H4: 特定収入 | I4: 特定収入 以外 | J4: 特定収入内訳（上段：課税支出額、下段特定収入の按分） | P4: 特定収入に係る課税仕入れ等に係る消費税額
F5: 支出額合計 | J5: 0.03 | K5: 0.05 | L5: 0.08 | M5: 0.08 | N5: 0.1 | P5: 0.05 | Q5: 0.08 | R5: 0.08 | S5: 0.1 | T5: 計 | U5: ④４条収入とのチェック
A6: 国庫補助金 | G6: =SUM(G8:G43) -> 3488000 | H6: =H19+H37 -> 3488000 | I6: =I19+I37 -> 0 | J6: =+J20+J38 -> 0 | K6: =+K20+K38 -> 0 | L6: =+L20+L38 -> 0 | M6: =+M20+M38 -> 0 | N6: =+N20+N38 -> 3488000 | P6: =+P20+P38 -> 0 | Q6: =+Q20+Q38 -> 0 | R6: =+R20+R38 -> 0 | S6: =+S20+S38 -> 317091 | T6: =+T20+T38 -> 317091 | U6: =+T6-'[4]4条収入'!$AH$34 -> 0
B8: 市 営 浄 化 槽 | C8: 浄化槽 | D8: 12,726.2千円×１／３ | E8: 5年度分 市営浄化槽事業 (補助事業現年分)の 課税支出割合 | G8: 3488000
F19: 12760200 | H19: =IFERROR(ROUND(SUM(G8:G21)*F19/F20,0),0) -> 3488000 | I19: =SUM(G8:G31)-H19 -> 0 | L19: 0 | M19: 0 | N19: =F19-SUM(L19:M19) -> 12760200
F20: 12760200 | L20: =+H19-SUM(J20:K20,M20:N20) -> 0 | M20: =IFERROR(ROUND(M19/F19*H19,0),0) -> 0 | N20: =IFERROR(ROUND(N19/F19*H19,0),0) -> 3488000 | P20: =+ROUND(K20*P$5/(1+P$5),0) -> 0 | Q20: =+ROUND(L20*Q$5/(1+Q$5),0) -> 0 | R20: =+ROUND(M20*R$5/(1+R$5),0) -> 0 | S20: =+ROUND(N20*S$5/(1+S$5),0) -> 317091 | T20: =SUM(P20:S20) -> 317091
C32: 浄化槽 | D32: R4→R5 繰越なし | E32: 4年度分 市営浄化槽事業 (補助事業繰越分)の 課税支出割合 | G32: 0
F37: 0 | H37: =IFERROR(ROUND(SUM(G32:G39)*F37/F38,0),0) -> 0 | I37: =SUM(G32:G43)-H37 -> 0 | L37: =+F37-SUM(J37:K37,M37:N37) -> 0
F38: 0 | L38: =+H37-SUM(J38:K38,M38:N38) -> 0 | M38: =IFERROR(ROUND(M37/F37*H37,0),0) -> 0 | N38: =IFERROR(ROUND(N37/F37*H37,0),0) -> 0 | P38: =+ROUND(K38*P$5/(1+P$5),0) -> 0 | Q38: =+ROUND(L38*Q$5/(1+Q$5),0) -> 0 | R38: =+ROUND(M38*R$5/(1+R$5),0) -> 0 | S38: =+ROUND(N38*S$5/(1+S$5),0) -> 0 | T38: =SUM(P38:S38) -> 0

Sheet 受益（公）
A1: =+"令和"&MID(総括表!A2,3,1)&"年度決算 不課税収入区分表(受益者負担金)" -> 令和５年度決算 不課税収入区分表(受益者負担金)
I3: (単位：円)
A4: 区分 | D4: 対象経費 | E4: 按分方法 | F4: 課税支出額 | G4: 不課税収入額 | H4: 特定収入 | I4: 特定収入 以外 | J4: 特定収入内訳（上段：課税支出額、下段特定収入の按分） | P4: 特定収入に係る課税仕入れ等に係る消費税額
F5: 支出額合計 | J5: 0.03 | K5: 0.05 | L5: 0.08 | M5: 0.08 | N5: 0.1 | P5: 0.05 | Q5: 0.08 | R5: 0.08 | S5: 0.1 | T5: 計 | U5: ④４条収入とのチェック
A6: 受益者負担金 | G6: =G10+G8 -> 8799605 | H6: =H10+H8 -> 8525089 | I6: =I10+I8 -> 274516 | K6: =K9+K11 -> 0 | L6: =L9+L11 -> 338 | M6: =M9+M11 -> 99 | N6: =N9+N11 -> 8524652 | P6: =P9+P11 -> 0 | Q6: =Q9+Q11 -> 25 | R6: =R9+R11 -> 7 | S6: =S9+S11 -> 774968 | T6: =T9+T11 -> 775000 | U6: =+T6-'[4]4条収入'!$AH$44 -> 0
B8: 公共下水道 補助事業充当分 | E8: 5年度分補助事業 の課税支出割合 （現年） | F8: ='4条補助（公）'!F19 -> 5036234000 | G8: =E15 -> 5005000 | H8: =IFERROR(ROUND(F8/F9*G8,0),0) -> 5005000 | I8: =G8-H8 -> 0 | L8: ='4条補助（公）'!K19+'4条補助（公）'!L19 -> 0 | M8: ='4条補助（公）'!M19 -> 0 | N8: ='4条補助（公）'!N19 -> 5036234000
F9: =D15 -> 5036234000 | L9: =+H8-SUM(J9:K9,M9:N9) -> 0 | M9: =IFERROR(ROUND(M8/F8*H8,0),0) -> 0 | N9: =IFERROR(ROUND(N8/F8*H8,0),0) -> 5005000 | P9: =+ROUND(K9*P$5/(1+P$5),0) -> 0 | Q9: =+ROUND(L9*Q$5/(1+Q$5),0) -> 0 | R9: =+ROUND(M9*R$5/(1+R$5),0) -> 0 | S9: =+ROUND(N9*S$5/(1+S$5),0) -> 455000 | T9: =SUM(P9:S9) -> 455000
B10: 公共下水道 起債事業充当分 | E10: 5年度分起債事業 の課税支出割合 （現年） | F10: 1308137124 | G10: =E16 -> 3794605 | H10: =IFERROR(ROUND(F10/F11*G10,0),0) -> 3520089 | I10: =G10-H10 -> 274516 | L10: 125712 | M10: 36840 | N10: =F10-SUM(L10:M10) -> 1307974572
F11: =D16 -> 1410153000 | L11: =+H10-SUM(J11:K11,M11:N11) -> 338 | M11: =IFERROR(ROUND(M10/F10*H10,0),0) -> 99 | N11: =IFERROR(ROUND(N10/F10*H10,0),0) -> 3519652 | P11: =+ROUND(K11*P$5/(1+P$5),0) -> 0 | Q11: =+ROUND(L11*Q$5/(1+Q$5),0) -> 25 | R11: =+ROUND(M11*R$5/(1+R$5),0) -> 7 | S11: =+ROUND(N11*S$5/(1+S$5),0) -> 319968 | T11: =SUM(P11:S11) -> 320000
C14: 区分 | D14: 支出額 | E14: 受益者負担金の事業別金額
C15: 補助事業分(現年) | D15: ='4条補助（公）'!F20 -> 5036234000 | E15: 5005000
C16: 起債事業分(現年) | D16: 1410153000 | E16: =3390885+403720 -> 3794605
C17: 計 | D17: =D15+D16 -> 6446387000 | E17: =E15+E16 -> 8799605
E18: =E17-E15-E16 -> 0

Sheet 受益（区域外）
A1: =+"令和"&MID(総括表!A2,3,1)&"年度決算 不課税収入区分表(受益者分担金)（汚水処理施設整備）全体" -> 令和５年度決算 不課税収入区分表(受益者分担金)（汚水処理施設整備）全体
I3: (単位：円)
A4: 区分 | D4: 対象経費 | E4: 按分方法 | F4: 課税支出額 | G4: 不課税収入額 | H4: 特定収入 | I4: 特定収入 以外 | J4: 特定収入内訳（上段：課税支出額、下段特定収入の按分） | P4: 特定収入に係る課税仕入れ等に係る消費税額
F5: 支出額合計 | J5: 0.03 | K5: 0.05 | L5: 0.08 | M5: 0.08 | N5: 0.1 | P5: 0.05 | Q5: 0.08 | R5: 0.08 | S5: 0.1 | T5: 計 | U5: ④４条収入とのチェック
A6: 受益者分担金 | G6: =G10+G8 -> 35218280 | H6: =H10+H8 -> 33459431 | I6: =I10+I8 -> 1758849 | J6: =SUM(J26,J46,J66) -> 0 | K6: =SUM(K26,K46,K66) -> 0 | L6: =SUM(L26,L46,L66) -> 0 | M6: =SUM(M26,M46,M66) -> 0 | N6: =SUM(N26,N46,N66) -> 33459431 | P6: =SUM(P26,P46,P66) -> 0 | Q6: =SUM(Q26,Q46,Q66) -> 0 | R6: =SUM(R26,R46,R66) -> 0 | S6: =SUM(S26,S46,S66) -> 3041767 | T6: =SUM(T26,T46,T66) -> 3041767 | U6: =+T6-'[4]4条収入'!$AH$46 -> 0
B8: 汚水処理施設整備 補助事業充当分 | E8: 5年度分補助事業 の課税支出割合 （現年） | F8: =SUM(F28,F48,F68) -> 37960200 | G8: =SUM(G28,G48,G68) -> 1842000 | H8: =SUM(H28,H48,H68) -> 1842000 | I8: =G8-H8 -> 0 | J8: =SUM(J28,J48,J68) -> 0 | K8: =SUM(K28,K48,K68) -> 0 | L8: =SUM(L28,L48,L68) -> 0 | M8: =SUM(M28,M48,M68) -> 0 | N8: =SUM(N28,N48,N68) -> 37960200
F9: =D15 -> 37960200 | J9: =SUM(J29,J49,J69) -> 0 | K9: =SUM(K29,K49,K69) -> 0 | L9: =SUM(L29,L49,L69) -> 0 | M9: =SUM(M29,M49,M69) -> 0 | N9: =SUM(N29,N49,N69) -> 1842000 | P9: =SUM(P29,P49,P69) -> 0 | Q9: =SUM(Q29,Q49,Q69) -> 0 | R9: =SUM(R29,R49,R69) -> 0 | S9: =SUM(S29,S49,S69) -> 167455 | T9: =SUM(T29,T49,T69) -> 167455
B10: 汚水処理施設整備 起債事業充当分 | E10: 5年度分起債事業 の課税支出割合 （現年） | F10: =SUM(F30,F50,F70) -> 222348632 | G10: =SUM(G30,G50,G70) -> 33376280 | H10: =SUM(H30,H50,H70) -> 31617431 | I10: =G10-H10 -> 1758849 | J10: =SUM(J30,J50,J70) -> 0 | K10: =SUM(K30,K50,K70) -> 0 | L10: =SUM(L30,L50,L70) -> 0 | M10: =SUM(M30,M50,M70) -> 0 | N10: =SUM(N30,N50,N70) -> 222348632
F11: =D16 -> 235300000 | J11: =SUM(J31,J51,J71) -> 0 | K11: =SUM(K31,K51,K71) -> 0 | L11: =SUM(L31,L51,L71) -> 0 | M11: =SUM(M31,M51,M71) -> 0 | N11: =SUM(N31,N51,N71) -> 31617431 | P11: =SUM(P31,P51,P71) -> 0 | Q11: =SUM(Q31,Q51,Q71) -> 0 | R11: =SUM(R31,R51,R71) -> 0 | S11: =SUM(S31,S51,S71) -> 2874312 | T11: =SUM(T31,T51,T71) -> 2874312
C14: 区分 | D14: 支出額 | E14: 受益者分担金の事業別金額
C15: 補助事業分(現年) | D15: =SUM(D35,D55,D75) -> 37960200 | E15: =SUM(E35,E55,E75) -> 1842000
C16: 起債事業分(現年) | D16: =SUM(D36,D56,D76) -> 235300000 | E16: =SUM(E36,E56,E76) -> 33376280
C17: 計 | D17: =D15+D16 -> 273260200 | E17: =E15+E16 -> 35218280
E18: =E17-E15-E16 -> 0
A21: =+"令和"&MID(総括表!A2,3,2)&"年度決算 不課税収入区分表(受益者分担金)（汚水処理施設整備）特環" -> 令和５年年度決算 不課税収入区分表(受益者分担金)（汚水処理施設整備）特環
I23: (単位：円)
A24: 区分 | D24: 対象経費 | E24: 按分方法 | F24: 課税支出額 | G24: 不課税収入額 | H24: 特定収入 | I24: 特定収入 以外
F25: 支出額合計
A26: 受益者分担金 | G26: =G30+G28 -> 17022400 | H26: =H30+H28 -> 15741150 | I26: =I30+I28 -> 1281250 | L26: =L29+L31 -> 0 | M26: =M29+M31 -> 0 | N26: =N29+N31 -> 15741150 | P26: =P29+P31 -> 0 | Q26: =Q29+Q31 -> 0 | R26: =R29+R31 -> 0 | S26: =S29+S31 -> 1431014 | T26: =T29+T31 -> 1431014 | U26: =+T26-'[4]4条収入'!$AH$47 -> 0
B28: 汚水処理施設整備 補助事業充当分 | E28: =+$E$8 -> 5年度分補助事業 の課税支出割合 （現年） | F28: ='4条補助（特）'!F19 -> 25200000 | G28: =E35 -> 1246000 | H28: =IFERROR(ROUND(F28/F29*G28,0),0) -> 1246000 | I28: =G28-H28 -> 0 | L28: =+'4条補助（特）'!K19+'4条補助（特）'!L19 -> 0 | M28: =+'4条補助（特）'!M19 -> 0 | N28: =+'4条補助（特）'!N19 -> 25200000
F29: =D35 -> 25200000 | L29: =+H28-SUM(J29:K29,M29:N29) -> 0 | M29: =IFERROR(ROUND(M28/F28*H28,0),0) -> 0 | N29: =IFERROR(ROUND(N28/F28*H28,0),0) -> 1246000 | P29: =+ROUND(K29*P$5/(1+P$5),0) -> 0 | Q29: =+ROUND(L29*Q$5/(1+Q$5),0) -> 0 | R29: =+ROUND(M29*R$5/(1+R$5),0) -> 0 | S29: =+ROUND(N29*S$5/(1+S$5),0) -> 113273 | T29: =SUM(P29:S29) -> 113273
B30: 汚水処理施設整備 起債事業充当分 | E30: =+$E$10 -> 5年度分起債事業 の課税支出割合 （現年） | F30: 105752376 | G30: =E36 -> 15776400 | H30: =IFERROR(ROUND(F30/F31*G30,0),0) -> 14495150 | I30: =G30-H30 -> 1281250 | L30: 0 | M30: 0 | N30: =F30-SUM(L30:M30) -> 105752376
F31: =D36 -> 115100000 | L31: =+H30-SUM(J31:K31,M31:N31) -> 0 | M31: =IFERROR(ROUND(M30/F30*H30,0),0) -> 0 | N31: =IFERROR(ROUND(N30/F30*H30,0),0) -> 14495150 | P31: =+ROUND(K31*P$5/(1+P$5),0) -> 0 | Q31: =+ROUND(L31*Q$5/(1+Q$5),0) -> 0 | R31: =+ROUND(M31*R$5/(1+R$5),0) -> 0 | S31: =+ROUND(N31*S$5/(1+S$5),0) -> 1317741 | T31: =SUM(P31:S31) -> 1317741
C34: 区分 | D34: 支出額 | E34: 受益者分担金の事業別金額
C35: 補助事業分(現年) | D35: ='4条補助（特）'!F20 -> 25200000 | E35: =223000+1023000 -> 1246000
C36: 起債事業分(現年) | D36: 115100000 | E36: =431600+15344800 -> 15776400
C37: 計 | D37: =D35+D36 -> 140300000 | E37: =E35+E36 -> 17022400
E38: =E37-E35-E36 -> 0
A41: =+"令和"&MID(総括表!A2,3,2)&"度決算 不課税収入区分表(受益者分担金)（汚水処理施設整備）農集" -> 令和５年度決算 不課税収入区分表(受益者分担金)（汚水処理施設整備）農集
I43: (単位：円)
A44: 区分 | D44: 対象経費 | E44: 按分方法 | F44: 課税支出額 | G44: 不課税収入額 | H44: 特定収入 | I44: 特定収入 以外
F45: 支出額合計
A46: 受益者分担金 | G46: =G50+G48 -> 14115880 | H46: =H50+H48 -> 13788037 | I46: =I50+I48 -> 327843 | L46: =L49+L51 -> 0 | M46: =M49+M51 -> 0 | N46: =N49+N51 -> 13788037 | P46: =P49+P51 -> 0 | Q46: =Q49+Q51 -> 0 | R46: =R49+R51 -> 0 | S46: =S49+S51 -> 1253458 | T46: =T49+T51 -> 1253458 | U46: =+T46-'[4]4条収入'!$AH$48 -> 0
B48: 汚水処理施設整備 補助事業充当分 | E48: =+$E$8 -> 5年度分補助事業 の課税支出割合 （現年） | F48: ='4条補助（農）'!F19 -> 0 | G48: =E55 -> 0 | H48: =IFERROR(ROUND(F48/F49*G48,0),0) -> 0 | I48: =G48-H48 -> 0 | L48: =+'4条補助（農）'!K19+'4条補助（農）'!L19 -> 0 | M48: =+'4条補助（農）'!M19 -> 0 | N48: =+'4条補助（農）'!N19 -> 0
F49: =D55 -> 0 | L49: =+H48-SUM(J49:K49,M49:N49) -> 0 | M49: =IFERROR(ROUND(M48/F48*H48,0),0) -> 0 | N49: =IFERROR(ROUND(N48/F48*H48,0),0) -> 0 | P49: =+ROUND(K49*P$5/(1+P$5),0) -> 0 | Q49: =+ROUND(L49*Q$5/(1+Q$5),0) -> 0 | R49: =+ROUND(M49*R$5/(1+R$5),0) -> 0 | S49: =+ROUND(N49*S$5/(1+S$5),0) -> 0 | T49: =SUM(P49:S49) -> 0
B50: 汚水処理施設整備 起債事業充当分 | E50: =+$E$10 -> 5年度分起債事業 の課税支出割合 （現年） | F50: 77262892 | G50: =E56 -> 14115880 | H50: =IFERROR(ROUND(F50/F51*G50,0),0) -> 13788037 | I50: =G50-H50 -> 327843 | L50: 0 | M50: 0 | N50: =F50-SUM(L50:M50) -> 77262892
F51: =D56 -> 79100000 | L51: =+H50-SUM(J51:K51,M51:N51) -> 0 | M51: =IFERROR(ROUND(M50/F50*H50,0),0) -> 0 | N51: =IFERROR(ROUND(N50/F50*H50,0),0) -> 13788037 | P51: =+ROUND(K51*P$5/(1+P$5),0) -> 0 | Q51: =+ROUND(L51*Q$5/(1+Q$5),0) -> 0 | R51: =+ROUND(M51*R$5/(1+R$5),0) -> 0 | S51: =+ROUND(N51*S$5/(1+S$5),0) -> 1253458 | T51: =SUM(P51:S51) -> 1253458
C54: 区分 | D54: 支出額 | E54: 受益者分担金の事業別金額
C55: 補助事業分(現年) | D55: ='4条補助（農）'!F20 -> 0 | E55: 0
C56: 起債事業分(現年) | D56: 79100000 | E56: 14115880
...

Sheet 4条その他
A1: =+"令和"&MID(総括表!A2,3,1)&"年度決算 不課税収入区分表(その他国庫補金）" -> 令和５年度決算 不課税収入区分表(その他国庫補金）
I3: (単位：円)
A4: 区分 | D4: 対象経費 | E4: 按分方法 | F4: 課税支出額 | G4: 不課税収入額 | H4: 特定収入 | I4: 特定収入 以外 | J4: 特定収入内訳（上段：課税支出額、下段特定収入の按分） | P4: 特定収入に係る課税仕入れ等に係る消費税額
F5: 支出額合計 | J5: 0.03 | K5: 0.05 | L5: 0.08 | M5: 0.08 | N5: 0.1 | P5: 0.05 | Q5: 0.08 | R5: 0.08 | S5: 0.1 | T5: 計 | U5: ④４条収入とのチェック
A6: その他国庫補助金 | G6: =SUM(G8,G22,G36,G50) -> 0 | H6: =SUM(H8,H22,H36,H50) -> 0 | I6: =SUM(I8,I22,I36,I50) -> 0 | J6: =SUM(J9,J23,J37,J51) -> 0 | K6: =SUM(K9,K23,K37,K51) -> 0 | L6: =SUM(L9,L23,L37,L51) -> 0 | M6: =SUM(M9,M23,M37,M51) -> 0 | N6: =SUM(N9,N23,N37,N51) -> 0 | P6: =SUM(P9,P23,P37,P51) -> 0 | Q6: =SUM(Q9,Q23,Q37,Q51) -> 0 | R6: =SUM(R9,R23,R37,R51) -> 0 | S6: =SUM(S9,S23,S37,S51) -> 0 | T6: =SUM(T9,T23,T37,T51) -> 0 | U6: =+T6-'[4]4条収入'!$AH$26 -> 0
B8: その他国庫補助金(公共） | G8: =SUM(G10:G21) -> 0 | H8: =SUM(H10:H21) -> 0 | I8: =SUM(I10:I21) -> 0
L9: =+L13+L19 -> 0 | M9: =+M13+M19 -> 0 | N9: =+N13+N19 -> 0 | P9: =+P13+P19 -> 0 | Q9: =+Q13+Q19 -> 0 | R9: =+R13+R19 -> 0 | S9: =+S13+S19 -> 0 | T9: =+T13+T19 -> 0 | U9: =+T9-'[4]4条収入'!$AH$27 -> 0
B10: 公共下水道事業 | C10: 公共土木施設災害 復旧事業費国庫負担金 | D10: 対象事業費×２／３ | E10: 4年度分 公共土木施設災害復旧事業費(補助事業現年分)の課税支出割合 | G10: 0
F12: 0 | H12: =IFERROR(ROUND(SUM(G10:G15)*F12/F13,0),0) -> 0 | I12: =SUM(G10:G15)-H12 -> 0 | L12: 0 | M12: 0 | N12: =F12-SUM(L12:M12) -> 0
F13: 0 | L13: =+H12-SUM(J13:K13,M13:N13) -> 0 | M13: =IFERROR(ROUND(M12/F12*H12,0),0) -> 0 | N13: =IFERROR(ROUND(N12/F12*H12,0),0) -> 0 | P13: =+ROUND(K13*P$5/(1+P$5),0) -> 0 | Q13: =+ROUND(L13*Q$5/(1+Q$5),0) -> 0 | R13: =+ROUND(M13*R$5/(1+R$5),0) -> 0 | S13: =+ROUND(N13*S$5/(1+S$5),0) -> 0 | T13: =SUM(P13:S13) -> 0
C16: 公共土木施設災害 復旧事業費国庫負担金 | D16: 対象事業費×２／３ | E16: 3年度分 公共土木施設災害復旧事業費(補助事業繰越分)の課税支出割合 | G16: 0
F18: 0 | H18: =IFERROR(ROUND(SUM(G16:G21)*F18/F19,0),0) -> 0 | I18: =SUM(G16:G21)-H18 -> 0 | N18: =F18-SUM(L18:M18) -> 0
F19: 0 | L19: =+H18-SUM(J19:K19,M19:N19) -> 0 | M19: =IFERROR(ROUND(M18/F18*H18,0),0) -> 0 | N19: =IFERROR(ROUND(N18/F18*H18,0),0) -> 0 | P19: =+ROUND(K19*P$5/(1+P$5),0) -> 0 | Q19: =+ROUND(L19*Q$5/(1+Q$5),0) -> 0 | R19: =+ROUND(M19*R$5/(1+R$5),0) -> 0 | S19: =+ROUND(N19*S$5/(1+S$5),0) -> 0 | T19: =SUM(P19:S19) -> 0
B22: その他国庫補助金(特環） | G22: =SUM(G24:G35) -> 0 | H22: =SUM(H24:H35) -> 0 | I22: =SUM(I24:I35) -> 0
L23: =+L27+L33 -> 0 | M23: =+M27+M33 -> 0 | N23: =+N27+N33 -> 0 | P23: =+P27+P33 -> 0 | Q23: =+Q27+Q33 -> 0 | R23: =+R27+R33 -> 0 | S23: =+S27+S33 -> 0 | T23: =+T27+T33 -> 0 | U23: =+T23-'[4]4条収入'!$AH$28 -> 0
B24: 特定環境保全公共下水道 | C24: 公共土木施設災害 復旧事業費国庫負担金 | D24: 対象事業費×２／３ | E24: =+E10 -> 4年度分 公共土木施設災害復旧事業費(補助事業現年分)の課税支出割合 | G24: 0
F26: 0 | H26: =IFERROR(ROUND(SUM(G24:G29)*F26/F27,0),0) -> 0 | I26: =SUM(G24:G29)-H26 -> 0 | N26: =F26-SUM(L26:M26) -> 0
F27: 0 | L27: =+H26-SUM(J27:K27,M27:N27) -> 0 | M27: =IFERROR(ROUND(M26/F26*H26,0),0) -> 0 | N27: =IFERROR(ROUND(N26/F26*H26,0),0) -> 0 | P27: =+ROUND(K27*P$5/(1+P$5),0) -> 0 | Q27: =+ROUND(L27*Q$5/(1+Q$5),0) -> 0 | R27: =+ROUND(M27*R$5/(1+R$5),0) -> 0 | S27: =+ROUND(N27*S$5/(1+S$5),0) -> 0 | T27: =SUM(P27:S27) -> 0
C30: 公共土木施設災害 復旧事業費国庫負担金 | D30: 対象事業費×２／３ | E30: =+E16 -> 3年度分 公共土木施設災害復旧事業費(補助事業繰越分)の課税支出割合 | G30: 0
F32: 0 | H32: =IFERROR(ROUND(SUM(G30:G35)*F32/F33,0),0) -> 0 | I32: =SUM(G30:G35)-H32 -> 0 | N32: =F32-SUM(L32:M32) -> 0
F33: 0 | L33: =+H32-SUM(J33:K33,M33:N33) -> 0 | M33: =IFERROR(ROUND(M32/F32*H32,0),0) -> 0 | N33: =IFERROR(ROUND(N32/F32*H32,0),0) -> 0 | P33: =+ROUND(K33*P$5/(1+P$5),0) -> 0 | Q33: =+ROUND(L33*Q$5/(1+Q$5),0) -> 0 | R33: =+ROUND(M33*R$5/(1+R$5),0) -> 0 | S33: =+ROUND(N33*S$5/(1+S$5),0) -> 0 | T33: =SUM(P33:S33) -> 0
B36: その他国庫補助金(農集） | G36: =SUM(G38:G49) -> 0 | H36: =SUM(H38:H49) -> 0 | I36: =SUM(I38:I49) -> 0
L37: =+L41+L47 -> 0 | M37: =+M41+M47 -> 0 | N37: =+N41+N47 -> 0 | P37: =+P41+P47 -> 0 | Q37: =+Q41+Q47 -> 0 | R37: =+R41+R47 -> 0 | S37: =+S41+S47 -> 0 | T37: =+T41+T47 -> 0 | U37: =+T37-'[4]4条収入'!$AH$29 -> 0
B38: 農業集落排水事業 | C38: 災害関連農村生活環境 施設復旧事業国庫補助金 | D38: 対象事業費×１／２ | E38: 4年度分 災害関連農村生活環境施設復旧事業(補助事業現年分)の課税支出割合 | G38: 0
F40: 0 | H40: =IFERROR(ROUND(SUM(G38:G43)*F40/F41,0),0) -> 0 | I40: =SUM(G38:G43)-H40 -> 0 | L40: 0 | M40: 0 | N40: =F40-SUM(L40:M40) -> 0
F41: 0 | L41: =+H40-SUM(J41:K41,M41:N41) -> 0 | M41: =IFERROR(ROUND(M40/F40*H40,0),0) -> 0 | N41: =IFERROR(ROUND(N40/F40*H40,0),0) -> 0 | P41: =+ROUND(K41*P$5/(1+P$5),0) -> 0 | Q41: =+ROUND(L41*Q$5/(1+Q$5),0) -> 0 | R41: =+ROUND(M41*R$5/(1+R$5),0) -> 0 | S41: =+ROUND(N41*S$5/(1+S$5),0) -> 0 | T41: =SUM(P41:S41) -> 0
C44: 災害関連農村生活環境 施設復旧事業国庫補助金 | D44: 対象事業費×１／２ | E44: 3年度分 災害関連農村生活環境施設復旧事業(補助事業繰越分)の課税支出割合 | G44: 0
F46: 0 | H46: =IFERROR(ROUND(SUM(G44:G49)*F46/F47,0),0) -> 0 | I46: =SUM(G44:G49)-H46 -> 0 | N46: =F46-SUM(L46:M46) -> 0
F47: 0 | L47: =+H46-SUM(J47:K47,M47:N47) -> 0 | M47: =IFERROR(ROUND(M46/F46*H46,0),0) -> 0 | N47: =IFERROR(ROUND(N46/F46*H46,0),0) -> 0 | P47: =+ROUND(K47*P$5/(1+P$5),0) -> 0 | Q47: =+ROUND(L47*Q$5/(1+Q$5),0) -> 0 | R47: =+ROUND(M47*R$5/(1+R$5),0) -> 0 | S47: =+ROUND(N47*S$5/(1+S$5),0) -> 0 | T47: =SUM(P47:S47) -> 0
B50: その他国庫補助金(浄化槽） | G50: =SUM(G52:G63) -> 0 | H50: =SUM(H52:H63) -> 0 | I50: =SUM(I52:I63) -> 0
L51: =+L55+L61 -> 0 | M51: =+M55+M61 -> 0 | N51: =+N55+N61 -> 0 | P51: =+P55+P61 -> 0 | Q51: =+Q55+Q61 -> 0 | R51: =+R55+R61 -> 0 | S51: =+S55+S61 -> 0 | T51: =+T55+T61 -> 0 | U51: =+T51-'[4]4条収入'!$AH$30 -> 0
B52: 市営浄化槽事業
H54: =IFERROR(ROUND(SUM(G52:G57)*F54/F55,0),0) -> 0 | I54: =SUM(G52:G57)-H54 -> 0 | N54: =F54-SUM(L54:M54) -> 0
L55: =+H54-SUM(J55:K55,M55:N55) -> 0 | M55: =IFERROR(ROUND(M54/F54*H54,0),0) -> 0 | N55: =IFERROR(ROUND(N54/F54*H54,0),0) -> 0 | P55: =+ROUND(K55*P$5/(1+P$5),0) -> 0 | Q55: =+ROUND(L55*Q$5/(1+Q$5),0) -> 0 | R55: =+ROUND(M55*R$5/(1+R$5),0) -> 0 | S55: =+ROUND(N55*S$5/(1+S$5),0) -> 0 | T55: =SUM(P55:S55) -> 0
H60: =IFERROR(ROUND(SUM(G58:G63)*F60/F61,0),0) -> 0 | I60: =SUM(G58:G63)-H60 -> 0 | N60: =F60-SUM(L60:M60) -> 0
L61: =+H60-SUM(J61:K61,M61:N61) -> 0 | M61: =IFERROR(ROUND(M60/F60*H60,0),0) -> 0 | N61: =IFERROR(ROUND(N60/F60*H60,0),0) -> 0 | P61: =+ROUND(K61*P$5/(1+P$5),0) -> 0 | Q61: =+ROUND(L61*Q$5/(1+Q$5),0) -> 0 | R61: =+ROUND(M61*R$5/(1+R$5),0) -> 0 | S61: =+ROUND(N61*S$5/(1+S$5),0) -> 0 | T61: =SUM(P61:S61) -> 0
F64: 4条収入シート その他国庫補助金 | G64: =+'[4]4条収入'!$E$26 -> 0
F65: チェック | G65: =+G6-G64 -> 0

Sheet 4条工事負担金
A1: =+"令和"&MID(総括表!A2,3,1)&"年度決算 不課税収入区分表(工事負担金)" -> 令和５年度決算 不課税収入区分表(工事負担金)
I3: (単位：円)
A4: 区分 | D4: 対象経費 | E4: 按分方法 | F4: 課税支出額 | G4: 不課税収入額 | H4: 特定収入 | I4: 特定収入 以外 | J4: 特定収入内訳（上段：課税支出額、下段特定収入の按分） | P4: 特定収入に係る課税仕入れ等に係る消費税額
F5: 支出額合計 | J5: 0.03 | K5: 0.05 | L5: 0.08 | M5: 0.08 | N5: 0.1 | P5: 0.05 | Q5: 0.08 | R5: 0.08 | S5: 0.1 | T5: 計 | U5: ④４条収入とのチェック
A6: 工事負担金 | G6: =SUM(G8:G17) -> 514968182 | H6: =SUM(H8:H17) -> 351364357 | I6: =SUM(I8:I17) -> 163603825 | J6: =+SUM(J9,J11,J13,J15,J17) -> 0 | K6: =+SUM(K9,K11,K13,K15,K17) -> 131982078 | L6: =+SUM(L9,L11,L13,L15,L17) -> 1246566 | M6: =+SUM(M9,M11,M13,M15,M17) -> 0 | N6: =+SUM(N9,N11,N13,N15,N17) -> 218135713 | P6: =+SUM(P9,P11,P13,P15,P17) -> 6284861 | Q6: =+SUM(Q9,Q11,Q13,Q15,Q17) -> 92338 | R6: =+SUM(R9,R11,R13,R15,R17) -> 0 | S6: =+SUM(S9,S11,S13,S15,S17) -> 19830519 | T6: =+SUM(T9,T11,T13,T15,T17) -> 26207718 | U6: =+T6-'[4]4条収入'!$AH$50 -> 1
B8: 公共下水道 単市事業充当分 （西風新都を含む） | E8: 5年度分単市事業 の課税支出割合 (現年＋繰越) | F8: =F33 -> 465460043 | G8: ='工事負担金（所属別内訳）'!G76 -> 0 | H8: =IFERROR(ROUND(F8/F9*G8,0),0) -> 0 | I8: =G8-H8 -> 0 | L8: 0 | M8: 0 | N8: =F8-SUM(L8:M8) -> 465460043
F9: =F34 -> 1093621564 | L9: =+H8-SUM(J9:K9,M9:N9) -> 0 | M9: =IFERROR(ROUND(M8/F8*H8,0),0) -> 0 | N9: =IFERROR(ROUND(N8/F8*H8,0),0) -> 0 | P9: =+ROUND(K9*P$5/(1+P$5),0) -> 0 | Q9: =+ROUND(L9*Q$5/(1+Q$5),0) -> 0 | R9: =+ROUND(M9*R$5/(1+R$5),0) -> 0 | S9: =+ROUND(N9*S$5/(1+S$5),0) -> 0 | T9: =SUM(P9:S9) -> 0 | U9: =+SUM(T9:T13)+T17 -> 19830519 | V9: ←工事費充当分の計
B10: 排水設備整備事業 充当分 | E10: 5年度分排水設備事業 の課税支出割合 | F10: =+'[5]4条支出'!$K$8 -> 518619849 | G10: ='工事負担金（所属別内訳）'!G80 -> 279746516 | H10: =IFERROR(ROUND(F10/F11*G10,0),0) -> 218135713 | I10: =G10-H10 -> 61610803 | L10: =+[5]排水!F$41+[5]排水!G$41+[5]排水!H$41 -> 0 | M10: =+[5]排水!I$41 -> 0 | N10: =+[5]排水!J$41 -> 518619849
F11: =+'[5]4条支出'!$E$8 -> 665100151 | L11: =+H10-SUM(J11:K11,M11:N11) -> 0 | M11: =IFERROR(ROUND(M10/F10*H10,0),0) -> 0 | N11: =IFERROR(ROUND(N10/F10*H10,0),0) -> 218135713 | P11: =+ROUND(K11*P$5/(1+P$5),0) -> 0 | Q11: =+ROUND(L11*Q$5/(1+Q$5),0) -> 0 | R11: =+ROUND(M11*R$5/(1+R$5),0) -> 0 | S11: =+ROUND(N11*S$5/(1+S$5),0) -> 19830519 | T11: =SUM(P11:S11) -> 19830519
B12: 諸設備新設改良事業 充当分 | E12: 5年度分諸設備新設改良 事業の課税支出割合 | F12: =+'[5]4条支出'!$K$11 -> 59178010 | G12: ='工事負担金（所属別内訳）'!G83 -> 0 | H12: =IFERROR(ROUND(F12/F13*G12,0),0) -> 0 | I12: =G12-H12 -> 0 | L12: =+[5]諸公!F$41+[5]諸公!G$41+[5]諸公!H$41 -> 0 | M12: =+[5]諸公!I$41 -> 0 | N12: =+[5]諸公!J$41 -> 59178010
F13: =+'[5]4条支出'!$E$11 -> 59178010 | L13: =+H12-SUM(J13:K13,M13:N13) -> 0 | M13: =IFERROR(ROUND(M12/F12*H12,0),0) -> 0 | N13: =IFERROR(ROUND(N12/F12*H12,0),0) -> 0 | P13: =+ROUND(K13*P$5/(1+P$5),0) -> 0 | Q13: =+ROUND(L13*Q$5/(1+Q$5),0) -> 0 | R13: =+ROUND(M13*R$5/(1+R$5),0) -> 0 | S13: =+ROUND(N13*S$5/(1+S$5),0) -> 0 | T13: =SUM(P13:S13) -> 0
B14: 元金償還金充当分 | E14: 起債年度の課税支出割合 (別紙算出表) | G14: ='工事負担金（元金償還分)'!G14 -> 235221666 | H14: ='工事負担金（元金償還分)'!H14 -> 133228644 | I14: ='工事負担金（元金償還分)'!I14 -> 101993022
K15: =+SUM(西風:廿日市!K51:K52) -> 131982078 | L15: =+SUM(西風:廿日市!K53) -> 1246566 | N15: =+SUM(西風:廿日市!K54) -> 0 | P15: =+ROUND(K15*P$5/(1+P$5),0) -> 6284861 | Q15: =+ROUND(L15*Q$5/(1+Q$5),0) -> 92338 | R15: =+ROUND(M15*R$5/(1+R$5),0) -> 0 | S15: =+ROUND(N15*S$5/(1+S$5),0) -> 0 | T15: =SUM(P15:S15) -> 6377199
B16: 市街化区域外汚水処理施設 整備事業充当分 | E16: 5年度分市街化区域外汚水処理施設整備事業の課税支出割合 | G16: =SUM(G18:G23) -> 0 | H16: =SUM(H18:H23) -> 0 | I16: =G16-H16 -> 0 | L16: =L18+L20+L22 -> 0 | M16: =M18+M20+M22 -> 0 | N16: =N18+N20+N22 -> 656665462
