Workbook

Sheet (申)3%
B1: 消費税等計算チェックシート | AZ1: 単位：円
B2: チェック項目 | E2: 検証 | AZ2: 申告書等
B3: 課税標準等 | C3: 1 | D3: 行政手数料収入を課税売上にしていないか（一部のものを除き、非課税となる） | E3: 「その他営業収益」の「手数料」をチェック
C5: 2 | D5: 土地の貸付（原則非課税）のうち、契約期間が1か月未満の場合や、駐車場その他の施設の利用に伴って土地が使用される場合は課税としているか | E5: 「雑収益」の「その他雑収益」をチェック
C8: 3 | D8: 課税の対象となる対価補償金以外の補償金を課税売上にしていないか（水道管移設保証金、ガス管移設保証金等は不課税）
C11: 4 | D11: 損害賠償金を課税売上にしていないか（一般的には不課税）
C13: 5 | D13: 建物等固定資産（土地を除く）の売却について、差益部分のみを課税売上にしていないか | E13: 「固定資産売却益」及び「土地売却代金」をチェック
C15: 6 | D15: 車両等を購入した場合、下取り価額を課税売上にしていないか
C17: 7 | D17: 土地建物一括譲渡の場合、対価の額の区分は正しいか
C19: 8 | D19: 課税売上額の計算
E20: 収益的収入のうち課税売上（税込） | R20: =基礎数値!D3 -> 0 | Y20: ※ 「決算総括表」より
E21: 資本的収入のうち課税売上（税込） | R21: =基礎数値!D4 -> 0 | Y21: ※ 「決算総括表」より | AJ21: 計 | AK21: =R20+R21 -> 0 | AQ21: A
E23: 課税売上から控除するもの
H24: 仕入対価の返還等の額 | R24: =基礎数値!D6 -> 0 | X24: B | Y24: ※ 「過年度損益修正益」「その他特別利益」のうち、課税支出が返還されたもの
H25: 売上対価の返還等の額 | R25: =基礎数値!D7 -> 0 | X25: C | Y25: ※ 「過年度損益修正損」「その他特別損失」のうち、課税収入を返還したもの
E27: 課税売上額（税抜） | R27: =ROUNDDOWN((AK21-R24-R25)*100/103,0) -> 0 | X27: D | Y27: ※ （A－B－C）×100/103 | AZ27: 付表２①
E29: 課税標準額（税抜） | R29: =ROUNDDOWN((AK21-R24)*100/103,-3) -> 0 | X29: E | Y29: ※ （A－B）×100/103 1,000円未満切捨 | AZ29: 付表１①
E31: 課税標準額に対する消費税額 | R31: =ROUNDDOWN(R29*3/100,0) -> 0 | X31: F | Y31: ※ E×3% | AZ31: 付表１②
B33: 課税売上割合 | C33: 1 | D33: 課税売上割合の計算
E34: 課税売上額
E35: 免税売上額
E36: 課税資産の譲渡等の対価の額
E38: 収益的収入のうち非課税売上（税込）
E39: 資本的収入のうち非課税売上（税込）
E40: 資産の譲渡等の対価の額
E42: 課税売上割合
B44: 課税仕入れ | C44: 1 | D44: 土地の借受（原則非課税）のうち、契約期間が1か月未満の場合や、駐車場その他の施設の利用に伴って土地を使用する場合は課税としているか | E44: 賃借料をチェック
C47: 2 | D47: 課税の対象となる対価補償金以外の補償金を課税仕入れにしていないか（水道管移設保証金、ガス管移設保証金等は不課税） | E47: 保証金をチェック
C50: 3 | D50: 損害賠償金を課税仕入れにしていないか（一般的には不課税）
C52: 4 | D52: 免税・非課税・不課税仕入れを課税仕入れにしていないか | E52: 各費目をチェック
C54: 5 | D54: 資産の譲渡損を課税仕入れにしていないか | E54: 固定資産売却損をチェック
C56: 6 | D56: 経過措置対象取引（3%取引）がある場合、課税仕入れを3%取引と4%取引に区分して計算しているか | E56: 該当なし
C58: 7 | D58: 課税仕入れ等の税額の計算
E59: 収益的支出のうち課税支出（税込） | R59: =基礎数値!D11 -> 0 | Y59: ※ 「決算総括表」より
E60: 資本的支出のうち課税支出（税込） | R60: =基礎数値!D12 -> 0 | Y60: ※ 「決算総括表」より | AJ60: 計 | AK60: =R59+R60 -> 0 | AQ60: K
E64: 課税仕入れから控除するもの
H65: 返還等対価・貸倒れの額 | R65: =基礎数値!D14 -> 0 | X65: L | Y65: ※ 「過年度損益修正損」「その他特別損失」の課税支出うち、該当分
H66: 仕入対価の返還等の額 | R66: =R24 -> 0 | Y66: ※ Bの額
E68: 課税仕入れに係る支払対価の額（税込） | T68: =AK60-R65-R66 -> 0 | AA68: ※ K-L-B | AZ68: 付表２⑧
E70: 課税仕入れに係る消費税額 | T70: =ROUNDDOWN((AK60-R65-R66)*3/103,0) -> 0 | Z70: M | AA70: ※ （K-L-B）×3/103 ＜付表２の注３による計算＞ | AZ70: 付表２⑨⑫
...

Sheet (申)5%
B1: 消費税等計算チェックシート | AZ1: 単位：円
B2: チェック項目 | E2: 検証 | AZ2: 申告書等
B3: 課税標準等 | C3: 1 | D3: 行政手数料収入を課税売上にしていないか（一部のものを除き、非課税となる） | E3: 「その他営業収益」の「手数料」をチェック
C5: 2 | D5: 土地の貸付（原則非課税）のうち、契約期間が1か月未満の場合や、駐車場その他の施設の利用に伴って土地が使用される場合は課税としているか | E5: 「雑収益」の「その他雑収益」をチェック
C8: 3 | D8: 課税の対象となる対価補償金以外の補償金を課税売上にしていないか（水道管移設保証金、ガス管移設保証金等は不課税）
C11: 4 | D11: 損害賠償金を課税売上にしていないか（一般的には不課税）
C13: 5 | D13: 建物等固定資産（土地を除く）の売却について、差益部分のみを課税売上にしていないか | E13: 「固定資産売却益」及び「土地売却代金」をチェック
C15: 6 | D15: 車両等を購入した場合、下取り価額を課税売上にしていないか
C17: 7 | D17: 土地建物一括譲渡の場合、対価の額の区分は正しいか
C19: 8 | D19: 課税売上額の計算
E20: 収益的収入のうち課税売上（税込） | R20: =基礎数値!E3 -> 0 | Y20: ※ 「決算総括表」より
E21: 資本的収入のうち課税売上（税込） | R21: =基礎数値!E4 -> 0 | Y21: ※ 「決算総括表」より | AJ21: 計 | AK21: =R20+R21 -> 0 | AQ21: A
E23: 課税売上から控除するもの
H24: 仕入対価の返還等の額 | R24: =基礎数値!E6 -> 0 | X24: B | Y24: ※ 「過年度損益修正益」「その他特別利益」のうち、課税支出が返還されたもの
H25: 売上対価の返還等の額 | R25: =基礎数値!E7 -> 0 | X25: C | Y25: ※ 「過年度損益修正損」「その他特別損失」のうち、課税収入を返還したもの
E27: 課税売上額（税抜） | R27: =ROUNDDOWN((AK21-R24-R25)*100/105,0) -> 0 | X27: D | Y27: ※ （A－B－C）×100/105 | AZ27: 付表２①
E29: 課税標準額（税抜） | R29: =ROUNDDOWN((AK21-R24)*100/105,-3) -> 0 | X29: E | Y29: ※ （A－B）×100/105 1,000円未満切捨 | AZ29: 付表１①
E31: 課税標準額に対する消費税額 | R31: =ROUNDDOWN(R29*4/100,0) -> 0 | X31: F | Y31: ※ E×4% | AZ31: 付表１②
B33: 課税売上割合 | C33: 1 | D33: 課税売上割合の計算
E34: 課税売上額
E35: 免税売上額
E36: 課税資産の譲渡等の対価の額
E38: 収益的収入のうち非課税売上（税込）
E39: 資本的収入のうち非課税売上（税込）
E40: 資産の譲渡等の対価の額
E42: 課税売上割合
B44: 課税仕入れ | C44: 1 | D44: 土地の借受（原則非課税）のうち、契約期間が1か月未満の場合や、駐車場その他の施設の利用に伴って土地を使用する場合は課税としているか | E44: 賃借料をチェック
C47: 2 | D47: 課税の対象となる対価補償金以外の補償金を課税仕入れにしていないか（水道管移設保証金、ガス管移設保証金等は不課税） | E47: 保証金をチェック
C50: 3 | D50: 損害賠償金を課税仕入れにしていないか（一般的には不課税）
C52: 4 | D52: 免税・非課税・不課税仕入れを課税仕入れにしていないか | E52: 各費目をチェック
C54: 5 | D54: 資産の譲渡損を課税仕入れにしていないか | E54: 固定資産売却損をチェック
C56: 6 | D56: 経過措置対象取引（3%取引）がある場合、課税仕入れを3%取引と4%取引に区分して計算しているか | E56: 該当なし
C58: 7 | D58: 課税仕入れ等の税額の計算
E59: 収益的支出のうち課税支出（税込） | R59: =基礎数値!E11 -> 1120996 | Y59: ※ 「決算総括表」より
E60: 資本的支出のうち課税支出（税込） | R60: =基礎数値!E12 -> 0 | Y60: ※ 「決算総括表」より | AJ60: 計 | AK60: =R59+R60 -> 1120996 | AQ60: K
E64: 課税仕入れから控除するもの
H65: 返還等対価・貸倒れの額 | R65: =基礎数値!E14 -> 1120996 | X65: L | Y65: ※ 「過年度損益修正損」「その他特別損失」の課税支出うち、該当分
H66: 仕入対価の返還等の額 | R66: =R24 -> 0 | Y66: ※ Bの額
E68: 課税仕入れに係る支払対価の額（税込） | T68: =AK60-R65-R66 -> 0 | AA68: ※ K-L-B | AZ68: 付表２⑨
E70: 課税仕入れに係る消費税額 | T70: =ROUNDDOWN((AK60-R65-R66)*4/105,0) -> 0 | Z70: M | AA70: ※ （K-L-B）×4/105 ＜付表２の注３による計算＞ | AZ70: 付表２⑩⑮
...

Sheet (申)8%
B1: 消費税等計算チェックシート | AZ1: 単位：円
B2: チェック項目 | E2: 検証 | AZ2: 申告書等
B3: 課税標準等 | C3: 1 | D3: 行政手数料収入を課税売上にしていないか（一部のものを除き、非課税となる） | E3: 「その他営業収益」の「手数料」をチェック
C5: 2 | D5: 土地の貸付（原則非課税）のうち、契約期間が1か月未満の場合や、駐車場その他の施設の利用に伴って土地が使用される場合は課税としているか | E5: 「雑収益」の「その他雑収益」をチェック
C8: 3 | D8: 課税の対象となる対価補償金以外の補償金を課税売上にしていないか（水道管移設保証金、ガス管移設保証金等は不課税）
C11: 4 | D11: 損害賠償金を課税売上にしていないか（一般的には不課税）
C13: 5 | D13: 建物等固定資産（土地を除く）の売却について、差益部分のみを課税売上にしていないか | E13: 「固定資産売却益」及び「土地売却代金」をチェック
C15: 6 | D15: 車両等を購入した場合、下取り価額を課税売上にしていないか
C17: 7 | D17: 土地建物一括譲渡の場合、対価の額の区分は正しいか
C19: 8 | D19: 課税売上額の計算
E20: 収益的収入のうち課税売上（税込） | R20: =基礎数値!F3 -> 47053 | Y20: ※ 「決算総括表」より
E21: 資本的収入のうち課税売上（税込） | R21: =基礎数値!F4 -> 0 | Y21: ※ 「決算総括表」より | AJ21: 計 | AK21: =R20+R21 -> 47053 | AQ21: A
E23: 課税売上から控除するもの
H24: 仕入対価の返還等の額 | R24: =基礎数値!F6 -> 0 | X24: B | Y24: ※ 「過年度損益修正益」「その他特別利益」のうち、課税支出が返還されたもの
H25: 売上対価の返還等の額 | R25: =基礎数値!F7 -> 39339 | X25: C | Y25: ※ 「過年度損益修正損」「その他特別損失」のうち、課税収入を返還したもの
E27: 課税売上額（税抜） | R27: =ROUNDDOWN((AK21-R24-R25)*100/108,0) -> 7142 | X27: D | Y27: ※ （A－B－C）×100/108 | AZ27: 付表２①
E29: 課税標準額（税抜） | R29: =ROUNDDOWN((AK21-R24)*100/108,-3) -> 43000 | X29: E | Y29: ※ （A－B）×100/108 1,000円未満切捨 | AZ29: 付表１①
E31: 課税標準額に対する消費税額 | R31: =ROUNDDOWN(R29*63/1000,0) -> 2709 | X31: F | Y31: ※ E×6.3% | AZ31: 付表１②
B33: 課税売上割合 | C33: 1 | D33: 課税売上割合の計算
E34: 課税売上額
E35: 免税売上額
E36: 課税資産の譲渡等の対価の額
E38: 収益的収入のうち非課税売上（税込）
E39: 資本的収入のうち非課税売上（税込）
E40: 資産の譲渡等の対価の額
E42: 課税売上割合
B44: 課税仕入れ | C44: 1 | D44: 土地の借受（原則非課税）のうち、契約期間が1か月未満の場合や、駐車場その他の施設の利用に伴って土地を使用する場合は課税としているか | E44: 賃借料をチェック
C47: 2 | D47: 課税の対象となる対価補償金以外の補償金を課税仕入れにしていないか（水道管移設保証金、ガス管移設保証金等は不課税） | E47: 保証金をチェック
C50: 3 | D50: 損害賠償金を課税仕入れにしていないか（一般的には不課税）
C52: 4 | D52: 免税・非課税・不課税仕入れを課税仕入れにしていないか | E52: 各費目をチェック
C54: 5 | D54: 資産の譲渡損を課税仕入れにしていないか | E54: 固定資産売却損をチェック
C56: 6 | D56: 経過措置対象取引（3%取引）がある場合、課税仕入れを3%取引と4%取引に区分して計算しているか | E56: 該当なし
C58: 7 | D58: 課税仕入れ等の税額の計算
E59: 収益的支出のうち課税支出（税込） | R59: =基礎数値!F11 -> 25903142 | Y59: ※ 「決算総括表」より
E60: 資本的支出のうち課税支出（税込） | R60: =基礎数値!F12 -> 125712 | Y60: ※ 「決算総括表」より | AJ60: 計 | AK60: =R59+R60 -> 26028854 | AQ60: K
E64: 課税仕入れから控除するもの
H65: 返還等対価・貸倒れの額 | R65: =基礎数値!F14 -> 24706340 | X65: L | Y65: ※ 「過年度損益修正損」「その他特別損失」の課税支出うち、該当分
H66: 仕入対価の返還等の額 | R66: =R24 -> 0 | Y66: ※ Bの額
E68: 課税仕入れに係る支払対価の額（税込） | T68: =AK60-R65-R66 -> 1322514 | AA68: ※ K-L-B | AZ68: 付表２⑨
E70: 課税仕入れに係る消費税額 | T70: =ROUNDDOWN((AK60-R65-R66)*63/1080,0) -> 77146 | Z70: M | AA70: ※ （K-L-B）×6.3/108 ＜付表２の注３による計算＞ | AZ70: 付表２⑩⑮
...

Sheet (申)軽8%
B1: 消費税等計算チェックシート | AZ1: 単位：円
B2: チェック項目 | E2: 検証 | AZ2: 申告書等
B3: 課税標準等 | C3: 1 | D3: 行政手数料収入を課税売上にしていないか（一部のものを除き、非課税となる） | E3: 「その他営業収益」の「手数料」をチェック
C5: 2 | D5: 土地の貸付（原則非課税）のうち、契約期間が1か月未満の場合や、駐車場その他の施設の利用に伴って土地が使用される場合は課税としているか | E5: 「雑収益」の「その他雑収益」をチェック
C8: 3 | D8: 課税の対象となる対価補償金以外の補償金を課税売上にしていないか（水道管移設保証金、ガス管移設保証金等は不課税）
C11: 4 | D11: 損害賠償金を課税売上にしていないか（一般的には不課税）
C13: 5 | D13: 建物等固定資産（土地を除く）の売却について、差益部分のみを課税売上にしていないか | E13: 「固定資産売却益」及び「土地売却代金」をチェック
C15: 6 | D15: 車両等を購入した場合、下取り価額を課税売上にしていないか
C17: 7 | D17: 土地建物一括譲渡の場合、対価の額の区分は正しいか
C19: 8 | D19: 課税売上額の計算
E20: 収益的収入のうち課税売上（税込） | R20: =基礎数値!G3 -> 0 | Y20: ※ 「決算総括表」より
E21: 資本的収入のうち課税売上（税込） | R21: =基礎数値!G4 -> 0 | Y21: ※ 「決算総括表」より | AJ21: 計 | AK21: =R20+R21 -> 0 | AQ21: A
E23: 課税売上から控除するもの
H24: 仕入対価の返還等の額 | R24: =基礎数値!G6 -> 0 | X24: B | Y24: ※ 「過年度損益修正益」「その他特別利益」のうち、課税支出が返還されたもの
H25: 売上対価の返還等の額 | R25: =基礎数値!G7 -> 0 | X25: C | Y25: ※ 「過年度損益修正損」「その他特別損失」のうち、課税収入を返還したもの
E27: 課税売上額（税抜） | R27: =ROUNDDOWN((AK21-R24-R25)*100/108,0) -> 0 | X27: D | Y27: ※ （A－B－C）×100/108 | AZ27: 付表２①
E29: 課税標準額（税抜） | R29: =ROUNDDOWN((AK21-R24)*100/108,-3) -> 0 | X29: E | Y29: ※ （A－B）×100/108 1,000円未満切捨 | AZ29: 付表１①
E31: 課税標準額に対する消費税額 | R31: =ROUNDDOWN(R29*62.4/1000,0) -> 0 | X31: F | Y31: ※ E×6.24% | AZ31: 付表１②
B33: 課税売上割合 | C33: 1 | D33: 課税売上割合の計算
E34: 課税売上額
E35: 免税売上額
E36: 課税資産の譲渡等の対価の額
E38: 収益的収入のうち非課税売上（税込）
E39: 資本的収入のうち非課税売上（税込）
E40: 資産の譲渡等の対価の額
E42: 課税売上割合
B44: 課税仕入れ | C44: 1 | D44: 土地の借受（原則非課税）のうち、契約期間が1か月未満の場合や、駐車場その他の施設の利用に伴って土地を使用する場合は課税としているか | E44: 賃借料をチェック
C47: 2 | D47: 課税の対象となる対価補償金以外の補償金を課税仕入れにしていないか（水道管移設保証金、ガス管移設保証金等は不課税） | E47: 保証金をチェック
C50: 3 | D50: 損害賠償金を課税仕入れにしていないか（一般的には不課税）
C52: 4 | D52: 免税・非課税・不課税仕入れを課税仕入れにしていないか | E52: 各費目をチェック
C54: 5 | D54: 資産の譲渡損を課税仕入れにしていないか | E54: 固定資産売却損をチェック
C56: 6 | D56: 経過措置対象取引（3%取引）がある場合、課税仕入れを3%取引と4%取引に区分して計算しているか | E56: 該当なし
C58: 7 | D58: 課税仕入れ等の税額の計算
E59: 収益的支出のうち課税支出（税込） | R59: =基礎数値!G11 -> 500878 | Y59: ※ 「決算総括表」より
E60: 資本的支出のうち課税支出（税込） | R60: =基礎数値!G12 -> 36840 | Y60: ※ 「決算総括表」より | AJ60: 計 | AK60: =R59+R60 -> 537718 | AQ60: K
E64: 課税仕入れから控除するもの
H65: 返還等対価・貸倒れの額 | R65: =基礎数値!G14 -> 0 | X65: L | Y65: ※ 「過年度損益修正損」「その他特別損失」の課税支出うち、該当分
H66: 仕入対価の返還等の額 | R66: =R24 -> 0 | Y66: ※ Bの額
E68: 課税仕入れに係る支払対価の額（税込） | T68: =AK60-R65-R66 -> 537718 | AA68: ※ K-L-B | AZ68: 付表２⑨
E70: 課税仕入れに係る消費税額 | T70: =ROUNDDOWN((AK60-R65-R66)*62.4/1080,0) -> 31068 | Z70: M | AA70: ※ （K-L-B）×6.24/108 ＜付表２の注３による計算＞ | AZ70: 付表２⑩⑮
...

Sheet (申)10%
B1: 消費税等計算チェックシート | AZ1: 単位：円
B2: チェック項目 | E2: 検証 | AZ2: 申告書等
B3: 課税標準等 | C3: 1 | D3: 行政手数料収入を課税売上にしていないか（一部のものを除き、非課税となる） | E3: 「その他営業収益」の「手数料」をチェック
C5: 2 | D5: 土地の貸付（原則非課税）のうち、契約期間が1か月未満の場合や、駐車場その他の施設の利用に伴って土地が使用される場合は課税としているか | E5: 「雑収益」の「その他雑収益」をチェック
C8: 3 | D8: 課税の対象となる対価補償金以外の補償金を課税売上にしていないか（水道管移設保証金、ガス管移設保証金等は不課税）
C11: 4 | D11: 損害賠償金を課税売上にしていないか（一般的には不課税）
C13: 5 | D13: 建物等固定資産（土地を除く）の売却について、差益部分のみを課税売上にしていないか | E13: 「固定資産売却益」及び「土地売却代金」をチェック
C15: 6 | D15: 車両等を購入した場合、下取り価額を課税売上にしていないか
C17: 7 | D17: 土地建物一括譲渡の場合、対価の額の区分は正しいか
C19: 8 | D19: 課税売上額の計算
E20: 収益的収入のうち課税売上（税込） | R20: =基礎数値!H3 -> 20730008529 | Y20: ※ 「決算総括表」より
E21: 資本的収入のうち課税売上（税込） | R21: =基礎数値!H4 -> 39691410 | Y21: ※ 「決算総括表」より | AJ21: 計 | AK21: =R20+R21 -> 20769699939 | AQ21: A
E23: 課税売上から控除するもの
H24: 仕入対価の返還等の額 | R24: =基礎数値!H6 -> 0 | X24: B | Y24: ※ 「過年度損益修正益」「その他特別利益」のうち、課税支出が返還されたもの
H25: 売上対価の返還等の額 | R25: =基礎数値!H7 -> 10639743 | X25: C | Y25: ※ 「過年度損益修正損」「その他特別損失」のうち、課税収入を返還したもの
E27: 課税売上額（税抜） | R27: =ROUNDDOWN((AK21-R24-R25)*100/110,0) -> 18871872905 | X27: D | Y27: ※ （A－B－C）×100/110 | AZ27: 付表２①
E29: 課税標準額（税抜） | R29: =ROUNDDOWN((AK21-R24)*100/110,-3) -> 18881545000 | X29: E | Y29: ※ （A－B）×100/110 1,000円未満切捨 | AZ29: 付表１①
E31: 課税標準額に対する消費税額 | R31: =ROUNDDOWN(R29*78/1000,0) -> 1472760510 | X31: F | Y31: ※ E×7.8% | AZ31: 付表１②
B33: 課税売上割合 | C33: 1 | D33: 課税売上割合の計算
E34: 課税売上額
E35: 免税売上額
E36: 課税資産の譲渡等の対価の額
E38: 収益的収入のうち非課税売上（税込）
E39: 資本的収入のうち非課税売上（税込）
E40: 資産の譲渡等の対価の額
E42: 課税売上割合
B44: 課税仕入れ | C44: 1 | D44: 土地の借受（原則非課税）のうち、契約期間が1か月未満の場合や、駐車場その他の施設の利用に伴って土地を使用する場合は課税としているか | E44: 賃借料をチェック
C47: 2 | D47: 課税の対象となる対価補償金以外の補償金を課税仕入れにしていないか（水道管移設保証金、ガス管移設保証金等は不課税） | E47: 保証金をチェック
C50: 3 | D50: 損害賠償金を課税仕入れにしていないか（一般的には不課税）
C52: 4 | D52: 免税・非課税・不課税仕入れを課税仕入れにしていないか | E52: 各費目をチェック
C54: 5 | D54: 資産の譲渡損を課税仕入れにしていないか | E54: 固定資産売却損をチェック
C56: 6 | D56: 経過措置対象取引（3%取引）がある場合、課税仕入れを3%取引と4%取引に区分して計算しているか | E56: 該当なし
C58: 7 | D58: 課税仕入れ等の税額の計算
E59: 収益的支出のうち課税支出（税込） | R59: =基礎数値!H11 -> 9106828850 | Y59: ※ 「決算総括表」より
E60: 資本的支出のうち課税支出（税込） | R60: =基礎数値!H12 -> 16278736624 | Y60: ※ 「決算総括表」より | AJ60: 計 | AK60: =R59+R60 -> 25385565474
E61: 免税業者との取引額 | R61: =基礎数値!H16 -> 34600 | Y61: 免税業者以外との取引額 | AI61: =基礎数値!H11-R61+基礎数値!H12 -> 25385530874
E62: 税控除できない額 | R62: =ROUNDDOWN(R61*0.2*78/1100,0) -> 490 | Y62: 課税仕入れに係る消費税額 | AI62: =ROUNDDOWN((AK60-R65-R66)*78/1100,0)-R62-R63 -> 1799310462
E63: 免税業者との取引額の税額 | R63: =ROUNDDOWN(R61*78/1100,0)-R62 -> 1963
E64: 課税仕入れから控除するもの
H65: 返還等対価・貸倒れの額 | R65: =基礎数値!H14 -> 10639743 | X65: L | Y65: ※ 「過年度損益修正損」「その他特別損失」の課税支出うち、該当分
...

Sheet (申)計
B1: 消費税等計算チェックシート | AZ1: 単位：円
B2: チェック項目 | E2: 検証 | AZ2: 申告書等
B3: 課税標準等 | C3: 1 | D3: 行政手数料収入を課税売上にしていないか（一部のものを除き、非課税となる） | E3: 「その他営業収益」の「手数料」をチェック
C5: 2 | D5: 土地の貸付（原則非課税）のうち、契約期間が1か月未満の場合や、駐車場その他の施設の利用に伴って土地が使用される場合は課税としているか | E5: 「雑収益」の「その他雑収益」をチェック
C8: 3 | D8: 課税の対象となる対価補償金以外の補償金を課税売上にしていないか（水道管移設保証金、ガス管移設保証金等は不課税）
C11: 4 | D11: 損害賠償金を課税売上にしていないか（一般的には不課税）
C13: 5 | D13: 建物等固定資産（土地を除く）の売却について、差益部分のみを課税売上にしていないか | E13: 「固定資産売却益」及び「土地売却代金」をチェック
C15: 6 | D15: 車両等を購入した場合、下取り価額を課税売上にしていないか
C17: 7 | D17: 土地建物一括譲渡の場合、対価の額の区分は正しいか
C19: 8 | D19: 課税売上額の計算
E20: 収益的収入のうち課税売上（税込） | R20: ='(申)3%'!R20:W20+'(申)5%'!R20:W20+'(申)8%'!R20:W20+'(申)軽8%'!R20:W20+'(申)10%'!R20:W20 -> 20730055582
E21: 資本的収入のうち課税売上（税込） | R21: ='(申)3%'!R21:W21+'(申)5%'!R21:W21+'(申)8%'!R21:W21+'(申)軽8%'!R21:W21+'(申)10%'!R21:W21 -> 39691410 | AJ21: 計 | AK21: =R20+R21 -> 20769746992 | AQ21: A
E23: 課税売上から控除するもの
H24: 仕入対価の返還等の額 | R24: ='(申)3%'!R24:W24+'(申)5%'!R24:W24+'(申)8%'!R24:W24+'(申)軽8%'!R24:W24+'(申)10%'!R24:W24 -> 0 | X24: B
H25: 売上対価の返還等の額 | R25: ='(申)3%'!R25:W25+'(申)5%'!R25:W25+'(申)8%'!R25:W25+'(申)軽8%'!R25:W25+'(申)10%'!R25:W25 -> 10679082 | X25: C
E27: 課税売上額（税抜） | R27: ='(申)3%'!R27:W27+'(申)5%'!R27:W27+'(申)8%'!R27:W27+'(申)軽8%'!R27:W27+'(申)10%'!R27:W27 -> 18871880047 | X27: D | AZ27: 付表２①
E29: 課税標準額（税抜） | R29: ='(申)3%'!R29:W29+'(申)5%'!R29:W29+'(申)8%'!R29:W29+'(申)軽8%'!R29:W29+'(申)10%'!R29:W29 -> 18881588000 | X29: E | AZ29: 付表１①
AZ30: 申告書①
E31: 課税標準額に対する消費税額 | R31: ='(申)3%'!R31:W31+'(申)5%'!R31:W31+'(申)8%'!R31:W31+'(申)軽8%'!R31:W31+'(申)10%'!R31:W31 -> 1472763219 | X31: F | AZ31: 付表１②
AZ32: 申告書②
B33: 課税売上割合 | C33: 1 | D33: 課税売上割合の計算
E34: 課税売上額 | R34: =R27 -> 18871880047 | Y34: ※ Dの額
E35: 免税売上額 | R35: =基礎数値!I8 -> 86860 | X35: G | Y35: ※ 管理課資料、「決算総括表」より | AZ35: 付表２②
E36: 課税資産の譲渡等の対価の額 | R36: =R34+R35 -> 18871966907 | X36: H | Y36: ※ D＋G | AC36: 【課税売上割合の分子】 | AZ36: 申告書⑮ 付表２④⑤
E38: 収益的収入のうち非課税売上（税込） | R38: =基礎数値!I9 -> 22644840 | Y38: ※ 「決算総括表」より
E39: 資本的収入のうち非課税売上（税込） | R39: =基礎数値!I10 -> 45948113 | Y39: ※ 「決算総括表」より | AJ39: 計 | AK39: =R38+R39 -> 68592953 | AQ39: I | AZ39: 付表２⑥
E40: 資産の譲渡等の対価の額 | R40: =R36+AK39 -> 18940559860 | X40: J | Y40: ※ H＋I | AC40: 【課税売上割合の分母】 | AZ40: 申告書⑯
AZ41: 付表２⑦
E42: 課税売上割合 | R42: =ROUNDDOWN(R36/R40,4) -> 0.9963 | Y42: ※ H/J 端数切捨て | AG42: 【付表２記載値】 | AZ42: 付表２⑧
B44: 課税仕入れ | C44: 1 | D44: 土地の借受（原則非課税）のうち、契約期間が1か月未満の場合や、駐車場その他の施設の利用に伴って土地を使用する場合は課税としているか | E44: 賃借料をチェック
C47: 2 | D47: 課税の対象となる対価補償金以外の補償金を課税仕入れにしていないか（水道管移設保証金、ガス管移設保証金等は不課税） | E47: 保証金をチェック
C50: 3 | D50: 損害賠償金を課税仕入れにしていないか（一般的には不課税）
C52: 4 | D52: 免税・非課税・不課税仕入れを課税仕入れにしていないか | E52: 各費目をチェック
C54: 5 | D54: 資産の譲渡損を課税仕入れにしていないか | E54: 固定資産売却損をチェック
C56: 6 | D56: 経過措置対象取引（3%取引）がある場合、課税仕入れを3%取引と4%取引に区分して計算しているか | E56: 該当なし
C58: 7 | D58: 課税仕入れ等の税額の計算
E59: 収益的支出のうち課税支出（税込） | R59: ='(申)3%'!R59:W59+'(申)5%'!R59:W59+'(申)8%'!R59:W59+'(申)軽8%'!R59:W59+'(申)10%'!R59:W59 -> 9134353866
E60: 資本的支出のうち課税支出（税込） | R60: ='(申)3%'!R60:W60+'(申)5%'!R60:W60+'(申)8%'!R60:W60+'(申)軽8%'!R60:W60+'(申)10%'!R60:W60 -> 16278899176 | AJ60: 計 | AK60: ='(申)3%'!AK60:AP60+'(申)5%'!AK60:AP60+'(申)8%'!AK60:AP60+'(申)軽8%'!AK60:AP60+'(申)10%'!AK60:AP60 -> 25413253042 | AQ60: K
E64: 課税仕入れから控除するもの
H65: 返還等対価・貸倒れの額 | R65: ='(申)3%'!R65:W65+'(申)5%'!R65:W65+'(申)8%'!R65:W65+'(申)軽8%'!R65:W65+'(申)10%'!R65:W65 -> 36467079 | X65: L
...

Sheet 消費税旧
A1: =+CONCATENATE("令和",MID([1]雨汚水!D1,3,1),"年度決算における消費税額チェック") -> 令和５年度決算における消費税額チェック
B3: ３条税込み収入額 | D3: =+'[2]3条収入'!E69 -> 44454711283 | H3: 【消費税雑支出】
B4: ３条税抜き収入額（消費税雑収入除く。） | D4: =+'[2]3条収入'!AI69-'[2]3条収入'!AI54 -> 42570161569 | I4: 調整項目 | J4: 雑支出計上 | K4: 雑収益計上
B5: ３条仮受消費税（控除前課税標準額） | D5: =D3-D4 -> 1884549714 | E5: A | I5: 特定収入に係る課税仕入れ等の税額 | J5: ='[2]3条収入'!AH69 -> 210253123
B6: 課税標準額から控除するものに係る税額 | D6: =SUM(J49:J51) -> 0 | E6: B | I6: 仮受消費税からの控除
B7: 課税標準額に対する消費税額 | D7: =D3-D4-D6 -> 1884549714 | E7: ①=A-B | I7: 仮払消費税からの控除
B8: ３条税込み支出額（消費税除く。） | D8: =+'[3]3条支出'!E41 -> 42643669657 | I8: 課税売上割合を乗じることにより控除できなくなった額 ⑦=②-③-（④-⑤） | J8: =D12-G12-(D13-G13) -> 2233728
B9: ３条税抜き支出額（消費税雑支出除く。） | D9: =+'[3]3条支出'!T41-[3]営外!T17-[3]営外!T18-[3]営外!$T$19 -> 41815647458 | I9: 免税事業者に係る控除不能額 | J9: =-J77 -> 629
B10: ３条仮払消費税（控除前） | D10: =D8-D9 -> 828022199 | E10: C
B11: 課税仕入れから控除する税額 | D11: =SUM(J63:J72) -> 970163 | E11: D | I11: 返還等対価、貸倒れに係る税額 | K11: =-SUM(J73:J77) -> -1879936
B12: 課税仕入れに係る消費税額（控除後） | D12: =D8-D9-D11 -> 827052036 | E12: ②=C-D | F12: 課税仕入等の税額（②×課税売上割合） | G12: =ROUNDDOWN(D12*G43/G44,0) -> 824056879 | H12: ③ | I12: 計 | J12: =SUM(J5:J11) -> 212487480 | K12: =SUM(K5:K11) -> -1879936
B13: ３条の控除不可消費税（雑支出） | D13: =+'[2]3条収入'!AH69 -> 210253123 | E13: ④ | F13: 特定収入に係る課税仕入の額（④×課税売上割合） | G13: =ROUNDDOWN(D13*G43/G44,0) -> 209491694 | H13: ⑤ | J13: =+SUM(J7:J9) -> 2234357 | K13: =+IF(J13=[3]営外!T18+[3]営外!T19,"←営外シートR18と一致","←左の値を営外シートR18に直打ち入力すること") -> ←左の値を営外シートR18に直打ち入力すること
F14: 返還等対価、貸倒れに係る税額 | G14: =SUM(J68:J77) -> 2850099 | H14: E | K14: ↑現在の決算作業では、計算式により消費税シートから値が飛ぶようになっているため不要
F15: 仕入控除税額（③－⑤＋E） | G15: =G12-G13+G14 -> 617415284 | H15: ⑥
B16: ３条で納付すべき消費税 | D16: =D7-G15 -> 1267134430 | E16: ｱ=①－⑥
B18: ４条税込み収入額 | D18: =+'[4]4条収入'!E91 -> 42025205141
B19: ４条税抜き収入額 | D19: =+'[4]4条収入'!AI91 -> 42021596831
B20: ４条仮受消費税 | D20: =D18-D19 -> 3608310 | E20: ①' | I20: 課税売上割合を乗じることにより控除できなくなった額 ⑦'=②'-③'-（④'-⑤'）
B21: ４条税込み支出額 | D21: =+'[5]4条支出'!E41 -> 61875977537 | I21: =D23-G23-(D24-G24) -> 3370060
B22: ４条税抜き支出額 | D22: =+'[5]4条支出'!T41 -> 60396080350
B23: ４条仮払消費税 | D23: =D21-D22 -> 1479897187 | E23: ②' | F23: 課税仕入等の税額（②'×課税売上割合） | G23: =ROUNDDOWN(D23*G43/G44,0) -> 1474537761 | H23: ③'
B24: ４条の控除不可消費税 | D24: =+'[4]4条収入'!AH91 -> 549323121 | E24: ④' | F24: 特定収入に係る課税仕入の額（④'×課税売上割合） | G24: =ROUNDDOWN(D24*G43/G44,0) -> 547333755 | H24: ⑤'
F25: 仕入控除税額（③'－⑤'） | G25: =G23-G24 -> 927204006 | H25: ⑥'
B26: ４条で納付すべき消費税（資本的収支調整額） | D26: =D20-G25 -> -923595696 | E26: ｲ=①'－⑥'
B28: 下水道事業会計消費税納付額 | D28: =D16+D26 -> 343538734 | E28: ｱ+ｲ
B29: 決算計上消費税額 | D29: =+'[6](繰)3条支出 '!G22 -> 0
B30: 差引き | D30: =D28-D29 -> 343538734
F33: ３条課税売上額 (a) | G33: =+'[2]3条収入'!K69 -> 20730055582
F34: ３条仮受消費税額 (b) | G34: =D5 -> 1884549714
C35: 申告納付額（実際の納付額） | D35: =+'(申)計'!T146+'(申)計'!T154+'(申)計'!T159 -> 343538600 | F35: 課税売上から控除するもの (ｱ) | G35: =SUM(I49:I58) -> 9708919
C36: 差 | D36: =D28-D35 -> 134 | F36: ３条非課税収入額 (ｃ) | G36: =+'[2]3条収入'!L69 -> 22644840
F37: ４条課税売上額 (d) | G37: =+'[4]4条収入'!K91 -> 39691410
F38: ４条仮受消費税額 (e) | G38: =D20 -> 3608310
F39: ４条非課税収入額 (f) | G39: =+'[4]4条収入'!L91 -> 45948113
F40: 免税額 | G40: =+'[2]3条収入'!M69 -> 86860
F41: 課税売上割合｛(a-b-ｱ)+(d-e)｝／｛(a-b-ｱ+c)+(d-e+f)｝ | G41: =ROUNDDOWN((G33-G34-G35+G37-G38)/(G33-G34-G35+G36+G37-G38+G39),4) -> 0.9963
F43: 課税資産の譲渡等の対価の額（課税売上（税抜）+免税売上） | G43: =(G33-G34-G35)+(G37-G38)+G40 -> 18871966909
F44: 資産の譲渡等の対価の額（課税売上（税抜）+免税売上+非課税売上） | G44: =(G33-G34-G35+G36)+(G37-G38+G39)+G40 -> 18940559862
F48: ※ 課税売上から控除するもの 内訳 | G48: 税込 | I48: 税抜 | J48: 税額
F49: 仕入対価の返還等の額（3%） | G49: =+対価返還!BC3 -> 0 | H49: → | I49: =+対価返還!BM3 -> 0 | J49: =+G49-I49 -> 0
...

Sheet 対価返還
AV1: 雨水（税込） | AZ1: 汚水 | BC1: 合計 | BD1: チェック | BF1: 雨水（税抜） | BJ1: 汚水（税抜） | BM1: 合計 | BN1: 備考
AV2: 区域内 | AW2: 区域外 | AX2: 一般行政 | AY2: 計 | AZ2: 基準内 | BA2: 基準外 | BB2: 計 | BF2: 区域内 | BG2: 区域外 | BH2: 一般行政 | BI2: 計 | BJ2: 基準内 | BK2: 基準外 | BL2: 計
AS3: 仕入対価の返還等の額（3%） | AT3: 3 | AV3: =+SUMIFS(AV$18:AV$296,$P$18:$P$296,"営業外収益",$AT$18:$AT$296,$AT3)+SUMIFS(AV$18:AV$296,$P$18:$P$296,"特別利益",$AT$18:$AT$296,$AT3) -> 0 | AW3: =+SUMIFS(AW$18:AW$296,$P$18:$P$296,"営業外収益",$AT$18:$AT$296,$AT3)+SUMIFS(AW$18:AW$296,$P$18:$P$296,"特別利益",$AT$18:$AT$296,$AT3) -> 0 | AX3: =+SUMIFS(AX$18:AX$296,$P$18:$P$296,"営業外収益",$AT$18:$AT$296,$AT3)+SUMIFS(AX$18:AX$296,$P$18:$P$296,"特別利益",$AT$18:$AT$296,$AT3) -> 0 | AY3: =+SUMIFS(AY$18:AY$296,$P$18:$P$296,"営業外収益",$AT$18:$AT$296,$AT3)+SUMIFS(AY$18:AY$296,$P$18:$P$296,"特別利益",$AT$18:$AT$296,$AT3) -> 0 | AZ3: =+SUMIFS(AZ$18:AZ$296,$P$18:$P$296,"営業外収益",$AT$18:$AT$296,$AT3)+SUMIFS(AZ$18:AZ$296,$P$18:$P$296,"特別利益",$AT$18:$AT$296,$AT3) -> 0 | BA3: =+SUMIFS(BA$18:BA$296,$P$18:$P$296,"営業外収益",$AT$18:$AT$296,$AT3)+SUMIFS(BA$18:BA$296,$P$18:$P$296,"特別利益",$AT$18:$AT$296,$AT3) -> 0 | BB3: =+SUMIFS(BB$18:BB$296,$P$18:$P$296,"営業外収益",$AT$18:$AT$296,$AT3)+SUMIFS(BB$18:BB$296,$P$18:$P$296,"特別利益",$AT$18:$AT$296,$AT3) -> 0 | BC3: =+SUMIFS(BC$18:BC$296,$P$18:$P$296,"営業外収益",$AT$18:$AT$296,$AT3)+SUMIFS(BC$18:BC$296,$P$18:$P$296,"特別利益",$AT$18:$AT$296,$AT3) -> 0 | BD3: =+SUMIFS(BD$18:BD$296,$P$18:$P$296,"営業外収益",$AT$18:$AT$296,$AT3)+SUMIFS(BD$18:BD$296,$P$18:$P$296,"特別利益",$AT$18:$AT$296,$AT3) -> 0 | BF3: =+IFERROR(ROUNDUP(AV3*100/(100+$AT3),0),AV3) -> 0 | BG3: =+IFERROR(ROUNDUP(AW3*100/(100+$AT3),0),AW3) -> 0 | BH3: =+IFERROR(ROUNDUP(AX3*100/(100+$AT3),0),AX3) -> 0 | BI3: =SUM(BF3:BH3) -> 0 | BJ3: =+IFERROR(ROUNDUP(AZ3*100/(100+$AT3),0),AZ3) -> 0 | BK3: =+IFERROR(ROUNDUP(BA3*100/(100+$AT3),0),BA3) -> 0 | BL3: =SUM(BJ3:BK3) -> 0 | BM3: =+BI3+BL3 -> 0 | BO3: =+BC3-BM3 -> 0
AS4: 仕入対価の返還等の額（5%） | AT4: 5 | AV4: =+SUMIFS(AV$18:AV$296,$P$18:$P$296,"営業外収益",$AT$18:$AT$296,$AT4)+SUMIFS(AV$18:AV$296,$P$18:$P$296,"特別利益",$AT$18:$AT$296,$AT4) -> 0 | AW4: =+SUMIFS(AW$18:AW$296,$P$18:$P$296,"営業外収益",$AT$18:$AT$296,$AT4)+SUMIFS(AW$18:AW$296,$P$18:$P$296,"特別利益",$AT$18:$AT$296,$AT4) -> 0 | AX4: =+SUMIFS(AX$18:AX$296,$P$18:$P$296,"営業外収益",$AT$18:$AT$296,$AT4)+SUMIFS(AX$18:AX$296,$P$18:$P$296,"特別利益",$AT$18:$AT$296,$AT4) -> 0 | AY4: =+SUMIFS(AY$18:AY$296,$P$18:$P$296,"営業外収益",$AT$18:$AT$296,$AT4)+SUMIFS(AY$18:AY$296,$P$18:$P$296,"特別利益",$AT$18:$AT$296,$AT4) -> 0 | AZ4: =+SUMIFS(AZ$18:AZ$296,$P$18:$P$296,"営業外収益",$AT$18:$AT$296,$AT4)+SUMIFS(AZ$18:AZ$296,$P$18:$P$296,"特別利益",$AT$18:$AT$296,$AT4) -> 0 | BA4: =+SUMIFS(BA$18:BA$296,$P$18:$P$296,"営業外収益",$AT$18:$AT$296,$AT4)+SUMIFS(BA$18:BA$296,$P$18:$P$296,"特別利益",$AT$18:$AT$296,$AT4) -> 0 | BB4: =+SUMIFS(BB$18:BB$296,$P$18:$P$296,"営業外収益",$AT$18:$AT$296,$AT4)+SUMIFS(BB$18:BB$296,$P$18:$P$296,"特別利益",$AT$18:$AT$296,$AT4) -> 0 | BC4: =+SUMIFS(BC$18:BC$296,$P$18:$P$296,"営業外収益",$AT$18:$AT$296,$AT4)+SUMIFS(BC$18:BC$296,$P$18:$P$296,"特別利益",$AT$18:$AT$296,$AT4) -> 0 | BD4: =+SUMIFS(BD$18:BD$296,$P$18:$P$296,"営業外収益",$AT$18:$AT$296,$AT4)+SUMIFS(BD$18:BD$296,$P$18:$P$296,"特別利益",$AT$18:$AT$296,$AT4) -> 0 | BF4: =+IFERROR(ROUNDUP(AV4*100/(100+$AT4),0),AV4) -> 0 | BG4: =+IFERROR(ROUNDUP(AW4*100/(100+$AT4),0),AW4) -> 0 | BH4: =+IFERROR(ROUNDUP(AX4*100/(100+$AT4),0),AX4) -> 0 | BI4: =SUM(BF4:BH4) -> 0 | BJ4: =+IFERROR(ROUNDUP(AZ4*100/(100+$AT4),0),AZ4) -> 0 | BK4: =+IFERROR(ROUNDUP(BA4*100/(100+$AT4),0),BA4) -> 0 | BL4: =SUM(BJ4:BK4) -> 0 | BM4: =+BI4+BL4 -> 0 | BO4: =+BC4-BM4 -> 0
AS5: 仕入対価の返還等の額（8%） | AT5: 8 | AV5: =+SUMIFS(AV$18:AV$296,$P$18:$P$296,"営業外収益",$AT$18:$AT$296,$AT5)+SUMIFS(AV$18:AV$296,$P$18:$P$296,"特別利益",$AT$18:$AT$296,$AT5) -> 0 | AW5: =+SUMIFS(AW$18:AW$296,$P$18:$P$296,"営業外収益",$AT$18:$AT$296,$AT5)+SUMIFS(AW$18:AW$296,$P$18:$P$296,"特別利益",$AT$18:$AT$296,$AT5) -> 0 | AX5: =+SUMIFS(AX$18:AX$296,$P$18:$P$296,"営業外収益",$AT$18:$AT$296,$AT5)+SUMIFS(AX$18:AX$296,$P$18:$P$296,"特別利益",$AT$18:$AT$296,$AT5) -> 0 | AY5: =+SUMIFS(AY$18:AY$296,$P$18:$P$296,"営業外収益",$AT$18:$AT$296,$AT5)+SUMIFS(AY$18:AY$296,$P$18:$P$296,"特別利益",$AT$18:$AT$296,$AT5) -> 0 | AZ5: =+SUMIFS(AZ$18:AZ$296,$P$18:$P$296,"営業外収益",$AT$18:$AT$296,$AT5)+SUMIFS(AZ$18:AZ$296,$P$18:$P$296,"特別利益",$AT$18:$AT$296,$AT5) -> 0 | BA5: =+SUMIFS(BA$18:BA$296,$P$18:$P$296,"営業外収益",$AT$18:$AT$296,$AT5)+SUMIFS(BA$18:BA$296,$P$18:$P$296,"特別利益",$AT$18:$AT$296,$AT5) -> 0 | BB5: =+SUMIFS(BB$18:BB$296,$P$18:$P$296,"営業外収益",$AT$18:$AT$296,$AT5)+SUMIFS(BB$18:BB$296,$P$18:$P$296,"特別利益",$AT$18:$AT$296,$AT5) -> 0 | BC5: =+SUMIFS(BC$18:BC$296,$P$18:$P$296,"営業外収益",$AT$18:$AT$296,$AT5)+SUMIFS(BC$18:BC$296,$P$18:$P$296,"特別利益",$AT$18:$AT$296,$AT5) -> 0 | BD5: =+SUMIFS(BD$18:BD$296,$P$18:$P$296,"営業外収益",$AT$18:$AT$296,$AT5)+SUMIFS(BD$18:BD$296,$P$18:$P$296,"特別利益",$AT$18:$AT$296,$AT5) -> 0 | BF5: =+IFERROR(ROUNDUP(AV5*100/(100+$AT5),0),AV5) -> 0 | BG5: =+IFERROR(ROUNDUP(AW5*100/(100+$AT5),0),AW5) -> 0 | BH5: =+IFERROR(ROUNDUP(AX5*100/(100+$AT5),0),AX5) -> 0 | BI5: =SUM(BF5:BH5) -> 0 | BJ5: =+IFERROR(ROUNDUP(AZ5*100/(100+$AT5),0),AZ5) -> 0 | BK5: =+IFERROR(ROUNDUP(BA5*100/(100+$AT5),0),BA5) -> 0 | BL5: =SUM(BJ5:BK5) -> 0 | BM5: =+BI5+BL5 -> 0 | BO5: =+BC5-BM5 -> 0
AS6: 仕入対価の返還等の額（8%（軽）） | AT6: 8 | AV6: =+SUMIFS(AV$18:AV$296,$P$18:$P$296,"営業外収益",$AS$18:$AS$296,81)+SUMIFS(AV$18:AV$296,$P$18:$P$296,"特別利益",$AS$18:$AS$296,81) -> 0 | AW6: =+SUMIFS(AW$18:AW$296,$P$18:$P$296,"営業外収益",$AS$18:$AS$296,81)+SUMIFS(AW$18:AW$296,$P$18:$P$296,"特別利益",$AS$18:$AS$296,81) -> 0 | AX6: =+SUMIFS(AX$18:AX$296,$P$18:$P$296,"営業外収益",$AS$18:$AS$296,81)+SUMIFS(AX$18:AX$296,$P$18:$P$296,"特別利益",$AS$18:$AS$296,81) -> 0 | AY6: =+SUMIFS(AY$18:AY$296,$P$18:$P$296,"営業外収益",$AS$18:$AS$296,81)+SUMIFS(AY$18:AY$296,$P$18:$P$296,"特別利益",$AS$18:$AS$296,81) -> 0 | AZ6: =+SUMIFS(AZ$18:AZ$296,$P$18:$P$296,"営業外収益",$AS$18:$AS$296,81)+SUMIFS(AZ$18:AZ$296,$P$18:$P$296,"特別利益",$AS$18:$AS$296,81) -> 0 | BA6: =+SUMIFS(BA$18:BA$296,$P$18:$P$296,"営業外収益",$AS$18:$AS$296,81)+SUMIFS(BA$18:BA$296,$P$18:$P$296,"特別利益",$AS$18:$AS$296,81) -> 0 | BB6: =+SUMIFS(BB$18:BB$296,$P$18:$P$296,"営業外収益",$AS$18:$AS$296,81)+SUMIFS(BB$18:BB$296,$P$18:$P$296,"特別利益",$AS$18:$AS$296,81) -> 0 | BC6: =+SUMIFS(BC$18:BC$296,$P$18:$P$296,"営業外収益",$AS$18:$AS$296,81)+SUMIFS(BC$18:BC$296,$P$18:$P$296,"特別利益",$AS$18:$AS$296,81) -> 0 | BD6: =+SUMIFS(BD$18:BD$296,$P$18:$P$296,"営業外収益",$AS$18:$AS$296,81)+SUMIFS(BD$18:BD$296,$P$18:$P$296,"特別利益",$AS$18:$AS$296,81) -> 0 | BF6: =+IFERROR(ROUNDUP(AV6*100/(100+$AT6),0),AV6) -> 0 | BG6: =+IFERROR(ROUNDUP(AW6*100/(100+$AT6),0),AW6) -> 0 | BH6: =+IFERROR(ROUNDUP(AX6*100/(100+$AT6),0),AX6) -> 0 | BI6: =SUM(BF6:BH6) -> 0 | BJ6: =+IFERROR(ROUNDUP(AZ6*100/(100+$AT6),0),AZ6) -> 0 | BK6: =+IFERROR(ROUNDUP(BA6*100/(100+$AT6),0),BA6) -> 0 | BL6: =SUM(BJ6:BK6) -> 0 | BM6: =+BI6+BL6 -> 0 | BO6: =+BC6-BM6 -> 0
AS7: 仕入対価の返還等の額（10%） | AT7: 10 | AV7: =+SUMIFS(AV$18:AV$296,$P$18:$P$296,"営業外収益",$AT$18:$AT$296,$AT7)+SUMIFS(AV$18:AV$296,$P$18:$P$296,"特別利益",$AT$18:$AT$296,$AT7) -> 0 | AW7: =+SUMIFS(AW$18:AW$296,$P$18:$P$296,"営業外収益",$AT$18:$AT$296,$AT7)+SUMIFS(AW$18:AW$296,$P$18:$P$296,"特別利益",$AT$18:$AT$296,$AT7) -> 0 | AX7: =+SUMIFS(AX$18:AX$296,$P$18:$P$296,"営業外収益",$AT$18:$AT$296,$AT7)+SUMIFS(AX$18:AX$296,$P$18:$P$296,"特別利益",$AT$18:$AT$296,$AT7) -> 0 | AY7: =+SUMIFS(AY$18:AY$296,$P$18:$P$296,"営業外収益",$AT$18:$AT$296,$AT7)+SUMIFS(AY$18:AY$296,$P$18:$P$296,"特別利益",$AT$18:$AT$296,$AT7) -> 0 | AZ7: =+SUMIFS(AZ$18:AZ$296,$P$18:$P$296,"営業外収益",$AT$18:$AT$296,$AT7)+SUMIFS(AZ$18:AZ$296,$P$18:$P$296,"特別利益",$AT$18:$AT$296,$AT7) -> 0 | BA7: =+SUMIFS(BA$18:BA$296,$P$18:$P$296,"営業外収益",$AT$18:$AT$296,$AT7)+SUMIFS(BA$18:BA$296,$P$18:$P$296,"特別利益",$AT$18:$AT$296,$AT7) -> 0 | BB7: =+SUMIFS(BB$18:BB$296,$P$18:$P$296,"営業外収益",$AT$18:$AT$296,$AT7)+SUMIFS(BB$18:BB$296,$P$18:$P$296,"特別利益",$AT$18:$AT$296,$AT7) -> 0 | BC7: =+SUMIFS(BC$18:BC$296,$P$18:$P$296,"営業外収益",$AT$18:$AT$296,$AT7)+SUMIFS(BC$18:BC$296,$P$18:$P$296,"特別利益",$AT$18:$AT$296,$AT7) -> 0 | BD7: =+SUMIFS(BD$18:BD$296,$P$18:$P$296,"営業外収益",$AT$18:$AT$296,$AT7)+SUMIFS(BD$18:BD$296,$P$18:$P$296,"特別利益",$AT$18:$AT$296,$AT7) -> 0 | BF7: =+IFERROR(ROUNDUP(AV7*100/(100+$AT7),0),AV7) -> 0 | BG7: =+IFERROR(ROUNDUP(AW7*100/(100+$AT7),0),AW7) -> 0 | BH7: =+IFERROR(ROUNDUP(AX7*100/(100+$AT7),0),AX7) -> 0 | BI7: =SUM(BF7:BH7) -> 0 | BJ7: =+IFERROR(ROUNDUP(AZ7*100/(100+$AT7),0),AZ7) -> 0 | BK7: =+IFERROR(ROUNDUP(BA7*100/(100+$AT7),0),BA7) -> 0 | BL7: =SUM(BJ7:BK7) -> 0 | BM7: =+BI7+BL7 -> 0 | BO7: =+BC7-BM7 -> 0
AS8: 仕入対価の返還の額 計 | AV8: =+SUM(AV3:AV7) -> 0 | AW8: =+SUM(AW3:AW7) -> 0 | AX8: =+SUM(AX3:AX7) -> 0 | AY8: =+SUM(AY3:AY7) -> 0 | AZ8: =+SUM(AZ3:AZ7) -> 0 | BA8: =+SUM(BA3:BA7) -> 0 | BB8: =+SUM(BB3:BB7) -> 0 | BC8: =+SUM(BC3:BC7) -> 0 | ... BM8: =+SUM(BM3:BM7) -> 0 | BO8: =+BC8-BM8 -> 0
AS9: 売上対価の返還等の額（3%） | AT9: 3 | AV9: =+SUMIFS(AV$18:AV$296,$P$18:$P$296,"営業外費用",$AT$18:$AT$296,$AT9)+SUMIFS(AV$18:AV$296,$P$18:$P$296,"特別損失",$AT$18:$AT$296,$AT9) -> 0 | AW9: =+SUMIFS(AW$18:AW$296,$P$18:$P$296,"営業外費用",$AT$18:$AT$296,$AT9)+SUMIFS(AW$18:AW$296,$P$18:$P$296,"特別損失",$AT$18:$AT$296,$AT9) -> 0 | AX9: =+SUMIFS(AX$18:AX$296,$P$18:$P$296,"営業外費用",$AT$18:$AT$296,$AT9)+SUMIFS(AX$18:AX$296,$P$18:$P$296,"特別損失",$AT$18:$AT$296,$AT9) -> 0 | AY9: =+SUMIFS(AY$18:AY$296,$P$18:$P$296,"営業外費用",$AT$18:$AT$296,$AT9)+SUMIFS(AY$18:AY$296,$P$18:$P$296,"特別損失",$AT$18:$AT$296,$AT9) -> 0 | AZ9: =+SUMIFS(AZ$18:AZ$296,$P$18:$P$296,"営業外費用",$AT$18:$AT$296,$AT9)+SUMIFS(AZ$18:AZ$296,$P$18:$P$296,"特別損失",$AT$18:$AT$296,$AT9) -> 0 | BA9: =+SUMIFS(BA$18:BA$296,$P$18:$P$296,"営業外費用",$AT$18:$AT$296,$AT9)+SUMIFS(BA$18:BA$296,$P$18:$P$296,"特別損失",$AT$18:$AT$296,$AT9) -> 0 | BB9: =+SUMIFS(BB$18:BB$296,$P$18:$P$296,"営業外費用",$AT$18:$AT$296,$AT9)+SUMIFS(BB$18:BB$296,$P$18:$P$296,"特別損失",$AT$18:$AT$296,$AT9) -> 0 | BC9: =+SUMIFS(BC$18:BC$296,$P$18:$P$296,"営業外費用",$AT$18:$AT$296,$AT9)+SUMIFS(BC$18:BC$296,$P$18:$P$296,"特別損失",$AT$18:$AT$296,$AT9) -> 0 | BD9: =+SUMIFS(BD$18:BD$296,$P$18:$P$296,"営業外費用",$AT$18:$AT$296,$AT9)+SUMIFS(BD$18:BD$296,$P$18:$P$296,"特別損失",$AT$18:$AT$296,$AT9) -> 0 | BF9: =+IFERROR(ROUNDUP(AV9*100/(100+$AT9),0),AV9) -> 0 | BG9: =+IFERROR(ROUNDUP(AW9*100/(100+$AT9),0),AW9) -> 0 | BH9: =+IFERROR(ROUNDUP(AX9*100/(100+$AT9),0),AX9) -> 0 | BI9: =SUM(BF9:BH9) -> 0 | BJ9: =+IFERROR(ROUNDUP(AZ9*100/(100+$AT9),0),AZ9) -> 0 | BK9: =+IFERROR(ROUNDUP(BA9*100/(100+$AT9),0),BA9) -> 0 | BL9: =SUM(BJ9:BK9) -> 0 | BM9: =+BI9+BL9 -> 0 | BO9: =+BC9-BM9 -> 0
AS10: 売上対価の返還等の額（5%） | AT10: 5 | AV10: =+SUMIFS(AV$18:AV$296,$P$18:$P$296,"営業外費用",$AT$18:$AT$296,$AT10)+SUMIFS(AV$18:AV$296,$P$18:$P$296,"特別損失",$AT$18:$AT$296,$AT10) -> 0 | AW10: =+SUMIFS(AW$18:AW$296,$P$18:$P$296,"営業外費用",$AT$18:$AT$296,$AT10)+SUMIFS(AW$18:AW$296,$P$18:$P$296,"特別損失",$AT$18:$AT$296,$AT10) -> 0 | AX10: =+SUMIFS(AX$18:AX$296,$P$18:$P$296,"営業外費用",$AT$18:$AT$296,$AT10)+SUMIFS(AX$18:AX$296,$P$18:$P$296,"特別損失",$AT$18:$AT$296,$AT10) -> 0 | AY10: =+SUMIFS(AY$18:AY$296,$P$18:$P$296,"営業外費用",$AT$18:$AT$296,$AT10)+SUMIFS(AY$18:AY$296,$P$18:$P$296,"特別損失",$AT$18:$AT$296,$AT10) -> 0 | AZ10: =+SUMIFS(AZ$18:AZ$296,$P$18:$P$296,"営業外費用",$AT$18:$AT$296,$AT10)+SUMIFS(AZ$18:AZ$296,$P$18:$P$296,"特別損失",$AT$18:$AT$296,$AT10) -> 0 | BA10: =+SUMIFS(BA$18:BA$296,$P$18:$P$296,"営業外費用",$AT$18:$AT$296,$AT10)+SUMIFS(BA$18:BA$296,$P$18:$P$296,"特別損失",$AT$18:$AT$296,$AT10) -> 0 | BB10: =+SUMIFS(BB$18:BB$296,$P$18:$P$296,"営業外費用",$AT$18:$AT$296,$AT10)+SUMIFS(BB$18:BB$296,$P$18:$P$296,"特別損失",$AT$18:$AT$296,$AT10) -> 0 | BC10: =+SUMIFS(BC$18:BC$296,$P$18:$P$296,"営業外費用",$AT$18:$AT$296,$AT10)+SUMIFS(BC$18:BC$296,$P$18:$P$296,"特別損失",$AT$18:$AT$296,$AT10) -> 0 | BD10: =+SUMIFS(BD$18:BD$296,$P$18:$P$296,"営業外費用",$AT$18:$AT$296,$AT10)+SUMIFS(BD$18:BD$296,$P$18:$P$296,"特別損失",$AT$18:$AT$296,$AT10) -> 0 | BF10: =+IFERROR(ROUNDUP(AV10*100/(100+$AT10),0),AV10) -> 0 | BG10: =+IFERROR(ROUNDUP(AW10*100/(100+$AT10),0),AW10) -> 0 | BH10: =+IFERROR(ROUNDUP(AX10*100/(100+$AT10),0),AX10) -> 0 | BI10: =SUM(BF10:BH10) -> 0 | BJ10: =+IFERROR(ROUNDUP(AZ10*100/(100+$AT10),0),AZ10) -> 0 | BK10: =+IFERROR(ROUNDUP(BA10*100/(100+$AT10),0),BA10) -> 0 | BL10: =SUM(BJ10:BK10) -> 0 | BM10: =+BI10+BL10 -> 0 | BO10: =+BC10-BM10 -> 0
AS11: 売上対価の返還等の額（8%） | AT11: 8 | AV11: =+SUMIFS(AV$18:AV$296,$P$18:$P$296,"営業外費用",$AT$18:$AT$296,$AT11)+SUMIFS(AV$18:AV$296,$P$18:$P$296,"特別損失",$AT$18:$AT$296,$AT11) -> 0 | AW11: =+SUMIFS(AW$18:AW$296,$P$18:$P$296,"営業外費用",$AT$18:$AT$296,$AT11)+SUMIFS(AW$18:AW$296,$P$18:$P$296,"特別損失",$AT$18:$AT$296,$AT11) -> 0 | AX11: =+SUMIFS(AX$18:AX$296,$P$18:$P$296,"営業外費用",$AT$18:$AT$296,$AT11)+SUMIFS(AX$18:AX$296,$P$18:$P$296,"特別損失",$AT$18:$AT$296,$AT11) -> 0 | AY11: =+SUMIFS(AY$18:AY$296,$P$18:$P$296,"営業外費用",$AT$18:$AT$296,$AT11)+SUMIFS(AY$18:AY$296,$P$18:$P$296,"特別損失",$AT$18:$AT$296,$AT11) -> 0 | AZ11: =+SUMIFS(AZ$18:AZ$296,$P$18:$P$296,"営業外費用",$AT$18:$AT$296,$AT11)+SUMIFS(AZ$18:AZ$296,$P$18:$P$296,"特別損失",$AT$18:$AT$296,$AT11) -> 0 | BA11: =+SUMIFS(BA$18:BA$296,$P$18:$P$296,"営業外費用",$AT$18:$AT$296,$AT11)+SUMIFS(BA$18:BA$296,$P$18:$P$296,"特別損失",$AT$18:$AT$296,$AT11) -> 39339 | BB11: =+SUMIFS(BB$18:BB$296,$P$18:$P$296,"営業外費用",$AT$18:$AT$296,$AT11)+SUMIFS(BB$18:BB$296,$P$18:$P$296,"特別損失",$AT$18:$AT$296,$AT11) -> 39339 | BC11: =+SUMIFS(BC$18:BC$296,$P$18:$P$296,"営業外費用",$AT$18:$AT$296,$AT11)+SUMIFS(BC$18:BC$296,$P$18:$P$296,"特別損失",$AT$18:$AT$296,$AT11) -> 39339 | BD11: =+SUMIFS(BD$18:BD$296,$P$18:$P$296,"営業外費用",$AT$18:$AT$296,$AT11)+SUMIFS(BD$18:BD$296,$P$18:$P$296,"特別損失",$AT$18:$AT$296,$AT11) -> 0 | BF11: =+IFERROR(ROUNDUP(AV11*100/(100+$AT11),0),AV11) -> 0 | BG11: =+IFERROR(ROUNDUP(AW11*100/(100+$AT11),0),AW11) -> 0 | BH11: =+IFERROR(ROUNDUP(AX11*100/(100+$AT11),0),AX11) -> 0 | BI11: =SUM(BF11:BH11) -> 0 | BJ11: =+IFERROR(ROUNDUP(AZ11*100/(100+$AT11),0),AZ11) -> 0 | BK11: =+IFERROR(ROUNDUP(BA11*100/(100+$AT11),0),BA11) -> 36425 | BL11: =SUM(BJ11:BK11) -> 36425 | BM11: =+BI11+BL11 -> 36425 | BO11: =+BC11-BM11 -> 2914
AS12: 売上対価の返還等の額（8%（軽）） | AT12: 8 | AV12: =+SUMIFS(AV$18:AV$296,$P$18:$P$296,"営業外費用",$AS$18:$AS$296,82)+SUMIFS(AV$18:AV$296,$P$18:$P$296,"特別損失",$AS$18:$AS$296,82) -> 0 | AW12: =+SUMIFS(AW$18:AW$296,$P$18:$P$296,"営業外費用",$AS$18:$AS$296,82)+SUMIFS(AW$18:AW$296,$P$18:$P$296,"特別損失",$AS$18:$AS$296,82) -> 0 | AX12: =+SUMIFS(AX$18:AX$296,$P$18:$P$296,"営業外費用",$AS$18:$AS$296,82)+SUMIFS(AX$18:AX$296,$P$18:$P$296,"特別損失",$AS$18:$AS$296,82) -> 0 | AY12: =+SUMIFS(AY$18:AY$296,$P$18:$P$296,"営業外費用",$AS$18:$AS$296,82)+SUMIFS(AY$18:AY$296,$P$18:$P$296,"特別損失",$AS$18:$AS$296,82) -> 0 | AZ12: =+SUMIFS(AZ$18:AZ$296,$P$18:$P$296,"営業外費用",$AS$18:$AS$296,82)+SUMIFS(AZ$18:AZ$296,$P$18:$P$296,"特別損失",$AS$18:$AS$296,82) -> 0 | BA12: =+SUMIFS(BA$18:BA$296,$P$18:$P$296,"営業外費用",$AS$18:$AS$296,82)+SUMIFS(BA$18:BA$296,$P$18:$P$296,"特別損失",$AS$18:$AS$296,82) -> 0 | BB12: =+SUMIFS(BB$18:BB$296,$P$18:$P$296,"営業外費用",$AS$18:$AS$296,82)+SUMIFS(BB$18:BB$296,$P$18:$P$296,"特別損失",$AS$18:$AS$296,82) -> 0 | BC12: =+SUMIFS(BC$18:BC$296,$P$18:$P$296,"営業外費用",$AS$18:$AS$296,82)+SUMIFS(BC$18:BC$296,$P$18:$P$296,"特別損失",$AS$18:$AS$296,82) -> 0 | BD12: =+SUMIFS(BD$18:BD$296,$P$18:$P$296,"営業外費用",$AS$18:$AS$296,82)+SUMIFS(BD$18:BD$296,$P$18:$P$296,"特別損失",$AS$18:$AS$296,82) -> 0 | BF12: =+IFERROR(ROUNDUP(AV12*100/(100+$AT12),0),AV12) -> 0 | BG12: =+IFERROR(ROUNDUP(AW12*100/(100+$AT12),0),AW12) -> 0 | BH12: =+IFERROR(ROUNDUP(AX12*100/(100+$AT12),0),AX12) -> 0 | BI12: =SUM(BF12:BH12) -> 0 | BJ12: =+IFERROR(ROUNDUP(AZ12*100/(100+$AT12),0),AZ12) -> 0 | BK12: =+IFERROR(ROUNDUP(BA12*100/(100+$AT12),0),BA12) -> 0 | BL12: =SUM(BJ12:BK12) -> 0 | BM12: =+BI12+BL12 -> 0 | BO12: =+BC12-BM12 -> 0
AS13: 売上対価の返還等の額（10%） | AT13: 10 | AV13: =+SUMIFS(AV$18:AV$296,$P$18:$P$296,"営業外費用",$AT$18:$AT$296,$AT13)+SUMIFS(AV$18:AV$296,$P$18:$P$296,"特別損失",$AT$18:$AT$296,$AT13) -> 0 | AW13: =+SUMIFS(AW$18:AW$296,$P$18:$P$296,"営業外費用",$AT$18:$AT$296,$AT13)+SUMIFS(AW$18:AW$296,$P$18:$P$296,"特別損失",$AT$18:$AT$296,$AT13) -> 0 | AX13: =+SUMIFS(AX$18:AX$296,$P$18:$P$296,"営業外費用",$AT$18:$AT$296,$AT13)+SUMIFS(AX$18:AX$296,$P$18:$P$296,"特別損失",$AT$18:$AT$296,$AT13) -> 0 | AY13: =+SUMIFS(AY$18:AY$296,$P$18:$P$296,"営業外費用",$AT$18:$AT$296,$AT13)+SUMIFS(AY$18:AY$296,$P$18:$P$296,"特別損失",$AT$18:$AT$296,$AT13) -> 0 | AZ13: =+SUMIFS(AZ$18:AZ$296,$P$18:$P$296,"営業外費用",$AT$18:$AT$296,$AT13)+SUMIFS(AZ$18:AZ$296,$P$18:$P$296,"特別損失",$AT$18:$AT$296,$AT13) -> 0 | BA13: =+SUMIFS(BA$18:BA$296,$P$18:$P$296,"営業外費用",$AT$18:$AT$296,$AT13)+SUMIFS(BA$18:BA$296,$P$18:$P$296,"特別損失",$AT$18:$AT$296,$AT13) -> 10639743 | BB13: =+SUMIFS(BB$18:BB$296,$P$18:$P$296,"営業外費用",$AT$18:$AT$296,$AT13)+SUMIFS(BB$18:BB$296,$P$18:$P$296,"特別損失",$AT$18:$AT$296,$AT13) -> 10639743 | BC13: =+SUMIFS(BC$18:BC$296,$P$18:$P$296,"営業外費用",$AT$18:$AT$296,$AT13)+SUMIFS(BC$18:BC$296,$P$18:$P$296,"特別損失",$AT$18:$AT$296,$AT13) -> 10639743 | BD13: =+SUMIFS(BD$18:BD$296,$P$18:$P$296,"営業外費用",$AT$18:$AT$296,$AT13)+SUMIFS(BD$18:BD$296,$P$18:$P$296,"特別損失",$AT$18:$AT$296,$AT13) -> 0 | BF13: =+IFERROR(ROUNDUP(AV13*100/(100+$AT13),0),AV13) -> 0 | BG13: =+IFERROR(ROUNDUP(AW13*100/(100+$AT13),0),AW13) -> 0 | BH13: =+IFERROR(ROUNDUP(AX13*100/(100+$AT13),0),AX13) -> 0 | BI13: =SUM(BF13:BH13) -> 0 | BJ13: =+IFERROR(ROUNDUP(AZ13*100/(100+$AT13),0),AZ13) -> 0 | BK13: =+IFERROR(ROUNDUP(BA13*100/(100+$AT13),0),BA13) -> 9672494 | BL13: =SUM(BJ13:BK13) -> 9672494 | BM13: =+BI13+BL13 -> 9672494 | BO13: =+BC13-BM13 -> 967249
AS14: 売上対価の返還の額 計 | AV14: =+SUM(AV9:AV13) -> 0 | AW14: =+SUM(AW9:AW13) -> 0 | AX14: =+SUM(AX9:AX13) -> 0 | AY14: =+SUM(AY9:AY13) -> 0 | AZ14: =+SUM(AZ9:AZ13) -> 0 | BA14: =+SUM(BA9:BA13) -> 10679082 | BB14: =+SUM(BB9:BB13) -> 10679082 | BC14: =+SUM(BC9:BC13) -> 10679082 | ... BM14: =+SUM(BM9:BM13) -> 9708919 | BO14: =+BC14-BM14 -> 970163
A15: ↓以下がコピペ領域
Y16: =+SUBTOTAL(109,Y18:Y948) -> 10679082 | AV16: =+SUBTOTAL(109,AV18:AV948) -> 0 | AW16: =+SUBTOTAL(109,AW18:AW948) -> 0 | AX16: =+SUBTOTAL(109,AX18:AX948) -> 0 | AY16: =+SUBTOTAL(109,AY18:AY948) -> 0 | AZ16: =+SUBTOTAL(109,AZ18:AZ948) -> 0 | BA16: =+SUBTOTAL(109,BA18:BA948) -> 10679082 | BB16: =+SUBTOTAL(109,BB18:BB948) -> 10679082 | BC16: =+SUBTOTAL(109,BC18:BC948) -> 10679082 | BD16: =+SUBTOTAL(109,BD18:BD948) -> 0 | BF16: =+SUBTOTAL(109,BF18:BF948) -> 0 | BG16: =+SUBTOTAL(109,BG18:BG948) -> 0 | BH16: =+SUBTOTAL(109,BH18:BH948) -> 0 | BI16: =+SUBTOTAL(109,BI18:BI948) -> 0 | BJ16: =+SUBTOTAL(109,BJ18:BJ948) -> 0 | BK16: =+SUBTOTAL(109,BK18:BK948) -> 9708919 | BL16: =+SUBTOTAL(109,BL18:BL948) -> 9708919 | BM16: =+SUBTOTAL(109,BM18:BM948) -> 9708919
AL17: ---- | AS17: 0 | AT17: 0 | AV17: 雨水（税込） | AZ17: 汚水 | BC17: 合計 | BD17: チェック | BF17: 雨水（税込） | BJ17: 汚水 | BM17: 合計 | BN17: 備考
A18: 事業区分 | B18: 所属 | C18: 所属名 | D18: 主管課 | E18: 主管課名 | F18: 年月日 | G18: 振替年月日 | H18: 事項 | I18: 種別 | J18: 伝票番号 | K18: 枝番 | L18: 内訳番号 | M18: 現繰 | N18: 予算科目 | O18: 款名称 | P18: 項名称 | Q18: 目名称 | R18: 節名称 | S18: 細節名称 | T18: 事業コード | U18: 事業名 | V18: 予算額 | W18: 概算額 | X18: 確定額 | Y18: 執行額 | Z18: 借方勘定 | AA18: 借方勘定科目 | AB18: 借方金額 | AC18: 貸方勘定 | AD18: 貸方勘定科目 | AE18: 貸方金額 | AF18: 税区分 | AG18: 税率 | AH18: 税額 | AI18: 税抜金額 | AJ18: 債権者 | AL18: 複合伝票番号 | AM18: 確認状況 | AN18: 正しい課税区分 | AO18: 正しい税率 | AP18: 備考 | AQ18: 重複 | AS18: 集計用課税区分 | AT18: 集計用税率 | AV18: 区域内 | AW18: 区域外 | AX18: 一般行政 | AY18: 計 | AZ18: 基準内 | BA18: 基準外 | BB18: 計 | BF18: 区域内 | BG18: 区域外 | BH18: 一般行政 | BI18: 計 | BJ18: 基準内 | BK18: 基準外 | BL18: 計 | BO18: AAA | BP18: AAA | BQ18: AAA | BR18: AAA | BS18: AAA | BT18: AAA
A19: 1 | D19: 1502110500 | E19: 管理課 | F19: R06/01/10 | G19: R06/01/10 | H19: 下水道使用料返還金の支出 | I19: 振替伝票（未払計上） | J19: 34005121 | K19: 000 | L19: 001 | M19: 1 | N19: 0884066300 | O19: 下水道事業費用 | P19: 営業外費用 | Q19: 雑支出 | R19: その他雑支出 | T19: 921472 | U19: 下水道使用料賦課（返還金） | V19: 0 | W19: 0 | X19: 0 | Y19: 23932 | Z19: 088406001063000000 | AA19: その他雑支出 | AB19: 23932 | AC19: 051410001001000000 | AD19: その他未払金 | AE19: 23932 | AF19: 15 | AG19: 8 | AH19: 1767 | AI19: 22165 | AJ19: 田畑 美香 | AL19: 34005121-000-001-1-0884066300-921472-15 | AM19: 1 | AN19: 0 | AO19: 0 | AP19: 0 | AS19: 15 | AT19: 8 | AV19: 0 | AW19: 0 | AX19: 0 | AY19: 0 | AZ19: 0 | BA19: 23932 | BB19: 23932 | BC19: 23932 | BD19: 0 | BF19: 0 | BG19: 0 | BH19: 0 | BI19: 0 | BJ19: 0 | BK19: 22159 | BL19: 22159 | BM19: 22159
A20: 1 | D20: 1502110500 | E20: 管理課 | F20: R05/11/01 | G20: R05/11/01 | H20: 下水道使用料過誤納還付金の精算（１０月分） | I20: 振替伝票（予算振替） | J20: 37000234 | K20: 000 | L20: 001 | M20: 1 | N20: 0885060600 | O20: 下水道事業費用 | P20: 特別損失 | Q20: 過年度損益修正損 | R20: 過年度損益修正損 | T20: 921481 | U20: 下水道使用料賦課徴収 | V20: 0 | W20: 0 | X20: 0 | Y20: 7639 | Z20: 088506001006000000 | AA20: 過年度損益修正損 | AB20: 7639 | AC20: 022602001006000000 | AD20: 下水道使用料還付前渡資金 | AE20: 7639 | AF20: 18 | AG20: 10 | AH20: 694 | AI20: 6945 | AL20: 37000234-000-001-1-0885060600-921481-18 | AM20: 1 | AN20: 0 | AO20: 0 | AP20: 0 | AS20: 18 | AT20: 10 | AV20: 0 | AW20: 0 | AX20: 0 | AY20: 0 | AZ20: 0 | BA20: 7639 | BB20: 7639 | BC20: 7639 | BD20: 0 | BF20: 0 | BG20: 0 | BH20: 0 | BI20: 0 | BJ20: 0 | BK20: 6945 | BL20: 6945 | BM20: 6945
A21: 1 | D21: 1502110500 | E21: 管理課 | F21: R05/11/01 | G21: R05/11/01 | H21: 下水道使用料過誤納還付金の精算（１０月分） | I21: 振替伝票（予算振替） | J21: 37000235 | K21: 000 | L21: 001 | M21: 1 | N21: 0885060600 | O21: 下水道事業費用 | P21: 特別損失 | Q21: 過年度損益修正損 | R21: 過年度損益修正損 | T21: 921481 | U21: 下水道使用料賦課徴収 | V21: 0 | W21: 0 | X21: 0 | Y21: 3359 | Z21: 088506001006000000 | AA21: 過年度損益修正損 | AB21: 3359 | AC21: 022602001006000000 | AD21: 下水道使用料還付前渡資金 | AE21: 3359 | AF21: 18 | AG21: 10 | AH21: 305 | AI21: 3054 | AL21: 37000235-000-001-1-0885060600-921481-18 | AM21: 1 | AN21: 0 | AO21: 0 | AP21: 0 | AS21: 18 | AT21: 10 | AV21: 0 | AW21: 0 | AX21: 0 | AY21: 0 | AZ21: 0 | BA21: 3359 | BB21: 3359 | BC21: 3359 | BD21: 0 | BF21: 0 | BG21: 0 | BH21: 0 | BI21: 0 | BJ21: 0 | BK21: 3054 | BL21: 3054 | BM21: 3054
A22: 1 | D22: 1502110500 | E22: 管理課 | F22: R05/11/01 | G22: R05/11/01 | H22: 下水道使用料過誤納還付金の精算（１０月分） | I22: 振替伝票（予算振替） | J22: 37000236 | K22: 000 | L22: 001 | M22: 1 | N22: 0885060600 | O22: 下水道事業費用 | P22: 特別損失 | Q22: 過年度損益修正損 | R22: 過年度損益修正損 | T22: 921481 | U22: 下水道使用料賦課徴収 | V22: 0 | W22: 0 | X22: 0 | Y22: 465 | Z22: 088506001006000000 | AA22: 過年度損益修正損 | AB22: 465 | AC22: 022602001006000000 | AD22: 下水道使用料還付前渡資金 | AE22: 465 | AF22: 18 | AG22: 10 | AH22: 42 | AI22: 423 | AL22: 37000236-000-001-1-0885060600-921481-18 | AM22: 1 | AN22: 0 | AO22: 0 | AP22: 0 | AS22: 18 | AT22: 10 | AV22: 0 | AW22: 0 | AX22: 0 | AY22: 0 | AZ22: 0 | BA22: 465 | BB22: 465 | BC22: 465 | BD22: 0 | BF22: 0 | BG22: 0 | BH22: 0 | BI22: 0 | BJ22: 0 | BK22: 423 | BL22: 423 | BM22: 423
A23: 1 | D23: 1502110500 | E23: 管理課 | F23: R05/12/01 | G23: R05/12/01 | H23: 下水道使用料過誤納還付金の精算（１１月分） | I23: 振替伝票（予算振替） | J23: 37000266 | K23: 000 | L23: 001 | M23: 1 | N23: 0885060600 | O23: 下水道事業費用 | P23: 特別損失 | Q23: 過年度損益修正損 | R23: 過年度損益修正損 | T23: 921481 | U23: 下水道使用料賦課徴収 | V23: 0 | W23: 0 | X23: 0 | Y23: 797 | Z23: 088506001006000000 | AA23: 過年度損益修正損 | AB23: 797 | AC23: 022602001006000000 | AD23: 下水道使用料還付前渡資金 | AE23: 797 | AF23: 18 | AG23: 10 | AH23: 72 | AI23: 725 | AL23: 37000266-000-001-1-0885060600-921481-18 | AM23: 1 | AN23: 0 | AO23: 0 | AP23: 0 | AS23: 18 | AT23: 10 | AV23: 0 | AW23: 0 | AX23: 0 | AY23: 0 | AZ23: 0 | BA23: 797 | BB23: 797 | BC23: 797 | BD23: 0 | BF23: 0 | BG23: 0 | BH23: 0 | BI23: 0 | BJ23: 0 | BK23: 725 | BL23: 725 | BM23: 725
A24: 1 | D24: 1502110500 | E24: 管理課 | F24: R05/12/01 | G24: R05/12/01 | H24: 下水道使用料過誤納還付金の精算（１１月分） | I24: 振替伝票（予算振替） | J24: 37000267 | K24: 000 | L24: 001 | M24: 1 | N24: 0885060600 | O24: 下水道事業費用 | P24: 特別損失 | Q24: 過年度損益修正損 | R24: 過年度損益修正損 | T24: 921481 | U24: 下水道使用料賦課徴収 | V24: 0 | W24: 0 | X24: 0 | Y24: 377 | Z24: 088506001006000000 | AA24: 過年度損益修正損 | AB24: 377 | AC24: 022602001006000000 | AD24: 下水道使用料還付前渡資金 | AE24: 377 | AF24: 18 | AG24: 10 | AH24: 32 | AI24: 345 | AL24: 37000267-000-001-1-0885060600-921481-18 | AM24: 1 | AN24: 0 | AO24: 0 | AP24: 0 | AS24: 18 | AT24: 10 | AV24: 0 | AW24: 0 | AX24: 0 | AY24: 0 | AZ24: 0 | BA24: 377 | BB24: 377 | BC24: 377 | BD24: 0 | BF24: 0 | BG24: 0 | BH24: 0 | BI24: 0 | BJ24: 0 | BK24: 343 | BL24: 343 | BM24: 343
A25: 1 | D25: 1502110500 | E25: 管理課 | F25: R05/12/01 | G25: R05/12/01 | H25: 下水道使用料過誤納還付金の精算（１１月分） | I25: 振替伝票（予算振替） | J25: 37000268 | K25: 000 | L25: 001 | M25: 1 | N25: 0885060600 | O25: 下水道事業費用 | P25: 特別損失 | Q25: 過年度損益修正損 | R25: 過年度損益修正損 | T25: 921481 | U25: 下水道使用料賦課徴収 | V25: 0 | W25: 0 | X25: 0 | Y25: 1117 | Z25: 088506001006000000 | AA25: 過年度損益修正損 | AB25: 1117 | AC25: 022602001006000000 | AD25: 下水道使用料還付前渡資金 | AE25: 1117 | AF25: 18 | AG25: 10 | AH25: 101 | AI25: 1016 | AL25: 37000268-000-001-1-0885060600-921481-18 | AM25: 1 | AN25: 0 | AO25: 0 | AP25: 0 | AS25: 18 | AT25: 10 | AV25: 0 | AW25: 0 | AX25: 0 | AY25: 0 | AZ25: 0 | BA25: 1117 | BB25: 1117 | BC25: 1117 | BD25: 0 | BF25: 0 | BG25: 0 | BH25: 0 | BI25: 0 | BJ25: 0 | BK25: 1015 | BL25: 1015 | BM25: 1015
A26: 1 | D26: 1502110500 | E26: 管理課 | F26: R06/01/01 | G26: R06/01/01 | H26: 下水道使用料過誤納還付金の精算（１２月分） | I26: 振替伝票（予算振替） | J26: 37000289 | K26: 000 | L26: 001 | M26: 1 | N26: 0885060600 | O26: 下水道事業費用 | P26: 特別損失 | Q26: 過年度損益修正損 | R26: 過年度損益修正損 | T26: 921481 | U26: 下水道使用料賦課徴収 | V26: 0 | W26: 0 | X26: 0 | Y26: 455 | Z26: 088506001006000000 | AA26: 過年度損益修正損 | AB26: 455 | AC26: 022602001006000000 | AD26: 下水道使用料還付前渡資金 | AE26: 455 | AF26: 18 | AG26: 10 | AH26: 41 | AI26: 414 | AL26: 37000289-000-001-1-0885060600-921481-18 | AM26: 1 | AN26: 0 | AO26: 0 | AP26: 0 | AS26: 18 | AT26: 10 | AV26: 0 | AW26: 0 | AX26: 0 | AY26: 0 | AZ26: 0 | BA26: 455 | BB26: 455 | BC26: 455 | BD26: 0 | BF26: 0 | BG26: 0 | BH26: 0 | BI26: 0 | BJ26: 0 | BK26: 414 | BL26: 414 | BM26: 414
A27: 1 | D27: 1502110500 | E27: 管理課 | F27: R06/01/01 | G27: R06/01/01 | H27: 下水道使用料過誤納還付金の精算（１２月分） | I27: 振替伝票（予算振替） | J27: 37000290 | K27: 000 | L27: 001 | M27: 1 | N27: 0885060600 | O27: 下水道事業費用 | P27: 特別損失 | Q27: 過年度損益修正損 | R27: 過年度損益修正損 | T27: 921481 | U27: 下水道使用料賦課徴収 | V27: 0 | W27: 0 | X27: 0 | Y27: 119045 | Z27: 088506001006000000 | AA27: 過年度損益修正損 | AB27: 119045 | AC27: 022602001006000000 | AD27: 下水道使用料還付前渡資金 | AE27: 119045 | AF27: 18 | AG27: 10 | AH27: 10822 | AI27: 108223 | AL27: 37000290-000-001-1-0885060600-921481-18 | AM27: 1 | AN27: 0 | AO27: 0 | AP27: 0 | AS27: 18 | AT27: 10 | AV27: 0 | AW27: 0 | AX27: 0 | AY27: 0 | AZ27: 0 | BA27: 119045 | BB27: 119045 | BC27: 119045 | BD27: 0 | BF27: 0 | BG27: 0 | BH27: 0 | BI27: 0 | BJ27: 0 | BK27: 108223 | BL27: 108223 | BM27: 108223
A28: 1 | D28: 1502110500 | E28: 管理課 | F28: R06/02/01 | G28: R06/02/01 | H28: 下水道使用料過誤納還付金の精算（１月分） | I28: 振替伝票（予算振替） | J28: 37000354 | K28: 000 | L28: 001 | M28: 1 | N28: 0885060600 | O28: 下水道事業費用 | P28: 特別損失 | Q28: 過年度損益修正損 | R28: 過年度損益修正損 | T28: 921481 | U28: 下水道使用料賦課徴収 | V28: 0 | W28: 0 | X28: 0 | Y28: 46834 | Z28: 088506001006000000 | AA28: 過年度損益修正損 | AB28: 46834 | AC28: 022602001006000000 | AD28: 下水道使用料還付前渡資金 | AE28: 46834 | AF28: 18 | AG28: 10 | AH28: 4257 | AI28: 42577 | AL28: 37000354-000-001-1-0885060600-921481-18 | AM28: 1 | AN28: 0 | AO28: 0 | AP28: 0 | AS28: 18 | AT28: 10 | AV28: 0 | AW28: 0 | AX28: 0 | AY28: 0 | AZ28: 0 | BA28: 46834 | BB28: 46834 | BC28: 46834 | BD28: 0 | BF28: 0 | BG28: 0 | BH28: 0 | BI28: 0 | BJ28: 0 | BK28: 42576 | BL28: 42576 | BM28: 42576
A29: 1 | D29: 1502110500 | E29: 管理課 | F29: R06/02/01 | G29: R06/02/01 | H29: 下水道使用料過誤納還付金の精算（１月分） | I29: 振替伝票（予算振替） | J29: 37000355 | K29: 000 | L29: 001 | M29: 1 | N29: 0885060600 | O29: 下水道事業費用 | P29: 特別損失 | Q29: 過年度損益修正損 | R29: 過年度損益修正損 | T29: 921481 | U29: 下水道使用料賦課徴収 | V29: 0 | W29: 0 | X29: 0 | Y29: 139433 | Z29: 088506001006000000 | AA29: 過年度損益修正損 | AB29: 139433 | AC29: 022602001006000000 | AD29: 下水道使用料還付前渡資金 | AE29: 139433 | AF29: 18 | AG29: 10 | AH29: 12675 | AI29: 126758 | AL29: 37000355-000-001-1-0885060600-921481-18 | AM29: 1 | AN29: 0 | AO29: 0 | AP29: 0 | AS29: 18 | AT29: 10 | AV29: 0 | AW29: 0 | AX29: 0 | AY29: 0 | AZ29: 0 | BA29: 139433 | BB29: 139433 | BC29: 139433 | BD29: 0 | BF29: 0 | BG29: 0 | BH29: 0 | BI29: 0 | BJ29: 0 | BK29: 126757 | BL29: 126757 | BM29: 126757
A30: 1 | D30: 1502110500 | E30: 管理課 | F30: R06/03/01 | G30: R06/03/01 | H30: 下水道使用料過誤納還付金の精算（２月分） | I30: 振替伝票（予算振替） | J30: 37000368 | K30: 000 | L30: 001 | M30: 1 | N30: 0885060600 | O30: 下水道事業費用 | P30: 特別損失 | Q30: 過年度損益修正損 | R30: 過年度損益修正損 | T30: 921481 | U30: 下水道使用料賦課徴収 | V30: 0 | W30: 0 | X30: 0 | Y30: 288 | Z30: 088506001006000000 | AA30: 過年度損益修正損 | AB30: 288 | AC30: 022602001006000000 | AD30: 下水道使用料還付前渡資金 | AE30: 288 | AF30: 18 | AG30: 10 | AH30: 26 | AI30: 262 | AL30: 37000368-000-001-1-0885060600-921481-18 | AM30: 1 | AN30: 0 | AO30: 0 | AP30: 0 | AS30: 18 | AT30: 10 | AV30: 0 | AW30: 0 | AX30: 0 | AY30: 0 | AZ30: 0 | BA30: 288 | BB30: 288 | BC30: 288 | BD30: 0 | BF30: 0 | BG30: 0 | BH30: 0 | BI30: 0 | BJ30: 0 | BK30: 262 | BL30: 262 | BM30: 262
A31: 1 | D31: 1502110500 | E31: 管理課 | F31: R06/03/01 | G31: R06/03/01 | H31: 下水道使用料過誤納還付金の精算（２月分） | I31: 振替伝票（予算振替） | J31: 37000369 | K31: 000 | L31: 001 | M31: 1 | N31: 0885060600 | O31: 下水道事業費用 | P31: 特別損失 | Q31: 過年度損益修正損 | R31: 過年度損益修正損 | T31: 921481 | U31: 下水道使用料賦課徴収 | V31: 0 | W31: 0 | X31: 0 | Y31: 765 | Z31: 088506001006000000 | AA31: 過年度損益修正損 | AB31: 765 | AC31: 022602001006000000 | AD31: 下水道使用料還付前渡資金 | AE31: 765 | AF31: 18 | AG31: 10 | AH31: 69 | AI31: 696 | AL31: 37000369-000-001-1-0885060600-921481-18 | AM31: 1 | AN31: 0 | AO31: 0 | AP31: 0 | AS31: 18 | AT31: 10 | AV31: 0 | AW31: 0 | AX31: 0 | AY31: 0 | AZ31: 0 | BA31: 765 | BB31: 765 | BC31: 765 | BD31: 0 | BF31: 0 | BG31: 0 | BH31: 0 | BI31: 0 | BJ31: 0 | BK31: 695 | BL31: 695 | BM31: 695
... A59: 1 | D59: 1502110500 | E59: 管理課 | F59: R05/04/18 | G59: R05/04/18 | H59: 過年度分下水道使用料過誤納還付金（口座還付分） | I59: 振替伝票（予算振替） | J59: 37000037 | K59: 000 | L59: 001 | M59: 1 | N59: 0885060600 | O59: 下水道事業費用 | P59: 特別損失 | Q59: 過年度損益修正損 | R59: 過年度損益修正損 | T59: 921481 | U59: 下水道使用料賦課徴収 | V59: 0 | W59: 0 | X59: 0 | Y59: 83432 | Z59: 088506001006000000 | AA59: 過年度損益修正損 | AB59: 83432 | AC59: 021402001002010000 | AD59: 未収下水道使用料０ | AE59: 83432 | AF59: 18 | AG59: 10 | AH59: 7584 | AI59: 75848 | AL59: 37000037-000-001-1-0885060600-921481-18 | AM59: 1 | AN59: 0 | AO59: 0 | AP59: 0 | AS59: 18 | AT59: 10 | AV59: 0 | AW59: 0 | AX59: 0 | AY59: 0 | AZ59: 0 | BA59: 83432 | BB59: 83432 | BC59: 83432 | BD59: 0 | BF59: 0 | BG59: 0 | BH59: 0 | BI59: 0 | BJ59: 0 | BK59: 75847 | BL59: 75847 | BM59: 75847
A60: 1 | D60: 1502110500 | E60: 管理課 | F60: R05/05/09 | G60: R05/05/09 | H60: 過年度分下水道使用料過誤納還付金（口座還付分） | I60: 振替伝票（予算振替） | J60: 37000038 | K60: 000 | L60: 001 | M60: 1 | N60: 0885060600 | O60: 下水道事業費用 | P60: 特別損失 | Q60: 過年度損益修正損 | R60: 過年度損益修正損 | T60: 921481 | U60: 下水道使用料賦課徴収 | V60: 0 | W60: 0 | X60: 0 | Y60: 5402 | Z60: 088506001006000000 | AA60: 過年度損益修正損 | AB60: 5402 | AC60: 021402001002010000 | AD60: 未収下水道使用料０ | AE60: 5402 | AF60: 15 | AG60: 10 | AH60: 491 | AI60: 4911 | AL60: 37000038-000-001-1-0885060600-921481-15 | AM60: 2 | AN60: 18 | AO60: 10 | AP60: 0 | AS60: 18 | AT60: 10 | AV60: 0 | AW60: 0 | AX60: 0 | AY60: 0 | AZ60: 0 | BA60: 5402 | BB60: 5402 | BC60: 5402 | BD60: 0 | BF60: 0 | BG60: 0 | BH60: 0 | BI60: 0 | BJ60: 0 | BK60: 4911 | BL60: 4911 | BM60: 4911
A61: 1 | D61: 1502110500 | E61: 管理課 | F61: R05/04/26 | G61: R05/04/26 | H61: 過年度分下水道使用料過誤納還付金（口座還付分） | I61: 振替伝票（予算振替） | J61: 37000039 | K61: 000 | L61: 001 | M61: 1 | N61: 0885060600 | O61: 下水道事業費用 | P61: 特別損失 | Q61: 過年度損益修正損 | R61: 過年度損益修正損 | T61: 921481 | U61: 下水道使用料賦課徴収 | V61: 0 | W61: 0 | X61: 0 | Y61: 5696 | Z61: 088506001006000000 | AA61: 過年度損益修正損 | AB61: 5696 | AC61: 021402001002010000 | AD61: 未収下水道使用料０ | AE61: 5696 | AF61: 15 | AG61: 10 | AH61: 518 | AI61: 5178 | AL61: 37000039-000-001-1-0885060600-921481-15 | AM61: 2 | AN61: 18 | AO61: 10 | AP61: 0 | AS61: 18 | AT61: 10 | AV61: 0 | AW61: 0 | AX61: 0 | AY61: 0 | AZ61: 0 | BA61: 5696 | BB61: 5696 | BC61: 5696 | BD61: 0 | BF61: 0 | BG61: 0 | BH61: 0 | BI61: 0 | BJ61: 0 | BK61: 5178 | BL61: 5178 | BM61: 5178
A62: 1 | D62: 1502110500 | E62: 管理課 | F62: R06/03/18 | G62: R06/03/18 | H62: 過年度分下水道使用料過誤納還付金（口座還付分） | I62: 振替伝票（予算振替） | J62: 37000411 | K62: 000 | L62: 001 | M62: 1 | N62: 0885060600 | O62: 下水道事業費用 | P62: 特別損失 | Q62: 過年度損益修正損 | R62: 過年度損益修正損 | T62: 921481 | U62: 下水道使用料賦課徴収 | V62: 0 | W62: 0 | X62: 0 | Y62: 33818 | Z62: 088506001006000000 | AA62: 過年度損益修正損 | AB62: 33818 | AC62: 021402001002010000 | AD62: 未収下水道使用料０ | AE62: 33818 | AF62: 18 | AG62: 10 | AH62: 3073 | AI62: 30745 | AL62: 37000411-000-001-1-0885060600-921481-18 | AM62: 1 | AN62: 0 | AO62: 0 | AP62: 0 | AS62: 18 | AT62: 10 | AV62: 0 | AW62: 0 | AX62: 0 | AY62: 0 | AZ62: 0 | BA62: 33818 | BB62: 33818 | BC62: 33818 | BD62: 0 | BF62: 0 | BG62: 0 | BH62: 0 | BI62: 0 | BJ62: 0 | BK62: 30744 | BL62: 30744 | BM62: 30744
A63: 1 | D63: 1502110500 | E63: 管理課 | F63: R06/02/06 | G63: R06/02/06 | H63: 過年度分下水道使用料過誤納還付金（口座還付分） | I63: 振替伝票（予算振替） | J63: 37000338 | K63: 000 | L63: 001 | M63: 1 | N63: 0885060600 | O63: 下水道事業費用 | P63: 特別損失 | Q63: 過年度損益修正損 | R63: 過年度損益修正損 | T63: 921481 | U63: 下水道使用料賦課徴収 | V63: 0 | W63: 0 | X63: 0 | Y63: 764 | Z63: 088506001006000000 | AA63: 過年度損益修正損 | AB63: 764 | AC63: 021402001002010000 | AD63: 未収下水道使用料０ | AE63: 764 | AF63: 18 | AG63: 10 | AH63: 69 | AI63: 695 | AL63: 37000338-000-001-1-0885060600-921481-18 | AM63: 1 | AN63: 0 | AO63: 0 | AP63: 0 | AS63: 18 | AT63: 10 | AV63: 0 | AW63: 0 | AX63: 0 | AY63: 0 | AZ63: 0 | BA63: 764 | BB63: 764 | BC63: 764 | BD63: 0 | BF63: 0 | BG63: 0 | BH63: 0 | BI63: 0 | BJ63: 0 | BK63: 695 | BL63: 695 | BM63: 695
A64: 1 | D64: 1502110500 | E64: 管理課 | F64: R06/01/09 | G64: R06/01/09 | H64: 過年度分下水道使用料過誤納還付金（口座還付分） | I64: 振替伝票（予算振替） | J64: 37000296 | K64: 000 | L64: 001 | M64: 1 | N64: 0885060600 | O64: 下水道事業費用 | P64: 特別損失 | Q64: 過年度損益修正損 | R64: 過年度損益修正損 | T64: 921481 | U64: 下水道使用料賦課徴収 | V64: 0 | W64: 0 | X64: 0 | Y64: 31460 | Z64: 088506001006000000 | AA64: 過年度損益修正損 | AB64: 31460 | AC64: 021402001002010000 | AD64: 未収下水道使用料０ | AE64: 31460 | AF64: 18 | AG64: 10 | AH64: 2860 | AI64: 28600 | AL64: 37000296-000-001-1-0885060600-921481-18 | AM64: 1 | AN64: 0 | AO64: 0 | AP64: 0 | AS64: 18 | AT64: 10 | AV64: 0 | AW64: 0 | AX64: 0 | AY64: 0 | AZ64: 0 | BA64: 31460 | BB64: 31460 | BC64: 31460 | BD64: 0 | BF64: 0 | BG64: 0 | BH64: 0 | BI64: 0 | BJ64: 0 | BK64: 28600 | BL64: 28600 | BM64: 28600
A65: 1 | D65: 1502110500 | E65: 管理課 | F65: R06/01/09 | G65: R06/01/09 | H65: 過年度分下水道使用料過誤納還付金（口座還付分） | I65: 振替伝票（予算振替） | J65: 37000297 | K65: 000 | L65: 001 | M65: 1 | N65: 0885060600 | O65: 下水道事業費用 | P65: 特別損失 | Q65: 過年度損益修正損 | R65: 過年度損益修正損 | T65: 921481 | U65: 下水道使用料賦課徴収 | V65: 0 | W65: 0 | X65: 0 | Y65: 9264 | Z65: 088506001006000000 | AA65: 過年度損益修正損 | AB65: 9264 | AC65: 021402001002010000 | AD65: 未収下水道使用料０ | AE65: 9264 | AF65: 15 | AG65: 8 | AH65: 684 | AI65: 8580 | AL65: 37000297-000-001-1-0885060600-921481-15 | AM65: 1 | AN65: 0 | AO65: 0 | AP65: 0 | AS65: 15 | AT65: 8 | AV65: 0 | AW65: 0 | AX65: 0 | AY65: 0 | AZ65: 0 | BA65: 9264 | BB65: 9264 | BC65: 9264 | BD65: 0 | BF65: 0 | BG65: 0 | BH65: 0 | BI65: 0 | BJ65: 0 | BK65: 8578 | BL65: 8578 | BM65: 8578
A66: 1 | D66: 1502110500 | E66: 管理課 | F66: R06/01/16 | G66: R06/01/16 | H66: 過年度分下水道使用料過誤納還付金（口座還付分） | I66: 振替伝票（予算振替） | J66: 37000302 | K66: 000 | L66: 001 | M66: 1 | N66: 0885060600 | O66: 下水道事業費用 | P66: 特別損失 | Q66: 過年度損益修正損 | R66: 過年度損益修正損 | T66: 921481 | U66: 下水道使用料賦課徴収 | V66: 0 | W66: 0 | X66: 0 | Y66: 7770 | Z66: 088506001006000000 | AA66: 過年度損益修正損 | AB66: 7770 | AC66: 021402001002010000 | AD66: 未収下水道使用料０ | AE66: 7770 | AF66: 18 | AG66: 10 | AH66: 706 | AI66: 7064 | AL66: 37000302-000-001-1-0885060600-921481-18 | AM66: 1 | AN66: 0 | AO66: 0 | AP66: 0 | AS66: 18 | AT66: 10 | AV66: 0 | AW66: 0 | AX66: 0 | AY66: 0 | AZ66: 0 | BA66: 7770 | BB66: 7770 | BC66: 7770 | BD66: 0 | BF66: 0 | BG66: 0 | BH66: 0 | BI66: 0 | BJ66: 0 | BK66: 7064 | BL66: 7064 | BM66: 7064
A67: 1 | D67: 1502110500 | E67: 管理課 | F67: R06/02/27 | G67: R06/02/27 | H67: 過年度分下水道使用料過誤納還付金（口座還付分） | I67: 振替伝票（予算振替） | J67: 37000356 | K67: 000 | L67: 001 | M67: 1 | N67: 0885060600 | O67: 下水道事業費用 | P67: 特別損失 | Q67: 過年度損益修正損 | R67: 過年度損益修正損 | T67: 921481 | U67: 下水道使用料賦課徴収 | V67: 0 | W67: 0 | X67: 0 | Y67: 4587 | Z67: 088506001006000000 | AA67: 過年度損益修正損 | AB67: 4587 | AC67: 021402001002010000 | AD67: 未収下水道使用料０ | AE67: 4587 | AF67: 18 | AG67: 10 | AH67: 417 | AI67: 4170 | AL67: 37000356-000-001-1-0885060600-921481-18 | AM67: 1 | AN67: 0 | AO67: 0 | AP67: 0 | AS67: 18 | AT67: 10 | AV67: 0 | AW67: 0 | AX67: 0 | AY67: 0 | AZ67: 0 | BA67: 4587 | BB67: 4587 | BC67: 4587 | BD67: 0 | BF67: 0 | BG67: 0 | BH67: 0 | BI67: 0 | BJ67: 0 | BK67: 4170 | BL67: 4170 | BM67: 4170
...

Sheet 基礎数値
B1: =+CONCATENATE(LEFT('[3]3条支出'!$D$1,8)," 消費税計算に係る基礎数値") -> 令和５年度決算 消費税計算に係る基礎数値
D2: 3%適用部分 | E2: 5%適用部分 | F2: 8%適用部分 | G2: 8%（軽）適用部分 | H2: 10%適用部分 | I2: 計 | J2: 備考
B3: 収益的収入のうち課税売上（税込） | D3: =+'[2]3条収入'!F69 -> 0 | E3: =+'[2]3条収入'!G69 -> 0 | F3: =+'[2]3条収入'!H69 -> 47053 | G3: =+'[2]3条収入'!I69 -> 0 | H3: =+'[2]3条収入'!J69 -> 20730008529 | I3: =SUM(D3:H3) -> 20730055582 | J3: 「決算総括表」より
B4: 資本的収入のうち課税売上（税込） | D4: =+'[4]4条収入'!F91 -> 0 | E4: =+'[4]4条収入'!G91 -> 0 | F4: =+'[4]4条収入'!H91 -> 0 | G4: =+'[4]4条収入'!I91 -> 0 | H4: =+'[4]4条収入'!J91 -> 39691410 | I4: =SUM(D4:H4) -> 39691410 | J4: 「決算総括表」より
B5: 課税売上から控除するもの
C6: 仕入対価の返還等の額（税込） | D6: =+対価返還!BC3 -> 0 | E6: =+対価返還!BC4 -> 0 | F6: =+対価返還!BC5 -> 0 | G6: =+対価返還!BC6 -> 0 | H6: =+対価返還!BC7 -> 0 | I6: =SUM(D6:H6) -> 0 | J6: 「過年度損益修正益」「その他特別利益」のうち、課税支出が返還されたもの（過去に支払った通勤手当の還付、建設負担金の精算に伴う還付など）
C7: 売上対価の返還等の額（税込） | D7: =+対価返還!BC9 -> 0 | E7: =+対価返還!BC10 -> 0 | F7: =+対価返還!BC11 -> 39339 | G7: =+対価返還!BC12 -> 0 | H7: =+対価返還!BC13 -> 10639743 | I7: =SUM(D7:H7) -> 10679082 | J7: 「雑支出」「過年度損益修正損」「その他特別損失」のうち、課税収入を返還したもの（下水道使用料の調定減額、過誤納還付金など）
B8: 免税売上額 | I8: =+'[2]3条収入'!M69 -> 86860 | J8: 管理課資料、「決算総括表」より
B9: 収益的収入のうち非課税売上（税込） | I9: =+'[2]3条収入'!L69 -> 22644840 | J9: 「決算総括表」より
B10: 資本的収入のうち非課税売上（税込） | I10: =+'[4]4条収入'!L91 -> 45948113 | J10: 「決算総括表」より
B11: 収益的支出のうち課税支出（税込） | D11: =+'[3]3条支出'!F41+D17 -> 0 | E11: =+'[3]3条支出'!G41+E17 -> 1120996 | F11: =+'[3]3条支出'!H41+F17 -> 25903142 | G11: =+'[3]3条支出'!I41+G17 -> 500878 | H11: =+'[3]3条支出'!J41+H17 -> 9106828850 | I11: =SUM(D11:H11) -> 9134353866 | J11: 「決算総括表」より （H27決算から貸倒引当金の取り崩し分を計上）
B12: 資本的支出のうち課税支出（税込） | D12: =+'[5]4条支出'!F41 -> 0 | E12: =+'[5]4条支出'!G41 -> 0 | F12: =+'[5]4条支出'!H41 -> 125712 | G12: =+'[5]4条支出'!I41 -> 36840 | H12: =+'[5]4条支出'!J41 -> 16278736624 | I12: =SUM(D12:H12) -> 16278899176 | J12: 「決算総括表」より
B13: 課税仕入れから控除するもの
C14: 返還等対価・貸倒れの額（税込） | D14: =+D7+D17 -> 0 | E14: =+E7+E17 -> 1120996 | F14: =+F7+F17 -> 24706340 | G14: =+G7+G17 -> 0 | H14: =+H7+H17 -> 10639743 | I14: =SUM(D14:H14) -> 36467079 | J14: 「雑支出」「過年度損益修正損」「その他特別損失」の課税支出うち、該当分（下水道使用料の減額調定・過誤納還付金・時効欠損*、排水設備取付管設置工事受託金の還付など）
C15: 仕入対価の返還等の額（税込） | D15: =+D6 -> 0 | E15: =+E6 -> 0 | F15: =+F6 -> 0 | G15: =+G6 -> 0 | H15: =+H6 -> 0 | I15: =SUM(D15:H15) -> 0
B16: 免税業者との取引額（税込） | D16: 0 | G16: 0 | H16: 34600 | I16: =SUM(D16:H16) -> 34600 | J16: 免税業者との取引額を税込額で入力
B17: 貸倒れに係る金額（税込） | D17: 0 | E17: 1120996 | F17: 24667001 | G17: 0 | H17: 0 | I17: =SUM(D17:H17) -> 25787997 | J17: 特別損失の課税支出のうち、時効欠損分*
B18: 収益的支出のうち特定収入 | D18: =+[7]総括表!K62 -> 0 | E18: =+[7]総括表!L62 -> 0 | F18: =+[7]総括表!M62 -> 455392 | G18: =+[7]総括表!N62 -> 130568 | H18: =+[7]総括表!O62 -> 2312306920 | I18: =SUM(D18:H18) -> 2312892880 | J18: 「決算総括表」の「不課税収入」のうち「課税仕入に特定」
B19: 資本的支出のうち特定収入 | D19: =+[7]総括表!K172 -> 0 | E19: =+[7]総括表!L172 -> 131982078 | F19: =+[7]総括表!M172 -> 1246904 | G19: =+[7]総括表!N172 -> 99 | H19: =+[7]総括表!O172 -> 5972404802 | I19: =SUM(D19:H19) -> 6105633883
B20: 使途不特定の特定収入 | I20: 0
B21: 中間納付税額
C22: 消費税 | I22: 365767600
C23: 地方消費税 | I23: 103164600
C24: 計 | I24: =SUM(I22:I23) -> 468932200
J25: ＊時効欠損は、平成26年度の会計制度の見直しに伴い、貸倒引当金を繰り入れたことから、平成27年度申告からは取崩し分を計上する

Sheet 消費税
F1: 消費税率 | G1: 0.03 | H1: 0.04 | I1: 0.063 | J1: 0.0624 | K1: 0.078 | N1: 消費税率 | O1: =+G1 -> 0.03 | P1: =+H1 -> 0.04 | Q1: =+I1 -> 0.063 | R1: =+J1 -> 0.0624 | S1: =+K1 -> 0.078 | U1: =+G1 -> 0.03 | V1: =+H1 -> 0.04 | W1: =+I1 -> 0.063 | X1: =+R1 -> 0.0624 | Y1: =+K1 -> 0.078 | AA1: =+G1 -> 0.03 | AB1: =+H1 -> 0.04 | AC1: =+I1 -> 0.063 | AD1: =+X1 -> 0.0624 | AE1: =+K1 -> 0.078
F2: 地方消費税率 | G2: =+G7-G1 -> 0 | H2: =+H7-H1 -> 0.01 | I2: =+I7-I1 -> 0.017 | J2: =+J7-J1 -> 0.0176 | K2: =+K7-K1 -> 0.022 | N2: 地方消費税率 | O2: =+O7-O1 -> 0 | P2: =+P7-P1 -> 0.01 | Q2: =+Q7-Q1 -> 0.017 | R2: =+R7-R1 -> 0.0176 | S2: =+S7-S1 -> 0.022 | U2: =+U7-U1 -> 0 | V2: =+V7-V1 -> 0.01 | W2: =+W7-W1 -> 0.017 | X2: =+X7-X1 -> 0.0176 | Y2: =+Y7-Y1 -> 0.022 | AA2: =+AA7-AA1 -> 0 | AB2: =+AB7-AB1 -> 0.01 | AC2: =+AC7-AC1 -> 0.017 | AD2: =+AD7-AD1 -> 0.0176 | AE2: =+AE7-AE1 -> 0.022
B3: =+CONCATENATE(LEFT('[3]3条支出'!$D$1,8)," 消費税等計算チェックシート") -> 令和５年度決算 消費税等計算チェックシート | L3: 単位：円 | AF3: 単位：円
B4: チェック項目 | F4: 収益的収支・資本的収支の別 | G4: 申告ベース（収益的収支と資本的収支の合計額） | N4: 収益的収支・資本的収支の別 | O4: 収益的収支のみ+資本的収支のみの単純計 | U4: 収益的収支のみ | AA4: 資本的収支のみ
E5: 区 分 | F5: 消費税及び地方消費税の計算 | G5: 申告ベース（消費税を計算後、地方消費税を計算） | N5: 消費税及び地方消費税の計算 | O5: 「消費税」を「消費税及び地方消費税」に読み替えて計算 | U5: 「消費税」を「消費税及び地方消費税」に読み替えて計算 | AA5: 「消費税」を「消費税及び地方消費税」に読み替えて計算
F6: 金額単位端数処理の取扱い | G6: 申告ベース（課税標準額千円単位、納税額百円単位） | N6: 金額単位端数処理の取扱い | O6: 1円単位での端数処理 | U6: 1円単位での端数処理 | AA6: 1円単位での端数処理
