Workbook

Sheet 最終チェック（資本的支出の財源内訳と照合）
C1: ピンクは手入力、黄色は自動計算 | E1: 令和４年度 | G1: 令和5年度 | H1: 備考（資本的支出の財源内訳との照合場所）
C2: ※ここでの計算はエラーチェックのために行うものであり、他のシートには一切反映されません
A3: 資本的支出総額（執行額） | D3: a | E3: 59709459299 | G3: ='(繰)4条支出 '!G5 -> 61875977537 | H3: 全５（決算）の決算額 E72と一致
G4: 2.6989462e+09 | H4: 全５（決算）の一般財源R72を入力
A5: 資本的収入 | D5: b=c-d | E5: 39670381852 | G5: =G4+'(繰)4条収入'!G35 -> 41438646781 | H5: 全５（決算）の企業債～固定資産売却代金+一般財源 F72～M72+R72と一致
B6: 執行額（一般会計出資金収入含む） | D6: c | E6: =E5+E7 -> 40554720469 | G6: =G5+G7 -> 42025205141
B7: うち翌年度に繰越す予算への財源充当額 | D7: d | E7: 884338617 | G7: ='(繰)4条支出 '!J5-'(繰)4条収入'!L5 -> 586558360 | H7: 全３（繰越）の出資金 R75と一致
A9: 資本的収支不足額 | D9: e=a-b | E9: =E3-E5 -> 20039077447 | G9: =G3-G5 -> 20437330756
A11: 補填財源 | D11: f=g+h+i+j | E11: =SUM(E12:E13,E16:E17) -> 20039077447 | G11: =SUM(G12:G13,G16:G17) -> 20437330756
B12: 消費税資本的収支調整額 | D12: g | E12: 769659721 | G12: ='(繰)案'!E33 -> 923595698 | H12: 黄色部分は全１（現年）の当年度消費税 O78と一致
B13: 繰越工事資金 | D13: h=i+j | E13: =SUM(E14:E15) -> 627253803 | G13: =SUM(G14:G15) -> 884338617
C14: 前年度からの自己財源 | D14: i | E14: 627111363 | G14: =E7 -> 884338617
C15: 前々年度からの自己財源（事故繰越分） | D15: j | E15: 142440 | H15: 事故繰越分の予算繰越計算書の自己財源
B16: 損益勘定留保資金 | D16: k | E16: 17443558426 | G16: ='(繰)案'!E22 -> 17579830234 | H16: 全１（現年）の減価償却費+資産減耗費+その他 O74+O75+O79と一致
B17: 減債積立金 | D17: l | E17: 1198605497 | G17: ='(繰)案'!E34 -> 1049566207 | H17: 全１（現年）の減債積立金 O77と一致
A19: 過不足額 | D19: m=e-f | E19: =E9-E11 -> 0 | G19: =G9-G11 -> 0 | H19: ←この数値が０になることを確認

Sheet (繰)案
A1: （案の１）
A2: 1 一般会計繰入金予算額 | E2: ='(繰)対前年'!G46 -> 17495336000 | F2: 円
A3: 2 一般会計繰入金受入済額 | D3: （Ａ） | E3: =+E2 -> 17495336000 | F3: 円
A4: 3 前受金（災害復旧等繰越財源分） | D4: （Ｂ） | E4: =+'(繰)対前年'!G36 -> 0 | F4: 円
A5: 3 一般会計繰入金精算額 ＝ 下水決算額 | D5: （B） | E5: =+'(繰)対前年'!H39 -> 17481810139 | F5: 円 | H5: ↓非表示行あり
A6: 5 前年度一般会計出資金未収額 | D6: （Ｄ） | E6: =+'(繰)対前年'!H38 -> 0 | F6: 円
A7: 4 差引精算戻入額 | D7: （Ａ－Ｂ） | E7: =E3+E4-E5-E6 -> 13525861 | F7: 円
A9: 【一般会計繰入金精算額＝下水決算額の説明】
B10: 1 収益的収支（３条分、税抜き） | H10: ↓3条収入・支出シート
C11: (1) 支出決算額 | D11: （ア） | E11: ='(繰)3条支出 '!I4 -> 42028134935 | F11: 円 | H11: =+'[1]3条支出'!T41 -> 42028134935
C12: (2) 収入決算額（繰入金除く。） | D12: （イ） | E12: ='(繰)3条収入'!H4-'(繰)3条収入'!H7-'(繰)3条収入'!H15 -> 28375736546 | F12: 円 | H12: =+'[2]3条収入'!AI69 -> 42572042134
C13: (3) 当年度純利益 | D13: （ウ） | E13: =+'(繰)3条収入'!H4-'(繰)3条支出 '!I4 -> 543907199 | F13: 円 | H13: =+'[2]3条収入'!AI74 -> 543907199
C14: (4) 繰入金額（一般会計負担金、一般会計補助金） | D14: （ア－イ＋ウ） | E14: =E11-E12+E13 -> 14196305588 | F14: 円 | G14: （C） | H14: =+'[2]3条収入'!AI9+'[2]3条収入'!AI42 -> 14196305588
B16: ２ 資本的収支（４条分、税込み、みなしベース）
C17: (1) 支出決算額 | D17: （エ） | E17: ='(繰)4条支出 '!K5 -> 61852897933 | F17: 円
C18: (2) 収入決算額（繰入金除く。） | D18: （オ） | E18: =SUM('(繰)4条収入'!M6,'(繰)4条収入'!M16,'(繰)4条収入'!M20,'(繰)4条収入'!M22,'(繰)4条収入'!M29,'(繰)4条収入'!M30) -> 38957586329 | F18: 円
C19: （前年度充当財源（企業債未発行分）を除く）
C20: (3) 補てん財源 | D20: （カ） | E20: =E22+E31+E34+E35 -> 19609807053 | F20: 円
C21: （補てん財源の内訳）
C22: ①当年度分損益勘定留保資金 | E22: =SUM(E23:E30) -> 17579830234 | F22: 円 | H22: ↓資金余剰調整額
C23: ＊減価償却費 | E23: ='(繰)3条支出 '!I18-H23 -> 26551442230 | F23: 円
C24: ＊固定資産除却費 | E24: =+[1]減耗!T5 -> 503761871 | F24: 円 | H24: ↓非表示行あり
C25: ＊固定資産売却損 | E25: ='(繰)3条支出 '!G25 -> 10315355 | F25: 円
C26: ＊減損損失 | E26: =+'(繰)3条支出 '!I28 -> 0 | F26: 円
C27: ＊長期前受金戻入（償却・除却見合分） | E27: =-'(繰)3条収入'!H18 -> -9485355002 | F27: 円
C28: ＊長期前受金戻入益（減損見合分） | E28: =-'(繰)3条収入'!H20 -> 0
C29: ＊過年度損益修正益 | E29: -334220 | F29: 円
C30: ＊企業債発行差金(見なし決算分） | E30: =+[1]営外!T12 -> 0 | F30: 円
C31: ②消費税及び地方消費税資本的収支調整額 | E31: =E32+E33 -> 923595698 | F31: 円
C32: ＊過年度分 | E32: 0 | F32: 円
C33: ＊現年度分 | E33: =-[3]消費税!AF118 -> 923595698 | F33: 円
C34: ③減債積立金 | E34: 1049566207 | F34: 円 | H34: ↓非表示行あり
C35: ④繰越工事資金当年度充当額 | E35: 56814914 | F35: 円
C37: (4) 繰入金額（一般会計出資金、一般会計借入金） | D37: （エ－オ－カ） | E37: =E17-E18-E20 -> 3285504551 | F37: 円 | G37: （D） | J37: 予算
D38: （Ｄ）のうち 一般会計借入金 | E38: ='(繰)4条収入'!I28 -> 0 | J38: 3640474000
D39: 一般会計出資金 | E39: =E37-E38 -> 3285504551 | J39: =E37-J38 -> -354969449
B41: ３ 繰入金総額（C+D）＝今回精算（確定）額＝下水決算額
E42: =E14+E37 -> 17481810139 | F42: 円 | G42: （Ｂ）

Sheet (繰)精算書
H1: （案の２） | J1: =+DATE(MID([4]雨汚水!D1,3,1)+2019,3,31) -> 45382
B2: 広 島 市 長 様 （財政局財政課）
J3: 広島市長 （下水道局経営企画課）
A5: =+CONCATENATE(LEFT('[1]3条支出'!$D$1,7),"下水道事業会計に対する一般会計繰入金の精算について") -> 令和５年度決算下水道事業会計に対する一般会計繰入金の精算について
B7: このことについて、下記のとおり精算します。ついては、5月31日を納期限とした納入通知書を作成してください。
A8: 記
J9: （単位：円）
A10: 科 目 | G10: 受入済額(a) | H10: 精算額(b) | I10: 精算戻入額(a-b) | J10: 備 考 | K10: AAA | L10: AAA | M10: AAA | N10: AAA
A11: 下水道事業収益 | G11: =G12+G22 -> 13854862000 | H11: =H12+H22 -> 14196305588 | I11: =G11-H11 -> -341443588 | N11: =OR(G11>0,H11>0,I11>0) -> TRUE
B12: 営業収益 | G12: =G13 -> 13854862000 | H12: =H13 -> 14187102335 | I12: =G12-H12 -> -332240335 | N12: =OR(G12>0,H12>0,I12>0) -> TRUE
C13: 一般会計負担金 | G13: =G14+G19+G20+G21+G18 -> 13854862000 | H13: =H14+H19+H20+H21 -> 14187102335 | I13: =G13-H13 -> -332240335 | N13: =OR(G13>0,H13>0,I13>0) -> TRUE
D14: 雨水処理負担金 | G14: =SUM(G15:G17) -> 13738282000 | H14: =SUM(H15:H18) -> 14079749832 | I14: =G14-H14 -> -341467832 | N14: =OR(G14>0,H14>0,I14>0) -> TRUE
E15: 維持管理費分 | G15: =+'(繰)対前年'!G9 -> 3686798000 | H15: ='(繰)対前年'!H9-H18 -> 3591522898 | I15: =G15-H15 -> 95275102 | J15: 補助費 | N15: =OR(G15>0,H15>0,I15>0) -> TRUE
E16: 減価償却費分 | G16: =+'(繰)対前年'!G10 -> 7912710000 | H16: ='(繰)対前年'!H10 -> 8476549651 | I16: =G16-H16 -> -563839651 | J16: 普建 | N16: =OR(G16>0,H16>0,I16>0) -> TRUE
E17: 支払利息分 | G17: =+'(繰)対前年'!G11 -> 2138774000 | H17: ='(繰)対前年'!H11 -> 2011677283 | I17: =G17-H17 -> 127096717 | J17: 普建 | N17: =OR(G17>0,H17>0,I17>0) -> TRUE
E18: 維持管理費分（災害復旧繰越分) | G18: =+'(繰)対前年'!G12 -> 0 | H18: ='(繰)繰入金'!H11 -> 0 | I18: =G18-H18 -> 0 | J18: 補助費 | N18: =OR(G18>0,H18>0,I18>0) -> FALSE
D19: 水質指導費負担金 | G19: =+'(繰)対前年'!G13 -> 61778000 | H19: ='(繰)対前年'!H13 -> 52443869 | I19: =G19-H19 -> 9334131 | J19: 補助費 | N19: =OR(G19>0,H19>0,I19>0) -> TRUE
D20: 普及促進費負担金 | G20: =+'(繰)対前年'!G14 -> 40039000 | H20: ='(繰)対前年'!H14 -> 44424775 | I20: =G20-H20 -> -4385775 | J20: 補助費 | N20: =OR(G20>0,H20>0,I20>0) -> TRUE
D21: 貸付事業費負担金 | G21: =+'(繰)対前年'!G15 -> 14763000 | H21: ='(繰)対前年'!H15 -> 10483859 | I21: =G21-H21 -> 4279141 | J21: 補助費 | K21: =+'(繰)繰入金'!H11 -> 0 | L21: ← | M21: 普建分 | N21: =OR(G21>0,H21>0,I21>0) -> TRUE
B22: 営業外収益 | G22: =G23 -> 0 | H22: =H23 -> 9203253 | I22: =G22-H22 -> -9203253 | N22: =OR(G22>0,H22>0,I22>0) -> TRUE
C23: 一般会計補助金 | G23: =G24+G31 -> 0 | H23: =H24+H31 -> 9203253 | I23: =G23-H23 -> -9203253 | N23: =OR(G23>0,H23>0,I23>0) -> TRUE
D24: 汚水処理補助金 | G24: =SUM(G25:G28) -> 0 | H24: =SUM(H25:H28) -> 4980 | I24: =G24-H24 -> -4980 | N24: =OR(G24>0,H24>0,I24>0) -> TRUE
E25: 維持管理費分 | G25: ='(繰)対前年'!G19 -> 0 | H25: 0 | I25: =G25-H25 -> 0 | N25: =OR(G25>0,H25>0,I25>0) -> FALSE
E26: 減価償却費分 | G26: ='(繰)対前年'!G20 -> 0 | H26: ='(繰)対前年'!H20 -> 0 | I26: =G26-H26 -> 0 | J26: 普建 | N26: =OR(G26>0,H26>0,I26>0) -> FALSE
E27: 支払利息分 | G27: ='(繰)対前年'!G21 -> 0 | H27: ='(繰)対前年'!H21 -> 0 | I27: =G27-H27 -> 0 | J27: 普建 | N27: =OR(G27>0,H27>0,I27>0) -> FALSE
E28: 下水道使用料減免分 | G28: =+'(繰)対前年'!G22 -> 0 | H28: ='(繰)対前年'!H22 -> 4980 | I28: =G28-H28 -> -4980 | J28: 普建 | N28: =OR(G28>0,H28>0,I28>0) -> TRUE
F29: 当年度分 | G29: =+'(繰)対前年'!G23 -> 0 | H29: ='(繰)対前年'!H23 -> 0 | I29: =G29-H29 -> 0 | N29: =OR(G29>0,H29>0,I29>0) -> FALSE
F30: 前年度未収分 | G30: =+'(繰)対前年'!G24 -> 0 | H30: ='(繰)対前年'!H24 -> 0 | I30: =G30-H30 -> 0 | N30: =OR(G30>0,H30>0,I30>0) -> FALSE
D31: その他補助金 | G31: =+'(繰)対前年'!G25 -> 0 | H31: ='(繰)対前年'!H25 -> 9198273 | I31: =G31-H31 -> -9198273 | J31: 補助費 | N31: =OR(G31>0,H31>0,I31>0) -> TRUE
A32: 資本的収入 | G32: =G33+G36 -> 3640474000 | H32: =H33+H36 -> 3285504551 | I32: =G32-H32 -> 354969449 | N32: =OR(G32>0,H32>0,I32>0) -> TRUE
B33: 一般会計出資金 | G33: =G34 -> 3640474000 | H33: =H34 -> 3285504551 | I33: =G33-H33 -> 354969449 | N33: =OR(G33>0,H33>0,I33>0) -> TRUE
C34: 下水道建設費出資金 | G34: =SUM(G35:G35) -> 3640474000 | H34: =SUM(H35:H35) -> 3285504551 | I34: =G34-H34 -> 354969449 | N34: =OR(G34>0,H34>0,I34>0) -> TRUE
D35: 下水道建設費出資金 | G35: =+'(繰)対前年'!G29 -> 3640474000 | H35: ='(繰)対前年'!H29 -> 3285504551 | I35: =G35-H35 -> 354969449 | J35: 普建 | N35: =OR(G35>0,H35>0,I35>0) -> TRUE
B36: 水洗化貸付事業収入 | G36: =G37 -> 0 | H36: =H37 -> 0 | I36: =G36-H36 -> 0 | N36: =OR(G36>0,H36>0,I36>0) -> FALSE
C37: 一般会計借入金 | G37: =SUM(G38:G40) -> 0 | H37: =SUM(H38:H40) -> 0 | I37: =G37-H37 -> 0 | J37: 貸付金 | N37: =OR(G37>0,H37>0,I37>0) -> FALSE
D38: 水洗便所改造資金貸付借入金 | G38: =+'(繰)対前年'!G32 -> 0 | H38: ='(繰)対前年'!H32 -> 0 | I38: =G38-H38 -> 0 | N38: =OR(G38>0,H38>0,I38>0) -> FALSE
D39: し尿浄化槽廃止資金貸付借入金 | G39: =+'(繰)対前年'!G33 -> 0 | H39: ='(繰)対前年'!H33 -> 0 | I39: =G39-H39 -> 0 | N39: =OR(G39>0,H39>0,I39>0) -> FALSE
D40: 排水設備改修資金貸付借入金 | G40: =+'(繰)対前年'!G34 -> 0 | H40: ='(繰)対前年'!H34 -> 0 | I40: =G40-H40 -> 0 | N40: =OR(G40>0,H40>0,I40>0) -> FALSE
A41: 計 （当年度決算分） | N41: =TRUE() -> TRUE
G42: =G11+G32 -> 17495336000 | H42: =H11+H32 -> 17481810139 | I42: =I11+I32 -> 13525861 | N42: =TRUE() -> TRUE
...

Sheet (繰)繰入金
A1: =+CONCATENATE(LEFT('[1]3条支出'!$D$1,5),"一般会計繰入金の性質別等の区分") -> 令和５年度一般会計繰入金の性質別等の区分
J2: （単位：円）
A3: 科 目 | G3: 議決予算額(a) | H3: 決算額(b) | I3: 差 引(a-b) | J3: 備 考 | K3: 抽出用
A4: 下水道事業収益 | G4: =G5+G15 -> 13854862000 | H4: =H5+H15 -> 14196305588 | I4: =G4-H4 -> -341443588 | K4: =OR(G4>0,H4>0,I4>0) -> TRUE
B5: 営業収益 | G5: =G6 -> 13854862000 | H5: =H6 -> 14187102335 | I5: =G5-H5 -> -332240335 | K5: =OR(G5>0,H5>0,I5>0) -> TRUE
C6: 一般会計負担金 | G6: =G7+G12+G13+G14+G11 -> 13854862000 | H6: =H7+H12+H13+H14 -> 14187102335 | I6: =G6-H6 -> -332240335 | K6: =OR(G6>0,H6>0,I6>0) -> TRUE
D7: 雨水処理負担金 | G7: =SUM(G8:G10) -> 13738282000 | H7: =SUM(H8:H11) -> 14079749832 | I7: =G7-H7 -> -341467832 | K7: =OR(G7>0,H7>0,I7>0) -> TRUE
E8: 維持管理費分 | G8: ='(繰)対前年'!G9 -> 3686798000 | H8: ='(繰)対前年'!H9-H11 -> 3591522898 | I8: =G8-H8 -> 95275102 | J8: 補助費 | K8: =OR(G8>0,H8>0,I8>0) -> TRUE
E9: 減価償却費分 | G9: ='(繰)対前年'!G10 -> 7912710000 | H9: ='(繰)対前年'!H10 -> 8476549651 | I9: =G9-H9 -> -563839651 | J9: 普建 | K9: =OR(G9>0,H9>0,I9>0) -> TRUE
E10: 支払利息分 | G10: ='(繰)対前年'!G11 -> 2138774000 | H10: ='(繰)対前年'!H11 -> 2011677283 | I10: =G10-H10 -> 127096717 | J10: 普建 | K10: =OR(G10>0,H10>0,I10>0) -> TRUE
E11: 維持管理費分（災害復旧繰越分) | G11: 0 | H11: 0 | I11: =G11-H11 -> 0 | J11: 補助費 | K11: =OR(G11>0,H11>0,I11>0) -> FALSE
D12: 水質指導費負担金 | G12: ='(繰)対前年'!G13 -> 61778000 | H12: ='(繰)対前年'!H13 -> 52443869 | I12: =G12-H12 -> 9334131 | J12: 補助費 | K12: =OR(G12>0,H12>0,I12>0) -> TRUE
D13: 普及促進費負担金 | G13: ='(繰)対前年'!G14 -> 40039000 | H13: ='(繰)対前年'!H14 -> 44424775 | I13: =G13-H13 -> -4385775 | J13: 補助費 | K13: =OR(G13>0,H13>0,I13>0) -> TRUE
D14: 貸付事業費負担金 | G14: ='(繰)対前年'!G15 -> 14763000 | H14: ='(繰)対前年'!H15 -> 10483859 | I14: =G14-H14 -> 4279141 | J14: 補助費 | K14: =OR(G14>0,H14>0,I14>0) -> TRUE
B15: 営業外収益 | G15: =G16 -> 0 | H15: =H16 -> 9203253 | I15: =G15-H15 -> -9203253 | K15: =OR(G15>0,H15>0,I15>0) -> TRUE
C16: 一般会計補助金 | G16: =G17+G24 -> 0 | H16: =H17+H24 -> 9203253 | I16: =G16-H16 -> -9203253 | K16: =OR(G16>0,H16>0,I16>0) -> TRUE
D17: 汚水処理補助金 | G17: =SUM(G18:G21) -> 0 | H17: =SUM(H18:H21) -> 4980 | I17: =G17-H17 -> -4980 | K17: =OR(G17>0,H17>0,I17>0) -> TRUE
E18: 維持管理費分 | G18: 0 | H18: 0 | I18: =G18-H18 -> 0 | K18: =OR(G18>0,H18>0,I18>0) -> FALSE
E19: 減価償却費分 | G19: ='(繰)対前年'!G20 -> 0 | H19: ='(繰)対前年'!H20 -> 0 | I19: =G19-H19 -> 0 | J19: 普建 | K19: =OR(G19>0,H19>0,I19>0) -> FALSE
E20: 支払利息分 | G20: ='(繰)対前年'!G21 -> 0 | H20: ='(繰)対前年'!H21 -> 0 | I20: =G20-H20 -> 0 | J20: 普建 | K20: =OR(G20>0,H20>0,I20>0) -> FALSE
E21: 下水道使用料減免分 | G21: ='(繰)対前年'!G22 -> 0 | H21: ='(繰)対前年'!H22 -> 4980 | I21: =G21-H21 -> -4980 | J21: 普建 | K21: =OR(G21>0,H21>0,I21>0) -> TRUE
F22: 当年度分 | G22: ='(繰)対前年'!G23 -> 0 | H22: ='(繰)対前年'!H23 -> 0 | I22: =G22-H22 -> 0 | K22: =OR(G22>0,H22>0,I22>0) -> FALSE
F23: 前年度未収分 | G23: ='(繰)対前年'!G24 -> 0 | H23: ='(繰)対前年'!H24 -> 0 | I23: =G23-H23 -> 0 | K23: =OR(G23>0,H23>0,I23>0) -> FALSE
D24: その他補助金 | G24: ='(繰)対前年'!G25 -> 0 | H24: ='(繰)対前年'!H25 -> 9198273 | I24: =G24-H24 -> -9198273 | J24: 補助費 | K24: =OR(G24>0,H24>0,I24>0) -> TRUE
A25: 資本的収入 | G25: =G26+G29 -> 3640474000 | H25: =H26+H29 -> 3285504551 | I25: =G25-H25 -> 354969449 | K25: =OR(G25>0,H25>0,I25>0) -> TRUE
B26: 一般会計出資金 | G26: =G27 -> 3640474000 | H26: =H27 -> 3285504551 | I26: =G26-H26 -> 354969449 | K26: =OR(G26>0,H26>0,I26>0) -> TRUE
C27: 下水道建設費出資金 | G27: =SUM(G28:G28) -> 3640474000 | H27: =SUM(H28:H28) -> 3285504551 | I27: =G27-H27 -> 354969449 | K27: =OR(G27>0,H27>0,I27>0) -> TRUE
D28: 下水道建設費出資金 | G28: ='(繰)対前年'!G29 -> 3640474000 | H28: ='(繰)対前年'!H29 -> 3285504551 | I28: =G28-H28 -> 354969449 | J28: 普建 | K28: =OR(G28>0,H28>0,I28>0) -> TRUE
B29: 水洗化貸付事業収入 | G29: =G30 -> 0 | H29: =H30 -> 0 | I29: =G29-H29 -> 0 | K29: =OR(G29>0,H29>0,I29>0) -> FALSE
C30: 一般会計借入金 | G30: =SUM(G31:G33) -> 0 | H30: =SUM(H31:H33) -> 0 | I30: =G30-H30 -> 0 | J30: 貸付金 | K30: =OR(G30>0,H30>0,I30>0) -> FALSE
D31: 水洗便所改造資金貸付借入金 | G31: ='(繰)対前年'!G32 -> 0 | H31: ='(繰)対前年'!H32 -> 0 | I31: =G31-H31 -> 0 | K31: =OR(G31>0,H31>0,I31>0) -> FALSE
D32: し尿浄化槽廃止資金貸付借入金 | G32: ='(繰)対前年'!G33 -> 0 | H32: ='(繰)対前年'!H33 -> 0 | I32: =G32-H32 -> 0 | K32: =OR(G32>0,H32>0,I32>0) -> FALSE
D33: 排水設備改修資金貸付借入金 | G33: ='(繰)対前年'!G34 -> 0 | H33: ='(繰)対前年'!H34 -> 0 | I33: =G33-H33 -> 0 | K33: =OR(G33>0,H33>0,I33>0) -> FALSE
A34: 計 （当年度決算分） | G34: =G4+G25 -> 17495336000 | H34: =H4+H25 -> 17481810139 | I34: =I4+I25 -> 13525861 | K34: =OR(G34>0,H34>0,I34>0) -> TRUE
B35: 前受金（災害復旧等繰越財源分） | G35: ='(繰)精算書'!G45 -> 0 | H35: ='(繰)精算書'!H45 -> 0 | I35: =G35-H35 -> 0 | J35: 補助費 | K35: =OR(G35>0,H35>0,I35>0) -> FALSE
A36: 合計 | G36: =G34+G35 -> 17495336000 | H36: =H34+H35 -> 17481810139 | I36: =G36-H36 -> 13525861 | K36: =OR(G36>0,H36>0,I36>0) -> TRUE
A37: 前年度下水道建設費出資金未収金 | G37: ='(繰)対前年'!G38 -> 0 | H37: ='(繰)対前年'!H38 -> 0 | I37: =G37-H37 -> 0 | J37: 普建 | K37: =OR(G37>0,H37>0,I37>0) -> FALSE
A38: 合 計 | G38: =SUM(G36:G37) -> 17495336000 | H38: =SUM(H36:H37) -> 17481810139 | I38: =SUM(I36:I37) -> 13525861 | K38: =OR(G38>0,H38>0,I38>0) -> TRUE
E40: 区 分 | G40: 議決予算額 | H40: 決算額(b) | I40: 差 引(a-b)
E41: 普建 | G41: =+'(繰)対前年'!G43 -> 13691958000 | H41: =SUMIF(J4:J33,E41,H4:H33)+H37 -> 13773736465 | I41: =G41-H41 -> -81778465
...

Sheet (繰)対前年
A1: =+CONCATENATE(LEFT('[1]3条支出'!$D$1,5),"一般会計繰入金の前年度比較表") -> 令和５年度一般会計繰入金の前年度比較表
L2: （単位：円）
A3: 科 目 | G3: 議決予算額 | H3: 決算額 | I3: 予算との比較 | K3: 前年度決算額 | L3: 前年度決算額との比較 | N3: 財政収支計画額 | O3: 財政収支計画額との比較 | Q3: 備 考
G4: (a) | H4: (b) | I4: 差引(a-b) | J4: 対予算 比 | K4: (c) | L4: 差引(ｂ-ｃ) | M4: 対前年 度比 | N4: （Ｄ） | O4: 差引き(d-b) | P4: 対前年度比 | R4: 抽出用
A5: 下水道事業収益 | G5: =G6+G16 -> 13854862000 | H5: =H6+H16 -> 14196305588 | I5: =G5-H5 -> -341443588 | J5: =IF(AND(G5=0,H5>0),"皆増",IF(AND(G5>0,H5=0),"皆減",IF(AND(G5=0,H5=0),"-",H5/G5))) -> 1.0246443 | K5: =K6+K16 -> 13993380952 | L5: =L6+L16 -> 202924636 | M5: =IF(AND(K5=0,H5>0),"皆増",IF(AND(K5>0,H5=0),"皆減",IF(AND(K5=0,H5=0),"-",H5/K5))) -> 1.0145015 | N5: =N6+N16 -> 0 | O5: =N5-H5 -> -14196305588 | P5: =H5/N5 -> #DIV/0! | R5: =IF(OR(G5>0,H5>0,K5>0),"表示（自動）","非表示（自動）") -> 表示（自動）
B6: 営業収益 | G6: =G7 -> 13854862000 | H6: =H7 -> 14187102335 | I6: =G6-H6 -> -332240335 | J6: =IF(AND(G6=0,H6>0),"皆増",IF(AND(G6>0,H6=0),"皆減",IF(AND(G6=0,H6=0),"-",H6/G6))) -> 1.0239801 | K6: =K7 -> 13993349494 | L6: =SUM(L7) -> 193752841 | M6: =IF(AND(K6=0,H6>0),"皆増",IF(AND(K6>0,H6=0),"皆減",IF(AND(K6=0,H6=0),"-",H6/K6))) -> 1.0138461 | N6: =N7 -> 0 | O6: =N6-H6 -> -14187102335 | P6: =H6/N6 -> #DIV/0! | R6: =IF(OR(G6>0,H6>0,K6>0),"表示（自動）","非表示（自動）") -> 表示（自動）
C7: 一般会計負担金 | G7: =G8+G13+G14+G15+G12 -> 13854862000 | H7: =H8+H13+H14+H15+H12 -> 14187102335 | I7: =G7-H7 -> -332240335 | J7: =IF(AND(G7=0,H7>0),"皆増",IF(AND(G7>0,H7=0),"皆減",IF(AND(G7=0,H7=0),"-",H7/G7))) -> 1.0239801 | K7: =K8+K13+K14+K15+K12 -> 13993349494 | L7: =L8+L13+L14+L15+L12 -> 193752841 | M7: =IF(AND(K7=0,H7>0),"皆増",IF(AND(K7>0,H7=0),"皆減",IF(AND(K7=0,H7=0),"-",H7/K7))) -> 1.0138461 | N7: =N8+N13+N14+N15+N12 -> 0 | O7: =N7-H7 -> -14187102335 | P7: =H7/N7 -> #DIV/0! | R7: =IF(OR(G7>0,H7>0,K7>0),"表示（自動）","非表示（自動）") -> 表示（自動）
D8: 雨水処理負担金 | G8: =SUM(G9:G11) -> 13738282000 | H8: =SUM(H9:H11) -> 14079749832 | I8: =G8-H8 -> -341467832 | J8: =IF(AND(G8=0,H8>0),"皆増",IF(AND(G8>0,H8=0),"皆減",IF(AND(G8=0,H8=0),"-",H8/G8))) -> 1.0248552 | K8: =SUM(K9:K11) -> 13893559179 | L8: =SUM(L9:L11) -> 186190653 | M8: =IF(AND(K8=0,H8>0),"皆増",IF(AND(K8>0,H8=0),"皆減",IF(AND(K8=0,H8=0),"-",H8/K8))) -> 1.0134012 | N8: =SUM(N9:N11) -> 0 | O8: =N8-H8 -> -14079749832 | P8: =H8/N8 -> #DIV/0! | R8: =IF(OR(G8>0,H8>0,K8>0),"表示（自動）","非表示（自動）") -> 表示（自動）
E9: 維持管理費分 | G9: =3629553000+4934000+52311000 -> 3686798000 | H9: =+'[2]3条収入'!AI11 -> 3591522898 | I9: =G9-H9 -> 95275102 | J9: =IF(AND(G9=0,H9>0),"皆増",IF(AND(G9>0,H9=0),"皆減",IF(AND(G9=0,H9=0),"-",H9/G9))) -> 0.97415776 | K9: 3319461162 | L9: =H9-K9 -> 272061736 | M9: =IF(AND(K9=0,H9>0),"皆増",IF(AND(K9>0,H9=0),"皆減",IF(AND(K9=0,H9=0),"-",H9/K9))) -> 1.0819596 | O9: =N9-H9 -> -3591522898 | P9: =H9/N9 -> #DIV/0! | Q9: 補助費 | R9: =IF(OR(G9>0,H9>0,K9>0),"表示（自動）","非表示（自動）") -> 表示（自動）
E10: 減価償却費分 | G10: 7912710000 | H10: =+'[2]3条収入'!AI12 -> 8476549651 | I10: =G10-H10 -> -563839651 | J10: =IF(AND(G10=0,H10>0),"皆増",IF(AND(G10>0,H10=0),"皆減",IF(AND(G10=0,H10=0),"-",H10/G10))) -> 1.0712575 | K10: 8333522738 | L10: =H10-K10 -> 143026913 | M10: =IF(AND(K10=0,H10>0),"皆増",IF(AND(K10>0,H10=0),"皆減",IF(AND(K10=0,H10=0),"-",H10/K10))) -> 1.0171628 | O10: =N10-H10 -> -8476549651 | P10: =H10/N10 -> #DIV/0! | Q10: 普建 | R10: =IF(OR(G10>0,H10>0,K10>0),"表示（自動）","非表示（自動）") -> 表示（自動）
E11: 支払利息分 | G11: 2138774000 | H11: =+'[2]3条収入'!AI13 -> 2011677283 | I11: =G11-H11 -> 127096717 | J11: =IF(AND(G11=0,H11>0),"皆増",IF(AND(G11>0,H11=0),"皆減",IF(AND(G11=0,H11=0),"-",H11/G11))) -> 0.94057497 | K11: 2240575279 | L11: =H11-K11 -> -228897996 | M11: =IF(AND(K11=0,H11>0),"皆増",IF(AND(K11>0,H11=0),"皆減",IF(AND(K11=0,H11=0),"-",H11/K11))) -> 0.89783963 | O11: =N11-H11 -> -2011677283 | P11: =H11/N11 -> #DIV/0! | Q11: 普建 | R11: =IF(OR(G11>0,H11>0,K11>0),"表示（自動）","非表示（自動）") -> 表示（自動） | S11: ↓高資本費対策 R5決算から使うよ
D12: 高資本費対策費負担金 | G12: 0 | H12: 0 | I12: =G12-H12 -> 0 | J12: =IF(AND(G12=0,H12>0),"皆増",IF(AND(G12>0,H12=0),"皆減",IF(AND(G12=0,H12=0),"-",H12/G12))) -> - | K12: 0 | L12: =H12-K12 -> 0 | M12: =IF(AND(K12=0,H12>0),"皆増",IF(AND(K12>0,H12=0),"皆減",IF(AND(K12=0,H12=0),"-",H12/K12))) -> - | O12: =N12-H12 -> 0 | P12: =H12/N12 -> #DIV/0! | Q12: 普建 | R12: =IF(OR(G12>0,H12>0,K12>0),"表示（自動）","非表示（自動）") -> 非表示（自動） | S12: R5決算から使うよ
D13: 水質指導費負担金 | G13: 61778000 | H13: =+'[2]3条収入'!AI14 -> 52443869 | I13: =G13-H13 -> 9334131 | J13: =IF(AND(G13=0,H13>0),"皆増",IF(AND(G13>0,H13=0),"皆減",IF(AND(G13=0,H13=0),"-",H13/G13))) -> 0.84890849 | K13: 51549179 | L13: =H13-K13 -> 894690 | M13: =IF(AND(K13=0,H13>0),"皆増",IF(AND(K13>0,H13=0),"皆減",IF(AND(K13=0,H13=0),"-",H13/K13))) -> 1.017356 | O13: =N13-H13 -> -52443869 | P13: =H13/N13 -> #DIV/0! | Q13: 補助費 | R13: =IF(OR(G13>0,H13>0,K13>0),"表示（自動）","非表示（自動）") -> 表示（自動）
D14: 普及促進費負担金 | G14: 40039000 | H14: =+'[2]3条収入'!AI15 -> 44424775 | I14: =G14-H14 -> -4385775 | J14: =IF(AND(G14=0,H14>0),"皆増",IF(AND(G14>0,H14=0),"皆減",IF(AND(G14=0,H14=0),"-",H14/G14))) -> 1.1095376 | K14: 37494710 | L14: =H14-K14 -> 6930065 | M14: =IF(AND(K14=0,H14>0),"皆増",IF(AND(K14>0,H14=0),"皆減",IF(AND(K14=0,H14=0),"-",H14/K14))) -> 1.1848278 | O14: =N14-H14 -> -44424775 | P14: =H14/N14 -> #DIV/0! | Q14: 補助費 | R14: =IF(OR(G14>0,H14>0,K14>0),"表示（自動）","非表示（自動）") -> 表示（自動）
D15: 貸付事業費負担金 | G15: 14763000 | H15: =+'[2]3条収入'!AI16 -> 10483859 | I15: =G15-H15 -> 4279141 | J15: =IF(AND(G15=0,H15>0),"皆増",IF(AND(G15>0,H15=0),"皆減",IF(AND(G15=0,H15=0),"-",H15/G15))) -> 0.71014421 | K15: 10746426 | L15: =H15-K15 -> -262567 | M15: =IF(AND(K15=0,H15>0),"皆増",IF(AND(K15>0,H15=0),"皆減",IF(AND(K15=0,H15=0),"-",H15/K15))) -> 0.97556704 | O15: =N15-H15 -> -10483859 | P15: =H15/N15 -> #DIV/0! | Q15: 補助費 | R15: =IF(OR(G15>0,H15>0,K15>0),"表示（自動）","非表示（自動）") -> 表示（自動）
B16: 営業外収益 | G16: =G17 -> 0 | H16: =H17 -> 9203253 | I16: =G16-H16 -> -9203253 | J16: =IF(AND(G16=0,H16>0),"皆増",IF(AND(G16>0,H16=0),"皆減",IF(AND(G16=0,H16=0),"-",H16/G16))) -> 皆増 | K16: =K17 -> 31458 | L16: =SUM(L17) -> 9171795 | M16: =IF(AND(K16=0,H16>0),"皆増",IF(AND(K16>0,H16=0),"皆減",IF(AND(K16=0,H16=0),"-",H16/K16))) -> 292.55684 | N16: =N17 -> 0 | O16: =N16-H16 -> -9203253 | P16: =H16/N16 -> #DIV/0! | R16: =IF(OR(G16>0,H16>0,K16>0),"表示（自動）","非表示（自動）") -> 表示（自動）
C17: 一般会計補助金 | G17: =G18+G25 -> 0 | H17: =H18+H25 -> 9203253 | I17: =G17-H17 -> -9203253 | J17: =IF(AND(G17=0,H17>0),"皆増",IF(AND(G17>0,H17=0),"皆減",IF(AND(G17=0,H17=0),"-",H17/G17))) -> 皆増 | K17: =K18+K25 -> 31458 | L17: =SUM(L18,L25) -> 9171795 | M17: =IF(AND(K17=0,H17>0),"皆増",IF(AND(K17>0,H17=0),"皆減",IF(AND(K17=0,H17=0),"-",H17/K17))) -> 292.55684 | N17: =N18 -> 0 | O17: =N17-H17 -> -9203253 | P17: =H17/N17 -> #DIV/0! | R17: =IF(OR(G17>0,H17>0,K17>0),"表示（自動）","非表示（自動）") -> 表示（自動）
D18: 汚水処理補助金 | G18: =SUM(G19:G22) -> 0 | H18: =SUM(H19:H22) -> 4980 | I18: =G18-H18 -> -4980 | J18: =IF(AND(G18=0,H18>0),"皆増",IF(AND(G18>0,H18=0),"皆減",IF(AND(G18=0,H18=0),"-",H18/G18))) -> 皆増 | K18: =SUM(K19:K22) -> 31458 | L18: =SUM(L19:L22) -> -26478 | M18: =IF(AND(K18=0,H18>0),"皆増",IF(AND(K18>0,H18=0),"皆減",IF(AND(K18=0,H18=0),"-",H18/K18))) -> 0.15830631 | N18: =SUM(N19:N22) -> 0 | O18: =N18-H18 -> -4980 | P18: =H18/N18 -> #DIV/0! | R18: =IF(OR(G18>0,H18>0,K18>0),"表示（自動）","非表示（自動）") -> 表示（自動）
E19: 維持管理費分 | G19: 0 | H19: =+'[2]3条収入'!AI44 -> 0 | I19: =G19-H19 -> 0 | J19: =IF(AND(G19=0,H19>0),"皆増",IF(AND(G19>0,H19=0),"皆減",IF(AND(G19=0,H19=0),"-",H19/G19))) -> - | L19: 0 | M19: =IF(AND(K19=0,H19>0),"皆増",IF(AND(K19>0,H19=0),"皆減",IF(AND(K19=0,H19=0),"-",H19/K19))) -> - | N19: 0 | O19: 0 | P19: - | R19: =IF(OR(G19>0,H19>0,K19>0),"表示（自動）","非表示（自動）") -> 非表示（自動）
E20: 減価償却費分 | G20: 0 | H20: =+'[2]3条収入'!AI45 -> 0 | I20: =G20-H20 -> 0 | J20: =IF(AND(G20=0,H20>0),"皆増",IF(AND(G20>0,H20=0),"皆減",IF(AND(G20=0,H20=0),"-",H20/G20))) -> - | K20: 0 | L20: =H20-K20 -> 0 | M20: =IF(AND(K20=0,H20>0),"皆増",IF(AND(K20>0,H20=0),"皆減",IF(AND(K20=0,H20=0),"-",H20/K20))) -> - | O20: =N20-H20 -> 0 | P20: =H20/N20 -> #DIV/0! | Q20: 普建 | R20: =IF(OR(G20>0,H20>0,K20>0),"表示（自動）","非表示（自動）") -> 非表示（自動）
E21: 支払利息分 | G21: 0 | H21: =+'[2]3条収入'!AI46 -> 0 | I21: =G21-H21 -> 0 | J21: =IF(AND(G21=0,H21>0),"皆増",IF(AND(G21>0,H21=0),"皆減",IF(AND(G21=0,H21=0),"-",H21/G21))) -> - | K21: 0 | L21: =H21-K21 -> 0 | M21: =IF(AND(K21=0,H21>0),"皆増",IF(AND(K21>0,H21=0),"皆減",IF(AND(K21=0,H21=0),"-",H21/K21))) -> - | O21: =N21-H21 -> 0 | P21: =H21/N21 -> #DIV/0! | Q21: 普建 | R21: =IF(OR(G21>0,H21>0,K21>0),"表示（自動）","非表示（自動）") -> 非表示（自動）
E22: 下水道使用料減免分 | G22: 0 | H22: =+'[2]3条収入'!AI47 -> 4980 | I22: =G22-H22 -> -4980 | J22: =IF(AND(G22=0,H22>0),"皆増",IF(AND(G22>0,H22=0),"皆減",IF(AND(G22=0,H22=0),"-",H22/G22))) -> 皆増 | K22: 31458 | L22: =H22-K22 -> -26478 | M22: =IF(AND(K22=0,H22>0),"皆増",IF(AND(K22>0,H22=0),"皆減",IF(AND(K22=0,H22=0),"-",H22/K22))) -> 0.15830631 | O22: =N22-H22 -> -4980 | P22: =H22/N22 -> #DIV/0! | Q22: 普建 | R22: =IF(OR(G22>0,H22>0,K22>0),"表示（自動）","非表示（自動）") -> 表示（自動）
F23: 当年度分 | I23: =G23-H23 -> 0 | J23: =IF(AND(G23=0,H23>0),"皆増",IF(AND(G23>0,H23=0),"皆減",IF(AND(G23=0,H23=0),"-",H23/G23))) -> - | L23: =H23-K23 -> 0 | M23: =IF(AND(K23=0,H23>0),"皆増",IF(AND(K23>0,H23=0),"皆減",IF(AND(K23=0,H23=0),"-",H23/K23))) -> - | R23: =IF(OR(G23>0,H23>0,K23>0),"表示（自動）","非表示（自動）") -> 非表示（自動）
F24: 前年度未収分 | G24: 0 | I24: =G24-H24 -> 0 | J24: =IF(AND(G24=0,H24>0),"皆増",IF(AND(G24>0,H24=0),"皆減",IF(AND(G24=0,H24=0),"-",H24/G24))) -> - | K24: 0 | L24: =H24-K24 -> 0 | M24: =IF(AND(K24=0,H24>0),"皆増",IF(AND(K24>0,H24=0),"皆減",IF(AND(K24=0,H24=0),"-",H24/K24))) -> - | R24: =IF(OR(G24>0,H24>0,K24>0),"表示（自動）","非表示（自動）") -> 非表示（自動） | T24: =IF(ISERROR(H24/G24),IF(AND(G24=0,H24=0),"-",IF(G24=0,"皆増",H24/G24)),H24/G24) -> -
D25: その他補助金 | G25: 0 | H25: =+'[2]3条収入'!AI48 -> 9198273 | I25: =G25-H25 -> -9198273 | J25: =IF(AND(G25=0,H25>0),"皆増",IF(AND(G25>0,H25=0),"皆減",IF(AND(G25=0,H25=0),"-",H25/G25))) -> 皆増 | K25: 0 | L25: =H25-K25 -> 9198273 | M25: =IF(AND(K25=0,H25>0),"皆増",IF(AND(K25>0,H25=0),"皆減",IF(AND(K25=0,H25=0),"-",H25/K25))) -> 皆増 | Q25: 補助費 | R25: =IF(OR(G25>0,H25>0,K25>0),"表示（自動）","非表示（自動）") -> 表示（自動）
A26: 資本的収入 | G26: =G27+G30 -> 3640474000 | H26: =H27+H30 -> 3285504551 | I26: =G26-H26 -> 354969449 | J26: =IF(AND(G26=0,H26>0),"皆増",IF(AND(G26>0,H26=0),"皆減",IF(AND(G26=0,H26=0),"-",H26/G26))) -> 0.90249362 | K26: =K27+K30 -> 4465118734 | L26: =H26-K26 -> -1179614183 | M26: =IF(AND(K26=0,H26>0),"皆増",IF(AND(K26>0,H26=0),"皆減",IF(AND(K26=0,H26=0),"-",H26/K26))) -> 0.73581572 | N26: =N27+N30 -> 0 | O26: =N26-H26 -> -3285504551 | P26: =H26/N26 -> #DIV/0! | R26: =IF(OR(G26>0,H26>0,K26>0),"表示（自動）","非表示（自動）") -> 表示（自動）
B27: 一般会計出資金 | G27: =G28 -> 3640474000 | H27: =H28 -> 3285504551 | I27: =G27-H27 -> 354969449 | J27: =IF(AND(G27=0,H27>0),"皆増",IF(AND(G27>0,H27=0),"皆減",IF(AND(G27=0,H27=0),"-",H27/G27))) -> 0.90249362 | K27: =K28 -> 4465118734 | L27: =H27-K27 -> -1179614183 | M27: =IF(AND(K27=0,H27>0),"皆増",IF(AND(K27>0,H27=0),"皆減",IF(AND(K27=0,H27=0),"-",H27/K27))) -> 0.73581572 | N27: =N28 -> 0 | O27: =N27-H27 -> -3285504551 | P27: =H27/N27 -> #DIV/0! | R27: =IF(OR(G27>0,H27>0,K27>0),"表示（自動）","非表示（自動）") -> 表示（自動）
C28: 下水道建設費出資金 | G28: =SUM(G29:G29) -> 3640474000 | H28: =SUM(H29:H29) -> 3285504551 | I28: =SUM(I29:I29) -> 354969449 | J28: =IF(AND(G28=0,H28>0),"皆増",IF(AND(G28>0,H28=0),"皆減",IF(AND(G28=0,H28=0),"-",H28/G28))) -> 0.90249362 | K28: =SUM(K29:K29) -> 4465118734 | L28: =H28-K28 -> -1179614183 | M28: =IF(AND(K28=0,H28>0),"皆増",IF(AND(K28>0,H28=0),"皆減",IF(AND(K28=0,H28=0),"-",H28/K28))) -> 0.73581572 | N28: =N29 -> 0 | O28: =N28-H28 -> -3285504551 | P28: =H28/N28 -> #DIV/0! | R28: =IF(OR(G28>0,H28>0,K28>0),"表示（自動）","非表示（自動）") -> 表示（自動）
D29: 下水道建設費出資金 | G29: 3640474000 | H29: =+'[5]4条収入'!E22 -> 3285504551 | I29: =G29-H29 -> 354969449 | J29: =IF(AND(G29=0,H29>0),"皆増",IF(AND(G29>0,H29=0),"皆減",IF(AND(G29=0,H29=0),"-",H29/G29))) -> 0.90249362 | K29: 4465118734 | L29: =H29-K29 -> -1179614183 | M29: =IF(AND(K29=0,H29>0),"皆増",IF(AND(K29>0,H29=0),"皆減",IF(AND(K29=0,H29=0),"-",H29/K29))) -> 0.73581572 | O29: =N29-H29 -> -3285504551 | P29: =H29/N29 -> #DIV/0! | Q29: 普建 | R29: =IF(OR(G29>0,H29>0,K29>0),"表示（自動）","非表示（自動）") -> 表示（自動）
B30: 水洗化貸付事業収入 | G30: =G31 -> 0 | H30: =H31 -> 0 | I30: =G30-H30 -> 0 | J30: =IF(AND(G30=0,H30>0),"皆増",IF(AND(G30>0,H30=0),"皆減",IF(AND(G30=0,H30=0),"-",H30/G30))) -> - | K30: =K31 -> 0 | L30: =H30-K30 -> 0 | M30: =IF(AND(K30=0,H30>0),"皆増",IF(AND(K30>0,H30=0),"皆減",IF(AND(K30=0,H30=0),"-",H30/K30))) -> - | N30: =N31 -> 0 | O30: =N30-H30 -> 0 | P30: =H30/N30 -> #DIV/0! | R30: =IF(OR(G30>0,H30>0,K30>0),"表示（自動）","非表示（自動）") -> 非表示（自動）
C31: 一般会計借入金 | G31: =SUM(G32:G34) -> 0 | H31: =SUM(H32:H34) -> 0 | I31: =G31-H31 -> 0 | J31: =IF(AND(G31=0,H31>0),"皆増",IF(AND(G31>0,H31=0),"皆減",IF(AND(G31=0,H31=0),"-",H31/G31))) -> - | K31: =SUM(K32:K34) -> 0 | L31: =H31-K31 -> 0 | M31: =IF(AND(K31=0,H31>0),"皆増",IF(AND(K31>0,H31=0),"皆減",IF(AND(K31=0,H31=0),"-",H31/K31))) -> - | N31: =SUM(N32:N34) -> 0 | O31: =N31-H31 -> 0 | P31: =H31/N31 -> #DIV/0! | Q31: 貸付金 | R31: =IF(OR(G31>0,H31>0,K31>0),"表示（自動）","非表示（自動）") -> 非表示（自動）
D32: 水洗便所改造資金 貸付借入金 | G32: 0 | H32: =+'[5]4条収入'!E59 -> 0 | I32: =G32-H32 -> 0 | J32: =IF(AND(G32=0,H32>0),"皆増",IF(AND(G32>0,H32=0),"皆減",IF(AND(G32=0,H32=0),"-",H32/G32))) -> - | K32: 0 | L32: =H32-K32 -> 0 | M32: =IF(AND(K32=0,H32>0),"皆増",IF(AND(K32>0,H32=0),"皆減",IF(AND(K32=0,H32=0),"-",H32/K32))) -> - | O32: =N32-H32 -> 0 | P32: =H32/N32 -> #DIV/0! | R32: =IF(OR(G32>0,H32>0,K32>0),"表示（自動）","非表示（自動）") -> 非表示（自動）
D33: し尿浄化槽廃止資金 貸付借入金 | G33: 0 | H33: =+'[5]4条収入'!E63 -> 0 | I33: =G33-H33 -> 0 | J33: =IF(AND(G33=0,H33>0),"皆増",IF(AND(G33>0,H33=0),"皆減",IF(AND(G33=0,H33=0),"-",H33/G33))) -> - | K33: 0 | L33: =H33-K33 -> 0 | M33: =IF(AND(K33=0,H33>0),"皆増",IF(AND(K33>0,H33=0),"皆減",IF(AND(K33=0,H33=0),"-",H33/K33))) -> - | O33: =N33-H33 -> 0 | P33: =H33/N33 -> #DIV/0! | R33: =IF(OR(G33>0,H33>0,K33>0),"表示（自動）","非表示（自動）") -> 非表示（自動）
D34: 排水設備改修資金 貸付借入金 | G34: 0 | H34: =+'[5]4条収入'!E67 -> 0 | I34: =G34-H34 -> 0 | J34: =IF(AND(G34=0,H34>0),"皆増",IF(AND(G34>0,H34=0),"皆減",IF(AND(G34=0,H34=0),"-",H34/G34))) -> - | K34: 0 | L34: =H34-K34 -> 0 | M34: =IF(AND(K34=0,H34>0),"皆増",IF(AND(K34>0,H34=0),"皆減",IF(AND(K34=0,H34=0),"-",H34/K34))) -> - | O34: =N34-H34 -> 0 | P34: =H34/N34 -> #DIV/0! | R34: =IF(OR(G34>0,H34>0,K34>0),"表示（自動）","非表示（自動）") -> 非表示（自動）
A35: 計 （下水決算分） | G35: =G5+G26 -> 17495336000 | H35: =H5+H26 -> 17481810139 | I35: =G35-H35 -> 13525861 | J35: =IF(AND(G35=0,H35>0),"皆増",IF(AND(G35>0,H35=0),"皆減",IF(AND(G35=0,H35=0),"-",H35/G35))) -> 0.99922689 | K35: =K5+K26 -> 18458499686 | L35: =H35-K35 -> -976689547 | M35: =IF(AND(K35=0,H35>0),"皆増",IF(AND(K35>0,H35=0),"皆減",IF(AND(K35=0,H35=0),"-",H35/K35))) -> 0.94708727 | N35: =N5+N26 -> 0 | O35: =N35-H35 -> -17481810139 | P35: =H35/N35 -> #DIV/0! | R35: =IF(OR(G35>0,H35>0,K35>0),"表示（自動）","非表示（自動）") -> 表示（自動）
A36: 前受金 （災害復旧等繰越財源分） | G36: 0 | H36: ='(繰)繰入金'!H35 -> 0 | I36: =G36-H36 -> 0 | J36: - | K36: 0 | L36: =H36-K36 -> 0 | M36: =IF(AND(K36=0,H36>0),"皆増",IF(AND(K36>0,H36=0),"皆減",IF(AND(K36=0,H36=0),"-",H36/K36))) -> - | N36: =N8+N29 -> 0 | O36: =N36-H36 -> 0 | P36: =H36/N36 -> #DIV/0! | Q36: 補助費 | R36: =IF(OR(G36>0,H36>0,K36>0),"表示（自動）","非表示（自動）") -> 非表示（自動）
A37: 計 | G37: =G35+G36 -> 17495336000 | H37: =H35+H36 -> 17481810139 | I37: =G37-H37 -> 13525861 | J37: =IF(AND(G37=0,H37>0),"皆増",IF(AND(G37>0,H37=0),"皆減",IF(AND(G37=0,H37=0),"-",H37/G37))) -> 0.99922689 | K37: =K35+K36 -> 18458499686 | L37: =H37-K37 -> -976689547 | M37: =IF(AND(K37=0,H37>0),"皆増",IF(AND(K37>0,H37=0),"皆減",IF(AND(K37=0,H37=0),"-",H37/K37))) -> 0.94708727 | N37: =N11+N32 -> 0 | O37: =N37-H37 -> -17481810139 | P37: =H37/N37 -> #DIV/0! | R37: =IF(OR(G37>0,H37>0,K37>0),"表示（自動）","非表示（自動）") -> 表示（自動）
A38: 前年度下水道建設費出資金未収金 | G38: 0 | H38: 0 | I38: =G38-H38 -> 0 | J38: - | K38: 0 | L38: =H38-K38 -> 0 | M38: =IF(AND(K38=0,H38>0),"皆増",IF(AND(K38>0,H38=0),"皆減",IF(AND(K38=0,H38=0),"-",H38/K38))) -> - | R38: =IF(OR(G38>0,H38>0,K38>0),"表示（自動）","非表示（自動）") -> 非表示（自動）
A39: 合 計 | G39: =G37+G38 -> 17495336000 | H39: =H37+H38 -> 17481810139 | I39: =I37+I38 -> 13525861 | J39: =IF(AND(G39=0,H39>0),"皆増",IF(AND(G39>0,H39=0),"皆減",IF(AND(G39=0,H39=0),"-",H39/G39))) -> 0.99922689 | K39: =K37+K38 -> 18458499686 | L39: =H39-K39 -> -976689547 | M39: =IF(AND(K39=0,H39>0),"皆増",IF(AND(K39>0,H39=0),"皆減",IF(AND(K39=0,H39=0),"-",H39/K39))) -> 0.94708727 | R39: =IF(OR(G39>0,H39>0,K39>0),"表示（自動）","非表示（自動）") -> 表示（自動）
R40: 表示（強制）
...

Sheet (繰)3条収入
C1: =+CONCATENATE(LEFT('[1]3条支出'!$D$1,5)," 収益的収入（決算）") -> 令和５年度 収益的収入（決算） | H1: （単位：円）
A2: 科 目 | D2: 予算額（繰越+現年） | E2: 流用・振替等 | F2: 現計予算額 | G2: 税込決算額 | H2: 税抜決算額
D3: （補正後） Ａ | E3: 増減額 Ｂ | F3: Ｃ（Ａ＋Ｂ） | G3: Ｄ | H3: （消費税雑収益加算後）
A4: 下水道事業収益 | D4: =D5+D10+D19 -> 44975817000 | E4: =E5+E10+E19 -> 0 | F4: =D4+E4 -> 44975817000 | G4: =G5+G10+G19 -> 44454711283 | H4: =H5+H10+H19 -> 42572042134
B5: 営業収益 | D5: =+SUM(D6:D9) -> 35444153000 | E5: =+SUM(E6:E9) -> 0 | F5: =+SUM(F6:F9) -> 35444153000 | G5: =+SUM(G6:G9) -> 34865911732 | H5: =+SUM(H6:H9) -> 32986083408
C6: 下水道使用料 | D6: 21384728000 | F6: =D6+E6 -> 21384728000 | G6: =+'[2]3条収入'!$E$8 -> 20488962528 | H6: =+'[2]3条収入'!$AI$8 -> 18626337467
C7: 一般会計負担金 | D7: 13854862000 | F7: =D7+E7 -> 13854862000 | G7: =+'[2]3条収入'!$E$9 -> 14187102335 | H7: =+'[2]3条収入'!$AI$9 -> 14187102335
C8: 受託工事収益 | F8: =D8+E8 -> 0 | G8: =+'[2]3条収入'!$E$18 -> 0 | H8: =+'[2]3条収入'!$AI$18 -> 0
C9: その他営業収益 | D9: 204563000 | F9: =D9+E9 -> 204563000 | G9: =+'[2]3条収入'!$E$19 -> 189846869 | H9: =+'[2]3条収入'!$AI$19 -> 172643606
B10: 営業外収益 | D10: =+SUM(D11:D18) -> 9528788000 | E10: =+SUM(E11:E18) -> 0 | F10: =+SUM(F11:F18) -> 9528788000 | G10: =+SUM(G11:G18) -> 9584600552 | H10: =+SUM(H11:H18) -> 9581905615
C11: 受取利息 | D11: 70000 | F11: =D11+E11 -> 70000 | G11: =+'[2]3条収入'!$E$28 -> 88770 | H11: =+'[2]3条収入'!$AI$28 -> 88770
C12: 国庫補助金 | F12: =D12+E12 -> 0 | G12: =+'[2]3条収入'!$E$32 -> 0 | H12: =+'[2]3条収入'!$AI$32 -> 0
C13: 県補助金 | F13: =D13+E13 -> 0
C14: 負担金 | D14: 49683000 | F14: =D14+E14 -> 49683000 | G14: =+'[2]3条収入'!$E$39 -> 53493193 | H14: =+'[2]3条収入'!$AI$39 -> 50128048
C15: 一般会計補助金 | F15: =D15+E15 -> 0 | G15: =+'[2]3条収入'!$E$42 -> 9203253 | H15: =+'[2]3条収入'!$AI$42 -> 9203253
C16: 消費税等還付金 | D16: 0 | E16: 0 | F16: =D16+E16 -> 0 | G16: =+'[2]3条収入'!$E$49 -> 0 | H16: =+'[2]3条収入'!$AI$49 -> 0
C17: 雑収益 | D17: 23945000 | F17: =D17+E17 -> 23945000 | G17: =+'[2]3条収入'!$E$51 -> 36460334 | H17: =+'[2]3条収入'!$AI$51 -> 37130542
C18: 長期前受金戻入（償却・除却） | D18: 9455090000 | F18: =D18+E18 -> 9455090000 | G18: =+'[2]3条収入'!$E$55 -> 9485355002 | H18: =+'[2]3条収入'!$AI$55 -> 9485355002
B19: 特別利益 | D19: =+SUM(D20:D23) -> 2876000 | E19: =+SUM(E20:E23) -> 0 | F19: =+SUM(F20:F23) -> 2876000 | G19: =+SUM(G20:G23) -> 4198999 | H19: =+SUM(H20:H23) -> 4053111
C20: 長期前受金戻入益（減損） | D20: 0 | F20: =D20+E20 -> 0 | G20: =+'[2]3条収入'!$E$66 -> 0 | H20: =+'[2]3条収入'!$AI$66 -> 0
C21: 固定資産売却益 | D21: 0 | F21: =D21+E21 -> 0 | G21: =+'[2]3条収入'!$E$58 -> 0 | H21: =+'[2]3条収入'!$AI$58 -> 0
C22: 過年度損益修正益 | D22: 2876000 | F22: =D22+E22 -> 2876000 | G22: =+'[2]3条収入'!$E$60 -> 2769570 | H22: =+'[2]3条収入'!$AI$60 -> 2623682
C23: その他特別利益 | D23: 0 | F23: =D23+E23 -> 0 | G23: =+'[2]3条収入'!$E$62 -> 1429429 | H23: =+'[2]3条収入'!$AI$62 -> 1429429
F26: 純利益 | G26: =+G4-'(繰)3条支出 '!G4+[3]消費税!AF113 -> 1811041626 | H26: =+H4-'(繰)3条支出 '!I4 -> 543907199
F27: 繰入金を除いた額→ | G27: =G4-G7-G15 -> 30258405695 | H27: =H4-H7-H15 -> 28375736546
H29: =+'[2]3条収入'!AI74 -> 543907199
H30: =+H26-H29 -> 0

Sheet (繰)3条支出 
C1: =+CONCATENATE(LEFT('[1]3条支出'!$D$1,5)," 収益的支出（決算）") -> 令和５年度 収益的支出（決算） | I1: （単位：円）
A2: 科 目 | D2: 予算額（繰越+現年） | E2: 流用・振替等 | F2: 現計予算額 | G2: 税込決算額 | H2: 税抜決算額 | I2: 税抜決算額
D3: （補正後） Ａ | E3: 増減額 Ｂ | F3: Ｃ（Ａ＋Ｂ） | G3: Ｄ | H3: 控除不可消費税加算前 | I3: 控除不可消費税加算後
A4: 下水道事業費用 | D4: =D5+D20+D24+D29 -> 43953299000 | E4: =E5+E20+E24+E29 -> 0 | F4: =F5+F20+F24+F29 -> 43953299000 | G4: =G5+G20+G24+G29 -> 42643669657 | H4: =H5+H20+H24+H29 -> 41815647458 | I4: =I5+I20+I24+I29 -> 42028134935
B5: 営業費用 | D5: =+SUM(D6:D19) -> 39325285000 | E5: =+SUM(E6:E19) -> 0 | F5: =+SUM(F6:F19) -> 39325285000 | G5: =+SUM(G6:G19) -> 38667489041 | H5: =+SUM(H6:H19) -> 37846544540 | I5: =+SUM(I6:I19) -> 37846544540
C6: 管きょ費 | D6: 649416000 | E6: 0 | F6: =D6+E6 -> 649416000 | G6: =+'[1]3条支出'!$E$6 -> 611819957 | H6: =+'[1]3条支出'!$T$6 -> 564664608 | I6: =+'[1]3条支出'!$T$6 -> 564664608
C7: 水質指導費 | D7: 61778000 | E7: 0 | F7: =D7+E7 -> 61778000 | G7: =+'[1]3条支出'!$E$7 -> 52443869 | H7: =+'[1]3条支出'!$T$7 -> 51313295 | I7: =+'[1]3条支出'!$T$7 -> 51313295
C8: ポンプ場費 | D8: 2446053000 | E8: -14060287 | F8: =D8+E8 -> 2431992713 | G8: =+'[1]3条支出'!$E$8 -> 2356040225 | H8: =+'[1]3条支出'!$T$8 -> 2251657967 | I8: =+'[1]3条支出'!$T$8 -> 2251657967
C9: 処理場費 | D9: 7107004000 | E9: 1992633 | F9: =D9+E9 -> 7108996633 | G9: =+'[1]3条支出'!$E$9 -> 6557703864 | H9: =+'[1]3条支出'!$T$9 -> 6037810078 | I9: =+'[1]3条支出'!$T$9 -> 6037810078
C10: 普及促進費 | D10: 80070000 | E10: 12067654 | F10: =D10+E10 -> 92137654 | G10: =+'[1]3条支出'!$E$11 -> 88849549 | H10: =+'[1]3条支出'!$T$11 -> 87134052 | I10: =+'[1]3条支出'!$T$11 -> 87134052
C11: 水洗化貸付事業費 | D11: 14763000 | E11: 0 | F11: =D11+E11 -> 14763000 | G11: =+'[1]3条支出'!$E$12 -> 10483859 | H11: =+'[1]3条支出'!$T$12 -> 10396270 | I11: =+'[1]3条支出'!$T$12 -> 10396270
C12: 業務費 | D12: 1032244000 | E12: 0 | F12: =D12+E12 -> 1032244000 | G12: =+'[1]3条支出'!$E$13 -> 1019945143 | H12: =+'[1]3条支出'!$T$13 -> 929691714 | I12: =+'[1]3条支出'!$T$13 -> 929691714
C13: 総係費 | D13: 552278000 | E13: 0 | F13: =D13+E13 -> 552278000 | G13: =+'[1]3条支出'!$E$14 -> 483965214 | H13: =+'[1]3条支出'!$T$14 -> 466286409 | I13: =+'[1]3条支出'!$T$14 -> 466286409
C14: 特環公共下水道費 | D14: =108656000+623000 -> 109279000 | E14: 1800000 | F14: =D14+E14 -> 111079000 | G14: =+'[1]3条支出'!$E$15 -> 106990906 | H14: =+'[1]3条支出'!$T$15 -> 97276922 | I14: =+'[1]3条支出'!$T$15 -> 97276922
C15: 農業集落排水費 | D15: =257093000+4311000 -> 261404000 | E15: -1800000 | F15: =D15+E15 -> 259604000 | G15: =+'[1]3条支出'!$E$16 -> 247654024 | H15: =+'[1]3条支出'!$T$16 -> 225167795 | I15: =+'[1]3条支出'!$T$16 -> 225167795
C16: 浄化槽費 | D16: 78829000 | E16: 0 | F16: =D16+E16 -> 78829000 | G16: =+'[1]3条支出'!$E$17 -> 76388330 | H16: =+'[1]3条支出'!$T$17 -> 69941329 | I16: =+'[1]3条支出'!$T$17 -> 69941329
C17: 災害復旧費 | D17: 0 | E17: 0 | F17: =D17+E17 -> 0 | G17: =+'[1]3条支出'!$E$18 -> 0 | H17: =+'[1]3条支出'!$T$18 -> 0 | I17: =+'[1]3条支出'!$T$18 -> 0
C18: 減価償却費 | D18: 26580629000 | E18: 0 | F18: =D18+E18 -> 26580629000 | G18: =+'[1]3条支出'!$E$19 -> 26551442230 | H18: =+'[1]3条支出'!$T$19 -> 26551442230 | I18: =+'[1]3条支出'!$T$19 -> 26551442230
C19: 資産減耗費 | D19: 351538000 | E19: 0 | F19: =D19+E19 -> 351538000 | G19: =+'[1]3条支出'!$E$20 -> 503761871 | H19: =+'[1]3条支出'!$T$20 -> 503761871 | I19: =+'[1]3条支出'!$T$20 -> 503761871
B20: 営業外費用 | D20: =+SUM(D21:D23) -> 4599725000 | E20: =+SUM(E21:E23) -> 9198273 | F20: =+SUM(F21:F23) -> 4608923273 | G20: =+SUM(G21:G23) -> 3955185318 | H20: =+SUM(H21:H23) -> 3949076064 | I20: =+SUM(I21:I23) -> 4161563541
C21: 支払利息及び 企業債取扱諸費 | D21: 4207550000 | E21: -25896 | F21: =D21+E21 -> 4207524104 | G21: =+'[1]3条支出'!$E$23 -> 3945961149 | H21: =+'[1]3条支出'!$T$23 -> 3940341717 | I21: =+'[1]3条支出'!$T$23 -> 3940341717
C22: 消費税 | D22: 392158000 | E22: 0 | F22: =D22+E22 -> 392158000 | G22: =+[3]消費税!Z113+[3]消費税!AF113 -> 0
C23: 雑支出 | D23: 17000 | E23: 9224169 | F23: =D23+E23 -> 9241169 | G23: =+'[1]3条支出'!$E$24 -> 9224169 | H23: =+'[1]3条支出'!$T$24 -> 8734347 | I23: =+'[1]3条支出'!$T$24++'[1]3条支出'!$T$25 -> 221221824
B24: 特別損失 | D24: =+SUM(D25:D28) -> 8289000 | E24: =+SUM(E25:E28) -> 0 | F24: =+SUM(F25:F28) -> 8289000 | G24: =+SUM(G25:G28) -> 20995298 | H24: =+SUM(H25:H28) -> 20026854 | I24: =+SUM(I25:I28) -> 20026854
C25: 固定資産売却損 | D25: 0 | E25: 0 | F25: =D25+E25 -> 0 | G25: =+'[1]3条支出'!$E$30 -> 10315355 | H25: =+'[1]3条支出'!$T$30 -> 10315355 | I25: =+'[1]3条支出'!$T$30 -> 10315355
C26: 過年度損益修正損 | D26: 8248000 | E26: 0 | F26: =D26+E26 -> 8248000 | G26: =+'[1]3条支出'!$E$28 -> 10679943 | H26: =+'[1]3条支出'!$T$28 -> 9711499 | I26: =+'[1]3条支出'!$T$28 -> 9711499
C27: その他特別損失 | D27: 41000 | E27: 0 | F27: =D27+E27 -> 41000 | G27: =+'[1]3条支出'!$E$29 -> 0 | H27: =+'[1]3条支出'!$T$29 -> 0 | I27: =+'[1]3条支出'!$T$29 -> 0
C28: 減損損失 | D28: 0 | E28: 0 | F28: =D28+E28 -> 0 | G28: =+'[1]3条支出'!$E$31 -> 0 | H28: =+'[1]3条支出'!$T$31 -> 0 | I28: =+'[1]3条支出'!$T$31 -> 0
B29: 予備費 | D29: =D30 -> 20000000 | E29: =E30 -> -9198273 | F29: =F30 -> 10801727 | G29: =G30 -> 0 | H29: =H30 -> 0 | I29: =I30 -> 0
C30: 予備費 | D30: 20000000 | E30: -9198273 | F30: =D30+E30 -> 10801727 | G30: 0 | H30: 0 | I30: 0
E50: 、

Sheet (繰)4条収入
C1: =+CONCATENATE(LEFT('[1]3条支出'!$D$1,5)," 資本的収入（決算）") -> 令和５年度 資本的収入（決算）
A2: =+CONCATENATE("（",MID([4]雨汚水!D1,3,1),"年度現年度分みなしベース）") -> （５年度現年度分みなしベース） | M2: （単位：円） | O2: （単位：円）
A3: 科 目 | D3: 議決予算額 （補正後） | E3: 流用・振替等 増減額 | F3: 現計予算額 | G3: 決算額（電算） | H3: 前年度充当額（未発行債） | I3: 当年度決算額 | J3: 前年度繰越 充当財源 | K3: 当年度決算 未充当額 | L3: 翌年度繰越 充当財源 | M3: みなし決算額 | N3: 翌年度繰越 充当額 | O3: 差 引
D4: Ａ | E4: Ｂ | F4: Ｃ（Ａ＋Ｂ） | G4: Ｄ | H4: E | I4: F(D-E) | J4: Ｇ | K4: Ｈ | L4: Ｉ | M4: Ｊ(F-G+H＋Ｉ) | N4: K | O4: J－Ｃ
A5: 資本的収入 | D5: =SUM(D6,D13,D16,D20,D22,D26,D30,D32) -> 42627050000 | E5: =SUM(E6,E13,E16,E20,E22,E26,E30,E32) -> 0 | F5: =SUM(F6,F13,F16,F20,F22,F26,F30,F32) -> 42627050000 | G5: =SUM(G6,G13,G16,G20,G22,G26,G30,G32) -> 42025205141 | H5: =SUM(H6,H13,H16,H20,H22,H26,H30,H32) -> 0 | I5: =SUM(I6,I13,I16,I20,I22,I26,I30,I32) -> 42025205141 | J5: =SUM(J6,J13,J16,J20,J22,J26,J30,J32) -> 8421400000 | K5: =SUM(K6,K13,K16,K20,K22,K26,K30,K32) -> 0 | ... O5: =SUM(O6,O13,O16,O20,O22,O26,O30,O32) -> -411506598
B6: 企業債 | D6: =SUM(D7:D12) -> 32505200000 | E6: =SUM(E7:E12) -> 0 | F6: =SUM(F7:F12) -> 32505200000 | G6: =SUM(G7:G12) -> 32373300000 | H6: =SUM(H7:H12) -> 0 | I6: =SUM(I7:I12) -> 32373300000 | J6: =SUM(J7:J12) -> 5247400000 | K6: =SUM(K7:K12) -> 0 | ... O6: =SUM(O7:O12) -> -152500000
C7: 公共下水道事業債 | D7: =8330600000+654200000 -> 8984800000 | E7: 0 | F7: =D7+E7 -> 8984800000 | G7: =+'[5]4条収入'!$E$9 -> 8822500000 | H7: 0 | I7: =G7-H7 -> 8822500000 | J7: 4973100000 | L7: 5135400000 | M7: =I7-J7+K7+L7 -> 8984800000 | N7: =L7 -> 5135400000 | O7: =M7-F7 -> 0
C8: 市街化区域外汚水処理施設事業債 | D8: 310500000 | E8: 0 | F8: =D8+E8 -> 310500000 | G8: =+'[5]4条収入'!$E$12 -> 493400000 | H8: 0 | I8: =G8-H8 -> 493400000 | J8: 274300000 | L8: 91400000 | M8: =I8-J8+K8+L8 -> 310500000 | N8: =L8 -> 91400000 | O8: =F8-M8 -> 0
C9: 流域下水道事業債 | D9: 160100000 | E9: 0 | F9: =D9+E9 -> 160100000 | G9: =+'[5]4条収入'!$E$13 -> 120200000 | H9: 0 | I9: =G9-H9 -> 120200000 | M9: =I9-J9+K9+L9 -> 120200000 | N9: =L9 -> 0 | O9: =M9-F9 -> -39900000
C10: 資本費平準化債 | D10: 6039000000 | E10: 0 | F10: =D10+E10 -> 6039000000 | G10: =+'[5]4条収入'!$E$14 -> 5929500000 | H10: 0 | I10: =G10-H10 -> 5929500000 | M10: =I10-J10+K10+L10 -> 5929500000 | N10: =L10 -> 0 | O10: =M10-F10 -> -109500000
C11: 災害復旧事業債 | D11: 0 | E11: 0 | F11: =D11+E11 -> 0 | G11: =+'[5]4条収入'!$E$15 -> 0 | H11: 0 | I11: =G11-H11 -> 0 | M11: =I11-J11+K11+L11 -> 0 | N11: =L11 -> 0 | O11: =M11-F11 -> 0
C12: その他事業債（借換債等） | D12: =17007700000+3100000 -> 17010800000 | E12: 0 | F12: =D12+E12 -> 17010800000 | G12: =+'[5]4条収入'!$E$16 -> 17007700000 | H12: 0 | I12: =G12-H12 -> 17007700000 | M12: =I12-J12+K12+L12 -> 17007700000 | N12: =L12 -> 0 | O12: =M12-F12 -> -3100000
B13: 一般会計出資金 | D13: =SUM(D14:D15) -> 3640474000 | E13: =SUM(E14:E15) -> 0 | F13: =SUM(F14:F15) -> 3640474000 | G13: =SUM(G14:G15) -> 3285504551 | H13: =SUM(H14:H15) -> 0 | I13: =SUM(I14:I15) -> 3285504551 | J13: =SUM(J14:J15) -> 0 | K13: =SUM(K14:K15) -> 0 | ... O13: =SUM(O14:O15) -> -354969449
C14: 下水道建設費出資金 | D14: 3640474000 | F14: =D14+E14 -> 3640474000 | G14: =+'[5]4条収入'!E22 -> 3285504551 | H14: 0 | I14: =G14-H14 -> 3285504551 | J14: 0 | M14: =I14-J14+K14+L14 -> 3285504551 | N14: =L14 -> 0 | O14: =M14-F14 -> -354969449
C15: その他出資金 | D15: 0 | E15: 0 | F15: =D15+E15 -> 0 | G15: 0 | H15: 0 | I15: =G15-H15 -> 0 | J15: 0 | M15: =I15-J15+K15+L15 -> 0 | N15: =L15 -> 0 | O15: =F15-M15 -> 0
B16: 国庫補助金 | D16: =SUM(D17:D19) -> 5769500000 | E16: =SUM(E17:E19) -> 0 | F16: =SUM(F17:F19) -> 5769500000 | G16: =SUM(G17:G19) -> 5717788000 | H16: =SUM(H17:H19) -> 0 | I16: =SUM(I17:I19) -> 5717788000 | J16: =SUM(J17:J19) -> 3174000000 | K16: =SUM(K17:K19) -> 0 | ... O16: =SUM(O17:O19) -> -30773739
C17: 公共下水道整備国庫補助金 | D17: =5097000000+665800000 -> 5762800000 | E17: 0 | F17: =D17+E17 -> 5762800000 | G17: =+'[5]4条収入'!$E$25 -> 5683800000 | H17: 0 | I17: =G17-H17 -> 5683800000 | J17: 3156100000 | L17: 3218100000 | M17: =I17-J17+K17+L17 -> 5745800000 | N17: =L17 -> 3218100000 | O17: =M17-F17 -> -17000000
C18: その他国庫補助金 | D18: 2000000 | E18: 0 | F18: =D18+E18 -> 2000000 | G18: =+'[5]4条収入'!$E$26 -> 0 | H18: 0 | I18: =G18-H18 -> 0 | M18: =I18-J18+K18+L18 -> 0 | N18: =L18 -> 0 | O18: =F18-M18 -> 2000000
C19: 汚水処理施設整備交付金 | D19: 4700000 | E19: 0 | F19: =D19+E19 -> 4700000 | G19: =+'[5]4条収入'!$E$31 -> 33988000 | H19: 0 | I19: =G19-H19 -> 33988000 | J19: 17900000 | L19: =2400000+1985739 -> 4385739 | M19: =I19-J19+K19+L19 -> 20473739 | N19: =L19 -> 4385739 | O19: =F19-M19 -> -15773739
B20: 工事受託金 | D20: =D21 -> 54236000 | E20: =E21 -> 0 | F20: =F21 -> 54236000 | G20: =G21 -> 24373083 | H20: =H21 -> 0 | I20: =I21 -> 24373083 | J20: =J21 -> 0 | K20: =K21 -> 0 | ... O20: =O21 -> -29862917
C21: 工事受託金 | D21: 54236000 | E21: 0 | F21: =D21+E21 -> 54236000 | G21: =+'[5]4条収入'!$E$37 -> 24373083 | H21: 0 | I21: =G21-H21 -> 24373083 | K21: 0 | L21: 0 | M21: =I21-J21+K21+L21 -> 24373083 | N21: =L21 -> 0 | O21: =M21-F21 -> -29862917
B22: 負担金 | D22: =SUM(D23:D25) -> 632996000 | E22: =SUM(E23:E25) -> 0 | F22: =SUM(F23:F25) -> 632996000 | G22: =SUM(G23:G25) -> 574304394 | H22: =SUM(H23:H25) -> 0 | I22: =SUM(I23:I25) -> 574304394 | J22: =SUM(J23:J25) -> 0 | K22: =SUM(K23:K25) -> 0 | ... O22: =SUM(O23:O25) -> 131308394
C23: 受益者負担金 | D23: 14208000 | E23: 0 | F23: =D23+E23 -> 14208000 | G23: =+'[5]4条収入'!$E$43 -> 8799605 | H23: 0 | I23: =G23-H23 -> 8799605 | K23: 0 | L23: 0 | M23: =I23-J23+K23+L23 -> 8799605 | N23: =L23 -> 0 | O23: =M23-F23 -> -5408395
C24: 受益者分担金 | D24: 40980000 | E24: 0 | F24: =D24+E24 -> 40980000 | G24: =+'[5]4条収入'!$E$45 -> 35218280 | H24: 0 | I24: =G24-H24 -> 35218280 | K24: 0 | M24: =I24-J24+K24+L24 -> 35218280 | N24: =L24 -> 0 | O24: =M24-F24 -> -5761720
C25: 工事負担金 | D25: 577808000 | E25: 0 | F25: =D25+E25 -> 577808000 | G25: =+'[5]4条収入'!$E$50 -> 530286509 | H25: 0 | I25: =G25-H25 -> 530286509 | L25: =60000000+130000000 -> 190000000 | M25: =I25-J25+K25+L25 -> 720286509 | N25: =L25 -> 190000000 | O25: =M25-F25 -> 142478509
B26: 水洗化貸付事業収入 | D26: =SUM(D27:D29) -> 9913000 | E26: =SUM(E27:E29) -> 0 | F26: =SUM(F27:F29) -> 9913000 | G26: =SUM(G27:G29) -> 3987000 | H26: =SUM(H27:H29) -> 0 | I26: =SUM(I27:I29) -> 3987000 | J26: =SUM(J27:J29) -> 0 | K26: =SUM(K27:K29) -> 0 | M26: =SUM(M27:M29) -> 3987000 | N26: =SUM(N27:N29) -> 0 | O26: =SUM(O27:O29) -> -5926000
C27: 貸付企業債 | D27: 0 | E27: 0 | F27: =D27+E27 -> 0 | G27: =+'[5]4条収入'!$E$56 -> 0 | H27: 0 | I27: =G27-H27 -> 0 | K27: 0 | L27: 0 | M27: =I27-J27+K27+L27 -> 0 | N27: =L27 -> 0 | O27: =M27-F27 -> 0
C28: 一般会計借入金 | D28: 0 | E28: 0 | F28: =D28+E28 -> 0 | G28: =+'[5]4条収入'!$E$58 -> 0 | H28: 0 | I28: =G28-H28 -> 0 | K28: 0 | L28: 0 | M28: =I28-J28-K28-L28 -> 0 | N28: =L28 -> 0 | O28: =F28-M28 -> 0
C29: 貸付金回収金 | D29: 9913000 | E29: 0 | F29: =D29+E29 -> 9913000 | G29: =+'[5]4条収入'!$E$71 -> 3987000 | H29: 0 | I29: =G29-H29 -> 3987000 | K29: 0 | L29: 0 | M29: =I29-J29+K29+L29 -> 3987000 | N29: =L29 -> 0 | O29: =M29-F29 -> -5926000
B30: 固定資産売却代金 | D30: =D31 -> 14731000 | E30: =E31 -> 0 | F30: =F31 -> 14731000 | G30: =G31 -> 45948113 | H30: =H31 -> 0 | I30: =I31 -> 45948113 | J30: =J31 -> 0 | K30: =K31 -> 0 | ... O30: =O31 -> 31217113
C31: 土地売却代金 | D31: 14731000 | E31: 0 | F31: =D31+E31 -> 14731000 | G31: =+'[5]4条収入'!$E$87 -> 45948113 | H31: 0 | I31: =G31-H31 -> 45948113 | J31: 0 | K31: 0 | L31: 0 | M31: =I31-J31+K31+L31 -> 45948113 | N31: =L31 -> 0 | O31: =M31-F31 -> 31217113
B32: その他資本的収入 | D32: =D33 -> 0 | E32: =E33 -> 0 | F32: =F33 -> 0 | G32: =G33 -> 0 | H32: =H33 -> 0 | I32: =I33 -> 0 | J32: =J33 -> 0 | K32: =K33 -> 0 | ... O32: =O33 -> 0
C33: その他資本的収入 | D33: 0 | E33: 0 | F33: =D33+E33 -> 0 | G33: =+'[5]4条収入'!$E$89 -> 0 | H33: 0 | I33: =G33-H33 -> 0 | J33: 0 | K33: 0 | L33: 0 | M33: =I33-J33+K33+L33 -> 0 | N33: =L33 -> 0 | O33: =M33-F33 -> 0
B35: ＊ | C35: 資本的収入合計 | F35: ＝ | G35: =G5-G13 -> 38739700590 | K35: （収入決算額）
M43: =M5-M13 -> 38957586329

Sheet (繰)4条支出 
C1: =+CONCATENATE(LEFT('[1]3条支出'!$D$1,5)," 資本的支出（決算）") -> 令和５年度 資本的支出（決算）
A2: =+CONCATENATE("（",MID([4]雨汚水!D1,3,1),"年度現年度分みなしベース）") -> （５年度現年度分みなしベース） | K2: （単位：円）
A3: 科 目 | D3: 議決予算額 （補正後） | E3: 流用・振替等 増減額 | F3: 現計予算額 | G3: 決算額（電算） | H3: 4-5繰越 決算額 | I3: 5現年度分 決算額 | J3: 翌年度繰越額 | K3: みなし決算額 | L3: 不用額
D4: Ａ | E4: Ｂ | F4: Ｃ（Ａ＋Ｂ） | G4: Ｄ | H4: Ｅ | I4: Ｆ（Ｄ-Ｅ） | J4: Ｇ | K4: Ｈ（F+G） | L4: Ｃ－Ｈ
A5: 資本的支出 | D5: =SUM(D6,D15,D17,D21) -> 62055911000 | E5: =SUM(E6,E15,E17,E21) -> 0 | F5: =SUM(F6,F15,F17,F21) -> 62055911000 | G5: =SUM(G6,G15,G17,G21) -> 61875977537 | H5: =SUM(H6,H15,H17,H21) -> 9248923703 | I5: =SUM(I6,I15,I17,I21) -> 52627053834 | J5: =SUM(J6,J15,J17,J21) -> 9225844099 | K5: =SUM(K6,K15,K17,K21) -> 61852897933 | L5: =SUM(L6,L15,L17,L21) -> 203013067
B6: 建設改良費 | D6: =SUM(D7:D14) -> 17424201000 | E6: =SUM(E7:E14) -> 0 | F6: =SUM(F7:F14) -> 17424201000 | G6: =SUM(G7:G14) -> 17250555070 | H6: =SUM(H7:H14) -> 9248923703 | I6: =SUM(I7:I14) -> 8001631367 | J6: =SUM(J7:J14) -> 9225844099 | K6: =SUM(K7:K14) -> 17227475466 | L6: =SUM(L7:L14) -> 196725534
C7: 公共下水道整備費 | D7: =14573171000+1320000000 -> 15893171000 | E7: 0 | F7: =D7+E7 -> 15893171000 | G7: =+'[6]4条支出'!E6 -> 15677649564 | H7: 8377952802 | I7: =G7-H7 -> 7299696762 | J7: 8532522419 | K7: =G7+J7-H7 -> 15832219181 | L7: =F7-K7 -> 60951819
C8: 受益者負担金業務費 | D8: 18558000 | E8: 0 | F8: =D8+E8 -> 18558000 | G8: =+'[6]4条支出'!E7 -> 15860357 | I8: =G8-H8 -> 15860357 | K8: =G8+J8-H8 -> 15860357 | L8: =F8-K8 -> 2697643
C9: 排水設備整備費 | D9: 779527000 | E9: 0 | F9: =D9+E9 -> 779527000 | G9: =+'[6]4条支出'!E8 -> 665100151 | H9: 454024301 | I9: =G9-H9 -> 211075850 | J9: 520900202 | K9: =G9+J9-H9 -> 731976052 | L9: =F9-K9 -> 47550948
C10: 都市下水路整備費 | D10: 0 | E10: 0 | F10: =D10+E10 -> 0 | G10: =+'[6]4条支出'!E9 -> 0 | I10: =G10-H10 -> 0 | K10: =G10+J10-H10 -> 0 | L10: =F10-K10 -> 0
C11: 流域下水道整備費 | D11: 172142000 | E11: 0 | F11: =D11+E11 -> 172142000 | G11: =+'[6]4条支出'!E10 -> 131921564 | I11: =G11-H11 -> 131921564 | K11: =G11+J11-H11 -> 131921564 | L11: =F11-K11 -> 40220436
C12: 諸設備新設改良費 | D12: 90944000 | F12: =D12+E12 -> 90944000 | G12: =+'[6]4条支出'!E11 -> 59178010 | H12: 21253100 | I12: =G12-H12 -> 37924910 | J12: 46750000 | K12: =G12+J12-H12 -> 84674910 | L12: =F12-K12 -> 6269090
C13: 建設利息 | D13: 12600000 | E13: 0 | F13: =D13+E13 -> 12600000 | G13: =+'[6]4条支出'!E15 -> 12600000 | I13: =G13-H13 -> 12600000 | K13: =G13+J13-H13 -> 12600000 | L13: =F13-K13 -> 0
C14: 市街化区域外整備費 | D14: 457259000 | F14: =D14+E14 -> 457259000 | G14: =+'[6]4条支出'!E16 -> 688245424 | H14: 395693500 | I14: =G14-H14 -> 292551924 | J14: 125671478 | K14: =G14+J14-H14 -> 418223402 | L14: =F14-K14 -> 39035598
B15: 償還金 | D15: =D16 -> 44621423000 | E15: =E16 -> 0 | F15: =F16 -> 44621423000 | G15: =G16 -> 44621240467 | H15: =H16 -> 0 | I15: =I16 -> 44621240467 | J15: =J16 -> 0 | K15: =K16 -> 44621240467 | L15: =F15-K15 -> 182533
C16: 企業債償還金 | D16: 44621423000 | E16: 0 | F16: =D16+E16 -> 44621423000 | G16: =+'[6]4条支出'!E21 -> 44621240467 | H16: 0 | I16: =G16-H16 -> 44621240467 | J16: 0 | K16: =G16+J16-H16 -> 44621240467 | L16: =F16-K16 -> 182533
B17: 水洗化貸付事業費 | D17: =SUM(D18:D20) -> 10287000 | E17: =SUM(E18:E20) -> 0 | F17: =SUM(F18:F20) -> 10287000 | G17: =SUM(G18:G20) -> 4182000 | H17: =SUM(H18:H20) -> 0 | I17: =SUM(I18:I20) -> 4182000 | J17: =SUM(J18:J20) -> 0 | K17: =SUM(K18:K20) -> 4182000 | L17: =SUM(L18:L20) -> 6105000
C18: 貸付金 | D18: 8096000 | E18: 0 | F18: =D18+E18 -> 8096000 | G18: =+'[6]4条支出'!E24 -> 3759000 | H18: 0 | I18: =G18-H18 -> 3759000 | J18: 0 | K18: =G18+J18-H18 -> 3759000 | L18: =F18-K18 -> 4337000
C19: 貸付資金企業債償還金 | D19: 0 | E19: 0 | F19: =D19+E19 -> 0 | G19: =+'[6]4条支出'!E25 -> 0 | I19: =G19-H19 -> 0 | K19: =G19+J19-H19 -> 0 | L19: =F19-K19 -> 0
C20: 一般会計借入金償還金 | D20: 2191000 | E20: 0 | F20: =D20+E20 -> 2191000 | G20: =+'[6]4条支出'!E26 -> 423000 | H20: 0 | I20: =G20-H20 -> 423000 | J20: 0 | K20: =G20+J20-H20 -> 423000 | L20: =F20-K20 -> 1768000
B21: 返還金 | D21: =D22 -> 0 | E21: =E22 -> 0 | F21: =F22 -> 0 | G21: =G22 -> 0 | H21: =H22 -> 0 | I21: =I22 -> 0 | J21: =J22 -> 0 | K21: =K22 -> 0 | L21: =F21-K21 -> 0
C22: 国庫補助金返還金 | D22: 0 | E22: 0 | F22: =D22+E22 -> 0 | G22: =+'[6]4条支出'!E28 -> 0 | H22: 0 | I22: =G22-H22 -> 0 | J22: 0 | K22: =G22+J22-H22 -> 0 | L22: =F22-K22 -> 0

Sheet 出資金しくみ
B1: =+CONCATENATE(LEFT('[1]3条支出'!$D$1,5),"決算における一般会計出資金のしくみ") -> 令和５年度決算における一般会計出資金のしくみ
Q2: (単位:円)
B3: 収益的収入及び支出(税抜き) | L3: 資本的収入及び支出(税込み)
B4: (収入) | F4: (支出) | L4: (収入) | P4: (支出)
L6: 企業債
F7: 維持管理費 | L7: =+'(繰)4条収入'!M6 -> 32352700000
F8: =+[4]雨汚水!AD47 -> 11030037961 | M8: (現年度分)
B9: 下水道使用料 | M9: =+L7-M11 -> 27125900000
B10: =+'[2]3条収入'!AI8 -> 18626337467 | M10: (翌年度繰越分)
M11: =+'(繰)4条収入'!L6 -> 5226800000
F13: 資本費 | L13: 国庫補助金 | P13: 建設改良費
F14: =+[4]雨汚水!AD48 -> 30998096974 | L14: =+'(繰)4条収入'!M16 -> 5766273739 | P14: =+'(繰)4条支出 '!K6 -> 17227475466
B15: 国庫補助金・県補助金 | M15: (現年度分) | Q15: (現年度分)
B16: =+'[2]3条収入'!AI32 -> 0 | M16: =+L14-M18 -> 2543788000 | Q16: =P14-Q18 -> 8001631367
M17: (翌年度繰越分) | Q17: (翌年度繰越分)
M18: =+'(繰)4条収入'!L16 -> 3222485739 | Q18: =+'(繰)4条支出 '!J6 -> 9225844099
B19: 負担金 | L19: その他収入
B20: =+'[2]3条収入'!AI39 -> 50128048 | L20: =M22+M24 -> 838612590
M21: (現年度分)
M22: =(+SUM('(繰)4条収入'!M20,'(繰)4条収入'!M22,'(繰)4条収入'!M29,'(繰)4条収入'!M30))-M24 -> 648612590
M23: (翌年度繰越分)
M24: =+SUM('(繰)4条収入'!L20,'(繰)4条収入'!L22,'(繰)4条収入'!L29,'(繰)4条収入'!L30) -> 190000000
F27: 補てん財源 | L27: 補てん財源
F28: (損益勘定留保資金) | L28: =M30+M32+M34+M36+M38+M40 -> 19609807053
F29: =G34+G36+G38+G40 -> 17579830234 | M29: (過年度損益勘定留保資金)
B30: 一般会計負担金 | F30: (うち前年度からの繰越分を除く) | M30: =+G42 -> 0
B31: =+'[2]3条収入'!AI9 -> 14187102335 | G31: =-F29-G42 -> -17579830234 | M31: (当年度損益勘定留保資金)
M32: =+-G31 -> 17579830234
G33: 減価償却費 | P33: 企業債償還金
G34: =+[4]雨汚水!E34 -> 26551442230 | P34: =+'(繰)4条支出 '!K15 -> 44621240467
G35: 固定資産除却費等 | M35: (当年度消費税等資本的収支調整額)
B36: 一般会計補助金 | G36: =+[4]雨汚水!E35+[4]雨汚水!E42+[4]雨汚水!E44+[4]雨汚水!$E$28 -> 514077226 | M36: =+-[3]消費税!AF118 -> 923595698
B37: =+'[2]3条収入'!AI42 -> 9203253 | G37: 長期前受金戻入等 | M37: (減債積立金)
G38: =-([4]雨汚水!E85+[4]雨汚水!E86+[4]雨汚水!E93+[4]雨汚水!E95) -> -9485689222 | M38: =+'(繰)案'!E34 -> 1049566207
G39: 企業債発行差金（実決算） | M39: (前年度繰越工事資金当年度充当額)
G40: 0 | M40: =+'(繰)案'!E35 -> 56814914
G41: (うち前年度からの繰越分) | P41: 水洗化貸付事業費
G42: 0 | L42: 一般会計出資金 | P42: =+'(繰)4条支出 '!K17 -> 4182000
L43: =+'(繰)4条収入'!M14 -> 3285504551
F44: 合計額
...

Sheet 総括表 (メモなし)
K1: 令和6年5月22日
K2: 経営企画課
A3: =DBCS(TEXT(DATE($T$4,12,31),"[$-ja-JP]ggge年度下水道事業会計決算【速報】")) -> 令和５年度下水道事業会計決算【速報】
A4: １ 決算 | T4: 2023
A5: (1) 収益的収入及び支出(税込) | K5: （単位：千円）
A6: 区 分 | E6: =TEXT(DATE(T4,12,31),"[$-ja-JP]ggge年度") -> 令和5年度 | H6: 増 △ 減
E7: 議決予算 （a） | F7: 4月決見 （b） | G7: 決算 (c) | H7: 決算(c) -議決予算(a) | J7: 決算(c) -4月決見(b) | X7: G列 項目名リスト
I8: 率 | K8: 率 | P8: 決算円 | Q8: 端数調整 | R8: 千円 | S8: 注意
A9: 下水道事業収益 | E9: =E10+E12+E13 -> 44975817 | F9: =F10+F12+F13 -> 44165221 | G9: =G10+G12+G13 -> 44454711 | H9: =G9-E9 -> -521106 | I9: =IF(AND(E9=0,G9=0),"－ ",IF(E9=0,"皆増 ",IF(G9=0,"皆減 ",H9/E9))) -> -0.01158636 | J9: =G9-F9 -> 289490 | K9: =IF(AND(F9=0,G9=0),"－ ",IF(F9=0,"皆増 ",IF(G9=0,"皆減 ",J9/F9))) -> 0.0065547051 | P9: =P10+P12+P13 -> 44454711283 | Q9: =Q10+Q12+Q13 -> -1 | R9: =R10+R12+R13 -> 44454711 | X9: 要求額 （ｃ）
B10: 営業収益 | E10: 35444153 | F10: 34582538 | G10: =R10 -> 34865912 | H10: =G10-E10 -> -578241 | I10: =IF(AND(E10=0,G10=0),"－ ",IF(E10=0,"皆増 ",IF(G10=0,"皆減 ",H10/E10))) -> -0.016314144 | J10: =G10-F10 -> 283374 | K10: =IF(AND(F10=0,G10=0),"－ ",IF(F10=0,"皆増 ",IF(G10=0,"皆減 ",J10/F10))) -> 0.0081941354 | P10: ='[2]3条収入'!$E$27 -> 34865911732 | R10: =ROUND(P10/1000,0)+Q10 -> 34865912 | X10: 査定額 （ｃ）
C11: (下水道使用料) | E11: 21384728 | F11: 20441757 | G11: =R11 -> 20488963 | H11: =G11-E11 -> -895765 | I11: =IF(AND(E11=0,G11=0),"－ ",IF(E11=0,"皆増 ",IF(G11=0,"皆減 ",H11/E11))) -> -0.041888071 | J11: =G11-F11 -> 47206 | K11: =IF(AND(F11=0,G11=0),"－ ",IF(F11=0,"皆増 ",IF(G11=0,"皆減 ",J11/F11))) -> 0.0023092927 | P11: ='[2]3条収入'!$E$7 -> 20488962528 | R11: =ROUND(P11/1000,0)+Q11 -> 20488963 | X11: 決見額 （ｃ）
B12: 営業外収益 | E12: 9528788 | F12: 9579686 | G12: =R12 -> 9584600 | H12: =G12-E12 -> 55812 | I12: =IF(AND(E12=0,G12=0),"－ ",IF(E12=0,"皆増 ",IF(G12=0,"皆減 ",H12/E12))) -> 0.0058571982 | J12: =G12-F12 -> 4914 | K12: =IF(AND(F12=0,G12=0),"－ ",IF(F12=0,"皆増 ",IF(G12=0,"皆減 ",J12/F12))) -> 0.00051296045 | P12: ='[2]3条収入'!$E$57 -> 9584600552 | Q12: -1 | R12: =ROUND(P12/1000,0)+Q12 -> 9584600 | X12: 予算案 （ｃ）
B13: 特別利益 | E13: 2876 | F13: 2997 | G13: =R13 -> 4199 | H13: =G13-E13 -> 1323 | I13: =IF(AND(E13=0,G13=0),"－ ",IF(E13=0,"皆増 ",IF(G13=0,"皆減 ",H13/E13))) -> 0.46001391 | J13: =G13-F13 -> 1202 | K13: =IF(AND(F13=0,G13=0),"－ ",IF(F13=0,"皆増 ",IF(G13=0,"皆減 ",J13/F13))) -> 0.40106773 | P13: ='[2]3条収入'!$E$68 -> 4198999 | R13: =ROUND(P13/1000,0)+Q13 -> 4199
A14: 下 水 道 事 業 費 用 | E14: =SUM(E15,E16,E17,E18) -> 43953299 | F14: =SUM(F15,F16,F17,F18) -> 43109924 | G14: =SUM(G15,G16,G17,G18) -> 42987208 | H14: =G14-E14 -> -966091 | I14: =IF(AND(E14=0,G14=0),"－ ",IF(E14=0,"皆増 ",IF(G14=0,"皆減 ",H14/E14))) -> -0.021979943 | J14: =G14-F14 -> -122716 | K14: =IF(AND(F14=0,G14=0),"－ ",IF(F14=0,"皆増 ",IF(G14=0,"皆減 ",J14/F14))) -> -0.0028465835 | P14: =SUM(P15:P18) -> 42987208386 | Q14: =SUM(Q15:Q18) -> 0 | R14: =SUM(R15:R18) -> 42987208
B15: 営業費用 | E15: 39325285 | F15: 38869045 | G15: =R15 -> 38667489 | H15: =G15-E15 -> -657796 | I15: =IF(AND(E15=0,G15=0),"－ ",IF(E15=0,"皆増 ",IF(G15=0,"皆減 ",H15/E15))) -> -0.01672705 | J15: =G15-F15 -> -201556 | K15: =IF(AND(F15=0,G15=0),"－ ",IF(F15=0,"皆増 ",IF(G15=0,"皆減 ",J15/F15))) -> -0.0051855146 | P15: ='[1]3条支出'!$E$5 -> 38667489041 | R15: =ROUND(P15/1000,0)+Q15 -> 38667489
B16: 営業外費用 | E16: 4599725 | F16: =4210270+8000 -> 4218270 | G16: =R16 -> 4298724 | H16: =G16-E16 -> -301001 | I16: =IF(AND(E16=0,G16=0),"－ ",IF(E16=0,"皆増 ",IF(G16=0,"皆減 ",H16/E16))) -> -0.065438912 | J16: =G16-F16 -> 80454 | K16: =IF(AND(F16=0,G16=0),"－ ",IF(F16=0,"皆増 ",IF(G16=0,"皆減 ",J16/F16))) -> 0.019072748 | P16: ='[1]3条支出'!$E$22+[1]営外!$E$22 -> 4298724047 | R16: =ROUND(P16/1000,0)+Q16 -> 4298724 | S16: 3条支出（3条消費税・4条消費税含む） ＝営業外費用（消費税除く）＋消費税
B17: 特別損失 | E17: 8289 | F17: =22609 -> 22609 | G17: =R17 -> 20995 | H17: =G17-E17 -> 12706 | I17: =IF(AND(E17=0,G17=0),"－ ",IF(E17=0,"皆増 ",IF(G17=0,"皆減 ",H17/E17))) -> 1.5328749 | J17: =G17-F17 -> -1614 | K17: =IF(AND(F17=0,G17=0),"－ ",IF(F17=0,"皆増 ",IF(G17=0,"皆減 ",J17/F17))) -> -0.071387501 | P17: ='[1]3条支出'!$E$27 -> 20995298 | R17: =ROUND(P17/1000,0)+Q17 -> 20995
B18: 予備費 | E18: 20000 | F18: 0 | G18: =R18 -> 0 | H18: =G18-E18 -> -20000 | I18: =IF(AND(E18=0,G18=0),"－ ",IF(E18=0,"皆増 ",IF(G18=0,"皆減 ",H18/E18))) -> 皆減 | J18: =G18-F18 -> 0 | K18: =IF(AND(F18=0,G18=0),"－ ",IF(F18=0,"皆増 ",IF(G18=0,"皆減 ",J18/F18))) -> － | P18: 0 | R18: =ROUND(P18/1000,0)+Q18 -> 0
A20: 収支差引 | E20: =E9-E14 -> 1022518 | F20: =F9-F14 -> 1055297 | G20: =G9-G14 -> 1467503 | H20: =G20-E20 -> 444985 | I20: =IF(AND(E20=0,G20=0),"－ ",IF(E20=0,"皆増 ",IF(G20=0,"皆減 ",H20/E20))) -> 0.43518549 | J20: =G20-F20 -> 412206 | K20: =IF(AND(F20=0,G20=0),"－ ",IF(F20=0,"皆増 ",IF(G20=0,"皆減 ",J20/F20))) -> 0.39060663 | P20: =P9-P14 -> 1467502897 | Q20: =Q9-Q14 -> -1 | R20: =R9-R14 -> 1467503
P21: =[3]消費税!$AF$118 -> -923595698 | R21: =ROUND(P21/1000,0)+Q21 -> -923596 | S21: 消費税資本的収支調整を控除 | V21: チェック
A22: 税抜収支差引（純利益） | E22: 120300 | F22: 87814 | G22: =R22 -> 543907 | H22: =G22-E22 -> 423607 | I22: =IF(AND(E22=0,G22=0),"－ ",IF(E22=0,"皆増 ",IF(G22=0,"皆減 ",H22/E22))) -> 3.5212552 | J22: =G22-F22 -> 456093 | K22: =IF(AND(F22=0,G22=0),"－ ",IF(F22=0,"皆増 ",IF(G22=0,"皆減 ",J22/F22))) -> 5.1938529 | P22: =SUM(P20:P21) -> 543907199 | R22: =ROUND(P22/1000,0)+Q22 -> 543907 | T22: ='(繰)案'!E13 -> 543907199 | V22: =P22-T22 -> 0
A24: (2) 資本的収入及び支出（税込） | M24: （単位：千円）
A25: 区 分 | E25: =E6 -> 令和5年度 | I25: 増 △ 減
E26: 議決予算 （a） | F26: 4月決見 （b） | G26: =G$7 -> 決算 (c) | H26: 翌年度への 繰越 (d) | I26: 決算(c)+翌年度への繰越(d) | L26: 決算(c)+翌年度への繰越(d)
I27: -議決予算(a) | K27: 率 | L27: -4月決見(b) | M27: 率 | T27: 税込３条収入（一般会計負担金を除く） | U27: ① | W27: =IF(G9=ROUND((V27+V28)/1000,0),"OK","エラー") -> エラー
A28: 資本的収入 | E28: =SUM(E29:E31) -> 51048450 | F28: =SUM(F29:F31) -> 50593733 | G28: =SUM(G29:G31) -> 42025205 | H28: =SUM(H29:H31) -> 8639286 | J28: =G28+H28-E28 -> -383959 | K28: =IF(AND(E28=0,SUM(G28:H28)=0),"－ ",IF(E28=0,"皆増 ",IF(SUM(G28:H28)=0,"皆減 ",J28/E28))) -> -0.0075214625 | L28: =G28+H28-F28 -> 70758 | M28: =IF(AND(F28=0,SUM(G28:H28)=0),"－ ",IF(F28=0,"皆増 ",IF(SUM(G28:H28)=0,"皆減 ",L28/F28))) -> 0.0013985527 | P28: =P29+P30+P31 -> 42025205141 | Q28: =Q29+Q30+Q31 -> 0 | R28: =R29+R30+R31 -> 42025205 | T28: 一般会計負担金 | U28: ②
B29: 企業債 | E29: =32505200+5247400 -> 37752600 | F29: =32352700+5247400 -> 37600100 | G29: =R29 -> 32373300 | H29: 5226800 | J29: =G29+H29-E29 -> -152500 | K29: =IF(AND(E29=0,SUM(G29:H29)=0),"－ ",IF(E29=0,"皆増 ",IF(SUM(G29:H29)=0,"皆減 ",J29/E29))) -> -0.0040394569 | L29: =G29+H29-F29 -> 0 | M29: =IF(AND(F29=0,SUM(G29:H29)=0),"－ ",IF(F29=0,"皆増 ",IF(SUM(G29:H29)=0,"皆減 ",L29/F29))) -> 0 | P29: ='[5]4条収入'!$E$7 -> 32373300000 | R29: =ROUND(P29/1000,0)+Q29 -> 32373300 | T29: 税込３条支出 | U29: ③ | W29: =IF(G14=ROUND((V29+V30)/1000,0),"OK","エラー") -> エラー
B30: 国庫補助金 | E30: =5769500+3174000 -> 8943500 | F30: =5766211+3174000 -> 8940211 | G30: =R30 -> 5717788 | H30: 3222486 | J30: =G30+H30-E30 -> -3226 | K30: =IF(AND(E30=0,SUM(G30:H30)=0),"－ ",IF(E30=0,"皆増 ",IF(SUM(G30:H30)=0,"皆減 ",J30/E30))) -> -0.00036070889 | L30: =G30+H30-F30 -> 63 | M30: =IF(AND(F30=0,SUM(G30:H30)=0),"－ ",IF(F30=0,"皆増 ",IF(SUM(G30:H30)=0,"皆減 ",L30/F30))) -> 7.0468135e-06 | P30: ='[5]4条収入'!$E$23 -> 5717788000 | R30: =ROUND(P30/1000,0)+Q30 -> 5717788 | T30: 消費税納付額 | U30: ④
B31: その他資本的収入 | E31: 4352350 | F31: 4053422 | G31: =R31 -> 3934117 | H31: =130000+60000 -> 190000 | J31: =G31+H31-E31 -> -228233 | K31: =IF(AND(E31=0,SUM(G31:H31)=0),"－ ",IF(E31=0,"皆増 ",IF(SUM(G31:H31)=0,"皆減 ",J31/E31))) -> -0.052439027 | L31: =G31+H31-F31 -> 70695 | M31: =IF(AND(F31=0,SUM(G31:H31)=0),"－ ",IF(F31=0,"皆増 ",IF(SUM(G31:H31)=0,"皆減 ",L31/F31))) -> 0.017440819 | P31: ='[5]4条収入'!$E$91-SUM(P29:P30) -> 3934117141 | R31: =ROUND(P31/1000,0)+Q31 -> 3934117 | T31: 消費税４条調整額 | U31: ⑤
