Workbook

Sheet 使い方
B2: 育児時短勤務手当金 管理台帳 使い方
B4: ■ 毎月の流れ（Excelだけで動作・マクロ不使用）
B5: 1. 【マクロ有効版(.xlsm)】「請求記録」シート上部の［申請書ファイルを取り込む］ボタン → 提出された電子申請書(.xlsx/.xlsm)を複数選択 → 次の空行へ自動で追記（受付日＝今日）。入力エラーが残っている申請書・同じ職員同じ月の重複は取り込まず、理由を表示します。
B6: 【マクロなし版(.xlsx)】電子申請書の「共済組合提出データ」シート2行目（A2:T2）をコピー →「請求記録」の次の空行のB列へ『値のみ貼り付け』。
B7: 紙の申請書は黄色い列に直接入力（最低限：職員番号・対象年・対象月・報酬額）。
B8: 2. 氏名・所属・標準報酬月額・判定（○△×）・決定額・ステータスが自動で出ます。「チェック」列に文字が出た行は、申請書と人給/マスタの食い違い等があるので確認します。
B9: 3. 基幹システムへ入力して支給月が決まったら、「支給月」列を選択 →ステータスが「支給済」になります。
B10: 4. 支給を保留するときは「保留理由」（と保留開始日・次回確認予定日）を入れるだけ。「保留一覧」に自動で載り、経過日数が出ます。解決したら「保留解消日」または「支給月」を入れると一覧から消えます（履歴は残ります）。
B11: 5. 請求前に保留する場合（育休期間の変更待ち等）は「職員マスタ」の【職員単位の保留】に入れます。
B13: ■ シートの役割
B14: 請求記録：1請求1行の台帳（ここが本体。3,000行まで）／保留一覧：保留中の請求・職員と理由別件数／月次集計：対象月別・支給月別の件数と金額／職員別一覧：従来のリストと同じ見方（月×職員）
B15: 職員マスタ：職員ごとの時短期間・標準報酬月額・子の生年月日／人給データ：人給の出力を貼り付ける場所（職員マスタに自動反映）／設定：最低限度額(2,411円)・給付率・保留理由の一覧
... B24: ・旧リストから移行した行の保留開始日は不明のため空欄です（入れると経過日数が出ます）。

Sheet 請求記録
A1: 請求記録（1請求＝1行）
A2: 電子申請書の「共済組合提出データ」2行目をB列に値のみ貼り付け、または黄色い列を直接入力。灰色の列は自動計算です。
A4: ▼ 申請書の内容（貼付／入力） | V4: ▼ 自動判定と管理（黄色＝入力）
A5: 受付日 | B5: 職員番号 | C5: 対象年(令和) | D5: 対象月 | E5: 報酬額 | F5: 通勤手当有無 | G5: 通勤手当月額 | H5: 氏名(申請書) | I5: 組合員記号 | J5: 組合員番号 | K5: 勤務区分 | L5: 時短開始日 | M5: 時短終了日 | N5: 請求期間開始 | O5: 請求期間終了 | P5: 子の氏名 | Q5: 子の生年月日 | R5: 所属名称 | S5: 請求日 | T5: 初回請求 | U5: 申請書の入力エラー件数 | V5: 氏名 | W5: 所属 | X5: 対象月 | Y5: 標準報酬月額 | Z5: 判定 | AA5: 計算額 | AB5: 決定額（手修正） | AC5: 決定額 | AD5: ステータス | AE5: 保留理由 | AF5: 保留開始日 | AG5: 保留解消日 | AH5: 次回確認予定日 | AI5: 保留経過日数 | AJ5: 支給月 | AK5: チェック（空欄＝問題なし） | AL5: 備考 | AM5: 保留連番 | AN5: マスタ行 | AO5: 対象月初日
B6: 5901723 | C6: 8 | D6: 5 | E6: 438260 | V6: =IF($AN6="",IF($B6="","",$H6),IF(INDEX(職員マスタ!$B$6:$B$405,$AN6)="",$H6,INDEX(職員マスタ!$B$6:$B$405,$AN6))) | W6: =IF($AN6="",IF($B6="","",$R6),IF(INDEX(職員マスタ!$C$6:$C$405,$AN6)="",$R6,INDEX(職員マスタ!$C$6:$C$405,$AN6))) | X6: =IF($AO6="","","R"&$C6&"."&$D6) | Y6: =IF($AN6="","",IF(INDEX(職員マスタ!$K$6:$K$405,$AN6)="","",INDEX(職員マスタ!$K$6:$K$405,$AN6))) | Z6: =IF(OR($E6="",$Y6=""),"",IF($E6>=$Y6,"×",IF($E6>=$Y6*設定!$C$5,"△","○"))) | AA6: =IF($Z6="","",IF($Z6="×",0,IF($Z6="○",ROUNDDOWN($E6*設定!$C$4,0),ROUNDDOWN($E6*ROUND((9*$Y6-9*$E6)/(10*$E6),4),0)))) | AC6: =IF($B6="","",IF($AB6<>"",$AB6,IF($AA6="","",IF($AA6<=設定!$C$3,0,$AA6)))) | AD6: =IF($B6="","",IF(AND($AE6<>"",$AG6="",$AJ6=""),"保留中",IF($AJ6<>"",IF(N($AC6)>0,"支給済","不支給"),IF($AC6="","要確認",IF($AC6=0,"不支給","未処理"))))) | AI6: =IF(AND($AD6="保留中",$AF6<>""),TODAY()-$AF6,"") | AK6: =IF($B6="","",IF($AO6="","対象年月が未入力／","")&IF($B6="","",IF($AN6="","職員マスタに未登録の職員番号／",IF($Y6="","標準報酬月額が未登録／","")&IF(AND($AO6<>"",OR(AND(INDEX(職員マスタ!$G$6:$G$405,$AN6)<>"",INDEX(職員マスタ!$G$6:$G$405,$AN6)>EOMONTH($AO6,0)),AND(INDEX(職員マスタ!$H$6:$H$405,$AN6)<>"",INDEX(職員マスタ!$H$6:$H$405,$AN6)<$AO6))),"対象月が時短期間外／","")&IF(AND(INDEX(職員マスタ!$F$6:$F$405,$AN6)<>"",$AO6<>"",INDEX(職員マスタ!$F$6:$F$405,$AN6)<$AO6),"対象月に子が2歳到達済／","")&IF(AND($H6<>"",INDEX(職員マスタ!$B$6:$B$405,$AN6)<>"",SUBSTITUTE(SUBSTITUTE($H6," ","")," ","")<>SUBSTITUTE(SUBSTITUTE(INDEX(職員マスタ!$B$6:$B$405,$AN6)," ","")," ","")),"氏名がマスタと相違／","")&IF(AND($Q6<>"",INDEX(職員マスタ!$E$6:$E$405,$AN6)<>"",$Q6<>INDEX(職員マスタ!$E$6:$E$405,$AN6)),"子の生年月日がマスタと相違／","")&IF(AND($L6<>"",INDEX(職員マスタ!$G$6:$G$405,$AN6)<>"",$L6<>INDEX(職員マスタ!$G$6:$G$405,$AN6)),"時短開始日がマスタと相違／","")&IF(AND($M6<>"",INDEX(職員マスタ!$H$6:$H$405,$AN6)<>"",$M6<>INDEX(職員マスタ!$H$6:$H$405,$AN6)),"時短終了日がマスタと相違／","")))&IF(AND($B6<>"",$E6=""),"報酬額が未入力／","")&IF(N($U6)>0,"申請書に入力エラーが残っています／","")&IF(AND($B6<>"",$AO6<>""),IF(COUNTIFS($B$6:$B$3005,$B6,$C$6:$C$3005,$C6,$D$6:$D$3005,$D6)>1,"同じ月の請求が重複しています／",""),"")&IF(AND(N($E6)>0,$Z6<>"",$Z6<>"×",$AC6=0,$AB6=""),"計算額が下限以下のため不支給／","")) | AM6: =IF($AD6="保留中",COUNTIF($AD$6:$AD6,"保留中"),"") | AN6: =IF($AO6="","",IF(SUMPRODUCT(MAX((職員マスタ!$A$6:$A$405=$B6)*(((職員マスタ!$G$6:$G$405="")+(職員マスタ!$G$6:$G$405<=EOMONTH($AO6,0)))>0)*(((職員マスタ!$H$6:$H$405="")+(職員マスタ!$H$6:$H$405>=$AO6))>0)*(ROW(職員マスタ!$A$6:$A$405)-5)))>0,SUMPRODUCT(MAX((職員マスタ!$A$6:$A$405=$B6)*(((職員マスタ!$G$6:$G$405="")+(職員マスタ!$G$6:$G$405<=EOMONTH($AO6,0)))>0)*(((職員マスタ!$H$6:$H$405="")+(職員マスタ!$H$6:$H$405>=$AO6))>0)*(ROW(職員マスタ!$A$6:$A$405)-5))),IFERROR(MATCH($B6,職員マスタ!$A$6:$A$405,0),""))) | AO6: =IF(OR($B6="",$C6="",$D6=""),"",DATE($C6+2018,$D6,1))
B7: 5901723 | C7: 8 | D7: 6 | E7: 386542 | V7: =IF($AN7="",IF($B7="","",$H7),IF(INDEX(職員マスタ!$B$6:$B$405,$AN7)="",$H7,INDEX(職員マスタ!$B$6:$B$405,$AN7))) | W7: =IF($AN7="",IF($B7="","",$R7),IF(INDEX(職員マスタ!$C$6:$C$405,$AN7)="",$R7,INDEX(職員マスタ!$C$6:$C$405,$AN7))) | X7: =IF($AO7="","","R"&$C7&"."&$D7) | Y7: =IF($AN7="","",IF(INDEX(職員マスタ!$K$6:$K$405,$AN7)="","",INDEX(職員マスタ!$K$6:$K$405,$AN7))) | Z7: =IF(OR($E7="",$Y7=""),"",IF($E7>=$Y7,"×",IF($E7>=$Y7*設定!$C$5,"△","○"))) | AA7: =IF($Z7="","",IF($Z7="×",0,IF($Z7="○",ROUNDDOWN($E7*設定!$C$4,0),ROUNDDOWN($E7*ROUND((9*$Y7-9*$E7)/(10*$E7),4),0)))) | AC7: =IF($B7="","",IF($AB7<>"",$AB7,IF($AA7="","",IF($AA7<=設定!$C$3,0,$AA7)))) | AD7: =IF($B7="","",IF(AND($AE7<>"",$AG7="",$AJ7=""),"保留中",IF($AJ7<>"",IF(N($AC7)>0,"支給済","不支給"),IF($AC7="","要確認",IF($AC7=0,"不支給","未処理"))))) | AI7: =IF(AND($AD7="保留中",$AF7<>""),TODAY()-$AF7,"") | AJ7: R8.8 | AK7: =IF($B7="","",IF($AO7="","対象年月が未入力／","")&IF($B7="","",IF($AN7="","職員マスタに未登録の職員番号／",IF($Y7="","標準報酬月額が未登録／","")&IF(AND($AO7<>"",OR(AND(INDEX(職員マスタ!$G$6:$G$405,$AN7)<>"",INDEX(職員マスタ!$G$6:$G$405,$AN7)>EOMONTH($AO7,0)),AND(INDEX(職員マスタ!$H$6:$H$405,$AN7)<>"",INDEX(職員マスタ!$H$6:$H$405,$AN7)<$AO7))),"対象月が時短期間外／","")&IF(AND(INDEX(職員マスタ!$F$6:$F$405,$AN7)<>"",$AO7<>"",INDEX(職員マスタ!$F$6:$F$405,$AN7)<$AO7),"対象月に子が2歳到達済／","")&IF(AND($H7<>"",INDEX(職員マスタ!$B$6:$B$405,$AN7)<>"",SUBSTITUTE(SUBSTITUTE($H7," ","")," ","")<>SUBSTITUTE(SUBSTITUTE(INDEX(職員マスタ!$B$6:$B$405,$AN7)," ","")," ","")),"氏名がマスタと相違／","")&IF(AND($Q7<>"",INDEX(職員マスタ!$E$6:$E$405,$AN7)<>"",$Q7<>INDEX(職員マスタ!$E$6:$E$405,$AN7)),"子の生年月日がマスタと相違／","")&IF(AND($L7<>"",INDEX(職員マスタ!$G$6:$G$405,$AN7)<>"",$L7<>INDEX(職員マスタ!$G$6:$G$405,$AN7)),"時短開始日がマスタと相違／","")&IF(AND($M7<>"",INDEX(職員マスタ!$H$6:$H$405,$AN7)<>"",$M7<>INDEX(職員マスタ!$H$6:$H$405,$AN7)),"時短終了日がマスタと相違／","")))&IF(AND($B7<>"",$E7=""),"報酬額が未入力／","")&IF(N($U7)>0,"申請書に入力エラーが残っています／","")&IF(AND($B7<>"",$AO7<>""),IF(COUNTIFS($B$6:$B$3005,$B7,$C$6:$C$3005,$C7,$D$6:$D$3005,$D7)>1,"同じ月の請求が重複しています／",""),"")&IF(AND(N($E7)>0,$Z7<>"",$Z7<>"×",$AC7=0,$AB7=""),"計算額が下限以下のため不支給／","")) | AM7: =IF($AD7="保留中",COUNTIF($AD$6:$AD7,"保留中"),"") | AN7: =IF($AO7="","",IF(SUMPRODUCT(MAX((職員マスタ!$A$6:$A$405=$B7)*(((職員マスタ!$G$6:$G$405="")+(職員マスタ!$G$6:$G$405<=EOMONTH($AO7,0)))>0)*(((職員マスタ!$H$6:$H$405="")+(職員マスタ!$H$6:$H$405>=$AO7))>0)*(ROW(職員マスタ!$A$6:$A$405)-5)))>0,SUMPRODUCT(MAX((職員マスタ!$A$6:$A$405=$B7)*(((職員マスタ!$G$6:$G$405="")+(職員マスタ!$G$6:$G$405<=EOMONTH($AO7,0)))>0)*(((職員マスタ!$H$6:$H$405="")+(職員マスタ!$H$6:$H$405>=$AO7))>0)*(ROW(職員マスタ!$A$6:$A$405)-5))),IFERROR(MATCH($B7,職員マスタ!$A$6:$A$405,0),""))) | AO7: =IF(OR($B7="",$C7="",$D7=""),"",DATE($C7+2018,$D7,1))
B8: 5901723 | C8: 8 | D8: 7 | E8: 397430 | V8: =IF($AN8="",IF($B8="","",$H8),IF(INDEX(職員マスタ!$B$6:$B$405,$AN8)="",$H8,INDEX(職員マスタ!$B$6:$B$405,$AN8))) | W8: =IF($AN8="",IF($B8="","",$R8),IF(INDEX(職員マスタ!$C$6:$C$405,$AN8)="",$R8,INDEX(職員マスタ!$C$6:$C$405,$AN8))) | X8: =IF($AO8="","","R"&$C8&"."&$D8) | Y8: =IF($AN8="","",IF(INDEX(職員マスタ!$K$6:$K$405,$AN8)="","",INDEX(職員マスタ!$K$6:$K$405,$AN8))) | Z8: =IF(OR($E8="",$Y8=""),"",IF($E8>=$Y8,"×",IF($E8>=$Y8*設定!$C$5,"△","○"))) | AA8: =IF($Z8="","",IF($Z8="×",0,IF($Z8="○",ROUNDDOWN($E8*設定!$C$4,0),ROUNDDOWN($E8*ROUND((9*$Y8-9*$E8)/(10*$E8),4),0)))) | AC8: =IF($B8="","",IF($AB8<>"",$AB8,IF($AA8="","",IF($AA8<=設定!$C$3,0,$AA8)))) | AD8: =IF($B8="","",IF(AND($AE8<>"",$AG8="",$AJ8=""),"保留中",IF($AJ8<>"",IF(N($AC8)>0,"支給済","不支給"),IF($AC8="","要確認",IF($AC8=0,"不支給","未処理"))))) | AI8: =IF(AND($AD8="保留中",$AF8<>""),TODAY()-$AF8,"") | AJ8: R8.9 | AK8: =IF($B8="","",IF($AO8="","対象年月が未入力／","")&IF($B8="","",IF($AN8="","職員マスタに未登録の職員番号／",IF($Y8="","標準報酬月額が未登録／","")&IF(AND($AO8<>"",OR(AND(INDEX(職員マスタ!$G$6:$G$405,$AN8)<>"",INDEX(職員マスタ!$G$6:$G$405,$AN8)>EOMONTH($AO8,0)),AND(INDEX(職員マスタ!$H$6:$H$405,$AN8)<>"",INDEX(職員マスタ!$H$6:$H$405,$AN8)<$AO8))),"対象月が時短期間外／","")&IF(AND(INDEX(職員マスタ!$F$6:$F$405,$AN8)<>"",$AO8<>"",INDEX(職員マスタ!$F$6:$F$405,$AN8)<$AO8),"対象月に子が2歳到達済／","")&IF(AND($H8<>"",INDEX(職員マスタ!$B$6:$B$405,$AN8)<>"",SUBSTITUTE(SUBSTITUTE($H8," ","")," ","")<>SUBSTITUTE(SUBSTITUTE(INDEX(職員マスタ!$B$6:$B$405,$AN8)," ","")," ","")),"氏名がマスタと相違／","")&IF(AND($Q8<>"",INDEX(職員マスタ!$E$6:$E$405,$AN8)<>"",$Q8<>INDEX(職員マスタ!$E$6:$E$405,$AN8)),"子の生年月日がマスタと相違／","")&IF(AND($L8<>"",INDEX(職員マスタ!$G$6:$G$405,$AN8)<>"",$L8<>INDEX(職員マスタ!$G$6:$G$405,$AN8)),"時短開始日がマスタと相違／","")&IF(AND($M8<>"",INDEX(職員マスタ!$H$6:$H$405,$AN8)<>"",$M8<>INDEX(職員マスタ!$H$6:$H$405,$AN8)),"時短終了日がマスタと相違／","")))&IF(AND($B8<>"",$E8=""),"報酬額が未入力／","")&IF(N($U8)>0,"申請書に入力エラーが残っています／","")&IF(AND($B8<>"",$AO8<>""),IF(COUNTIFS($B$6:$B$3005,$B8,$C$6:$C$3005,$C8,$D$6:$D$3005,$D8)>1,"同じ月の請求が重複しています／",""),"")&IF(AND(N($E8)>0,$Z8<>"",$Z8<>"×",$AC8=0,$AB8=""),"計算額が下限以下のため不支給／","")) | AM8: =IF($AD8="保留中",COUNTIF($AD$6:$AD8,"保留中"),"") | AN8: =IF($AO8="","",IF(SUMPRODUCT(MAX((職員マスタ!$A$6:$A$405=$B8)*(((職員マスタ!$G$6:$G$405="")+(職員マスタ!$G$6:$G$405<=EOMONTH($AO8,0)))>0)*(((職員マスタ!$H$6:$H$405="")+(職員マスタ!$H$6:$H$405>=$AO8))>0)*(ROW(職員マスタ!$A$6:$A$405)-5)))>0,SUMPRODUCT(MAX((職員マスタ!$A$6:$A$405=$B8)*(((職員マスタ!$G$6:$G$405="")+(職員マスタ!$G$6:$G$405<=EOMONTH($AO8,0)))>0)*(((職員マスタ!$H$6:$H$405="")+(職員マスタ!$H$6:$H$405>=$AO8))>0)*(ROW(職員マスタ!$A$6:$A$405)-5))),IFERROR(MATCH($B8,職員マスタ!$A$6:$A$405,0),""))) | AO8: =IF(OR($B8="",$C8="",$D8=""),"",DATE($C8+2018,$D8,1))
B9: 5901723 | C9: 8 | D9: 8 | E9: 378376 | V9: =IF($AN9="",IF($B9="","",$H9),IF(INDEX(職員マスタ!$B$6:$B$405,$AN9)="",$H9,INDEX(職員マスタ!$B$6:$B$405,$AN9))) | W9: =IF($AN9="",IF($B9="","",$R9),IF(INDEX(職員マスタ!$C$6:$C$405,$AN9)="",$R9,INDEX(職員マスタ!$C$6:$C$405,$AN9))) | X9: =IF($AO9="","","R"&$C9&"."&$D9) | Y9: =IF($AN9="","",IF(INDEX(職員マスタ!$K$6:$K$405,$AN9)="","",INDEX(職員マスタ!$K$6:$K$405,$AN9))) | Z9: =IF(OR($E9="",$Y9=""),"",IF($E9>=$Y9,"×",IF($E9>=$Y9*設定!$C$5,"△","○"))) | AA9: =IF($Z9="","",IF($Z9="×",0,IF($Z9="○",ROUNDDOWN($E9*設定!$C$4,0),ROUNDDOWN($E9*ROUND((9*$Y9-9*$E9)/(10*$E9),4),0)))) | AC9: =IF($B9="","",IF($AB9<>"",$AB9,IF($AA9="","",IF($AA9<=設定!$C$3,0,$AA9)))) | AD9: =IF($B9="","",IF(AND($AE9<>"",$AG9="",$AJ9=""),"保留中",IF($AJ9<>"",IF(N($AC9)>0,"支給済","不支給"),IF($AC9="","要確認",IF($AC9=0,"不支給","未処理"))))) | AI9: =IF(AND($AD9="保留中",$AF9<>""),TODAY()-$AF9,"") | AJ9: R8.10 | AK9: =IF($B9="","",IF($AO9="","対象年月が未入力／","")&IF($B9="","",IF($AN9="","職員マスタに未登録の職員番号／",IF($Y9="","標準報酬月額が未登録／","")&IF(AND($AO9<>"",OR(AND(INDEX(職員マスタ!$G$6:$G$405,$AN9)<>"",INDEX(職員マスタ!$G$6:$G$405,$AN9)>EOMONTH($AO9,0)),AND(INDEX(職員マスタ!$H$6:$H$405,$AN9)<>"",INDEX(職員マスタ!$H$6:$H$405,$AN9)<$AO9))),"対象月が時短期間外／","")&IF(AND(INDEX(職員マスタ!$F$6:$F$405,$AN9)<>"",$AO9<>"",INDEX(職員マスタ!$F$6:$F$405,$AN9)<$AO9),"対象月に子が2歳到達済／","")&IF(AND($H9<>"",INDEX(職員マスタ!$B$6:$B$405,$AN9)<>"",SUBSTITUTE(SUBSTITUTE($H9," ","")," ","")<>SUBSTITUTE(SUBSTITUTE(INDEX(職員マスタ!$B$6:$B$405,$AN9)," ","")," ","")),"氏名がマスタと相違／","")&IF(AND($Q9<>"",INDEX(職員マスタ!$E$6:$E$405,$AN9)<>"",$Q9<>INDEX(職員マスタ!$E$6:$E$405,$AN9)),"子の生年月日がマスタと相違／","")&IF(AND($L9<>"",INDEX(職員マスタ!$G$6:$G$405,$AN9)<>"",$L9<>INDEX(職員マスタ!$G$6:$G$405,$AN9)),"時短開始日がマスタと相違／","")&IF(AND($M9<>"",INDEX(職員マスタ!$H$6:$H$405,$AN9)<>"",$M9<>INDEX(職員マスタ!$H$6:$H$405,$AN9)),"時短終了日がマスタと相違／","")))&IF(AND($B9<>"",$E9=""),"報酬額が未入力／","")&IF(N($U9)>0,"申請書に入力エラーが残っています／","")&IF(AND($B9<>"",$AO9<>""),IF(COUNTIFS($B$6:$B$3005,$B9,$C$6:$C$3005,$C9,$D$6:$D$3005,$D9)>1,"同じ月の請求が重複しています／",""),"")&IF(AND(N($E9)>0,$Z9<>"",$Z9<>"×",$AC9=0,$AB9=""),"計算額が下限以下のため不支給／","")) | AM9: =IF($AD9="保留中",COUNTIF($AD$6:$AD9,"保留中"),"") | AN9: =IF($AO9="","",IF(SUMPRODUCT(MAX((職員マスタ!$A$6:$A$405=$B9)*(((職員マスタ!$G$6:$G$405="")+(職員マスタ!$G$6:$G$405<=EOMONTH($AO9,0)))>0)*(((職員マスタ!$H$6:$H$405="")+(職員マスタ!$H$6:$H$405>=$AO9))>0)*(ROW(職員マスタ!$A$6:$A$405)-5)))>0,SUMPRODUCT(MAX((職員マスタ!$A$6:$A$405=$B9)*(((職員マスタ!$G$6:$G$405="")+(職員マスタ!$G$6:$G$405<=EOMONTH($AO9,0)))>0)*(((職員マスタ!$H$6:$H$405="")+(職員マスタ!$H$6:$H$405>=$AO9))>0)*(ROW(職員マスタ!$A$6:$A$405)-5))),IFERROR(MATCH($B9,職員マスタ!$A$6:$A$405,0),""))) | AO9: =IF(OR($B9="",$C9="",$D9=""),"",DATE($C9+2018,$D9,1))
B10: 6202204 | C10: 7 | D10: 4 | E10: 153009 | V10: =IF($AN10="",IF($B10="","",$H10),IF(INDEX(職員マスタ!$B$6:$B$405,$AN10)="",$H10,INDEX(職員マスタ!$B$6:$B$405,$AN10))) | W10: =IF($AN10="",IF($B10="","",$R10),IF(INDEX(職員マスタ!$C$6:$C$405,$AN10)="",$R10,INDEX(職員マスタ!$C$6:$C$405,$AN10))) | X10: =IF($AO10="","","R"&$C10&"."&$D10) | Y10: =IF($AN10="","",IF(INDEX(職員マスタ!$K$6:$K$405,$AN10)="","",INDEX(職員マスタ!$K$6:$K$405,$AN10))) | Z10: =IF(OR($E10="",$Y10=""),"",IF($E10>=$Y10,"×",IF($E10>=$Y10*設定!$C$5,"△","○"))) | AA10: =IF($Z10="","",IF($Z10="×",0,IF($Z10="○",ROUNDDOWN($E10*設定!$C$4,0),ROUNDDOWN($E10*ROUND((9*$Y10-9*$E10)/(10*$E10),4),0)))) | AC10: =IF($B10="","",IF($AB10<>"",$AB10,IF($AA10="","",IF($AA10<=設定!$C$3,0,$AA10)))) | AD10: =IF($B10="","",IF(AND($AE10<>"",$AG10="",$AJ10=""),"保留中",IF($AJ10<>"",IF(N($AC10)>0,"支給済","不支給"),IF($AC10="","要確認",IF($AC10=0,"不支給","未処理"))))) | AI10: =IF(AND($AD10="保留中",$AF10<>""),TODAY()-$AF10,"") | AJ10: R7.8 | AK10: =IF($B10="","",IF($AO10="","対象年月が未入力／","")&IF($B10="","",IF($AN10="","職員マスタに未登録の職員番号／",IF($Y10="","標準報酬月額が未登録／","")&IF(AND($AO10<>"",OR(AND(INDEX(職員マスタ!$G$6:$G$405,$AN10)<>"",INDEX(職員マスタ!$G$6:$G$405,$AN10)>EOMONTH($AO10,0)),AND(INDEX(職員マスタ!$H$6:$H$405,$AN10)<>"",INDEX(職員マスタ!$H$6:$H$405,$AN10)<$AO10))),"対象月が時短期間外／","")&IF(AND(INDEX(職員マスタ!$F$6:$F$405,$AN10)<>"",$AO10<>"",INDEX(職員マスタ!$F$6:$F$405,$AN10)<$AO10),"対象月に子が2歳到達済／","")&IF(AND($H10<>"",INDEX(職員マスタ!$B$6:$B$405,$AN10)<>"",SUBSTITUTE(SUBSTITUTE($H10," ","")," ","")<>SUBSTITUTE(SUBSTITUTE(INDEX(職員マスタ!$B$6:$B$405,$AN10)," ","")," ","")),"氏名がマスタと相違／","")&IF(AND($Q10<>"",INDEX(職員マスタ!$E$6:$E$405,$AN10)<>"",$Q10<>INDEX(職員マスタ!$E$6:$E$405,$AN10)),"子の生年月日がマスタと相違／","")&IF(AND($L10<>"",INDEX(職員マスタ!$G$6:$G$405,$AN10)<>"",$L10<>INDEX(職員マスタ!$G$6:$G$405,$AN10)),"時短開始日がマスタと相違／","")&IF(AND($M10<>"",INDEX(職員マスタ!$H$6:$H$405,$AN10)<>"",$M10<>INDEX(職員マスタ!$H$6:$H$405,$AN10)),"時短終了日がマスタと相違／","")))&IF(AND($B10<>"",$E10=""),"報酬額が未入力／","")&IF(N($U10)>0,"申請書に入力エラーが残っています／","")&IF(AND($B10<>"",$AO10<>""),IF(COUNTIFS($B$6:$B$3005,$B10,$C$6:$C$3005,$C10,$D$6:$D$3005,$D10)>1,"同じ月の請求が重複しています／",""),"")&IF(AND(N($E10)>0,$Z10<>"",$Z10<>"×",$AC10=0,$AB10=""),"計算額が下限以下のため不支給／","")) | AM10: =IF($AD10="保留中",COUNTIF($AD$6:$AD10,"保留中"),"") | AN10: =IF($AO10="","",IF(SUMPRODUCT(MAX((職員マスタ!$A$6:$A$405=$B10)*(((職員マスタ!$G$6:$G$405="")+(職員マスタ!$G$6:$G$405<=EOMONTH($AO10,0)))>0)*(((職員マスタ!$H$6:$H$405="")+(職員マスタ!$H$6:$H$405>=$AO10))>0)*(ROW(職員マスタ!$A$6:$A$405)-5)))>0,SUMPRODUCT(MAX((職員マスタ!$A$6:$A$405=$B10)*(((職員マスタ!$G$6:$G$405="")+(職員マスタ!$G$6:$G$405<=EOMONTH($AO10,0)))>0)*(((職員マスタ!$H$6:$H$405="")+(職員マスタ!$H$6:$H$405>=$AO10))>0)*(ROW(職員マスタ!$A$6:$A$405)-5))),IFERROR(MATCH($B10,職員マスタ!$A$6:$A$405,0),""))) | AO10: =IF(OR($B10="",$C10="",$D10=""),"",DATE($C10+2018,$D10,1))
B11: 6202204 | C11: 7 | D11: 5 | E11: 207843 | V11: =IF($AN11="",IF($B11="","",$H11),IF(INDEX(職員マスタ!$B$6:$B$405,$AN11)="",$H11,INDEX(職員マスタ!$B$6:$B$405,$AN11))) | W11: =IF($AN11="",IF($B11="","",$R11),IF(INDEX(職員マスタ!$C$6:$C$405,$AN11)="",$R11,INDEX(職員マスタ!$C$6:$C$405,$AN11))) | X11: =IF($AO11="","","R"&$C11&"."&$D11) | Y11: =IF($AN11="","",IF(INDEX(職員マスタ!$K$6:$K$405,$AN11)="","",INDEX(職員マスタ!$K$6:$K$405,$AN11))) | Z11: =IF(OR($E11="",$Y11=""),"",IF($E11>=$Y11,"×",IF($E11>=$Y11*設定!$C$5,"△","○"))) | AA11: =IF($Z11="","",IF($Z11="×",0,IF($Z11="○",ROUNDDOWN($E11*設定!$C$4,0),ROUNDDOWN($E11*ROUND((9*$Y11-9*$E11)/(10*$E11),4),0)))) | AC11: =IF($B11="","",IF($AB11<>"",$AB11,IF($AA11="","",IF($AA11<=設定!$C$3,0,$AA11)))) | AD11: =IF($B11="","",IF(AND($AE11<>"",$AG11="",$AJ11=""),"保留中",IF($AJ11<>"",IF(N($AC11)>0,"支給済","不支給"),IF($AC11="","要確認",IF($AC11=0,"不支給","未処理"))))) | AI11: =IF(AND($AD11="保留中",$AF11<>""),TODAY()-$AF11,"") | AJ11: R7.8 | AK11: =IF($B11="","",IF($AO11="","対象年月が未入力／","")&IF($B11="","",IF($AN11="","職員マスタに未登録の職員番号／",IF($Y11="","標準報酬月額が未登録／","")&IF(AND($AO11<>"",OR(AND(INDEX(職員マスタ!$G$6:$G$405,$AN11)<>"",INDEX(職員マスタ!$G$6:$G$405,$AN11)>EOMONTH($AO11,0)),AND(INDEX(職員マスタ!$H$6:$H$405,$AN11)<>"",INDEX(職員マスタ!$H$6:$H$405,$AN11)<$AO11))),"対象月が時短期間外／","")&IF(AND(INDEX(職員マスタ!$F$6:$F$405,$AN11)<>"",$AO11<>"",INDEX(職員マスタ!$F$6:$F$405,$AN11)<$AO11),"対象月に子が2歳到達済／","")&IF(AND($H11<>"",INDEX(職員マスタ!$B$6:$B$405,$AN11)<>"",SUBSTITUTE(SUBSTITUTE($H11," ","")," ","")<>SUBSTITUTE(SUBSTITUTE(INDEX(職員マスタ!$B$6:$B$405,$AN11)," ","")," ","")),"氏名がマスタと相違／","")&IF(AND($Q11<>"",INDEX(職員マスタ!$E$6:$E$405,$AN11)<>"",$Q11<>INDEX(職員マスタ!$E$6:$E$405,$AN11)),"子の生年月日がマスタと相違／","")&IF(AND($L11<>"",INDEX(職員マスタ!$G$6:$G$405,$AN11)<>"",$L11<>INDEX(職員マスタ!$G$6:$G$405,$AN11)),"時短開始日がマスタと相違／","")&IF(AND($M11<>"",INDEX(職員マスタ!$H$6:$H$405,$AN11)<>"",$M11<>INDEX(職員マスタ!$H$6:$H$405,$AN11)),"時短終了日がマスタと相違／","")))&IF(AND($B11<>"",$E11=""),"報酬額が未入力／","")&IF(N($U11)>0,"申請書に入力エラーが残っています／","")&IF(AND($B11<>"",$AO11<>""),IF(COUNTIFS($B$6:$B$3005,$B11,$C$6:$C$3005,$C11,$D$6:$D$3005,$D11)>1,"同じ月の請求が重複しています／",""),"")&IF(AND(N($E11)>0,$Z11<>"",$Z11<>"×",$AC11=0,$AB11=""),"計算額が下限以下のため不支給／","")) | AM11: =IF($AD11="保留中",COUNTIF($AD$6:$AD11,"保留中"),"") | AN11: =IF($AO11="","",IF(SUMPRODUCT(MAX((職員マスタ!$A$6:$A$405=$B11)*(((職員マスタ!$G$6:$G$405="")+(職員マスタ!$G$6:$G$405<=EOMONTH($AO11,0)))>0)*(((職員マスタ!$H$6:$H$405="")+(職員マスタ!$H$6:$H$405>=$AO11))>0)*(ROW(職員マスタ!$A$6:$A$405)-5)))>0,SUMPRODUCT(MAX((職員マスタ!$A$6:$A$405=$B11)*(((職員マスタ!$G$6:$G$405="")+(職員マスタ!$G$6:$G$405<=EOMONTH($AO11,0)))>0)*(((職員マスタ!$H$6:$H$405="")+(職員マスタ!$H$6:$H$405>=$AO11))>0)*(ROW(職員マスタ!$A$6:$A$405)-5))),IFERROR(MATCH($B11,職員マスタ!$A$6:$A$405,0),""))) | AO11: =IF(OR($B11="",$C11="",$D11=""),"",DATE($C11+2018,$D11,1))
B12: 6202204 | C12: 7 | D12: 6 | E12: 204190 | V12: =IF($AN12="",IF($B12="","",$H12),IF(INDEX(職員マスタ!$B$6:$B$405,$AN12)="",$H12,INDEX(職員マスタ!$B$6:$B$405,$AN12))) | W12: =IF($AN12="",IF($B12="","",$R12),IF(INDEX(職員マスタ!$C$6:$C$405,$AN12)="",$R12,INDEX(職員マスタ!$C$6:$C$405,$AN12))) | X12: =IF($AO12="","","R"&$C12&"."&$D12) | Y12: =IF($AN12="","",IF(INDEX(職員マスタ!$K$6:$K$405,$AN12)="","",INDEX(職員マスタ!$K$6:$K$405,$AN12))) | Z12: =IF(OR($E12="",$Y12=""),"",IF($E12>=$Y12,"×",IF($E12>=$Y12*設定!$C$5,"△","○"))) | AA12: =IF($Z12="","",IF($Z12="×",0,IF($Z12="○",ROUNDDOWN($E12*設定!$C$4,0),ROUNDDOWN($E12*ROUND((9*$Y12-9*$E12)/(10*$E12),4),0)))) | AC12: =IF($B12="","",IF($AB12<>"",$AB12,IF($AA12="","",IF($AA12<=設定!$C$3,0,$AA12)))) | AD12: =IF($B12="","",IF(AND($AE12<>"",$AG12="",$AJ12=""),"保留中",IF($AJ12<>"",IF(N($AC12)>0,"支給済","不支給"),IF($AC12="","要確認",IF($AC12=0,"不支給","未処理"))))) | AI12: =IF(AND($AD12="保留中",$AF12<>""),TODAY()-$AF12,"") | AJ12: R7.8 | AK12: =IF($B12="","",IF($AO12="","対象年月が未入力／","")&IF($B12="","",IF($AN12="","職員マスタに未登録の職員番号／",IF($Y12="","標準報酬月額が未登録／","")&IF(AND($AO12<>"",OR(AND(INDEX(職員マスタ!$G$6:$G$405,$AN12)<>"",INDEX(職員マスタ!$G$6:$G$405,$AN12)>EOMONTH($AO12,0)),AND(INDEX(職員マスタ!$H$6:$H$405,$AN12)<>"",INDEX(職員マスタ!$H$6:$H$405,$AN12)<$AO12))),"対象月が時短期間外／","")&IF(AND(INDEX(職員マスタ!$F$6:$F$405,$AN12)<>"",$AO12<>"",INDEX(職員マスタ!$F$6:$F$405,$AN12)<$AO12),"対象月に子が2歳到達済／","")&IF(AND($H12<>"",INDEX(職員マスタ!$B$6:$B$405,$AN12)<>"",SUBSTITUTE(SUBSTITUTE($H12," ","")," ","")<>SUBSTITUTE(SUBSTITUTE(INDEX(職員マスタ!$B$6:$B$405,$AN12)," ","")," ","")),"氏名がマスタと相違／","")&IF(AND($Q12<>"",INDEX(職員マスタ!$E$6:$E$405,$AN12)<>"",$Q12<>INDEX(職員マスタ!$E$6:$E$405,$AN12)),"子の生年月日がマスタと相違／","")&IF(AND($L12<>"",INDEX(職員マスタ!$G$6:$G$405,$AN12)<>"",$L12<>INDEX(職員マスタ!$G$6:$G$405,$AN12)),"時短開始日がマスタと相違／","")&IF(AND($M12<>"",INDEX(職員マスタ!$H$6:$H$405,$AN12)<>"",$M12<>INDEX(職員マスタ!$H$6:$H$405,$AN12)),"時短終了日がマスタと相違／","")))&IF(AND($B12<>"",$E12=""),"報酬額が未入力／","")&IF(N($U12)>0,"申請書に入力エラーが残っています／","")&IF(AND($B12<>"",$AO12<>""),IF(COUNTIFS($B$6:$B$3005,$B12,$C$6:$C$3005,$C12,$D$6:$D$3005,$D12)>1,"同じ月の請求が重複しています／",""),"")&IF(AND(N($E12)>0,$Z12<>"",$Z12<>"×",$AC12=0,$AB12=""),"計算額が下限以下のため不支給／","")) | AM12: =IF($AD12="保留中",COUNTIF($AD$6:$AD12,"保留中"),"") | AN12: =IF($AO12="","",IF(SUMPRODUCT(MAX((職員マスタ!$A$6:$A$405=$B12)*(((職員マスタ!$G$6:$G$405="")+(職員マスタ!$G$6:$G$405<=EOMONTH($AO12,0)))>0)*(((職員マスタ!$H$6:$H$405="")+(職員マスタ!$H$6:$H$405>=$AO12))>0)*(ROW(職員マスタ!$A$6:$A$405)-5)))>0,SUMPRODUCT(MAX((職員マスタ!$A$6:$A$405=$B12)*(((職員マスタ!$G$6:$G$405="")+(職員マスタ!$G$6:$G$405<=EOMONTH($AO12,0)))>0)*(((職員マスタ!$H$6:$H$405="")+(職員マスタ!$H$6:$H$405>=$AO12))>0)*(ROW(職員マスタ!$A$6:$A$405)-5))),IFERROR(MATCH($B12,職員マスタ!$A$6:$A$405,0),""))) | AO12: =IF(OR($B12="",$C12="",$D12=""),"",DATE($C12+2018,$D12,1))
B13: 6202204 | C13: 7 | D13: 7 | E13: 206249 | V13: =IF($AN13="",IF($B13="","",$H13),IF(INDEX(職員マスタ!$B$6:$B$405,$AN13)="",$H13,INDEX(職員マスタ!$B$6:$B$405,$AN13))) | W13: =IF($AN13="",IF($B13="","",$R13),IF(INDEX(職員マスタ!$C$6:$C$405,$AN13)="",$R13,INDEX(職員マスタ!$C$6:$C$405,$AN13))) | X13: =IF($AO13="","","R"&$C13&"."&$D13) | Y13: =IF($AN13="","",IF(INDEX(職員マスタ!$K$6:$K$405,$AN13)="","",INDEX(職員マスタ!$K$6:$K$405,$AN13))) | Z13: =IF(OR($E13="",$Y13=""),"",IF($E13>=$Y13,"×",IF($E13>=$Y13*設定!$C$5,"△","○"))) | AA13: =IF($Z13="","",IF($Z13="×",0,IF($Z13="○",ROUNDDOWN($E13*設定!$C$4,0),ROUNDDOWN($E13*ROUND((9*$Y13-9*$E13)/(10*$E13),4),0)))) | AC13: =IF($B13="","",IF($AB13<>"",$AB13,IF($AA13="","",IF($AA13<=設定!$C$3,0,$AA13)))) | AD13: =IF($B13="","",IF(AND($AE13<>"",$AG13="",$AJ13=""),"保留中",IF($AJ13<>"",IF(N($AC13)>0,"支給済","不支給"),IF($AC13="","要確認",IF($AC13=0,"不支給","未処理"))))) | AI13: =IF(AND($AD13="保留中",$AF13<>""),TODAY()-$AF13,"") | AJ13: R7.9 | AK13: =IF($B13="","",IF($AO13="","対象年月が未入力／","")&IF($B13="","",IF($AN13="","職員マスタに未登録の職員番号／",IF($Y13="","標準報酬月額が未登録／","")&IF(AND($AO13<>"",OR(AND(INDEX(職員マスタ!$G$6:$G$405,$AN13)<>"",INDEX(職員マスタ!$G$6:$G$405,$AN13)>EOMONTH($AO13,0)),AND(INDEX(職員マスタ!$H$6:$H$405,$AN13)<>"",INDEX(職員マスタ!$H$6:$H$405,$AN13)<$AO13))),"対象月が時短期間外／","")&IF(AND(INDEX(職員マスタ!$F$6:$F$405,$AN13)<>"",$AO13<>"",INDEX(職員マスタ!$F$6:$F$405,$AN13)<$AO13),"対象月に子が2歳到達済／","")&IF(AND($H13<>"",INDEX(職員マスタ!$B$6:$B$405,$AN13)<>"",SUBSTITUTE(SUBSTITUTE($H13," ","")," ","")<>SUBSTITUTE(SUBSTITUTE(INDEX(職員マスタ!$B$6:$B$405,$AN13)," ","")," ","")),"氏名がマスタと相違／","")&IF(AND($Q13<>"",INDEX(職員マスタ!$E$6:$E$405,$AN13)<>"",$Q13<>INDEX(職員マスタ!$E$6:$E$405,$AN13)),"子の生年月日がマスタと相違／","")&IF(AND($L13<>"",INDEX(職員マスタ!$G$6:$G$405,$AN13)<>"",$L13<>INDEX(職員マスタ!$G$6:$G$405,$AN13)),"時短開始日がマスタと相違／","")&IF(AND($M13<>"",INDEX(職員マスタ!$H$6:$H$405,$AN13)<>"",$M13<>INDEX(職員マスタ!$H$6:$H$405,$AN13)),"時短終了日がマスタと相違／","")))&IF(AND($B13<>"",$E13=""),"報酬額が未入力／","")&IF(N($U13)>0,"申請書に入力エラーが残っています／","")&IF(AND($B13<>"",$AO13<>""),IF(COUNTIFS($B$6:$B$3005,$B13,$C$6:$C$3005,$C13,$D$6:$D$3005,$D13)>1,"同じ月の請求が重複しています／",""),"")&IF(AND(N($E13)>0,$Z13<>"",$Z13<>"×",$AC13=0,$AB13=""),"計算額が下限以下のため不支給／","")) | AM13: =IF($AD13="保留中",COUNTIF($AD$6:$AD13,"保留中"),"") | AN13: =IF($AO13="","",IF(SUMPRODUCT(MAX((職員マスタ!$A$6:$A$405=$B13)*(((職員マスタ!$G$6:$G$405="")+(職員マスタ!$G$6:$G$405<=EOMONTH($AO13,0)))>0)*(((職員マスタ!$H$6:$H$405="")+(職員マスタ!$H$6:$H$405>=$AO13))>0)*(ROW(職員マスタ!$A$6:$A$405)-5)))>0,SUMPRODUCT(MAX((職員マスタ!$A$6:$A$405=$B13)*(((職員マスタ!$G$6:$G$405="")+(職員マスタ!$G$6:$G$405<=EOMONTH($AO13,0)))>0)*(((職員マスタ!$H$6:$H$405="")+(職員マスタ!$H$6:$H$405>=$AO13))>0)*(ROW(職員マスタ!$A$6:$A$405)-5))),IFERROR(MATCH($B13,職員マスタ!$A$6:$A$405,0),""))) | AO13: =IF(OR($B13="",$C13="",$D13=""),"",DATE($C13+2018,$D13,1))
B14: 6202204 | C14: 7 | D14: 8 | E14: 202131 | V14: =IF($AN14="",IF($B14="","",$H14),IF(INDEX(職員マスタ!$B$6:$B$405,$AN14)="",$H14,INDEX(職員マスタ!$B$6:$B$405,$AN14))) | W14: =IF($AN14="",IF($B14="","",$R14),IF(INDEX(職員マスタ!$C$6:$C$405,$AN14)="",$R14,INDEX(職員マスタ!$C$6:$C$405,$AN14))) | X14: =IF($AO14="","","R"&$C14&"."&$D14) | Y14: =IF($AN14="","",IF(INDEX(職員マスタ!$K$6:$K$405,$AN14)="","",INDEX(職員マスタ!$K$6:$K$405,$AN14))) | Z14: =IF(OR($E14="",$Y14=""),"",IF($E14>=$Y14,"×",IF($E14>=$Y14*設定!$C$5,"△","○"))) | AA14: =IF($Z14="","",IF($Z14="×",0,IF($Z14="○",ROUNDDOWN($E14*設定!$C$4,0),ROUNDDOWN($E14*ROUND((9*$Y14-9*$E14)/(10*$E14),4),0)))) | AC14: =IF($B14="","",IF($AB14<>"",$AB14,IF($AA14="","",IF($AA14<=設定!$C$3,0,$AA14)))) | AD14: =IF($B14="","",IF(AND($AE14<>"",$AG14="",$AJ14=""),"保留中",IF($AJ14<>"",IF(N($AC14)>0,"支給済","不支給"),IF($AC14="","要確認",IF($AC14=0,"不支給","未処理"))))) | AI14: =IF(AND($AD14="保留中",$AF14<>""),TODAY()-$AF14,"") | AJ14: R7.10 | AK14: =IF($B14="","",IF($AO14="","対象年月が未入力／","")&IF($B14="","",IF($AN14="","職員マスタに未登録の職員番号／",IF($Y14="","標準報酬月額が未登録／","")&IF(AND($AO14<>"",OR(AND(INDEX(職員マスタ!$G$6:$G$405,$AN14)<>"",INDEX(職員マスタ!$G$6:$G$405,$AN14)>EOMONTH($AO14,0)),AND(INDEX(職員マスタ!$H$6:$H$405,$AN14)<>"",INDEX(職員マスタ!$H$6:$H$405,$AN14)<$AO14))),"対象月が時短期間外／","")&IF(AND(INDEX(職員マスタ!$F$6:$F$405,$AN14)<>"",$AO14<>"",INDEX(職員マスタ!$F$6:$F$405,$AN14)<$AO14),"対象月に子が2歳到達済／","")&IF(AND($H14<>"",INDEX(職員マスタ!$B$6:$B$405,$AN14)<>"",SUBSTITUTE(SUBSTITUTE($H14," ","")," ","")<>SUBSTITUTE(SUBSTITUTE(INDEX(職員マスタ!$B$6:$B$405,$AN14)," ","")," ","")),"氏名がマスタと相違／","")&IF(AND($Q14<>"",INDEX(職員マスタ!$E$6:$E$405,$AN14)<>"",$Q14<>INDEX(職員マスタ!$E$6:$E$405,$AN14)),"子の生年月日がマスタと相違／","")&IF(AND($L14<>"",INDEX(職員マスタ!$G$6:$G$405,$AN14)<>"",$L14<>INDEX(職員マスタ!$G$6:$G$405,$AN14)),"時短開始日がマスタと相違／","")&IF(AND($M14<>"",INDEX(職員マスタ!$H$6:$H$405,$AN14)<>"",$M14<>INDEX(職員マスタ!$H$6:$H$405,$AN14)),"時短終了日がマスタと相違／","")))&IF(AND($B14<>"",$E14=""),"報酬額が未入力／","")&IF(N($U14)>0,"申請書に入力エラーが残っています／","")&IF(AND($B14<>"",$AO14<>""),IF(COUNTIFS($B$6:$B$3005,$B14,$C$6:$C$3005,$C14,$D$6:$D$3005,$D14)>1,"同じ月の請求が重複しています／",""),"")&IF(AND(N($E14)>0,$Z14<>"",$Z14<>"×",$AC14=0,$AB14=""),"計算額が下限以下のため不支給／","")) | AM14: =IF($AD14="保留中",COUNTIF($AD$6:$AD14,"保留中"),"") | AN14: =IF($AO14="","",IF(SUMPRODUCT(MAX((職員マスタ!$A$6:$A$405=$B14)*(((職員マスタ!$G$6:$G$405="")+(職員マスタ!$G$6:$G$405<=EOMONTH($AO14,0)))>0)*(((職員マスタ!$H$6:$H$405="")+(職員マスタ!$H$6:$H$405>=$AO14))>0)*(ROW(職員マスタ!$A$6:$A$405)-5)))>0,SUMPRODUCT(MAX((職員マスタ!$A$6:$A$405=$B14)*(((職員マスタ!$G$6:$G$405="")+(職員マスタ!$G$6:$G$405<=EOMONTH($AO14,0)))>0)*(((職員マスタ!$H$6:$H$405="")+(職員マスタ!$H$6:$H$405>=$AO14))>0)*(ROW(職員マスタ!$A$6:$A$405)-5))),IFERROR(MATCH($B14,職員マスタ!$A$6:$A$405,0),""))) | AO14: =IF(OR($B14="",$C14="",$D14=""),"",DATE($C14+2018,$D14,1))
B15: 6202204 | C15: 7 | D15: 9 | E15: 202131 | V15: =IF($AN15="",IF($B15="","",$H15),IF(INDEX(職員マスタ!$B$6:$B$405,$AN15)="",$H15,INDEX(職員マスタ!$B$6:$B$405,$AN15))) | W15: =IF($AN15="",IF($B15="","",$R15),IF(INDEX(職員マスタ!$C$6:$C$405,$AN15)="",$R15,INDEX(職員マスタ!$C$6:$C$405,$AN15))) | X15: =IF($AO15="","","R"&$C15&"."&$D15) | Y15: =IF($AN15="","",IF(INDEX(職員マスタ!$K$6:$K$405,$AN15)="","",INDEX(職員マスタ!$K$6:$K$405,$AN15))) | Z15: =IF(OR($E15="",$Y15=""),"",IF($E15>=$Y15,"×",IF($E15>=$Y15*設定!$C$5,"△","○"))) | AA15: =IF($Z15="","",IF($Z15="×",0,IF($Z15="○",ROUNDDOWN($E15*設定!$C$4,0),ROUNDDOWN($E15*ROUND((9*$Y15-9*$E15)/(10*$E15),4),0)))) | AC15: =IF($B15="","",IF($AB15<>"",$AB15,IF($AA15="","",IF($AA15<=設定!$C$3,0,$AA15)))) | AD15: =IF($B15="","",IF(AND($AE15<>"",$AG15="",$AJ15=""),"保留中",IF($AJ15<>"",IF(N($AC15)>0,"支給済","不支給"),IF($AC15="","要確認",IF($AC15=0,"不支給","未処理"))))) | AI15: =IF(AND($AD15="保留中",$AF15<>""),TODAY()-$AF15,"") | AJ15: R7.12 | AK15: =IF($B15="","",IF($AO15="","対象年月が未入力／","")&IF($B15="","",IF($AN15="","職員マスタに未登録の職員番号／",IF($Y15="","標準報酬月額が未登録／","")&IF(AND($AO15<>"",OR(AND(INDEX(職員マスタ!$G$6:$G$405,$AN15)<>"",INDEX(職員マスタ!$G$6:$G$405,$AN15)>EOMONTH($AO15,0)),AND(INDEX(職員マスタ!$H$6:$H$405,$AN15)<>"",INDEX(職員マスタ!$H$6:$H$405,$AN15)<$AO15))),"対象月が時短期間外／","")&IF(AND(INDEX(職員マスタ!$F$6:$F$405,$AN15)<>"",$AO15<>"",INDEX(職員マスタ!$F$6:$F$405,$AN15)<$AO15),"対象月に子が2歳到達済／","")&IF(AND($H15<>"",INDEX(職員マスタ!$B$6:$B$405,$AN15)<>"",SUBSTITUTE(SUBSTITUTE($H15," ","")," ","")<>SUBSTITUTE(SUBSTITUTE(INDEX(職員マスタ!$B$6:$B$405,$AN15)," ","")," ","")),"氏名がマスタと相違／","")&IF(AND($Q15<>"",INDEX(職員マスタ!$E$6:$E$405,$AN15)<>"",$Q15<>INDEX(職員マスタ!$E$6:$E$405,$AN15)),"子の生年月日がマスタと相違／","")&IF(AND($L15<>"",INDEX(職員マスタ!$G$6:$G$405,$AN15)<>"",$L15<>INDEX(職員マスタ!$G$6:$G$405,$AN15)),"時短開始日がマスタと相違／","")&IF(AND($M15<>"",INDEX(職員マスタ!$H$6:$H$405,$AN15)<>"",$M15<>INDEX(職員マスタ!$H$6:$H$405,$AN15)),"時短終了日がマスタと相違／","")))&IF(AND($B15<>"",$E15=""),"報酬額が未入力／","")&IF(N($U15)>0,"申請書に入力エラーが残っています／","")&IF(AND($B15<>"",$AO15<>""),IF(COUNTIFS($B$6:$B$3005,$B15,$C$6:$C$3005,$C15,$D$6:$D$3005,$D15)>1,"同じ月の請求が重複しています／",""),"")&IF(AND(N($E15)>0,$Z15<>"",$Z15<>"×",$AC15=0,$AB15=""),"計算額が下限以下のため不支給／","")) | AM15: =IF($AD15="保留中",COUNTIF($AD$6:$AD15,"保留中"),"") | AN15: =IF($AO15="","",IF(SUMPRODUCT(MAX((職員マスタ!$A$6:$A$405=$B15)*(((職員マスタ!$G$6:$G$405="")+(職員マスタ!$G$6:$G$405<=EOMONTH($AO15,0)))>0)*(((職員マスタ!$H$6:$H$405="")+(職員マスタ!$H$6:$H$405>=$AO15))>0)*(ROW(職員マスタ!$A$6:$A$405)-5)))>0,SUMPRODUCT(MAX((職員マスタ!$A$6:$A$405=$B15)*(((職員マスタ!$G$6:$G$405="")+(職員マスタ!$G$6:$G$405<=EOMONTH($AO15,0)))>0)*(((職員マスタ!$H$6:$H$405="")+(職員マスタ!$H$6:$H$405>=$AO15))>0)*(ROW(職員マスタ!$A$6:$A$405)-5))),IFERROR(MATCH($B15,職員マスタ!$A$6:$A$405,0),""))) | AO15: =IF(OR($B15="",$C15="",$D15=""),"",DATE($C15+2018,$D15,1))
B16: 6202204 | C16: 8 | D16: 4 | E16: 207321 | V16: =IF($AN16="",IF($B16="","",$H16),IF(INDEX(職員マスタ!$B$6:$B$405,$AN16)="",$H16,INDEX(職員マスタ!$B$6:$B$405,$AN16))) | W16: =IF($AN16="",IF($B16="","",$R16),IF(INDEX(職員マスタ!$C$6:$C$405,$AN16)="",$R16,INDEX(職員マスタ!$C$6:$C$405,$AN16))) | X16: =IF($AO16="","","R"&$C16&"."&$D16) | Y16: =IF($AN16="","",IF(INDEX(職員マスタ!$K$6:$K$405,$AN16)="","",INDEX(職員マスタ!$K$6:$K$405,$AN16))) | Z16: =IF(OR($E16="",$Y16=""),"",IF($E16>=$Y16,"×",IF($E16>=$Y16*設定!$C$5,"△","○"))) | AA16: =IF($Z16="","",IF($Z16="×",0,IF($Z16="○",ROUNDDOWN($E16*設定!$C$4,0),ROUNDDOWN($E16*ROUND((9*$Y16-9*$E16)/(10*$E16),4),0)))) | AC16: =IF($B16="","",IF($AB16<>"",$AB16,IF($AA16="","",IF($AA16<=設定!$C$3,0,$AA16)))) | AD16: =IF($B16="","",IF(AND($AE16<>"",$AG16="",$AJ16=""),"保留中",IF($AJ16<>"",IF(N($AC16)>0,"支給済","不支給"),IF($AC16="","要確認",IF($AC16=0,"不支給","未処理"))))) | AI16: =IF(AND($AD16="保留中",$AF16<>""),TODAY()-$AF16,"") | AJ16: R8.10 | AK16: =IF($B16="","",IF($AO16="","対象年月が未入力／","")&IF($B16="","",IF($AN16="","職員マスタに未登録の職員番号／",IF($Y16="","標準報酬月額が未登録／","")&IF(AND($AO16<>"",OR(AND(INDEX(職員マスタ!$G$6:$G$405,$AN16)<>"",INDEX(職員マスタ!$G$6:$G$405,$AN16)>EOMONTH($AO16,0)),AND(INDEX(職員マスタ!$H$6:$H$405,$AN16)<>"",INDEX(職員マスタ!$H$6:$H$405,$AN16)<$AO16))),"対象月が時短期間外／","")&IF(AND(INDEX(職員マスタ!$F$6:$F$405,$AN16)<>"",$AO16<>"",INDEX(職員マスタ!$F$6:$F$405,$AN16)<$AO16),"対象月に子が2歳到達済／","")&IF(AND($H16<>"",INDEX(職員マスタ!$B$6:$B$405,$AN16)<>"",SUBSTITUTE(SUBSTITUTE($H16," ","")," ","")<>SUBSTITUTE(SUBSTITUTE(INDEX(職員マスタ!$B$6:$B$405,$AN16)," ","")," ","")),"氏名がマスタと相違／","")&IF(AND($Q16<>"",INDEX(職員マスタ!$E$6:$E$405,$AN16)<>"",$Q16<>INDEX(職員マスタ!$E$6:$E$405,$AN16)),"子の生年月日がマスタと相違／","")&IF(AND($L16<>"",INDEX(職員マスタ!$G$6:$G$405,$AN16)<>"",$L16<>INDEX(職員マスタ!$G$6:$G$405,$AN16)),"時短開始日がマスタと相違／","")&IF(AND($M16<>"",INDEX(職員マスタ!$H$6:$H$405,$AN16)<>"",$M16<>INDEX(職員マスタ!$H$6:$H$405,$AN16)),"時短終了日がマスタと相違／","")))&IF(AND($B16<>"",$E16=""),"報酬額が未入力／","")&IF(N($U16)>0,"申請書に入力エラーが残っています／","")&IF(AND($B16<>"",$AO16<>""),IF(COUNTIFS($B$6:$B$3005,$B16,$C$6:$C$3005,$C16,$D$6:$D$3005,$D16)>1,"同じ月の請求が重複しています／",""),"")&IF(AND(N($E16)>0,$Z16<>"",$Z16<>"×",$AC16=0,$AB16=""),"計算額が下限以下のため不支給／","")) | AM16: =IF($AD16="保留中",COUNTIF($AD$6:$AD16,"保留中"),"") | AN16: =IF($AO16="","",IF(SUMPRODUCT(MAX((職員マスタ!$A$6:$A$405=$B16)*(((職員マスタ!$G$6:$G$405="")+(職員マスタ!$G$6:$G$405<=EOMONTH($AO16,0)))>0)*(((職員マスタ!$H$6:$H$405="")+(職員マスタ!$H$6:$H$405>=$AO16))>0)*(ROW(職員マスタ!$A$6:$A$405)-5)))>0,SUMPRODUCT(MAX((職員マスタ!$A$6:$A$405=$B16)*(((職員マスタ!$G$6:$G$405="")+(職員マスタ!$G$6:$G$405<=EOMONTH($AO16,0)))>0)*(((職員マスタ!$H$6:$H$405="")+(職員マスタ!$H$6:$H$405>=$AO16))>0)*(ROW(職員マスタ!$A$6:$A$405)-5))),IFERROR(MATCH($B16,職員マスタ!$A$6:$A$405,0),""))) | AO16: =IF(OR($B16="",$C16="",$D16=""),"",DATE($C16+2018,$D16,1))
B17: 6202204 | C17: 8 | D17: 5 | E17: 210045 | V17: =IF($AN17="",IF($B17="","",$H17),IF(INDEX(職員マスタ!$B$6:$B$405,$AN17)="",$H17,INDEX(職員マスタ!$B$6:$B$405,$AN17))) | W17: =IF($AN17="",IF($B17="","",$R17),IF(INDEX(職員マスタ!$C$6:$C$405,$AN17)="",$R17,INDEX(職員マスタ!$C$6:$C$405,$AN17))) | X17: =IF($AO17="","","R"&$C17&"."&$D17) | Y17: =IF($AN17="","",IF(INDEX(職員マスタ!$K$6:$K$405,$AN17)="","",INDEX(職員マスタ!$K$6:$K$405,$AN17))) | Z17: =IF(OR($E17="",$Y17=""),"",IF($E17>=$Y17,"×",IF($E17>=$Y17*設定!$C$5,"△","○"))) | AA17: =IF($Z17="","",IF($Z17="×",0,IF($Z17="○",ROUNDDOWN($E17*設定!$C$4,0),ROUNDDOWN($E17*ROUND((9*$Y17-9*$E17)/(10*$E17),4),0)))) | AC17: =IF($B17="","",IF($AB17<>"",$AB17,IF($AA17="","",IF($AA17<=設定!$C$3,0,$AA17)))) | AD17: =IF($B17="","",IF(AND($AE17<>"",$AG17="",$AJ17=""),"保留中",IF($AJ17<>"",IF(N($AC17)>0,"支給済","不支給"),IF($AC17="","要確認",IF($AC17=0,"不支給","未処理"))))) | AI17: =IF(AND($AD17="保留中",$AF17<>""),TODAY()-$AF17,"") | AJ17: R8.10 | AK17: =IF($B17="","",IF($AO17="","対象年月が未入力／","")&IF($B17="","",IF($AN17="","職員マスタに未登録の職員番号／",IF($Y17="","標準報酬月額が未登録／","")&IF(AND($AO17<>"",OR(AND(INDEX(職員マスタ!$G$6:$G$405,$AN17)<>"",INDEX(職員マスタ!$G$6:$G$405,$AN17)>EOMONTH($AO17,0)),AND(INDEX(職員マスタ!$H$6:$H$405,$AN17)<>"",INDEX(職員マスタ!$H$6:$H$405,$AN17)<$AO17))),"対象月が時短期間外／","")&IF(AND(INDEX(職員マスタ!$F$6:$F$405,$AN17)<>"",$AO17<>"",INDEX(職員マスタ!$F$6:$F$405,$AN17)<$AO17),"対象月に子が2歳到達済／","")&IF(AND($H17<>"",INDEX(職員マスタ!$B$6:$B$405,$AN17)<>"",SUBSTITUTE(SUBSTITUTE($H17," ","")," ","")<>SUBSTITUTE(SUBSTITUTE(INDEX(職員マスタ!$B$6:$B$405,$AN17)," ","")," ","")),"氏名がマスタと相違／","")&IF(AND($Q17<>"",INDEX(職員マスタ!$E$6:$E$405,$AN17)<>"",$Q17<>INDEX(職員マスタ!$E$6:$E$405,$AN17)),"子の生年月日がマスタと相違／","")&IF(AND($L17<>"",INDEX(職員マスタ!$G$6:$G$405,$AN17)<>"",$L17<>INDEX(職員マスタ!$G$6:$G$405,$AN17)),"時短開始日がマスタと相違／","")&IF(AND($M17<>"",INDEX(職員マスタ!$H$6:$H$405,$AN17)<>"",$M17<>INDEX(職員マスタ!$H$6:$H$405,$AN17)),"時短終了日がマスタと相違／","")))&IF(AND($B17<>"",$E17=""),"報酬額が未入力／","")&IF(N($U17)>0,"申請書に入力エラーが残っています／","")&IF(AND($B17<>"",$AO17<>""),IF(COUNTIFS($B$6:$B$3005,$B17,$C$6:$C$3005,$C17,$D$6:$D$3005,$D17)>1,"同じ月の請求が重複しています／",""),"")&IF(AND(N($E17)>0,$Z17<>"",$Z17<>"×",$AC17=0,$AB17=""),"計算額が下限以下のため不支給／","")) | AM17: =IF($AD17="保留中",COUNTIF($AD$6:$AD17,"保留中"),"") | AN17: =IF($AO17="","",IF(SUMPRODUCT(MAX((職員マスタ!$A$6:$A$405=$B17)*(((職員マスタ!$G$6:$G$405="")+(職員マスタ!$G$6:$G$405<=EOMONTH($AO17,0)))>0)*(((職員マスタ!$H$6:$H$405="")+(職員マスタ!$H$6:$H$405>=$AO17))>0)*(ROW(職員マスタ!$A$6:$A$405)-5)))>0,SUMPRODUCT(MAX((職員マスタ!$A$6:$A$405=$B17)*(((職員マスタ!$G$6:$G$405="")+(職員マスタ!$G$6:$G$405<=EOMONTH($AO17,0)))>0)*(((職員マスタ!$H$6:$H$405="")+(職員マスタ!$H$6:$H$405>=$AO17))>0)*(ROW(職員マスタ!$A$6:$A$405)-5))),IFERROR(MATCH($B17,職員マスタ!$A$6:$A$405,0),""))) | AO17: =IF(OR($B17="",$C17="",$D17=""),"",DATE($C17+2018,$D17,1))
B18: 6202204 | C18: 8 | D18: 6 | E18: 207321 | V18: =IF($AN18="",IF($B18="","",$H18),IF(INDEX(職員マスタ!$B$6:$B$405,$AN18)="",$H18,INDEX(職員マスタ!$B$6:$B$405,$AN18))) | W18: =IF($AN18="",IF($B18="","",$R18),IF(INDEX(職員マスタ!$C$6:$C$405,$AN18)="",$R18,INDEX(職員マスタ!$C$6:$C$405,$AN18))) | X18: =IF($AO18="","","R"&$C18&"."&$D18) | Y18: =IF($AN18="","",IF(INDEX(職員マスタ!$K$6:$K$405,$AN18)="","",INDEX(職員マスタ!$K$6:$K$405,$AN18))) | Z18: =IF(OR($E18="",$Y18=""),"",IF($E18>=$Y18,"×",IF($E18>=$Y18*設定!$C$5,"△","○"))) | AA18: =IF($Z18="","",IF($Z18="×",0,IF($Z18="○",ROUNDDOWN($E18*設定!$C$4,0),ROUNDDOWN($E18*ROUND((9*$Y18-9*$E18)/(10*$E18),4),0)))) | AC18: =IF($B18="","",IF($AB18<>"",$AB18,IF($AA18="","",IF($AA18<=設定!$C$3,0,$AA18)))) | AD18: =IF($B18="","",IF(AND($AE18<>"",$AG18="",$AJ18=""),"保留中",IF($AJ18<>"",IF(N($AC18)>0,"支給済","不支給"),IF($AC18="","要確認",IF($AC18=0,"不支給","未処理"))))) | AI18: =IF(AND($AD18="保留中",$AF18<>""),TODAY()-$AF18,"") | AJ18: R8.9 | AK18: =IF($B18="","",IF($AO18="","対象年月が未入力／","")&IF($B18="","",IF($AN18="","職員マスタに未登録の職員番号／",IF($Y18="","標準報酬月額が未登録／","")&IF(AND($AO18<>"",OR(AND(INDEX(職員マスタ!$G$6:$G$405,$AN18)<>"",INDEX(職員マスタ!$G$6:$G$405,$AN18)>EOMONTH($AO18,0)),AND(INDEX(職員マスタ!$H$6:$H$405,$AN18)<>"",INDEX(職員マスタ!$H$6:$H$405,$AN18)<$AO18))),"対象月が時短期間外／","")&IF(AND(INDEX(職員マスタ!$F$6:$F$405,$AN18)<>"",$AO18<>"",INDEX(職員マスタ!$F$6:$F$405,$AN18)<$AO18),"対象月に子が2歳到達済／","")&IF(AND($H18<>"",INDEX(職員マスタ!$B$6:$B$405,$AN18)<>"",SUBSTITUTE(SUBSTITUTE($H18," ","")," ","")<>SUBSTITUTE(SUBSTITUTE(INDEX(職員マスタ!$B$6:$B$405,$AN18)," ","")," ","")),"氏名がマスタと相違／","")&IF(AND($Q18<>"",INDEX(職員マスタ!$E$6:$E$405,$AN18)<>"",$Q18<>INDEX(職員マスタ!$E$6:$E$405,$AN18)),"子の生年月日がマスタと相違／","")&IF(AND($L18<>"",INDEX(職員マスタ!$G$6:$G$405,$AN18)<>"",$L18<>INDEX(職員マスタ!$G$6:$G$405,$AN18)),"時短開始日がマスタと相違／","")&IF(AND($M18<>"",INDEX(職員マスタ!$H$6:$H$405,$AN18)<>"",$M18<>INDEX(職員マスタ!$H$6:$H$405,$AN18)),"時短終了日がマスタと相違／","")))&IF(AND($B18<>"",$E18=""),"報酬額が未入力／","")&IF(N($U18)>0,"申請書に入力エラーが残っています／","")&IF(AND($B18<>"",$AO18<>""),IF(COUNTIFS($B$6:$B$3005,$B18,$C$6:$C$3005,$C18,$D$6:$D$3005,$D18)>1,"同じ月の請求が重複しています／",""),"")&IF(AND(N($E18)>0,$Z18<>"",$Z18<>"×",$AC18=0,$AB18=""),"計算額が下限以下のため不支給／","")) | AM18: =IF($AD18="保留中",COUNTIF($AD$6:$AD18,"保留中"),"") | AN18: =IF($AO18="","",IF(SUMPRODUCT(MAX((職員マスタ!$A$6:$A$405=$B18)*(((職員マスタ!$G$6:$G$405="")+(職員マスタ!$G$6:$G$405<=EOMONTH($AO18,0)))>0)*(((職員マスタ!$H$6:$H$405="")+(職員マスタ!$H$6:$H$405>=$AO18))>0)*(ROW(職員マスタ!$A$6:$A$405)-5)))>0,SUMPRODUCT(MAX((職員マスタ!$A$6:$A$405=$B18)*(((職員マスタ!$G$6:$G$405="")+(職員マスタ!$G$6:$G$405<=EOMONTH($AO18,0)))>0)*(((職員マスタ!$H$6:$H$405="")+(職員マスタ!$H$6:$H$405>=$AO18))>0)*(ROW(職員マスタ!$A$6:$A$405)-5))),IFERROR(MATCH($B18,職員マスタ!$A$6:$A$405,0),""))) | AO18: =IF(OR($B18="",$C18="",$D18=""),"",DATE($C18+2018,$D18,1))
... B20: 6202204 | C20: 8 | D20: 8 | E20: 207321 | V20: =IF($AN20="",IF($B20="","",$H20),IF(INDEX(職員マスタ!$B$6:$B$405,$AN20)="",$H20,INDEX(職員マスタ!$B$6:$B$405,$AN20))) | W20: =IF($AN20="",IF($B20="","",$R20),IF(INDEX(職員マスタ!$C$6:$C$405,$AN20)="",$R20,INDEX(職員マスタ!$C$6:$C$405,$AN20))) | X20: =IF($AO20="","","R"&$C20&"."&$D20) | Y20: =IF($AN20="","",IF(INDEX(職員マスタ!$K$6:$K$405,$AN20)="","",INDEX(職員マスタ!$K$6:$K$405,$AN20))) | Z20: =IF(OR($E20="",$Y20=""),"",IF($E20>=$Y20,"×",IF($E20>=$Y20*設定!$C$5,"△","○"))) | AA20: =IF($Z20="","",IF($Z20="×",0,IF($Z20="○",ROUNDDOWN($E20*設定!$C$4,0),ROUNDDOWN($E20*ROUND((9*$Y20-9*$E20)/(10*$E20),4),0)))) | AC20: =IF($B20="","",IF($AB20<>"",$AB20,IF($AA20="","",IF($AA20<=設定!$C$3,0,$AA20)))) | AD20: =IF($B20="","",IF(AND($AE20<>"",$AG20="",$AJ20=""),"保留中",IF($AJ20<>"",IF(N($AC20)>0,"支給済","不支給"),IF($AC20="","要確認",IF($AC20=0,"不支給","未処理"))))) | AI20: =IF(AND($AD20="保留中",$AF20<>""),TODAY()-$AF20,"") | AJ20: R8.10 | AK20: =IF($B20="","",IF($AO20="","対象年月が未入力／","")&IF($B20="","",IF($AN20="","職員マスタに未登録の職員番号／",IF($Y20="","標準報酬月額が未登録／","")&IF(AND($AO20<>"",OR(AND(INDEX(職員マスタ!$G$6:$G$405,$AN20)<>"",INDEX(職員マスタ!$G$6:$G$405,$AN20)>EOMONTH($AO20,0)),AND(INDEX(職員マスタ!$H$6:$H$405,$AN20)<>"",INDEX(職員マスタ!$H$6:$H$405,$AN20)<$AO20))),"対象月が時短期間外／","")&IF(AND(INDEX(職員マスタ!$F$6:$F$405,$AN20)<>"",$AO20<>"",INDEX(職員マスタ!$F$6:$F$405,$AN20)<$AO20),"対象月に子が2歳到達済／","")&IF(AND($H20<>"",INDEX(職員マスタ!$B$6:$B$405,$AN20)<>"",SUBSTITUTE(SUBSTITUTE($H20," ","")," ","")<>SUBSTITUTE(SUBSTITUTE(INDEX(職員マスタ!$B$6:$B$405,$AN20)," ","")," ","")),"氏名がマスタと相違／","")&IF(AND($Q20<>"",INDEX(職員マスタ!$E$6:$E$405,$AN20)<>"",$Q20<>INDEX(職員マスタ!$E$6:$E$405,$AN20)),"子の生年月日がマスタと相違／","")&IF(AND($L20<>"",INDEX(職員マスタ!$G$6:$G$405,$AN20)<>"",$L20<>INDEX(職員マスタ!$G$6:$G$405,$AN20)),"時短開始日がマスタと相違／","")&IF(AND($M20<>"",INDEX(職員マスタ!$H$6:$H$405,$AN20)<>"",$M20<>INDEX(職員マスタ!$H$6:$H$405,$AN20)),"時短終了日がマスタと相違／","")))&IF(AND($B20<>"",$E20=""),"報酬額が未入力／","")&IF(N($U20)>0,"申請書に入力エラーが残っています／","")&IF(AND($B20<>"",$AO20<>""),IF(COUNTIFS($B$6:$B$3005,$B20,$C$6:$C$3005,$C20,$D$6:$D$3005,$D20)>1,"同じ月の請求が重複しています／",""),"")&IF(AND(N($E20)>0,$Z20<>"",$Z20<>"×",$AC20=0,$AB20=""),"計算額が下限以下のため不支給／","")) | AM20: =IF($AD20="保留中",COUNTIF($AD$6:$AD20,"保留中"),"") | AN20: =IF($AO20="","",IF(SUMPRODUCT(MAX((職員マスタ!$A$6:$A$405=$B20)*(((職員マスタ!$G$6:$G$405="")+(職員マスタ!$G$6:$G$405<=EOMONTH($AO20,0)))>0)*(((職員マスタ!$H$6:$H$405="")+(職員マスタ!$H$6:$H$405>=$AO20))>0)*(ROW(職員マスタ!$A$6:$A$405)-5)))>0,SUMPRODUCT(MAX((職員マスタ!$A$6:$A$405=$B20)*(((職員マスタ!$G$6:$G$405="")+(職員マスタ!$G$6:$G$405<=EOMONTH($AO20,0)))>0)*(((職員マスタ!$H$6:$H$405="")+(職員マスタ!$H$6:$H$405>=$AO20))>0)*(ROW(職員マスタ!$A$6:$A$405)-5))),IFERROR(MATCH($B20,職員マスタ!$A$6:$A$405,0),""))) | AO20: =IF(OR($B20="",$C20="",$D20=""),"",DATE($C20+2018,$D20,1))
B21: 6300941 | C21: 8 | D21: 6 | E21: 370216 | V21: =IF($AN21="",IF($B21="","",$H21),IF(INDEX(職員マスタ!$B$6:$B$405,$AN21)="",$H21,INDEX(職員マスタ!$B$6:$B$405,$AN21))) | W21: =IF($AN21="",IF($B21="","",$R21),IF(INDEX(職員マスタ!$C$6:$C$405,$AN21)="",$R21,INDEX(職員マスタ!$C$6:$C$405,$AN21))) | X21: =IF($AO21="","","R"&$C21&"."&$D21) | Y21: =IF($AN21="","",IF(INDEX(職員マスタ!$K$6:$K$405,$AN21)="","",INDEX(職員マスタ!$K$6:$K$405,$AN21))) | Z21: =IF(OR($E21="",$Y21=""),"",IF($E21>=$Y21,"×",IF($E21>=$Y21*設定!$C$5,"△","○"))) | AA21: =IF($Z21="","",IF($Z21="×",0,IF($Z21="○",ROUNDDOWN($E21*設定!$C$4,0),ROUNDDOWN($E21*ROUND((9*$Y21-9*$E21)/(10*$E21),4),0)))) | AC21: =IF($B21="","",IF($AB21<>"",$AB21,IF($AA21="","",IF($AA21<=設定!$C$3,0,$AA21)))) | AD21: =IF($B21="","",IF(AND($AE21<>"",$AG21="",$AJ21=""),"保留中",IF($AJ21<>"",IF(N($AC21)>0,"支給済","不支給"),IF($AC21="","要確認",IF($AC21=0,"不支給","未処理"))))) | AI21: =IF(AND($AD21="保留中",$AF21<>""),TODAY()-$AF21,"") | AK21: =IF($B21="","",IF($AO21="","対象年月が未入力／","")&IF($B21="","",IF($AN21="","職員マスタに未登録の職員番号／",IF($Y21="","標準報酬月額が未登録／","")&IF(AND($AO21<>"",OR(AND(INDEX(職員マスタ!$G$6:$G$405,$AN21)<>"",INDEX(職員マスタ!$G$6:$G$405,$AN21)>EOMONTH($AO21,0)),AND(INDEX(職員マスタ!$H$6:$H$405,$AN21)<>"",INDEX(職員マスタ!$H$6:$H$405,$AN21)<$AO21))),"対象月が時短期間外／","")&IF(AND(INDEX(職員マスタ!$F$6:$F$405,$AN21)<>"",$AO21<>"",INDEX(職員マスタ!$F$6:$F$405,$AN21)<$AO21),"対象月に子が2歳到達済／","")&IF(AND($H21<>"",INDEX(職員マスタ!$B$6:$B$405,$AN21)<>"",SUBSTITUTE(SUBSTITUTE($H21," ","")," ","")<>SUBSTITUTE(SUBSTITUTE(INDEX(職員マスタ!$B$6:$B$405,$AN21)," ","")," ","")),"氏名がマスタと相違／","")&IF(AND($Q21<>"",INDEX(職員マスタ!$E$6:$E$405,$AN21)<>"",$Q21<>INDEX(職員マスタ!$E$6:$E$405,$AN21)),"子の生年月日がマスタと相違／","")&IF(AND($L21<>"",INDEX(職員マスタ!$G$6:$G$405,$AN21)<>"",$L21<>INDEX(職員マスタ!$G$6:$G$405,$AN21)),"時短開始日がマスタと相違／","")&IF(AND($M21<>"",INDEX(職員マスタ!$H$6:$H$405,$AN21)<>"",$M21<>INDEX(職員マスタ!$H$6:$H$405,$AN21)),"時短終了日がマスタと相違／","")))&IF(AND($B21<>"",$E21=""),"報酬額が未入力／","")&IF(N($U21)>0,"申請書に入力エラーが残っています／","")&IF(AND($B21<>"",$AO21<>""),IF(COUNTIFS($B$6:$B$3005,$B21,$C$6:$C$3005,$C21,$D$6:$D$3005,$D21)>1,"同じ月の請求が重複しています／",""),"")&IF(AND(N($E21)>0,$Z21<>"",$Z21<>"×",$AC21=0,$AB21=""),"計算額が下限以下のため不支給／","")) | AM21: =IF($AD21="保留中",COUNTIF($AD$6:$AD21,"保留中"),"") | AN21: =IF($AO21="","",IF(SUMPRODUCT(MAX((職員マスタ!$A$6:$A$405=$B21)*(((職員マスタ!$G$6:$G$405="")+(職員マスタ!$G$6:$G$405<=EOMONTH($AO21,0)))>0)*(((職員マスタ!$H$6:$H$405="")+(職員マスタ!$H$6:$H$405>=$AO21))>0)*(ROW(職員マスタ!$A$6:$A$405)-5)))>0,SUMPRODUCT(MAX((職員マスタ!$A$6:$A$405=$B21)*(((職員マスタ!$G$6:$G$405="")+(職員マスタ!$G$6:$G$405<=EOMONTH($AO21,0)))>0)*(((職員マスタ!$H$6:$H$405="")+(職員マスタ!$H$6:$H$405>=$AO21))>0)*(ROW(職員マスタ!$A$6:$A$405)-5))),IFERROR(MATCH($B21,職員マスタ!$A$6:$A$405,0),""))) | AO21: =IF(OR($B21="",$C21="",$D21=""),"",DATE($C21+2018,$D21,1))
B22: 6300941 | C22: 8 | D22: 7 | E22: 357142 | V22: =IF($AN22="",IF($B22="","",$H22),IF(INDEX(職員マスタ!$B$6:$B$405,$AN22)="",$H22,INDEX(職員マスタ!$B$6:$B$405,$AN22))) | W22: =IF($AN22="",IF($B22="","",$R22),IF(INDEX(職員マスタ!$C$6:$C$405,$AN22)="",$R22,INDEX(職員マスタ!$C$6:$C$405,$AN22))) | X22: =IF($AO22="","","R"&$C22&"."&$D22) | Y22: =IF($AN22="","",IF(INDEX(職員マスタ!$K$6:$K$405,$AN22)="","",INDEX(職員マスタ!$K$6:$K$405,$AN22))) | Z22: =IF(OR($E22="",$Y22=""),"",IF($E22>=$Y22,"×",IF($E22>=$Y22*設定!$C$5,"△","○"))) | AA22: =IF($Z22="","",IF($Z22="×",0,IF($Z22="○",ROUNDDOWN($E22*設定!$C$4,0),ROUNDDOWN($E22*ROUND((9*$Y22-9*$E22)/(10*$E22),4),0)))) | AC22: =IF($B22="","",IF($AB22<>"",$AB22,IF($AA22="","",IF($AA22<=設定!$C$3,0,$AA22)))) | AD22: =IF($B22="","",IF(AND($AE22<>"",$AG22="",$AJ22=""),"保留中",IF($AJ22<>"",IF(N($AC22)>0,"支給済","不支給"),IF($AC22="","要確認",IF($AC22=0,"不支給","未処理"))))) | AI22: =IF(AND($AD22="保留中",$AF22<>""),TODAY()-$AF22,"") | AJ22: R8.9 | AK22: =IF($B22="","",IF($AO22="","対象年月が未入力／","")&IF($B22="","",IF($AN22="","職員マスタに未登録の職員番号／",IF($Y22="","標準報酬月額が未登録／","")&IF(AND($AO22<>"",OR(AND(INDEX(職員マスタ!$G$6:$G$405,$AN22)<>"",INDEX(職員マスタ!$G$6:$G$405,$AN22)>EOMONTH($AO22,0)),AND(INDEX(職員マスタ!$H$6:$H$405,$AN22)<>"",INDEX(職員マスタ!$H$6:$H$405,$AN22)<$AO22))),"対象月が時短期間外／","")&IF(AND(INDEX(職員マスタ!$F$6:$F$405,$AN22)<>"",$AO22<>"",INDEX(職員マスタ!$F$6:$F$405,$AN22)<$AO22),"対象月に子が2歳到達済／","")&IF(AND($H22<>"",INDEX(職員マスタ!$B$6:$B$405,$AN22)<>"",SUBSTITUTE(SUBSTITUTE($H22," ","")," ","")<>SUBSTITUTE(SUBSTITUTE(INDEX(職員マスタ!$B$6:$B$405,$AN22)," ","")," ","")),"氏名がマスタと相違／","")&IF(AND($Q22<>"",INDEX(職員マスタ!$E$6:$E$405,$AN22)<>"",$Q22<>INDEX(職員マスタ!$E$6:$E$405,$AN22)),"子の生年月日がマスタと相違／","")&IF(AND($L22<>"",INDEX(職員マスタ!$G$6:$G$405,$AN22)<>"",$L22<>INDEX(職員マスタ!$G$6:$G$405,$AN22)),"時短開始日がマスタと相違／","")&IF(AND($M22<>"",INDEX(職員マスタ!$H$6:$H$405,$AN22)<>"",$M22<>INDEX(職員マスタ!$H$6:$H$405,$AN22)),"時短終了日がマスタと相違／","")))&IF(AND($B22<>"",$E22=""),"報酬額が未入力／","")&IF(N($U22)>0,"申請書に入力エラーが残っています／","")&IF(AND($B22<>"",$AO22<>""),IF(COUNTIFS($B$6:$B$3005,$B22,$C$6:$C$3005,$C22,$D$6:$D$3005,$D22)>1,"同じ月の請求が重複しています／",""),"")&IF(AND(N($E22)>0,$Z22<>"",$Z22<>"×",$AC22=0,$AB22=""),"計算額が下限以下のため不支給／","")) | AM22: =IF($AD22="保留中",COUNTIF($AD$6:$AD22,"保留中"),"") | AN22: =IF($AO22="","",IF(SUMPRODUCT(MAX((職員マスタ!$A$6:$A$405=$B22)*(((職員マスタ!$G$6:$G$405="")+(職員マスタ!$G$6:$G$405<=EOMONTH($AO22,0)))>0)*(((職員マスタ!$H$6:$H$405="")+(職員マスタ!$H$6:$H$405>=$AO22))>0)*(ROW(職員マスタ!$A$6:$A$405)-5)))>0,SUMPRODUCT(MAX((職員マスタ!$A$6:$A$405=$B22)*(((職員マスタ!$G$6:$G$405="")+(職員マスタ!$G$6:$G$405<=EOMONTH($AO22,0)))>0)*(((職員マスタ!$H$6:$H$405="")+(職員マスタ!$H$6:$H$405>=$AO22))>0)*(ROW(職員マスタ!$A$6:$A$405)-5))),IFERROR(MATCH($B22,職員マスタ!$A$6:$A$405,0),""))) | AO22: =IF(OR($B22="",$C22="",$D22=""),"",DATE($C22+2018,$D22,1))
B23: 6400857 | C23: 8 | D23: 4 | E23: 239718 | V23: =IF($AN23="",IF($B23="","",$H23),IF(INDEX(職員マスタ!$B$6:$B$405,$AN23)="",$H23,INDEX(職員マスタ!$B$6:$B$405,$AN23))) | W23: =IF($AN23="",IF($B23="","",$R23),IF(INDEX(職員マスタ!$C$6:$C$405,$AN23)="",$R23,INDEX(職員マスタ!$C$6:$C$405,$AN23))) | X23: =IF($AO23="","","R"&$C23&"."&$D23) | Y23: =IF($AN23="","",IF(INDEX(職員マスタ!$K$6:$K$405,$AN23)="","",INDEX(職員マスタ!$K$6:$K$405,$AN23))) | Z23: =IF(OR($E23="",$Y23=""),"",IF($E23>=$Y23,"×",IF($E23>=$Y23*設定!$C$5,"△","○"))) | AA23: =IF($Z23="","",IF($Z23="×",0,IF($Z23="○",ROUNDDOWN($E23*設定!$C$4,0),ROUNDDOWN($E23*ROUND((9*$Y23-9*$E23)/(10*$E23),4),0)))) | AC23: =IF($B23="","",IF($AB23<>"",$AB23,IF($AA23="","",IF($AA23<=設定!$C$3,0,$AA23)))) | AD23: =IF($B23="","",IF(AND($AE23<>"",$AG23="",$AJ23=""),"保留中",IF($AJ23<>"",IF(N($AC23)>0,"支給済","不支給"),IF($AC23="","要確認",IF($AC23=0,"不支給","未処理"))))) | AI23: =IF(AND($AD23="保留中",$AF23<>""),TODAY()-$AF23,"") | AJ23: R8.6 | AK23: =IF($B23="","",IF($AO23="","対象年月が未入力／","")&IF($B23="","",IF($AN23="","職員マスタに未登録の職員番号／",IF($Y23="","標準報酬月額が未登録／","")&IF(AND($AO23<>"",OR(AND(INDEX(職員マスタ!$G$6:$G$405,$AN23)<>"",INDEX(職員マスタ!$G$6:$G$405,$AN23)>EOMONTH($AO23,0)),AND(INDEX(職員マスタ!$H$6:$H$405,$AN23)<>"",INDEX(職員マスタ!$H$6:$H$405,$AN23)<$AO23))),"対象月が時短期間外／","")&IF(AND(INDEX(職員マスタ!$F$6:$F$405,$AN23)<>"",$AO23<>"",INDEX(職員マスタ!$F$6:$F$405,$AN23)<$AO23),"対象月に子が2歳到達済／","")&IF(AND($H23<>"",INDEX(職員マスタ!$B$6:$B$405,$AN23)<>"",SUBSTITUTE(SUBSTITUTE($H23," ","")," ","")<>SUBSTITUTE(SUBSTITUTE(INDEX(職員マスタ!$B$6:$B$405,$AN23)," ","")," ","")),"氏名がマスタと相違／","")&IF(AND($Q23<>"",INDEX(職員マスタ!$E$6:$E$405,$AN23)<>"",$Q23<>INDEX(職員マスタ!$E$6:$E$405,$AN23)),"子の生年月日がマスタと相違／","")&IF(AND($L23<>"",INDEX(職員マスタ!$G$6:$G$405,$AN23)<>"",$L23<>INDEX(職員マスタ!$G$6:$G$405,$AN23)),"時短開始日がマスタと相違／","")&IF(AND($M23<>"",INDEX(職員マスタ!$H$6:$H$405,$AN23)<>"",$M23<>INDEX(職員マスタ!$H$6:$H$405,$AN23)),"時短終了日がマスタと相違／","")))&IF(AND($B23<>"",$E23=""),"報酬額が未入力／","")&IF(N($U23)>0,"申請書に入力エラーが残っています／","")&IF(AND($B23<>"",$AO23<>""),IF(COUNTIFS($B$6:$B$3005,$B23,$C$6:$C$3005,$C23,$D$6:$D$3005,$D23)>1,"同じ月の請求が重複しています／",""),"")&IF(AND(N($E23)>0,$Z23<>"",$Z23<>"×",$AC23=0,$AB23=""),"計算額が下限以下のため不支給／","")) | AM23: =IF($AD23="保留中",COUNTIF($AD$6:$AD23,"保留中"),"") | AN23: =IF($AO23="","",IF(SUMPRODUCT(MAX((職員マスタ!$A$6:$A$405=$B23)*(((職員マスタ!$G$6:$G$405="")+(職員マスタ!$G$6:$G$405<=EOMONTH($AO23,0)))>0)*(((職員マスタ!$H$6:$H$405="")+(職員マスタ!$H$6:$H$405>=$AO23))>0)*(ROW(職員マスタ!$A$6:$A$405)-5)))>0,SUMPRODUCT(MAX((職員マスタ!$A$6:$A$405=$B23)*(((職員マスタ!$G$6:$G$405="")+(職員マスタ!$G$6:$G$405<=EOMONTH($AO23,0)))>0)*(((職員マスタ!$H$6:$H$405="")+(職員マスタ!$H$6:$H$405>=$AO23))>0)*(ROW(職員マスタ!$A$6:$A$405)-5))),IFERROR(MATCH($B23,職員マスタ!$A$6:$A$405,0),""))) | AO23: =IF(OR($B23="",$C23="",$D23=""),"",DATE($C23+2018,$D23,1))
B24: 6400857 | C24: 8 | D24: 5 | E24: 260051 | V24: =IF($AN24="",IF($B24="","",$H24),IF(INDEX(職員マスタ!$B$6:$B$405,$AN24)="",$H24,INDEX(職員マスタ!$B$6:$B$405,$AN24))) | W24: =IF($AN24="",IF($B24="","",$R24),IF(INDEX(職員マスタ!$C$6:$C$405,$AN24)="",$R24,INDEX(職員マスタ!$C$6:$C$405,$AN24))) | X24: =IF($AO24="","","R"&$C24&"."&$D24) | Y24: =IF($AN24="","",IF(INDEX(職員マスタ!$K$6:$K$405,$AN24)="","",INDEX(職員マスタ!$K$6:$K$405,$AN24))) | Z24: =IF(OR($E24="",$Y24=""),"",IF($E24>=$Y24,"×",IF($E24>=$Y24*設定!$C$5,"△","○"))) | AA24: =IF($Z24="","",IF($Z24="×",0,IF($Z24="○",ROUNDDOWN($E24*設定!$C$4,0),ROUNDDOWN($E24*ROUND((9*$Y24-9*$E24)/(10*$E24),4),0)))) | AC24: =IF($B24="","",IF($AB24<>"",$AB24,IF($AA24="","",IF($AA24<=設定!$C$3,0,$AA24)))) | AD24: =IF($B24="","",IF(AND($AE24<>"",$AG24="",$AJ24=""),"保留中",IF($AJ24<>"",IF(N($AC24)>0,"支給済","不支給"),IF($AC24="","要確認",IF($AC24=0,"不支給","未処理"))))) | AI24: =IF(AND($AD24="保留中",$AF24<>""),TODAY()-$AF24,"") | AJ24: R8.7 | AK24: =IF($B24="","",IF($AO24="","対象年月が未入力／","")&IF($B24="","",IF($AN24="","職員マスタに未登録の職員番号／",IF($Y24="","標準報酬月額が未登録／","")&IF(AND($AO24<>"",OR(AND(INDEX(職員マスタ!$G$6:$G$405,$AN24)<>"",INDEX(職員マスタ!$G$6:$G$405,$AN24)>EOMONTH($AO24,0)),AND(INDEX(職員マスタ!$H$6:$H$405,$AN24)<>"",INDEX(職員マスタ!$H$6:$H$405,$AN24)<$AO24))),"対象月が時短期間外／","")&IF(AND(INDEX(職員マスタ!$F$6:$F$405,$AN24)<>"",$AO24<>"",INDEX(職員マスタ!$F$6:$F$405,$AN24)<$AO24),"対象月に子が2歳到達済／","")&IF(AND($H24<>"",INDEX(職員マスタ!$B$6:$B$405,$AN24)<>"",SUBSTITUTE(SUBSTITUTE($H24," ","")," ","")<>SUBSTITUTE(SUBSTITUTE(INDEX(職員マスタ!$B$6:$B$405,$AN24)," ","")," ","")),"氏名がマスタと相違／","")&IF(AND($Q24<>"",INDEX(職員マスタ!$E$6:$E$405,$AN24)<>"",$Q24<>INDEX(職員マスタ!$E$6:$E$405,$AN24)),"子の生年月日がマスタと相違／","")&IF(AND($L24<>"",INDEX(職員マスタ!$G$6:$G$405,$AN24)<>"",$L24<>INDEX(職員マスタ!$G$6:$G$405,$AN24)),"時短開始日がマスタと相違／","")&IF(AND($M24<>"",INDEX(職員マスタ!$H$6:$H$405,$AN24)<>"",$M24<>INDEX(職員マスタ!$H$6:$H$405,$AN24)),"時短終了日がマスタと相違／","")))&IF(AND($B24<>"",$E24=""),"報酬額が未入力／","")&IF(N($U24)>0,"申請書に入力エラーが残っています／","")&IF(AND($B24<>"",$AO24<>""),IF(COUNTIFS($B$6:$B$3005,$B24,$C$6:$C$3005,$C24,$D$6:$D$3005,$D24)>1,"同じ月の請求が重複しています／",""),"")&IF(AND(N($E24)>0,$Z24<>"",$Z24<>"×",$AC24=0,$AB24=""),"計算額が下限以下のため不支給／","")) | AM24: =IF($AD24="保留中",COUNTIF($AD$6:$AD24,"保留中"),"") | AN24: =IF($AO24="","",IF(SUMPRODUCT(MAX((職員マスタ!$A$6:$A$405=$B24)*(((職員マスタ!$G$6:$G$405="")+(職員マスタ!$G$6:$G$405<=EOMONTH($AO24,0)))>0)*(((職員マスタ!$H$6:$H$405="")+(職員マスタ!$H$6:$H$405>=$AO24))>0)*(ROW(職員マスタ!$A$6:$A$405)-5)))>0,SUMPRODUCT(MAX((職員マスタ!$A$6:$A$405=$B24)*(((職員マスタ!$G$6:$G$405="")+(職員マスタ!$G$6:$G$405<=EOMONTH($AO24,0)))>0)*(((職員マスタ!$H$6:$H$405="")+(職員マスタ!$H$6:$H$405>=$AO24))>0)*(ROW(職員マスタ!$A$6:$A$405)-5))),IFERROR(MATCH($B24,職員マスタ!$A$6:$A$405,0),""))) | AO24: =IF(OR($B24="",$C24="",$D24=""),"",DATE($C24+2018,$D24,1))
B25: 6400857 | C25: 8 | D25: 6 | E25: 254399 | V25: =IF($AN25="",IF($B25="","",$H25),IF(INDEX(職員マスタ!$B$6:$B$405,$AN25)="",$H25,INDEX(職員マスタ!$B$6:$B$405,$AN25))) | W25: =IF($AN25="",IF($B25="","",$R25),IF(INDEX(職員マスタ!$C$6:$C$405,$AN25)="",$R25,INDEX(職員マスタ!$C$6:$C$405,$AN25))) | X25: =IF($AO25="","","R"&$C25&"."&$D25) | Y25: =IF($AN25="","",IF(INDEX(職員マスタ!$K$6:$K$405,$AN25)="","",INDEX(職員マスタ!$K$6:$K$405,$AN25))) | Z25: =IF(OR($E25="",$Y25=""),"",IF($E25>=$Y25,"×",IF($E25>=$Y25*設定!$C$5,"△","○"))) | AA25: =IF($Z25="","",IF($Z25="×",0,IF($Z25="○",ROUNDDOWN($E25*設定!$C$4,0),ROUNDDOWN($E25*ROUND((9*$Y25-9*$E25)/(10*$E25),4),0)))) | AC25: =IF($B25="","",IF($AB25<>"",$AB25,IF($AA25="","",IF($AA25<=設定!$C$3,0,$AA25)))) | AD25: =IF($B25="","",IF(AND($AE25<>"",$AG25="",$AJ25=""),"保留中",IF($AJ25<>"",IF(N($AC25)>0,"支給済","不支給"),IF($AC25="","要確認",IF($AC25=0,"不支給","未処理"))))) | AI25: =IF(AND($AD25="保留中",$AF25<>""),TODAY()-$AF25,"") | AJ25: R8.8 | AK25: =IF($B25="","",IF($AO25="","対象年月が未入力／","")&IF($B25="","",IF($AN25="","職員マスタに未登録の職員番号／",IF($Y25="","標準報酬月額が未登録／","")&IF(AND($AO25<>"",OR(AND(INDEX(職員マスタ!$G$6:$G$405,$AN25)<>"",INDEX(職員マスタ!$G$6:$G$405,$AN25)>EOMONTH($AO25,0)),AND(INDEX(職員マスタ!$H$6:$H$405,$AN25)<>"",INDEX(職員マスタ!$H$6:$H$405,$AN25)<$AO25))),"対象月が時短期間外／","")&IF(AND(INDEX(職員マスタ!$F$6:$F$405,$AN25)<>"",$AO25<>"",INDEX(職員マスタ!$F$6:$F$405,$AN25)<$AO25),"対象月に子が2歳到達済／","")&IF(AND($H25<>"",INDEX(職員マスタ!$B$6:$B$405,$AN25)<>"",SUBSTITUTE(SUBSTITUTE($H25," ","")," ","")<>SUBSTITUTE(SUBSTITUTE(INDEX(職員マスタ!$B$6:$B$405,$AN25)," ","")," ","")),"氏名がマスタと相違／","")&IF(AND($Q25<>"",INDEX(職員マスタ!$E$6:$E$405,$AN25)<>"",$Q25<>INDEX(職員マスタ!$E$6:$E$405,$AN25)),"子の生年月日がマスタと相違／","")&IF(AND($L25<>"",INDEX(職員マスタ!$G$6:$G$405,$AN25)<>"",$L25<>INDEX(職員マスタ!$G$6:$G$405,$AN25)),"時短開始日がマスタと相違／","")&IF(AND($M25<>"",INDEX(職員マスタ!$H$6:$H$405,$AN25)<>"",$M25<>INDEX(職員マスタ!$H$6:$H$405,$AN25)),"時短終了日がマスタと相違／","")))&IF(AND($B25<>"",$E25=""),"報酬額が未入力／","")&IF(N($U25)>0,"申請書に入力エラーが残っています／","")&IF(AND($B25<>"",$AO25<>""),IF(COUNTIFS($B$6:$B$3005,$B25,$C$6:$C$3005,$C25,$D$6:$D$3005,$D25)>1,"同じ月の請求が重複しています／",""),"")&IF(AND(N($E25)>0,$Z25<>"",$Z25<>"×",$AC25=0,$AB25=""),"計算額が下限以下のため不支給／","")) | AM25: =IF($AD25="保留中",COUNTIF($AD$6:$AD25,"保留中"),"") | AN25: =IF($AO25="","",IF(SUMPRODUCT(MAX((職員マスタ!$A$6:$A$405=$B25)*(((職員マスタ!$G$6:$G$405="")+(職員マスタ!$G$6:$G$405<=EOMONTH($AO25,0)))>0)*(((職員マスタ!$H$6:$H$405="")+(職員マスタ!$H$6:$H$405>=$AO25))>0)*(ROW(職員マスタ!$A$6:$A$405)-5)))>0,SUMPRODUCT(MAX((職員マスタ!$A$6:$A$405=$B25)*(((職員マスタ!$G$6:$G$405="")+(職員マスタ!$G$6:$G$405<=EOMONTH($AO25,0)))>0)*(((職員マスタ!$H$6:$H$405="")+(職員マスタ!$H$6:$H$405>=$AO25))>0)*(ROW(職員マスタ!$A$6:$A$405)-5))),IFERROR(MATCH($B25,職員マスタ!$A$6:$A$405,0),""))) | AO25: =IF(OR($B25="",$C25="",$D25=""),"",DATE($C25+2018,$D25,1))
B26: 6400857 | C26: 8 | D26: 7 | E26: 240269 | V26: =IF($AN26="",IF($B26="","",$H26),IF(INDEX(職員マスタ!$B$6:$B$405,$AN26)="",$H26,INDEX(職員マスタ!$B$6:$B$405,$AN26))) | W26: =IF($AN26="",IF($B26="","",$R26),IF(INDEX(職員マスタ!$C$6:$C$405,$AN26)="",$R26,INDEX(職員マスタ!$C$6:$C$405,$AN26))) | X26: =IF($AO26="","","R"&$C26&"."&$D26) | Y26: =IF($AN26="","",IF(INDEX(職員マスタ!$K$6:$K$405,$AN26)="","",INDEX(職員マスタ!$K$6:$K$405,$AN26))) | Z26: =IF(OR($E26="",$Y26=""),"",IF($E26>=$Y26,"×",IF($E26>=$Y26*設定!$C$5,"△","○"))) | AA26: =IF($Z26="","",IF($Z26="×",0,IF($Z26="○",ROUNDDOWN($E26*設定!$C$4,0),ROUNDDOWN($E26*ROUND((9*$Y26-9*$E26)/(10*$E26),4),0)))) | AC26: =IF($B26="","",IF($AB26<>"",$AB26,IF($AA26="","",IF($AA26<=設定!$C$3,0,$AA26)))) | AD26: =IF($B26="","",IF(AND($AE26<>"",$AG26="",$AJ26=""),"保留中",IF($AJ26<>"",IF(N($AC26)>0,"支給済","不支給"),IF($AC26="","要確認",IF($AC26=0,"不支給","未処理"))))) | AI26: =IF(AND($AD26="保留中",$AF26<>""),TODAY()-$AF26,"") | AJ26: R8.9 | AK26: =IF($B26="","",IF($AO26="","対象年月が未入力／","")&IF($B26="","",IF($AN26="","職員マスタに未登録の職員番号／",IF($Y26="","標準報酬月額が未登録／","")&IF(AND($AO26<>"",OR(AND(INDEX(職員マスタ!$G$6:$G$405,$AN26)<>"",INDEX(職員マスタ!$G$6:$G$405,$AN26)>EOMONTH($AO26,0)),AND(INDEX(職員マスタ!$H$6:$H$405,$AN26)<>"",INDEX(職員マスタ!$H$6:$H$405,$AN26)<$AO26))),"対象月が時短期間外／","")&IF(AND(INDEX(職員マスタ!$F$6:$F$405,$AN26)<>"",$AO26<>"",INDEX(職員マスタ!$F$6:$F$405,$AN26)<$AO26),"対象月に子が2歳到達済／","")&IF(AND($H26<>"",INDEX(職員マスタ!$B$6:$B$405,$AN26)<>"",SUBSTITUTE(SUBSTITUTE($H26," ","")," ","")<>SUBSTITUTE(SUBSTITUTE(INDEX(職員マスタ!$B$6:$B$405,$AN26)," ","")," ","")),"氏名がマスタと相違／","")&IF(AND($Q26<>"",INDEX(職員マスタ!$E$6:$E$405,$AN26)<>"",$Q26<>INDEX(職員マスタ!$E$6:$E$405,$AN26)),"子の生年月日がマスタと相違／","")&IF(AND($L26<>"",INDEX(職員マスタ!$G$6:$G$405,$AN26)<>"",$L26<>INDEX(職員マスタ!$G$6:$G$405,$AN26)),"時短開始日がマスタと相違／","")&IF(AND($M26<>"",INDEX(職員マスタ!$H$6:$H$405,$AN26)<>"",$M26<>INDEX(職員マスタ!$H$6:$H$405,$AN26)),"時短終了日がマスタと相違／","")))&IF(AND($B26<>"",$E26=""),"報酬額が未入力／","")&IF(N($U26)>0,"申請書に入力エラーが残っています／","")&IF(AND($B26<>"",$AO26<>""),IF(COUNTIFS($B$6:$B$3005,$B26,$C$6:$C$3005,$C26,$D$6:$D$3005,$D26)>1,"同じ月の請求が重複しています／",""),"")&IF(AND(N($E26)>0,$Z26<>"",$Z26<>"×",$AC26=0,$AB26=""),"計算額が下限以下のため不支給／","")) | AM26: =IF($AD26="保留中",COUNTIF($AD$6:$AD26,"保留中"),"") | AN26: =IF($AO26="","",IF(SUMPRODUCT(MAX((職員マスタ!$A$6:$A$405=$B26)*(((職員マスタ!$G$6:$G$405="")+(職員マスタ!$G$6:$G$405<=EOMONTH($AO26,0)))>0)*(((職員マスタ!$H$6:$H$405="")+(職員マスタ!$H$6:$H$405>=$AO26))>0)*(ROW(職員マスタ!$A$6:$A$405)-5)))>0,SUMPRODUCT(MAX((職員マスタ!$A$6:$A$405=$B26)*(((職員マスタ!$G$6:$G$405="")+(職員マスタ!$G$6:$G$405<=EOMONTH($AO26,0)))>0)*(((職員マスタ!$H$6:$H$405="")+(職員マスタ!$H$6:$H$405>=$AO26))>0)*(ROW(職員マスタ!$A$6:$A$405)-5))),IFERROR(MATCH($B26,職員マスタ!$A$6:$A$405,0),""))) | AO26: =IF(OR($B26="",$C26="",$D26=""),"",DATE($C26+2018,$D26,1))
B27: 6400857 | C27: 8 | D27: 8 | E27: 240269 | V27: =IF($AN27="",IF($B27="","",$H27),IF(INDEX(職員マスタ!$B$6:$B$405,$AN27)="",$H27,INDEX(職員マスタ!$B$6:$B$405,$AN27))) | W27: =IF($AN27="",IF($B27="","",$R27),IF(INDEX(職員マスタ!$C$6:$C$405,$AN27)="",$R27,INDEX(職員マスタ!$C$6:$C$405,$AN27))) | X27: =IF($AO27="","","R"&$C27&"."&$D27) | Y27: =IF($AN27="","",IF(INDEX(職員マスタ!$K$6:$K$405,$AN27)="","",INDEX(職員マスタ!$K$6:$K$405,$AN27))) | Z27: =IF(OR($E27="",$Y27=""),"",IF($E27>=$Y27,"×",IF($E27>=$Y27*設定!$C$5,"△","○"))) | AA27: =IF($Z27="","",IF($Z27="×",0,IF($Z27="○",ROUNDDOWN($E27*設定!$C$4,0),ROUNDDOWN($E27*ROUND((9*$Y27-9*$E27)/(10*$E27),4),0)))) | AC27: =IF($B27="","",IF($AB27<>"",$AB27,IF($AA27="","",IF($AA27<=設定!$C$3,0,$AA27)))) | AD27: =IF($B27="","",IF(AND($AE27<>"",$AG27="",$AJ27=""),"保留中",IF($AJ27<>"",IF(N($AC27)>0,"支給済","不支給"),IF($AC27="","要確認",IF($AC27=0,"不支給","未処理"))))) | AI27: =IF(AND($AD27="保留中",$AF27<>""),TODAY()-$AF27,"") | AJ27: R8.10 | AK27: =IF($B27="","",IF($AO27="","対象年月が未入力／","")&IF($B27="","",IF($AN27="","職員マスタに未登録の職員番号／",IF($Y27="","標準報酬月額が未登録／","")&IF(AND($AO27<>"",OR(AND(INDEX(職員マスタ!$G$6:$G$405,$AN27)<>"",INDEX(職員マスタ!$G$6:$G$405,$AN27)>EOMONTH($AO27,0)),AND(INDEX(職員マスタ!$H$6:$H$405,$AN27)<>"",INDEX(職員マスタ!$H$6:$H$405,$AN27)<$AO27))),"対象月が時短期間外／","")&IF(AND(INDEX(職員マスタ!$F$6:$F$405,$AN27)<>"",$AO27<>"",INDEX(職員マスタ!$F$6:$F$405,$AN27)<$AO27),"対象月に子が2歳到達済／","")&IF(AND($H27<>"",INDEX(職員マスタ!$B$6:$B$405,$AN27)<>"",SUBSTITUTE(SUBSTITUTE($H27," ","")," ","")<>SUBSTITUTE(SUBSTITUTE(INDEX(職員マスタ!$B$6:$B$405,$AN27)," ","")," ","")),"氏名がマスタと相違／","")&IF(AND($Q27<>"",INDEX(職員マスタ!$E$6:$E$405,$AN27)<>"",$Q27<>INDEX(職員マスタ!$E$6:$E$405,$AN27)),"子の生年月日がマスタと相違／","")&IF(AND($L27<>"",INDEX(職員マスタ!$G$6:$G$405,$AN27)<>"",$L27<>INDEX(職員マスタ!$G$6:$G$405,$AN27)),"時短開始日がマスタと相違／","")&IF(AND($M27<>"",INDEX(職員マスタ!$H$6:$H$405,$AN27)<>"",$M27<>INDEX(職員マスタ!$H$6:$H$405,$AN27)),"時短終了日がマスタと相違／","")))&IF(AND($B27<>"",$E27=""),"報酬額が未入力／","")&IF(N($U27)>0,"申請書に入力エラーが残っています／","")&IF(AND($B27<>"",$AO27<>""),IF(COUNTIFS($B$6:$B$3005,$B27,$C$6:$C$3005,$C27,$D$6:$D$3005,$D27)>1,"同じ月の請求が重複しています／",""),"")&IF(AND(N($E27)>0,$Z27<>"",$Z27<>"×",$AC27=0,$AB27=""),"計算額が下限以下のため不支給／","")) | AM27: =IF($AD27="保留中",COUNTIF($AD$6:$AD27,"保留中"),"") | AN27: =IF($AO27="","",IF(SUMPRODUCT(MAX((職員マスタ!$A$6:$A$405=$B27)*(((職員マスタ!$G$6:$G$405="")+(職員マスタ!$G$6:$G$405<=EOMONTH($AO27,0)))>0)*(((職員マスタ!$H$6:$H$405="")+(職員マスタ!$H$6:$H$405>=$AO27))>0)*(ROW(職員マスタ!$A$6:$A$405)-5)))>0,SUMPRODUCT(MAX((職員マスタ!$A$6:$A$405=$B27)*(((職員マスタ!$G$6:$G$405="")+(職員マスタ!$G$6:$G$405<=EOMONTH($AO27,0)))>0)*(((職員マスタ!$H$6:$H$405="")+(職員マスタ!$H$6:$H$405>=$AO27))>0)*(ROW(職員マスタ!$A$6:$A$405)-5))),IFERROR(MATCH($B27,職員マスタ!$A$6:$A$405,0),""))) | AO27: =IF(OR($B27="",$C27="",$D27=""),"",DATE($C27+2018,$D27,1))
