Workbook
Name _Hlk192790333: '原本 (裏)'!$B$23

Sheet 使い方
B2: 育児時短勤務手当金請求書（電子申請書） 使い方
B4: ■ 職員・庶務担当の方
B5: 1. このファイルを開き、「入力」シートの黄色いセルに入力します（インストール不要・Excelだけで動きます）。
B6: 2. 入力すると、右側の「チェック」欄が自動で ✓（OK）／✕（エラー）／△（要確認）になります。✕ は必ず直してください。
B7: 3. 日付は「令和」の年・月・日を数字で入力します（例：令和8年4月 → 年に8、月に4）。請求期間は自動で計算されます。
B8: 4. 「入力」シート最上段が緑色（✓）になったら、「請求書(表)」「請求書(裏)」を印刷し、所属機関の長の確認欄に記入・押印します。
B9: 5. 添付書類（承認書・出勤簿・支給明細書の写し等）を添えて、庶務担当を通じて共済組合へ提出します。
B10: ※入力エラーが残ったまま印刷すると、請求書の下に赤字で警告が印字されます。
B11: ※1か月分ごとに1回請求します。翌月分は、このファイルを「名前を付けて保存」し、対象月と報酬額などを書き換えて使えます。
B12: ※☆の項目（個人番号・標準報酬月額・決定額）と所属機関の長の氏名等は入力不要です。
B14: ■ 共済組合の方
B15: ・受け取ったファイルの「共済組合提出データ」シートの2行目をコピーし、管理台帳「請求記録」に値のみ貼り付けます。
... B19: Excel 2013以降（マクロ不使用）。シートは保護（パスワードなし）されており、黄色いセル以外は書き換えできません。

Sheet 入力
B1: 育児時短勤務手当金請求書 入力シート
B2: =IF(COUNTIF(K6:K52,"✕*")>0,"✕ 入力エラーが "&COUNTIF(K6:K52,"✕*")&" 件あります。赤い項目を直してください。",IF(COUNTIF(K6:K52,"△*")>0,"△ エラーはありません。注意が "&COUNTIF(K6:K52,"△*")&" 件あります。内容を確認してください。（印刷できます）","✓ すべて正しく入力されています。「請求書(表)」「請求書(裏)」を印刷し、添付書類をそろえて提出してください。"))
B3: 黄色いセルに入力してください。右の「チェック」欄が ✓（緑）になれば正しく入力できています。✕（赤）は必ず直してください。☆の項目（標準報酬月額・決定額・個人番号）は共済組合が記入するので入力不要です。
K4: チェック（自動） | L4: 記入例・説明
B5: ① 請求する月
B6: 職員番号（7桁） | K6: =IF(C6="","✕ 未入力です",IF(NOT(ISNUMBER(C6)),"✕ 数字で入力してください",IF(LEN(C6)<>7,"△ 職員番号は通常7桁です。確認してください","✓"))) | L6: 共済組合への提出データ用です（請求書には印字されません）
B7: 請求対象月（令和 年 月分） | C7: 令和 | E7: 年 | G7: 月分 | K7: =IF(COUNTA(D7,F7)=0,"✕ 未入力です",IF(N7="","✕ 年と月を入力してください",IF(N7<DATE(2025,4,1),"✕ 令和7年4月分以降が対象です",IF(N7>=DATE(YEAR(TODAY()),MONTH(TODAY()),1),"✕ まだ月が終わっていません。勤務した月の翌月以降に請求してください","✓")))) | L7: 育児時短勤務をした月。令和7年4月分以降が対象。月が終わってから請求します | N7: =IF(AND(ISNUMBER(D7),ISNUMBER(F7)),IFERROR(DATE(D7+2018,F7,1),""),"") | O7: =IF(N7="","",EOMONTH(N7,0))
B8: ② 組合員
B9: 組合員等記号番号 | E9: ― | K9: =IF(AND(C9="",F9=""),"✕ 未入力です",IF(C9="","✕ 記号が未入力です",IF(F9="","✕ 番号が未入力です","✓"))) | L9: 組合員証・資格情報通知書の記号と番号（半角）
B10: フリガナ | K10: =IF(C10="","✕ 未入力です",IF(SUMPRODUCT((_xlfn.UNICODE(MID(C10&REPT(" ",60),ROW($1:$60),1))<>32)*(_xlfn.UNICODE(MID(C10&REPT(" ",60),ROW($1:$60),1))<>12288)*(((_xlfn.UNICODE(MID(C10&REPT(" ",60),ROW($1:$60),1))<12449)+(_xlfn.UNICODE(MID(C10&REPT(" ",60),ROW($1:$60),1))>12540))>0))>0,"✕ 全角カタカナで入力してください（半角カナ・ひらがな・漢字は不可）",IF(AND(ISERROR(FIND(" ",C10)),ISERROR(FIND(" ",C10))),"△ 姓と名の間に空白を入れてください","✓"))) | L10: 全角カタカナ 例：ヒロシマ ハナコ（姓と名の間は空白）
B11: 組合員氏名 | K11: =IF(C11="","✕ 未入力です","✓") | L11: 例：広島 花子
B12: 性別 | K12: =IF(C12="","✕ 未入力です（選択してください）","✓")
B13: 生年月日 | E13: 年 | G13: 月 | I13: 日 | K13: =IF(AND(C13="",COUNTA(D13,F13,H13)=0),"✕ 未入力です",IF(C13="","✕ 昭和・平成を選んでください",IF(COUNT(D13,F13,H13)<3,"✕ 年・月・日をすべて入力してください",IF(AND(C13="昭和",D13>64),"✕ 昭和は64年までです",IF(AND(C13="平成",D13>31),"✕ 平成は31年までです",IF(N13="","✕ 存在しない日付です",IF(AND(N7<>"",OR(N7-N13<18*365,N7-N13>70*365)),"△ 年齢が18〜70歳の範囲外です。生年月日を確認してください","✓"))))))) | L13: 昭和・平成を選び、年月日を数字で入力 | N13: =IF(COUNT(D13,F13,H13)<3,"",IFERROR(IF(AND(D13>=1,F13>=1,F13<=12,H13>=1,DAY(DATE(D13+IF(C13="昭和",1925,1988),F13,H13))=H13),DATE(D13+IF(C13="昭和",1925,1988),F13,H13),""),""))
B14: ③ 所属機関
B15: 名称 | K15: =IF(C15="","✕ 未入力です","✓") | L15: 例：環境局環境保全課／○○保育園
B16: 所在地 | K16: =IF(C16="","✕ 未入力です","✓") | L16: 例：広島市中区国泰寺町1-6-34
B17: ④ 育児時短勤務（部分休業）の内容
B18: 勤務区分 | K18: =IF(C18="","✕ 未入力です（選択してください）","✓") | L18: 承認書の区分（育児短時間勤務／部分休業）
B19: 初回の請求ですか | K19: =IF(C19="","✕ 未入力です（選択してください）","✓") | L19: 初回請求のときは母子手帳等の写しが必要です
B20: 育児短時間勤務又は部分休業期間（開始） | C20: 令和 | E20: 年 | G20: 月 | I20: 日 | K20: =IF(COUNTA(D20,F20,H20)=0,"✕ 未入力です",IF(N20="","✕ 年月日が正しくありません（存在しない日付など）","✓")) | L20: 承認書に記載された期間の開始日 | N20: =IF(COUNT(D20,F20,H20)<3,"",IFERROR(IF(AND(D20>=1,F20>=1,F20<=12,H20>=1,DAY(DATE(D20+2018,F20,H20))=H20),DATE(D20+2018,F20,H20),""),""))
B21: 育児短時間勤務又は部分休業期間（終了） | C21: 令和 | E21: 年 | G21: 月 | I21: 日 | K21: =IF(COUNTA(D21,F21,H21)=0,"✕ 未入力です",IF(N21="","✕ 年月日が正しくありません（存在しない日付など）",IF(AND(N20<>"",N21<N20),"✕ 終了日が開始日より前です","✓"))) | L21: 承認書に記載された期間の終了日 | N21: =IF(COUNT(D21,F21,H21)<3,"",IFERROR(IF(AND(D21>=1,F21>=1,F21<=12,H21>=1,DAY(DATE(D21+2018,F21,H21))=H21),DATE(D21+2018,F21,H21),""),""))
B22: 支給終了の特別事由の開始日（該当時のみ） | C22: 令和 | E22: 年 | G22: 月 | I22: 日 | K22: =IF(COUNTA(D22,F22,H22)=0,"",IF(N22="","✕ 年月日が正しくありません","✓")) | L22: 産前産後休業・介護休業・育児休業を新たに始める場合のみ。その前日が請求期間の終了日になります | N22: =IF(COUNT(D22,F22,H22)<3,"",IFERROR(IF(AND(D22>=1,F22>=1,F22<=12,H22>=1,DAY(DATE(D22+2018,F22,H22))=H22),DATE(D22+2018,F22,H22),""),""))
B23: 育児時短勤務手当金請求期間（開始）【自動】 | C23: 令和 | D23: =IF(N23="","",YEAR(N23)-2018) | E23: 年 | F23: =IF(N23="","",MONTH(N23)) | G23: 月 | H23: =IF(N23="","",DAY(N23)) | I23: 日 | K23: =IF(N23="","",IF(AND(N24<>"",N24<N23),"✕ 請求期間がありません。対象月が勤務期間外か、子が2歳に達しています","✓")) | L23: 対象月・勤務期間・子の2歳到達日から自動計算（入力不要） | N23: =IF(OR(N7="",N20="",N21=""),"",MAX(N7,N20))
B24: 育児時短勤務手当金請求期間（終了）【自動】 | C24: 令和 | D24: =IF(N24="","",YEAR(N24)-2018) | E24: 年 | F24: =IF(N24="","",MONTH(N24)) | G24: 月 | H24: =IF(N24="","",DAY(N24)) | I24: 日 | K24: =IF(N24="","",IF(N24<N23,"✕ 請求期間がありません（上の入力を確認）","✓")) | L24: 子が2歳になる月は「2歳の誕生日の前々日」まで | N24: =IF(OR(N7="",N20="",N21="",N26=""),"",MIN(O7,N21,O26,IF(N22="",O7,N22-1)))
B25: 育児時短勤務に係る子の名前 | K25: =IF(C25="","✕ 未入力です","✓") | L25: 例：広島 太郎
B26: 子の生年月日 | C26: 令和 | E26: 年 | G26: 月 | I26: 日 | K26: =IF(COUNTA(D26,F26,H26)=0,"✕ 未入力です",IF(N26="","✕ 年月日が正しくありません（存在しない日付など）",IF(AND(N20<>"",N26>N20),"✕ 子の生年月日が勤務開始日より後になっています",IF(AND(N7<>"",O26<N7),"✕ 対象月には子が2歳に達しています（2歳の誕生日の前々日までが対象）","✓")))) | L26: 令和の年月日（母子手帳等で確認） | N26: =IF(COUNT(D26,F26,H26)<3,"",IFERROR(IF(AND(D26>=1,F26>=1,F26<=12,H26>=1,DAY(DATE(D26+2018,F26,H26))=H26),DATE(D26+2018,F26,H26),""),"")) | O26: =IF(N26="","",DATE(YEAR(N26)+2,MONTH(N26),DAY(N26)-2))
B27: ⑤ 報酬・通勤手当
B28: 支給対象月に支払われた報酬の額（円） | I28: 円 | K28: =IF(C28="","✕ 未入力です",IF(NOT(ISNUMBER(C28)),"✕ 数字で入力してください",IF(C28=0,"△ 0円です。支給明細書を確認してください",IF(C28>1000000,"△ 金額が大きすぎます。桁を確認してください","✓")))) | L28: 支給明細書の額（期末勤勉手当・給与改定差額を除く）。1月当たりの通勤手当を含む
B29: 通勤手当の有無 | K29: =IF(C29="","✕ 未入力です（選択してください）","✓")
B30: 1月当たりの通勤手当の額（円） | I30: 円 | K30: =IF(AND(C29="",C30=""),"",IF(AND(C29="有",OR(C30="",N(C30)=0)),"✕ 通勤手当が「有」の場合は金額を入力してください",IF(AND(C29="無",N(C30)>0),"✕ 通勤手当が「無」なのに金額が入力されています",IF(AND(ISNUMBER(C30),ISNUMBER(C28),C30>C28),"✕ 通勤手当が報酬の額より大きくなっています",IF(N(C30)>150000,"△ 通勤手当が月15万円を超えています。確認してください",IF(AND(C31="数か月分一括支給",N35<>"",C30<>N35),"△ 一括支給の計算補助（下欄）の額と異なります","✓")))))) | L30: 「無」の場合は空欄。報酬の額に含めた通勤手当の額
B31: 通勤手当の支給方法（「有」の場合） | K31: =IF(AND(C29="有",C31=""),"✕ 未入力です（選択してください）","✓") | L31: 数か月分をまとめて支給された場合は下の計算補助を使います
B32: 【計算補助】一括支給された通勤手当の総額（円） | I32: 円 | K32: =IF(C31<>"数か月分一括支給","",IF(AND(C31="数か月分一括支給",OR(C32="",C33="",C34="")),"✕ 総額・月数・何か月目を入力してください",IF(AND(C31="数か月分一括支給",C34>C33),"✕ 請求月が月数より大きくなっています","✓"))) | L32: 一括支給のときだけ入力。1月当たり＝総額÷月数（端数は最終月に加算）
B33: 【計算補助】支給月数（か月分） | E33: か月
B34: 【計算補助】請求月は何か月目か | E34: か月目
B35: 【計算補助】1月当たりの通勤手当の額（自動） | C35: =IF(N35="","",N35) | N35: =IF(AND(C31="数か月分一括支給",ISNUMBER(C32),ISNUMBER(C33),ISNUMBER(C34),N(C33)>0,N(C34)<=N(C33)),IF(C34=C33,C32-INT(C32/C33)*(C33-1),INT(C32/C33)),"")
B36: ⑥ 請求日・請求者
B37: 請求日 | C37: 令和 | E37: 年 | G37: 月 | I37: 日 | K37: =IF(COUNTA(D37,F37,H37)=0,"✕ 未入力です",IF(N37="","✕ 年月日が正しくありません（存在しない日付など）",IF(AND(O7<>"",N37<=O7),"✕ 請求日が対象月の末日以前です",IF(N37>TODAY()+1,"△ 請求日が未来の日付です","✓")))) | L37: 提出する日（対象月の末日より後） | N37: =IF(COUNT(D37,F37,H37)<3,"",IFERROR(IF(AND(D37>=1,F37>=1,F37<=12,H37>=1,DAY(DATE(D37+2018,F37,H37))=H37),DATE(D37+2018,F37,H37),""),""))
B38: 請求者 氏名 | K38: =IF(C38="","✕ 未入力です",IF(SUBSTITUTE(SUBSTITUTE(C38," ","")," ","")<>SUBSTITUTE(SUBSTITUTE(C11," ","")," ",""),"△ 組合員氏名と異なります","✓")) | L38: 組合員本人の氏名
B39: 請求者 ℡（連絡先） | K39: =IF(C39="","✕ 未入力です",IF(SUMPRODUCT((ROW($1:$15)<=LEN(SUBSTITUTE(C39,"-","")))*(((MID(SUBSTITUTE(C39,"-",""),ROW($1:$15),1)<"0")+(MID(SUBSTITUTE(C39,"-",""),ROW($1:$15),1)>"9"))>0))>0,"✕ 半角の数字とハイフンで入力してください",IF(LEN(SUBSTITUTE(C39,"-",""))<4,"✕ 桁数が足りません","✓"))) | L39: 半角数字とハイフン 例：090-1234-5678
B40: 庶務担当 氏名 | K40: =IF(C40="","✕ 未入力です","✓") | L40: 所属の庶務担当者
...

Sheet 請求書(表)
A1: 育児時短勤務手当金請求書 （育児短時間勤務・部分休業）
V2: 令和 | X2: =IF(入力!D7="","",入力!D7) | AA2: 年 | AC2: =IF(入力!F7="","",入力!F7) | AF2: 月分 | AH2: 共済組合記入欄
AH3: 基幹
AH4: ﾃﾞｰﾀ
W5: 組合員等 記号番号
A6: フ リ ガ ナ | I6: =IF(入力!C10="","",入力!C10) | AB6: =IF(入力!C9="","",入力!C9) | AE6: ― | AF6: =IF(入力!F9="","",入力!F9)
A7: 組合員氏名 | I7: =IF(入力!C11="","",入力!C11)
R8: =IF(入力!C12="女","（女）・ 男",IF(入力!C12="男","女 ・（男）","女 ・ 男"))
A9: 生 年 月 日 | H9: =IF(入力!C13="昭和","（Ｓ）・ Ｈ",IF(入力!C13="平成","Ｓ ・（Ｈ）","Ｓ ・ Ｈ")) | L9: =IF(入力!D13="","",入力!D13) | N9: 年 | O9: =IF(入力!F13="","",入力!F13) | Q9: 月 | R9: =IF(入力!H13="","",入力!H13) | T9: 日 | W9: ☆個人番号
W10: （ﾏｲﾅﾝﾊﾞｰ）
A11: 所属機関 | H11: 名 称 | K11: =IF(入力!C15="","",入力!C15)
H13: 所在地 | K13: =IF(入力!C16="","",入力!C16)
A15: 育児短時間勤務 又は部分休業期間 | K15: 令和 | M15: =IF(入力!D20="","",入力!D20) | O15: 年 | Q15: =IF(入力!F20="","",入力!F20) | S15: 月 | U15: =IF(入力!H20="","",入力!H20) | W15: 日 | Y15: ～ | Z15: 令和 | AB15: =IF(入力!D21="","",入力!D21) | AD15: 年 | AF15: =IF(入力!F21="","",入力!F21) | AH15: 月 | AJ15: =IF(入力!H21="","",入力!H21) | AL15: 日
A16: 育児時短勤務手当金 請求期間 | K16: 令和 | M16: =IF(入力!D23="","",入力!D23) | O16: 年 | Q16: =IF(入力!F23="","",入力!F23) | S16: 月 | U16: =IF(入力!H23="","",入力!H23) | W16: 日 | Y16: ～ | Z16: 令和 | AB16: =IF(入力!D24="","",入力!D24) | AD16: 年 | AF16: =IF(入力!F24="","",入力!F24) | AH16: 月 | AJ16: =IF(入力!H24="","",入力!H24) | AL16: 日
A17: 育児時短勤務に係る子の 名前・生年月日 | K17: =IF(入力!C25="","",入力!C25) | V17: 令和 | X17: =IF(入力!D26="","",入力!D26) | AA17: 年 | AC17: =IF(入力!F26="","",入力!F26) | AF17: 月 | AH17: =IF(入力!H26="","",入力!H26) | AK17: 日
A18: ☆育児時短勤務開始時の 標準報酬月額 | K18: 第 級 円 | AA18: ☆決定額 円
A19: 支給対象月に支払われた 報酬の額 | N19: =IF(入力!C28="","",入力!C28) | Y19: 円（１月当たりの通勤手当の額を含む。）
A20: 通勤手当に対する 特記事項
K21: ="通勤手当：" & IF(入力!C29="有","（有）・ 無",IF(入力!C29="無","有 ・（無）","有 ・ 無")) & " （該当するものに〇で囲んでください。）"
K22: １月当たりの通勤手当の額： | X22: =IF(入力!C30="","",入力!C30) | AC22: 円
B25: 上記のとおり、請求します。 | Y25: 庶務担当 氏名・℡ | AE25: =IF(入力!C40="","",入力!C40) | AH25: ・ | AI25: =IF(入力!C41="","",入力!C41)
C26: 広島市職員共済組合理事長 様
E27: 令和 | G27: =IF(入力!D37="","",入力!D37) | I27: 年 | J27: =IF(入力!F37="","",入力!F37) | L27: 月 | M27: =IF(入力!H37="","",入力!H37) | O27: 日 | W27: =IF(入力!C38="","",入力!C38)
Q29: 請求者 | T29: 氏名
T31: ℡（連絡先） | Z31: =IF(入力!C39="","",入力!C39)
B34: 上記の記載事項（標準報酬の等級及び月額を除く）は、事実と相違ないことを確認しました。
E36: 令和 年 月 日
Q37: 所属機関の長 | W37: 職名
Q39: （任命権者） | W39: 氏名
A42: 添付書類 (添付し請求者がチェック（✓） してください。） | K42: 育児短時間勤務 | Y42: 部分休業
K43: =IF(入力!C43="✓","☑","□") | L43: 育児短時間勤務承認書（写） | Y43: =IF(入力!C48="✓","☑","□") | Z43: 部分休業承認請求書兼承認書（写）
K44: =IF(入力!C44="✓","☑","□") | L44: 出勤簿（写） | Z44: または庶務事務システム承認画面（ハードコピー）
K45: =IF(入力!C45="✓","☑","□") | L45: 支給明細書（写） | Y45: =IF(入力!C49="✓","☑","□") | Z45: 出勤簿（写）
K46: =IF(入力!C46="✓","☑","□") | L46: 通勤手当が数か月分一括支給された場合、 その額のわかる支給明細書（写） | Y46: =IF(入力!C50="✓","☑","□") | Z46: 支給明細書（写）
Y47: =IF(入力!C51="✓","☑","□") | Z47: 通勤手当が数か月分一括支給された場合、 その額のわかる支給明細書（写）
K48: =IF(入力!C47="✓","☑","□") | L48: 母子手帳等（写）（※初回請求時のみ）
Y49: =IF(入力!C52="✓","☑","□") | Z49: 母子手帳等（写）（※初回請求時のみ）
B50: ☆の項目は記入不要です。 | AL50: R7.11
A51: =IF(COUNTIF(入力!K6:K52,"✕*")>0,"※入力エラーがあります。入力シートを直してから印刷してください（このまま提出しないでください）","")

Sheet 請求書(裏)
C2: 注 意
B3: １ この請求書は、育児時短勤務を行った月経過後に、育児時短勤務を行った月ごと提出してください。
B4: ２ 「育児時短勤務手当金請求期間」欄の終期について、育児時短勤務に係る子が２歳に達することに より育児時短勤務手当金の支給が終了する場合には、当該子の２歳の誕生日の前々日を記載してくだ さい。新たに産前産後休業、介護休業又は育児休業を開始することにより支給が終了する場合には、 当該開始した日の前日を記載してください。
B6: ３ 「支給対象月に支払われた報酬の額」欄は、支給対象月に支払われた報酬（期末勤勉手当及び給与 改定差額を除く。）の額を記載してください。
B8: また、通勤手当が数か月分一括して支給される場合は、通勤手当額を支給月数で除して得た額を報 酬額に含めてください（端数は最終月に加算）。
B10: ４ 「通勤手当に対する特記事項」欄には、「支給対象月に支払われた報酬の額」に含めた通勤手当に ついて記載してください。
B12: ５ この請求には、次の書類を添付してください。
B13: （１）育児短時間勤務に関する所属機関の長の証明書の写し（育児短時間勤務をした場合）
B14: （２）部分休業承認請求書兼承認書（写）または庶務事務システム承認画面（ハードコピー）（部分休業をした場合）
B15: （３）支給対象月に育児時短勤務をしたことがわかる出勤簿の写し
B16: （４）支給対象月に支払われた報酬の額がわかる支給明細書の写し （通勤手当が数か月分一括して支給された場合は、当該支給額がわかる支給明細書の写しを含む。）
B18: （５）母子健康手帳（出生届出済証明の部分）、住民票記載事項証明書、戸籍謄本等、子との関係と 年齢がわかる書類の写し（初回請求時のみ）

Sheet 共済組合提出データ
A1: 職員番号 | B1: 対象年(令和) | C1: 対象月 | D1: 報酬額 | E1: 通勤手当有無 | F1: 通勤手当月額 | G1: 氏名 | H1: 組合員記号 | I1: 組合員番号 | J1: 勤務区分 | K1: 時短開始日 | L1: 時短終了日 | M1: 請求期間開始 | N1: 請求期間終了 | O1: 子の氏名 | P1: 子の生年月日 | Q1: 所属名称 | R1: 請求日 | S1: 初回請求 | T1: 入力エラー件数
A2: =IF(入力!C6="","",入力!C6) | B2: =IF(入力!D7="","",入力!D7) | C2: =IF(入力!F7="","",入力!F7) | D2: =IF(入力!C28="","",入力!C28) | E2: =IF(入力!C29="","",入力!C29) | F2: =IF(入力!C30="","",入力!C30) | G2: =IF(入力!C11="","",入力!C11) | H2: =IF(入力!C9="","",入力!C9) | I2: =IF(入力!F9="","",入力!F9) | J2: =IF(入力!C18="","",入力!C18) | K2: =IF(入力!N20="","",入力!N20) | L2: =IF(入力!N21="","",入力!N21) | M2: =IF(入力!N23="","",入力!N23) | N2: =IF(入力!N24="","",入力!N24) | O2: =IF(入力!C25="","",入力!C25) | P2: =IF(入力!N26="","",入力!N26) | Q2: =IF(入力!C15="","",入力!C15) | R2: =IF(入力!N37="","",入力!N37) | S2: =IF(入力!C19="","",入力!C19) | T2: =COUNTIF(入力!K6:K52,"✕*")
A4: 【共済組合の方へ】2行目（A2:T2）をコピーし、管理台帳の「請求記録」へ『値のみ貼り付け』してください（職員の方は触らないでください）。
