Workbook
Name 委託費: リスト!$G$4:$G$16
Name 減価償却費: リスト!$U$4
Name 交際費: リスト!$Q$4
Name 光熱水料: リスト!$H$4
Name 厚生費: リスト!$C$4
Name 構成組合交付金: リスト!$S$4
Name 雑費: リスト!$T$4
Name 支払利息: リスト!$W$4
Name 事務費: リスト!$E$4:$E$11
Name 修繕費: リスト!$I$4
Name 諸謝金: リスト!$M$4:$M$8
Name 消費税: リスト!$P$4
Name 職員給与: リスト!$B$4:$B$8
Name 食糧費: リスト!$N$4
Name 選挙費: リスト!$R$4
Name 中項目: リスト!$A$3:$Y$3
Name 調査研究費: リスト!$K$4:$K$13
Name 賃金: リスト!$F$4
Name 賃借料: リスト!$J$4:$J$10
Name 特別修繕引当金繰入: リスト!$V$4
Name 普及費: リスト!$L$4:$L$8
Name 負担金: リスト!$O$4:$O$12
Name 旅費: リスト!$D$4:$D$6
Name 年度: '月次締め'!$C$4
Name 締月: '月次締め'!$C$6
Name 月初: '月次締め'!$C$7
Name 翌月初: '月次締め'!$D$7
Name 中項目・小項目: リスト!$A$3:$W$3
Name 役員報酬: リスト!$A$4:$A$6
Name 中項目・小項目: リスト!$A$3:$W$3
Name 役員報酬: リスト!$A$4:$A$6

Sheet 使い方
A1: 令和8年度 業務経理区分別執行管理簿（統合版） 使い方
A2: 元の「業務経理区分別執行管理簿」「貸付予算差引簿」「費用収益表」を1つにまとめました。シートの様式は元のままで、転記を自動にしています。
B4: 転記の流れ（すべて自動）
B5: ① 入力 | C5: 業務：「月例」に支払を入力（決算整理＝未払金は「決算整理」シート）。貸付：「貸付予算差引簿」の各費目に入力。 | D5: 入力するのは黄色のセルだけ
B6: ② 差引簿へ | C6: 「予算差引簿（短）」「予算差引簿（長）」へ、費目ごとに日付・摘要・金額が自動で転記されます。決算整理の分は「…未払」シートへ。 | D6: 人件費（非常勤職員手当・賃金）など全ての費目
B7: ③ 月別合計 | C7: 「差引簿集計（短）（長）」「貸付差引簿集計」で、費目ごとの月別合計が自動で出ます。 | D7: 確認済の分だけを集計
B8: ④ 費用収益表へ | C8: 費用収益表の各費目・各月へ自動で入ります。「月次締め」の「今回締める月」までが確定表示、それ以降は前年実績・見込（緑字）。 | D8: 手で転記する必要はありません
B10: 毎月の作業
B11: 支払担当者 | C11: 昨年実績の行を今年の支払に直し（日付・摘要・金額）、状態を「昨年実績」→「未確認」へ。 | D11: 旧：赤字を黒字にして金額を修正
B12: 経理担当者 | C12: 支払伝票が回ってきたら状態を「未確認」→「確認済」へ（プルダウン）。 | D12: 旧：金額を青く塗りつぶし
B13: 経理〆 | C13: 「月次締め」で今回締める月を選び、仮締め出納計算表の月合計を黄色セルに入力。差額0で OK。「検算」シートが全部 OK ならこのブックの数字は一致しています。
B15: 色のルール
B16: 黄色のセル | C16: 手入力するセル。それ以外は数式なので触りません。マクロ版（.xlsm）ではEnterで次の黄色セルへ移動します。
B17: 赤字 | C17: 状態＝昨年実績（今年の支払が確定するまで残す行）。
B18: 青字（月例）／水色の背景（差引簿の支出） | C18: 状態＝確認済。
B19: オレンジの背景（差引簿の支出） | C19: 状態＝未確認。
B20: 取り消し線（月例） | C20: 状態＝支払なし（今年度は支払がない行。差引簿・集計から除外）。
B22: 追加した列・シート（元の様式への追加）
B23: 月例・決算整理 P〜U列 | C23: P＝状態（入力）。Q〜U＝自動計算の作業列（費目・長期額・差引簿への通番・計上列）。消さないでください。
B24: 予算差引簿の「状態」列 | C24: 各ブロックの右端。月例の状態が自動で表示されます。
B25: 貸付予算差引簿の「状態」列 | C25: 各ブロックの右端（入力）。
B26: 差引簿のブロックの大きさ | C26: 行数は余裕を持たせてあります。足りなくなると見出しの右に赤字で「行不足」と出ます。

Sheet 月次締め
A1: 月次締め 操作盤と出納計算表との照合
A2: 月次〆のときは「今回締める月」を選ぶだけです。費用収益表がその月まで自動で確定表示になります（転記は不要）。黄色のセルに仮締めした出納計算表の月合計を入力し、差額が 0 になればOKです。
B4: 年度（令和） | C4: ='R7業務（長+短）'!E1 -> 8 | D4: ← 費用収益表（長+短）の年度から | F4: 自動検算 | G4: =IF(検算!$F$3=0,"すべてOK","NG "&検算!$F$3&"件（検算シート参照）") -> すべてOK
B5: 今回締める月 | C5: 9月 | D5: ← ここを変えると、その月まで費用収益表に確定計上されます（9月締め済みなら「9月」）
B6: 月番号（自動） | C6: =MATCH($C$5,科目表!$N$5:$N$18,0)-1 -> 6
B7: 対象月の開始日／翌月初（自動） | C7: =IF(締月=0,0,IF(締月=13,DATE(年度+2019,4,1),DATE(年度+2018+IF(締月>9,1,0),MOD(締月+2,12)+1,1))) -> 46266 | D7: =EDATE(C7,1) -> 46296
B9: ① 締める前のチェック（今回締める月の分）
B10: 項目 | C10: 業務 | D10: 貸付 | E10: 対応
B11: 確認済の件数 | C11: =IF(締月=0,0,COUNTIFS(月例!$U$5:$U$788,締月,月例!$P$5:$P$788,"確認済")+COUNTIFS(決算整理!$U$5:$U$1835,締月,決算整理!$P$5:$P$1835,"確認済")) -> 35 | D11: =IF(締月=0,0,COUNTIFS('旅費・事務費（消耗品・図書・通信・会議・雑費）R８'!$E$6:$E$25,"確認済",'旅費・事務費（消耗品・図書・通信・会議・雑費）R８'!$A$6:$A$25,">="&月初,'旅費・事務費（消耗品・図書・通信・会議・雑費）R８'!$A$6:$A$25,"<"&翌月初)+COUNTIFS('旅費・事務費（消耗品・図書・通信・会議・雑費）R８'!$E$29:$E$31,"確認済",'旅費・事務費（消耗品・図書・通信・会議・雑費）R８'!$A$29:$A$31,">="&月初,'旅費・事務費（消耗品・図書・通信・会議・雑費）R８'!$A$29:$A$31,"<"&翌月初)+COUNTIFS('旅費・事務費（消耗品・図書・通信・会議・雑費）R８'!$E$35:$E$67,"確認済",'旅費・事務費（消耗品・図書・通信・会議・雑費）R８'!$A$35:$A$67,">="&月初,'旅費・事務費（消耗品・図書・通信・会議・雑費）R８'!$A$35:$A$67,"<"&翌月初)+COUNTIFS('旅費・事務費（消耗品・図書・通信・会議・雑費）R８'!$J$6:$J$23,"確認済",'旅費・事務費（消耗品・図書・通信・会議・雑費）R８'!$F$6:$F$23,">="&月初,'旅費・事務費（消耗品・図書・通信・会議・雑費）R８'!$F$6:$F$23,"<"&翌月初)+COUNTIFS('旅費・事務費（消耗品・図書・通信・会議・雑費）R８'!$J$46:$J$67,"確認済",'旅費・事務費（消耗品・図書・通信・会議・雑費）R８'!$F$46:$F$67,">="&月初,'旅費・事務費（消耗品・図書・通信・会議・雑費）R８'!$F$46:$F$67,"<"&翌月初)+COUNTIFS('旅費・事務費（消耗品・図書・通信・会議・雑費）R８'!$J$27:$J$42,"確認済",'旅費・事務費（消耗品・図書・通信・会議・雑費）R８'!$F$27:$F$42,">="&月初,'旅費・事務費（消耗品・図書・通信・会議・雑費）R８'!$F$27:$F$42,"<"&翌月初)+COUNTIFS('旅費・事務費以外R８'!$E$29:$E$33,"確認済",'旅費・事務費以外R８'!$A$29:$A$33,">="&月初,'旅費・事務費以外R８'!$A$29:$A$33,"<"&翌月初)+COUNTIFS('旅費・事務費以外R８'!$E$6:$E$14,"確認済",'旅費・事務費以外R８'!$A$6:$A$14,">="&月初,'旅費・事務費以外R８'!$A$6:$A$14,"<"&翌月初)+COUNTIFS('旅費・事務費以外R８'!$E$18:$E$25,"確認済",'旅費・事務費以外R８'!$A$18:$A$25,">="&月初,'旅費・事務費以外R８'!$A$18:$A$25,"<"&翌月初)+COUNTIFS('旅費・事務費以外R８'!$E$37:$E$86,"確認済",'旅費・事務費以外R８'!$A$37:$A$86,">="&月初,'旅費・事務費以外R８'!$A$37:$A$86,"<"&翌月初)+COUNTIFS('旅費・事務費以外R８'!$J$6:$J$13,"確認済",'旅費・事務費以外R８'!$F$6:$F$13,">="&月初,'旅費・事務費以外R８'!$F$6:$F$13,"<"&翌月初)+COUNTIFS('旅費・事務費以外R８'!$J$26:$J$31,"確認済",'旅費・事務費以外R８'!$F$26:$F$31,">="&月初,'旅費・事務費以外R８'!$F$26:$F$31,"<"&翌月初)+COUNTIFS('旅費・事務費以外R８'!$J$45:$J$86,"確認済",'旅費・事務費以外R８'!$F$45:$F$86,">="&月初,'旅費・事務費以外R８'!$F$45:$F$86,"<"&翌月初)+COUNTIFS('旅費・事務費以外R８'!$J$35:$J$41,"確認済",'旅費・事務費以外R８'!$F$35:$F$41,">="&月初,'旅費・事務費以外R８'!$F$35:$F$41,"<"&翌月初)) -> 5 | E11: 差引簿・費用収益表に計上される行数
B12: 未確認（伝票待ち）の件数 | C12: =IF(締月=0,0,COUNTIFS(月例!$U$5:$U$788,締月,月例!$P$5:$P$788,"未確認")+COUNTIFS(決算整理!$U$5:$U$1835,締月,決算整理!$P$5:$P$1835,"未確認")) -> 0 | D12: =IF(締月=0,0,COUNTIFS('旅費・事務費（消耗品・図書・通信・会議・雑費）R８'!$E$6:$E$25,"未確認",'旅費・事務費（消耗品・図書・通信・会議・雑費）R８'!$A$6:$A$25,">="&月初,'旅費・事務費（消耗品・図書・通信・会議・雑費）R８'!$A$6:$A$25,"<"&翌月初)+COUNTIFS('旅費・事務費（消耗品・図書・通信・会議・雑費）R８'!$E$29:$E$31,"未確認",'旅費・事務費（消耗品・図書・通信・会議・雑費）R８'!$A$29:$A$31,">="&月初,'旅費・事務費（消耗品・図書・通信・会議・雑費）R８'!$A$29:$A$31,"<"&翌月初)+COUNTIFS('旅費・事務費（消耗品・図書・通信・会議・雑費）R８'!$E$35:$E$67,"未確認",'旅費・事務費（消耗品・図書・通信・会議・雑費）R８'!$A$35:$A$67,">="&月初,'旅費・事務費（消耗品・図書・通信・会議・雑費）R８'!$A$35:$A$67,"<"&翌月初)+COUNTIFS('旅費・事務費（消耗品・図書・通信・会議・雑費）R８'!$J$6:$J$23,"未確認",'旅費・事務費（消耗品・図書・通信・会議・雑費）R８'!$F$6:$F$23,">="&月初,'旅費・事務費（消耗品・図書・通信・会議・雑費）R８'!$F$6:$F$23,"<"&翌月初)+COUNTIFS('旅費・事務費（消耗品・図書・通信・会議・雑費）R８'!$J$46:$J$67,"未確認",'旅費・事務費（消耗品・図書・通信・会議・雑費）R８'!$F$46:$F$67,">="&月初,'旅費・事務費（消耗品・図書・通信・会議・雑費）R８'!$F$46:$F$67,"<"&翌月初)+COUNTIFS('旅費・事務費（消耗品・図書・通信・会議・雑費）R８'!$J$27:$J$42,"未確認",'旅費・事務費（消耗品・図書・通信・会議・雑費）R８'!$F$27:$F$42,">="&月初,'旅費・事務費（消耗品・図書・通信・会議・雑費）R８'!$F$27:$F$42,"<"&翌月初)+COUNTIFS('旅費・事務費以外R８'!$E$29:$E$33,"未確認",'旅費・事務費以外R８'!$A$29:$A$33,">="&月初,'旅費・事務費以外R８'!$A$29:$A$33,"<"&翌月初)+COUNTIFS('旅費・事務費以外R８'!$E$6:$E$14,"未確認",'旅費・事務費以外R８'!$A$6:$A$14,">="&月初,'旅費・事務費以外R８'!$A$6:$A$14,"<"&翌月初)+COUNTIFS('旅費・事務費以外R８'!$E$18:$E$25,"未確認",'旅費・事務費以外R８'!$A$18:$A$25,">="&月初,'旅費・事務費以外R８'!$A$18:$A$25,"<"&翌月初)+COUNTIFS('旅費・事務費以外R８'!$E$37:$E$86,"未確認",'旅費・事務費以外R８'!$A$37:$A$86,">="&月初,'旅費・事務費以外R８'!$A$37:$A$86,"<"&翌月初)+COUNTIFS('旅費・事務費以外R８'!$J$6:$J$13,"未確認",'旅費・事務費以外R８'!$F$6:$F$13,">="&月初,'旅費・事務費以外R８'!$F$6:$F$13,"<"&翌月初)+COUNTIFS('旅費・事務費以外R８'!$J$26:$J$31,"未確認",'旅費・事務費以外R８'!$F$26:$F$31,">="&月初,'旅費・事務費以外R８'!$F$26:$F$31,"<"&翌月初)+COUNTIFS('旅費・事務費以外R８'!$J$45:$J$86,"未確認",'旅費・事務費以外R８'!$F$45:$F$86,">="&月初,'旅費・事務費以外R８'!$F$45:$F$86,"<"&翌月初)+COUNTIFS('旅費・事務費以外R８'!$J$35:$J$41,"未確認",'旅費・事務費以外R８'!$F$35:$F$41,">="&月初,'旅費・事務費以外R８'!$F$35:$F$41,"<"&翌月初)) -> 0 | E12: 0 にしてから締めます（伝票を確認して「確認済」へ）
B13: 昨年実績のまま残っている件数（参考） | C13: =IF(締月=0,0,COUNTIFS(月例!$U$5:$U$788,締月,月例!$P$5:$P$788,"昨年実績")+COUNTIFS(決算整理!$U$5:$U$1835,締月,決算整理!$P$5:$P$1835,"昨年実績")) -> 22 | D13: =IF(締月=0,0,COUNTIFS('旅費・事務費（消耗品・図書・通信・会議・雑費）R８'!$E$6:$E$25,"昨年実績",'旅費・事務費（消耗品・図書・通信・会議・雑費）R８'!$A$6:$A$25,">="&月初,'旅費・事務費（消耗品・図書・通信・会議・雑費）R８'!$A$6:$A$25,"<"&翌月初)+COUNTIFS('旅費・事務費（消耗品・図書・通信・会議・雑費）R８'!$E$29:$E$31,"昨年実績",'旅費・事務費（消耗品・図書・通信・会議・雑費）R８'!$A$29:$A$31,">="&月初,'旅費・事務費（消耗品・図書・通信・会議・雑費）R８'!$A$29:$A$31,"<"&翌月初)+COUNTIFS('旅費・事務費（消耗品・図書・通信・会議・雑費）R８'!$E$35:$E$67,"昨年実績",'旅費・事務費（消耗品・図書・通信・会議・雑費）R８'!$A$35:$A$67,">="&月初,'旅費・事務費（消耗品・図書・通信・会議・雑費）R８'!$A$35:$A$67,"<"&翌月初)+COUNTIFS('旅費・事務費（消耗品・図書・通信・会議・雑費）R８'!$J$6:$J$23,"昨年実績",'旅費・事務費（消耗品・図書・通信・会議・雑費）R８'!$F$6:$F$23,">="&月初,'旅費・事務費（消耗品・図書・通信・会議・雑費）R８'!$F$6:$F$23,"<"&翌月初)+COUNTIFS('旅費・事務費（消耗品・図書・通信・会議・雑費）R８'!$J$46:$J$67,"昨年実績",'旅費・事務費（消耗品・図書・通信・会議・雑費）R８'!$F$46:$F$67,">="&月初,'旅費・事務費（消耗品・図書・通信・会議・雑費）R８'!$F$46:$F$67,"<"&翌月初)+COUNTIFS('旅費・事務費（消耗品・図書・通信・会議・雑費）R８'!$J$27:$J$42,"昨年実績",'旅費・事務費（消耗品・図書・通信・会議・雑費）R８'!$F$27:$F$42,">="&月初,'旅費・事務費（消耗品・図書・通信・会議・雑費）R８'!$F$27:$F$42,"<"&翌月初)+COUNTIFS('旅費・事務費以外R８'!$E$29:$E$33,"昨年実績",'旅費・事務費以外R８'!$A$29:$A$33,">="&月初,'旅費・事務費以外R８'!$A$29:$A$33,"<"&翌月初)+COUNTIFS('旅費・事務費以外R８'!$E$6:$E$14,"昨年実績",'旅費・事務費以外R８'!$A$6:$A$14,">="&月初,'旅費・事務費以外R８'!$A$6:$A$14,"<"&翌月初)+COUNTIFS('旅費・事務費以外R８'!$E$18:$E$25,"昨年実績",'旅費・事務費以外R８'!$A$18:$A$25,">="&月初,'旅費・事務費以外R８'!$A$18:$A$25,"<"&翌月初)+COUNTIFS('旅費・事務費以外R８'!$E$37:$E$86,"昨年実績",'旅費・事務費以外R８'!$A$37:$A$86,">="&月初,'旅費・事務費以外R８'!$A$37:$A$86,"<"&翌月初)+COUNTIFS('旅費・事務費以外R８'!$J$6:$J$13,"昨年実績",'旅費・事務費以外R８'!$F$6:$F$13,">="&月初,'旅費・事務費以外R８'!$F$6:$F$13,"<"&翌月初)+COUNTIFS('旅費・事務費以外R８'!$J$26:$J$31,"昨年実績",'旅費・事務費以外R８'!$F$26:$F$31,">="&月初,'旅費・事務費以外R８'!$F$26:$F$31,"<"&翌月初)+COUNTIFS('旅費・事務費以外R８'!$J$45:$J$86,"昨年実績",'旅費・事務費以外R８'!$F$45:$F$86,">="&月初,'旅費・事務費以外R８'!$F$45:$F$86,"<"&翌月初)+COUNTIFS('旅費・事務費以外R８'!$J$35:$J$41,"昨年実績",'旅費・事務費以外R８'!$F$35:$F$41,">="&月初,'旅費・事務費以外R８'!$F$35:$F$41,"<"&翌月初)) -> 0 | E13: 今年は支払がない行は「支払なし」にすると見やすくなります
B14: 点検NGの件数 | C14: =COUNTIF(月例!$Q$5:$Q$788,"※未登録")+COUNTIF(決算整理!$Q$5:$Q$1835,"※未登録")+COUNTIF('差引簿集計（短）'!$T$4:$T$80,"行不足")+COUNTIF('差引簿集計（長）'!$T$4:$T$80,"行不足") -> 0 | D14: =COUNTIFS('旅費・事務費（消耗品・図書・通信・会議・雑費）R８'!$A$6:$A$25,">0",'旅費・事務費（消耗品・図書・通信・会議・雑費）R８'!$E$6:$E$25,"")+COUNTIFS('旅費・事務費（消耗品・図書・通信・会議・雑費）R８'!$A$29:$A$31,">0",'旅費・事務費（消耗品・図書・通信・会議・雑費）R８'!$E$29:$E$31,"")+COUNTIFS('旅費・事務費（消耗品・図書・通信・会議・雑費）R８'!$A$35:$A$67,">0",'旅費・事務費（消耗品・図書・通信・会議・雑費）R８'!$E$35:$E$67,"")+COUNTIFS('旅費・事務費（消耗品・図書・通信・会議・雑費）R８'!$F$6:$F$23,">0",'旅費・事務費（消耗品・図書・通信・会議・雑費）R８'!$J$6:$J$23,"")+COUNTIFS('旅費・事務費（消耗品・図書・通信・会議・雑費）R８'!$F$46:$F$67,">0",'旅費・事務費（消耗品・図書・通信・会議・雑費）R８'!$J$46:$J$67,"")+COUNTIFS('旅費・事務費（消耗品・図書・通信・会議・雑費）R８'!$F$27:$F$42,">0",'旅費・事務費（消耗品・図書・通信・会議・雑費）R８'!$J$27:$J$42,"")+COUNTIFS('旅費・事務費以外R８'!$A$29:$A$33,">0",'旅費・事務費以外R８'!$E$29:$E$33,"")+COUNTIFS('旅費・事務費以外R８'!$A$6:$A$14,">0",'旅費・事務費以外R８'!$E$6:$E$14,"")+COUNTIFS('旅費・事務費以外R８'!$A$18:$A$25,">0",'旅費・事務費以外R８'!$E$18:$E$25,"")+COUNTIFS('旅費・事務費以外R８'!$A$37:$A$86,">0",'旅費・事務費以外R８'!$E$37:$E$86,"")+COUNTIFS('旅費・事務費以外R８'!$F$6:$F$13,">0",'旅費・事務費以外R８'!$J$6:$J$13,"")+COUNTIFS('旅費・事務費以外R８'!$F$26:$F$31,">0",'旅費・事務費以外R８'!$J$26:$J$31,"")+COUNTIFS('旅費・事務費以外R８'!$F$45:$F$86,">0",'旅費・事務費以外R８'!$J$45:$J$86,"")+COUNTIFS('旅費・事務費以外R８'!$F$35:$F$41,">0",'旅費・事務費以外R８'!$J$35:$J$41,"") -> 0 | E14: 費目未登録・差引簿の行不足・状態未設定
B15: 確認済 金額合計 | C15: =IF(締月=0,0,SUMIFS(月例!$F$5:$F$788,月例!$U$5:$U$788,締月,月例!$P$5:$P$788,"確認済")+SUMIFS(決算整理!$F$5:$F$1835,決算整理!$U$5:$U$1835,締月,決算整理!$P$5:$P$1835,"確認済")) -> 30634243 | D15: =IF(締月=0,0,SUMIFS('旅費・事務費（消耗品・図書・通信・会議・雑費）R８'!$C$6:$C$25,'旅費・事務費（消耗品・図書・通信・会議・雑費）R８'!$E$6:$E$25,"確認済",'旅費・事務費（消耗品・図書・通信・会議・雑費）R８'!$A$6:$A$25,">="&月初,'旅費・事務費（消耗品・図書・通信・会議・雑費）R８'!$A$6:$A$25,"<"&翌月初)+SUMIFS('旅費・事務費（消耗品・図書・通信・会議・雑費）R８'!$C$29:$C$31,'旅費・事務費（消耗品・図書・通信・会議・雑費）R８'!$E$29:$E$31,"確認済",'旅費・事務費（消耗品・図書・通信・会議・雑費）R８'!$A$29:$A$31,">="&月初,'旅費・事務費（消耗品・図書・通信・会議・雑費）R８'!$A$29:$A$31,"<"&翌月初)+SUMIFS('旅費・事務費（消耗品・図書・通信・会議・雑費）R８'!$C$35:$C$67,'旅費・事務費（消耗品・図書・通信・会議・雑費）R８'!$E$35:$E$67,"確認済",'旅費・事務費（消耗品・図書・通信・会議・雑費）R８'!$A$35:$A$67,">="&月初,'旅費・事務費（消耗品・図書・通信・会議・雑費）R８'!$A$35:$A$67,"<"&翌月初)+SUMIFS('旅費・事務費（消耗品・図書・通信・会議・雑費）R８'!$H$6:$H$23,'旅費・事務費（消耗品・図書・通信・会議・雑費）R８'!$J$6:$J$23,"確認済",'旅費・事務費（消耗品・図書・通信・会議・雑費）R８'!$F$6:$F$23,">="&月初,'旅費・事務費（消耗品・図書・通信・会議・雑費）R８'!$F$6:$F$23,"<"&翌月初)+SUMIFS('旅費・事務費（消耗品・図書・通信・会議・雑費）R８'!$H$46:$H$67,'旅費・事務費（消耗品・図書・通信・会議・雑費）R８'!$J$46:$J$67,"確認済",'旅費・事務費（消耗品・図書・通信・会議・雑費）R８'!$F$46:$F$67,">="&月初,'旅費・事務費（消耗品・図書・通信・会議・雑費）R８'!$F$46:$F$67,"<"&翌月初)+SUMIFS('旅費・事務費（消耗品・図書・通信・会議・雑費）R８'!$H$27:$H$42,'旅費・事務費（消耗品・図書・通信・会議・雑費）R８'!$J$27:$J$42,"確認済",'旅費・事務費（消耗品・図書・通信・会議・雑費）R８'!$F$27:$F$42,">="&月初,'旅費・事務費（消耗品・図書・通信・会議・雑費）R８'!$F$27:$F$42,"<"&翌月初)+SUMIFS('旅費・事務費以外R８'!$C$29:$C$33,'旅費・事務費以外R８'!$E$29:$E$33,"確認済",'旅費・事務費以外R８'!$A$29:$A$33,">="&月初,'旅費・事務費以外R８'!$A$29:$A$33,"<"&翌月初)+SUMIFS('旅費・事務費以外R８'!$C$6:$C$14,'旅費・事務費以外R８'!$E$6:$E$14,"確認済",'旅費・事務費以外R８'!$A$6:$A$14,">="&月初,'旅費・事務費以外R８'!$A$6:$A$14,"<"&翌月初)+SUMIFS('旅費・事務費以外R８'!$C$18:$C$25,'旅費・事務費以外R８'!$E$18:$E$25,"確認済",'旅費・事務費以外R８'!$A$18:$A$25,">="&月初,'旅費・事務費以外R８'!$A$18:$A$25,"<"&翌月初)+SUMIFS('旅費・事務費以外R８'!$C$37:$C$86,'旅費・事務費以外R８'!$E$37:$E$86,"確認済",'旅費・事務費以外R８'!$A$37:$A$86,">="&月初,'旅費・事務費以外R８'!$A$37:$A$86,"<"&翌月初)+SUMIFS('旅費・事務費以外R８'!$H$6:$H$13,'旅費・事務費以外R８'!$J$6:$J$13,"確認済",'旅費・事務費以外R８'!$F$6:$F$13,">="&月初,'旅費・事務費以外R８'!$F$6:$F$13,"<"&翌月初)+SUMIFS('旅費・事務費以外R８'!$H$26:$H$31,'旅費・事務費以外R８'!$J$26:$J$31,"確認済",'旅費・事務費以外R８'!$F$26:$F$31,">="&月初,'旅費・事務費以外R８'!$F$26:$F$31,"<"&翌月初)+SUMIFS('旅費・事務費以外R８'!$H$45:$H$86,'旅費・事務費以外R８'!$J$45:$J$86,"確認済",'旅費・事務費以外R８'!$F$45:$F$86,">="&月初,'旅費・事務費以外R８'!$F$45:$F$86,"<"&翌月初)+SUMIFS('旅費・事務費以外R８'!$H$35:$H$41,'旅費・事務費以外R８'!$J$35:$J$41,"確認済",'旅費・事務費以外R８'!$F$35:$F$41,">="&月初,'旅費・事務費以外R８'!$F$35:$F$41,"<"&翌月初)) -> 254511 | E15: 業務は短期＋長期の合計（月例＋決算整理）
B16: 締め可否 | C16: =IF(締月=0,"-",IF(AND(C12=0,C14=0),"OK","要対応")) -> OK | D16: =IF(締月=0,"-",IF(AND(D12=0,D14=0),"OK","要対応")) -> OK
B19: ② 出納計算表との照合（黄色のセルに仮締めした出納計算表の月合計を入力）
B21: 業務経理（短期）
B22: 月 | C22: 費用 | F22: 収益 | I22: 判定
C23: 費用収益表 | D23: 出納計算表 | E23: 差額 | F23: 費用収益表 | G23: 出納計算表 | H23: 差額
B24: 4月 | C24: ='R7業務 (短)'!C38 -> 534591 | E24: =IF(D24="","",C24-D24) | F24: ='R7業務 (短)'!C46 -> 2268000 | H24: =IF(G24="","",F24-G24) | I24: =IF(1>締月,"",IF(OR(D24="",G24=""),"出納計算表 未入力",IF(AND(E24=0,H24=0),"OK","NG 差額あり"))) -> 出納計算表 未入力
B25: 5月 | C25: ='R7業務 (短)'!D38 -> 4087081 | E25: =IF(D25="","",C25-D25) | F25: ='R7業務 (短)'!D46 -> 2150000 | H25: =IF(G25="","",F25-G25) | I25: =IF(2>締月,"",IF(OR(D25="",G25=""),"出納計算表 未入力",IF(AND(E25=0,H25=0),"OK","NG 差額あり"))) -> 出納計算表 未入力
B26: 6月 | C26: ='R7業務 (短)'!E38 -> 2455166 | E26: =IF(D26="","",C26-D26) | F26: ='R7業務 (短)'!E46 -> 2609000 | H26: =IF(G26="","",F26-G26) | I26: =IF(3>締月,"",IF(OR(D26="",G26=""),"出納計算表 未入力",IF(AND(E26=0,H26=0),"OK","NG 差額あり"))) -> 出納計算表 未入力
B27: 7月 | C27: ='R7業務 (短)'!F38 -> 1972276 | E27: =IF(D27="","",C27-D27) | F27: ='R7業務 (短)'!F46 -> 2725000 | H27: =IF(G27="","",F27-G27) | I27: =IF(4>締月,"",IF(OR(D27="",G27=""),"出納計算表 未入力",IF(AND(E27=0,H27=0),"OK","NG 差額あり"))) -> 出納計算表 未入力
B28: 8月 | C28: ='R7業務 (短)'!G38 -> 2709341 | E28: =IF(D28="","",C28-D28) | F28: ='R7業務 (短)'!G46 -> 2151000 | H28: =IF(G28="","",F28-G28) | I28: =IF(5>締月,"",IF(OR(D28="",G28=""),"出納計算表 未入力",IF(AND(E28=0,H28=0),"OK","NG 差額あり"))) -> 出納計算表 未入力
B29: 9月 | C29: ='R7業務 (短)'!H38 -> 24070375 | E29: =IF(D29="","",C29-D29) | F29: ='R7業務 (短)'!H46 -> 12794000 | H29: =IF(G29="","",F29-G29) | I29: =IF(6>締月,"",IF(OR(D29="",G29=""),"出納計算表 未入力",IF(AND(E29=0,H29=0),"OK","NG 差額あり"))) -> 出納計算表 未入力
B30: 10月 | C30: ='R7業務 (短)'!I38 -> 2454418 | E30: =IF(D30="","",C30-D30) | F30: ='R7業務 (短)'!I46 -> 2477000 | H30: =IF(G30="","",F30-G30) | I30: =IF(7>締月,"",IF(OR(D30="",G30=""),"出納計算表 未入力",IF(AND(E30=0,H30=0),"OK","NG 差額あり")))
B31: 11月 | C31: ='R7業務 (短)'!J38 -> 2501632 | E31: =IF(D31="","",C31-D31) | F31: ='R7業務 (短)'!J46 -> 2228000 | H31: =IF(G31="","",F31-G31) | I31: =IF(8>締月,"",IF(OR(D31="",G31=""),"出納計算表 未入力",IF(AND(E31=0,H31=0),"OK","NG 差額あり")))
B32: 12月 | C32: ='R7業務 (短)'!K38 -> 5009376 | E32: =IF(D32="","",C32-D32) | F32: ='R7業務 (短)'!K46 -> 2894000 | H32: =IF(G32="","",F32-G32) | I32: =IF(9>締月,"",IF(OR(D32="",G32=""),"出納計算表 未入力",IF(AND(E32=0,H32=0),"OK","NG 差額あり")))
B33: 1月 | C33: ='R7業務 (短)'!L38 -> 2079276 | E33: =IF(D33="","",C33-D33) | F33: ='R7業務 (短)'!L46 -> 2560000 | H33: =IF(G33="","",F33-G33) | I33: =IF(10>締月,"",IF(OR(D33="",G33=""),"出納計算表 未入力",IF(AND(E33=0,H33=0),"OK","NG 差額あり")))
B34: 2月 | C34: ='R7業務 (短)'!M38 -> 2212970 | E34: =IF(D34="","",C34-D34) | F34: ='R7業務 (短)'!M46 -> 2209000 | H34: =IF(G34="","",F34-G34) | I34: =IF(11>締月,"",IF(OR(D34="",G34=""),"出納計算表 未入力",IF(AND(E34=0,H34=0),"OK","NG 差額あり")))
B35: 3月 | C35: ='R7業務 (短)'!N38 -> 2135536 | E35: =IF(D35="","",C35-D35) | F35: ='R7業務 (短)'!N46 -> 3606000 | H35: =IF(G35="","",F35-G35) | I35: =IF(12>締月,"",IF(OR(D35="",G35=""),"出納計算表 未入力",IF(AND(E35=0,H35=0),"OK","NG 差額あり")))
B36: 4月(未払) | C36: ='R7業務 (短)'!O38 -> 3204092 | E36: =IF(D36="","",C36-D36) | F36: ='R7業務 (短)'!O46 -> 9655506 | H36: =IF(G36="","",F36-G36) | I36: =IF(13>締月,"",IF(OR(D36="",G36=""),"出納計算表 未入力",IF(AND(E36=0,H36=0),"OK","NG 差額あり")))
B37: 締め月までの合計 | C37: =SUMPRODUCT((ROW(C24:C36)-24+1<=締月)*C24:C36) -> 35828830 | D37: =SUMPRODUCT((ROW(D24:D36)-24+1<=締月)*D24:D36) -> 0 | E37: =C37-D37 -> 35828830 | F37: =SUMPRODUCT((ROW(F24:F36)-24+1<=締月)*F24:F36) -> 24697000 | G37: =SUMPRODUCT((ROW(G24:G36)-24+1<=締月)*G24:G36) -> 0 | H37: =F37-G37 -> 24697000
B39: 業務経理（長期）
B40: 月 | C40: 費用 | F40: 収益 | I40: 判定
C41: 費用収益表 | D41: 出納計算表 | E41: 差額 | F41: 費用収益表 | G41: 出納計算表 | H41: 差額
B42: 4月 | C42: ='R7業務（長）'!C38 -> 412079 | E42: =IF(D42="","",C42-D42) | F42: ='R7業務（長）'!C46 -> 4513000 | H42: =IF(G42="","",F42-G42) | I42: =IF(1>締月,"",IF(OR(D42="",G42=""),"出納計算表 未入力",IF(AND(E42=0,H42=0),"OK","NG 差額あり"))) -> 出納計算表 未入力
B43: 5月 | C43: ='R7業務（長）'!D38 -> 6019213 | E43: =IF(D43="","",C43-D43) | F43: ='R7業務（長）'!D46 -> 9026000 | H43: =IF(G43="","",F43-G43) | I43: =IF(2>締月,"",IF(OR(D43="",G43=""),"出納計算表 未入力",IF(AND(E43=0,H43=0),"OK","NG 差額あり"))) -> 出納計算表 未入力
B44: 6月 | C44: ='R7業務（長）'!E38 -> 6989919 | E44: =IF(D44="","",C44-D44) | F44: ='R7業務（長）'!E46 -> 10732000 | H44: =IF(G44="","",F44-G44) | I44: =IF(3>締月,"",IF(OR(D44="",G44=""),"出納計算表 未入力",IF(AND(E44=0,H44=0),"OK","NG 差額あり"))) -> 出納計算表 未入力
B45: 7月 | C45: ='R7業務（長）'!F38 -> 7671974 | E45: =IF(D45="","",C45-D45) | F45: ='R7業務（長）'!F46 -> 13189000 | H45: =IF(G45="","",F45-G45) | I45: =IF(4>締月,"",IF(OR(D45="",G45=""),"出納計算表 未入力",IF(AND(E45=0,H45=0),"OK","NG 差額あり"))) -> 出納計算表 未入力
B46: 8月 | C46: ='R7業務（長）'!G38 -> 7267746 | E46: =IF(D46="","",C46-D46) | F46: ='R7業務（長）'!G46 -> 9879000 | H46: =IF(G46="","",F46-G46) | I46: =IF(5>締月,"",IF(OR(D46="",G46=""),"出納計算表 未入力",IF(AND(E46=0,H46=0),"OK","NG 差額あり"))) -> 出納計算表 未入力
...

Sheet 月例
A1: 令和 ８ 年 度 業 務 経 理 経 費 給 付 区 分 別 執 行 額 一 覧 表
K2: （単位:円）
P3: ←支払担当者が「未確認」、経理担当者が伝票確認後に「確認済」
A4: 支出日 | C4: 中項目 | D4: 小項目 | E4: 摘要 | F4: 執行額 | G4: 経費区分 | H4: 短期 | I4: 厚年 | J4: 経過的 | K4: 退職等 | L4: （再掲） 退職等単独 | M4: 作業列 （支給月） | P4: 状態 | Q4: 費目 (自動) | R4: 長期額 (自動) | S4: 短期 通番キー | T4: 長期 通番キー | U4: 計上列 (自動)
A5: 45756 | C5: 事務費 | D5: 通信運搬費 | E5: 切手 | F5: 178000 | G5: 2 | H5: =IF(G5=1,F5-I5-J5-K5,IF(G5=2,F5,0)) -> 178000 | I5: =ROUND(IF(G5=1,F5*10/23,IF(G5=3,F5-J5-K5,IF(G5=4,F5,IF(G5=5,F5*10/11,IF(G5=7,F5*10/11,0))))),0) -> 0 | J5: =ROUND(IF(G5=1,F5/23,IF(G5=3,F5/12,IF(G5=5,F5-I5,IF(G5=8,F5,0)))),0) -> 0 | K5: =ROUND(IF(G5=1,F5/23,IF(G5=3,F5/12,IF(G5=6,F5,IF(G5=7,F5-I5,0)))),0) -> 0 | L5: =IF(G5=6,F5,0) -> 0 | M5: =IF(F5="",0,MONTH(A5)) -> 4 | P5: 昨年実績 | Q5: =IF($F5="","",IFERROR(VLOOKUP($C5&"|"&$D5,科目表!$A$5:$B$200,2,FALSE),"※未登録")) -> 通信運搬費 | R5: =IF($F5="","",$I5+$J5+$K5) -> 0 | S5: =IF(OR($F5="",$P5="支払なし",$H5=0,$Q5=""),"",$Q5&"|S|"&(COUNTIF(S$4:S4,$Q5&"|S|*")+1)) -> 通信運搬費|S|1 | T5: =IF(OR($F5="",$P5="支払なし",$R5=0,$Q5=""),"",$Q5&"|L|"&(COUNTIF(T$4:T4,$Q5&"|L|*")+1)) | U5: =IF(OR($F5="",$A5=""),"",MOD(MONTH($A5)-4,12)+1) -> 1
A6: 46140 | C6: 事務費 | D6: 事務用消耗品費 | E6: 令和８年度基幹ウイルス対策ソフト（ミツイワ株式会社）短期 | F6: 20482 | G6: 2 | H6: =IF(G6=1,F6-I6-J6-K6,IF(G6=2,F6,0)) -> 20482 | I6: =ROUND(IF(G6=1,F6*10/23,IF(G6=3,F6-J6-K6,IF(G6=4,F6,IF(G6=5,F6*10/11,IF(G6=7,F6*10/11,0))))),0) -> 0 | J6: =ROUND(IF(G6=1,F6/23,IF(G6=3,F6/12,IF(G6=5,F6-I6,IF(G6=8,F6,0)))),0) -> 0 | K6: =ROUND(IF(G6=1,F6/23,IF(G6=3,F6/12,IF(G6=6,F6,IF(G6=7,F6-I6,0)))),0) -> 0 | L6: =IF(G6=6,F6,0) -> 0 | M6: =IF(F6="",0,MONTH(A6)) -> 4 | P6: 確認済 | Q6: =IF($F6="","",IFERROR(VLOOKUP($C6&"|"&$D6,科目表!$A$5:$B$200,2,FALSE),"※未登録")) -> 事務用消耗品費 | R6: =IF($F6="","",$I6+$J6+$K6) -> 0 | S6: =IF(OR($F6="",$P6="支払なし",$H6=0,$Q6=""),"",$Q6&"|S|"&(COUNTIF(S$4:S5,$Q6&"|S|*")+1)) -> 事務用消耗品費|S|1 | T6: =IF(OR($F6="",$P6="支払なし",$R6=0,$Q6=""),"",$Q6&"|L|"&(COUNTIF(T$4:T5,$Q6&"|L|*")+1)) | U6: =IF(OR($F6="",$A6=""),"",MOD(MONTH($A6)-4,12)+1) -> 1
A7: 46140 | C7: 事務費 | D7: 事務用消耗品費 | E7: 令和８年度基幹ウイルス対策ソフト（ミツイワ株式会社）長期 | F7: 8778 | G7: 3 | H7: =IF(G7=1,F7-I7-J7-K7,IF(G7=2,F7,0)) -> 0 | I7: =ROUND(IF(G7=1,F7*10/23,IF(G7=3,F7-J7-K7,IF(G7=4,F7,IF(G7=5,F7*10/11,IF(G7=7,F7*10/11,0))))),0) -> 7314 | J7: =ROUND(IF(G7=1,F7/23,IF(G7=3,F7/12,IF(G7=5,F7-I7,IF(G7=8,F7,0)))),0) -> 732 | K7: =ROUND(IF(G7=1,F7/23,IF(G7=3,F7/12,IF(G7=6,F7,IF(G7=7,F7-I7,0)))),0) -> 732 | L7: =IF(G7=6,F7,0) -> 0 | M7: =IF(F7="",0,MONTH(A7)) -> 4 | P7: 確認済 | Q7: =IF($F7="","",IFERROR(VLOOKUP($C7&"|"&$D7,科目表!$A$5:$B$200,2,FALSE),"※未登録")) -> 事務用消耗品費 | R7: =IF($F7="","",$I7+$J7+$K7) -> 8778 | S7: =IF(OR($F7="",$P7="支払なし",$H7=0,$Q7=""),"",$Q7&"|S|"&(COUNTIF(S$4:S6,$Q7&"|S|*")+1)) | T7: =IF(OR($F7="",$P7="支払なし",$R7=0,$Q7=""),"",$Q7&"|L|"&(COUNTIF(T$4:T6,$Q7&"|L|*")+1)) -> 事務用消耗品費|L|1 | U7: =IF(OR($F7="",$A7=""),"",MOD(MONTH($A7)-4,12)+1) -> 1
A8: 44316 | C8: 事務費 | D8: 事務用消耗品費 | E8: CD／DVDファイルＡ４１２ＪーＣ 他 | F8: 24407 | G8: 2 | H8: =IF(G8=1,F8-I8-J8-K8,IF(G8=2,F8,0)) -> 24407 | I8: =ROUND(IF(G8=1,F8*10/23,IF(G8=3,F8-J8-K8,IF(G8=4,F8,IF(G8=5,F8*10/11,IF(G8=7,F8*10/11,0))))),0) -> 0 | J8: =ROUND(IF(G8=1,F8/23,IF(G8=3,F8/12,IF(G8=5,F8-I8,IF(G8=8,F8,0)))),0) -> 0 | K8: =ROUND(IF(G8=1,F8/23,IF(G8=3,F8/12,IF(G8=6,F8,IF(G8=7,F8-I8,0)))),0) -> 0 | L8: =IF(G8=6,F8,0) -> 0 | M8: =IF(F8="",0,MONTH(A8)) -> 4 | P8: 昨年実績 | Q8: =IF($F8="","",IFERROR(VLOOKUP($C8&"|"&$D8,科目表!$A$5:$B$200,2,FALSE),"※未登録")) -> 事務用消耗品費 | R8: =IF($F8="","",$I8+$J8+$K8) -> 0 | S8: =IF(OR($F8="",$P8="支払なし",$H8=0,$Q8=""),"",$Q8&"|S|"&(COUNTIF(S$4:S7,$Q8&"|S|*")+1)) -> 事務用消耗品費|S|2 | T8: =IF(OR($F8="",$P8="支払なし",$R8=0,$Q8=""),"",$Q8&"|L|"&(COUNTIF(T$4:T7,$Q8&"|L|*")+1)) | U8: =IF(OR($F8="",$A8=""),"",MOD(MONTH($A8)-4,12)+1) -> 1
A9: 45764 | C9: 事務費 | D9: 通信運搬費 | E9: 切手 | F9: 173700 | G9: 3 | H9: =IF(G9=1,F9-I9-J9-K9,IF(G9=2,F9,0)) -> 0 | I9: =ROUND(IF(G9=1,F9*10/23,IF(G9=3,F9-J9-K9,IF(G9=4,F9,IF(G9=5,F9*10/11,IF(G9=7,F9*10/11,0))))),0) -> 144750 | J9: =ROUND(IF(G9=1,F9/23,IF(G9=3,F9/12,IF(G9=5,F9-I9,IF(G9=8,F9,0)))),0) -> 14475 | K9: =ROUND(IF(G9=1,F9/23,IF(G9=3,F9/12,IF(G9=6,F9,IF(G9=7,F9-I9,0)))),0) -> 14475 | L9: =IF(G9=6,F9,0) -> 0 | M9: =IF(F9="",0,MONTH(A9)) -> 4 | P9: 昨年実績 | Q9: =IF($F9="","",IFERROR(VLOOKUP($C9&"|"&$D9,科目表!$A$5:$B$200,2,FALSE),"※未登録")) -> 通信運搬費 | R9: =IF($F9="","",$I9+$J9+$K9) -> 173700 | S9: =IF(OR($F9="",$P9="支払なし",$H9=0,$Q9=""),"",$Q9&"|S|"&(COUNTIF(S$4:S8,$Q9&"|S|*")+1)) | T9: =IF(OR($F9="",$P9="支払なし",$R9=0,$Q9=""),"",$Q9&"|L|"&(COUNTIF(T$4:T8,$Q9&"|L|*")+1)) -> 通信運搬費|L|1 | U9: =IF(OR($F9="",$A9=""),"",MOD(MONTH($A9)-4,12)+1) -> 1
A10: 46132 | C10: 委託費 | E10: レセプト電子データ提供料（1月診療分） | F10: 60235 | G10: 2 | H10: =IF(G10=1,F10-I10-J10-K10,IF(G10=2,F10,0)) -> 60235 | I10: =ROUND(IF(G10=1,F10*10/23,IF(G10=3,F10-J10-K10,IF(G10=4,F10,IF(G10=5,F10*10/11,IF(G10=7,F10*10/11,0))))),0) -> 0 | J10: =ROUND(IF(G10=1,F10/23,IF(G10=3,F10/12,IF(G10=5,F10-I10,IF(G10=8,F10,0)))),0) -> 0 | K10: =ROUND(IF(G10=1,F10/23,IF(G10=3,F10/12,IF(G10=6,F10,IF(G10=7,F10-I10,0)))),0) -> 0 | L10: =IF(G10=6,F10,0) -> 0 | M10: =IF(F10="",0,MONTH(A10)) -> 4 | P10: 確認済 | Q10: =IF($F10="","",IFERROR(VLOOKUP($C10&"|"&$D10,科目表!$A$5:$B$200,2,FALSE),"※未登録")) -> 委託費 | R10: =IF($F10="","",$I10+$J10+$K10) -> 0 | S10: =IF(OR($F10="",$P10="支払なし",$H10=0,$Q10=""),"",$Q10&"|S|"&(COUNTIF(S$4:S9,$Q10&"|S|*")+1)) -> 委託費|S|1 | T10: =IF(OR($F10="",$P10="支払なし",$R10=0,$Q10=""),"",$Q10&"|L|"&(COUNTIF(T$4:T9,$Q10&"|L|*")+1)) | U10: =IF(OR($F10="",$A10=""),"",MOD(MONTH($A10)-4,12)+1) -> 1
A11: 43941 | C11: 事務費 | D11: 雑費 | E11: 電子証明書発行・更新料（令和2年4月請求） | F11: 4000 | G11: 2 | H11: =IF(G11=1,F11-I11-J11-K11,IF(G11=2,F11,0)) -> 4000 | I11: =ROUND(IF(G11=1,F11*10/23,IF(G11=3,F11-J11-K11,IF(G11=4,F11,IF(G11=5,F11*10/11,IF(G11=7,F11*10/11,0))))),0) -> 0 | J11: =ROUND(IF(G11=1,F11/23,IF(G11=3,F11/12,IF(G11=5,F11-I11,IF(G11=8,F11,0)))),0) -> 0 | K11: =ROUND(IF(G11=1,F11/23,IF(G11=3,F11/12,IF(G11=6,F11,IF(G11=7,F11-I11,0)))),0) -> 0 | L11: =IF(G11=6,F11,0) -> 0 | M11: =IF(F11="",0,MONTH(A11)) -> 4 | P11: 昨年実績 | Q11: =IF($F11="","",IFERROR(VLOOKUP($C11&"|"&$D11,科目表!$A$5:$B$200,2,FALSE),"※未登録")) -> 事務費・雑費 | R11: =IF($F11="","",$I11+$J11+$K11) -> 0 | S11: =IF(OR($F11="",$P11="支払なし",$H11=0,$Q11=""),"",$Q11&"|S|"&(COUNTIF(S$4:S10,$Q11&"|S|*")+1)) -> 事務費・雑費|S|1 | T11: =IF(OR($F11="",$P11="支払なし",$R11=0,$Q11=""),"",$Q11&"|L|"&(COUNTIF(T$4:T10,$Q11&"|L|*")+1)) | U11: =IF(OR($F11="",$A11=""),"",MOD(MONTH($A11)-4,12)+1) -> 1
A12: 46150 | C12: 負担金 | E12: 広島県社会保険協会年会費(短期) | F12: 780 | G12: 2 | H12: =IF(G12=1,F12-I12-J12-K12,IF(G12=2,F12,0)) -> 780 | I12: =ROUND(IF(G12=1,F12*10/23,IF(G12=3,F12-J12-K12,IF(G12=4,F12,IF(G12=5,F12*10/11,IF(G12=7,F12*10/11,0))))),0) -> 0 | J12: =ROUND(IF(G12=1,F12/23,IF(G12=3,F12/12,IF(G12=5,F12-I12,IF(G12=8,F12,0)))),0) -> 0 | K12: =ROUND(IF(G12=1,F12/23,IF(G12=3,F12/12,IF(G12=6,F12,IF(G12=7,F12-I12,0)))),0) -> 0 | L12: =IF(G12=6,F12,0) -> 0 | M12: =IF(F12="",0,MONTH(A12)) -> 5 | P12: 確認済 | Q12: =IF($F12="","",IFERROR(VLOOKUP($C12&"|"&$D12,科目表!$A$5:$B$200,2,FALSE),"※未登録")) -> 県社保協会費 | R12: =IF($F12="","",$I12+$J12+$K12) -> 0 | S12: =IF(OR($F12="",$P12="支払なし",$H12=0,$Q12=""),"",$Q12&"|S|"&(COUNTIF(S$4:S11,$Q12&"|S|*")+1)) -> 県社保協会費|S|1 | T12: =IF(OR($F12="",$P12="支払なし",$R12=0,$Q12=""),"",$Q12&"|L|"&(COUNTIF(T$4:T11,$Q12&"|L|*")+1)) | U12: =IF(OR($F12="",$A12=""),"",MOD(MONTH($A12)-4,12)+1) -> 2
A13: 46150 | C13: 負担金 | E13: 広島県社会保険協会年会費(長期) | F13: 520 | G13: 3 | H13: =IF(G13=1,F13-I13-J13-K13,IF(G13=2,F13,0)) -> 0 | I13: =ROUND(IF(G13=1,F13*10/23,IF(G13=3,F13-J13-K13,IF(G13=4,F13,IF(G13=5,F13*10/11,IF(G13=7,F13*10/11,0))))),0) -> 434 | J13: =ROUND(IF(G13=1,F13/23,IF(G13=3,F13/12,IF(G13=5,F13-I13,IF(G13=8,F13,0)))),0) -> 43 | K13: =ROUND(IF(G13=1,F13/23,IF(G13=3,F13/12,IF(G13=6,F13,IF(G13=7,F13-I13,0)))),0) -> 43 | L13: =IF(G13=6,F13,0) -> 0 | M13: =IF(F13="",0,MONTH(A13)) -> 5 | P13: 確認済 | Q13: =IF($F13="","",IFERROR(VLOOKUP($C13&"|"&$D13,科目表!$A$5:$B$200,2,FALSE),"※未登録")) -> 県社保協会費 | R13: =IF($F13="","",$I13+$J13+$K13) -> 520 | S13: =IF(OR($F13="",$P13="支払なし",$H13=0,$Q13=""),"",$Q13&"|S|"&(COUNTIF(S$4:S12,$Q13&"|S|*")+1)) | T13: =IF(OR($F13="",$P13="支払なし",$R13=0,$Q13=""),"",$Q13&"|L|"&(COUNTIF(T$4:T12,$Q13&"|L|*")+1)) -> 県社保協会費|L|1 | U13: =IF(OR($F13="",$A13=""),"",MOD(MONTH($A13)-4,12)+1) -> 2
A14: 46133 | C14: 職員給与 | D14: 非常勤職員手当 | E14: ４月分給与（長期分） | F14: 380800 | G14: 3 | H14: =IF(G14=1,F14-I14-J14-K14,IF(G14=2,F14,0)) -> 0 | I14: =ROUND(IF(G14=1,F14*10/23,IF(G14=3,F14-J14-K14,IF(G14=4,F14,IF(G14=5,F14*10/11,IF(G14=7,F14*10/11,0))))),0) -> 317334 | J14: =ROUND(IF(G14=1,F14/23,IF(G14=3,F14/12,IF(G14=5,F14-I14,IF(G14=8,F14,0)))),0) -> 31733 | K14: =ROUND(IF(G14=1,F14/23,IF(G14=3,F14/12,IF(G14=6,F14,IF(G14=7,F14-I14,0)))),0) -> 31733 | L14: =IF(G14=6,F14,0) -> 0 | M14: =IF(F14="",0,MONTH(A14)) -> 4 | P14: 確認済 | Q14: =IF($F14="","",IFERROR(VLOOKUP($C14&"|"&$D14,科目表!$A$5:$B$200,2,FALSE),"※未登録")) -> 非常勤職員手当 | R14: =IF($F14="","",$I14+$J14+$K14) -> 380800 | S14: =IF(OR($F14="",$P14="支払なし",$H14=0,$Q14=""),"",$Q14&"|S|"&(COUNTIF(S$4:S13,$Q14&"|S|*")+1)) | T14: =IF(OR($F14="",$P14="支払なし",$R14=0,$Q14=""),"",$Q14&"|L|"&(COUNTIF(T$4:T13,$Q14&"|L|*")+1)) -> 非常勤職員手当|L|1 | U14: =IF(OR($F14="",$A14=""),"",MOD(MONTH($A14)-4,12)+1) -> 1
A15: 46133 | C15: 職員給与 | D15: 非常勤職員手当 | E15: ４月分給与（短期分）3月時間外除く | F15: 317340 | G15: 2 | H15: =IF(G15=1,F15-I15-J15-K15,IF(G15=2,F15,0)) -> 317340 | I15: =ROUND(IF(G15=1,F15*10/23,IF(G15=3,F15-J15-K15,IF(G15=4,F15,IF(G15=5,F15*10/11,IF(G15=7,F15*10/11,0))))),0) -> 0 | J15: =ROUND(IF(G15=1,F15/23,IF(G15=3,F15/12,IF(G15=5,F15-I15,IF(G15=8,F15,0)))),0) -> 0 | K15: =ROUND(IF(G15=1,F15/23,IF(G15=3,F15/12,IF(G15=6,F15,IF(G15=7,F15-I15,0)))),0) -> 0 | L15: 0 | M15: =IF(F15="",0,MONTH(A15)) -> 4 | P15: 確認済 | Q15: =IF($F15="","",IFERROR(VLOOKUP($C15&"|"&$D15,科目表!$A$5:$B$200,2,FALSE),"※未登録")) -> 非常勤職員手当 | R15: =IF($F15="","",$I15+$J15+$K15) -> 0 | S15: =IF(OR($F15="",$P15="支払なし",$H15=0,$Q15=""),"",$Q15&"|S|"&(COUNTIF(S$4:S14,$Q15&"|S|*")+1)) -> 非常勤職員手当|S|1 | T15: =IF(OR($F15="",$P15="支払なし",$R15=0,$Q15=""),"",$Q15&"|L|"&(COUNTIF(T$4:T14,$Q15&"|L|*")+1)) | U15: =IF(OR($F15="",$A15=""),"",MOD(MONTH($A15)-4,12)+1) -> 1
A16: 46133 | C16: 負担金 | D16: 互助会費 | E16: 助成金（４月長期分） | F16: 466 | G16: 3 | H16: =IF(G16=1,F16-I16-J16-K16,IF(G16=2,F16,0)) -> 0 | I16: =ROUND(IF(G16=1,F16*10/23,IF(G16=3,F16-J16-K16,IF(G16=4,F16,IF(G16=5,F16*10/11,IF(G16=7,F16*10/11,0))))),0) -> 388 | J16: =ROUND(IF(G16=1,F16/23,IF(G16=3,F16/12,IF(G16=5,F16-I16,IF(G16=8,F16,0)))),0) -> 39 | K16: =ROUND(IF(G16=1,F16/23,IF(G16=3,F16/12,IF(G16=6,F16,IF(G16=7,F16-I16,0)))),0) -> 39 | L16: =IF(G16=6,F16,0) -> 0 | M16: =IF(F16="",0,MONTH(A16)) -> 4 | P16: 確認済 | Q16: =IF($F16="","",IFERROR(VLOOKUP($C16&"|"&$D16,科目表!$A$5:$B$200,2,FALSE),"※未登録")) -> 互助会費 | R16: =IF($F16="","",$I16+$J16+$K16) -> 466 | S16: =IF(OR($F16="",$P16="支払なし",$H16=0,$Q16=""),"",$Q16&"|S|"&(COUNTIF(S$4:S15,$Q16&"|S|*")+1)) | T16: =IF(OR($F16="",$P16="支払なし",$R16=0,$Q16=""),"",$Q16&"|L|"&(COUNTIF(T$4:T15,$Q16&"|L|*")+1)) -> 互助会費|L|1 | U16: =IF(OR($F16="",$A16=""),"",MOD(MONTH($A16)-4,12)+1) -> 1
A17: 46133 | C17: 負担金 | D17: 互助会費 | E17: 助成金（４月短期分） | F17: 240 | G17: 2 | H17: =IF(G17=1,F17-I17-J17-K17,IF(G17=2,F17,0)) -> 240 | I17: =ROUND(IF(G17=1,F17*10/23,IF(G17=3,F17-J17-K17,IF(G17=4,F17,IF(G17=5,F17*10/11,IF(G17=7,F17*10/11,0))))),0) -> 0 | J17: =ROUND(IF(G17=1,F17/23,IF(G17=3,F17/12,IF(G17=5,F17-I17,IF(G17=8,F17,0)))),0) -> 0 | K17: =ROUND(IF(G17=1,F17/23,IF(G17=3,F17/12,IF(G17=6,F17,IF(G17=7,F17-I17,0)))),0) -> 0 | L17: =IF(G17=6,F17,0) -> 0 | M17: =IF(F17="",0,MONTH(A17)) -> 4 | P17: 確認済 | Q17: =IF($F17="","",IFERROR(VLOOKUP($C17&"|"&$D17,科目表!$A$5:$B$200,2,FALSE),"※未登録")) -> 互助会費 | R17: =IF($F17="","",$I17+$J17+$K17) -> 0 | S17: =IF(OR($F17="",$P17="支払なし",$H17=0,$Q17=""),"",$Q17&"|S|"&(COUNTIF(S$4:S16,$Q17&"|S|*")+1)) -> 互助会費|S|1 | T17: =IF(OR($F17="",$P17="支払なし",$R17=0,$Q17=""),"",$Q17&"|L|"&(COUNTIF(T$4:T16,$Q17&"|L|*")+1)) | U17: =IF(OR($F17="",$A17=""),"",MOD(MONTH($A17)-4,12)+1) -> 1
A18: 45044 | C18: 委託費 | E18: 個人番号管理システムシンクライアント（４～１０月） | F18: 24486 | G18: 2 | H18: =IF(G18=1,F18-I18-J18-K18,IF(G18=2,F18,0)) -> 24486 | I18: =ROUND(IF(G18=1,F18*10/23,IF(G18=3,F18-J18-K18,IF(G18=4,F18,IF(G18=5,F18*10/11,IF(G18=7,F18*10/11,0))))),0) -> 0 | J18: =ROUND(IF(G18=1,F18/23,IF(G18=3,F18/12,IF(G18=5,F18-I18,IF(G18=8,F18,0)))),0) -> 0 | K18: =ROUND(IF(G18=1,F18/23,IF(G18=3,F18/12,IF(G18=6,F18,IF(G18=7,F18-I18,0)))),0) -> 0 | L18: =IF(G18=6,F18,0) -> 0 | M18: =IF(F18="",0,MONTH(A18)) -> 4 | P18: 昨年実績 | Q18: =IF($F18="","",IFERROR(VLOOKUP($C18&"|"&$D18,科目表!$A$5:$B$200,2,FALSE),"※未登録")) -> 委託費 | R18: =IF($F18="","",$I18+$J18+$K18) -> 0 | S18: =IF(OR($F18="",$P18="支払なし",$H18=0,$Q18=""),"",$Q18&"|S|"&(COUNTIF(S$4:S17,$Q18&"|S|*")+1)) -> 委託費|S|2 | T18: =IF(OR($F18="",$P18="支払なし",$R18=0,$Q18=""),"",$Q18&"|L|"&(COUNTIF(T$4:T17,$Q18&"|L|*")+1)) | U18: =IF(OR($F18="",$A18=""),"",MOD(MONTH($A18)-4,12)+1) -> 1
A19: 45807 | C19: 事務費 | D19: 図書印刷費 | E19: 窓付封筒 １，０００枚 | F19: 49500 | G19: 2 | H19: =IF(G19=1,F19-I19-J19-K19,IF(G19=2,F19,0)) -> 49500 | I19: =ROUND(IF(G19=1,F19*10/23,IF(G19=3,F19-J19-K19,IF(G19=4,F19,IF(G19=5,F19*10/11,IF(G19=7,F19*10/11,0))))),0) -> 0 | J19: =ROUND(IF(G19=1,F19/23,IF(G19=3,F19/12,IF(G19=5,F19-I19,IF(G19=8,F19,0)))),0) -> 0 | K19: =ROUND(IF(G19=1,F19/23,IF(G19=3,F19/12,IF(G19=6,F19,IF(G19=7,F19-I19,0)))),0) -> 0 | L19: =IF(G19=6,F19,0) -> 0 | M19: =IF(F19="",0,MONTH(A19)) -> 5 | P19: 昨年実績 | Q19: =IF($F19="","",IFERROR(VLOOKUP($C19&"|"&$D19,科目表!$A$5:$B$200,2,FALSE),"※未登録")) -> 図書印刷費 | R19: =IF($F19="","",$I19+$J19+$K19) -> 0 | S19: =IF(OR($F19="",$P19="支払なし",$H19=0,$Q19=""),"",$Q19&"|S|"&(COUNTIF(S$4:S18,$Q19&"|S|*")+1)) -> 図書印刷費|S|1 | T19: =IF(OR($F19="",$P19="支払なし",$R19=0,$Q19=""),"",$Q19&"|L|"&(COUNTIF(T$4:T18,$Q19&"|L|*")+1)) | U19: =IF(OR($F19="",$A19=""),"",MOD(MONTH($A19)-4,12)+1) -> 2
A20: 45061 | C20: 事務費 | D20: 図書印刷費 | E20: 定年延長と共済組合制度 ３０部 | F20: 2970 | G20: 3 | H20: =IF(G20=1,F20-I20-J20-K20,IF(G20=2,F20,0)) -> 0 | I20: =ROUND(IF(G20=1,F20*10/23,IF(G20=3,F20-J20-K20,IF(G20=4,F20,IF(G20=5,F20*10/11,IF(G20=7,F20*10/11,0))))),0) -> 2474 | J20: =ROUND(IF(G20=1,F20/23,IF(G20=3,F20/12,IF(G20=5,F20-I20,IF(G20=8,F20,0)))),0) -> 248 | K20: =ROUND(IF(G20=1,F20/23,IF(G20=3,F20/12,IF(G20=6,F20,IF(G20=7,F20-I20,0)))),0) -> 248 | L20: =IF(G20=6,F20,0) -> 0 | M20: =IF(F20="",0,MONTH(A20)) -> 5 | P20: 昨年実績 | Q20: =IF($F20="","",IFERROR(VLOOKUP($C20&"|"&$D20,科目表!$A$5:$B$200,2,FALSE),"※未登録")) -> 図書印刷費 | R20: =IF($F20="","",$I20+$J20+$K20) -> 2970 | S20: =IF(OR($F20="",$P20="支払なし",$H20=0,$Q20=""),"",$Q20&"|S|"&(COUNTIF(S$4:S19,$Q20&"|S|*")+1)) | T20: =IF(OR($F20="",$P20="支払なし",$R20=0,$Q20=""),"",$Q20&"|L|"&(COUNTIF(T$4:T19,$Q20&"|L|*")+1)) -> 図書印刷費|L|1 | U20: =IF(OR($F20="",$A20=""),"",MOD(MONTH($A20)-4,12)+1) -> 2
A21: 45477 | C21: 事務費 | D21: 図書印刷費 | E21: 組合員原票（Ａ４）８００部 ほか | F21: 133650 | G21: 3 | H21: =IF(G21=1,F21-I21-J21-K21,IF(G21=2,F21,0)) -> 0 | I21: =ROUND(IF(G21=1,F21*10/23,IF(G21=3,F21-J21-K21,IF(G21=4,F21,IF(G21=5,F21*10/11,IF(G21=7,F21*10/11,0))))),0) -> 111374 | J21: =ROUND(IF(G21=1,F21/23,IF(G21=3,F21/12,IF(G21=5,F21-I21,IF(G21=8,F21,0)))),0) -> 11138 | K21: =ROUND(IF(G21=1,F21/23,IF(G21=3,F21/12,IF(G21=6,F21,IF(G21=7,F21-I21,0)))),0) -> 11138 | L21: =IF(G21=6,F21,0) -> 0 | M21: =IF(F21="",0,MONTH(A21)) -> 7 | P21: 昨年実績 | Q21: =IF($F21="","",IFERROR(VLOOKUP($C21&"|"&$D21,科目表!$A$5:$B$200,2,FALSE),"※未登録")) -> 図書印刷費 | R21: =IF($F21="","",$I21+$J21+$K21) -> 133650 | S21: =IF(OR($F21="",$P21="支払なし",$H21=0,$Q21=""),"",$Q21&"|S|"&(COUNTIF(S$4:S20,$Q21&"|S|*")+1)) | T21: =IF(OR($F21="",$P21="支払なし",$R21=0,$Q21=""),"",$Q21&"|L|"&(COUNTIF(T$4:T20,$Q21&"|L|*")+1)) -> 図書印刷費|L|2 | U21: =IF(OR($F21="",$A21=""),"",MOD(MONTH($A21)-4,12)+1) -> 4
A22: 44377 | C22: 事務費 | D22: 事務用消耗品費 | E22: 鋳造ゴム印 ３号以下214字 他 | F22: 9733 | G22: 3 | H22: =IF(G22=1,F22-I22-J22-K22,IF(G22=2,F22,0)) -> 0 | I22: =ROUND(IF(G22=1,F22*10/23,IF(G22=3,F22-J22-K22,IF(G22=4,F22,IF(G22=5,F22*10/11,IF(G22=7,F22*10/11,0))))),0) -> 8111 | J22: =ROUND(IF(G22=1,F22/23,IF(G22=3,F22/12,IF(G22=5,F22-I22,IF(G22=8,F22,0)))),0) -> 811 | K22: =ROUND(IF(G22=1,F22/23,IF(G22=3,F22/12,IF(G22=6,F22,IF(G22=7,F22-I22,0)))),0) -> 811 | L22: =IF(G22=6,F22,0) -> 0 | M22: =IF(F22="",0,MONTH(A22)) -> 6 | P22: 昨年実績 | Q22: =IF($F22="","",IFERROR(VLOOKUP($C22&"|"&$D22,科目表!$A$5:$B$200,2,FALSE),"※未登録")) -> 事務用消耗品費 | R22: =IF($F22="","",$I22+$J22+$K22) -> 9733 | S22: =IF(OR($F22="",$P22="支払なし",$H22=0,$Q22=""),"",$Q22&"|S|"&(COUNTIF(S$4:S21,$Q22&"|S|*")+1)) | T22: =IF(OR($F22="",$P22="支払なし",$R22=0,$Q22=""),"",$Q22&"|L|"&(COUNTIF(T$4:T21,$Q22&"|L|*")+1)) -> 事務用消耗品費|L|2 | U22: =IF(OR($F22="",$A22=""),"",MOD(MONTH($A22)-4,12)+1) -> 3
A23: 46171 | C23: 事務費 | D23: 事務用消耗品費 | E23: ラベル用紙 LBP-F7656-100N ２冊 他 | F23: 43890 | G23: 2 | H23: =IF(G23=1,F23-I23-J23-K23,IF(G23=2,F23,0)) -> 43890 | I23: =ROUND(IF(G23=1,F23*10/23,IF(G23=3,F23-J23-K23,IF(G23=4,F23,IF(G23=5,F23*10/11,IF(G23=7,F23*10/11,0))))),0) -> 0 | J23: =ROUND(IF(G23=1,F23/23,IF(G23=3,F23/12,IF(G23=5,F23-I23,IF(G23=8,F23,0)))),0) -> 0 | K23: =ROUND(IF(G23=1,F23/23,IF(G23=3,F23/12,IF(G23=6,F23,IF(G23=7,F23-I23,0)))),0) -> 0 | L23: =IF(G23=6,F23,0) -> 0 | M23: =IF(F23="",0,MONTH(A23)) -> 5 | P23: 確認済 | Q23: =IF($F23="","",IFERROR(VLOOKUP($C23&"|"&$D23,科目表!$A$5:$B$200,2,FALSE),"※未登録")) -> 事務用消耗品費 | R23: =IF($F23="","",$I23+$J23+$K23) -> 0 | S23: =IF(OR($F23="",$P23="支払なし",$H23=0,$Q23=""),"",$Q23&"|S|"&(COUNTIF(S$4:S22,$Q23&"|S|*")+1)) -> 事務用消耗品費|S|3 | T23: =IF(OR($F23="",$P23="支払なし",$R23=0,$Q23=""),"",$Q23&"|L|"&(COUNTIF(T$4:T22,$Q23&"|L|*")+1)) | U23: =IF(OR($F23="",$A23=""),"",MOD(MONTH($A23)-4,12)+1) -> 2
A24: 46154 | C24: 事務費負担金払込金 | E24: ４月分事務費負担金払込金と連合会交付金との相殺 | F24: 5366000 | G24: 5 | H24: =IF(G24=1,F24-I24-J24-K24,IF(G24=2,F24,0)) -> 0 | I24: =ROUND(IF(G24=1,F24*10/23,IF(G24=3,F24-J24-K24,IF(G24=4,F24,IF(G24=5,F24*10/11,IF(G24=7,F24*10/11,0))))),0) -> 4878182 | J24: =ROUND(IF(G24=1,F24/23,IF(G24=3,F24/12,IF(G24=5,F24-I24,IF(G24=8,F24,0)))),0) -> 487818 | K24: =ROUND(IF(G24=1,F24/23,IF(G24=3,F24/12,IF(G24=6,F24,IF(G24=7,F24-I24,0)))),0) -> 0 | L24: =IF(G24=6,F24,0) -> 0 | M24: =IF(F24="",0,MONTH(A24)) -> 5 | P24: 確認済 | Q24: =IF($F24="","",IFERROR(VLOOKUP($C24&"|"&$D24,科目表!$A$5:$B$200,2,FALSE),"※未登録")) -> 事務費負担金払込金 | R24: =IF($F24="","",$I24+$J24+$K24) -> 5366000 | S24: =IF(OR($F24="",$P24="支払なし",$H24=0,$Q24=""),"",$Q24&"|S|"&(COUNTIF(S$4:S23,$Q24&"|S|*")+1)) | T24: =IF(OR($F24="",$P24="支払なし",$R24=0,$Q24=""),"",$Q24&"|L|"&(COUNTIF(T$4:T23,$Q24&"|L|*")+1)) -> 事務費負担金払込金|L|1 | U24: =IF(OR($F24="",$A24=""),"",MOD(MONTH($A24)-4,12)+1) -> 2
A25: 46139 | C25: 負担金 | D25: 負担金 | E25: 共済短期・介護・子ども子育て負担金（4月月例分）長期 | F25: 22035 | G25: 3 | H25: =IF(G25=1,F25-I25-J25-K25,IF(G25=2,F25,0)) -> 0 | I25: =ROUND(IF(G25=1,F25*10/23,IF(G25=3,F25-J25-K25,IF(G25=4,F25,IF(G25=5,F25*10/11,IF(G25=7,F25*10/11,0))))),0) -> 18363 | J25: =ROUND(IF(G25=1,F25/23,IF(G25=3,F25/12,IF(G25=5,F25-I25,IF(G25=8,F25,0)))),0) -> 1836 | K25: =ROUND(IF(G25=1,F25/23,IF(G25=3,F25/12,IF(G25=6,F25,IF(G25=7,F25-I25,0)))),0) -> 1836 | L25: =IF(G25=6,F25,0) -> 0 | M25: =IF(F25="",0,MONTH(A25)) -> 4 | P25: 確認済 | Q25: =IF($F25="","",IFERROR(VLOOKUP($C25&"|"&$D25,科目表!$A$5:$B$200,2,FALSE),"※未登録")) -> 共済負担金等 | R25: =IF($F25="","",$I25+$J25+$K25) -> 22035 | S25: =IF(OR($F25="",$P25="支払なし",$H25=0,$Q25=""),"",$Q25&"|S|"&(COUNTIF(S$4:S24,$Q25&"|S|*")+1)) | T25: =IF(OR($F25="",$P25="支払なし",$R25=0,$Q25=""),"",$Q25&"|L|"&(COUNTIF(T$4:T24,$Q25&"|L|*")+1)) -> 共済負担金等|L|1 | U25: =IF(OR($F25="",$A25=""),"",MOD(MONTH($A25)-4,12)+1) -> 1
A26: 46139 | C26: 負担金 | D26: 負担金 | E26: 共済短期・介護・子ども子育て負担金（4月月例分）短期 | F26: 37074 | G26: 2 | H26: =IF(G26=1,F26-I26-J26-K26,IF(G26=2,F26,0)) -> 37074 | I26: =ROUND(IF(G26=1,F26*10/23,IF(G26=3,F26-J26-K26,IF(G26=4,F26,IF(G26=5,F26*10/11,IF(G26=7,F26*10/11,0))))),0) -> 0 | J26: =ROUND(IF(G26=1,F26/23,IF(G26=3,F26/12,IF(G26=5,F26-I26,IF(G26=8,F26,0)))),0) -> 0 | K26: =ROUND(IF(G26=1,F26/23,IF(G26=3,F26/12,IF(G26=6,F26,IF(G26=7,F26-I26,0)))),0) -> 0 | L26: =IF(G26=6,F26,0) -> 0 | M26: =IF(F26="",0,MONTH(A26)) -> 4 | P26: 確認済 | Q26: =IF($F26="","",IFERROR(VLOOKUP($C26&"|"&$D26,科目表!$A$5:$B$200,2,FALSE),"※未登録")) -> 共済負担金等 | R26: =IF($F26="","",$I26+$J26+$K26) -> 0 | S26: =IF(OR($F26="",$P26="支払なし",$H26=0,$Q26=""),"",$Q26&"|S|"&(COUNTIF(S$4:S25,$Q26&"|S|*")+1)) -> 共済負担金等|S|1 | T26: =IF(OR($F26="",$P26="支払なし",$R26=0,$Q26=""),"",$Q26&"|L|"&(COUNTIF(T$4:T25,$Q26&"|L|*")+1)) | U26: =IF(OR($F26="",$A26=""),"",MOD(MONTH($A26)-4,12)+1) -> 1
A27: 46153 | C27: 事務費 | D27: 送金料 | E27: 振込手数料（広銀）４月分 長期分 | F27: 18493 | G27: 3 | H27: =IF(G27=1,F27-I27-J27-K27,IF(G27=2,F27,0)) -> 0 | I27: =ROUND(IF(G27=1,F27*10/23,IF(G27=3,F27-J27-K27,IF(G27=4,F27,IF(G27=5,F27*10/11,IF(G27=7,F27*10/11,0))))),0) -> 15411 | J27: =ROUND(IF(G27=1,F27/23,IF(G27=3,F27/12,IF(G27=5,F27-I27,IF(G27=8,F27,0)))),0) -> 1541 | K27: =ROUND(IF(G27=1,F27/23,IF(G27=3,F27/12,IF(G27=6,F27,IF(G27=7,F27-I27,0)))),0) -> 1541 | L27: =IF(G27=6,F27,0) -> 0 | M27: =IF(F27="",0,MONTH(A27)) -> 5 | P27: 確認済 | Q27: =IF($F27="","",IFERROR(VLOOKUP($C27&"|"&$D27,科目表!$A$5:$B$200,2,FALSE),"※未登録")) -> 送金料 | R27: =IF($F27="","",$I27+$J27+$K27) -> 18493 | S27: =IF(OR($F27="",$P27="支払なし",$H27=0,$Q27=""),"",$Q27&"|S|"&(COUNTIF(S$4:S26,$Q27&"|S|*")+1)) | T27: =IF(OR($F27="",$P27="支払なし",$R27=0,$Q27=""),"",$Q27&"|L|"&(COUNTIF(T$4:T26,$Q27&"|L|*")+1)) -> 送金料|L|1 | U27: =IF(OR($F27="",$A27=""),"",MOD(MONTH($A27)-4,12)+1) -> 2
A28: 46153 | C28: 事務費 | D28: 送金料 | E28: 振込手数料（広銀）４月分 短期分 | F28: 139883 | G28: 2 | H28: =IF(G28=1,F28-I28-J28-K28,IF(G28=2,F28,0)) -> 139883 | I28: =ROUND(IF(G28=1,F28*10/23,IF(G28=3,F28-J28-K28,IF(G28=4,F28,IF(G28=5,F28*10/11,IF(G28=7,F28*10/11,0))))),0) -> 0 | J28: =ROUND(IF(G28=1,F28/23,IF(G28=3,F28/12,IF(G28=5,F28-I28,IF(G28=8,F28,0)))),0) -> 0 | K28: =ROUND(IF(G28=1,F28/23,IF(G28=3,F28/12,IF(G28=6,F28,IF(G28=7,F28-I28,0)))),0) -> 0 | L28: =IF(G28=6,F28,0) -> 0 | M28: =IF(F28="",0,MONTH(A28)) -> 5 | P28: 確認済 | Q28: =IF($F28="","",IFERROR(VLOOKUP($C28&"|"&$D28,科目表!$A$5:$B$200,2,FALSE),"※未登録")) -> 送金料 | R28: =IF($F28="","",$I28+$J28+$K28) -> 0 | S28: =IF(OR($F28="",$P28="支払なし",$H28=0,$Q28=""),"",$Q28&"|S|"&(COUNTIF(S$4:S27,$Q28&"|S|*")+1)) -> 送金料|S|1 | T28: =IF(OR($F28="",$P28="支払なし",$R28=0,$Q28=""),"",$Q28&"|L|"&(COUNTIF(T$4:T27,$Q28&"|L|*")+1)) | U28: =IF(OR($F28="",$A28=""),"",MOD(MONTH($A28)-4,12)+1) -> 2
A29: 46171 | C29: 事務費 | D29: 事務用消耗品費 | E29: ダイヤルロック UNK-02 7個 他 | F29: 14518 | G29: 2 | H29: =IF(G29=1,F29-I29-J29-K29,IF(G29=2,F29,0)) -> 14518 | I29: =ROUND(IF(G29=1,F29*10/23,IF(G29=3,F29-J29-K29,IF(G29=4,F29,IF(G29=5,F29*10/11,IF(G29=7,F29*10/11,0))))),0) -> 0 | J29: =ROUND(IF(G29=1,F29/23,IF(G29=3,F29/12,IF(G29=5,F29-I29,IF(G29=8,F29,0)))),0) -> 0 | K29: =ROUND(IF(G29=1,F29/23,IF(G29=3,F29/12,IF(G29=6,F29,IF(G29=7,F29-I29,0)))),0) -> 0 | L29: =IF(G29=6,F29,0) -> 0 | M29: =IF(F29="",0,MONTH(A29)) -> 5 | P29: 確認済 | Q29: =IF($F29="","",IFERROR(VLOOKUP($C29&"|"&$D29,科目表!$A$5:$B$200,2,FALSE),"※未登録")) -> 事務用消耗品費 | R29: =IF($F29="","",$I29+$J29+$K29) -> 0 | S29: =IF(OR($F29="",$P29="支払なし",$H29=0,$Q29=""),"",$Q29&"|S|"&(COUNTIF(S$4:S28,$Q29&"|S|*")+1)) -> 事務用消耗品費|S|4 | T29: =IF(OR($F29="",$P29="支払なし",$R29=0,$Q29=""),"",$Q29&"|L|"&(COUNTIF(T$4:T28,$Q29&"|L|*")+1)) | U29: =IF(OR($F29="",$A29=""),"",MOD(MONTH($A29)-4,12)+1) -> 2
A30: 46171 | C30: 賃借料 | E30: パソコン（業務経理用）４月分 | F30: 5060 | G30: 2 | H30: =IF(G30=1,F30-I30-J30-K30,IF(G30=2,F30,0)) -> 5060 | I30: =ROUND(IF(G30=1,F30*10/23,IF(G30=3,F30-J30-K30,IF(G30=4,F30,IF(G30=5,F30*10/11,IF(G30=7,F30*10/11,0))))),0) -> 0 | J30: =ROUND(IF(G30=1,F30/23,IF(G30=3,F30/12,IF(G30=5,F30-I30,IF(G30=8,F30,0)))),0) -> 0 | K30: =ROUND(IF(G30=1,F30/23,IF(G30=3,F30/12,IF(G30=6,F30,IF(G30=7,F30-I30,0)))),0) -> 0 | L30: =IF(G30=6,F30,0) -> 0 | M30: =IF(F30="",0,MONTH(A30)) -> 5 | P30: 確認済 | Q30: =IF($F30="","",IFERROR(VLOOKUP($C30&"|"&$D30,科目表!$A$5:$B$200,2,FALSE),"※未登録")) -> 賃借料 | R30: =IF($F30="","",$I30+$J30+$K30) -> 0 | S30: =IF(OR($F30="",$P30="支払なし",$H30=0,$Q30=""),"",$Q30&"|S|"&(COUNTIF(S$4:S29,$Q30&"|S|*")+1)) -> 賃借料|S|1 | T30: =IF(OR($F30="",$P30="支払なし",$R30=0,$Q30=""),"",$Q30&"|L|"&(COUNTIF(T$4:T29,$Q30&"|L|*")+1)) | U30: =IF(OR($F30="",$A30=""),"",MOD(MONTH($A30)-4,12)+1) -> 2
A31: 46157 | C31: 賃金 | E31: 臨時職員賃金４月分 天畠吏梨外1名分（短期１００％） | F31: 425880 | G31: 2 | H31: =IF(G31=1,F31-I31-J31-K31,IF(G31=2,F31,0)) -> 425880 | I31: =ROUND(IF(G31=1,F31*10/23,IF(G31=3,F31-J31-K31,IF(G31=4,F31,IF(G31=5,F31*10/11,IF(G31=7,F31*10/11,0))))),0) -> 0 | J31: =ROUND(IF(G31=1,F31/23,IF(G31=3,F31/12,IF(G31=5,F31-I31,IF(G31=8,F31,0)))),0) -> 0 | K31: =ROUND(IF(G31=1,F31/23,IF(G31=3,F31/12,IF(G31=6,F31,IF(G31=7,F31-I31,0)))),0) -> 0 | L31: =IF(G31=6,F31,0) -> 0 | M31: =IF(F31="",0,MONTH(A31)) -> 5 | P31: 確認済 | Q31: =IF($F31="","",IFERROR(VLOOKUP($C31&"|"&$D31,科目表!$A$5:$B$200,2,FALSE),"※未登録")) -> 賃金 | R31: =IF($F31="","",$I31+$J31+$K31) -> 0 | S31: =IF(OR($F31="",$P31="支払なし",$H31=0,$Q31=""),"",$Q31&"|S|"&(COUNTIF(S$4:S30,$Q31&"|S|*")+1)) -> 賃金|S|1 | T31: =IF(OR($F31="",$P31="支払なし",$R31=0,$Q31=""),"",$Q31&"|L|"&(COUNTIF(T$4:T30,$Q31&"|L|*")+1)) | U31: =IF(OR($F31="",$A31=""),"",MOD(MONTH($A31)-4,12)+1) -> 2
A32: 46162 | C32: 委託費 | E32: 社会保障等制度 中間サーバー等運営負担金 | F32: 1798068 | G32: 2 | H32: =IF(G32=1,F32-I32-J32-K32,IF(G32=2,F32,0)) -> 1798068 | I32: =ROUND(IF(G32=1,F32*10/23,IF(G32=3,F32-J32-K32,IF(G32=4,F32,IF(G32=5,F32*10/11,IF(G32=7,F32*10/11,0))))),0) -> 0 | J32: =ROUND(IF(G32=1,F32/23,IF(G32=3,F32/12,IF(G32=5,F32-I32,IF(G32=8,F32,0)))),0) -> 0 | K32: =ROUND(IF(G32=1,F32/23,IF(G32=3,F32/12,IF(G32=6,F32,IF(G32=7,F32-I32,0)))),0) -> 0 | L32: =IF(G32=6,F32,0) -> 0 | M32: =IF(F32="",0,MONTH(A32)) -> 5 | P32: 確認済 | Q32: =IF($F32="","",IFERROR(VLOOKUP($C32&"|"&$D32,科目表!$A$5:$B$200,2,FALSE),"※未登録")) -> 委託費 | R32: =IF($F32="","",$I32+$J32+$K32) -> 0 | S32: =IF(OR($F32="",$P32="支払なし",$H32=0,$Q32=""),"",$Q32&"|S|"&(COUNTIF(S$4:S31,$Q32&"|S|*")+1)) -> 委託費|S|3 | T32: =IF(OR($F32="",$P32="支払なし",$R32=0,$Q32=""),"",$Q32&"|L|"&(COUNTIF(T$4:T31,$Q32&"|L|*")+1)) | U32: =IF(OR($F32="",$A32=""),"",MOD(MONTH($A32)-4,12)+1) -> 2
A33: 46171 | C33: 事務費 | D33: 送金料 | E33: ゆうちょ銀行手数料（４月分）短期 | F33: 109019 | G33: 2 | H33: =IF(G33=1,F33-I33-J33-K33,IF(G33=2,F33,0)) -> 109019 | I33: =ROUND(IF(G33=1,F33*10/23,IF(G33=3,F33-J33-K33,IF(G33=4,F33,IF(G33=5,F33*10/11,IF(G33=7,F33*10/11,0))))),0) -> 0 | J33: =ROUND(IF(G33=1,F33/23,IF(G33=3,F33/12,IF(G33=5,F33-I33,IF(G33=8,F33,0)))),0) -> 0 | K33: =ROUND(IF(G33=1,F33/23,IF(G33=3,F33/12,IF(G33=6,F33,IF(G33=7,F33-I33,0)))),0) -> 0 | L33: =IF(G33=6,F33,0) -> 0 | M33: =IF(F33="",0,MONTH(A33)) -> 5 | P33: 確認済 | Q33: =IF($F33="","",IFERROR(VLOOKUP($C33&"|"&$D33,科目表!$A$5:$B$200,2,FALSE),"※未登録")) -> 送金料 | R33: =IF($F33="","",$I33+$J33+$K33) -> 0 | S33: =IF(OR($F33="",$P33="支払なし",$H33=0,$Q33=""),"",$Q33&"|S|"&(COUNTIF(S$4:S32,$Q33&"|S|*")+1)) -> 送金料|S|2 | T33: =IF(OR($F33="",$P33="支払なし",$R33=0,$Q33=""),"",$Q33&"|L|"&(COUNTIF(T$4:T32,$Q33&"|L|*")+1)) | U33: =IF(OR($F33="",$A33=""),"",MOD(MONTH($A33)-4,12)+1) -> 2
A34: 46171 | C34: 事務費 | D34: 雑費 | E34: ゆうちょ銀行振替口座残高証明（４月分）短期 | F34: 550 | G34: 2 | H34: =IF(G34=1,F34-I34-J34-K34,IF(G34=2,F34,0)) -> 550 | I34: =ROUND(IF(G34=1,F34*10/23,IF(G34=3,F34-J34-K34,IF(G34=4,F34,IF(G34=5,F34*10/11,IF(G34=7,F34*10/11,0))))),0) -> 0 | J34: =ROUND(IF(G34=1,F34/23,IF(G34=3,F34/12,IF(G34=5,F34-I34,IF(G34=8,F34,0)))),0) -> 0 | K34: =ROUND(IF(G34=1,F34/23,IF(G34=3,F34/12,IF(G34=6,F34,IF(G34=7,F34-I34,0)))),0) -> 0 | L34: =IF(G34=6,F34,0) -> 0 | M34: =IF(F34="",0,MONTH(A34)) -> 5 | P34: 確認済 | Q34: =IF($F34="","",IFERROR(VLOOKUP($C34&"|"&$D34,科目表!$A$5:$B$200,2,FALSE),"※未登録")) -> 事務費・雑費 | R34: =IF($F34="","",$I34+$J34+$K34) -> 0 | S34: =IF(OR($F34="",$P34="支払なし",$H34=0,$Q34=""),"",$Q34&"|S|"&(COUNTIF(S$4:S33,$Q34&"|S|*")+1)) -> 事務費・雑費|S|2 | T34: =IF(OR($F34="",$P34="支払なし",$R34=0,$Q34=""),"",$Q34&"|L|"&(COUNTIF(T$4:T33,$Q34&"|L|*")+1)) | U34: =IF(OR($F34="",$A34=""),"",MOD(MONTH($A34)-4,12)+1) -> 2
A35: 46163 | C35: 職員給与 | D35: 非常勤職員手当 | E35: ５月分給与（長期分） | F35: 380800 | G35: 3 | H35: =IF(G35=1,F35-I35-J35-K35,IF(G35=2,F35,0)) -> 0 | I35: =ROUND(IF(G35=1,F35*10/23,IF(G35=3,F35-J35-K35,IF(G35=4,F35,IF(G35=5,F35*10/11,IF(G35=7,F35*10/11,0))))),0) -> 317334 | J35: =ROUND(IF(G35=1,F35/23,IF(G35=3,F35/12,IF(G35=5,F35-I35,IF(G35=8,F35,0)))),0) -> 31733 | K35: =ROUND(IF(G35=1,F35/23,IF(G35=3,F35/12,IF(G35=6,F35,IF(G35=7,F35-I35,0)))),0) -> 31733 | L35: =IF(G35=6,F35,0) -> 0 | M35: =IF(F35="",0,MONTH(A35)) -> 5 | P35: 確認済 | Q35: =IF($F35="","",IFERROR(VLOOKUP($C35&"|"&$D35,科目表!$A$5:$B$200,2,FALSE),"※未登録")) -> 非常勤職員手当 | R35: =IF($F35="","",$I35+$J35+$K35) -> 380800 | S35: =IF(OR($F35="",$P35="支払なし",$H35=0,$Q35=""),"",$Q35&"|S|"&(COUNTIF(S$4:S34,$Q35&"|S|*")+1)) | T35: =IF(OR($F35="",$P35="支払なし",$R35=0,$Q35=""),"",$Q35&"|L|"&(COUNTIF(T$4:T34,$Q35&"|L|*")+1)) -> 非常勤職員手当|L|2 | U35: =IF(OR($F35="",$A35=""),"",MOD(MONTH($A35)-4,12)+1) -> 2
A36: 46163 | C36: 職員給与 | D36: 非常勤職員手当 | E36: ５月分給与（短期分） | F36: 248436 | G36: 2 | H36: =IF(G36=1,F36-I36-J36-K36,IF(G36=2,F36,0)) -> 248436 | I36: =ROUND(IF(G36=1,F36*10/23,IF(G36=3,F36-J36-K36,IF(G36=4,F36,IF(G36=5,F36*10/11,IF(G36=7,F36*10/11,0))))),0) -> 0 | J36: =ROUND(IF(G36=1,F36/23,IF(G36=3,F36/12,IF(G36=5,F36-I36,IF(G36=8,F36,0)))),0) -> 0 | K36: =ROUND(IF(G36=1,F36/23,IF(G36=3,F36/12,IF(G36=6,F36,IF(G36=7,F36-I36,0)))),0) -> 0 | L36: 0 | M36: =IF(F36="",0,MONTH(A36)) -> 5 | P36: 確認済 | Q36: =IF($F36="","",IFERROR(VLOOKUP($C36&"|"&$D36,科目表!$A$5:$B$200,2,FALSE),"※未登録")) -> 非常勤職員手当 | R36: =IF($F36="","",$I36+$J36+$K36) -> 0 | S36: =IF(OR($F36="",$P36="支払なし",$H36=0,$Q36=""),"",$Q36&"|S|"&(COUNTIF(S$4:S35,$Q36&"|S|*")+1)) -> 非常勤職員手当|S|2 | T36: =IF(OR($F36="",$P36="支払なし",$R36=0,$Q36=""),"",$Q36&"|L|"&(COUNTIF(T$4:T35,$Q36&"|L|*")+1)) | U36: =IF(OR($F36="",$A36=""),"",MOD(MONTH($A36)-4,12)+1) -> 2
A37: 46163 | C37: 負担金 | D37: 互助会費 | E37: 助成金（５月長期分） | F37: 466 | G37: 3 | H37: =IF(G37=1,F37-I37-J37-K37,IF(G37=2,F37,0)) -> 0 | I37: =ROUND(IF(G37=1,F37*10/23,IF(G37=3,F37-J37-K37,IF(G37=4,F37,IF(G37=5,F37*10/11,IF(G37=7,F37*10/11,0))))),0) -> 388 | J37: =ROUND(IF(G37=1,F37/23,IF(G37=3,F37/12,IF(G37=5,F37-I37,IF(G37=8,F37,0)))),0) -> 39 | K37: =ROUND(IF(G37=1,F37/23,IF(G37=3,F37/12,IF(G37=6,F37,IF(G37=7,F37-I37,0)))),0) -> 39 | L37: =IF(G37=6,F37,0) -> 0 | M37: =IF(F37="",0,MONTH(A37)) -> 5 | P37: 確認済 | Q37: =IF($F37="","",IFERROR(VLOOKUP($C37&"|"&$D37,科目表!$A$5:$B$200,2,FALSE),"※未登録")) -> 互助会費 | R37: =IF($F37="","",$I37+$J37+$K37) -> 466 | S37: =IF(OR($F37="",$P37="支払なし",$H37=0,$Q37=""),"",$Q37&"|S|"&(COUNTIF(S$4:S36,$Q37&"|S|*")+1)) | T37: =IF(OR($F37="",$P37="支払なし",$R37=0,$Q37=""),"",$Q37&"|L|"&(COUNTIF(T$4:T36,$Q37&"|L|*")+1)) -> 互助会費|L|2 | U37: =IF(OR($F37="",$A37=""),"",MOD(MONTH($A37)-4,12)+1) -> 2
A38: 46163 | C38: 負担金 | D38: 互助会費 | E38: 助成金（５月短期分） | F38: 240 | G38: 2 | H38: =IF(G38=1,F38-I38-J38-K38,IF(G38=2,F38,0)) -> 240 | I38: =ROUND(IF(G38=1,F38*10/23,IF(G38=3,F38-J38-K38,IF(G38=4,F38,IF(G38=5,F38*10/11,IF(G38=7,F38*10/11,0))))),0) -> 0 | J38: =ROUND(IF(G38=1,F38/23,IF(G38=3,F38/12,IF(G38=5,F38-I38,IF(G38=8,F38,0)))),0) -> 0 | K38: =ROUND(IF(G38=1,F38/23,IF(G38=3,F38/12,IF(G38=6,F38,IF(G38=7,F38-I38,0)))),0) -> 0 | L38: =IF(G38=6,F38,0) -> 0 | M38: =IF(F38="",0,MONTH(A38)) -> 5 | P38: 確認済 | Q38: =IF($F38="","",IFERROR(VLOOKUP($C38&"|"&$D38,科目表!$A$5:$B$200,2,FALSE),"※未登録")) -> 互助会費 | R38: =IF($F38="","",$I38+$J38+$K38) -> 0 | S38: =IF(OR($F38="",$P38="支払なし",$H38=0,$Q38=""),"",$Q38&"|S|"&(COUNTIF(S$4:S37,$Q38&"|S|*")+1)) -> 互助会費|S|2 | T38: =IF(OR($F38="",$P38="支払なし",$R38=0,$Q38=""),"",$Q38&"|L|"&(COUNTIF(T$4:T37,$Q38&"|L|*")+1)) | U38: =IF(OR($F38="",$A38=""),"",MOD(MONTH($A38)-4,12)+1) -> 2
A39: 46162 | C39: 委託費 | E39: レセプト電子データ提供料（２月診療分） | F39: 61859 | G39: 2 | H39: =IF(G39=1,F39-I39-J39-K39,IF(G39=2,F39,0)) -> 61859 | I39: =ROUND(IF(G39=1,F39*10/23,IF(G39=3,F39-J39-K39,IF(G39=4,F39,IF(G39=5,F39*10/11,IF(G39=7,F39*10/11,0))))),0) -> 0 | J39: =ROUND(IF(G39=1,F39/23,IF(G39=3,F39/12,IF(G39=5,F39-I39,IF(G39=8,F39,0)))),0) -> 0 | K39: =ROUND(IF(G39=1,F39/23,IF(G39=3,F39/12,IF(G39=6,F39,IF(G39=7,F39-I39,0)))),0) -> 0 | L39: =IF(G39=6,F39,0) -> 0 | M39: =IF(F39="",0,MONTH(A39)) -> 5 | P39: 確認済 | Q39: =IF($F39="","",IFERROR(VLOOKUP($C39&"|"&$D39,科目表!$A$5:$B$200,2,FALSE),"※未登録")) -> 委託費 | R39: =IF($F39="","",$I39+$J39+$K39) -> 0 | S39: =IF(OR($F39="",$P39="支払なし",$H39=0,$Q39=""),"",$Q39&"|S|"&(COUNTIF(S$4:S38,$Q39&"|S|*")+1)) -> 委託費|S|4 | T39: =IF(OR($F39="",$P39="支払なし",$R39=0,$Q39=""),"",$Q39&"|L|"&(COUNTIF(T$4:T38,$Q39&"|L|*")+1)) | U39: =IF(OR($F39="",$A39=""),"",MOD(MONTH($A39)-4,12)+1) -> 2
A40: 45065 | C40: 委託費 | E40: 社会保障等制度 中間サーバー等運営負担金 | F40: 661740 | G40: 2 | H40: =IF(G40=1,F40-I40-J40-K40,IF(G40=2,F40,0)) -> 661740 | I40: =ROUND(IF(G40=1,F40*10/23,IF(G40=3,F40-J40-K40,IF(G40=4,F40,IF(G40=5,F40*10/11,IF(G40=7,F40*10/11,0))))),0) -> 0 | J40: =ROUND(IF(G40=1,F40/23,IF(G40=3,F40/12,IF(G40=5,F40-I40,IF(G40=8,F40,0)))),0) -> 0 | K40: =ROUND(IF(G40=1,F40/23,IF(G40=3,F40/12,IF(G40=6,F40,IF(G40=7,F40-I40,0)))),0) -> 0 | L40: =IF(G40=6,F40,0) -> 0 | M40: =IF(F40="",0,MONTH(A40)) -> 5 | P40: 昨年実績 | Q40: =IF($F40="","",IFERROR(VLOOKUP($C40&"|"&$D40,科目表!$A$5:$B$200,2,FALSE),"※未登録")) -> 委託費 | R40: =IF($F40="","",$I40+$J40+$K40) -> 0 | S40: =IF(OR($F40="",$P40="支払なし",$H40=0,$Q40=""),"",$Q40&"|S|"&(COUNTIF(S$4:S39,$Q40&"|S|*")+1)) -> 委託費|S|5 | T40: =IF(OR($F40="",$P40="支払なし",$R40=0,$Q40=""),"",$Q40&"|L|"&(COUNTIF(T$4:T39,$Q40&"|L|*")+1)) | U40: =IF(OR($F40="",$A40=""),"",MOD(MONTH($A40)-4,12)+1) -> 2
...

Sheet 決算整理
A1: 【 決 算 整 理 】 令 和 ８ 年 度 業 務 経 理 経 費 給 付 区 分 別 執 行 額 一 覧 表
K2: （単位:円）
P3: ←支払担当者が「未確認」、経理担当者が伝票確認後に「確認済」
A4: 支出日 | B4: 決算整理 区分 | C4: 中項目 | D4: 小項目 | E4: 摘要 | F4: 執行額 | G4: 経費区分 | H4: 短期 | I4: 厚年 | J4: 経過的 | K4: 退職等 | L4: （再掲） 退職等単独 | P4: 状態 | Q4: 費目 (自動) | R4: 長期額 (自動) | S4: 短期 通番キー | T4: 長期 通番キー | U4: 計上列 (自動)
A5: 43951 | B5: 未払金 | C5: 委託費 | E5: 人・給システム、庶務事務システム及び端末の使用料（短期分） | F5: 17630 | G5: 2 | H5: =IF(G5=1,F5-I5-J5-K5,IF(G5=2,F5,0)) -> 17630 | I5: =ROUND(IF(G5=1,F5*10/23,IF(G5=3,F5-J5-K5,IF(G5=4,F5,IF(G5=5,F5*10/11,IF(G5=7,F5*10/11,0))))),0) -> 0 | J5: =ROUND(IF(G5=1,F5/23,IF(G5=3,F5/12,IF(G5=5,F5-I5,IF(G5=8,F5,0)))),0) -> 0 | K5: =ROUND(IF(G5=1,F5/23,IF(G5=3,F5/12,IF(G5=6,F5,IF(G5=7,F5-I5,0)))),0) -> 0 | L5: =IF(G5=6,F5,0) -> 0 | N5: 非常勤職員手当 | P5: 昨年実績 | Q5: =IF($F5="","",IFERROR(VLOOKUP($C5&"|"&$D5,科目表!$A$5:$B$200,2,FALSE),"※未登録")) -> 委託費 | R5: =IF($F5="","",$I5+$J5+$K5) -> 0 | S5: =IF(OR($F5="",$P5="支払なし",$H5=0,$Q5=""),"",$Q5&"|S|"&(COUNTIF(S$4:S4,$Q5&"|S|*")+1)) -> 委託費|S|1 | T5: =IF(OR($F5="",$P5="支払なし",$R5=0,$Q5=""),"",$Q5&"|L|"&(COUNTIF(T$4:T4,$Q5&"|L|*")+1)) | U5: =IF($F5="","",13) -> 13
A6: 44666 | B6: 未払金 | C6: 事務費 | D6: 図書印刷費 | E6: 窓付角形封筒（のり付）１，０００枚ほか | F6: 149600 | G6: 3 | H6: =IF(G6=1,F6-I6-J6-K6,IF(G6=2,F6,0)) -> 0 | I6: =ROUND(IF(G6=1,F6*10/23,IF(G6=3,F6-J6-K6,IF(G6=4,F6,IF(G6=5,F6*10/11,IF(G6=7,F6*10/11,0))))),0) -> 124666 | J6: =ROUND(IF(G6=1,F6/23,IF(G6=3,F6/12,IF(G6=5,F6-I6,IF(G6=8,F6,0)))),0) -> 12467 | K6: =ROUND(IF(G6=1,F6/23,IF(G6=3,F6/12,IF(G6=6,F6,IF(G6=7,F6-I6,0)))),0) -> 12467 | L6: =IF(G6=6,F6,0) -> 0 | P6: 昨年実績 | Q6: =IF($F6="","",IFERROR(VLOOKUP($C6&"|"&$D6,科目表!$A$5:$B$200,2,FALSE),"※未登録")) -> 図書印刷費 | R6: =IF($F6="","",$I6+$J6+$K6) -> 149600 | S6: =IF(OR($F6="",$P6="支払なし",$H6=0,$Q6=""),"",$Q6&"|S|"&(COUNTIF(S$4:S5,$Q6&"|S|*")+1)) | T6: =IF(OR($F6="",$P6="支払なし",$R6=0,$Q6=""),"",$Q6&"|L|"&(COUNTIF(T$4:T5,$Q6&"|L|*")+1)) -> 図書印刷費|L|1 | U6: =IF($F6="","",13) -> 13
A7: 45777 | B7: 未払金 | C7: 事務費 | D7: 図書印刷費 | E7: 厚生法規総覧追録 ５９６６－５９７５号 | F7: 33154 | G7: 2 | H7: =IF(G7=1,F7-I7-J7-K7,IF(G7=2,F7,0)) -> 33154 | I7: =ROUND(IF(G7=1,F7*10/23,IF(G7=3,F7-J7-K7,IF(G7=4,F7,IF(G7=5,F7*10/11,IF(G7=7,F7*10/11,0))))),0) -> 0 | J7: =ROUND(IF(G7=1,F7/23,IF(G7=3,F7/12,IF(G7=5,F7-I7,IF(G7=8,F7,0)))),0) -> 0 | K7: =ROUND(IF(G7=1,F7/23,IF(G7=3,F7/12,IF(G7=6,F7,IF(G7=7,F7-I7,0)))),0) -> 0 | L7: =IF(G7=6,F7,0) -> 0 | P7: 昨年実績 | Q7: =IF($F7="","",IFERROR(VLOOKUP($C7&"|"&$D7,科目表!$A$5:$B$200,2,FALSE),"※未登録")) -> 図書印刷費 | R7: =IF($F7="","",$I7+$J7+$K7) -> 0 | S7: =IF(OR($F7="",$P7="支払なし",$H7=0,$Q7=""),"",$Q7&"|S|"&(COUNTIF(S$4:S6,$Q7&"|S|*")+1)) -> 図書印刷費|S|1 | T7: =IF(OR($F7="",$P7="支払なし",$R7=0,$Q7=""),"",$Q7&"|L|"&(COUNTIF(T$4:T6,$Q7&"|L|*")+1)) | U7: =IF($F7="","",13) -> 13
A8: 45777 | B8: 未払金 | C8: 事務費 | D8: 図書印刷費 | E8: 長３封筒 ４，０００枚 | F8: 48400 | G8: 2 | H8: =IF(G8=1,F8-I8-J8-K8,IF(G8=2,F8,0)) -> 48400 | I8: =ROUND(IF(G8=1,F8*10/23,IF(G8=3,F8-J8-K8,IF(G8=4,F8,IF(G8=5,F8*10/11,IF(G8=7,F8*10/11,0))))),0) -> 0 | J8: =ROUND(IF(G8=1,F8/23,IF(G8=3,F8/12,IF(G8=5,F8-I8,IF(G8=8,F8,0)))),0) -> 0 | K8: =ROUND(IF(G8=1,F8/23,IF(G8=3,F8/12,IF(G8=6,F8,IF(G8=7,F8-I8,0)))),0) -> 0 | L8: =IF(G8=6,F8,0) -> 0 | P8: 昨年実績 | Q8: =IF($F8="","",IFERROR(VLOOKUP($C8&"|"&$D8,科目表!$A$5:$B$200,2,FALSE),"※未登録")) -> 図書印刷費 | R8: =IF($F8="","",$I8+$J8+$K8) -> 0 | S8: =IF(OR($F8="",$P8="支払なし",$H8=0,$Q8=""),"",$Q8&"|S|"&(COUNTIF(S$4:S7,$Q8&"|S|*")+1)) -> 図書印刷費|S|2 | T8: =IF(OR($F8="",$P8="支払なし",$R8=0,$Q8=""),"",$Q8&"|L|"&(COUNTIF(T$4:T7,$Q8&"|L|*")+1)) | U8: =IF($F8="","",13) -> 13
A9: 46127 | B9: 未払金 | C9: 委託費 | E9: 個別システム保守料（令７年度）短期分 | F9: 360360 | G9: 2 | H9: =IF(G9=1,F9-I9-J9-K9,IF(G9=2,F9,0)) -> 360360 | I9: =ROUND(IF(G9=1,F9*10/23,IF(G9=3,F9-J9-K9,IF(G9=4,F9,IF(G9=5,F9*10/11,IF(G9=7,F9*10/11,0))))),0) -> 0 | J9: =ROUND(IF(G9=1,F9/23,IF(G9=3,F9/12,IF(G9=5,F9-I9,IF(G9=8,F9,0)))),0) -> 0 | K9: =ROUND(IF(G9=1,F9/23,IF(G9=3,F9/12,IF(G9=6,F9,IF(G9=7,F9-I9,0)))),0) -> 0 | L9: =IF(G9=6,F9,0) -> 0 | N9: 退職給与金 | P9: 昨年実績 | Q9: =IF($F9="","",IFERROR(VLOOKUP($C9&"|"&$D9,科目表!$A$5:$B$200,2,FALSE),"※未登録")) -> 委託費 | R9: =IF($F9="","",$I9+$J9+$K9) -> 0 | S9: =IF(OR($F9="",$P9="支払なし",$H9=0,$Q9=""),"",$Q9&"|S|"&(COUNTIF(S$4:S8,$Q9&"|S|*")+1)) -> 委託費|S|2 | T9: =IF(OR($F9="",$P9="支払なし",$R9=0,$Q9=""),"",$Q9&"|L|"&(COUNTIF(T$4:T8,$Q9&"|L|*")+1)) | U9: =IF($F9="","",13) -> 13
A10: 43951 | B10: 未払金 | C10: 委託費 | E10: 短期給付等に係る個人番号管理システム端末保守サービス（３月分） | F10: 385 | G10: 2 | H10: =IF(G10=1,F10-I10-J10-K10,IF(G10=2,F10,0)) -> 385 | I10: =ROUND(IF(G10=1,F10*10/23,IF(G10=3,F10-J10-K10,IF(G10=4,F10,IF(G10=5,F10*10/11,IF(G10=7,F10*10/11,0))))),0) -> 0 | J10: =ROUND(IF(G10=1,F10/23,IF(G10=3,F10/12,IF(G10=5,F10-I10,IF(G10=8,F10,0)))),0) -> 0 | K10: =ROUND(IF(G10=1,F10/23,IF(G10=3,F10/12,IF(G10=6,F10,IF(G10=7,F10-I10,0)))),0) -> 0 | L10: =IF(G10=6,F10,0) -> 0 | N10: 健康診断費 | P10: 昨年実績 | Q10: =IF($F10="","",IFERROR(VLOOKUP($C10&"|"&$D10,科目表!$A$5:$B$200,2,FALSE),"※未登録")) -> 委託費 | R10: =IF($F10="","",$I10+$J10+$K10) -> 0 | S10: =IF(OR($F10="",$P10="支払なし",$H10=0,$Q10=""),"",$Q10&"|S|"&(COUNTIF(S$4:S9,$Q10&"|S|*")+1)) -> 委託費|S|3 | T10: =IF(OR($F10="",$P10="支払なし",$R10=0,$Q10=""),"",$Q10&"|L|"&(COUNTIF(T$4:T9,$Q10&"|L|*")+1)) | U10: =IF($F10="","",13) -> 13
A11: 44679 | B11: 未払金 | C11: 委託費 | E11: 病院機構人給システム（ネットワーク等経費）短期 | F11: 43626 | G11: 2 | H11: =IF(G11=1,F11-I11-J11-K11,IF(G11=2,F11,0)) -> 43626 | I11: =ROUND(IF(G11=1,F11*10/23,IF(G11=3,F11-J11-K11,IF(G11=4,F11,IF(G11=5,F11*10/11,IF(G11=7,F11*10/11,0))))),0) -> 0 | J11: =ROUND(IF(G11=1,F11/23,IF(G11=3,F11/12,IF(G11=5,F11-I11,IF(G11=8,F11,0)))),0) -> 0 | K11: =ROUND(IF(G11=1,F11/23,IF(G11=3,F11/12,IF(G11=6,F11,IF(G11=7,F11-I11,0)))),0) -> 0 | L11: =IF(G11=6,F11,0) -> 0 | N11: 事務用消耗品費 | P11: 昨年実績 | Q11: =IF($F11="","",IFERROR(VLOOKUP($C11&"|"&$D11,科目表!$A$5:$B$200,2,FALSE),"※未登録")) -> 委託費 | R11: =IF($F11="","",$I11+$J11+$K11) -> 0 | S11: =IF(OR($F11="",$P11="支払なし",$H11=0,$Q11=""),"",$Q11&"|S|"&(COUNTIF(S$4:S10,$Q11&"|S|*")+1)) -> 委託費|S|4 | T11: =IF(OR($F11="",$P11="支払なし",$R11=0,$Q11=""),"",$Q11&"|L|"&(COUNTIF(T$4:T10,$Q11&"|L|*")+1)) | U11: =IF($F11="","",13) -> 13
A12: 43951 | B12: 未払金 | C12: 委託費 | E12: 清掃・警備・ごみ処理（１０～３月分） | F12: 4154 | G12: 2 | H12: =IF(G12=1,F12-I12-J12-K12,IF(G12=2,F12,0)) -> 4154 | I12: =ROUND(IF(G12=1,F12*10/23,IF(G12=3,F12-J12-K12,IF(G12=4,F12,IF(G12=5,F12*10/11,IF(G12=7,F12*10/11,0))))),0) -> 0 | J12: =ROUND(IF(G12=1,F12/23,IF(G12=3,F12/12,IF(G12=5,F12-I12,IF(G12=8,F12,0)))),0) -> 0 | K12: =ROUND(IF(G12=1,F12/23,IF(G12=3,F12/12,IF(G12=6,F12,IF(G12=7,F12-I12,0)))),0) -> 0 | L12: =IF(G12=6,F12,0) -> 0 | N12: 図書印刷費 | P12: 昨年実績 | Q12: =IF($F12="","",IFERROR(VLOOKUP($C12&"|"&$D12,科目表!$A$5:$B$200,2,FALSE),"※未登録")) -> 委託費 | R12: =IF($F12="","",$I12+$J12+$K12) -> 0 | S12: =IF(OR($F12="",$P12="支払なし",$H12=0,$Q12=""),"",$Q12&"|S|"&(COUNTIF(S$4:S11,$Q12&"|S|*")+1)) -> 委託費|S|5 | T12: =IF(OR($F12="",$P12="支払なし",$R12=0,$Q12=""),"",$Q12&"|L|"&(COUNTIF(T$4:T11,$Q12&"|L|*")+1)) | U12: =IF($F12="","",13) -> 13
A13: 43951 | B13: 未払金 | C13: 委託費 | E13: 柔整等療養費支給申請書の入力（３月分） | F13: 61281 | G13: 2 | H13: =IF(G13=1,F13-I13-J13-K13,IF(G13=2,F13,0)) -> 61281 | I13: =ROUND(IF(G13=1,F13*10/23,IF(G13=3,F13-J13-K13,IF(G13=4,F13,IF(G13=5,F13*10/11,IF(G13=7,F13*10/11,0))))),0) -> 0 | J13: =ROUND(IF(G13=1,F13/23,IF(G13=3,F13/12,IF(G13=5,F13-I13,IF(G13=8,F13,0)))),0) -> 0 | K13: =ROUND(IF(G13=1,F13/23,IF(G13=3,F13/12,IF(G13=6,F13,IF(G13=7,F13-I13,0)))),0) -> 0 | L13: =IF(G13=6,F13,0) -> 0 | N13: 送金料 | P13: 昨年実績 | Q13: =IF($F13="","",IFERROR(VLOOKUP($C13&"|"&$D13,科目表!$A$5:$B$200,2,FALSE),"※未登録")) -> 委託費 | R13: =IF($F13="","",$I13+$J13+$K13) -> 0 | S13: =IF(OR($F13="",$P13="支払なし",$H13=0,$Q13=""),"",$Q13&"|S|"&(COUNTIF(S$4:S12,$Q13&"|S|*")+1)) -> 委託費|S|6 | T13: =IF(OR($F13="",$P13="支払なし",$R13=0,$Q13=""),"",$Q13&"|L|"&(COUNTIF(T$4:T12,$Q13&"|L|*")+1)) | U13: =IF($F13="","",13) -> 13
A14: 44679 | B14: 未払金 | C14: 委託費 | E14: 統合管理端末保守料（３月分） | F14: 770 | G14: 2 | H14: =IF(G14=1,F14-I14-J14-K14,IF(G14=2,F14,0)) -> 770 | I14: =ROUND(IF(G14=1,F14*10/23,IF(G14=3,F14-J14-K14,IF(G14=4,F14,IF(G14=5,F14*10/11,IF(G14=7,F14*10/11,0))))),0) -> 0 | J14: =ROUND(IF(G14=1,F14/23,IF(G14=3,F14/12,IF(G14=5,F14-I14,IF(G14=8,F14,0)))),0) -> 0 | K14: =ROUND(IF(G14=1,F14/23,IF(G14=3,F14/12,IF(G14=6,F14,IF(G14=7,F14-I14,0)))),0) -> 0 | L14: =IF(G14=6,F14,0) -> 0 | N14: 通信運搬費 | P14: 昨年実績 | Q14: =IF($F14="","",IFERROR(VLOOKUP($C14&"|"&$D14,科目表!$A$5:$B$200,2,FALSE),"※未登録")) -> 委託費 | R14: =IF($F14="","",$I14+$J14+$K14) -> 0 | S14: =IF(OR($F14="",$P14="支払なし",$H14=0,$Q14=""),"",$Q14&"|S|"&(COUNTIF(S$4:S13,$Q14&"|S|*")+1)) -> 委託費|S|7 | T14: =IF(OR($F14="",$P14="支払なし",$R14=0,$Q14=""),"",$Q14&"|L|"&(COUNTIF(T$4:T13,$Q14&"|L|*")+1)) | U14: =IF($F14="","",13) -> 13
