Workbook
Name 年度: '月次締め'!$C$4
Name 締月: '月次締め'!$C$6

Sheet 使い方
A1: 令和8年度 費用収益表 統合ブック 使い方
A2: 旧：管理簿・予算差引簿・費用収益表の3ファイルを、「入力は台帳1か所だけ」「費用収益表は自動計上」「照合も自動」に作り替えたブックです。
B4: 毎月の流れ（旧→新）
B5: 担当 | C5: 新しいやり方 | D5: 旧
B6: ① 支払担当者 | C6: 入力シートで、昨年実績の行を今年の支払に直します（日付・金額）。状態を「昨年実績」→「未確認」へ。 | D6: 赤字を黒字にして金額を修正
B7: ② 経理担当者 | C7: 支払伝票が回ってきたら、その行の状態を「未確認」→「確認済」へ（プルダウン）。 | D7: 金額を青で塗りつぶして確認
B8: ③ 経理〆 | C8: 「月次締め」シートで「今回締める月」を選ぶ。費用収益表はその月まで自動で確定計上されます。 | D8: 黒字＋色塗りを費用収益表へ手で転記
B9: ④ 照合 | C9: 「月次締め」の黄色いセルに仮締め出納計算表の月合計を入力。差額が 0 で「OK」になればOK。 | D9: 費用収益表と出納計算表を目で照合
B10: ⑤ 月次更新 | C10: OK を確認して基幹システムで月次更新処理。「検算」シートが全部 OK ならこのブックの数字は一致しています。 | D10: 同じ
B12: 色のルール（状態から自動で付きます）
B13: 赤字 | C13: 状態＝昨年実績。今年の支払が確定するまで残しておく行（集計には入りません）。
B14: 黄色の背景 | C14: 状態＝未確認。今年の支払として入力済みだが、伝票確認前。
B15: 青い背景 | C15: 状態＝確認済。締め月までの分が費用収益表に計上されます。
B16: 取り消し線（灰色） | C16: 状態＝支払なし。今年度は支払がない行（集計から除外。行は残せます）。
B17: 費用収益表の緑字 | C17: 締め月より後の月＝前年実績・見込（旧表の値）。締め月までは黒字の確定値になります。
B18: 青字のセル | C18: 手入力するセル（金額・予算・収益など）。黒字は数式なので触りません。
B20: シート一覧
B21: 月次締め | C21: 操作盤。今回締める月の選択／締める前のチェック／出納計算表との照合。
B22: 入力_業務 / 入力_貸付 | C22: 台帳（旧：管理簿・予算差引簿）。支払はここだけに入力。行を足すときは最終行の下へ（業務1,600行・貸付400行まで）。
B23: 費用収益表（4枚） | C23: 業務合計・短期・長期・貸付。旧表と同じ配置。台帳連動の行は自動計算、収益・給与・予算などは手入力。
B24: 給付区分別 | C24: 旧：給付区分別執行額（月別／年度分）。確認済のみ集計。
B25: 科目表 | C25: プルダウンの元と、台帳の科目を費用収益表のどの行に入れるかのルール。
B26: 検算 / 旧表照合 | C26: 自動検算。旧表照合は、旧・費用収益表（9月締め時点）と1セルずつ突き合わせた結果。
B28: 注意
B29: 数式の列は消さない | C29: 灰色の列（短期・厚年…・費用収益表の行・計上列・点検など）は数式です。台帳に行を足すときは最終行の下の空き行に入力するだけでOK（数式は1,600行／400行分あらかじめ入っています）。
B30: 経費区分 | C30: 1〜8の按分ルールは旧「端数処理」と同じです（科目表の右側に一覧）。
B31: 来年度の更新 | C31: ①ブックを複製 ②月次締めの年度を変更 ③台帳の状態をすべて「昨年実績」に（フィルタ→コピー貼り付け）④費用収益表の予算・参考値を更新。

Sheet 月次締め
A1: 月次締め 操作盤と出納計算表との照合
A2: 月次〆のときは「今回締める月」を選ぶだけです。費用収益表がその月まで自動で確定表示になります（転記は不要）。黄色のセルに仮締めした出納計算表の月合計を入力し、差額が 0 になればOKです。
B4: 年度（令和） | C4: 8 | F4: 自動検算 | G4: =IF(検算!$F$3=0,"すべてOK","NG "&検算!$F$3&"件（検算シート参照）") -> すべてOK
B5: 今回締める月 | C5: 9月 | D5: ← ここを変えると、その月まで費用収益表に確定計上されます（9月締め済みなら「9月」）
B6: 月番号（自動） | C6: =MATCH($C$5,科目表!$N$5:$N$18,0)-1 -> 6
B8: ① 締める前のチェック（今回締める月の分）
B9: 項目 | C9: 業務 | D9: 貸付 | E9: 対応
B10: 確認済（青塗り相当）の件数 | C10: =IF(締月=0,0,COUNTIFS(入力_業務!$P$5:$P$1604,締月,入力_業務!$I$5:$I$1604,"確認済")) -> 35 | D10: =IF(締月=0,0,COUNTIFS(入力_貸付!$H$5:$H$404,締月,入力_貸付!$G$5:$G$404,"確認済")) -> 6 | E10: 費用収益表に計上される行数です
B11: 未確認（伝票待ち）の件数 | C11: =IF(締月=0,0,COUNTIFS(入力_業務!$P$5:$P$1604,締月,入力_業務!$I$5:$I$1604,"未確認")) -> 0 | D11: =IF(締月=0,0,COUNTIFS(入力_貸付!$H$5:$H$404,締月,入力_貸付!$G$5:$G$404,"未確認")) -> 0 | E11: 0 にしてから締めます（伝票を確認して「確認済」へ）
B12: 昨年実績のまま残っている件数（参考） | C12: =IF(締月=0,0,COUNTIFS(入力_業務!$P$5:$P$1604,締月,入力_業務!$I$5:$I$1604,"昨年実績")) -> 22 | D12: =IF(締月=0,0,COUNTIFS(入力_貸付!$H$5:$H$404,締月,入力_貸付!$G$5:$G$404,"昨年実績")) -> 2 | E12: 今年は支払がない行は「支払なし」にすると見やすくなります
B13: 点検NGの件数（台帳全体） | C13: =COUNTIF(入力_業務!$Q$5:$Q$1604,"?*") -> 0 | D13: =COUNTIF(入力_貸付!$J$5:$J$404,"?*") -> 0 | E13: 入力シートの「点検」列に内容が出ます
B14: 確認済 金額合計 | C14: =IF(締月=0,0,SUMIFS(入力_業務!$G$5:$G$1604,入力_業務!$P$5:$P$1604,締月,入力_業務!$I$5:$I$1604,"確認済")) -> 30634243 | D14: =IF(締月=0,0,SUMIFS(入力_貸付!$F$5:$F$404,入力_貸付!$H$5:$H$404,締月,入力_貸付!$G$5:$G$404,"確認済")) -> 325836 | E14: 旧：転記する金額の合計。業務は短期＋長期の合計
B15: 締め可否 | C15: =IF(締月=0,"-",IF(AND(C11=0,C13=0),"OK","要対応")) -> OK | D15: =IF(締月=0,"-",IF(AND(D11=0,D13=0),"OK","要対応")) -> OK
B18: ② 出納計算表との照合（黄色のセルに仮締めした出納計算表の月合計を入力）
B20: 業務経理（短期）
B21: 月 | C21: 費用 | F21: 収益 | I21: 判定
C22: 費用収益表 | D22: 出納計算表 | E22: 差額 | F22: 費用収益表 | G22: 出納計算表 | H22: 差額
B23: 4月 | C23: ='費用収益表_業務短期'!C38 -> 534591 | E23: =IF(D23="","",C23-D23) | F23: ='費用収益表_業務短期'!C46 -> 2268000 | H23: =IF(G23="","",F23-G23) | I23: =IF(1>締月,"",IF(OR(D23="",G23=""),"出納計算表 未入力",IF(AND(E23=0,H23=0),"OK","NG 差額あり"))) -> 出納計算表 未入力
B24: 5月 | C24: ='費用収益表_業務短期'!D38 -> 4087081 | E24: =IF(D24="","",C24-D24) | F24: ='費用収益表_業務短期'!D46 -> 2150000 | H24: =IF(G24="","",F24-G24) | I24: =IF(2>締月,"",IF(OR(D24="",G24=""),"出納計算表 未入力",IF(AND(E24=0,H24=0),"OK","NG 差額あり"))) -> 出納計算表 未入力
B25: 6月 | C25: ='費用収益表_業務短期'!E38 -> 2455166 | E25: =IF(D25="","",C25-D25) | F25: ='費用収益表_業務短期'!E46 -> 2609000 | H25: =IF(G25="","",F25-G25) | I25: =IF(3>締月,"",IF(OR(D25="",G25=""),"出納計算表 未入力",IF(AND(E25=0,H25=0),"OK","NG 差額あり"))) -> 出納計算表 未入力
B26: 7月 | C26: ='費用収益表_業務短期'!F38 -> 1972276 | E26: =IF(D26="","",C26-D26) | F26: ='費用収益表_業務短期'!F46 -> 2725000 | H26: =IF(G26="","",F26-G26) | I26: =IF(4>締月,"",IF(OR(D26="",G26=""),"出納計算表 未入力",IF(AND(E26=0,H26=0),"OK","NG 差額あり"))) -> 出納計算表 未入力
B27: 8月 | C27: ='費用収益表_業務短期'!G38 -> 2709341 | E27: =IF(D27="","",C27-D27) | F27: ='費用収益表_業務短期'!G46 -> 2151000 | H27: =IF(G27="","",F27-G27) | I27: =IF(5>締月,"",IF(OR(D27="",G27=""),"出納計算表 未入力",IF(AND(E27=0,H27=0),"OK","NG 差額あり"))) -> 出納計算表 未入力
B28: 9月 | C28: ='費用収益表_業務短期'!H38 -> 24070375 | E28: =IF(D28="","",C28-D28) | F28: ='費用収益表_業務短期'!H46 -> 12794000 | H28: =IF(G28="","",F28-G28) | I28: =IF(6>締月,"",IF(OR(D28="",G28=""),"出納計算表 未入力",IF(AND(E28=0,H28=0),"OK","NG 差額あり"))) -> 出納計算表 未入力
B29: 10月 | C29: ='費用収益表_業務短期'!I38 -> 2454418 | E29: =IF(D29="","",C29-D29) | F29: ='費用収益表_業務短期'!I46 -> 2477000 | H29: =IF(G29="","",F29-G29) | I29: =IF(7>締月,"",IF(OR(D29="",G29=""),"出納計算表 未入力",IF(AND(E29=0,H29=0),"OK","NG 差額あり")))
B30: 11月 | C30: ='費用収益表_業務短期'!J38 -> 2501632 | E30: =IF(D30="","",C30-D30) | F30: ='費用収益表_業務短期'!J46 -> 2228000 | H30: =IF(G30="","",F30-G30) | I30: =IF(8>締月,"",IF(OR(D30="",G30=""),"出納計算表 未入力",IF(AND(E30=0,H30=0),"OK","NG 差額あり")))
B31: 12月 | C31: ='費用収益表_業務短期'!K38 -> 5009376 | E31: =IF(D31="","",C31-D31) | F31: ='費用収益表_業務短期'!K46 -> 2894000 | H31: =IF(G31="","",F31-G31) | I31: =IF(9>締月,"",IF(OR(D31="",G31=""),"出納計算表 未入力",IF(AND(E31=0,H31=0),"OK","NG 差額あり")))
B32: 1月 | C32: ='費用収益表_業務短期'!L38 -> 2079276 | E32: =IF(D32="","",C32-D32) | F32: ='費用収益表_業務短期'!L46 -> 2560000 | H32: =IF(G32="","",F32-G32) | I32: =IF(10>締月,"",IF(OR(D32="",G32=""),"出納計算表 未入力",IF(AND(E32=0,H32=0),"OK","NG 差額あり")))
B33: 2月 | C33: ='費用収益表_業務短期'!M38 -> 2212970 | E33: =IF(D33="","",C33-D33) | F33: ='費用収益表_業務短期'!M46 -> 2209000 | H33: =IF(G33="","",F33-G33) | I33: =IF(11>締月,"",IF(OR(D33="",G33=""),"出納計算表 未入力",IF(AND(E33=0,H33=0),"OK","NG 差額あり")))
B34: 3月 | C34: ='費用収益表_業務短期'!N38 -> 2135536 | E34: =IF(D34="","",C34-D34) | F34: ='費用収益表_業務短期'!N46 -> 3606000 | H34: =IF(G34="","",F34-G34) | I34: =IF(12>締月,"",IF(OR(D34="",G34=""),"出納計算表 未入力",IF(AND(E34=0,H34=0),"OK","NG 差額あり")))
B35: 4月(未払) | C35: ='費用収益表_業務短期'!O38 -> 3204092 | E35: =IF(D35="","",C35-D35) | F35: ='費用収益表_業務短期'!O46 -> 9655506 | H35: =IF(G35="","",F35-G35) | I35: =IF(13>締月,"",IF(OR(D35="",G35=""),"出納計算表 未入力",IF(AND(E35=0,H35=0),"OK","NG 差額あり")))
B36: 締め月までの合計 | C36: =SUMPRODUCT((ROW(C23:C35)-23+1<=締月)*C23:C35) -> 35828830 | D36: =SUMPRODUCT((ROW(D23:D35)-23+1<=締月)*D23:D35) -> 0 | E36: =C36-D36 -> 35828830 | F36: =SUMPRODUCT((ROW(F23:F35)-23+1<=締月)*F23:F35) -> 24697000 | G36: =SUMPRODUCT((ROW(G23:G35)-23+1<=締月)*G23:G35) -> 0 | H36: =F36-G36 -> 24697000
B38: 業務経理（長期）
B39: 月 | C39: 費用 | F39: 収益 | I39: 判定
C40: 費用収益表 | D40: 出納計算表 | E40: 差額 | F40: 費用収益表 | G40: 出納計算表 | H40: 差額
B41: 4月 | C41: ='費用収益表_業務長期'!C38 -> 412079 | E41: =IF(D41="","",C41-D41) | F41: ='費用収益表_業務長期'!C46 -> 4513000 | H41: =IF(G41="","",F41-G41) | I41: =IF(1>締月,"",IF(OR(D41="",G41=""),"出納計算表 未入力",IF(AND(E41=0,H41=0),"OK","NG 差額あり"))) -> 出納計算表 未入力
B42: 5月 | C42: ='費用収益表_業務長期'!D38 -> 6019213 | E42: =IF(D42="","",C42-D42) | F42: ='費用収益表_業務長期'!D46 -> 9026000 | H42: =IF(G42="","",F42-G42) | I42: =IF(2>締月,"",IF(OR(D42="",G42=""),"出納計算表 未入力",IF(AND(E42=0,H42=0),"OK","NG 差額あり"))) -> 出納計算表 未入力
B43: 6月 | C43: ='費用収益表_業務長期'!E38 -> 6989919 | E43: =IF(D43="","",C43-D43) | F43: ='費用収益表_業務長期'!E46 -> 10732000 | H43: =IF(G43="","",F43-G43) | I43: =IF(3>締月,"",IF(OR(D43="",G43=""),"出納計算表 未入力",IF(AND(E43=0,H43=0),"OK","NG 差額あり"))) -> 出納計算表 未入力
B44: 7月 | C44: ='費用収益表_業務長期'!F38 -> 7671974 | E44: =IF(D44="","",C44-D44) | F44: ='費用収益表_業務長期'!F46 -> 13189000 | H44: =IF(G44="","",F44-G44) | I44: =IF(4>締月,"",IF(OR(D44="",G44=""),"出納計算表 未入力",IF(AND(E44=0,H44=0),"OK","NG 差額あり"))) -> 出納計算表 未入力
B45: 8月 | C45: ='費用収益表_業務長期'!G38 -> 7267746 | E45: =IF(D45="","",C45-D45) | F45: ='費用収益表_業務長期'!G46 -> 9879000 | H45: =IF(G45="","",F45-G45) | I45: =IF(5>締月,"",IF(OR(D45="",G45=""),"出納計算表 未入力",IF(AND(E45=0,H45=0),"OK","NG 差額あり"))) -> 出納計算表 未入力
B46: 9月 | C46: ='費用収益表_業務長期'!H38 -> 6563868 | E46: =IF(D46="","",C46-D46) | F46: ='費用収益表_業務長期'!H46 -> 9882148 | H46: =IF(G46="","",F46-G46) | I46: =IF(6>締月,"",IF(OR(D46="",G46=""),"出納計算表 未入力",IF(AND(E46=0,H46=0),"OK","NG 差額あり"))) -> 出納計算表 未入力
...

Sheet 入力_業務
A1: 入力_業務 業務経理 台帳（旧：管理簿「月例」「決算整理」を一本化）
A2: 支払担当者：昨年実績の行を今年の支払に直し、状態を「未確認」へ。 経理担当者：支払伝票を確認したら状態を「確認済」へ（旧：金額を青塗り）。 色は状態から自動で付きます（赤字＝昨年実績／黄＝未確認／青＝確認済）。 灰色の列は数式なので消さないでください。
A4: No | B4: 種別 | C4: 支払日 | D4: 中項目 | E4: 小項目 | F4: 摘要 | G4: 金額 | H4: 経費区分 | I4: 状態 | J4: 短期 | K4: 厚年 | L4: 経過的 | M4: 退職等 | N4: 長期計 | O4: 費用収益表の行 | P4: 計上列 | Q4: 点検 | R4: 元データ
A5: 1 | B5: 月例 | C5: 45756 | D5: 事務費 | E5: 通信運搬費 | F5: 切手 | G5: 178000 | H5: 2 | I5: 昨年実績 | J5: =IF($G5="","",IF($H5=1,$G5-ROUND($G5*10/23,0)-2*ROUND($G5/23,0),IF($H5=2,$G5,0))) -> 178000 | K5: =IF($G5="","",IF($H5=1,ROUND($G5*10/23,0),IF($H5=3,$G5-2*ROUND($G5/12,0),IF($H5=4,$G5,IF(OR($H5=5,$H5=7),ROUND($G5*10/11,0),0))))) -> 0 | L5: =IF($G5="","",IF($H5=1,ROUND($G5/23,0),IF($H5=3,ROUND($G5/12,0),IF($H5=5,$G5-ROUND($G5*10/11,0),IF($H5=8,$G5,0))))) -> 0 | M5: =IF($G5="","",IF($H5=1,ROUND($G5/23,0),IF($H5=3,ROUND($G5/12,0),IF($H5=6,$G5,IF($H5=7,$G5-ROUND($G5*10/11,0),0))))) -> 0 | N5: =IF($G5="","",K5+L5+M5) -> 0 | O5: =IF($G5="","",IFERROR(VLOOKUP($D5&"|"&$E5,科目表!$A$5:$B$200,2,FALSE),"※未登録")) -> 通信運搬費 | P5: =IF(OR($G5="",$C5=""),"",IF($B5="決算整理",13,MOD(MONTH($C5)-4,12)+1)) -> 1 | Q5: =IF($G5="","",TRIM(IF(J5+K5+L5+M5<>$G5,"按分不一致 ","")&IF(O5="※未登録","科目未登録 ","")&IF(OR($H5="",ISERROR(MATCH($H5,{1,2,3,4,5,6,7,8},0))),"経費区分? ","")&IF($I5="","状態未設定 ","")&IF(AND(OR($I5="確認済",$I5="未確認"),$B5="月例",OR($C5="",$C5<DATE(年度+2018,4,1),$C5>DATE(年度+2019,3,31))),"年度外の日付 ","")&IF(AND(OR($I5="確認済",$I5="未確認"),O5="対象外"),"対象外の科目 ",""))) | R5: 月例!5
A6: 2 | B6: 月例 | C6: 46140 | D6: 事務費 | E6: 事務用消耗品費 | F6: 令和８年度基幹ウイルス対策ソフト（ミツイワ株式会社）短期 | G6: 20482 | H6: 2 | I6: 確認済 | J6: =IF($G6="","",IF($H6=1,$G6-ROUND($G6*10/23,0)-2*ROUND($G6/23,0),IF($H6=2,$G6,0))) -> 20482 | K6: =IF($G6="","",IF($H6=1,ROUND($G6*10/23,0),IF($H6=3,$G6-2*ROUND($G6/12,0),IF($H6=4,$G6,IF(OR($H6=5,$H6=7),ROUND($G6*10/11,0),0))))) -> 0 | L6: =IF($G6="","",IF($H6=1,ROUND($G6/23,0),IF($H6=3,ROUND($G6/12,0),IF($H6=5,$G6-ROUND($G6*10/11,0),IF($H6=8,$G6,0))))) -> 0 | M6: =IF($G6="","",IF($H6=1,ROUND($G6/23,0),IF($H6=3,ROUND($G6/12,0),IF($H6=6,$G6,IF($H6=7,$G6-ROUND($G6*10/11,0),0))))) -> 0 | N6: =IF($G6="","",K6+L6+M6) -> 0 | O6: =IF($G6="","",IFERROR(VLOOKUP($D6&"|"&$E6,科目表!$A$5:$B$200,2,FALSE),"※未登録")) -> 事務用消耗品費 | P6: =IF(OR($G6="",$C6=""),"",IF($B6="決算整理",13,MOD(MONTH($C6)-4,12)+1)) -> 1 | Q6: =IF($G6="","",TRIM(IF(J6+K6+L6+M6<>$G6,"按分不一致 ","")&IF(O6="※未登録","科目未登録 ","")&IF(OR($H6="",ISERROR(MATCH($H6,{1,2,3,4,5,6,7,8},0))),"経費区分? ","")&IF($I6="","状態未設定 ","")&IF(AND(OR($I6="確認済",$I6="未確認"),$B6="月例",OR($C6="",$C6<DATE(年度+2018,4,1),$C6>DATE(年度+2019,3,31))),"年度外の日付 ","")&IF(AND(OR($I6="確認済",$I6="未確認"),O6="対象外"),"対象外の科目 ",""))) | R6: 月例!6
A7: 3 | B7: 月例 | C7: 46140 | D7: 事務費 | E7: 事務用消耗品費 | F7: 令和８年度基幹ウイルス対策ソフト（ミツイワ株式会社）長期 | G7: 8778 | H7: 3 | I7: 確認済 | J7: =IF($G7="","",IF($H7=1,$G7-ROUND($G7*10/23,0)-2*ROUND($G7/23,0),IF($H7=2,$G7,0))) -> 0 | K7: =IF($G7="","",IF($H7=1,ROUND($G7*10/23,0),IF($H7=3,$G7-2*ROUND($G7/12,0),IF($H7=4,$G7,IF(OR($H7=5,$H7=7),ROUND($G7*10/11,0),0))))) -> 7314 | L7: =IF($G7="","",IF($H7=1,ROUND($G7/23,0),IF($H7=3,ROUND($G7/12,0),IF($H7=5,$G7-ROUND($G7*10/11,0),IF($H7=8,$G7,0))))) -> 732 | M7: =IF($G7="","",IF($H7=1,ROUND($G7/23,0),IF($H7=3,ROUND($G7/12,0),IF($H7=6,$G7,IF($H7=7,$G7-ROUND($G7*10/11,0),0))))) -> 732 | N7: =IF($G7="","",K7+L7+M7) -> 8778 | O7: =IF($G7="","",IFERROR(VLOOKUP($D7&"|"&$E7,科目表!$A$5:$B$200,2,FALSE),"※未登録")) -> 事務用消耗品費 | P7: =IF(OR($G7="",$C7=""),"",IF($B7="決算整理",13,MOD(MONTH($C7)-4,12)+1)) -> 1 | Q7: =IF($G7="","",TRIM(IF(J7+K7+L7+M7<>$G7,"按分不一致 ","")&IF(O7="※未登録","科目未登録 ","")&IF(OR($H7="",ISERROR(MATCH($H7,{1,2,3,4,5,6,7,8},0))),"経費区分? ","")&IF($I7="","状態未設定 ","")&IF(AND(OR($I7="確認済",$I7="未確認"),$B7="月例",OR($C7="",$C7<DATE(年度+2018,4,1),$C7>DATE(年度+2019,3,31))),"年度外の日付 ","")&IF(AND(OR($I7="確認済",$I7="未確認"),O7="対象外"),"対象外の科目 ",""))) | R7: 月例!7
A8: 4 | B8: 月例 | C8: 44316 | D8: 事務費 | E8: 事務用消耗品費 | F8: CD／DVDファイルＡ４１２ＪーＣ 他 | G8: 24407 | H8: 2 | I8: 昨年実績 | J8: =IF($G8="","",IF($H8=1,$G8-ROUND($G8*10/23,0)-2*ROUND($G8/23,0),IF($H8=2,$G8,0))) -> 24407 | K8: =IF($G8="","",IF($H8=1,ROUND($G8*10/23,0),IF($H8=3,$G8-2*ROUND($G8/12,0),IF($H8=4,$G8,IF(OR($H8=5,$H8=7),ROUND($G8*10/11,0),0))))) -> 0 | L8: =IF($G8="","",IF($H8=1,ROUND($G8/23,0),IF($H8=3,ROUND($G8/12,0),IF($H8=5,$G8-ROUND($G8*10/11,0),IF($H8=8,$G8,0))))) -> 0 | M8: =IF($G8="","",IF($H8=1,ROUND($G8/23,0),IF($H8=3,ROUND($G8/12,0),IF($H8=6,$G8,IF($H8=7,$G8-ROUND($G8*10/11,0),0))))) -> 0 | N8: =IF($G8="","",K8+L8+M8) -> 0 | O8: =IF($G8="","",IFERROR(VLOOKUP($D8&"|"&$E8,科目表!$A$5:$B$200,2,FALSE),"※未登録")) -> 事務用消耗品費 | P8: =IF(OR($G8="",$C8=""),"",IF($B8="決算整理",13,MOD(MONTH($C8)-4,12)+1)) -> 1 | Q8: =IF($G8="","",TRIM(IF(J8+K8+L8+M8<>$G8,"按分不一致 ","")&IF(O8="※未登録","科目未登録 ","")&IF(OR($H8="",ISERROR(MATCH($H8,{1,2,3,4,5,6,7,8},0))),"経費区分? ","")&IF($I8="","状態未設定 ","")&IF(AND(OR($I8="確認済",$I8="未確認"),$B8="月例",OR($C8="",$C8<DATE(年度+2018,4,1),$C8>DATE(年度+2019,3,31))),"年度外の日付 ","")&IF(AND(OR($I8="確認済",$I8="未確認"),O8="対象外"),"対象外の科目 ",""))) | R8: 月例!8
A9: 5 | B9: 月例 | C9: 45764 | D9: 事務費 | E9: 通信運搬費 | F9: 切手 | G9: 173700 | H9: 3 | I9: 昨年実績 | J9: =IF($G9="","",IF($H9=1,$G9-ROUND($G9*10/23,0)-2*ROUND($G9/23,0),IF($H9=2,$G9,0))) -> 0 | K9: =IF($G9="","",IF($H9=1,ROUND($G9*10/23,0),IF($H9=3,$G9-2*ROUND($G9/12,0),IF($H9=4,$G9,IF(OR($H9=5,$H9=7),ROUND($G9*10/11,0),0))))) -> 144750 | L9: =IF($G9="","",IF($H9=1,ROUND($G9/23,0),IF($H9=3,ROUND($G9/12,0),IF($H9=5,$G9-ROUND($G9*10/11,0),IF($H9=8,$G9,0))))) -> 14475 | M9: =IF($G9="","",IF($H9=1,ROUND($G9/23,0),IF($H9=3,ROUND($G9/12,0),IF($H9=6,$G9,IF($H9=7,$G9-ROUND($G9*10/11,0),0))))) -> 14475 | N9: =IF($G9="","",K9+L9+M9) -> 173700 | O9: =IF($G9="","",IFERROR(VLOOKUP($D9&"|"&$E9,科目表!$A$5:$B$200,2,FALSE),"※未登録")) -> 通信運搬費 | P9: =IF(OR($G9="",$C9=""),"",IF($B9="決算整理",13,MOD(MONTH($C9)-4,12)+1)) -> 1 | Q9: =IF($G9="","",TRIM(IF(J9+K9+L9+M9<>$G9,"按分不一致 ","")&IF(O9="※未登録","科目未登録 ","")&IF(OR($H9="",ISERROR(MATCH($H9,{1,2,3,4,5,6,7,8},0))),"経費区分? ","")&IF($I9="","状態未設定 ","")&IF(AND(OR($I9="確認済",$I9="未確認"),$B9="月例",OR($C9="",$C9<DATE(年度+2018,4,1),$C9>DATE(年度+2019,3,31))),"年度外の日付 ","")&IF(AND(OR($I9="確認済",$I9="未確認"),O9="対象外"),"対象外の科目 ",""))) | R9: 月例!9
A10: 6 | B10: 月例 | C10: 46132 | D10: 委託費 | F10: レセプト電子データ提供料（1月診療分） | G10: 60235 | H10: 2 | I10: 確認済 | J10: =IF($G10="","",IF($H10=1,$G10-ROUND($G10*10/23,0)-2*ROUND($G10/23,0),IF($H10=2,$G10,0))) -> 60235 | K10: =IF($G10="","",IF($H10=1,ROUND($G10*10/23,0),IF($H10=3,$G10-2*ROUND($G10/12,0),IF($H10=4,$G10,IF(OR($H10=5,$H10=7),ROUND($G10*10/11,0),0))))) -> 0 | L10: =IF($G10="","",IF($H10=1,ROUND($G10/23,0),IF($H10=3,ROUND($G10/12,0),IF($H10=5,$G10-ROUND($G10*10/11,0),IF($H10=8,$G10,0))))) -> 0 | M10: =IF($G10="","",IF($H10=1,ROUND($G10/23,0),IF($H10=3,ROUND($G10/12,0),IF($H10=6,$G10,IF($H10=7,$G10-ROUND($G10*10/11,0),0))))) -> 0 | N10: =IF($G10="","",K10+L10+M10) -> 0 | O10: =IF($G10="","",IFERROR(VLOOKUP($D10&"|"&$E10,科目表!$A$5:$B$200,2,FALSE),"※未登録")) -> 委託費 | P10: =IF(OR($G10="",$C10=""),"",IF($B10="決算整理",13,MOD(MONTH($C10)-4,12)+1)) -> 1 | Q10: =IF($G10="","",TRIM(IF(J10+K10+L10+M10<>$G10,"按分不一致 ","")&IF(O10="※未登録","科目未登録 ","")&IF(OR($H10="",ISERROR(MATCH($H10,{1,2,3,4,5,6,7,8},0))),"経費区分? ","")&IF($I10="","状態未設定 ","")&IF(AND(OR($I10="確認済",$I10="未確認"),$B10="月例",OR($C10="",$C10<DATE(年度+2018,4,1),$C10>DATE(年度+2019,3,31))),"年度外の日付 ","")&IF(AND(OR($I10="確認済",$I10="未確認"),O10="対象外"),"対象外の科目 ",""))) | R10: 月例!10
A11: 7 | B11: 月例 | C11: 43941 | D11: 事務費 | E11: 雑費 | F11: 電子証明書発行・更新料（令和2年4月請求） | G11: 4000 | H11: 2 | I11: 昨年実績 | J11: =IF($G11="","",IF($H11=1,$G11-ROUND($G11*10/23,0)-2*ROUND($G11/23,0),IF($H11=2,$G11,0))) -> 4000 | K11: =IF($G11="","",IF($H11=1,ROUND($G11*10/23,0),IF($H11=3,$G11-2*ROUND($G11/12,0),IF($H11=4,$G11,IF(OR($H11=5,$H11=7),ROUND($G11*10/11,0),0))))) -> 0 | L11: =IF($G11="","",IF($H11=1,ROUND($G11/23,0),IF($H11=3,ROUND($G11/12,0),IF($H11=5,$G11-ROUND($G11*10/11,0),IF($H11=8,$G11,0))))) -> 0 | M11: =IF($G11="","",IF($H11=1,ROUND($G11/23,0),IF($H11=3,ROUND($G11/12,0),IF($H11=6,$G11,IF($H11=7,$G11-ROUND($G11*10/11,0),0))))) -> 0 | N11: =IF($G11="","",K11+L11+M11) -> 0 | O11: =IF($G11="","",IFERROR(VLOOKUP($D11&"|"&$E11,科目表!$A$5:$B$200,2,FALSE),"※未登録")) -> 事務費・雑費 | P11: =IF(OR($G11="",$C11=""),"",IF($B11="決算整理",13,MOD(MONTH($C11)-4,12)+1)) -> 1 | Q11: =IF($G11="","",TRIM(IF(J11+K11+L11+M11<>$G11,"按分不一致 ","")&IF(O11="※未登録","科目未登録 ","")&IF(OR($H11="",ISERROR(MATCH($H11,{1,2,3,4,5,6,7,8},0))),"経費区分? ","")&IF($I11="","状態未設定 ","")&IF(AND(OR($I11="確認済",$I11="未確認"),$B11="月例",OR($C11="",$C11<DATE(年度+2018,4,1),$C11>DATE(年度+2019,3,31))),"年度外の日付 ","")&IF(AND(OR($I11="確認済",$I11="未確認"),O11="対象外"),"対象外の科目 ",""))) | R11: 月例!11
A12: 8 | B12: 月例 | C12: 46150 | D12: 負担金 | F12: 広島県社会保険協会年会費(短期) | G12: 780 | H12: 2 | I12: 確認済 | J12: =IF($G12="","",IF($H12=1,$G12-ROUND($G12*10/23,0)-2*ROUND($G12/23,0),IF($H12=2,$G12,0))) -> 780 | K12: =IF($G12="","",IF($H12=1,ROUND($G12*10/23,0),IF($H12=3,$G12-2*ROUND($G12/12,0),IF($H12=4,$G12,IF(OR($H12=5,$H12=7),ROUND($G12*10/11,0),0))))) -> 0 | L12: =IF($G12="","",IF($H12=1,ROUND($G12/23,0),IF($H12=3,ROUND($G12/12,0),IF($H12=5,$G12-ROUND($G12*10/11,0),IF($H12=8,$G12,0))))) -> 0 | M12: =IF($G12="","",IF($H12=1,ROUND($G12/23,0),IF($H12=3,ROUND($G12/12,0),IF($H12=6,$G12,IF($H12=7,$G12-ROUND($G12*10/11,0),0))))) -> 0 | N12: =IF($G12="","",K12+L12+M12) -> 0 | O12: =IF($G12="","",IFERROR(VLOOKUP($D12&"|"&$E12,科目表!$A$5:$B$200,2,FALSE),"※未登録")) -> 県社保協会費 | P12: =IF(OR($G12="",$C12=""),"",IF($B12="決算整理",13,MOD(MONTH($C12)-4,12)+1)) -> 2 | Q12: =IF($G12="","",TRIM(IF(J12+K12+L12+M12<>$G12,"按分不一致 ","")&IF(O12="※未登録","科目未登録 ","")&IF(OR($H12="",ISERROR(MATCH($H12,{1,2,3,4,5,6,7,8},0))),"経費区分? ","")&IF($I12="","状態未設定 ","")&IF(AND(OR($I12="確認済",$I12="未確認"),$B12="月例",OR($C12="",$C12<DATE(年度+2018,4,1),$C12>DATE(年度+2019,3,31))),"年度外の日付 ","")&IF(AND(OR($I12="確認済",$I12="未確認"),O12="対象外"),"対象外の科目 ",""))) | R12: 月例!12
A13: 9 | B13: 月例 | C13: 46150 | D13: 負担金 | F13: 広島県社会保険協会年会費(長期) | G13: 520 | H13: 3 | I13: 確認済 | J13: =IF($G13="","",IF($H13=1,$G13-ROUND($G13*10/23,0)-2*ROUND($G13/23,0),IF($H13=2,$G13,0))) -> 0 | K13: =IF($G13="","",IF($H13=1,ROUND($G13*10/23,0),IF($H13=3,$G13-2*ROUND($G13/12,0),IF($H13=4,$G13,IF(OR($H13=5,$H13=7),ROUND($G13*10/11,0),0))))) -> 434 | L13: =IF($G13="","",IF($H13=1,ROUND($G13/23,0),IF($H13=3,ROUND($G13/12,0),IF($H13=5,$G13-ROUND($G13*10/11,0),IF($H13=8,$G13,0))))) -> 43 | M13: =IF($G13="","",IF($H13=1,ROUND($G13/23,0),IF($H13=3,ROUND($G13/12,0),IF($H13=6,$G13,IF($H13=7,$G13-ROUND($G13*10/11,0),0))))) -> 43 | N13: =IF($G13="","",K13+L13+M13) -> 520 | O13: =IF($G13="","",IFERROR(VLOOKUP($D13&"|"&$E13,科目表!$A$5:$B$200,2,FALSE),"※未登録")) -> 県社保協会費 | P13: =IF(OR($G13="",$C13=""),"",IF($B13="決算整理",13,MOD(MONTH($C13)-4,12)+1)) -> 2 | Q13: =IF($G13="","",TRIM(IF(J13+K13+L13+M13<>$G13,"按分不一致 ","")&IF(O13="※未登録","科目未登録 ","")&IF(OR($H13="",ISERROR(MATCH($H13,{1,2,3,4,5,6,7,8},0))),"経費区分? ","")&IF($I13="","状態未設定 ","")&IF(AND(OR($I13="確認済",$I13="未確認"),$B13="月例",OR($C13="",$C13<DATE(年度+2018,4,1),$C13>DATE(年度+2019,3,31))),"年度外の日付 ","")&IF(AND(OR($I13="確認済",$I13="未確認"),O13="対象外"),"対象外の科目 ",""))) | R13: 月例!13
A14: 10 | B14: 月例 | C14: 46133 | D14: 職員給与 | E14: 非常勤職員手当 | F14: ４月分給与（長期分） | G14: 380800 | H14: 3 | I14: 確認済 | J14: =IF($G14="","",IF($H14=1,$G14-ROUND($G14*10/23,0)-2*ROUND($G14/23,0),IF($H14=2,$G14,0))) -> 0 | K14: =IF($G14="","",IF($H14=1,ROUND($G14*10/23,0),IF($H14=3,$G14-2*ROUND($G14/12,0),IF($H14=4,$G14,IF(OR($H14=5,$H14=7),ROUND($G14*10/11,0),0))))) -> 317334 | L14: =IF($G14="","",IF($H14=1,ROUND($G14/23,0),IF($H14=3,ROUND($G14/12,0),IF($H14=5,$G14-ROUND($G14*10/11,0),IF($H14=8,$G14,0))))) -> 31733 | M14: =IF($G14="","",IF($H14=1,ROUND($G14/23,0),IF($H14=3,ROUND($G14/12,0),IF($H14=6,$G14,IF($H14=7,$G14-ROUND($G14*10/11,0),0))))) -> 31733 | N14: =IF($G14="","",K14+L14+M14) -> 380800 | O14: =IF($G14="","",IFERROR(VLOOKUP($D14&"|"&$E14,科目表!$A$5:$B$200,2,FALSE),"※未登録")) -> 非常勤職員手当 | P14: =IF(OR($G14="",$C14=""),"",IF($B14="決算整理",13,MOD(MONTH($C14)-4,12)+1)) -> 1 | Q14: =IF($G14="","",TRIM(IF(J14+K14+L14+M14<>$G14,"按分不一致 ","")&IF(O14="※未登録","科目未登録 ","")&IF(OR($H14="",ISERROR(MATCH($H14,{1,2,3,4,5,6,7,8},0))),"経費区分? ","")&IF($I14="","状態未設定 ","")&IF(AND(OR($I14="確認済",$I14="未確認"),$B14="月例",OR($C14="",$C14<DATE(年度+2018,4,1),$C14>DATE(年度+2019,3,31))),"年度外の日付 ","")&IF(AND(OR($I14="確認済",$I14="未確認"),O14="対象外"),"対象外の科目 ",""))) | R14: 月例!14
A15: 11 | B15: 月例 | C15: 46133 | D15: 職員給与 | E15: 非常勤職員手当 | F15: ４月分給与（短期分）3月時間外除く | G15: 317340 | H15: 2 | I15: 確認済 | J15: =IF($G15="","",IF($H15=1,$G15-ROUND($G15*10/23,0)-2*ROUND($G15/23,0),IF($H15=2,$G15,0))) -> 317340 | K15: =IF($G15="","",IF($H15=1,ROUND($G15*10/23,0),IF($H15=3,$G15-2*ROUND($G15/12,0),IF($H15=4,$G15,IF(OR($H15=5,$H15=7),ROUND($G15*10/11,0),0))))) -> 0 | L15: =IF($G15="","",IF($H15=1,ROUND($G15/23,0),IF($H15=3,ROUND($G15/12,0),IF($H15=5,$G15-ROUND($G15*10/11,0),IF($H15=8,$G15,0))))) -> 0 | M15: =IF($G15="","",IF($H15=1,ROUND($G15/23,0),IF($H15=3,ROUND($G15/12,0),IF($H15=6,$G15,IF($H15=7,$G15-ROUND($G15*10/11,0),0))))) -> 0 | N15: =IF($G15="","",K15+L15+M15) -> 0 | O15: =IF($G15="","",IFERROR(VLOOKUP($D15&"|"&$E15,科目表!$A$5:$B$200,2,FALSE),"※未登録")) -> 非常勤職員手当 | P15: =IF(OR($G15="",$C15=""),"",IF($B15="決算整理",13,MOD(MONTH($C15)-4,12)+1)) -> 1 | Q15: =IF($G15="","",TRIM(IF(J15+K15+L15+M15<>$G15,"按分不一致 ","")&IF(O15="※未登録","科目未登録 ","")&IF(OR($H15="",ISERROR(MATCH($H15,{1,2,3,4,5,6,7,8},0))),"経費区分? ","")&IF($I15="","状態未設定 ","")&IF(AND(OR($I15="確認済",$I15="未確認"),$B15="月例",OR($C15="",$C15<DATE(年度+2018,4,1),$C15>DATE(年度+2019,3,31))),"年度外の日付 ","")&IF(AND(OR($I15="確認済",$I15="未確認"),O15="対象外"),"対象外の科目 ",""))) | R15: 月例!15
A16: 12 | B16: 月例 | C16: 46133 | D16: 負担金 | E16: 互助会費 | F16: 助成金（４月長期分） | G16: 466 | H16: 3 | I16: 確認済 | J16: =IF($G16="","",IF($H16=1,$G16-ROUND($G16*10/23,0)-2*ROUND($G16/23,0),IF($H16=2,$G16,0))) -> 0 | K16: =IF($G16="","",IF($H16=1,ROUND($G16*10/23,0),IF($H16=3,$G16-2*ROUND($G16/12,0),IF($H16=4,$G16,IF(OR($H16=5,$H16=7),ROUND($G16*10/11,0),0))))) -> 388 | L16: =IF($G16="","",IF($H16=1,ROUND($G16/23,0),IF($H16=3,ROUND($G16/12,0),IF($H16=5,$G16-ROUND($G16*10/11,0),IF($H16=8,$G16,0))))) -> 39 | M16: =IF($G16="","",IF($H16=1,ROUND($G16/23,0),IF($H16=3,ROUND($G16/12,0),IF($H16=6,$G16,IF($H16=7,$G16-ROUND($G16*10/11,0),0))))) -> 39 | N16: =IF($G16="","",K16+L16+M16) -> 466 | O16: =IF($G16="","",IFERROR(VLOOKUP($D16&"|"&$E16,科目表!$A$5:$B$200,2,FALSE),"※未登録")) -> 互助会費 | P16: =IF(OR($G16="",$C16=""),"",IF($B16="決算整理",13,MOD(MONTH($C16)-4,12)+1)) -> 1 | Q16: =IF($G16="","",TRIM(IF(J16+K16+L16+M16<>$G16,"按分不一致 ","")&IF(O16="※未登録","科目未登録 ","")&IF(OR($H16="",ISERROR(MATCH($H16,{1,2,3,4,5,6,7,8},0))),"経費区分? ","")&IF($I16="","状態未設定 ","")&IF(AND(OR($I16="確認済",$I16="未確認"),$B16="月例",OR($C16="",$C16<DATE(年度+2018,4,1),$C16>DATE(年度+2019,3,31))),"年度外の日付 ","")&IF(AND(OR($I16="確認済",$I16="未確認"),O16="対象外"),"対象外の科目 ",""))) | R16: 月例!16
A17: 13 | B17: 月例 | C17: 46133 | D17: 負担金 | E17: 互助会費 | F17: 助成金（４月短期分） | G17: 240 | H17: 2 | I17: 確認済 | J17: =IF($G17="","",IF($H17=1,$G17-ROUND($G17*10/23,0)-2*ROUND($G17/23,0),IF($H17=2,$G17,0))) -> 240 | K17: =IF($G17="","",IF($H17=1,ROUND($G17*10/23,0),IF($H17=3,$G17-2*ROUND($G17/12,0),IF($H17=4,$G17,IF(OR($H17=5,$H17=7),ROUND($G17*10/11,0),0))))) -> 0 | L17: =IF($G17="","",IF($H17=1,ROUND($G17/23,0),IF($H17=3,ROUND($G17/12,0),IF($H17=5,$G17-ROUND($G17*10/11,0),IF($H17=8,$G17,0))))) -> 0 | M17: =IF($G17="","",IF($H17=1,ROUND($G17/23,0),IF($H17=3,ROUND($G17/12,0),IF($H17=6,$G17,IF($H17=7,$G17-ROUND($G17*10/11,0),0))))) -> 0 | N17: =IF($G17="","",K17+L17+M17) -> 0 | O17: =IF($G17="","",IFERROR(VLOOKUP($D17&"|"&$E17,科目表!$A$5:$B$200,2,FALSE),"※未登録")) -> 互助会費 | P17: =IF(OR($G17="",$C17=""),"",IF($B17="決算整理",13,MOD(MONTH($C17)-4,12)+1)) -> 1 | Q17: =IF($G17="","",TRIM(IF(J17+K17+L17+M17<>$G17,"按分不一致 ","")&IF(O17="※未登録","科目未登録 ","")&IF(OR($H17="",ISERROR(MATCH($H17,{1,2,3,4,5,6,7,8},0))),"経費区分? ","")&IF($I17="","状態未設定 ","")&IF(AND(OR($I17="確認済",$I17="未確認"),$B17="月例",OR($C17="",$C17<DATE(年度+2018,4,1),$C17>DATE(年度+2019,3,31))),"年度外の日付 ","")&IF(AND(OR($I17="確認済",$I17="未確認"),O17="対象外"),"対象外の科目 ",""))) | R17: 月例!17
A18: 14 | B18: 月例 | C18: 45044 | D18: 委託費 | F18: 個人番号管理システムシンクライアント（４～１０月） | G18: 24486 | H18: 2 | I18: 昨年実績 | J18: =IF($G18="","",IF($H18=1,$G18-ROUND($G18*10/23,0)-2*ROUND($G18/23,0),IF($H18=2,$G18,0))) -> 24486 | K18: =IF($G18="","",IF($H18=1,ROUND($G18*10/23,0),IF($H18=3,$G18-2*ROUND($G18/12,0),IF($H18=4,$G18,IF(OR($H18=5,$H18=7),ROUND($G18*10/11,0),0))))) -> 0 | L18: =IF($G18="","",IF($H18=1,ROUND($G18/23,0),IF($H18=3,ROUND($G18/12,0),IF($H18=5,$G18-ROUND($G18*10/11,0),IF($H18=8,$G18,0))))) -> 0 | M18: =IF($G18="","",IF($H18=1,ROUND($G18/23,0),IF($H18=3,ROUND($G18/12,0),IF($H18=6,$G18,IF($H18=7,$G18-ROUND($G18*10/11,0),0))))) -> 0 | N18: =IF($G18="","",K18+L18+M18) -> 0 | O18: =IF($G18="","",IFERROR(VLOOKUP($D18&"|"&$E18,科目表!$A$5:$B$200,2,FALSE),"※未登録")) -> 委託費 | P18: =IF(OR($G18="",$C18=""),"",IF($B18="決算整理",13,MOD(MONTH($C18)-4,12)+1)) -> 1 | Q18: =IF($G18="","",TRIM(IF(J18+K18+L18+M18<>$G18,"按分不一致 ","")&IF(O18="※未登録","科目未登録 ","")&IF(OR($H18="",ISERROR(MATCH($H18,{1,2,3,4,5,6,7,8},0))),"経費区分? ","")&IF($I18="","状態未設定 ","")&IF(AND(OR($I18="確認済",$I18="未確認"),$B18="月例",OR($C18="",$C18<DATE(年度+2018,4,1),$C18>DATE(年度+2019,3,31))),"年度外の日付 ","")&IF(AND(OR($I18="確認済",$I18="未確認"),O18="対象外"),"対象外の科目 ",""))) | R18: 月例!18
A19: 15 | B19: 月例 | C19: 45807 | D19: 事務費 | E19: 図書印刷費 | F19: 窓付封筒 １，０００枚 | G19: 49500 | H19: 2 | I19: 昨年実績 | J19: =IF($G19="","",IF($H19=1,$G19-ROUND($G19*10/23,0)-2*ROUND($G19/23,0),IF($H19=2,$G19,0))) -> 49500 | K19: =IF($G19="","",IF($H19=1,ROUND($G19*10/23,0),IF($H19=3,$G19-2*ROUND($G19/12,0),IF($H19=4,$G19,IF(OR($H19=5,$H19=7),ROUND($G19*10/11,0),0))))) -> 0 | L19: =IF($G19="","",IF($H19=1,ROUND($G19/23,0),IF($H19=3,ROUND($G19/12,0),IF($H19=5,$G19-ROUND($G19*10/11,0),IF($H19=8,$G19,0))))) -> 0 | M19: =IF($G19="","",IF($H19=1,ROUND($G19/23,0),IF($H19=3,ROUND($G19/12,0),IF($H19=6,$G19,IF($H19=7,$G19-ROUND($G19*10/11,0),0))))) -> 0 | N19: =IF($G19="","",K19+L19+M19) -> 0 | O19: =IF($G19="","",IFERROR(VLOOKUP($D19&"|"&$E19,科目表!$A$5:$B$200,2,FALSE),"※未登録")) -> 図書印刷費 | P19: =IF(OR($G19="",$C19=""),"",IF($B19="決算整理",13,MOD(MONTH($C19)-4,12)+1)) -> 2 | Q19: =IF($G19="","",TRIM(IF(J19+K19+L19+M19<>$G19,"按分不一致 ","")&IF(O19="※未登録","科目未登録 ","")&IF(OR($H19="",ISERROR(MATCH($H19,{1,2,3,4,5,6,7,8},0))),"経費区分? ","")&IF($I19="","状態未設定 ","")&IF(AND(OR($I19="確認済",$I19="未確認"),$B19="月例",OR($C19="",$C19<DATE(年度+2018,4,1),$C19>DATE(年度+2019,3,31))),"年度外の日付 ","")&IF(AND(OR($I19="確認済",$I19="未確認"),O19="対象外"),"対象外の科目 ",""))) | R19: 月例!19
A20: 16 | B20: 月例 | C20: 45061 | D20: 事務費 | E20: 図書印刷費 | F20: 定年延長と共済組合制度 ３０部 | G20: 2970 | H20: 3 | I20: 昨年実績 | J20: =IF($G20="","",IF($H20=1,$G20-ROUND($G20*10/23,0)-2*ROUND($G20/23,0),IF($H20=2,$G20,0))) -> 0 | K20: =IF($G20="","",IF($H20=1,ROUND($G20*10/23,0),IF($H20=3,$G20-2*ROUND($G20/12,0),IF($H20=4,$G20,IF(OR($H20=5,$H20=7),ROUND($G20*10/11,0),0))))) -> 2474 | L20: =IF($G20="","",IF($H20=1,ROUND($G20/23,0),IF($H20=3,ROUND($G20/12,0),IF($H20=5,$G20-ROUND($G20*10/11,0),IF($H20=8,$G20,0))))) -> 248 | M20: =IF($G20="","",IF($H20=1,ROUND($G20/23,0),IF($H20=3,ROUND($G20/12,0),IF($H20=6,$G20,IF($H20=7,$G20-ROUND($G20*10/11,0),0))))) -> 248 | N20: =IF($G20="","",K20+L20+M20) -> 2970 | O20: =IF($G20="","",IFERROR(VLOOKUP($D20&"|"&$E20,科目表!$A$5:$B$200,2,FALSE),"※未登録")) -> 図書印刷費 | P20: =IF(OR($G20="",$C20=""),"",IF($B20="決算整理",13,MOD(MONTH($C20)-4,12)+1)) -> 2 | Q20: =IF($G20="","",TRIM(IF(J20+K20+L20+M20<>$G20,"按分不一致 ","")&IF(O20="※未登録","科目未登録 ","")&IF(OR($H20="",ISERROR(MATCH($H20,{1,2,3,4,5,6,7,8},0))),"経費区分? ","")&IF($I20="","状態未設定 ","")&IF(AND(OR($I20="確認済",$I20="未確認"),$B20="月例",OR($C20="",$C20<DATE(年度+2018,4,1),$C20>DATE(年度+2019,3,31))),"年度外の日付 ","")&IF(AND(OR($I20="確認済",$I20="未確認"),O20="対象外"),"対象外の科目 ",""))) | R20: 月例!20
A21: 17 | B21: 月例 | C21: 45477 | D21: 事務費 | E21: 図書印刷費 | F21: 組合員原票（Ａ４）８００部 ほか | G21: 133650 | H21: 3 | I21: 昨年実績 | J21: =IF($G21="","",IF($H21=1,$G21-ROUND($G21*10/23,0)-2*ROUND($G21/23,0),IF($H21=2,$G21,0))) -> 0 | K21: =IF($G21="","",IF($H21=1,ROUND($G21*10/23,0),IF($H21=3,$G21-2*ROUND($G21/12,0),IF($H21=4,$G21,IF(OR($H21=5,$H21=7),ROUND($G21*10/11,0),0))))) -> 111374 | L21: =IF($G21="","",IF($H21=1,ROUND($G21/23,0),IF($H21=3,ROUND($G21/12,0),IF($H21=5,$G21-ROUND($G21*10/11,0),IF($H21=8,$G21,0))))) -> 11138 | M21: =IF($G21="","",IF($H21=1,ROUND($G21/23,0),IF($H21=3,ROUND($G21/12,0),IF($H21=6,$G21,IF($H21=7,$G21-ROUND($G21*10/11,0),0))))) -> 11138 | N21: =IF($G21="","",K21+L21+M21) -> 133650 | O21: =IF($G21="","",IFERROR(VLOOKUP($D21&"|"&$E21,科目表!$A$5:$B$200,2,FALSE),"※未登録")) -> 図書印刷費 | P21: =IF(OR($G21="",$C21=""),"",IF($B21="決算整理",13,MOD(MONTH($C21)-4,12)+1)) -> 4 | Q21: =IF($G21="","",TRIM(IF(J21+K21+L21+M21<>$G21,"按分不一致 ","")&IF(O21="※未登録","科目未登録 ","")&IF(OR($H21="",ISERROR(MATCH($H21,{1,2,3,4,5,6,7,8},0))),"経費区分? ","")&IF($I21="","状態未設定 ","")&IF(AND(OR($I21="確認済",$I21="未確認"),$B21="月例",OR($C21="",$C21<DATE(年度+2018,4,1),$C21>DATE(年度+2019,3,31))),"年度外の日付 ","")&IF(AND(OR($I21="確認済",$I21="未確認"),O21="対象外"),"対象外の科目 ",""))) | R21: 月例!21
A22: 18 | B22: 月例 | C22: 44377 | D22: 事務費 | E22: 事務用消耗品費 | F22: 鋳造ゴム印 ３号以下214字 他 | G22: 9733 | H22: 3 | I22: 昨年実績 | J22: =IF($G22="","",IF($H22=1,$G22-ROUND($G22*10/23,0)-2*ROUND($G22/23,0),IF($H22=2,$G22,0))) -> 0 | K22: =IF($G22="","",IF($H22=1,ROUND($G22*10/23,0),IF($H22=3,$G22-2*ROUND($G22/12,0),IF($H22=4,$G22,IF(OR($H22=5,$H22=7),ROUND($G22*10/11,0),0))))) -> 8111 | L22: =IF($G22="","",IF($H22=1,ROUND($G22/23,0),IF($H22=3,ROUND($G22/12,0),IF($H22=5,$G22-ROUND($G22*10/11,0),IF($H22=8,$G22,0))))) -> 811 | M22: =IF($G22="","",IF($H22=1,ROUND($G22/23,0),IF($H22=3,ROUND($G22/12,0),IF($H22=6,$G22,IF($H22=7,$G22-ROUND($G22*10/11,0),0))))) -> 811 | N22: =IF($G22="","",K22+L22+M22) -> 9733 | O22: =IF($G22="","",IFERROR(VLOOKUP($D22&"|"&$E22,科目表!$A$5:$B$200,2,FALSE),"※未登録")) -> 事務用消耗品費 | P22: =IF(OR($G22="",$C22=""),"",IF($B22="決算整理",13,MOD(MONTH($C22)-4,12)+1)) -> 3 | Q22: =IF($G22="","",TRIM(IF(J22+K22+L22+M22<>$G22,"按分不一致 ","")&IF(O22="※未登録","科目未登録 ","")&IF(OR($H22="",ISERROR(MATCH($H22,{1,2,3,4,5,6,7,8},0))),"経費区分? ","")&IF($I22="","状態未設定 ","")&IF(AND(OR($I22="確認済",$I22="未確認"),$B22="月例",OR($C22="",$C22<DATE(年度+2018,4,1),$C22>DATE(年度+2019,3,31))),"年度外の日付 ","")&IF(AND(OR($I22="確認済",$I22="未確認"),O22="対象外"),"対象外の科目 ",""))) | R22: 月例!22
A23: 19 | B23: 月例 | C23: 46171 | D23: 事務費 | E23: 事務用消耗品費 | F23: ラベル用紙 LBP-F7656-100N ２冊 他 | G23: 43890 | H23: 2 | I23: 確認済 | J23: =IF($G23="","",IF($H23=1,$G23-ROUND($G23*10/23,0)-2*ROUND($G23/23,0),IF($H23=2,$G23,0))) -> 43890 | K23: =IF($G23="","",IF($H23=1,ROUND($G23*10/23,0),IF($H23=3,$G23-2*ROUND($G23/12,0),IF($H23=4,$G23,IF(OR($H23=5,$H23=7),ROUND($G23*10/11,0),0))))) -> 0 | L23: =IF($G23="","",IF($H23=1,ROUND($G23/23,0),IF($H23=3,ROUND($G23/12,0),IF($H23=5,$G23-ROUND($G23*10/11,0),IF($H23=8,$G23,0))))) -> 0 | M23: =IF($G23="","",IF($H23=1,ROUND($G23/23,0),IF($H23=3,ROUND($G23/12,0),IF($H23=6,$G23,IF($H23=7,$G23-ROUND($G23*10/11,0),0))))) -> 0 | N23: =IF($G23="","",K23+L23+M23) -> 0 | O23: =IF($G23="","",IFERROR(VLOOKUP($D23&"|"&$E23,科目表!$A$5:$B$200,2,FALSE),"※未登録")) -> 事務用消耗品費 | P23: =IF(OR($G23="",$C23=""),"",IF($B23="決算整理",13,MOD(MONTH($C23)-4,12)+1)) -> 2 | Q23: =IF($G23="","",TRIM(IF(J23+K23+L23+M23<>$G23,"按分不一致 ","")&IF(O23="※未登録","科目未登録 ","")&IF(OR($H23="",ISERROR(MATCH($H23,{1,2,3,4,5,6,7,8},0))),"経費区分? ","")&IF($I23="","状態未設定 ","")&IF(AND(OR($I23="確認済",$I23="未確認"),$B23="月例",OR($C23="",$C23<DATE(年度+2018,4,1),$C23>DATE(年度+2019,3,31))),"年度外の日付 ","")&IF(AND(OR($I23="確認済",$I23="未確認"),O23="対象外"),"対象外の科目 ",""))) | R23: 月例!23
A24: 20 | B24: 月例 | C24: 46154 | D24: 事務費負担金払込金 | F24: ４月分事務費負担金払込金と連合会交付金との相殺 | G24: 5366000 | H24: 5 | I24: 確認済 | J24: =IF($G24="","",IF($H24=1,$G24-ROUND($G24*10/23,0)-2*ROUND($G24/23,0),IF($H24=2,$G24,0))) -> 0 | K24: =IF($G24="","",IF($H24=1,ROUND($G24*10/23,0),IF($H24=3,$G24-2*ROUND($G24/12,0),IF($H24=4,$G24,IF(OR($H24=5,$H24=7),ROUND($G24*10/11,0),0))))) -> 4878182 | L24: =IF($G24="","",IF($H24=1,ROUND($G24/23,0),IF($H24=3,ROUND($G24/12,0),IF($H24=5,$G24-ROUND($G24*10/11,0),IF($H24=8,$G24,0))))) -> 487818 | M24: =IF($G24="","",IF($H24=1,ROUND($G24/23,0),IF($H24=3,ROUND($G24/12,0),IF($H24=6,$G24,IF($H24=7,$G24-ROUND($G24*10/11,0),0))))) -> 0 | N24: =IF($G24="","",K24+L24+M24) -> 5366000 | O24: =IF($G24="","",IFERROR(VLOOKUP($D24&"|"&$E24,科目表!$A$5:$B$200,2,FALSE),"※未登録")) -> 事務費負担金払込金 | P24: =IF(OR($G24="",$C24=""),"",IF($B24="決算整理",13,MOD(MONTH($C24)-4,12)+1)) -> 2 | Q24: =IF($G24="","",TRIM(IF(J24+K24+L24+M24<>$G24,"按分不一致 ","")&IF(O24="※未登録","科目未登録 ","")&IF(OR($H24="",ISERROR(MATCH($H24,{1,2,3,4,5,6,7,8},0))),"経費区分? ","")&IF($I24="","状態未設定 ","")&IF(AND(OR($I24="確認済",$I24="未確認"),$B24="月例",OR($C24="",$C24<DATE(年度+2018,4,1),$C24>DATE(年度+2019,3,31))),"年度外の日付 ","")&IF(AND(OR($I24="確認済",$I24="未確認"),O24="対象外"),"対象外の科目 ",""))) | R24: 月例!24
A25: 21 | B25: 月例 | C25: 46139 | D25: 負担金 | E25: 負担金 | F25: 共済短期・介護・子ども子育て負担金（4月月例分）長期 | G25: 22035 | H25: 3 | I25: 確認済 | J25: =IF($G25="","",IF($H25=1,$G25-ROUND($G25*10/23,0)-2*ROUND($G25/23,0),IF($H25=2,$G25,0))) -> 0 | K25: =IF($G25="","",IF($H25=1,ROUND($G25*10/23,0),IF($H25=3,$G25-2*ROUND($G25/12,0),IF($H25=4,$G25,IF(OR($H25=5,$H25=7),ROUND($G25*10/11,0),0))))) -> 18363 | L25: =IF($G25="","",IF($H25=1,ROUND($G25/23,0),IF($H25=3,ROUND($G25/12,0),IF($H25=5,$G25-ROUND($G25*10/11,0),IF($H25=8,$G25,0))))) -> 1836 | M25: =IF($G25="","",IF($H25=1,ROUND($G25/23,0),IF($H25=3,ROUND($G25/12,0),IF($H25=6,$G25,IF($H25=7,$G25-ROUND($G25*10/11,0),0))))) -> 1836 | N25: =IF($G25="","",K25+L25+M25) -> 22035 | O25: =IF($G25="","",IFERROR(VLOOKUP($D25&"|"&$E25,科目表!$A$5:$B$200,2,FALSE),"※未登録")) -> 共済負担金等 | P25: =IF(OR($G25="",$C25=""),"",IF($B25="決算整理",13,MOD(MONTH($C25)-4,12)+1)) -> 1 | Q25: =IF($G25="","",TRIM(IF(J25+K25+L25+M25<>$G25,"按分不一致 ","")&IF(O25="※未登録","科目未登録 ","")&IF(OR($H25="",ISERROR(MATCH($H25,{1,2,3,4,5,6,7,8},0))),"経費区分? ","")&IF($I25="","状態未設定 ","")&IF(AND(OR($I25="確認済",$I25="未確認"),$B25="月例",OR($C25="",$C25<DATE(年度+2018,4,1),$C25>DATE(年度+2019,3,31))),"年度外の日付 ","")&IF(AND(OR($I25="確認済",$I25="未確認"),O25="対象外"),"対象外の科目 ",""))) | R25: 月例!25
A26: 22 | B26: 月例 | C26: 46139 | D26: 負担金 | E26: 負担金 | F26: 共済短期・介護・子ども子育て負担金（4月月例分）短期 | G26: 37074 | H26: 2 | I26: 確認済 | J26: =IF($G26="","",IF($H26=1,$G26-ROUND($G26*10/23,0)-2*ROUND($G26/23,0),IF($H26=2,$G26,0))) -> 37074 | K26: =IF($G26="","",IF($H26=1,ROUND($G26*10/23,0),IF($H26=3,$G26-2*ROUND($G26/12,0),IF($H26=4,$G26,IF(OR($H26=5,$H26=7),ROUND($G26*10/11,0),0))))) -> 0 | L26: =IF($G26="","",IF($H26=1,ROUND($G26/23,0),IF($H26=3,ROUND($G26/12,0),IF($H26=5,$G26-ROUND($G26*10/11,0),IF($H26=8,$G26,0))))) -> 0 | M26: =IF($G26="","",IF($H26=1,ROUND($G26/23,0),IF($H26=3,ROUND($G26/12,0),IF($H26=6,$G26,IF($H26=7,$G26-ROUND($G26*10/11,0),0))))) -> 0 | N26: =IF($G26="","",K26+L26+M26) -> 0 | O26: =IF($G26="","",IFERROR(VLOOKUP($D26&"|"&$E26,科目表!$A$5:$B$200,2,FALSE),"※未登録")) -> 共済負担金等 | P26: =IF(OR($G26="",$C26=""),"",IF($B26="決算整理",13,MOD(MONTH($C26)-4,12)+1)) -> 1 | Q26: =IF($G26="","",TRIM(IF(J26+K26+L26+M26<>$G26,"按分不一致 ","")&IF(O26="※未登録","科目未登録 ","")&IF(OR($H26="",ISERROR(MATCH($H26,{1,2,3,4,5,6,7,8},0))),"経費区分? ","")&IF($I26="","状態未設定 ","")&IF(AND(OR($I26="確認済",$I26="未確認"),$B26="月例",OR($C26="",$C26<DATE(年度+2018,4,1),$C26>DATE(年度+2019,3,31))),"年度外の日付 ","")&IF(AND(OR($I26="確認済",$I26="未確認"),O26="対象外"),"対象外の科目 ",""))) | R26: 月例!26
A27: 23 | B27: 月例 | C27: 46153 | D27: 事務費 | E27: 送金料 | F27: 振込手数料（広銀）４月分 長期分 | G27: 18493 | H27: 3 | I27: 確認済 | J27: =IF($G27="","",IF($H27=1,$G27-ROUND($G27*10/23,0)-2*ROUND($G27/23,0),IF($H27=2,$G27,0))) -> 0 | K27: =IF($G27="","",IF($H27=1,ROUND($G27*10/23,0),IF($H27=3,$G27-2*ROUND($G27/12,0),IF($H27=4,$G27,IF(OR($H27=5,$H27=7),ROUND($G27*10/11,0),0))))) -> 15411 | L27: =IF($G27="","",IF($H27=1,ROUND($G27/23,0),IF($H27=3,ROUND($G27/12,0),IF($H27=5,$G27-ROUND($G27*10/11,0),IF($H27=8,$G27,0))))) -> 1541 | M27: =IF($G27="","",IF($H27=1,ROUND($G27/23,0),IF($H27=3,ROUND($G27/12,0),IF($H27=6,$G27,IF($H27=7,$G27-ROUND($G27*10/11,0),0))))) -> 1541 | N27: =IF($G27="","",K27+L27+M27) -> 18493 | O27: =IF($G27="","",IFERROR(VLOOKUP($D27&"|"&$E27,科目表!$A$5:$B$200,2,FALSE),"※未登録")) -> 送金料 | P27: =IF(OR($G27="",$C27=""),"",IF($B27="決算整理",13,MOD(MONTH($C27)-4,12)+1)) -> 2 | Q27: =IF($G27="","",TRIM(IF(J27+K27+L27+M27<>$G27,"按分不一致 ","")&IF(O27="※未登録","科目未登録 ","")&IF(OR($H27="",ISERROR(MATCH($H27,{1,2,3,4,5,6,7,8},0))),"経費区分? ","")&IF($I27="","状態未設定 ","")&IF(AND(OR($I27="確認済",$I27="未確認"),$B27="月例",OR($C27="",$C27<DATE(年度+2018,4,1),$C27>DATE(年度+2019,3,31))),"年度外の日付 ","")&IF(AND(OR($I27="確認済",$I27="未確認"),O27="対象外"),"対象外の科目 ",""))) | R27: 月例!27
A28: 24 | B28: 月例 | C28: 46153 | D28: 事務費 | E28: 送金料 | F28: 振込手数料（広銀）４月分 短期分 | G28: 139883 | H28: 2 | I28: 確認済 | J28: =IF($G28="","",IF($H28=1,$G28-ROUND($G28*10/23,0)-2*ROUND($G28/23,0),IF($H28=2,$G28,0))) -> 139883 | K28: =IF($G28="","",IF($H28=1,ROUND($G28*10/23,0),IF($H28=3,$G28-2*ROUND($G28/12,0),IF($H28=4,$G28,IF(OR($H28=5,$H28=7),ROUND($G28*10/11,0),0))))) -> 0 | L28: =IF($G28="","",IF($H28=1,ROUND($G28/23,0),IF($H28=3,ROUND($G28/12,0),IF($H28=5,$G28-ROUND($G28*10/11,0),IF($H28=8,$G28,0))))) -> 0 | M28: =IF($G28="","",IF($H28=1,ROUND($G28/23,0),IF($H28=3,ROUND($G28/12,0),IF($H28=6,$G28,IF($H28=7,$G28-ROUND($G28*10/11,0),0))))) -> 0 | N28: =IF($G28="","",K28+L28+M28) -> 0 | O28: =IF($G28="","",IFERROR(VLOOKUP($D28&"|"&$E28,科目表!$A$5:$B$200,2,FALSE),"※未登録")) -> 送金料 | P28: =IF(OR($G28="",$C28=""),"",IF($B28="決算整理",13,MOD(MONTH($C28)-4,12)+1)) -> 2 | Q28: =IF($G28="","",TRIM(IF(J28+K28+L28+M28<>$G28,"按分不一致 ","")&IF(O28="※未登録","科目未登録 ","")&IF(OR($H28="",ISERROR(MATCH($H28,{1,2,3,4,5,6,7,8},0))),"経費区分? ","")&IF($I28="","状態未設定 ","")&IF(AND(OR($I28="確認済",$I28="未確認"),$B28="月例",OR($C28="",$C28<DATE(年度+2018,4,1),$C28>DATE(年度+2019,3,31))),"年度外の日付 ","")&IF(AND(OR($I28="確認済",$I28="未確認"),O28="対象外"),"対象外の科目 ",""))) | R28: 月例!28
A29: 25 | B29: 月例 | C29: 46171 | D29: 事務費 | E29: 事務用消耗品費 | F29: ダイヤルロック UNK-02 7個 他 | G29: 14518 | H29: 2 | I29: 確認済 | J29: =IF($G29="","",IF($H29=1,$G29-ROUND($G29*10/23,0)-2*ROUND($G29/23,0),IF($H29=2,$G29,0))) -> 14518 | K29: =IF($G29="","",IF($H29=1,ROUND($G29*10/23,0),IF($H29=3,$G29-2*ROUND($G29/12,0),IF($H29=4,$G29,IF(OR($H29=5,$H29=7),ROUND($G29*10/11,0),0))))) -> 0 | L29: =IF($G29="","",IF($H29=1,ROUND($G29/23,0),IF($H29=3,ROUND($G29/12,0),IF($H29=5,$G29-ROUND($G29*10/11,0),IF($H29=8,$G29,0))))) -> 0 | M29: =IF($G29="","",IF($H29=1,ROUND($G29/23,0),IF($H29=3,ROUND($G29/12,0),IF($H29=6,$G29,IF($H29=7,$G29-ROUND($G29*10/11,0),0))))) -> 0 | N29: =IF($G29="","",K29+L29+M29) -> 0 | O29: =IF($G29="","",IFERROR(VLOOKUP($D29&"|"&$E29,科目表!$A$5:$B$200,2,FALSE),"※未登録")) -> 事務用消耗品費 | P29: =IF(OR($G29="",$C29=""),"",IF($B29="決算整理",13,MOD(MONTH($C29)-4,12)+1)) -> 2 | Q29: =IF($G29="","",TRIM(IF(J29+K29+L29+M29<>$G29,"按分不一致 ","")&IF(O29="※未登録","科目未登録 ","")&IF(OR($H29="",ISERROR(MATCH($H29,{1,2,3,4,5,6,7,8},0))),"経費区分? ","")&IF($I29="","状態未設定 ","")&IF(AND(OR($I29="確認済",$I29="未確認"),$B29="月例",OR($C29="",$C29<DATE(年度+2018,4,1),$C29>DATE(年度+2019,3,31))),"年度外の日付 ","")&IF(AND(OR($I29="確認済",$I29="未確認"),O29="対象外"),"対象外の科目 ",""))) | R29: 月例!29
A30: 26 | B30: 月例 | C30: 46171 | D30: 賃借料 | F30: パソコン（業務経理用）４月分 | G30: 5060 | H30: 2 | I30: 確認済 | J30: =IF($G30="","",IF($H30=1,$G30-ROUND($G30*10/23,0)-2*ROUND($G30/23,0),IF($H30=2,$G30,0))) -> 5060 | K30: =IF($G30="","",IF($H30=1,ROUND($G30*10/23,0),IF($H30=3,$G30-2*ROUND($G30/12,0),IF($H30=4,$G30,IF(OR($H30=5,$H30=7),ROUND($G30*10/11,0),0))))) -> 0 | L30: =IF($G30="","",IF($H30=1,ROUND($G30/23,0),IF($H30=3,ROUND($G30/12,0),IF($H30=5,$G30-ROUND($G30*10/11,0),IF($H30=8,$G30,0))))) -> 0 | M30: =IF($G30="","",IF($H30=1,ROUND($G30/23,0),IF($H30=3,ROUND($G30/12,0),IF($H30=6,$G30,IF($H30=7,$G30-ROUND($G30*10/11,0),0))))) -> 0 | N30: =IF($G30="","",K30+L30+M30) -> 0 | O30: =IF($G30="","",IFERROR(VLOOKUP($D30&"|"&$E30,科目表!$A$5:$B$200,2,FALSE),"※未登録")) -> 賃借料 | P30: =IF(OR($G30="",$C30=""),"",IF($B30="決算整理",13,MOD(MONTH($C30)-4,12)+1)) -> 2 | Q30: =IF($G30="","",TRIM(IF(J30+K30+L30+M30<>$G30,"按分不一致 ","")&IF(O30="※未登録","科目未登録 ","")&IF(OR($H30="",ISERROR(MATCH($H30,{1,2,3,4,5,6,7,8},0))),"経費区分? ","")&IF($I30="","状態未設定 ","")&IF(AND(OR($I30="確認済",$I30="未確認"),$B30="月例",OR($C30="",$C30<DATE(年度+2018,4,1),$C30>DATE(年度+2019,3,31))),"年度外の日付 ","")&IF(AND(OR($I30="確認済",$I30="未確認"),O30="対象外"),"対象外の科目 ",""))) | R30: 月例!30
A31: 27 | B31: 月例 | C31: 46157 | D31: 賃金 | F31: 臨時職員賃金４月分 天畠吏梨外1名分（短期１００％） | G31: 425880 | H31: 2 | I31: 確認済 | J31: =IF($G31="","",IF($H31=1,$G31-ROUND($G31*10/23,0)-2*ROUND($G31/23,0),IF($H31=2,$G31,0))) -> 425880 | K31: =IF($G31="","",IF($H31=1,ROUND($G31*10/23,0),IF($H31=3,$G31-2*ROUND($G31/12,0),IF($H31=4,$G31,IF(OR($H31=5,$H31=7),ROUND($G31*10/11,0),0))))) -> 0 | L31: =IF($G31="","",IF($H31=1,ROUND($G31/23,0),IF($H31=3,ROUND($G31/12,0),IF($H31=5,$G31-ROUND($G31*10/11,0),IF($H31=8,$G31,0))))) -> 0 | M31: =IF($G31="","",IF($H31=1,ROUND($G31/23,0),IF($H31=3,ROUND($G31/12,0),IF($H31=6,$G31,IF($H31=7,$G31-ROUND($G31*10/11,0),0))))) -> 0 | N31: =IF($G31="","",K31+L31+M31) -> 0 | O31: =IF($G31="","",IFERROR(VLOOKUP($D31&"|"&$E31,科目表!$A$5:$B$200,2,FALSE),"※未登録")) -> 賃金 | P31: =IF(OR($G31="",$C31=""),"",IF($B31="決算整理",13,MOD(MONTH($C31)-4,12)+1)) -> 2 | Q31: =IF($G31="","",TRIM(IF(J31+K31+L31+M31<>$G31,"按分不一致 ","")&IF(O31="※未登録","科目未登録 ","")&IF(OR($H31="",ISERROR(MATCH($H31,{1,2,3,4,5,6,7,8},0))),"経費区分? ","")&IF($I31="","状態未設定 ","")&IF(AND(OR($I31="確認済",$I31="未確認"),$B31="月例",OR($C31="",$C31<DATE(年度+2018,4,1),$C31>DATE(年度+2019,3,31))),"年度外の日付 ","")&IF(AND(OR($I31="確認済",$I31="未確認"),O31="対象外"),"対象外の科目 ",""))) | R31: 月例!31
A32: 28 | B32: 月例 | C32: 46162 | D32: 委託費 | F32: 社会保障等制度 中間サーバー等運営負担金 | G32: 1798068 | H32: 2 | I32: 確認済 | J32: =IF($G32="","",IF($H32=1,$G32-ROUND($G32*10/23,0)-2*ROUND($G32/23,0),IF($H32=2,$G32,0))) -> 1798068 | K32: =IF($G32="","",IF($H32=1,ROUND($G32*10/23,0),IF($H32=3,$G32-2*ROUND($G32/12,0),IF($H32=4,$G32,IF(OR($H32=5,$H32=7),ROUND($G32*10/11,0),0))))) -> 0 | L32: =IF($G32="","",IF($H32=1,ROUND($G32/23,0),IF($H32=3,ROUND($G32/12,0),IF($H32=5,$G32-ROUND($G32*10/11,0),IF($H32=8,$G32,0))))) -> 0 | M32: =IF($G32="","",IF($H32=1,ROUND($G32/23,0),IF($H32=3,ROUND($G32/12,0),IF($H32=6,$G32,IF($H32=7,$G32-ROUND($G32*10/11,0),0))))) -> 0 | N32: =IF($G32="","",K32+L32+M32) -> 0 | O32: =IF($G32="","",IFERROR(VLOOKUP($D32&"|"&$E32,科目表!$A$5:$B$200,2,FALSE),"※未登録")) -> 委託費 | P32: =IF(OR($G32="",$C32=""),"",IF($B32="決算整理",13,MOD(MONTH($C32)-4,12)+1)) -> 2 | Q32: =IF($G32="","",TRIM(IF(J32+K32+L32+M32<>$G32,"按分不一致 ","")&IF(O32="※未登録","科目未登録 ","")&IF(OR($H32="",ISERROR(MATCH($H32,{1,2,3,4,5,6,7,8},0))),"経費区分? ","")&IF($I32="","状態未設定 ","")&IF(AND(OR($I32="確認済",$I32="未確認"),$B32="月例",OR($C32="",$C32<DATE(年度+2018,4,1),$C32>DATE(年度+2019,3,31))),"年度外の日付 ","")&IF(AND(OR($I32="確認済",$I32="未確認"),O32="対象外"),"対象外の科目 ",""))) | R32: 月例!32
A33: 29 | B33: 月例 | C33: 46171 | D33: 事務費 | E33: 送金料 | F33: ゆうちょ銀行手数料（４月分）短期 | G33: 109019 | H33: 2 | I33: 確認済 | J33: =IF($G33="","",IF($H33=1,$G33-ROUND($G33*10/23,0)-2*ROUND($G33/23,0),IF($H33=2,$G33,0))) -> 109019 | K33: =IF($G33="","",IF($H33=1,ROUND($G33*10/23,0),IF($H33=3,$G33-2*ROUND($G33/12,0),IF($H33=4,$G33,IF(OR($H33=5,$H33=7),ROUND($G33*10/11,0),0))))) -> 0 | L33: =IF($G33="","",IF($H33=1,ROUND($G33/23,0),IF($H33=3,ROUND($G33/12,0),IF($H33=5,$G33-ROUND($G33*10/11,0),IF($H33=8,$G33,0))))) -> 0 | M33: =IF($G33="","",IF($H33=1,ROUND($G33/23,0),IF($H33=3,ROUND($G33/12,0),IF($H33=6,$G33,IF($H33=7,$G33-ROUND($G33*10/11,0),0))))) -> 0 | N33: =IF($G33="","",K33+L33+M33) -> 0 | O33: =IF($G33="","",IFERROR(VLOOKUP($D33&"|"&$E33,科目表!$A$5:$B$200,2,FALSE),"※未登録")) -> 送金料 | P33: =IF(OR($G33="",$C33=""),"",IF($B33="決算整理",13,MOD(MONTH($C33)-4,12)+1)) -> 2 | Q33: =IF($G33="","",TRIM(IF(J33+K33+L33+M33<>$G33,"按分不一致 ","")&IF(O33="※未登録","科目未登録 ","")&IF(OR($H33="",ISERROR(MATCH($H33,{1,2,3,4,5,6,7,8},0))),"経費区分? ","")&IF($I33="","状態未設定 ","")&IF(AND(OR($I33="確認済",$I33="未確認"),$B33="月例",OR($C33="",$C33<DATE(年度+2018,4,1),$C33>DATE(年度+2019,3,31))),"年度外の日付 ","")&IF(AND(OR($I33="確認済",$I33="未確認"),O33="対象外"),"対象外の科目 ",""))) | R33: 月例!33
A34: 30 | B34: 月例 | C34: 46171 | D34: 事務費 | E34: 雑費 | F34: ゆうちょ銀行振替口座残高証明（４月分）短期 | G34: 550 | H34: 2 | I34: 確認済 | J34: =IF($G34="","",IF($H34=1,$G34-ROUND($G34*10/23,0)-2*ROUND($G34/23,0),IF($H34=2,$G34,0))) -> 550 | K34: =IF($G34="","",IF($H34=1,ROUND($G34*10/23,0),IF($H34=3,$G34-2*ROUND($G34/12,0),IF($H34=4,$G34,IF(OR($H34=5,$H34=7),ROUND($G34*10/11,0),0))))) -> 0 | L34: =IF($G34="","",IF($H34=1,ROUND($G34/23,0),IF($H34=3,ROUND($G34/12,0),IF($H34=5,$G34-ROUND($G34*10/11,0),IF($H34=8,$G34,0))))) -> 0 | M34: =IF($G34="","",IF($H34=1,ROUND($G34/23,0),IF($H34=3,ROUND($G34/12,0),IF($H34=6,$G34,IF($H34=7,$G34-ROUND($G34*10/11,0),0))))) -> 0 | N34: =IF($G34="","",K34+L34+M34) -> 0 | O34: =IF($G34="","",IFERROR(VLOOKUP($D34&"|"&$E34,科目表!$A$5:$B$200,2,FALSE),"※未登録")) -> 事務費・雑費 | P34: =IF(OR($G34="",$C34=""),"",IF($B34="決算整理",13,MOD(MONTH($C34)-4,12)+1)) -> 2 | Q34: =IF($G34="","",TRIM(IF(J34+K34+L34+M34<>$G34,"按分不一致 ","")&IF(O34="※未登録","科目未登録 ","")&IF(OR($H34="",ISERROR(MATCH($H34,{1,2,3,4,5,6,7,8},0))),"経費区分? ","")&IF($I34="","状態未設定 ","")&IF(AND(OR($I34="確認済",$I34="未確認"),$B34="月例",OR($C34="",$C34<DATE(年度+2018,4,1),$C34>DATE(年度+2019,3,31))),"年度外の日付 ","")&IF(AND(OR($I34="確認済",$I34="未確認"),O34="対象外"),"対象外の科目 ",""))) | R34: 月例!34
A35: 31 | B35: 月例 | C35: 46163 | D35: 職員給与 | E35: 非常勤職員手当 | F35: ５月分給与（長期分） | G35: 380800 | H35: 3 | I35: 確認済 | J35: =IF($G35="","",IF($H35=1,$G35-ROUND($G35*10/23,0)-2*ROUND($G35/23,0),IF($H35=2,$G35,0))) -> 0 | K35: =IF($G35="","",IF($H35=1,ROUND($G35*10/23,0),IF($H35=3,$G35-2*ROUND($G35/12,0),IF($H35=4,$G35,IF(OR($H35=5,$H35=7),ROUND($G35*10/11,0),0))))) -> 317334 | L35: =IF($G35="","",IF($H35=1,ROUND($G35/23,0),IF($H35=3,ROUND($G35/12,0),IF($H35=5,$G35-ROUND($G35*10/11,0),IF($H35=8,$G35,0))))) -> 31733 | M35: =IF($G35="","",IF($H35=1,ROUND($G35/23,0),IF($H35=3,ROUND($G35/12,0),IF($H35=6,$G35,IF($H35=7,$G35-ROUND($G35*10/11,0),0))))) -> 31733 | N35: =IF($G35="","",K35+L35+M35) -> 380800 | O35: =IF($G35="","",IFERROR(VLOOKUP($D35&"|"&$E35,科目表!$A$5:$B$200,2,FALSE),"※未登録")) -> 非常勤職員手当 | P35: =IF(OR($G35="",$C35=""),"",IF($B35="決算整理",13,MOD(MONTH($C35)-4,12)+1)) -> 2 | Q35: =IF($G35="","",TRIM(IF(J35+K35+L35+M35<>$G35,"按分不一致 ","")&IF(O35="※未登録","科目未登録 ","")&IF(OR($H35="",ISERROR(MATCH($H35,{1,2,3,4,5,6,7,8},0))),"経費区分? ","")&IF($I35="","状態未設定 ","")&IF(AND(OR($I35="確認済",$I35="未確認"),$B35="月例",OR($C35="",$C35<DATE(年度+2018,4,1),$C35>DATE(年度+2019,3,31))),"年度外の日付 ","")&IF(AND(OR($I35="確認済",$I35="未確認"),O35="対象外"),"対象外の科目 ",""))) | R35: 月例!35
A36: 32 | B36: 月例 | C36: 46163 | D36: 職員給与 | E36: 非常勤職員手当 | F36: ５月分給与（短期分） | G36: 248436 | H36: 2 | I36: 確認済 | J36: =IF($G36="","",IF($H36=1,$G36-ROUND($G36*10/23,0)-2*ROUND($G36/23,0),IF($H36=2,$G36,0))) -> 248436 | K36: =IF($G36="","",IF($H36=1,ROUND($G36*10/23,0),IF($H36=3,$G36-2*ROUND($G36/12,0),IF($H36=4,$G36,IF(OR($H36=5,$H36=7),ROUND($G36*10/11,0),0))))) -> 0 | L36: =IF($G36="","",IF($H36=1,ROUND($G36/23,0),IF($H36=3,ROUND($G36/12,0),IF($H36=5,$G36-ROUND($G36*10/11,0),IF($H36=8,$G36,0))))) -> 0 | M36: =IF($G36="","",IF($H36=1,ROUND($G36/23,0),IF($H36=3,ROUND($G36/12,0),IF($H36=6,$G36,IF($H36=7,$G36-ROUND($G36*10/11,0),0))))) -> 0 | N36: =IF($G36="","",K36+L36+M36) -> 0 | O36: =IF($G36="","",IFERROR(VLOOKUP($D36&"|"&$E36,科目表!$A$5:$B$200,2,FALSE),"※未登録")) -> 非常勤職員手当 | P36: =IF(OR($G36="",$C36=""),"",IF($B36="決算整理",13,MOD(MONTH($C36)-4,12)+1)) -> 2 | Q36: =IF($G36="","",TRIM(IF(J36+K36+L36+M36<>$G36,"按分不一致 ","")&IF(O36="※未登録","科目未登録 ","")&IF(OR($H36="",ISERROR(MATCH($H36,{1,2,3,4,5,6,7,8},0))),"経費区分? ","")&IF($I36="","状態未設定 ","")&IF(AND(OR($I36="確認済",$I36="未確認"),$B36="月例",OR($C36="",$C36<DATE(年度+2018,4,1),$C36>DATE(年度+2019,3,31))),"年度外の日付 ","")&IF(AND(OR($I36="確認済",$I36="未確認"),O36="対象外"),"対象外の科目 ",""))) | R36: 月例!36
A37: 33 | B37: 月例 | C37: 46163 | D37: 負担金 | E37: 互助会費 | F37: 助成金（５月長期分） | G37: 466 | H37: 3 | I37: 確認済 | J37: =IF($G37="","",IF($H37=1,$G37-ROUND($G37*10/23,0)-2*ROUND($G37/23,0),IF($H37=2,$G37,0))) -> 0 | K37: =IF($G37="","",IF($H37=1,ROUND($G37*10/23,0),IF($H37=3,$G37-2*ROUND($G37/12,0),IF($H37=4,$G37,IF(OR($H37=5,$H37=7),ROUND($G37*10/11,0),0))))) -> 388 | L37: =IF($G37="","",IF($H37=1,ROUND($G37/23,0),IF($H37=3,ROUND($G37/12,0),IF($H37=5,$G37-ROUND($G37*10/11,0),IF($H37=8,$G37,0))))) -> 39 | M37: =IF($G37="","",IF($H37=1,ROUND($G37/23,0),IF($H37=3,ROUND($G37/12,0),IF($H37=6,$G37,IF($H37=7,$G37-ROUND($G37*10/11,0),0))))) -> 39 | N37: =IF($G37="","",K37+L37+M37) -> 466 | O37: =IF($G37="","",IFERROR(VLOOKUP($D37&"|"&$E37,科目表!$A$5:$B$200,2,FALSE),"※未登録")) -> 互助会費 | P37: =IF(OR($G37="",$C37=""),"",IF($B37="決算整理",13,MOD(MONTH($C37)-4,12)+1)) -> 2 | Q37: =IF($G37="","",TRIM(IF(J37+K37+L37+M37<>$G37,"按分不一致 ","")&IF(O37="※未登録","科目未登録 ","")&IF(OR($H37="",ISERROR(MATCH($H37,{1,2,3,4,5,6,7,8},0))),"経費区分? ","")&IF($I37="","状態未設定 ","")&IF(AND(OR($I37="確認済",$I37="未確認"),$B37="月例",OR($C37="",$C37<DATE(年度+2018,4,1),$C37>DATE(年度+2019,3,31))),"年度外の日付 ","")&IF(AND(OR($I37="確認済",$I37="未確認"),O37="対象外"),"対象外の科目 ",""))) | R37: 月例!37
A38: 34 | B38: 月例 | C38: 46163 | D38: 負担金 | E38: 互助会費 | F38: 助成金（５月短期分） | G38: 240 | H38: 2 | I38: 確認済 | J38: =IF($G38="","",IF($H38=1,$G38-ROUND($G38*10/23,0)-2*ROUND($G38/23,0),IF($H38=2,$G38,0))) -> 240 | K38: =IF($G38="","",IF($H38=1,ROUND($G38*10/23,0),IF($H38=3,$G38-2*ROUND($G38/12,0),IF($H38=4,$G38,IF(OR($H38=5,$H38=7),ROUND($G38*10/11,0),0))))) -> 0 | L38: =IF($G38="","",IF($H38=1,ROUND($G38/23,0),IF($H38=3,ROUND($G38/12,0),IF($H38=5,$G38-ROUND($G38*10/11,0),IF($H38=8,$G38,0))))) -> 0 | M38: =IF($G38="","",IF($H38=1,ROUND($G38/23,0),IF($H38=3,ROUND($G38/12,0),IF($H38=6,$G38,IF($H38=7,$G38-ROUND($G38*10/11,0),0))))) -> 0 | N38: =IF($G38="","",K38+L38+M38) -> 0 | O38: =IF($G38="","",IFERROR(VLOOKUP($D38&"|"&$E38,科目表!$A$5:$B$200,2,FALSE),"※未登録")) -> 互助会費 | P38: =IF(OR($G38="",$C38=""),"",IF($B38="決算整理",13,MOD(MONTH($C38)-4,12)+1)) -> 2 | Q38: =IF($G38="","",TRIM(IF(J38+K38+L38+M38<>$G38,"按分不一致 ","")&IF(O38="※未登録","科目未登録 ","")&IF(OR($H38="",ISERROR(MATCH($H38,{1,2,3,4,5,6,7,8},0))),"経費区分? ","")&IF($I38="","状態未設定 ","")&IF(AND(OR($I38="確認済",$I38="未確認"),$B38="月例",OR($C38="",$C38<DATE(年度+2018,4,1),$C38>DATE(年度+2019,3,31))),"年度外の日付 ","")&IF(AND(OR($I38="確認済",$I38="未確認"),O38="対象外"),"対象外の科目 ",""))) | R38: 月例!38
A39: 35 | B39: 月例 | C39: 46162 | D39: 委託費 | F39: レセプト電子データ提供料（２月診療分） | G39: 61859 | H39: 2 | I39: 確認済 | J39: =IF($G39="","",IF($H39=1,$G39-ROUND($G39*10/23,0)-2*ROUND($G39/23,0),IF($H39=2,$G39,0))) -> 61859 | K39: =IF($G39="","",IF($H39=1,ROUND($G39*10/23,0),IF($H39=3,$G39-2*ROUND($G39/12,0),IF($H39=4,$G39,IF(OR($H39=5,$H39=7),ROUND($G39*10/11,0),0))))) -> 0 | L39: =IF($G39="","",IF($H39=1,ROUND($G39/23,0),IF($H39=3,ROUND($G39/12,0),IF($H39=5,$G39-ROUND($G39*10/11,0),IF($H39=8,$G39,0))))) -> 0 | M39: =IF($G39="","",IF($H39=1,ROUND($G39/23,0),IF($H39=3,ROUND($G39/12,0),IF($H39=6,$G39,IF($H39=7,$G39-ROUND($G39*10/11,0),0))))) -> 0 | N39: =IF($G39="","",K39+L39+M39) -> 0 | O39: =IF($G39="","",IFERROR(VLOOKUP($D39&"|"&$E39,科目表!$A$5:$B$200,2,FALSE),"※未登録")) -> 委託費 | P39: =IF(OR($G39="",$C39=""),"",IF($B39="決算整理",13,MOD(MONTH($C39)-4,12)+1)) -> 2 | Q39: =IF($G39="","",TRIM(IF(J39+K39+L39+M39<>$G39,"按分不一致 ","")&IF(O39="※未登録","科目未登録 ","")&IF(OR($H39="",ISERROR(MATCH($H39,{1,2,3,4,5,6,7,8},0))),"経費区分? ","")&IF($I39="","状態未設定 ","")&IF(AND(OR($I39="確認済",$I39="未確認"),$B39="月例",OR($C39="",$C39<DATE(年度+2018,4,1),$C39>DATE(年度+2019,3,31))),"年度外の日付 ","")&IF(AND(OR($I39="確認済",$I39="未確認"),O39="対象外"),"対象外の科目 ",""))) | R39: 月例!39
A40: 36 | B40: 月例 | C40: 45065 | D40: 委託費 | F40: 社会保障等制度 中間サーバー等運営負担金 | G40: 661740 | H40: 2 | I40: 昨年実績 | J40: =IF($G40="","",IF($H40=1,$G40-ROUND($G40*10/23,0)-2*ROUND($G40/23,0),IF($H40=2,$G40,0))) -> 661740 | K40: =IF($G40="","",IF($H40=1,ROUND($G40*10/23,0),IF($H40=3,$G40-2*ROUND($G40/12,0),IF($H40=4,$G40,IF(OR($H40=5,$H40=7),ROUND($G40*10/11,0),0))))) -> 0 | L40: =IF($G40="","",IF($H40=1,ROUND($G40/23,0),IF($H40=3,ROUND($G40/12,0),IF($H40=5,$G40-ROUND($G40*10/11,0),IF($H40=8,$G40,0))))) -> 0 | M40: =IF($G40="","",IF($H40=1,ROUND($G40/23,0),IF($H40=3,ROUND($G40/12,0),IF($H40=6,$G40,IF($H40=7,$G40-ROUND($G40*10/11,0),0))))) -> 0 | N40: =IF($G40="","",K40+L40+M40) -> 0 | O40: =IF($G40="","",IFERROR(VLOOKUP($D40&"|"&$E40,科目表!$A$5:$B$200,2,FALSE),"※未登録")) -> 委託費 | P40: =IF(OR($G40="",$C40=""),"",IF($B40="決算整理",13,MOD(MONTH($C40)-4,12)+1)) -> 2 | Q40: =IF($G40="","",TRIM(IF(J40+K40+L40+M40<>$G40,"按分不一致 ","")&IF(O40="※未登録","科目未登録 ","")&IF(OR($H40="",ISERROR(MATCH($H40,{1,2,3,4,5,6,7,8},0))),"経費区分? ","")&IF($I40="","状態未設定 ","")&IF(AND(OR($I40="確認済",$I40="未確認"),$B40="月例",OR($C40="",$C40<DATE(年度+2018,4,1),$C40>DATE(年度+2019,3,31))),"年度外の日付 ","")&IF(AND(OR($I40="確認済",$I40="未確認"),O40="対象外"),"対象外の科目 ",""))) | R40: 月例!40
A41: 37 | B41: 月例 | C41: 44336 | D41: 事務費 | E41: 通信運搬費 | F41: 電話料金（４月使用・５月請求分） | G41: 5407 | H41: 2 | I41: 昨年実績 | J41: =IF($G41="","",IF($H41=1,$G41-ROUND($G41*10/23,0)-2*ROUND($G41/23,0),IF($H41=2,$G41,0))) -> 5407 | K41: =IF($G41="","",IF($H41=1,ROUND($G41*10/23,0),IF($H41=3,$G41-2*ROUND($G41/12,0),IF($H41=4,$G41,IF(OR($H41=5,$H41=7),ROUND($G41*10/11,0),0))))) -> 0 | L41: =IF($G41="","",IF($H41=1,ROUND($G41/23,0),IF($H41=3,ROUND($G41/12,0),IF($H41=5,$G41-ROUND($G41*10/11,0),IF($H41=8,$G41,0))))) -> 0 | M41: =IF($G41="","",IF($H41=1,ROUND($G41/23,0),IF($H41=3,ROUND($G41/12,0),IF($H41=6,$G41,IF($H41=7,$G41-ROUND($G41*10/11,0),0))))) -> 0 | N41: =IF($G41="","",K41+L41+M41) -> 0 | O41: =IF($G41="","",IFERROR(VLOOKUP($D41&"|"&$E41,科目表!$A$5:$B$200,2,FALSE),"※未登録")) -> 通信運搬費 | P41: =IF(OR($G41="",$C41=""),"",IF($B41="決算整理",13,MOD(MONTH($C41)-4,12)+1)) -> 2 | Q41: =IF($G41="","",TRIM(IF(J41+K41+L41+M41<>$G41,"按分不一致 ","")&IF(O41="※未登録","科目未登録 ","")&IF(OR($H41="",ISERROR(MATCH($H41,{1,2,3,4,5,6,7,8},0))),"経費区分? ","")&IF($I41="","状態未設定 ","")&IF(AND(OR($I41="確認済",$I41="未確認"),$B41="月例",OR($C41="",$C41<DATE(年度+2018,4,1),$C41>DATE(年度+2019,3,31))),"年度外の日付 ","")&IF(AND(OR($I41="確認済",$I41="未確認"),O41="対象外"),"対象外の科目 ",""))) | R41: 月例!41
...

Sheet 入力_貸付
A1: 入力_貸付 貸付経理 台帳（旧：貸付予算差引簿を一本化）
A2: 科目ごとに並べてあります（予算差引簿と同じ見方で「見込残額」が見られます）。新しい支払は最終行の下に追記してください。 状態の使い方は「入力_業務」と同じです。 種別「決算整理」＝3月分を4月に支払うもの（旧：黄色）。
A4: No | B4: 種別 | C4: 支払日 | D4: 科目 | E4: 摘要 | F4: 金額 | G4: 状態 | H4: 計上列 | I4: 見込残額 | J4: 点検 | K4: 元データ
A5: 1 | B5: 通常 | C5: 45559 | D5: 厚生費 | E5: 定期健康診断等（神岡、中村、作本） | F5: 10890 | G5: 昨年実績 | H5: =IF(OR($F5="",$C5=""),"",IF($B5="決算整理",13,MOD(MONTH($C5)-4,12)+1)) -> 6 | I5: =IF(OR($F5="",$D5=""),"",IFERROR(INDEX(費用収益表_貸付!$S$1:$S$60,VLOOKUP($D5,科目表!$K$5:$L$40,2,FALSE))-SUMIFS($F$5:$F5,$D$5:$D5,$D5),"?")) -> 13110 | J5: =IF($F5="","",TRIM(IF(ISERROR(MATCH($D5,科目表!$K$5:$K$40,0)),"科目未登録 ","")&IF($G5="","状態未設定 ","")&IF(AND(OR($G5="確認済",$G5="未確認"),$B5="通常",OR($C5="",$C5<DATE(年度+2018,4,1),$C5>DATE(年度+2019,3,31))),"年度外の日付 ",""))) | K5: 管理簿②!6
A6: 2 | B6: 通常 | C6: 44592 | D6: 厚生費 | E6: 人間ドック 神岡 | F6: 13940 | G6: 昨年実績 | H6: =IF(OR($F6="",$C6=""),"",IF($B6="決算整理",13,MOD(MONTH($C6)-4,12)+1)) -> 10 | I6: =IF(OR($F6="",$D6=""),"",IFERROR(INDEX(費用収益表_貸付!$S$1:$S$60,VLOOKUP($D6,科目表!$K$5:$L$40,2,FALSE))-SUMIFS($F$5:$F6,$D$5:$D6,$D6),"?")) -> -830 | J6: =IF($F6="","",TRIM(IF(ISERROR(MATCH($D6,科目表!$K$5:$K$40,0)),"科目未登録 ","")&IF($G6="","状態未設定 ","")&IF(AND(OR($G6="確認済",$G6="未確認"),$B6="通常",OR($C6="",$C6<DATE(年度+2018,4,1),$C6>DATE(年度+2019,3,31))),"年度外の日付 ",""))) | K6: 管理簿②!7
A7: 3 | B7: 通常 | C7: 44592 | D7: 厚生費 | E7: 定期健康診断（勝部、作本） | F7: 13860 | G7: 昨年実績 | H7: =IF(OR($F7="",$C7=""),"",IF($B7="決算整理",13,MOD(MONTH($C7)-4,12)+1)) -> 10 | I7: =IF(OR($F7="",$D7=""),"",IFERROR(INDEX(費用収益表_貸付!$S$1:$S$60,VLOOKUP($D7,科目表!$K$5:$L$40,2,FALSE))-SUMIFS($F$5:$F7,$D$5:$D7,$D7),"?")) -> -14690 | J7: =IF($F7="","",TRIM(IF(ISERROR(MATCH($D7,科目表!$K$5:$K$40,0)),"科目未登録 ","")&IF($G7="","状態未設定 ","")&IF(AND(OR($G7="確認済",$G7="未確認"),$B7="通常",OR($C7="",$C7<DATE(年度+2018,4,1),$C7>DATE(年度+2019,3,31))),"年度外の日付 ",""))) | K7: 管理簿②!8
A8: 4 | B8: 通常 | C8: 46262 | D8: 厚生費 | E8: 定期健康診断等 貸付経理分（神岡） | F8: 1980 | G8: 確認済 | H8: =IF(OR($F8="",$C8=""),"",IF($B8="決算整理",13,MOD(MONTH($C8)-4,12)+1)) -> 5 | I8: =IF(OR($F8="",$D8=""),"",IFERROR(INDEX(費用収益表_貸付!$S$1:$S$60,VLOOKUP($D8,科目表!$K$5:$L$40,2,FALSE))-SUMIFS($F$5:$F8,$D$5:$D8,$D8),"?")) -> -16670 | J8: =IF($F8="","",TRIM(IF(ISERROR(MATCH($D8,科目表!$K$5:$K$40,0)),"科目未登録 ","")&IF($G8="","状態未設定 ","")&IF(AND(OR($G8="確認済",$G8="未確認"),$B8="通常",OR($C8="",$C8<DATE(年度+2018,4,1),$C8>DATE(年度+2019,3,31))),"年度外の日付 ",""))) | K8: 管理簿②!9
A9: 5 | B9: 通常 | C9: 46280 | D9: 厚生費 | E9: 定期健康診断（中村、作本、福場） | F9: 21527 | G9: 確認済 | H9: =IF(OR($F9="",$C9=""),"",IF($B9="決算整理",13,MOD(MONTH($C9)-4,12)+1)) -> 6 | I9: =IF(OR($F9="",$D9=""),"",IFERROR(INDEX(費用収益表_貸付!$S$1:$S$60,VLOOKUP($D9,科目表!$K$5:$L$40,2,FALSE))-SUMIFS($F$5:$F9,$D$5:$D9,$D9),"?")) -> -38197 | J9: =IF($F9="","",TRIM(IF(ISERROR(MATCH($D9,科目表!$K$5:$K$40,0)),"科目未登録 ","")&IF($G9="","状態未設定 ","")&IF(AND(OR($G9="確認済",$G9="未確認"),$B9="通常",OR($C9="",$C9<DATE(年度+2018,4,1),$C9>DATE(年度+2019,3,31))),"年度外の日付 ",""))) | K9: 管理簿②!11
A10: 6 | B10: 通常 | C10: 46140 | D10: 事務用消耗品費 | E10: 令和８年度基幹ウイルス対策ソフト（ミツイワ株式会社） | F10: 4389 | G10: 確認済 | H10: =IF(OR($F10="",$C10=""),"",IF($B10="決算整理",13,MOD(MONTH($C10)-4,12)+1)) -> 1 | I10: =IF(OR($F10="",$D10=""),"",IFERROR(INDEX(費用収益表_貸付!$S$1:$S$60,VLOOKUP($D10,科目表!$K$5:$L$40,2,FALSE))-SUMIFS($F$5:$F10,$D$5:$D10,$D10),"?")) -> 437611 | J10: =IF($F10="","",TRIM(IF(ISERROR(MATCH($D10,科目表!$K$5:$K$40,0)),"科目未登録 ","")&IF($G10="","状態未設定 ","")&IF(AND(OR($G10="確認済",$G10="未確認"),$B10="通常",OR($C10="",$C10<DATE(年度+2018,4,1),$C10>DATE(年度+2019,3,31))),"年度外の日付 ",""))) | K10: 管理簿①!6
A11: 7 | B11: 通常 | C11: 46188 | D11: 事務用消耗品費 | E11: フラッグインデックス ６８２－１－ＲＥ ２個 ほか８点 | F11: 11491 | G11: 確認済 | H11: =IF(OR($F11="",$C11=""),"",IF($B11="決算整理",13,MOD(MONTH($C11)-4,12)+1)) -> 3 | I11: =IF(OR($F11="",$D11=""),"",IFERROR(INDEX(費用収益表_貸付!$S$1:$S$60,VLOOKUP($D11,科目表!$K$5:$L$40,2,FALSE))-SUMIFS($F$5:$F11,$D$5:$D11,$D11),"?")) -> 426120 | J11: =IF($F11="","",TRIM(IF(ISERROR(MATCH($D11,科目表!$K$5:$K$40,0)),"科目未登録 ","")&IF($G11="","状態未設定 ","")&IF(AND(OR($G11="確認済",$G11="未確認"),$B11="通常",OR($C11="",$C11<DATE(年度+2018,4,1),$C11>DATE(年度+2019,3,31))),"年度外の日付 ",""))) | K11: 管理簿①!7
A12: 8 | B12: 通常 | C12: 45884 | D12: 事務用消耗品費 | E12: ドラムカートリッジ純正品（LB322） １個 | F12: 45265 | G12: 昨年実績 | H12: =IF(OR($F12="",$C12=""),"",IF($B12="決算整理",13,MOD(MONTH($C12)-4,12)+1)) -> 5 | I12: =IF(OR($F12="",$D12=""),"",IFERROR(INDEX(費用収益表_貸付!$S$1:$S$60,VLOOKUP($D12,科目表!$K$5:$L$40,2,FALSE))-SUMIFS($F$5:$F12,$D$5:$D12,$D12),"?")) -> 380855 | J12: =IF($F12="","",TRIM(IF(ISERROR(MATCH($D12,科目表!$K$5:$K$40,0)),"科目未登録 ","")&IF($G12="","状態未設定 ","")&IF(AND(OR($G12="確認済",$G12="未確認"),$B12="通常",OR($C12="",$C12<DATE(年度+2018,4,1),$C12>DATE(年度+2019,3,31))),"年度外の日付 ",""))) | K12: 管理簿①!8
A13: 9 | B13: 通常 | C13: 44515 | D13: 事務用消耗品費 | E13: ニイタカケミガード４㎏ | F13: 2700 | G13: 昨年実績 | H13: =IF(OR($F13="",$C13=""),"",IF($B13="決算整理",13,MOD(MONTH($C13)-4,12)+1)) -> 8 | I13: =IF(OR($F13="",$D13=""),"",IFERROR(INDEX(費用収益表_貸付!$S$1:$S$60,VLOOKUP($D13,科目表!$K$5:$L$40,2,FALSE))-SUMIFS($F$5:$F13,$D$5:$D13,$D13),"?")) -> 378155 | J13: =IF($F13="","",TRIM(IF(ISERROR(MATCH($D13,科目表!$K$5:$K$40,0)),"科目未登録 ","")&IF($G13="","状態未設定 ","")&IF(AND(OR($G13="確認済",$G13="未確認"),$B13="通常",OR($C13="",$C13<DATE(年度+2018,4,1),$C13>DATE(年度+2019,3,31))),"年度外の日付 ",""))) | K13: 管理簿①!9
A14: 10 | B14: 通常 | C14: 45562 | D14: 事務用消耗品費 | E14: トナーカートリッジ再生品（ＬＰＢ３Ｔ３４） 3個 | F14: 22770 | G14: 昨年実績 | H14: =IF(OR($F14="",$C14=""),"",IF($B14="決算整理",13,MOD(MONTH($C14)-4,12)+1)) -> 6 | I14: =IF(OR($F14="",$D14=""),"",IFERROR(INDEX(費用収益表_貸付!$S$1:$S$60,VLOOKUP($D14,科目表!$K$5:$L$40,2,FALSE))-SUMIFS($F$5:$F14,$D$5:$D14,$D14),"?")) -> 355385 | J14: =IF($F14="","",TRIM(IF(ISERROR(MATCH($D14,科目表!$K$5:$K$40,0)),"科目未登録 ","")&IF($G14="","状態未設定 ","")&IF(AND(OR($G14="確認済",$G14="未確認"),$B14="通常",OR($C14="",$C14<DATE(年度+2018,4,1),$C14>DATE(年度+2019,3,31))),"年度外の日付 ",""))) | K14: 管理簿①!10
